Workbook

Sheet Summary
A1: Balance date (change to today's date to bring accruals forward) | B1: 45962
A2: Yellow cells are inputs. Blue text = hand-entered. Black = formula. Source: Bonus_Leave_GC.xlsx (Sheet1) as supplied; EH balances to be pasted in column K.
A3: Employee | B3: Service band (register) | C3: Eligibility date (register) | D3: 5+ rate start month (input) | E3: Expected accrued to balance date (rules) | F3: Accrued per register entries to balance date | G3: Marked used (green) to balance date | H3: Recalculated balance (F - G) | I3: Register's own balance (row 4) | J3: Register minus recalculated (I - H) | K3: EH balance (paste from Employment Hero) | L3: EH minus recalculated (K - H) | M3: Rules minus register entries (E - F) | N3: Flags / notes
A4: Christopher Lehmann | B4: 3-5yrs | C4: 44645 | D4: 45717 | E4: =SUMPRODUCT((Schedule!$A$4:$A$137<=$B$1)*INDEX(Schedule!$B$4:$AD$137,0,MATCH($A4,Schedule!$B$1:$AD$1,0))) -> 12 | F4: =SUMPRODUCT((Register!$A$2:$A$135<=$B$1)*INDEX(Register!$B$2:$AD$135,0,MATCH($A4,Register!$B$1:$AD$1,0))) -> 12 | G4: =SUMPRODUCT((Used!$A$2:$A$135<=$B$1)*INDEX(Used!$B$2:$AD$135,0,MATCH($A4,Used!$B$1:$AD$1,0))) -> 8 | H4: =F4-G4 -> 4 | I4: 4 | J4: =I4-H4 -> 0 | L4: =IF(K4="","",K4-H4) | M4: =E4-F4 -> 0
A5: Daniel Sobkowski | B5: 5+ yrs | C5: 42945 | D5: 43282 | E5: =SUMPRODUCT((Schedule!$A$4:$A$137<=$B$1)*INDEX(Schedule!$B$4:$AD$137,0,MATCH($A5,Schedule!$B$1:$AD$1,0))) -> 40 | F5: =SUMPRODUCT((Register!$A$2:$A$135<=$B$1)*INDEX(Register!$B$2:$AD$135,0,MATCH($A5,Register!$B$1:$AD$1,0))) -> 40 | G5: =SUMPRODUCT((Used!$A$2:$A$135<=$B$1)*INDEX(Used!$B$2:$AD$135,0,MATCH($A5,Used!$B$1:$AD$1,0))) -> 18 | H5: =F5-G5 -> 22 | I5: 22 | J5: =I5-H5 -> 0 | L5: =IF(K5="","",K5-H5) | M5: =E5-F5 -> 0 | N5: 5+ rate start inferred from entries (no yellow cell). Register adds +1 by hand for the part-used Jul-21 accrual.
A6: Danielle Hurley | B6: 3-5yrs | C6: 45702 | D6: 46419 | E6: =SUMPRODUCT((Schedule!$A$4:$A$137<=$B$1)*INDEX(Schedule!$B$4:$AD$137,0,MATCH($A6,Schedule!$B$1:$AD$1,0))) -> 3 | F6: =SUMPRODUCT((Register!$A$2:$A$135<=$B$1)*INDEX(Register!$B$2:$AD$135,0,MATCH($A6,Register!$B$1:$AD$1,0))) -> 3 | G6: =SUMPRODUCT((Used!$A$2:$A$135<=$B$1)*INDEX(Used!$B$2:$AD$135,0,MATCH($A6,Used!$B$1:$AD$1,0))) -> 0 | H6: =F6-G6 -> 3 | I6: 3 | J6: =I6-H6 -> 0 | L6: =IF(K6="","",K6-H6) | M6: =E6-F6 -> 0 | N6: Yellow cell is 2 yrs after eligibility; everyone else is 3 yrs. Check which is right.
A7: Dominique Deveraux | B7: 3-5yrs | C7: 45473 | D7: 46174 | E7: =SUMPRODUCT((Schedule!$A$4:$A$137<=$B$1)*INDEX(Schedule!$B$4:$AD$137,0,MATCH($A7,Schedule!$B$1:$AD$1,0))) -> 5 | F7: =SUMPRODUCT((Register!$A$2:$A$135<=$B$1)*INDEX(Register!$B$2:$AD$135,0,MATCH($A7,Register!$B$1:$AD$1,0))) -> 5 | G7: =SUMPRODUCT((Used!$A$2:$A$135<=$B$1)*INDEX(Used!$B$2:$AD$135,0,MATCH($A7,Used!$B$1:$AD$1,0))) -> 0 | H7: =F7-G7 -> 5 | I7: 5 | J7: =I7-H7 -> 0 | L7: =IF(K7="","",K7-H7) | M7: =E7-F7 -> 0 | N7: Yellow cell is 2 yrs after eligibility; everyone else is 3 yrs. Check which is right.
A8: Duncan Lugstein | B8: 5+ yrs | C8: 42767 | D8: 42767 | E8: =SUMPRODUCT((Schedule!$A$4:$A$137<=$B$1)*INDEX(Schedule!$B$4:$AD$137,0,MATCH($A8,Schedule!$B$1:$AD$1,0))) -> 44 | F8: =SUMPRODUCT((Register!$A$2:$A$135<=$B$1)*INDEX(Register!$B$2:$AD$135,0,MATCH($A8,Register!$B$1:$AD$1,0))) -> 40.5 | G8: =SUMPRODUCT((Used!$A$2:$A$135<=$B$1)*INDEX(Used!$B$2:$AD$135,0,MATCH($A8,Used!$B$1:$AD$1,0))) -> 1 | H8: =F8-G8 -> 39.5 | I8: 39.5 | J8: =I8-H8 -> 0 | L8: =IF(K8="","",K8-H8) | M8: =E8-F8 -> 3.5 | N8: Register total sums from Nov-17 without marking Aug-17 as used first; early 0.5 day entries do not fit the rules pattern.
A9: Henning Schulze | B9: 5+ yrs | C9: 42918 | D9: 42917 | E9: =SUMPRODUCT((Schedule!$A$4:$A$137<=$B$1)*INDEX(Schedule!$B$4:$AD$137,0,MATCH($A9,Schedule!$B$1:$AD$1,0))) -> 42 | F9: =SUMPRODUCT((Register!$A$2:$A$135<=$B$1)*INDEX(Register!$B$2:$AD$135,0,MATCH($A9,Register!$B$1:$AD$1,0))) -> 42 | G9: =SUMPRODUCT((Used!$A$2:$A$135<=$B$1)*INDEX(Used!$B$2:$AD$135,0,MATCH($A9,Used!$B$1:$AD$1,0))) -> 27 | H9: =F9-G9 -> 15 | I9: 20 | J9: =I9-H9 -> 5 | L9: =IF(K9="","",K9-H9) | M9: =E9-F9 -> 0 | N9: Register total (row 4) includes 6 days already marked green as used, and stops at Jul-25. 5+ rate start inferred.
A10: Ryan Gomes | B10: 5+ yrs | C10: 42917 | D10: 42917 | E10: =SUMPRODUCT((Schedule!$A$4:$A$137<=$B$1)*INDEX(Schedule!$B$4:$AD$137,0,MATCH($A10,Schedule!$B$1:$AD$1,0))) -> 42 | F10: =SUMPRODUCT((Register!$A$2:$A$135<=$B$1)*INDEX(Register!$B$2:$AD$135,0,MATCH($A10,Register!$B$1:$AD$1,0))) -> 31 | G10: =SUMPRODUCT((Used!$A$2:$A$135<=$B$1)*INDEX(Used!$B$2:$AD$135,0,MATCH($A10,Used!$B$1:$AD$1,0))) -> 0 | H10: =F10-G10 -> 31 | I10: 10 | J10: =I10-H10 -> -21 | L10: =IF(K10="","",K10-H10) | M10: =E10-F10 -> 11 | N10: No cells marked used, but register total starts at Oct-21. Entries stop Jul-23 (leaver?). 5+ rate start inferred.
A11: Roger Wehbe | B11: 5+ yrs | C11: 42285 | D11: 44105 | E11: =SUMPRODUCT((Schedule!$A$4:$A$137<=$B$1)*INDEX(Schedule!$B$4:$AD$137,0,MATCH($A11,Schedule!$B$1:$AD$1,0))) -> 37 | F11: =SUMPRODUCT((Register!$A$2:$A$135<=$B$1)*INDEX(Register!$B$2:$AD$135,0,MATCH($A11,Register!$B$1:$AD$1,0))) -> 20 | G11: =SUMPRODUCT((Used!$A$2:$A$135<=$B$1)*INDEX(Used!$B$2:$AD$135,0,MATCH($A11,Used!$B$1:$AD$1,0))) -> 9 | H11: =F11-G11 -> 11 | I11: 10 | J11: =I11-H11 -> -1 | L11: =IF(K11="","",K11-H11) | M11: =E11-F11 -> 17 | N11: Register total starts Oct-21, excluding the unmarked Jul-21 accrual, and stops Jul-25. Entries stop Jul-23 (leaver?). Green fills sit on empty cells. 5+ rate start inferred.
A12: George Azzi | B12: 5+ yrs | C12: 43498 | D12: 44593 | E12: =SUMPRODUCT((Schedule!$A$4:$A$137<=$B$1)*INDEX(Schedule!$B$4:$AD$137,0,MATCH($A12,Schedule!$B$1:$AD$1,0))) -> 28 | F12: =SUMPRODUCT((Register!$A$2:$A$135<=$B$1)*INDEX(Register!$B$2:$AD$135,0,MATCH($A12,Register!$B$1:$AD$1,0))) -> 23 | G12: =SUMPRODUCT((Used!$A$2:$A$135<=$B$1)*INDEX(Used!$B$2:$AD$135,0,MATCH($A12,Used!$B$1:$AD$1,0))) -> 14 | H12: =F12-G12 -> 9 | I12: 15 | J12: =I12-H12 -> 6 | L12: =IF(K12="","",K12-H12) | M12: =E12-F12 -> 5 | N12: Register total stops at Jul-25. Entries stop Nov-24.
A13: Gary Carter | B13: 5+ yrs | C13: 43532 | D13: 44621 | E13: =SUMPRODUCT((Schedule!$A$4:$A$137<=$B$1)*INDEX(Schedule!$B$4:$AD$137,0,MATCH($A13,Schedule!$B$1:$AD$1,0))) -> 27 | F13: =SUMPRODUCT((Register!$A$2:$A$135<=$B$1)*INDEX(Register!$B$2:$AD$135,0,MATCH($A13,Register!$B$1:$AD$1,0))) -> 26.5 | G13: =SUMPRODUCT((Used!$A$2:$A$135<=$B$1)*INDEX(Used!$B$2:$AD$135,0,MATCH($A13,Used!$B$1:$AD$1,0))) -> 16 | H13: =F13-G13 -> 10.5 | I13: 12.5 | J13: =I13-H13 -> 2 | L13: =IF(K13="","",K13-H13) | M13: =E13-F13 -> 0.5 | N13: Register adds +0.5 by hand for the part-used Jul-19 accrual.
A14: James Butler | B14: 3-5yrs | C14: 44638 | D14: 45717 | E14: =SUMPRODUCT((Schedule!$A$4:$A$137<=$B$1)*INDEX(Schedule!$B$4:$AD$137,0,MATCH($A14,Schedule!$B$1:$AD$1,0))) -> 12 | F14: =SUMPRODUCT((Register!$A$2:$A$135<=$B$1)*INDEX(Register!$B$2:$AD$135,0,MATCH($A14,Register!$B$1:$AD$1,0))) -> 12 | G14: =SUMPRODUCT((Used!$A$2:$A$135<=$B$1)*INDEX(Used!$B$2:$AD$135,0,MATCH($A14,Used!$B$1:$AD$1,0))) -> 0 | H14: =F14-G14 -> 12 | I14: 12 | J14: =I14-H14 -> 0 | L14: =IF(K14="","",K14-H14) | M14: =E14-F14 -> 0
A15: Jordan Sexty | B15: 5+ yrs | C15: 43579 | D15: 44652 | E15: =SUMPRODUCT((Schedule!$A$4:$A$137<=$B$1)*INDEX(Schedule!$B$4:$AD$137,0,MATCH($A15,Schedule!$B$1:$AD$1,0))) -> 27 | F15: =SUMPRODUCT((Register!$A$2:$A$135<=$B$1)*INDEX(Register!$B$2:$AD$135,0,MATCH($A15,Register!$B$1:$AD$1,0))) -> 27 | G15: =SUMPRODUCT((Used!$A$2:$A$135<=$B$1)*INDEX(Used!$B$2:$AD$135,0,MATCH($A15,Used!$B$1:$AD$1,0))) -> 0 | H15: =F15-G15 -> 27 | I15: 27 | J15: =I15-H15 -> 0 | L15: =IF(K15="","",K15-H15) | M15: =E15-F15 -> 0
A16: Ross Howat | B16: 3-5 yrs | C16: 43601 | D16: 44682 | E16: =SUMPRODUCT((Schedule!$A$4:$A$137<=$B$1)*INDEX(Schedule!$B$4:$AD$137,0,MATCH($A16,Schedule!$B$1:$AD$1,0))) -> 27 | F16: =SUMPRODUCT((Register!$A$2:$A$135<=$B$1)*INDEX(Register!$B$2:$AD$135,0,MATCH($A16,Register!$B$1:$AD$1,0))) -> 23 | G16: =SUMPRODUCT((Used!$A$2:$A$135<=$B$1)*INDEX(Used!$B$2:$AD$135,0,MATCH($A16,Used!$B$1:$AD$1,0))) -> 0 | H16: =F16-G16 -> 23 | I16: 118 | J16: =I16-H16 -> 95 | L16: =IF(K16="","",K16-H16) | M16: =E16-F16 -> 4 | N16: Register total formula spans columns N to U (other employees) - value 118 is wrong. No cells marked used. Entries stop Feb-25.
A17: John Chae | B17: 5+ yrs | C17: 43643 | D17: 44713 | E17: =SUMPRODUCT((Schedule!$A$4:$A$137<=$B$1)*INDEX(Schedule!$B$4:$AD$137,0,MATCH($A17,Schedule!$B$1:$AD$1,0))) -> 26 | F17: =SUMPRODUCT((Register!$A$2:$A$135<=$B$1)*INDEX(Register!$B$2:$AD$135,0,MATCH($A17,Register!$B$1:$AD$1,0))) -> 26 | G17: =SUMPRODUCT((Used!$A$2:$A$135<=$B$1)*INDEX(Used!$B$2:$AD$135,0,MATCH($A17,Used!$B$1:$AD$1,0))) -> 3 | H17: =F17-G17 -> 23 | I17: 13 | J17: =I17-H17 -> -10 | L17: =IF(K17="","",K17-H17) | M17: =E17-F17 -> 0 | N17: Register total only sums Jun-20 to Jun-23; grey block Dec-23 to Sep-24 unexplained. Entries stop Jun-26 in a 2027 grid.
A18: Nick Szwarcberg | B18: 3-5 yrs | C18: 43729 | D18: 44805 | E18: =SUMPRODUCT((Schedule!$A$4:$A$137<=$B$1)*INDEX(Schedule!$B$4:$AD$137,0,MATCH($A18,Schedule!$B$1:$AD$1,0))) -> 25 | F18: =SUMPRODUCT((Register!$A$2:$A$135<=$B$1)*INDEX(Register!$B$2:$AD$135,0,MATCH($A18,Register!$B$1:$AD$1,0))) -> 23 | G18: =SUMPRODUCT((Used!$A$2:$A$135<=$B$1)*INDEX(Used!$B$2:$AD$135,0,MATCH($A18,Used!$B$1:$AD$1,0))) -> 5 | H18: =F18-G18 -> 18 | I18: 105 | J18: =I18-H18 -> 87 | L18: =IF(K18="","",K18-H18) | M18: =E18-F18 -> 2 | N18: Register total formula spans columns P to W (other employees) - value 105 is wrong. Entries stop Jun-25 (leaver?). 5+ rate start inferred.
A19: Kyle Krishnappa | C19: 45905 | D19: 45901 | E19: =SUMPRODUCT((Schedule!$A$4:$A$137<=$B$1)*INDEX(Schedule!$B$4:$AD$137,0,MATCH($A19,Schedule!$B$1:$AD$1,0))) -> 1 | F19: =SUMPRODUCT((Register!$A$2:$A$135<=$B$1)*INDEX(Register!$B$2:$AD$135,0,MATCH($A19,Register!$B$1:$AD$1,0))) -> 1 | G19: =SUMPRODUCT((Used!$A$2:$A$135<=$B$1)*INDEX(Used!$B$2:$AD$135,0,MATCH($A19,Used!$B$1:$AD$1,0))) -> 0 | H19: =F19-G19 -> 1 | I19: 1 | J19: =I19-H19 -> 0 | L19: =IF(K19="","",K19-H19) | M19: =E19-F19 -> 0 | N19: No service band. Stray green fills copied from Nick's column. Two yellow cells (Sep-25 and Sep-27); Sep-25 treated as accrual start only.
A20: Milo Rankin | B20: 3-5yrs | C20: 44960 | D20: 46054 | E20: =SUMPRODUCT((Schedule!$A$4:$A$137<=$B$1)*INDEX(Schedule!$B$4:$AD$137,0,MATCH($A20,Schedule!$B$1:$AD$1,0))) -> 9 | F20: =SUMPRODUCT((Register!$A$2:$A$135<=$B$1)*INDEX(Register!$B$2:$AD$135,0,MATCH($A20,Register!$B$1:$AD$1,0))) -> 9 | G20: =SUMPRODUCT((Used!$A$2:$A$135<=$B$1)*INDEX(Used!$B$2:$AD$135,0,MATCH($A20,Used!$B$1:$AD$1,0))) -> 0 | H20: =F20-G20 -> 9 | I20: 9 | J20: =I20-H20 -> 0 | L20: =IF(K20="","",K20-H20) | M20: =E20-F20 -> 0
A21: Patrick Lee | B21: 3-5yrs | C21: 44939 | D21: 46023 | E21: =SUMPRODUCT((Schedule!$A$4:$A$137<=$B$1)*INDEX(Schedule!$B$4:$AD$137,0,MATCH($A21,Schedule!$B$1:$AD$1,0))) -> 9 | F21: =SUMPRODUCT((Register!$A$2:$A$135<=$B$1)*INDEX(Register!$B$2:$AD$135,0,MATCH($A21,Register!$B$1:$AD$1,0))) -> 9 | G21: =SUMPRODUCT((Used!$A$2:$A$135<=$B$1)*INDEX(Used!$B$2:$AD$135,0,MATCH($A21,Used!$B$1:$AD$1,0))) -> 8 | H21: =F21-G21 -> 1 | I21: 1 | J21: =I21-H21 -> 0 | L21: =IF(K21="","",K21-H21) | M21: =E21-F21 -> 0
A22: Simon Gruenefeld | B22: 3-5yrs | C22: 44645 | D22: 45717 | E22: =SUMPRODUCT((Schedule!$A$4:$A$137<=$B$1)*INDEX(Schedule!$B$4:$AD$137,0,MATCH($A22,Schedule!$B$1:$AD$1,0))) -> 12 | F22: =SUMPRODUCT((Register!$A$2:$A$135<=$B$1)*INDEX(Register!$B$2:$AD$135,0,MATCH($A22,Register!$B$1:$AD$1,0))) -> 12 | G22: =SUMPRODUCT((Used!$A$2:$A$135<=$B$1)*INDEX(Used!$B$2:$AD$135,0,MATCH($A22,Used!$B$1:$AD$1,0))) -> 4 | H22: =F22-G22 -> 8 | I22: 8 | J22: =I22-H22 -> 0 | L22: =IF(K22="","",K22-H22) | M22: =E22-F22 -> 0
A23: Tyler Wood | B23: 5+ yrs | C23: 44015 | D23: 45108 | E23: =SUMPRODUCT((Schedule!$A$4:$A$137<=$B$1)*INDEX(Schedule!$B$4:$AD$137,0,MATCH($A23,Schedule!$B$1:$AD$1,0))) -> 21 | F23: =SUMPRODUCT((Register!$A$2:$A$135<=$B$1)*INDEX(Register!$B$2:$AD$135,0,MATCH($A23,Register!$B$1:$AD$1,0))) -> 21 | G23: =SUMPRODUCT((Used!$A$2:$A$135<=$B$1)*INDEX(Used!$B$2:$AD$135,0,MATCH($A23,Used!$B$1:$AD$1,0))) -> 0 | H23: =F23-G23 -> 21 | I23: 20 | J23: =I23-H23 -> -1 | L23: =IF(K23="","",K23-H23) | M23: =E23-F23 -> 0 | N23: No cells marked used, but register total starts Jan-19 (before eligibility) so it is effectively all accruals to Sep-25.
A24: Josh Howard | B24: 3-5 yrs | C24: 44043 | D24: 45108 | E24: =SUMPRODUCT((Schedule!$A$4:$A$137<=$B$1)*INDEX(Schedule!$B$4:$AD$137,0,MATCH($A24,Schedule!$B$1:$AD$1,0))) -> 21 | F24: =SUMPRODUCT((Register!$A$2:$A$135<=$B$1)*INDEX(Register!$B$2:$AD$135,0,MATCH($A24,Register!$B$1:$AD$1,0))) -> 21 | G24: =SUMPRODUCT((Used!$A$2:$A$135<=$B$1)*INDEX(Used!$B$2:$AD$135,0,MATCH($A24,Used!$B$1:$AD$1,0))) -> 2 | H24: =F24-G24 -> 19 | I24: 16 | J24: =I24-H24 -> -3 | L24: =IF(K24="","",K24-H24) | M24: =E24-F24 -> 0 | N24: Register total starts Oct-21 but only Jul-20 and Nov-20 are marked used; stops Jul-25.
A25: Wade Tonna | B25: 3-5yrs | C25: 44351 | D25: 45444 | E25: =SUMPRODUCT((Schedule!$A$4:$A$137<=$B$1)*INDEX(Schedule!$B$4:$AD$137,0,MATCH($A25,Schedule!$B$1:$AD$1,0))) -> 16 | F25: =SUMPRODUCT((Register!$A$2:$A$135<=$B$1)*INDEX(Register!$B$2:$AD$135,0,MATCH($A25,Register!$B$1:$AD$1,0))) -> 16 | G25: =SUMPRODUCT((Used!$A$2:$A$135<=$B$1)*INDEX(Used!$B$2:$AD$135,0,MATCH($A25,Used!$B$1:$AD$1,0))) -> 4 | H25: =F25-G25 -> 12 | I25: 12 | J25: =I25-H25 -> 0 | L25: =IF(K25="","",K25-H25) | M25: =E25-F25 -> 0 | N25: Register total starts Oct-22 and stops Sep-25.
A26: Melinda Fourie | B26: 3-5 yrs | C26: 44374 | D26: 45444 | E26: =SUMPRODUCT((Schedule!$A$4:$A$137<=$B$1)*INDEX(Schedule!$B$4:$AD$137,0,MATCH($A26,Schedule!$B$1:$AD$1,0))) -> 16 | F26: =SUMPRODUCT((Register!$A$2:$A$135<=$B$1)*INDEX(Register!$B$2:$AD$135,0,MATCH($A26,Register!$B$1:$AD$1,0))) -> 16 | G26: =SUMPRODUCT((Used!$A$2:$A$135<=$B$1)*INDEX(Used!$B$2:$AD$135,0,MATCH($A26,Used!$B$1:$AD$1,0))) -> 0 | H26: =F26-G26 -> 16 | I26: 14 | J26: =I26-H26 -> -2 | L26: =IF(K26="","",K26-H26) | M26: =E26-F26 -> 0 | N26: No cells marked used; register total starts Oct-21 (skips Jun-21) and stops Jul-25.
A27: Alexandra Meneses | B27: 3-5yrs | C27: 44449 | D27: 45536 | E27: =SUMPRODUCT((Schedule!$A$4:$A$137<=$B$1)*INDEX(Schedule!$B$4:$AD$137,0,MATCH($A27,Schedule!$B$1:$AD$1,0))) -> 15 | F27: =SUMPRODUCT((Register!$A$2:$A$135<=$B$1)*INDEX(Register!$B$2:$AD$135,0,MATCH($A27,Register!$B$1:$AD$1,0))) -> 15 | G27: =SUMPRODUCT((Used!$A$2:$A$135<=$B$1)*INDEX(Used!$B$2:$AD$135,0,MATCH($A27,Used!$B$1:$AD$1,0))) -> 0 | H27: =F27-G27 -> 15 | I27: 12 | J27: =I27-H27 -> -3 | L27: =IF(K27="","",K27-H27) | M27: =E27-F27 -> 0 | N27: Eligibility date typed as text '10/09/221' - assumed 10 Sep 2021. No cells marked used; register total starts Oct-21 and stops Jul-25.
A28: Sergiy Khrustal | B28: 3-5yrs | C28: 44479 | D28: 45627 | E28: =SUMPRODUCT((Schedule!$A$4:$A$137<=$B$1)*INDEX(Schedule!$B$4:$AD$137,0,MATCH($A28,Schedule!$B$1:$AD$1,0))) -> 14 | F28: =SUMPRODUCT((Register!$A$2:$A$135<=$B$1)*INDEX(Register!$B$2:$AD$135,0,MATCH($A28,Register!$B$1:$AD$1,0))) -> 13 | G28: =SUMPRODUCT((Used!$A$2:$A$135<=$B$1)*INDEX(Used!$B$2:$AD$135,0,MATCH($A28,Used!$B$1:$AD$1,0))) -> 0 | H28: =F28-G28 -> 13 | I28: 12 | J28: =I28-H28 -> -1 | L28: =IF(K28="","",K28-H28) | M28: =E28-F28 -> 1 | N28: Entries start Dec-21 but eligibility is Oct-21. Yellow cell Dec-24. Register total stops Jul-25.
A29: Jaazaniah Salanoa | B29: 3-5yrs | C29: 44577 | D29: 45658 | E29: =SUMPRODUCT((Schedule!$A$4:$A$137<=$B$1)*INDEX(Schedule!$B$4:$AD$137,0,MATCH($A29,Schedule!$B$1:$AD$1,0))) -> 13 | F29: =SUMPRODUCT((Register!$A$2:$A$135<=$B$1)*INDEX(Register!$B$2:$AD$135,0,MATCH($A29,Register!$B$1:$AD$1,0))) -> 12 | G29: =SUMPRODUCT((Used!$A$2:$A$135<=$B$1)*INDEX(Used!$B$2:$AD$135,0,MATCH($A29,Used!$B$1:$AD$1,0))) -> 0 | H29: =F29-G29 -> 12 | I29: 11 | J29: =I29-H29 -> -1 | L29: =IF(K29="","",K29-H29) | M29: =E29-F29 -> 1 | N29: Red name cell and red block Dec-23 to Dec-24 with no key entry (leave without accrual?). Jan-25 entry is 0. Register total stops Jul-25.
A30: Lauren Addison | B30: 3-5yrs | C30: 44596 | D30: 45689 | E30: =SUMPRODUCT((Schedule!$A$4:$A$137<=$B$1)*INDEX(Schedule!$B$4:$AD$137,0,MATCH($A30,Schedule!$B$1:$AD$1,0))) -> 13 | F30: =SUMPRODUCT((Register!$A$2:$A$135<=$B$1)*INDEX(Register!$B$2:$AD$135,0,MATCH($A30,Register!$B$1:$AD$1,0))) -> 13 | G30: =SUMPRODUCT((Used!$A$2:$A$135<=$B$1)*INDEX(Used!$B$2:$AD$135,0,MATCH($A30,Used!$B$1:$AD$1,0))) -> 0 | H30: =F30-G30 -> 13 | I30: 11 | J30: =I30-H30 -> -2 | L30: =IF(K30="","",K30-H30) | M30: =E30-F30 -> 0 | N30: Register total stops Jul-25.
A31: Jin Won A Choi | B31: 3-5yrs | E31: =SUMPRODUCT((Schedule!$A$4:$A$137<=$B$1)*INDEX(Schedule!$B$4:$AD$137,0,MATCH($A31,Schedule!$B$1:$AD$1,0))) -> 0 | F31: =SUMPRODUCT((Register!$A$2:$A$135<=$B$1)*INDEX(Register!$B$2:$AD$135,0,MATCH($A31,Register!$B$1:$AD$1,0))) -> 2 | G31: =SUMPRODUCT((Used!$A$2:$A$135<=$B$1)*INDEX(Used!$B$2:$AD$135,0,MATCH($A31,Used!$B$1:$AD$1,0))) -> 0 | H31: =F31-G31 -> 2 | I31: 2 | J31: =I31-H31 -> 0 | L31: =IF(K31="","",K31-H31) | M31: =E31-F31 -> -2 | N31: No eligibility date; only two entries (Apr-22, Aug-22). Probably a leaver - confirm and remove.
A32: Anna Aubusson | B32: 3-5yrs | C32: 45172 | D32: 46266 | E32: =SUMPRODUCT((Schedule!$A$4:$A$137<=$B$1)*INDEX(Schedule!$B$4:$AD$137,0,MATCH($A32,Schedule!$B$1:$AD$1,0))) -> 7 | F32: =SUMPRODUCT((Register!$A$2:$A$135<=$B$1)*INDEX(Register!$B$2:$AD$135,0,MATCH($A32,Register!$B$1:$AD$1,0))) -> 4 | G32: =SUMPRODUCT((Used!$A$2:$A$135<=$B$1)*INDEX(Used!$B$2:$AD$135,0,MATCH($A32,Used!$B$1:$AD$1,0))) -> 3 | H32: =F32-G32 -> 1 | I32: 1 | J32: =I32-H32 -> 0 | L32: =IF(K32="","",K32-H32) | M32: =E32-F32 -> 3 | N32: Register total only sums Jul-25 to Sep-25 although three earlier accruals are marked used and Sep-25 is not.
A33: Total | E33: =SUM(E4:E32) -> 564 | F33: =SUM(F4:F32) -> 518 | G33: =SUM(G4:G32) -> 122 | H33: =SUM(H4:H32) -> 396 | I33: =SUM(I4:I32) -> 546 | J33: =SUM(J4:J32) -> 150 | K33: =SUM(K4:K32) -> 0 | M33: =SUM(M4:M32) -> 46

Sheet Register
A1: Month | B1: Christopher Lehmann | C1: Daniel Sobkowski | D1: Danielle Hurley | E1: Dominique Deveraux | F1: Duncan Lugstein | G1: Henning Schulze | H1: Ryan Gomes | I1: Roger Wehbe | J1: George Azzi | K1: Gary Carter | L1: James Butler | M1: Jordan Sexty | N1: Ross Howat | O1: John Chae | P1: Nick Szwarcberg | Q1: Kyle Krishnappa | R1: Milo Rankin | S1: Patrick Lee | T1: Simon Gruenefeld | U1: Tyler Wood | V1: Josh Howard | W1: Wade Tonna | X1: Melinda Fourie | Y1: Alexandra Meneses | Z1: Sergiy Khrustal | AA1: Jaazaniah Salanoa | AB1: Lauren Addison | AC1: Jin Won A Choi | AD1: Anna Aubusson
A2: 42736
A3: 42767
A4: 42795
A5: 42826
A6: 42856
A7: 42887
A8: 42917 | C8: 1 | G8: 1 | H8: 1
A9: 42948 | F9: 1
A10: 42979
A11: 43009 | G11: 1 | H11: 1
A12: 43040 | C12: 1 | F12: 0.5
A13: 43070
A14: 43101 | G14: 1 | H14: 1
A15: 43132 | F15: 2
A16: 43160 | C16: 1
A17: 43191 | G17: 1 | H17: 1
A18: 43221 | F18: 1
A19: 43252
A20: 43282 | C20: 1 | G20: 2 | H20: 2
A21: 43313 | F21: 1
A22: 43344
A23: 43374 | C23: 1 | G23: 1 | H23: 1 | I23: 1
A24: 43405 | F24: 1
A25: 43435
A26: 43466 | C26: 1 | G26: 1 | H26: 1
A27: 43497 | F27: 2 | I27: 1 | J27: 1
A28: 43525 | K28: 1
A29: 43556 | C29: 1 | G29: 1 | H29: 1 | M29: 1
A30: 43586 | F30: 1 | N30: 1
A31: 43617 | I31: 1 | J31: 1 | O31: 1
A32: 43647 | C32: 2 | G32: 2 | H32: 2 | K32: 0.5
A33: 43678 | F33: 1 | M33: 1
A34: 43709 | N34: 1 | P34: 1
A35: 43739 | C35: 1 | G35: 1 | H35: 1 | I35: 1 | J35: 1 | O35: 1
A36: 43770 | F36: 1 | K36: 1
A37: 43800 | M37: 1
A38: 43831 | C38: 1 | G38: 1 | H38: 1 | N38: 1 | P38: 1
A39: 43862 | F39: 2 | I39: 1 | J39: 1 | O39: 1
A40: 43891 | K40: 1
...

Sheet Used
A1: Month | B1: Christopher Lehmann | C1: Daniel Sobkowski | D1: Danielle Hurley | E1: Dominique Deveraux | F1: Duncan Lugstein | G1: Henning Schulze | H1: Ryan Gomes | I1: Roger Wehbe | J1: George Azzi | K1: Gary Carter | L1: James Butler | M1: Jordan Sexty | N1: Ross Howat | O1: John Chae | P1: Nick Szwarcberg | Q1: Kyle Krishnappa | R1: Milo Rankin | S1: Patrick Lee | T1: Simon Gruenefeld | U1: Tyler Wood | V1: Josh Howard | W1: Wade Tonna | X1: Melinda Fourie | Y1: Alexandra Meneses | Z1: Sergiy Khrustal | AA1: Jaazaniah Salanoa | AB1: Lauren Addison | AC1: Jin Won A Choi | AD1: Anna Aubusson
A2: 42736
A3: 42767
A4: 42795
A5: 42826
A6: 42856
A7: 42887
A8: 42917 | C8: 1 | G8: 1
A9: 42948 | F9: 1
A10: 42979
A11: 43009 | G11: 1
A12: 43040 | C12: 1 | F12: 0
A13: 43070
A14: 43101 | G14: 1
A15: 43132
A16: 43160 | C16: 1
A17: 43191 | G17: 1
A18: 43221
A19: 43252
A20: 43282 | C20: 1 | G20: 2
A21: 43313
A22: 43344
A23: 43374 | C23: 1 | G23: 1 | I23: 1
A24: 43405
A25: 43435
A26: 43466 | C26: 1 | G26: 1
A27: 43497 | I27: 1 | J27: 1
A28: 43525 | K28: 1
A29: 43556 | C29: 1 | G29: 1
A30: 43586
A31: 43617 | I31: 1 | J31: 1 | O31: 1
A32: 43647 | C32: 2 | G32: 2 | K32: 0
A33: 43678
A34: 43709 | P34: 1
A35: 43739 | C35: 1 | G35: 1 | I35: 1 | J35: 1 | O35: 1
A36: 43770 | K36: 1
A37: 43800
A38: 43831 | C38: 1 | G38: 1 | P38: 1
A39: 43862 | I39: 1 | J39: 1 | O39: 1
A40: 43891 | K40: 1
...

Sheet Schedule
A1: Employee | B1: =Summary!A4 -> Christopher Lehmann | C1: =Summary!A5 -> Daniel Sobkowski | D1: =Summary!A6 -> Danielle Hurley | E1: =Summary!A7 -> Dominique Deveraux | F1: =Summary!A8 -> Duncan Lugstein | G1: =Summary!A9 -> Henning Schulze | H1: =Summary!A10 -> Ryan Gomes | I1: =Summary!A11 -> Roger Wehbe | J1: =Summary!A12 -> George Azzi | K1: =Summary!A13 -> Gary Carter | L1: =Summary!A14 -> James Butler | M1: =Summary!A15 -> Jordan Sexty | N1: =Summary!A16 -> Ross Howat | O1: =Summary!A17 -> John Chae | P1: =Summary!A18 -> Nick Szwarcberg | Q1: =Summary!A19 -> Kyle Krishnappa | R1: =Summary!A20 -> Milo Rankin | S1: =Summary!A21 -> Patrick Lee | T1: =Summary!A22 -> Simon Gruenefeld | U1: =Summary!A23 -> Tyler Wood | V1: =Summary!A24 -> Josh Howard | W1: =Summary!A25 -> Wade Tonna | X1: =Summary!A26 -> Melinda Fourie | Y1: =Summary!A27 -> Alexandra Meneses | Z1: =Summary!A28 -> Sergiy Khrustal | AA1: =Summary!A29 -> Jaazaniah Salanoa | AB1: =Summary!A30 -> Lauren Addison | AC1: =Summary!A31 -> Jin Won A Choi | AD1: =Summary!A32 -> Anna Aubusson
A2: Eligibility month | B2: =IF(ISNUMBER(Summary!C4),DATE(YEAR(Summary!C4),MONTH(Summary!C4),1),"") -> 44621 | C2: =IF(ISNUMBER(Summary!C5),DATE(YEAR(Summary!C5),MONTH(Summary!C5),1),"") -> 42917 | D2: =IF(ISNUMBER(Summary!C6),DATE(YEAR(Summary!C6),MONTH(Summary!C6),1),"") -> 45689 | E2: =IF(ISNUMBER(Summary!C7),DATE(YEAR(Summary!C7),MONTH(Summary!C7),1),"") -> 45444 | F2: =IF(ISNUMBER(Summary!C8),DATE(YEAR(Summary!C8),MONTH(Summary!C8),1),"") -> 42767 | G2: =IF(ISNUMBER(Summary!C9),DATE(YEAR(Summary!C9),MONTH(Summary!C9),1),"") -> 42917 | H2: =IF(ISNUMBER(Summary!C10),DATE(YEAR(Summary!C10),MONTH(Summary!C10),1),"") -> 42917 | I2: =IF(ISNUMBER(Summary!C11),DATE(YEAR(Summary!C11),MONTH(Summary!C11),1),"") -> 42278 | J2: =IF(ISNUMBER(Summary!C12),DATE(YEAR(Summary!C12),MONTH(Summary!C12),1),"") -> 43497 | K2: =IF(ISNUMBER(Summary!C13),DATE(YEAR(Summary!C13),MONTH(Summary!C13),1),"") -> 43525 | L2: =IF(ISNUMBER(Summary!C14),DATE(YEAR(Summary!C14),MONTH(Summary!C14),1),"") -> 44621 | M2: =IF(ISNUMBER(Summary!C15),DATE(YEAR(Summary!C15),MONTH(Summary!C15),1),"") -> 43556 | N2: =IF(ISNUMBER(Summary!C16),DATE(YEAR(Summary!C16),MONTH(Summary!C16),1),"") -> 43586 | O2: =IF(ISNUMBER(Summary!C17),DATE(YEAR(Summary!C17),MONTH(Summary!C17),1),"") -> 43617 | P2: =IF(ISNUMBER(Summary!C18),DATE(YEAR(Summary!C18),MONTH(Summary!C18),1),"") -> 43709 | Q2: =IF(ISNUMBER(Summary!C19),DATE(YEAR(Summary!C19),MONTH(Summary!C19),1),"") -> 45901 | R2: =IF(ISNUMBER(Summary!C20),DATE(YEAR(Summary!C20),MONTH(Summary!C20),1),"") -> 44958 | S2: =IF(ISNUMBER(Summary!C21),DATE(YEAR(Summary!C21),MONTH(Summary!C21),1),"") -> 44927 | T2: =IF(ISNUMBER(Summary!C22),DATE(YEAR(Summary!C22),MONTH(Summary!C22),1),"") -> 44621 | U2: =IF(ISNUMBER(Summary!C23),DATE(YEAR(Summary!C23),MONTH(Summary!C23),1),"") -> 44013 | V2: =IF(ISNUMBER(Summary!C24),DATE(YEAR(Summary!C24),MONTH(Summary!C24),1),"") -> 44013 | W2: =IF(ISNUMBER(Summary!C25),DATE(YEAR(Summary!C25),MONTH(Summary!C25),1),"") -> 44348 | X2: =IF(ISNUMBER(Summary!C26),DATE(YEAR(Summary!C26),MONTH(Summary!C26),1),"") -> 44348 | Y2: =IF(ISNUMBER(Summary!C27),DATE(YEAR(Summary!C27),MONTH(Summary!C27),1),"") -> 44440 | Z2: =IF(ISNUMBER(Summary!C28),DATE(YEAR(Summary!C28),MONTH(Summary!C28),1),"") -> 44470 | AA2: =IF(ISNUMBER(Summary!C29),DATE(YEAR(Summary!C29),MONTH(Summary!C29),1),"") -> 44562 | AB2: =IF(ISNUMBER(Summary!C30),DATE(YEAR(Summary!C30),MONTH(Summary!C30),1),"") -> 44593 | AC2: =IF(ISNUMBER(Summary!C31),DATE(YEAR(Summary!C31),MONTH(Summary!C31),1),"") | AD2: =IF(ISNUMBER(Summary!C32),DATE(YEAR(Summary!C32),MONTH(Summary!C32),1),"") -> 45170
A3: 5+ rate start month | B3: =IF(ISNUMBER(Summary!D4),DATE(YEAR(Summary!D4),MONTH(Summary!D4),1),"") -> 45717 | C3: =IF(ISNUMBER(Summary!D5),DATE(YEAR(Summary!D5),MONTH(Summary!D5),1),"") -> 43282 | D3: =IF(ISNUMBER(Summary!D6),DATE(YEAR(Summary!D6),MONTH(Summary!D6),1),"") -> 46419 | E3: =IF(ISNUMBER(Summary!D7),DATE(YEAR(Summary!D7),MONTH(Summary!D7),1),"") -> 46174 | F3: =IF(ISNUMBER(Summary!D8),DATE(YEAR(Summary!D8),MONTH(Summary!D8),1),"") -> 42767 | G3: =IF(ISNUMBER(Summary!D9),DATE(YEAR(Summary!D9),MONTH(Summary!D9),1),"") -> 42917 | H3: =IF(ISNUMBER(Summary!D10),DATE(YEAR(Summary!D10),MONTH(Summary!D10),1),"") -> 42917 | I3: =IF(ISNUMBER(Summary!D11),DATE(YEAR(Summary!D11),MONTH(Summary!D11),1),"") -> 44105 | J3: =IF(ISNUMBER(Summary!D12),DATE(YEAR(Summary!D12),MONTH(Summary!D12),1),"") -> 44593 | K3: =IF(ISNUMBER(Summary!D13),DATE(YEAR(Summary!D13),MONTH(Summary!D13),1),"") -> 44621 | L3: =IF(ISNUMBER(Summary!D14),DATE(YEAR(Summary!D14),MONTH(Summary!D14),1),"") -> 45717 | M3: =IF(ISNUMBER(Summary!D15),DATE(YEAR(Summary!D15),MONTH(Summary!D15),1),"") -> 44652 | N3: =IF(ISNUMBER(Summary!D16),DATE(YEAR(Summary!D16),MONTH(Summary!D16),1),"") -> 44682 | O3: =IF(ISNUMBER(Summary!D17),DATE(YEAR(Summary!D17),MONTH(Summary!D17),1),"") -> 44713 | P3: =IF(ISNUMBER(Summary!D18),DATE(YEAR(Summary!D18),MONTH(Summary!D18),1),"") -> 44805 | Q3: =IF(ISNUMBER(Summary!D19),DATE(YEAR(Summary!D19),MONTH(Summary!D19),1),"") -> 45901 | R3: =IF(ISNUMBER(Summary!D20),DATE(YEAR(Summary!D20),MONTH(Summary!D20),1),"") -> 46054 | S3: =IF(ISNUMBER(Summary!D21),DATE(YEAR(Summary!D21),MONTH(Summary!D21),1),"") -> 46023 | T3: =IF(ISNUMBER(Summary!D22),DATE(YEAR(Summary!D22),MONTH(Summary!D22),1),"") -> 45717 | U3: =IF(ISNUMBER(Summary!D23),DATE(YEAR(Summary!D23),MONTH(Summary!D23),1),"") -> 45108 | V3: =IF(ISNUMBER(Summary!D24),DATE(YEAR(Summary!D24),MONTH(Summary!D24),1),"") -> 45108 | W3: =IF(ISNUMBER(Summary!D25),DATE(YEAR(Summary!D25),MONTH(Summary!D25),1),"") -> 45444 | X3: =IF(ISNUMBER(Summary!D26),DATE(YEAR(Summary!D26),MONTH(Summary!D26),1),"") -> 45444 | Y3: =IF(ISNUMBER(Summary!D27),DATE(YEAR(Summary!D27),MONTH(Summary!D27),1),"") -> 45536 | Z3: =IF(ISNUMBER(Summary!D28),DATE(YEAR(Summary!D28),MONTH(Summary!D28),1),"") -> 45627 | AA3: =IF(ISNUMBER(Summary!D29),DATE(YEAR(Summary!D29),MONTH(Summary!D29),1),"") -> 45658 | AB3: =IF(ISNUMBER(Summary!D30),DATE(YEAR(Summary!D30),MONTH(Summary!D30),1),"") -> 45689 | AC3: =IF(ISNUMBER(Summary!D31),DATE(YEAR(Summary!D31),MONTH(Summary!D31),1),"") | AD3: =IF(ISNUMBER(Summary!D32),DATE(YEAR(Summary!D32),MONTH(Summary!D32),1),"") -> 46266
A4: 42736 | B4: =IF(OR(B$2="",$A4<B$2),0,IF(OR(B$3="",$A4<B$3),IF(MOD(((YEAR($A4)-YEAR(B$2))*12+MONTH($A4)-MONTH(B$2)),4)=0,1,0),IF(MOD(((YEAR($A4)-YEAR(B$3))*12+MONTH($A4)-MONTH(B$3)),3)=0,IF(AND(((YEAR($A4)-YEAR(B$3))*12+MONTH($A4)-MONTH(B$3))>0,MOD(((YEAR($A4)-YEAR(B$3))*12+MONTH($A4)-MONTH(B$3)),12)=0),2,1),0))) -> 0 | C4: =IF(OR(C$2="",$A4<C$2),0,IF(OR(C$3="",$A4<C$3),IF(MOD(((YEAR($A4)-YEAR(C$2))*12+MONTH($A4)-MONTH(C$2)),4)=0,1,0),IF(MOD(((YEAR($A4)-YEAR(C$3))*12+MONTH($A4)-MONTH(C$3)),3)=0,IF(AND(((YEAR($A4)-YEAR(C$3))*12+MONTH($A4)-MONTH(C$3))>0,MOD(((YEAR($A4)-YEAR(C$3))*12+MONTH($A4)-MONTH(C$3)),12)=0),2,1),0))) -> 0 | D4: =IF(OR(D$2="",$A4<D$2),0,IF(OR(D$3="",$A4<D$3),IF(MOD(((YEAR($A4)-YEAR(D$2))*12+MONTH($A4)-MONTH(D$2)),4)=0,1,0),IF(MOD(((YEAR($A4)-YEAR(D$3))*12+MONTH($A4)-MONTH(D$3)),3)=0,IF(AND(((YEAR($A4)-YEAR(D$3))*12+MONTH($A4)-MONTH(D$3))>0,MOD(((YEAR($A4)-YEAR(D$3))*12+MONTH($A4)-MONTH(D$3)),12)=0),2,1),0))) -> 0 | E4: =IF(OR(E$2="",$A4<E$2),0,IF(OR(E$3="",$A4<E$3),IF(MOD(((YEAR($A4)-YEAR(E$2))*12+MONTH($A4)-MONTH(E$2)),4)=0,1,0),IF(MOD(((YEAR($A4)-YEAR(E$3))*12+MONTH($A4)-MONTH(E$3)),3)=0,IF(AND(((YEAR($A4)-YEAR(E$3))*12+MONTH($A4)-MONTH(E$3))>0,MOD(((YEAR($A4)-YEAR(E$3))*12+MONTH($A4)-MONTH(E$3)),12)=0),2,1),0))) -> 0 | F4: =IF(OR(F$2="",$A4<F$2),0,IF(OR(F$3="",$A4<F$3),IF(MOD(((YEAR($A4)-YEAR(F$2))*12+MONTH($A4)-MONTH(F$2)),4)=0,1,0),IF(MOD(((YEAR($A4)-YEAR(F$3))*12+MONTH($A4)-MONTH(F$3)),3)=0,IF(AND(((YEAR($A4)-YEAR(F$3))*12+MONTH($A4)-MONTH(F$3))>0,MOD(((YEAR($A4)-YEAR(F$3))*12+MONTH($A4)-MONTH(F$3)),12)=0),2,1),0))) -> 0 | G4: =IF(OR(G$2="",$A4<G$2),0,IF(OR(G$3="",$A4<G$3),IF(MOD(((YEAR($A4)-YEAR(G$2))*12+MONTH($A4)-MONTH(G$2)),4)=0,1,0),IF(MOD(((YEAR($A4)-YEAR(G$3))*12+MONTH($A4)-MONTH(G$3)),3)=0,IF(AND(((YEAR($A4)-YEAR(G$3))*12+MONTH($A4)-MONTH(G$3))>0,MOD(((YEAR($A4)-YEAR(G$3))*12+MONTH($A4)-MONTH(G$3)),12)=0),2,1),0))) -> 0 | H4: =IF(OR(H$2="",$A4<H$2),0,IF(OR(H$3="",$A4<H$3),IF(MOD(((YEAR($A4)-YEAR(H$2))*12+MONTH($A4)-MONTH(H$2)),4)=0,1,0),IF(MOD(((YEAR($A4)-YEAR(H$3))*12+MONTH($A4)-MONTH(H$3)),3)=0,IF(AND(((YEAR($A4)-YEAR(H$3))*12+MONTH($A4)-MONTH(H$3))>0,MOD(((YEAR($A4)-YEAR(H$3))*12+MONTH($A4)-MONTH(H$3)),12)=0),2,1),0))) -> 0 | I4: =IF(OR(I$2="",$A4<I$2),0,IF(OR(I$3="",$A4<I$3),IF(MOD(((YEAR($A4)-YEAR(I$2))*12+MONTH($A4)-MONTH(I$2)),4)=0,1,0),IF(MOD(((YEAR($A4)-YEAR(I$3))*12+MONTH($A4)-MONTH(I$3)),3)=0,IF(AND(((YEAR($A4)-YEAR(I$3))*12+MONTH($A4)-MONTH(I$3))>0,MOD(((YEAR($A4)-YEAR(I$3))*12+MONTH($A4)-MONTH(I$3)),12)=0),2,1),0))) -> 0 | ... AD4: =IF(OR(AD$2="",$A4<AD$2),0,IF(OR(AD$3="",$A4<AD$3),IF(MOD(((YEAR($A4)-YEAR(AD$2))*12+MONTH($A4)-MONTH(AD$2)),4)=0,1,0),IF(MOD(((YEAR($A4)-YEAR(AD$3))*12+MONTH($A4)-MONTH(AD$3)),3)=0,IF(AND(((YEAR($A4)-YEAR(AD$3))*12+MONTH($A4)-MONTH(AD$3))>0,MOD(((YEAR($A4)-YEAR(AD$3))*12+MONTH($A4)-MONTH(AD$3)),12)=0),2,1),0))) -> 0
A5: 42767 | B5: =IF(OR(B$2="",$A5<B$2),0,IF(OR(B$3="",$A5<B$3),IF(MOD(((YEAR($A5)-YEAR(B$2))*12+MONTH($A5)-MONTH(B$2)),4)=0,1,0),IF(MOD(((YEAR($A5)-YEAR(B$3))*12+MONTH($A5)-MONTH(B$3)),3)=0,IF(AND(((YEAR($A5)-YEAR(B$3))*12+MONTH($A5)-MONTH(B$3))>0,MOD(((YEAR($A5)-YEAR(B$3))*12+MONTH($A5)-MONTH(B$3)),12)=0),2,1),0))) -> 0 | C5: =IF(OR(C$2="",$A5<C$2),0,IF(OR(C$3="",$A5<C$3),IF(MOD(((YEAR($A5)-YEAR(C$2))*12+MONTH($A5)-MONTH(C$2)),4)=0,1,0),IF(MOD(((YEAR($A5)-YEAR(C$3))*12+MONTH($A5)-MONTH(C$3)),3)=0,IF(AND(((YEAR($A5)-YEAR(C$3))*12+MONTH($A5)-MONTH(C$3))>0,MOD(((YEAR($A5)-YEAR(C$3))*12+MONTH($A5)-MONTH(C$3)),12)=0),2,1),0))) -> 0 | D5: =IF(OR(D$2="",$A5<D$2),0,IF(OR(D$3="",$A5<D$3),IF(MOD(((YEAR($A5)-YEAR(D$2))*12+MONTH($A5)-MONTH(D$2)),4)=0,1,0),IF(MOD(((YEAR($A5)-YEAR(D$3))*12+MONTH($A5)-MONTH(D$3)),3)=0,IF(AND(((YEAR($A5)-YEAR(D$3))*12+MONTH($A5)-MONTH(D$3))>0,MOD(((YEAR($A5)-YEAR(D$3))*12+MONTH($A5)-MONTH(D$3)),12)=0),2,1),0))) -> 0 | E5: =IF(OR(E$2="",$A5<E$2),0,IF(OR(E$3="",$A5<E$3),IF(MOD(((YEAR($A5)-YEAR(E$2))*12+MONTH($A5)-MONTH(E$2)),4)=0,1,0),IF(MOD(((YEAR($A5)-YEAR(E$3))*12+MONTH($A5)-MONTH(E$3)),3)=0,IF(AND(((YEAR($A5)-YEAR(E$3))*12+MONTH($A5)-MONTH(E$3))>0,MOD(((YEAR($A5)-YEAR(E$3))*12+MONTH($A5)-MONTH(E$3)),12)=0),2,1),0))) -> 0 | F5: =IF(OR(F$2="",$A5<F$2),0,IF(OR(F$3="",$A5<F$3),IF(MOD(((YEAR($A5)-YEAR(F$2))*12+MONTH($A5)-MONTH(F$2)),4)=0,1,0),IF(MOD(((YEAR($A5)-YEAR(F$3))*12+MONTH($A5)-MONTH(F$3)),3)=0,IF(AND(((YEAR($A5)-YEAR(F$3))*12+MONTH($A5)-MONTH(F$3))>0,MOD(((YEAR($A5)-YEAR(F$3))*12+MONTH($A5)-MONTH(F$3)),12)=0),2,1),0))) -> 1 | G5: =IF(OR(G$2="",$A5<G$2),0,IF(OR(G$3="",$A5<G$3),IF(MOD(((YEAR($A5)-YEAR(G$2))*12+MONTH($A5)-MONTH(G$2)),4)=0,1,0),IF(MOD(((YEAR($A5)-YEAR(G$3))*12+MONTH($A5)-MONTH(G$3)),3)=0,IF(AND(((YEAR($A5)-YEAR(G$3))*12+MONTH($A5)-MONTH(G$3))>0,MOD(((YEAR($A5)-YEAR(G$3))*12+MONTH($A5)-MONTH(G$3)),12)=0),2,1),0))) -> 0 | H5: =IF(OR(H$2="",$A5<H$2),0,IF(OR(H$3="",$A5<H$3),IF(MOD(((YEAR($A5)-YEAR(H$2))*12+MONTH($A5)-MONTH(H$2)),4)=0,1,0),IF(MOD(((YEAR($A5)-YEAR(H$3))*12+MONTH($A5)-MONTH(H$3)),3)=0,IF(AND(((YEAR($A5)-YEAR(H$3))*12+MONTH($A5)-MONTH(H$3))>0,MOD(((YEAR($A5)-YEAR(H$3))*12+MONTH($A5)-MONTH(H$3)),12)=0),2,1),0))) -> 0 | I5: =IF(OR(I$2="",$A5<I$2),0,IF(OR(I$3="",$A5<I$3),IF(MOD(((YEAR($A5)-YEAR(I$2))*12+MONTH($A5)-MONTH(I$2)),4)=0,1,0),IF(MOD(((YEAR($A5)-YEAR(I$3))*12+MONTH($A5)-MONTH(I$3)),3)=0,IF(AND(((YEAR($A5)-YEAR(I$3))*12+MONTH($A5)-MONTH(I$3))>0,MOD(((YEAR($A5)-YEAR(I$3))*12+MONTH($A5)-MONTH(I$3)),12)=0),2,1),0))) -> 1 | ... AD5: =IF(OR(AD$2="",$A5<AD$2),0,IF(OR(AD$3="",$A5<AD$3),IF(MOD(((YEAR($A5)-YEAR(AD$2))*12+MONTH($A5)-MONTH(AD$2)),4)=0,1,0),IF(MOD(((YEAR($A5)-YEAR(AD$3))*12+MONTH($A5)-MONTH(AD$3)),3)=0,IF(AND(((YEAR($A5)-YEAR(AD$3))*12+MONTH($A5)-MONTH(AD$3))>0,MOD(((YEAR($A5)-YEAR(AD$3))*12+MONTH($A5)-MONTH(AD$3)),12)=0),2,1),0))) -> 0
A6: 42795 | B6: =IF(OR(B$2="",$A6<B$2),0,IF(OR(B$3="",$A6<B$3),IF(MOD(((YEAR($A6)-YEAR(B$2))*12+MONTH($A6)-MONTH(B$2)),4)=0,1,0),IF(MOD(((YEAR($A6)-YEAR(B$3))*12+MONTH($A6)-MONTH(B$3)),3)=0,IF(AND(((YEAR($A6)-YEAR(B$3))*12+MONTH($A6)-MONTH(B$3))>0,MOD(((YEAR($A6)-YEAR(B$3))*12+MONTH($A6)-MONTH(B$3)),12)=0),2,1),0))) -> 0 | C6: =IF(OR(C$2="",$A6<C$2),0,IF(OR(C$3="",$A6<C$3),IF(MOD(((YEAR($A6)-YEAR(C$2))*12+MONTH($A6)-MONTH(C$2)),4)=0,1,0),IF(MOD(((YEAR($A6)-YEAR(C$3))*12+MONTH($A6)-MONTH(C$3)),3)=0,IF(AND(((YEAR($A6)-YEAR(C$3))*12+MONTH($A6)-MONTH(C$3))>0,MOD(((YEAR($A6)-YEAR(C$3))*12+MONTH($A6)-MONTH(C$3)),12)=0),2,1),0))) -> 0 | D6: =IF(OR(D$2="",$A6<D$2),0,IF(OR(D$3="",$A6<D$3),IF(MOD(((YEAR($A6)-YEAR(D$2))*12+MONTH($A6)-MONTH(D$2)),4)=0,1,0),IF(MOD(((YEAR($A6)-YEAR(D$3))*12+MONTH($A6)-MONTH(D$3)),3)=0,IF(AND(((YEAR($A6)-YEAR(D$3))*12+MONTH($A6)-MONTH(D$3))>0,MOD(((YEAR($A6)-YEAR(D$3))*12+MONTH($A6)-MONTH(D$3)),12)=0),2,1),0))) -> 0 | E6: =IF(OR(E$2="",$A6<E$2),0,IF(OR(E$3="",$A6<E$3),IF(MOD(((YEAR($A6)-YEAR(E$2))*12+MONTH($A6)-MONTH(E$2)),4)=0,1,0),IF(MOD(((YEAR($A6)-YEAR(E$3))*12+MONTH($A6)-MONTH(E$3)),3)=0,IF(AND(((YEAR($A6)-YEAR(E$3))*12+MONTH($A6)-MONTH(E$3))>0,MOD(((YEAR($A6)-YEAR(E$3))*12+MONTH($A6)-MONTH(E$3)),12)=0),2,1),0))) -> 0 | F6: =IF(OR(F$2="",$A6<F$2),0,IF(OR(F$3="",$A6<F$3),IF(MOD(((YEAR($A6)-YEAR(F$2))*12+MONTH($A6)-MONTH(F$2)),4)=0,1,0),IF(MOD(((YEAR($A6)-YEAR(F$3))*12+MONTH($A6)-MONTH(F$3)),3)=0,IF(AND(((YEAR($A6)-YEAR(F$3))*12+MONTH($A6)-MONTH(F$3))>0,MOD(((YEAR($A6)-YEAR(F$3))*12+MONTH($A6)-MONTH(F$3)),12)=0),2,1),0))) -> 0 | G6: =IF(OR(G$2="",$A6<G$2),0,IF(OR(G$3="",$A6<G$3),IF(MOD(((YEAR($A6)-YEAR(G$2))*12+MONTH($A6)-MONTH(G$2)),4)=0,1,0),IF(MOD(((YEAR($A6)-YEAR(G$3))*12+MONTH($A6)-MONTH(G$3)),3)=0,IF(AND(((YEAR($A6)-YEAR(G$3))*12+MONTH($A6)-MONTH(G$3))>0,MOD(((YEAR($A6)-YEAR(G$3))*12+MONTH($A6)-MONTH(G$3)),12)=0),2,1),0))) -> 0 | H6: =IF(OR(H$2="",$A6<H$2),0,IF(OR(H$3="",$A6<H$3),IF(MOD(((YEAR($A6)-YEAR(H$2))*12+MONTH($A6)-MONTH(H$2)),4)=0,1,0),IF(MOD(((YEAR($A6)-YEAR(H$3))*12+MONTH($A6)-MONTH(H$3)),3)=0,IF(AND(((YEAR($A6)-YEAR(H$3))*12+MONTH($A6)-MONTH(H$3))>0,MOD(((YEAR($A6)-YEAR(H$3))*12+MONTH($A6)-MONTH(H$3)),12)=0),2,1),0))) -> 0 | I6: =IF(OR(I$2="",$A6<I$2),0,IF(OR(I$3="",$A6<I$3),IF(MOD(((YEAR($A6)-YEAR(I$2))*12+MONTH($A6)-MONTH(I$2)),4)=0,1,0),IF(MOD(((YEAR($A6)-YEAR(I$3))*12+MONTH($A6)-MONTH(I$3)),3)=0,IF(AND(((YEAR($A6)-YEAR(I$3))*12+MONTH($A6)-MONTH(I$3))>0,MOD(((YEAR($A6)-YEAR(I$3))*12+MONTH($A6)-MONTH(I$3)),12)=0),2,1),0))) -> 0 | ... AD6: =IF(OR(AD$2="",$A6<AD$2),0,IF(OR(AD$3="",$A6<AD$3),IF(MOD(((YEAR($A6)-YEAR(AD$2))*12+MONTH($A6)-MONTH(AD$2)),4)=0,1,0),IF(MOD(((YEAR($A6)-YEAR(AD$3))*12+MONTH($A6)-MONTH(AD$3)),3)=0,IF(AND(((YEAR($A6)-YEAR(AD$3))*12+MONTH($A6)-MONTH(AD$3))>0,MOD(((YEAR($A6)-YEAR(AD$3))*12+MONTH($A6)-MONTH(AD$3)),12)=0),2,1),0))) -> 0
A7: 42826 | B7: =IF(OR(B$2="",$A7<B$2),0,IF(OR(B$3="",$A7<B$3),IF(MOD(((YEAR($A7)-YEAR(B$2))*12+MONTH($A7)-MONTH(B$2)),4)=0,1,0),IF(MOD(((YEAR($A7)-YEAR(B$3))*12+MONTH($A7)-MONTH(B$3)),3)=0,IF(AND(((YEAR($A7)-YEAR(B$3))*12+MONTH($A7)-MONTH(B$3))>0,MOD(((YEAR($A7)-YEAR(B$3))*12+MONTH($A7)-MONTH(B$3)),12)=0),2,1),0))) -> 0 | C7: =IF(OR(C$2="",$A7<C$2),0,IF(OR(C$3="",$A7<C$3),IF(MOD(((YEAR($A7)-YEAR(C$2))*12+MONTH($A7)-MONTH(C$2)),4)=0,1,0),IF(MOD(((YEAR($A7)-YEAR(C$3))*12+MONTH($A7)-MONTH(C$3)),3)=0,IF(AND(((YEAR($A7)-YEAR(C$3))*12+MONTH($A7)-MONTH(C$3))>0,MOD(((YEAR($A7)-YEAR(C$3))*12+MONTH($A7)-MONTH(C$3)),12)=0),2,1),0))) -> 0 | D7: =IF(OR(D$2="",$A7<D$2),0,IF(OR(D$3="",$A7<D$3),IF(MOD(((YEAR($A7)-YEAR(D$2))*12+MONTH($A7)-MONTH(D$2)),4)=0,1,0),IF(MOD(((YEAR($A7)-YEAR(D$3))*12+MONTH($A7)-MONTH(D$3)),3)=0,IF(AND(((YEAR($A7)-YEAR(D$3))*12+MONTH($A7)-MONTH(D$3))>0,MOD(((YEAR($A7)-YEAR(D$3))*12+MONTH($A7)-MONTH(D$3)),12)=0),2,1),0))) -> 0 | E7: =IF(OR(E$2="",$A7<E$2),0,IF(OR(E$3="",$A7<E$3),IF(MOD(((YEAR($A7)-YEAR(E$2))*12+MONTH($A7)-MONTH(E$2)),4)=0,1,0),IF(MOD(((YEAR($A7)-YEAR(E$3))*12+MONTH($A7)-MONTH(E$3)),3)=0,IF(AND(((YEAR($A7)-YEAR(E$3))*12+MONTH($A7)-MONTH(E$3))>0,MOD(((YEAR($A7)-YEAR(E$3))*12+MONTH($A7)-MONTH(E$3)),12)=0),2,1),0))) -> 0 | F7: =IF(OR(F$2="",$A7<F$2),0,IF(OR(F$3="",$A7<F$3),IF(MOD(((YEAR($A7)-YEAR(F$2))*12+MONTH($A7)-MONTH(F$2)),4)=0,1,0),IF(MOD(((YEAR($A7)-YEAR(F$3))*12+MONTH($A7)-MONTH(F$3)),3)=0,IF(AND(((YEAR($A7)-YEAR(F$3))*12+MONTH($A7)-MONTH(F$3))>0,MOD(((YEAR($A7)-YEAR(F$3))*12+MONTH($A7)-MONTH(F$3)),12)=0),2,1),0))) -> 0 | G7: =IF(OR(G$2="",$A7<G$2),0,IF(OR(G$3="",$A7<G$3),IF(MOD(((YEAR($A7)-YEAR(G$2))*12+MONTH($A7)-MONTH(G$2)),4)=0,1,0),IF(MOD(((YEAR($A7)-YEAR(G$3))*12+MONTH($A7)-MONTH(G$3)),3)=0,IF(AND(((YEAR($A7)-YEAR(G$3))*12+MONTH($A7)-MONTH(G$3))>0,MOD(((YEAR($A7)-YEAR(G$3))*12+MONTH($A7)-MONTH(G$3)),12)=0),2,1),0))) -> 0 | H7: =IF(OR(H$2="",$A7<H$2),0,IF(OR(H$3="",$A7<H$3),IF(MOD(((YEAR($A7)-YEAR(H$2))*12+MONTH($A7)-MONTH(H$2)),4)=0,1,0),IF(MOD(((YEAR($A7)-YEAR(H$3))*12+MONTH($A7)-MONTH(H$3)),3)=0,IF(AND(((YEAR($A7)-YEAR(H$3))*12+MONTH($A7)-MONTH(H$3))>0,MOD(((YEAR($A7)-YEAR(H$3))*12+MONTH($A7)-MONTH(H$3)),12)=0),2,1),0))) -> 0 | I7: =IF(OR(I$2="",$A7<I$2),0,IF(OR(I$3="",$A7<I$3),IF(MOD(((YEAR($A7)-YEAR(I$2))*12+MONTH($A7)-MONTH(I$2)),4)=0,1,0),IF(MOD(((YEAR($A7)-YEAR(I$3))*12+MONTH($A7)-MONTH(I$3)),3)=0,IF(AND(((YEAR($A7)-YEAR(I$3))*12+MONTH($A7)-MONTH(I$3))>0,MOD(((YEAR($A7)-YEAR(I$3))*12+MONTH($A7)-MONTH(I$3)),12)=0),2,1),0))) -> 0 | ... AD7: =IF(OR(AD$2="",$A7<AD$2),0,IF(OR(AD$3="",$A7<AD$3),IF(MOD(((YEAR($A7)-YEAR(AD$2))*12+MONTH($A7)-MONTH(AD$2)),4)=0,1,0),IF(MOD(((YEAR($A7)-YEAR(AD$3))*12+MONTH($A7)-MONTH(AD$3)),3)=0,IF(AND(((YEAR($A7)-YEAR(AD$3))*12+MONTH($A7)-MONTH(AD$3))>0,MOD(((YEAR($A7)-YEAR(AD$3))*12+MONTH($A7)-MONTH(AD$3)),12)=0),2,1),0))) -> 0
A8: 42856 | B8: =IF(OR(B$2="",$A8<B$2),0,IF(OR(B$3="",$A8<B$3),IF(MOD(((YEAR($A8)-YEAR(B$2))*12+MONTH($A8)-MONTH(B$2)),4)=0,1,0),IF(MOD(((YEAR($A8)-YEAR(B$3))*12+MONTH($A8)-MONTH(B$3)),3)=0,IF(AND(((YEAR($A8)-YEAR(B$3))*12+MONTH($A8)-MONTH(B$3))>0,MOD(((YEAR($A8)-YEAR(B$3))*12+MONTH($A8)-MONTH(B$3)),12)=0),2,1),0))) -> 0 | C8: =IF(OR(C$2="",$A8<C$2),0,IF(OR(C$3="",$A8<C$3),IF(MOD(((YEAR($A8)-YEAR(C$2))*12+MONTH($A8)-MONTH(C$2)),4)=0,1,0),IF(MOD(((YEAR($A8)-YEAR(C$3))*12+MONTH($A8)-MONTH(C$3)),3)=0,IF(AND(((YEAR($A8)-YEAR(C$3))*12+MONTH($A8)-MONTH(C$3))>0,MOD(((YEAR($A8)-YEAR(C$3))*12+MONTH($A8)-MONTH(C$3)),12)=0),2,1),0))) -> 0 | D8: =IF(OR(D$2="",$A8<D$2),0,IF(OR(D$3="",$A8<D$3),IF(MOD(((YEAR($A8)-YEAR(D$2))*12+MONTH($A8)-MONTH(D$2)),4)=0,1,0),IF(MOD(((YEAR($A8)-YEAR(D$3))*12+MONTH($A8)-MONTH(D$3)),3)=0,IF(AND(((YEAR($A8)-YEAR(D$3))*12+MONTH($A8)-MONTH(D$3))>0,MOD(((YEAR($A8)-YEAR(D$3))*12+MONTH($A8)-MONTH(D$3)),12)=0),2,1),0))) -> 0 | E8: =IF(OR(E$2="",$A8<E$2),0,IF(OR(E$3="",$A8<E$3),IF(MOD(((YEAR($A8)-YEAR(E$2))*12+MONTH($A8)-MONTH(E$2)),4)=0,1,0),IF(MOD(((YEAR($A8)-YEAR(E$3))*12+MONTH($A8)-MONTH(E$3)),3)=0,IF(AND(((YEAR($A8)-YEAR(E$3))*12+MONTH($A8)-MONTH(E$3))>0,MOD(((YEAR($A8)-YEAR(E$3))*12+MONTH($A8)-MONTH(E$3)),12)=0),2,1),0))) -> 0 | F8: =IF(OR(F$2="",$A8<F$2),0,IF(OR(F$3="",$A8<F$3),IF(MOD(((YEAR($A8)-YEAR(F$2))*12+MONTH($A8)-MONTH(F$2)),4)=0,1,0),IF(MOD(((YEAR($A8)-YEAR(F$3))*12+MONTH($A8)-MONTH(F$3)),3)=0,IF(AND(((YEAR($A8)-YEAR(F$3))*12+MONTH($A8)-MONTH(F$3))>0,MOD(((YEAR($A8)-YEAR(F$3))*12+MONTH($A8)-MONTH(F$3)),12)=0),2,1),0))) -> 1 | G8: =IF(OR(G$2="",$A8<G$2),0,IF(OR(G$3="",$A8<G$3),IF(MOD(((YEAR($A8)-YEAR(G$2))*12+MONTH($A8)-MONTH(G$2)),4)=0,1,0),IF(MOD(((YEAR($A8)-YEAR(G$3))*12+MONTH($A8)-MONTH(G$3)),3)=0,IF(AND(((YEAR($A8)-YEAR(G$3))*12+MONTH($A8)-MONTH(G$3))>0,MOD(((YEAR($A8)-YEAR(G$3))*12+MONTH($A8)-MONTH(G$3)),12)=0),2,1),0))) -> 0 | H8: =IF(OR(H$2="",$A8<H$2),0,IF(OR(H$3="",$A8<H$3),IF(MOD(((YEAR($A8)-YEAR(H$2))*12+MONTH($A8)-MONTH(H$2)),4)=0,1,0),IF(MOD(((YEAR($A8)-YEAR(H$3))*12+MONTH($A8)-MONTH(H$3)),3)=0,IF(AND(((YEAR($A8)-YEAR(H$3))*12+MONTH($A8)-MONTH(H$3))>0,MOD(((YEAR($A8)-YEAR(H$3))*12+MONTH($A8)-MONTH(H$3)),12)=0),2,1),0))) -> 0 | I8: =IF(OR(I$2="",$A8<I$2),0,IF(OR(I$3="",$A8<I$3),IF(MOD(((YEAR($A8)-YEAR(I$2))*12+MONTH($A8)-MONTH(I$2)),4)=0,1,0),IF(MOD(((YEAR($A8)-YEAR(I$3))*12+MONTH($A8)-MONTH(I$3)),3)=0,IF(AND(((YEAR($A8)-YEAR(I$3))*12+MONTH($A8)-MONTH(I$3))>0,MOD(((YEAR($A8)-YEAR(I$3))*12+MONTH($A8)-MONTH(I$3)),12)=0),2,1),0))) -> 0 | ... AD8: =IF(OR(AD$2="",$A8<AD$2),0,IF(OR(AD$3="",$A8<AD$3),IF(MOD(((YEAR($A8)-YEAR(AD$2))*12+MONTH($A8)-MONTH(AD$2)),4)=0,1,0),IF(MOD(((YEAR($A8)-YEAR(AD$3))*12+MONTH($A8)-MONTH(AD$3)),3)=0,IF(AND(((YEAR($A8)-YEAR(AD$3))*12+MONTH($A8)-MONTH(AD$3))>0,MOD(((YEAR($A8)-YEAR(AD$3))*12+MONTH($A8)-MONTH(AD$3)),12)=0),2,1),0))) -> 0
A9: 42887 | B9: =IF(OR(B$2="",$A9<B$2),0,IF(OR(B$3="",$A9<B$3),IF(MOD(((YEAR($A9)-YEAR(B$2))*12+MONTH($A9)-MONTH(B$2)),4)=0,1,0),IF(MOD(((YEAR($A9)-YEAR(B$3))*12+MONTH($A9)-MONTH(B$3)),3)=0,IF(AND(((YEAR($A9)-YEAR(B$3))*12+MONTH($A9)-MONTH(B$3))>0,MOD(((YEAR($A9)-YEAR(B$3))*12+MONTH($A9)-MONTH(B$3)),12)=0),2,1),0))) -> 0 | C9: =IF(OR(C$2="",$A9<C$2),0,IF(OR(C$3="",$A9<C$3),IF(MOD(((YEAR($A9)-YEAR(C$2))*12+MONTH($A9)-MONTH(C$2)),4)=0,1,0),IF(MOD(((YEAR($A9)-YEAR(C$3))*12+MONTH($A9)-MONTH(C$3)),3)=0,IF(AND(((YEAR($A9)-YEAR(C$3))*12+MONTH($A9)-MONTH(C$3))>0,MOD(((YEAR($A9)-YEAR(C$3))*12+MONTH($A9)-MONTH(C$3)),12)=0),2,1),0))) -> 0 | D9: =IF(OR(D$2="",$A9<D$2),0,IF(OR(D$3="",$A9<D$3),IF(MOD(((YEAR($A9)-YEAR(D$2))*12+MONTH($A9)-MONTH(D$2)),4)=0,1,0),IF(MOD(((YEAR($A9)-YEAR(D$3))*12+MONTH($A9)-MONTH(D$3)),3)=0,IF(AND(((YEAR($A9)-YEAR(D$3))*12+MONTH($A9)-MONTH(D$3))>0,MOD(((YEAR($A9)-YEAR(D$3))*12+MONTH($A9)-MONTH(D$3)),12)=0),2,1),0))) -> 0 | E9: =IF(OR(E$2="",$A9<E$2),0,IF(OR(E$3="",$A9<E$3),IF(MOD(((YEAR($A9)-YEAR(E$2))*12+MONTH($A9)-MONTH(E$2)),4)=0,1,0),IF(MOD(((YEAR($A9)-YEAR(E$3))*12+MONTH($A9)-MONTH(E$3)),3)=0,IF(AND(((YEAR($A9)-YEAR(E$3))*12+MONTH($A9)-MONTH(E$3))>0,MOD(((YEAR($A9)-YEAR(E$3))*12+MONTH($A9)-MONTH(E$3)),12)=0),2,1),0))) -> 0 | F9: =IF(OR(F$2="",$A9<F$2),0,IF(OR(F$3="",$A9<F$3),IF(MOD(((YEAR($A9)-YEAR(F$2))*12+MONTH($A9)-MONTH(F$2)),4)=0,1,0),IF(MOD(((YEAR($A9)-YEAR(F$3))*12+MONTH($A9)-MONTH(F$3)),3)=0,IF(AND(((YEAR($A9)-YEAR(F$3))*12+MONTH($A9)-MONTH(F$3))>0,MOD(((YEAR($A9)-YEAR(F$3))*12+MONTH($A9)-MONTH(F$3)),12)=0),2,1),0))) -> 0 | G9: =IF(OR(G$2="",$A9<G$2),0,IF(OR(G$3="",$A9<G$3),IF(MOD(((YEAR($A9)-YEAR(G$2))*12+MONTH($A9)-MONTH(G$2)),4)=0,1,0),IF(MOD(((YEAR($A9)-YEAR(G$3))*12+MONTH($A9)-MONTH(G$3)),3)=0,IF(AND(((YEAR($A9)-YEAR(G$3))*12+MONTH($A9)-MONTH(G$3))>0,MOD(((YEAR($A9)-YEAR(G$3))*12+MONTH($A9)-MONTH(G$3)),12)=0),2,1),0))) -> 0 | H9: =IF(OR(H$2="",$A9<H$2),0,IF(OR(H$3="",$A9<H$3),IF(MOD(((YEAR($A9)-YEAR(H$2))*12+MONTH($A9)-MONTH(H$2)),4)=0,1,0),IF(MOD(((YEAR($A9)-YEAR(H$3))*12+MONTH($A9)-MONTH(H$3)),3)=0,IF(AND(((YEAR($A9)-YEAR(H$3))*12+MONTH($A9)-MONTH(H$3))>0,MOD(((YEAR($A9)-YEAR(H$3))*12+MONTH($A9)-MONTH(H$3)),12)=0),2,1),0))) -> 0 | I9: =IF(OR(I$2="",$A9<I$2),0,IF(OR(I$3="",$A9<I$3),IF(MOD(((YEAR($A9)-YEAR(I$2))*12+MONTH($A9)-MONTH(I$2)),4)=0,1,0),IF(MOD(((YEAR($A9)-YEAR(I$3))*12+MONTH($A9)-MONTH(I$3)),3)=0,IF(AND(((YEAR($A9)-YEAR(I$3))*12+MONTH($A9)-MONTH(I$3))>0,MOD(((YEAR($A9)-YEAR(I$3))*12+MONTH($A9)-MONTH(I$3)),12)=0),2,1),0))) -> 1 | ... AD9: =IF(OR(AD$2="",$A9<AD$2),0,IF(OR(AD$3="",$A9<AD$3),IF(MOD(((YEAR($A9)-YEAR(AD$2))*12+MONTH($A9)-MONTH(AD$2)),4)=0,1,0),IF(MOD(((YEAR($A9)-YEAR(AD$3))*12+MONTH($A9)-MONTH(AD$3)),3)=0,IF(AND(((YEAR($A9)-YEAR(AD$3))*12+MONTH($A9)-MONTH(AD$3))>0,MOD(((YEAR($A9)-YEAR(AD$3))*12+MONTH($A9)-MONTH(AD$3)),12)=0),2,1),0))) -> 0
A10: 42917 | B10: =IF(OR(B$2="",$A10<B$2),0,IF(OR(B$3="",$A10<B$3),IF(MOD(((YEAR($A10)-YEAR(B$2))*12+MONTH($A10)-MONTH(B$2)),4)=0,1,0),IF(MOD(((YEAR($A10)-YEAR(B$3))*12+MONTH($A10)-MONTH(B$3)),3)=0,IF(AND(((YEAR($A10)-YEAR(B$3))*12+MONTH($A10)-MONTH(B$3))>0,MOD(((YEAR($A10)-YEAR(B$3))*12+MONTH($A10)-MONTH(B$3)),12)=0),2,1),0))) -> 0 | C10: =IF(OR(C$2="",$A10<C$2),0,IF(OR(C$3="",$A10<C$3),IF(MOD(((YEAR($A10)-YEAR(C$2))*12+MONTH($A10)-MONTH(C$2)),4)=0,1,0),IF(MOD(((YEAR($A10)-YEAR(C$3))*12+MONTH($A10)-MONTH(C$3)),3)=0,IF(AND(((YEAR($A10)-YEAR(C$3))*12+MONTH($A10)-MONTH(C$3))>0,MOD(((YEAR($A10)-YEAR(C$3))*12+MONTH($A10)-MONTH(C$3)),12)=0),2,1),0))) -> 1 | D10: =IF(OR(D$2="",$A10<D$2),0,IF(OR(D$3="",$A10<D$3),IF(MOD(((YEAR($A10)-YEAR(D$2))*12+MONTH($A10)-MONTH(D$2)),4)=0,1,0),IF(MOD(((YEAR($A10)-YEAR(D$3))*12+MONTH($A10)-MONTH(D$3)),3)=0,IF(AND(((YEAR($A10)-YEAR(D$3))*12+MONTH($A10)-MONTH(D$3))>0,MOD(((YEAR($A10)-YEAR(D$3))*12+MONTH($A10)-MONTH(D$3)),12)=0),2,1),0))) -> 0 | E10: =IF(OR(E$2="",$A10<E$2),0,IF(OR(E$3="",$A10<E$3),IF(MOD(((YEAR($A10)-YEAR(E$2))*12+MONTH($A10)-MONTH(E$2)),4)=0,1,0),IF(MOD(((YEAR($A10)-YEAR(E$3))*12+MONTH($A10)-MONTH(E$3)),3)=0,IF(AND(((YEAR($A10)-YEAR(E$3))*12+MONTH($A10)-MONTH(E$3))>0,MOD(((YEAR($A10)-YEAR(E$3))*12+MONTH($A10)-MONTH(E$3)),12)=0),2,1),0))) -> 0 | F10: =IF(OR(F$2="",$A10<F$2),0,IF(OR(F$3="",$A10<F$3),IF(MOD(((YEAR($A10)-YEAR(F$2))*12+MONTH($A10)-MONTH(F$2)),4)=0,1,0),IF(MOD(((YEAR($A10)-YEAR(F$3))*12+MONTH($A10)-MONTH(F$3)),3)=0,IF(AND(((YEAR($A10)-YEAR(F$3))*12+MONTH($A10)-MONTH(F$3))>0,MOD(((YEAR($A10)-YEAR(F$3))*12+MONTH($A10)-MONTH(F$3)),12)=0),2,1),0))) -> 0 | G10: =IF(OR(G$2="",$A10<G$2),0,IF(OR(G$3="",$A10<G$3),IF(MOD(((YEAR($A10)-YEAR(G$2))*12+MONTH($A10)-MONTH(G$2)),4)=0,1,0),IF(MOD(((YEAR($A10)-YEAR(G$3))*12+MONTH($A10)-MONTH(G$3)),3)=0,IF(AND(((YEAR($A10)-YEAR(G$3))*12+MONTH($A10)-MONTH(G$3))>0,MOD(((YEAR($A10)-YEAR(G$3))*12+MONTH($A10)-MONTH(G$3)),12)=0),2,1),0))) -> 1 | H10: =IF(OR(H$2="",$A10<H$2),0,IF(OR(H$3="",$A10<H$3),IF(MOD(((YEAR($A10)-YEAR(H$2))*12+MONTH($A10)-MONTH(H$2)),4)=0,1,0),IF(MOD(((YEAR($A10)-YEAR(H$3))*12+MONTH($A10)-MONTH(H$3)),3)=0,IF(AND(((YEAR($A10)-YEAR(H$3))*12+MONTH($A10)-MONTH(H$3))>0,MOD(((YEAR($A10)-YEAR(H$3))*12+MONTH($A10)-MONTH(H$3)),12)=0),2,1),0))) -> 1 | I10: =IF(OR(I$2="",$A10<I$2),0,IF(OR(I$3="",$A10<I$3),IF(MOD(((YEAR($A10)-YEAR(I$2))*12+MONTH($A10)-MONTH(I$2)),4)=0,1,0),IF(MOD(((YEAR($A10)-YEAR(I$3))*12+MONTH($A10)-MONTH(I$3)),3)=0,IF(AND(((YEAR($A10)-YEAR(I$3))*12+MONTH($A10)-MONTH(I$3))>0,MOD(((YEAR($A10)-YEAR(I$3))*12+MONTH($A10)-MONTH(I$3)),12)=0),2,1),0))) -> 0 | ... AD10: =IF(OR(AD$2="",$A10<AD$2),0,IF(OR(AD$3="",$A10<AD$3),IF(MOD(((YEAR($A10)-YEAR(AD$2))*12+MONTH($A10)-MONTH(AD$2)),4)=0,1,0),IF(MOD(((YEAR($A10)-YEAR(AD$3))*12+MONTH($A10)-MONTH(AD$3)),3)=0,IF(AND(((YEAR($A10)-YEAR(AD$3))*12+MONTH($A10)-MONTH(AD$3))>0,MOD(((YEAR($A10)-YEAR(AD$3))*12+MONTH($A10)-MONTH(AD$3)),12)=0),2,1),0))) -> 0
A11: 42948 | B11: =IF(OR(B$2="",$A11<B$2),0,IF(OR(B$3="",$A11<B$3),IF(MOD(((YEAR($A11)-YEAR(B$2))*12+MONTH($A11)-MONTH(B$2)),4)=0,1,0),IF(MOD(((YEAR($A11)-YEAR(B$3))*12+MONTH($A11)-MONTH(B$3)),3)=0,IF(AND(((YEAR($A11)-YEAR(B$3))*12+MONTH($A11)-MONTH(B$3))>0,MOD(((YEAR($A11)-YEAR(B$3))*12+MONTH($A11)-MONTH(B$3)),12)=0),2,1),0))) -> 0 | C11: =IF(OR(C$2="",$A11<C$2),0,IF(OR(C$3="",$A11<C$3),IF(MOD(((YEAR($A11)-YEAR(C$2))*12+MONTH($A11)-MONTH(C$2)),4)=0,1,0),IF(MOD(((YEAR($A11)-YEAR(C$3))*12+MONTH($A11)-MONTH(C$3)),3)=0,IF(AND(((YEAR($A11)-YEAR(C$3))*12+MONTH($A11)-MONTH(C$3))>0,MOD(((YEAR($A11)-YEAR(C$3))*12+MONTH($A11)-MONTH(C$3)),12)=0),2,1),0))) -> 0 | D11: =IF(OR(D$2="",$A11<D$2),0,IF(OR(D$3="",$A11<D$3),IF(MOD(((YEAR($A11)-YEAR(D$2))*12+MONTH($A11)-MONTH(D$2)),4)=0,1,0),IF(MOD(((YEAR($A11)-YEAR(D$3))*12+MONTH($A11)-MONTH(D$3)),3)=0,IF(AND(((YEAR($A11)-YEAR(D$3))*12+MONTH($A11)-MONTH(D$3))>0,MOD(((YEAR($A11)-YEAR(D$3))*12+MONTH($A11)-MONTH(D$3)),12)=0),2,1),0))) -> 0 | E11: =IF(OR(E$2="",$A11<E$2),0,IF(OR(E$3="",$A11<E$3),IF(MOD(((YEAR($A11)-YEAR(E$2))*12+MONTH($A11)-MONTH(E$2)),4)=0,1,0),IF(MOD(((YEAR($A11)-YEAR(E$3))*12+MONTH($A11)-MONTH(E$3)),3)=0,IF(AND(((YEAR($A11)-YEAR(E$3))*12+MONTH($A11)-MONTH(E$3))>0,MOD(((YEAR($A11)-YEAR(E$3))*12+MONTH($A11)-MONTH(E$3)),12)=0),2,1),0))) -> 0 | F11: =IF(OR(F$2="",$A11<F$2),0,IF(OR(F$3="",$A11<F$3),IF(MOD(((YEAR($A11)-YEAR(F$2))*12+MONTH($A11)-MONTH(F$2)),4)=0,1,0),IF(MOD(((YEAR($A11)-YEAR(F$3))*12+MONTH($A11)-MONTH(F$3)),3)=0,IF(AND(((YEAR($A11)-YEAR(F$3))*12+MONTH($A11)-MONTH(F$3))>0,MOD(((YEAR($A11)-YEAR(F$3))*12+MONTH($A11)-MONTH(F$3)),12)=0),2,1),0))) -> 1 | G11: =IF(OR(G$2="",$A11<G$2),0,IF(OR(G$3="",$A11<G$3),IF(MOD(((YEAR($A11)-YEAR(G$2))*12+MONTH($A11)-MONTH(G$2)),4)=0,1,0),IF(MOD(((YEAR($A11)-YEAR(G$3))*12+MONTH($A11)-MONTH(G$3)),3)=0,IF(AND(((YEAR($A11)-YEAR(G$3))*12+MONTH($A11)-MONTH(G$3))>0,MOD(((YEAR($A11)-YEAR(G$3))*12+MONTH($A11)-MONTH(G$3)),12)=0),2,1),0))) -> 0 | H11: =IF(OR(H$2="",$A11<H$2),0,IF(OR(H$3="",$A11<H$3),IF(MOD(((YEAR($A11)-YEAR(H$2))*12+MONTH($A11)-MONTH(H$2)),4)=0,1,0),IF(MOD(((YEAR($A11)-YEAR(H$3))*12+MONTH($A11)-MONTH(H$3)),3)=0,IF(AND(((YEAR($A11)-YEAR(H$3))*12+MONTH($A11)-MONTH(H$3))>0,MOD(((YEAR($A11)-YEAR(H$3))*12+MONTH($A11)-MONTH(H$3)),12)=0),2,1),0))) -> 0 | I11: =IF(OR(I$2="",$A11<I$2),0,IF(OR(I$3="",$A11<I$3),IF(MOD(((YEAR($A11)-YEAR(I$2))*12+MONTH($A11)-MONTH(I$2)),4)=0,1,0),IF(MOD(((YEAR($A11)-YEAR(I$3))*12+MONTH($A11)-MONTH(I$3)),3)=0,IF(AND(((YEAR($A11)-YEAR(I$3))*12+MONTH($A11)-MONTH(I$3))>0,MOD(((YEAR($A11)-YEAR(I$3))*12+MONTH($A11)-MONTH(I$3)),12)=0),2,1),0))) -> 0 | ... AD11: =IF(OR(AD$2="",$A11<AD$2),0,IF(OR(AD$3="",$A11<AD$3),IF(MOD(((YEAR($A11)-YEAR(AD$2))*12+MONTH($A11)-MONTH(AD$2)),4)=0,1,0),IF(MOD(((YEAR($A11)-YEAR(AD$3))*12+MONTH($A11)-MONTH(AD$3)),3)=0,IF(AND(((YEAR($A11)-YEAR(AD$3))*12+MONTH($A11)-MONTH(AD$3))>0,MOD(((YEAR($A11)-YEAR(AD$3))*12+MONTH($A11)-MONTH(AD$3)),12)=0),2,1),0))) -> 0
A12: 42979 | B12: =IF(OR(B$2="",$A12<B$2),0,IF(OR(B$3="",$A12<B$3),IF(MOD(((YEAR($A12)-YEAR(B$2))*12+MONTH($A12)-MONTH(B$2)),4)=0,1,0),IF(MOD(((YEAR($A12)-YEAR(B$3))*12+MONTH($A12)-MONTH(B$3)),3)=0,IF(AND(((YEAR($A12)-YEAR(B$3))*12+MONTH($A12)-MONTH(B$3))>0,MOD(((YEAR($A12)-YEAR(B$3))*12+MONTH($A12)-MONTH(B$3)),12)=0),2,1),0))) -> 0 | C12: =IF(OR(C$2="",$A12<C$2),0,IF(OR(C$3="",$A12<C$3),IF(MOD(((YEAR($A12)-YEAR(C$2))*12+MONTH($A12)-MONTH(C$2)),4)=0,1,0),IF(MOD(((YEAR($A12)-YEAR(C$3))*12+MONTH($A12)-MONTH(C$3)),3)=0,IF(AND(((YEAR($A12)-YEAR(C$3))*12+MONTH($A12)-MONTH(C$3))>0,MOD(((YEAR($A12)-YEAR(C$3))*12+MONTH($A12)-MONTH(C$3)),12)=0),2,1),0))) -> 0 | D12: =IF(OR(D$2="",$A12<D$2),0,IF(OR(D$3="",$A12<D$3),IF(MOD(((YEAR($A12)-YEAR(D$2))*12+MONTH($A12)-MONTH(D$2)),4)=0,1,0),IF(MOD(((YEAR($A12)-YEAR(D$3))*12+MONTH($A12)-MONTH(D$3)),3)=0,IF(AND(((YEAR($A12)-YEAR(D$3))*12+MONTH($A12)-MONTH(D$3))>0,MOD(((YEAR($A12)-YEAR(D$3))*12+MONTH($A12)-MONTH(D$3)),12)=0),2,1),0))) -> 0 | E12: =IF(OR(E$2="",$A12<E$2),0,IF(OR(E$3="",$A12<E$3),IF(MOD(((YEAR($A12)-YEAR(E$2))*12+MONTH($A12)-MONTH(E$2)),4)=0,1,0),IF(MOD(((YEAR($A12)-YEAR(E$3))*12+MONTH($A12)-MONTH(E$3)),3)=0,IF(AND(((YEAR($A12)-YEAR(E$3))*12+MONTH($A12)-MONTH(E$3))>0,MOD(((YEAR($A12)-YEAR(E$3))*12+MONTH($A12)-MONTH(E$3)),12)=0),2,1),0))) -> 0 | F12: =IF(OR(F$2="",$A12<F$2),0,IF(OR(F$3="",$A12<F$3),IF(MOD(((YEAR($A12)-YEAR(F$2))*12+MONTH($A12)-MONTH(F$2)),4)=0,1,0),IF(MOD(((YEAR($A12)-YEAR(F$3))*12+MONTH($A12)-MONTH(F$3)),3)=0,IF(AND(((YEAR($A12)-YEAR(F$3))*12+MONTH($A12)-MONTH(F$3))>0,MOD(((YEAR($A12)-YEAR(F$3))*12+MONTH($A12)-MONTH(F$3)),12)=0),2,1),0))) -> 0 | G12: =IF(OR(G$2="",$A12<G$2),0,IF(OR(G$3="",$A12<G$3),IF(MOD(((YEAR($A12)-YEAR(G$2))*12+MONTH($A12)-MONTH(G$2)),4)=0,1,0),IF(MOD(((YEAR($A12)-YEAR(G$3))*12+MONTH($A12)-MONTH(G$3)),3)=0,IF(AND(((YEAR($A12)-YEAR(G$3))*12+MONTH($A12)-MONTH(G$3))>0,MOD(((YEAR($A12)-YEAR(G$3))*12+MONTH($A12)-MONTH(G$3)),12)=0),2,1),0))) -> 0 | H12: =IF(OR(H$2="",$A12<H$2),0,IF(OR(H$3="",$A12<H$3),IF(MOD(((YEAR($A12)-YEAR(H$2))*12+MONTH($A12)-MONTH(H$2)),4)=0,1,0),IF(MOD(((YEAR($A12)-YEAR(H$3))*12+MONTH($A12)-MONTH(H$3)),3)=0,IF(AND(((YEAR($A12)-YEAR(H$3))*12+MONTH($A12)-MONTH(H$3))>0,MOD(((YEAR($A12)-YEAR(H$3))*12+MONTH($A12)-MONTH(H$3)),12)=0),2,1),0))) -> 0 | I12: =IF(OR(I$2="",$A12<I$2),0,IF(OR(I$3="",$A12<I$3),IF(MOD(((YEAR($A12)-YEAR(I$2))*12+MONTH($A12)-MONTH(I$2)),4)=0,1,0),IF(MOD(((YEAR($A12)-YEAR(I$3))*12+MONTH($A12)-MONTH(I$3)),3)=0,IF(AND(((YEAR($A12)-YEAR(I$3))*12+MONTH($A12)-MONTH(I$3))>0,MOD(((YEAR($A12)-YEAR(I$3))*12+MONTH($A12)-MONTH(I$3)),12)=0),2,1),0))) -> 0 | ... AD12: =IF(OR(AD$2="",$A12<AD$2),0,IF(OR(AD$3="",$A12<AD$3),IF(MOD(((YEAR($A12)-YEAR(AD$2))*12+MONTH($A12)-MONTH(AD$2)),4)=0,1,0),IF(MOD(((YEAR($A12)-YEAR(AD$3))*12+MONTH($A12)-MONTH(AD$3)),3)=0,IF(AND(((YEAR($A12)-YEAR(AD$3))*12+MONTH($A12)-MONTH(AD$3))>0,MOD(((YEAR($A12)-YEAR(AD$3))*12+MONTH($A12)-MONTH(AD$3)),12)=0),2,1),0))) -> 0
A13: 43009 | B13: =IF(OR(B$2="",$A13<B$2),0,IF(OR(B$3="",$A13<B$3),IF(MOD(((YEAR($A13)-YEAR(B$2))*12+MONTH($A13)-MONTH(B$2)),4)=0,1,0),IF(MOD(((YEAR($A13)-YEAR(B$3))*12+MONTH($A13)-MONTH(B$3)),3)=0,IF(AND(((YEAR($A13)-YEAR(B$3))*12+MONTH($A13)-MONTH(B$3))>0,MOD(((YEAR($A13)-YEAR(B$3))*12+MONTH($A13)-MONTH(B$3)),12)=0),2,1),0))) -> 0 | C13: =IF(OR(C$2="",$A13<C$2),0,IF(OR(C$3="",$A13<C$3),IF(MOD(((YEAR($A13)-YEAR(C$2))*12+MONTH($A13)-MONTH(C$2)),4)=0,1,0),IF(MOD(((YEAR($A13)-YEAR(C$3))*12+MONTH($A13)-MONTH(C$3)),3)=0,IF(AND(((YEAR($A13)-YEAR(C$3))*12+MONTH($A13)-MONTH(C$3))>0,MOD(((YEAR($A13)-YEAR(C$3))*12+MONTH($A13)-MONTH(C$3)),12)=0),2,1),0))) -> 0 | D13: =IF(OR(D$2="",$A13<D$2),0,IF(OR(D$3="",$A13<D$3),IF(MOD(((YEAR($A13)-YEAR(D$2))*12+MONTH($A13)-MONTH(D$2)),4)=0,1,0),IF(MOD(((YEAR($A13)-YEAR(D$3))*12+MONTH($A13)-MONTH(D$3)),3)=0,IF(AND(((YEAR($A13)-YEAR(D$3))*12+MONTH($A13)-MONTH(D$3))>0,MOD(((YEAR($A13)-YEAR(D$3))*12+MONTH($A13)-MONTH(D$3)),12)=0),2,1),0))) -> 0 | E13: =IF(OR(E$2="",$A13<E$2),0,IF(OR(E$3="",$A13<E$3),IF(MOD(((YEAR($A13)-YEAR(E$2))*12+MONTH($A13)-MONTH(E$2)),4)=0,1,0),IF(MOD(((YEAR($A13)-YEAR(E$3))*12+MONTH($A13)-MONTH(E$3)),3)=0,IF(AND(((YEAR($A13)-YEAR(E$3))*12+MONTH($A13)-MONTH(E$3))>0,MOD(((YEAR($A13)-YEAR(E$3))*12+MONTH($A13)-MONTH(E$3)),12)=0),2,1),0))) -> 0 | F13: =IF(OR(F$2="",$A13<F$2),0,IF(OR(F$3="",$A13<F$3),IF(MOD(((YEAR($A13)-YEAR(F$2))*12+MONTH($A13)-MONTH(F$2)),4)=0,1,0),IF(MOD(((YEAR($A13)-YEAR(F$3))*12+MONTH($A13)-MONTH(F$3)),3)=0,IF(AND(((YEAR($A13)-YEAR(F$3))*12+MONTH($A13)-MONTH(F$3))>0,MOD(((YEAR($A13)-YEAR(F$3))*12+MONTH($A13)-MONTH(F$3)),12)=0),2,1),0))) -> 0 | G13: =IF(OR(G$2="",$A13<G$2),0,IF(OR(G$3="",$A13<G$3),IF(MOD(((YEAR($A13)-YEAR(G$2))*12+MONTH($A13)-MONTH(G$2)),4)=0,1,0),IF(MOD(((YEAR($A13)-YEAR(G$3))*12+MONTH($A13)-MONTH(G$3)),3)=0,IF(AND(((YEAR($A13)-YEAR(G$3))*12+MONTH($A13)-MONTH(G$3))>0,MOD(((YEAR($A13)-YEAR(G$3))*12+MONTH($A13)-MONTH(G$3)),12)=0),2,1),0))) -> 1 | H13: =IF(OR(H$2="",$A13<H$2),0,IF(OR(H$3="",$A13<H$3),IF(MOD(((YEAR($A13)-YEAR(H$2))*12+MONTH($A13)-MONTH(H$2)),4)=0,1,0),IF(MOD(((YEAR($A13)-YEAR(H$3))*12+MONTH($A13)-MONTH(H$3)),3)=0,IF(AND(((YEAR($A13)-YEAR(H$3))*12+MONTH($A13)-MONTH(H$3))>0,MOD(((YEAR($A13)-YEAR(H$3))*12+MONTH($A13)-MONTH(H$3)),12)=0),2,1),0))) -> 1 | I13: =IF(OR(I$2="",$A13<I$2),0,IF(OR(I$3="",$A13<I$3),IF(MOD(((YEAR($A13)-YEAR(I$2))*12+MONTH($A13)-MONTH(I$2)),4)=0,1,0),IF(MOD(((YEAR($A13)-YEAR(I$3))*12+MONTH($A13)-MONTH(I$3)),3)=0,IF(AND(((YEAR($A13)-YEAR(I$3))*12+MONTH($A13)-MONTH(I$3))>0,MOD(((YEAR($A13)-YEAR(I$3))*12+MONTH($A13)-MONTH(I$3)),12)=0),2,1),0))) -> 1 | ... AD13: =IF(OR(AD$2="",$A13<AD$2),0,IF(OR(AD$3="",$A13<AD$3),IF(MOD(((YEAR($A13)-YEAR(AD$2))*12+MONTH($A13)-MONTH(AD$2)),4)=0,1,0),IF(MOD(((YEAR($A13)-YEAR(AD$3))*12+MONTH($A13)-MONTH(AD$3)),3)=0,IF(AND(((YEAR($A13)-YEAR(AD$3))*12+MONTH($A13)-MONTH(AD$3))>0,MOD(((YEAR($A13)-YEAR(AD$3))*12+MONTH($A13)-MONTH(AD$3)),12)=0),2,1),0))) -> 0
A14: 43040 | B14: =IF(OR(B$2="",$A14<B$2),0,IF(OR(B$3="",$A14<B$3),IF(MOD(((YEAR($A14)-YEAR(B$2))*12+MONTH($A14)-MONTH(B$2)),4)=0,1,0),IF(MOD(((YEAR($A14)-YEAR(B$3))*12+MONTH($A14)-MONTH(B$3)),3)=0,IF(AND(((YEAR($A14)-YEAR(B$3))*12+MONTH($A14)-MONTH(B$3))>0,MOD(((YEAR($A14)-YEAR(B$3))*12+MONTH($A14)-MONTH(B$3)),12)=0),2,1),0))) -> 0 | C14: =IF(OR(C$2="",$A14<C$2),0,IF(OR(C$3="",$A14<C$3),IF(MOD(((YEAR($A14)-YEAR(C$2))*12+MONTH($A14)-MONTH(C$2)),4)=0,1,0),IF(MOD(((YEAR($A14)-YEAR(C$3))*12+MONTH($A14)-MONTH(C$3)),3)=0,IF(AND(((YEAR($A14)-YEAR(C$3))*12+MONTH($A14)-MONTH(C$3))>0,MOD(((YEAR($A14)-YEAR(C$3))*12+MONTH($A14)-MONTH(C$3)),12)=0),2,1),0))) -> 1 | D14: =IF(OR(D$2="",$A14<D$2),0,IF(OR(D$3="",$A14<D$3),IF(MOD(((YEAR($A14)-YEAR(D$2))*12+MONTH($A14)-MONTH(D$2)),4)=0,1,0),IF(MOD(((YEAR($A14)-YEAR(D$3))*12+MONTH($A14)-MONTH(D$3)),3)=0,IF(AND(((YEAR($A14)-YEAR(D$3))*12+MONTH($A14)-MONTH(D$3))>0,MOD(((YEAR($A14)-YEAR(D$3))*12+MONTH($A14)-MONTH(D$3)),12)=0),2,1),0))) -> 0 | E14: =IF(OR(E$2="",$A14<E$2),0,IF(OR(E$3="",$A14<E$3),IF(MOD(((YEAR($A14)-YEAR(E$2))*12+MONTH($A14)-MONTH(E$2)),4)=0,1,0),IF(MOD(((YEAR($A14)-YEAR(E$3))*12+MONTH($A14)-MONTH(E$3)),3)=0,IF(AND(((YEAR($A14)-YEAR(E$3))*12+MONTH($A14)-MONTH(E$3))>0,MOD(((YEAR($A14)-YEAR(E$3))*12+MONTH($A14)-MONTH(E$3)),12)=0),2,1),0))) -> 0 | F14: =IF(OR(F$2="",$A14<F$2),0,IF(OR(F$3="",$A14<F$3),IF(MOD(((YEAR($A14)-YEAR(F$2))*12+MONTH($A14)-MONTH(F$2)),4)=0,1,0),IF(MOD(((YEAR($A14)-YEAR(F$3))*12+MONTH($A14)-MONTH(F$3)),3)=0,IF(AND(((YEAR($A14)-YEAR(F$3))*12+MONTH($A14)-MONTH(F$3))>0,MOD(((YEAR($A14)-YEAR(F$3))*12+MONTH($A14)-MONTH(F$3)),12)=0),2,1),0))) -> 1 | G14: =IF(OR(G$2="",$A14<G$2),0,IF(OR(G$3="",$A14<G$3),IF(MOD(((YEAR($A14)-YEAR(G$2))*12+MONTH($A14)-MONTH(G$2)),4)=0,1,0),IF(MOD(((YEAR($A14)-YEAR(G$3))*12+MONTH($A14)-MONTH(G$3)),3)=0,IF(AND(((YEAR($A14)-YEAR(G$3))*12+MONTH($A14)-MONTH(G$3))>0,MOD(((YEAR($A14)-YEAR(G$3))*12+MONTH($A14)-MONTH(G$3)),12)=0),2,1),0))) -> 0 | H14: =IF(OR(H$2="",$A14<H$2),0,IF(OR(H$3="",$A14<H$3),IF(MOD(((YEAR($A14)-YEAR(H$2))*12+MONTH($A14)-MONTH(H$2)),4)=0,1,0),IF(MOD(((YEAR($A14)-YEAR(H$3))*12+MONTH($A14)-MONTH(H$3)),3)=0,IF(AND(((YEAR($A14)-YEAR(H$3))*12+MONTH($A14)-MONTH(H$3))>0,MOD(((YEAR($A14)-YEAR(H$3))*12+MONTH($A14)-MONTH(H$3)),12)=0),2,1),0))) -> 0 | I14: =IF(OR(I$2="",$A14<I$2),0,IF(OR(I$3="",$A14<I$3),IF(MOD(((YEAR($A14)-YEAR(I$2))*12+MONTH($A14)-MONTH(I$2)),4)=0,1,0),IF(MOD(((YEAR($A14)-YEAR(I$3))*12+MONTH($A14)-MONTH(I$3)),3)=0,IF(AND(((YEAR($A14)-YEAR(I$3))*12+MONTH($A14)-MONTH(I$3))>0,MOD(((YEAR($A14)-YEAR(I$3))*12+MONTH($A14)-MONTH(I$3)),12)=0),2,1),0))) -> 0 | ... AD14: =IF(OR(AD$2="",$A14<AD$2),0,IF(OR(AD$3="",$A14<AD$3),IF(MOD(((YEAR($A14)-YEAR(AD$2))*12+MONTH($A14)-MONTH(AD$2)),4)=0,1,0),IF(MOD(((YEAR($A14)-YEAR(AD$3))*12+MONTH($A14)-MONTH(AD$3)),3)=0,IF(AND(((YEAR($A14)-YEAR(AD$3))*12+MONTH($A14)-MONTH(AD$3))>0,MOD(((YEAR($A14)-YEAR(AD$3))*12+MONTH($A14)-MONTH(AD$3)),12)=0),2,1),0))) -> 0
