Workbook

Sheet Staff
A1: CTS BONUS LEAVE TRACKER | C1: ACCRUAL MONTH (type the month-end date): | D1: 46295 | E1: Everything in the workbook is calculated as at this date: EARNED THIS MONTH = days whose milestone falls in that month. HOURS TO ACCRUE = everything still missing in EH (this month + any earlier months not yet posted). To see who you accrued for in a month, set the month here and filter Earned this month > 0.
A2: ="ACCRUING FOR "&UPPER(TEXT(AsOfDate,"mmmm yyyy"))&" | As at "&TEXT(AsOfDate,"dd/mm/yyyy")&" (change in D1)"&" | Report from "&TEXT(PFYDate+1,"dd/mm/yyyy")&" | Staff: "&COUNTIF($AK$5:$AK$154,1)&" | Accruing: "&COUNTIF($R$5:$R$154,"Yes*")&" | To accrue now: "&ROUND(SUMIF($Y$5:$Y$154,">0"),2)&""&" hrs for "&COUNTIF($Z$5:$Z$154,"Yes")&" people | Earned this month: "&ROUND(SUM($AE$5:$AE$154),2)&" days | Over-accrued in EH: "&COUNTIF($AH$5:$AH$154,">0")&" people, "&ROUND(SUMIF($AH$5:$AH$154,">0"),2)&" hrs" -> ACCRUING FOR SEPTEMBER 2026 | As at 30/09/2026 (change in D1) | Report from 01/07/2019 | Staff: 0 | Accruing: 0 | To accrue now: 0 hrs for 0 people | Earned this month: 0 days | Over-accrued in EH: 0 people, 0 hrs
A3: type here | B3: type here | C3: current: Full-Time / Part-Time / Casual | D3: type here | E3: next birthday | F3: type here | G3: date casual began | H3: date part-time began | I3: date full-time began | J3: optional: HR-adjusted service start (unpaid leave) | K3: next anniversary of commencement (FT/PT start) | L3: years since commencement (FT/PT start) | M3: qualifying service counted | N3: HOURS due per policy to date | O3: days due per policy to date | P3: part-timers only; blank = 24+ | Q3: from the three start dates | S3: date of next day | T3: EH go-live load (only if commenced before the report start) | U3: accrued in EH since commencement | V3: taken since commencement | W3: EH balance now | X3: policy accrual from report start to as-of | Y3: scheme hours to date - credited in EH (opening + accrued) | Z3: Yes = hours owed | AB3: 0 when the report covers full history | AC3: Bonus Leave rows found | AE3: days whose milestone falls in the accrual month | AF3: date of that milestone | AG3: milestones before 27/11/2017 - earn nothing | AH3: hours EH has credited above the scheme entitlement (0 = none) | AI3: Yes = keep what EH holds; accrue forward only | AJ3: free text - reconciliation notes, HR decisions
A4: Name | B4: Surname | C4: EmploymentType | D4: DateOfBirth | E4: Birthday | F4: StartDate | G4: Casual Start | H4: PTE Start | I4: FTE Start | J4: AnniversaryDate | K4: Anniversary | L4: Tenure | M4: Tenure (Y/M/D) | N4: Bonus leave Accrued | O4: Days | P4: PT Hrs/Week | Q4: Status Change | R4: Eligible? | S4: Next Accrual | T4: Opening Balance (hrs) | U4: Leave Accrued (hrs) | V4: Leave Taken (hrs) | W4: Closing Balance (hrs) | X4: Due per policy (hrs) | Y4: Hours to Accrue | Z4: Add to EH now? | AA4: Action | AB4: Opening gap vs policy (hrs) | AC4: Rows in EH report | AD4: Data Check | AE4: Earned this month (days) | AF4: Milestone this month | AG4: Days excluded (before scheme start) | AH4: Over-accrued in EH (hrs) | AI4: Accept EH balance to date? | AJ4: Notes | AK4: h active | AL4: h S | AM4: h n dates | AN4: h D1 | AO4: h D2 | AP4: h D3 | AQ4: h T1 | AR4: h T2 | AS4: h T3 | AT4: h P1 | AU4: h P2 | AV4: h P3 | AW4: h Pc | AX4: h M0 | AY4: h B1 | AZ4: h B2 | BA4: h MP | BB4: h B1P | BC4: h B2P | BD4: h daysNow | BE4: h daysPFY | BF4: h nextoff | BG4: h rows | BH4: h lastrow | BI4: h MM | BJ4: h B1M | BK4: h B2M | BL4: h daysLastMonth | BM4: h lastoff | BN4: h MS | BO4: h B1S | BP4: h B2S | BQ4: h daysPreScheme | BR4: h key
E5: =IF(OR(AK5=0,$D5=""),"",DATE(YEAR(AsOfDate)+IF(DATE(YEAR(AsOfDate),MONTH($D5),DAY($D5))<=AsOfDate,1,0),MONTH($D5),DAY($D5))) | K5: =IF(AK5=0,"",DATE(YEAR(AsOfDate)+IF(DATE(YEAR(AsOfDate),MONTH(AL5),DAY(AL5))<=AsOfDate,1,0),MONTH(AL5),DAY(AL5))) | L5: =IF(AK5=0,"",ROUND((AsOfDate-AL5)/365.25,1)) | M5: =IF(AK5=0,"",IF(AsOfDate<AL5,"-",DATEDIF(AL5,AsOfDate,"y")&"y "&DATEDIF(AL5,AsOfDate,"ym")&"m "&DATEDIF(AL5,AsOfDate,"md")&"d")) | N5: =IF(AK5=0,"",O5*HoursPerDay) | O5: =IF(AK5=0,"",MAX(0,BD5-BQ5)) | Q5: =IF(AK5=0,"",IF(AM5<2,"",AQ5&" to "&AR5&" on "&TEXT(AO5,"dd/mm/yyyy")&IF(AO5>AsOfDate," (future)",IF(AT5=AU5,"",IF(AU5="None"," - STOPPED accruing",IF(AT5="None"," - commencement for Bonus Leave"," - pathway changed"))))&IF(AM5<3,"","; "&AR5&" to "&AS5&" on "&TEXT(AP5,"dd/mm/yyyy")&IF(AP5>AsOfDate," (future)",IF(AU5=AV5,"",IF(AV5="None"," - STOPPED accruing",IF(AU5="None"," - commencement for Bonus Leave"," - pathway changed"))))))) | R5: =IF(AK5=0,"",IF(AW5="None",IF(O5>0,"No longer accruing","Not eligible - "&IF(AND(OR(ISNUMBER(SEARCH("part",$C5)),UPPER(TRIM($C5))="PT",UPPER(TRIM($C5))="PTE"),Apply2026="No"),"part-time (scheme is full-time only)",IF(AND(OR(ISNUMBER(SEARCH("part",$C5)),UPPER(TRIM($C5))="PT",UPPER(TRIM($C5))="PTE"),$P5<>"",N($P5)<PT_MinHours),"under "&PT_MinHours&" hrs",IF(IF($C5="","",IF(OR(ISNUMBER(SEARCH("full",$C5)),UPPER(TRIM($C5))="FT",UPPER(TRIM($C5))="FTE"),"Full-Time",IF(OR(ISNUMBER(SEARCH("part",$C5)),UPPER(TRIM($C5))="PT",UPPER(TRIM($C5))="PTE"),"Part-Time",IF(OR(ISNUMBER(SEARCH("cas",$C5)),UPPER(TRIM($C5))="CAS"),"Casual","Unknown"))))="Unknown","type not recognised",$C5)))),IF(O5>0,"Yes - Accrual Required","Not yet - from "&TEXT(S5,"dd/mm/yyyy")))) | S5: =IF(AK5=0,"",IF(AW5="None","",EDATE(AL5,BF5))) | T5: =IF(AK5=0,"",IF(NOT(LH_Ready),"",IF($F5>PFYDate,0,IF(LH_ColPeriod=0,W5-U5+V5,SUMIFS(INDEX(LH_Data,0,LH_ColAcc),INDEX(LH_Data,0,LH_ColFirst),$A5,INDEX(LH_Data,0,LH_ColSur),$B5,INDEX(LH_Data,0,LH_ColCat),BonusCat,INDEX(LH_Data,0,LH_ColPeriod),LH_OpenLabel)*UnitFactor)))) | U5: =IF(AK5=0,"",IF(NOT(LH_Ready),"",SUMIFS(INDEX(LH_Data,0,LH_ColAcc),INDEX(LH_Data,0,LH_ColFirst),$A5,INDEX(LH_Data,0,LH_ColSur),$B5,INDEX(LH_Data,0,LH_ColCat),BonusCat,INDEX(LH_Data,0,LH_ColStart),">="&AL5)*UnitFactor)) | V5: =IF(AK5=0,"",IF(NOT(LH_Ready),"",SUMIFS(INDEX(LH_Data,0,LH_ColTaken),INDEX(LH_Data,0,LH_ColFirst),$A5,INDEX(LH_Data,0,LH_ColSur),$B5,INDEX(LH_Data,0,LH_ColCat),BonusCat,INDEX(LH_Data,0,LH_ColStart),">="&AL5)*UnitFactor)) | W5: =IF(AK5=0,"",IF(NOT(LH_Ready),"",IF(BH5=0,0,INDEX(INDEX(LH_Data,0,LH_ColClose),BH5-1)*UnitFactor))) | X5: =IF(AK5=0,"",(MAX(0,BD5-BQ5)-MAX(0,BE5-BQ5))*HoursPerDay) | Y5: =IF(AK5=0,"",IF(NOT(LH_Ready),"",IF($AI5="Yes",N(AE5)*HoursPerDay-SUMIFS(INDEX(LH_Data,0,LH_ColAcc),INDEX(LH_Data,0,LH_ColFirst),$A5,INDEX(LH_Data,0,LH_ColSur),$B5,INDEX(LH_Data,0,LH_ColCat),BonusCat,INDEX(LH_Data,0,LH_ColStart),">="&(EOMONTH(AsOfDate,-1)+1),INDEX(LH_Data,0,LH_ColStart),"<="&AsOfDate)*UnitFactor,IF(BG5=0,N5,N5-N(T5)-N(U5))))) | Z5: =IF(OR(AK5=0,Y5=""),"",IF(Y5>0,"Yes","No")) | AA5: =IF(AK5=0,IF(LEN($A5&$B5)=0,"","FIX INPUT - StartDate missing"),IF(AD5<>"","FIX INPUT - "&AD5,IF(NOT(LH_Ready),"Paste Leave History export (Settings must show YES)",IF(AND($AI5="Yes",Y5<=0),"OK - EH balance accepted to date"&IF(N(AH5)>0," (EH holds "&AH5&" hrs over the scheme)","")&"; next day "&TEXT(S5,"dd mmm yy")&IF(N(AE5)>0," ("&AE5&" day(s) for "&UPPER(TEXT(AsOfDate,"mmm yyyy"))&" already in EH)",""),IF(Y5>0,"ACCRUE "&ROUND(Y5,2)&" hrs ("&ROUND(Y5/HoursPerDay,2)&" days): "&IF(N(AE5)>0,AE5&" day(s) for "&UPPER(TEXT(AsOfDate,"mmm yyyy"))&" (milestone "&UPPER(TEXT(AF5,"dd mmm yy"))&")"&IF(Y5/HoursPerDay>AE5+0.001," + "&ROUND(Y5/HoursPerDay-AE5,2)&" day(s) catch-up from earlier months",""),"all catch-up from earlier months, nothing new this month")&IF(BG5=0,"; no Bonus Leave in EH yet",""),IF(Y5<0,"CHECK - EH accrued "&ROUND(-Y5,2)&" hrs more than policy since commencement",IF(N(W5)>O5*HoursPerDay+0.01,"CHECK - EH balance "&ROUND(W5-O5*HoursPerDay,2)&" hrs more than policy entitlement",IF(O5>0,"OK - nothing to add"&IF(N(AE5)>0," ("&AE5&" day(s) for "&UPPER(TEXT(AsOfDate,"mmm yyyy"))&" already in EH)",""),IF(AW5="None",R5,"Not yet - first day on "&TEXT(S5,"dd/mm/yyyy")))))))))) | AB5: =IF(OR(AK5=0,T5=""),"",MAX(0,BE5-BQ5)*HoursPerDay-T5) | AC5: =IF(AK5=0,"",BG5) | AD5: =IF(AK5=0,"",TRIM(IF(OR(ISTEXT($F5),ISTEXT($H5),ISTEXT($I5),ISTEXT($G5),ISTEXT($J5),ISTEXT($D5)),"A date is typed as text - retype it as dd/mm/yyyy. ","")&IF(IF($C5="","",IF(OR(ISNUMBER(SEARCH("full",$C5)),UPPER(TRIM($C5))="FT",UPPER(TRIM($C5))="FTE"),"Full-Time",IF(OR(ISNUMBER(SEARCH("part",$C5)),UPPER(TRIM($C5))="PT",UPPER(TRIM($C5))="PTE"),"Part-Time",IF(OR(ISNUMBER(SEARCH("cas",$C5)),UPPER(TRIM($C5))="CAS"),"Casual","Unknown"))))="Unknown","EmploymentType not recognised - use Full-Time, Part-Time or Casual. ","")&IF(AND(AM5>=1,IF(AM5>=3,AS5,IF(AM5=2,AR5,AQ5))<>IF($C5="","",IF(OR(ISNUMBER(SEARCH("full",$C5)),UPPER(TRIM($C5))="FT",UPPER(TRIM($C5))="FTE"),"Full-Time",IF(OR(ISNUMBER(SEARCH("part",$C5)),UPPER(TRIM($C5))="PT",UPPER(TRIM($C5))="PTE"),"Part-Time",IF(OR(ISNUMBER(SEARCH("cas",$C5)),UPPER(TRIM($C5))="CAS"),"Casual","Unknown"))))),"EmploymentType does not match latest start date ("&IF(AM5>=3,AS5,IF(AM5=2,AR5,AQ5))&"). ","")&IF(AND(AM5>=1,AN5<>$F5),"Earliest type date should equal StartDate. ","")&IF(AND(AM5>=2,AN5=AO5),"Two types start on the same date. ","")&IF(AND(OR(ISNUMBER(SEARCH("part",$C5)),UPPER(TRIM($C5))="PT",UPPER(TRIM($C5))="PTE"),$P5=""),"Part-time: enter PT Hrs/Week (blank = 24+). ",""))) | AE5: =IF(AK5=0,"",O5-MAX(0,BL5-BQ5)) | AF5: =IF(OR(AK5=0,AE5="",N(AE5)=0,BM5=""),"",EDATE(AL5,BM5)) | AG5: =IF(AK5=0,"",MIN(BD5,BQ5)) | AH5: =IF(AK5=0,"",IF(NOT(LH_Ready),"",IF(BG5=0,0,MAX(0,ROUND(N(T5)+N(U5)-N5,2))))) | AK5: =IF(OR(LEN($A5&$B5)=0,$F5=""),0,1) -> 0 | AL5: =IF(AK5=0,"",IF(PreSchemeCounts="No",MAX(SchemeStart,IF($J5<>"",$J5,IF(OR(CasualCounts="Yes",COUNT($G5:$I5)=0),$F5,IF(Apply2026="No",IF($I5="",$F5,$I5),IF(COUNT($H5:$I5)=0,$F5,MIN($H5:$I5)))))),IF($J5<>"",$J5,IF(OR(CasualCounts="Yes",COUNT($G5:$I5)=0),$F5,IF(Apply2026="No",IF($I5="",$F5,$I5),IF(COUNT($H5:$I5)=0,$F5,MIN($H5:$I5))))))) | AM5: =IF(AK5=0,"",COUNT($G5:$I5)) | AN5: =IF(AK5=0,"",IFERROR(SMALL($G5:$I5,1),"")) | AO5: =IF(AK5=0,"",IFERROR(SMALL($G5:$I5,2),"")) | AP5: =IF(AK5=0,"",IFERROR(SMALL($G5:$I5,3),"")) | AQ5: =IF(AK5=0,"",IF(AN5="","",IF(AN5=$H5,"Part-Time",IF(AN5=$I5,"Full-Time","Casual")))) | AR5: =IF(AK5=0,"",IF(AO5="","",IF(AO5=$H5,"Part-Time",IF(AO5=$I5,"Full-Time","Casual")))) | AS5: =IF(AK5=0,"",IF(AP5="","",IF(AP5=$H5,"Part-Time",IF(AP5=$I5,"Full-Time","Casual")))) | AT5: =IF(AK5=0,"",IF(AM5=0,IF(OR(ISNUMBER(SEARCH("full",$C5)),UPPER(TRIM($C5))="FT",UPPER(TRIM($C5))="FTE"),"FT",IF(AND(OR(ISNUMBER(SEARCH("part",$C5)),UPPER(TRIM($C5))="PT",UPPER(TRIM($C5))="PTE"),Apply2026="Yes",OR($P5="",N($P5)>=PT_MinHours)),"PT","None")),IF(OR(ISNUMBER(SEARCH("full",AQ5)),UPPER(TRIM(AQ5))="FT",UPPER(TRIM(AQ5))="FTE"),"FT",IF(AND(OR(ISNUMBER(SEARCH("part",AQ5)),UPPER(TRIM(AQ5))="PT",UPPER(TRIM(AQ5))="PTE"),Apply2026="Yes",OR($P5="",N($P5)>=PT_MinHours)),"PT","None")))) | AU5: =IF(AK5=0,"",IF(AM5<2,"",IF(OR(ISNUMBER(SEARCH("full",AR5)),UPPER(TRIM(AR5))="FT",UPPER(TRIM(AR5))="FTE"),"FT",IF(AND(OR(ISNUMBER(SEARCH("part",AR5)),UPPER(TRIM(AR5))="PT",UPPER(TRIM(AR5))="PTE"),Apply2026="Yes",OR($P5="",N($P5)>=PT_MinHours)),"PT","None")))) | AV5: =IF(AK5=0,"",IF(AM5<3,"",IF(OR(ISNUMBER(SEARCH("full",AS5)),UPPER(TRIM(AS5))="FT",UPPER(TRIM(AS5))="FTE"),"FT",IF(AND(OR(ISNUMBER(SEARCH("part",AS5)),UPPER(TRIM(AS5))="PT",UPPER(TRIM(AS5))="PTE"),Apply2026="Yes",OR($P5="",N($P5)>=PT_MinHours)),"PT","None")))) | AW5: =IF(AK5=0,"",IF(AND(AM5>=3,AP5<=AsOfDate),AV5,IF(AND(AM5>=2,AO5<=AsOfDate),AU5,AT5))) | AX5: =IF(AK5=0,"",IF(AsOfDate<AL5,-1,12*(YEAR(AsOfDate)-YEAR(AL5))+MONTH(AsOfDate)-MONTH(AL5)-IF(DAY(AsOfDate)<MIN(DAY(AL5),DAY(EOMONTH(AsOfDate,0))),1,0))) | AY5: =IF(AK5=0,"",IF(OR(AM5<2,AO5>AsOfDate),AX5,IF((AO5-1)<AL5,-1,12*(YEAR((AO5-1))-YEAR(AL5))+MONTH((AO5-1))-MONTH(AL5)-IF(DAY((AO5-1))<MIN(DAY(AL5),DAY(EOMONTH((AO5-1),0))),1,0)))) | AZ5: =IF(AK5=0,"",IF(OR(AM5<3,AP5>AsOfDate),AX5,IF((AP5-1)<AL5,-1,12*(YEAR((AP5-1))-YEAR(AL5))+MONTH((AP5-1))-MONTH(AL5)-IF(DAY((AP5-1))<MIN(DAY(AL5),DAY(EOMONTH((AP5-1),0))),1,0)))) | BA5: =IF(AK5=0,"",IF(PFYDate<AL5,-1,12*(YEAR(PFYDate)-YEAR(AL5))+MONTH(PFYDate)-MONTH(AL5)-IF(DAY(PFYDate)<MIN(DAY(AL5),DAY(EOMONTH(PFYDate,0))),1,0))) | BB5: =IF(AK5=0,"",IF(OR(AM5<2,AO5>PFYDate),BA5,IF((AO5-1)<AL5,-1,12*(YEAR((AO5-1))-YEAR(AL5))+MONTH((AO5-1))-MONTH(AL5)-IF(DAY((AO5-1))<MIN(DAY(AL5),DAY(EOMONTH((AO5-1),0))),1,0)))) | BC5: =IF(AK5=0,"",IF(OR(AM5<3,AP5>PFYDate),BA5,IF((AP5-1)<AL5,-1,12*(YEAR((AP5-1))-YEAR(AL5))+MONTH((AP5-1))-MONTH(AL5)-IF(DAY((AP5-1))<MIN(DAY(AL5),DAY(EOMONTH((AP5-1),0))),1,0)))) | BD5: =IF(AK5=0,"",IF(AT5="FT",IF(AY5<FT_First,0,IF(AY5<FT_Y5,1+INT((AY5-FT_First)/FT_Int1),FT_PreY5+FT_PerYear*INT((AY5-FT_Y5)/12)+FT_AnnivDays+INT(MOD(AY5-FT_Y5,12)/FT_Int2)-IF(EDATE(AL5,FT_Y5)<PolicyEff,FT_AnnivDays-1,0))),IF(AT5="PT",IF(AY5<PT_First,0,1+INT((AY5-PT_First)/PT_Int)),0))+IF(AND(AM5>=2,AO5<=AsOfDate),IF(AU5="FT",IF(AZ5<FT_First,0,IF(AZ5<FT_Y5,1+INT((AZ5-FT_First)/FT_Int1),FT_PreY5+FT_PerYear*INT((AZ5-FT_Y5)/12)+FT_AnnivDays+INT(MOD(AZ5-FT_Y5,12)/FT_Int2)-IF(EDATE(AL5,FT_Y5)<PolicyEff,FT_AnnivDays-1,0))),IF(AU5="PT",IF(AZ5<PT_First,0,1+INT((AZ5-PT_First)/PT_Int)),0))-IF(AU5="FT",IF(AY5<FT_First,0,IF(AY5<FT_Y5,1+INT((AY5-FT_First)/FT_Int1),FT_PreY5+FT_PerYear*INT((AY5-FT_Y5)/12)+FT_AnnivDays+INT(MOD(AY5-FT_Y5,12)/FT_Int2)-IF(EDATE(AL5,FT_Y5)<PolicyEff,FT_AnnivDays-1,0))),IF(AU5="PT",IF(AY5<PT_First,0,1+INT((AY5-PT_First)/PT_Int)),0)),0)+IF(AND(AM5>=3,AP5<=AsOfDate),IF(AV5="FT",IF(AX5<FT_First,0,IF(AX5<FT_Y5,1+INT((AX5-FT_First)/FT_Int1),FT_PreY5+FT_PerYear*INT((AX5-FT_Y5)/12)+FT_AnnivDays+INT(MOD(AX5-FT_Y5,12)/FT_Int2)-IF(EDATE(AL5,FT_Y5)<PolicyEff,FT_AnnivDays-1,0))),IF(AV5="PT",IF(AX5<PT_First,0,1+INT((AX5-PT_First)/PT_Int)),0))-IF(AV5="FT",IF(AZ5<FT_First,0,IF(AZ5<FT_Y5,1+INT((AZ5-FT_First)/FT_Int1),FT_PreY5+FT_PerYear*INT((AZ5-FT_Y5)/12)+FT_AnnivDays+INT(MOD(AZ5-FT_Y5,12)/FT_Int2)-IF(EDATE(AL5,FT_Y5)<PolicyEff,FT_AnnivDays-1,0))),IF(AV5="PT",IF(AZ5<PT_First,0,1+INT((AZ5-PT_First)/PT_Int)),0)),0)) | BE5: =IF(AK5=0,"",IF(AT5="FT",IF(BB5<FT_First,0,IF(BB5<FT_Y5,1+INT((BB5-FT_First)/FT_Int1),FT_PreY5+FT_PerYear*INT((BB5-FT_Y5)/12)+FT_AnnivDays+INT(MOD(BB5-FT_Y5,12)/FT_Int2)-IF(EDATE(AL5,FT_Y5)<PolicyEff,FT_AnnivDays-1,0))),IF(AT5="PT",IF(BB5<PT_First,0,1+INT((BB5-PT_First)/PT_Int)),0))+IF(AND(AM5>=2,AO5<=PFYDate),IF(AU5="FT",IF(BC5<FT_First,0,IF(BC5<FT_Y5,1+INT((BC5-FT_First)/FT_Int1),FT_PreY5+FT_PerYear*INT((BC5-FT_Y5)/12)+FT_AnnivDays+INT(MOD(BC5-FT_Y5,12)/FT_Int2)-IF(EDATE(AL5,FT_Y5)<PolicyEff,FT_AnnivDays-1,0))),IF(AU5="PT",IF(BC5<PT_First,0,1+INT((BC5-PT_First)/PT_Int)),0))-IF(AU5="FT",IF(BB5<FT_First,0,IF(BB5<FT_Y5,1+INT((BB5-FT_First)/FT_Int1),FT_PreY5+FT_PerYear*INT((BB5-FT_Y5)/12)+FT_AnnivDays+INT(MOD(BB5-FT_Y5,12)/FT_Int2)-IF(EDATE(AL5,FT_Y5)<PolicyEff,FT_AnnivDays-1,0))),IF(AU5="PT",IF(BB5<PT_First,0,1+INT((BB5-PT_First)/PT_Int)),0)),0)+IF(AND(AM5>=3,AP5<=PFYDate),IF(AV5="FT",IF(BA5<FT_First,0,IF(BA5<FT_Y5,1+INT((BA5-FT_First)/FT_Int1),FT_PreY5+FT_PerYear*INT((BA5-FT_Y5)/12)+FT_AnnivDays+INT(MOD(BA5-FT_Y5,12)/FT_Int2)-IF(EDATE(AL5,FT_Y5)<PolicyEff,FT_AnnivDays-1,0))),IF(AV5="PT",IF(BA5<PT_First,0,1+INT((BA5-PT_First)/PT_Int)),0))-IF(AV5="FT",IF(BC5<FT_First,0,IF(BC5<FT_Y5,1+INT((BC5-FT_First)/FT_Int1),FT_PreY5+FT_PerYear*INT((BC5-FT_Y5)/12)+FT_AnnivDays+INT(MOD(BC5-FT_Y5,12)/FT_Int2)-IF(EDATE(AL5,FT_Y5)<PolicyEff,FT_AnnivDays-1,0))),IF(AV5="PT",IF(BC5<PT_First,0,1+INT((BC5-PT_First)/PT_Int)),0)),0)) | BF5: =IF(AK5=0,"",IF(AW5="FT",IF(AX5<FT_First,FT_First,IF(AX5<FT_Y5,MIN(FT_Y5,FT_First+FT_Int1*(INT((AX5-FT_First)/FT_Int1)+1)),FT_Y5+12*INT((AX5-FT_Y5)/12)+FT_Int2*(INT(MOD(AX5-FT_Y5,12)/FT_Int2)+1))),IF(AW5="PT",IF(AX5<PT_First,PT_First,PT_First+PT_Int*(INT((AX5-PT_First)/PT_Int)+1)),""))) | BG5: =IF(AK5=0,"",IF(NOT(LH_Ready),0,COUNTIFS(INDEX(LH_Data,0,LH_ColFirst),$A5,INDEX(LH_Data,0,LH_ColSur),$B5,INDEX(LH_Data,0,LH_ColCat),BonusCat))) | BH5: =IF(AK5=0,"",IF(OR(NOT(LH_Ready),BG5=0),0,SUMPRODUCT(MAX((INDEX(LH_Data,0,LH_ColFirst)=$A5)*(INDEX(LH_Data,0,LH_ColSur)=$B5)*(INDEX(LH_Data,0,LH_ColCat)=BonusCat)*ROW(LH_Data))))) | BI5: =IF(AK5=0,"",IF(EOMONTH(AsOfDate,-1)<AL5,-1,12*(YEAR(EOMONTH(AsOfDate,-1))-YEAR(AL5))+MONTH(EOMONTH(AsOfDate,-1))-MONTH(AL5)-IF(DAY(EOMONTH(AsOfDate,-1))<MIN(DAY(AL5),DAY(EOMONTH(EOMONTH(AsOfDate,-1),0))),1,0))) | BJ5: =IF(AK5=0,"",IF(OR(AM5<2,AO5>EOMONTH(AsOfDate,-1)),BI5,IF((AO5-1)<AL5,-1,12*(YEAR((AO5-1))-YEAR(AL5))+MONTH((AO5-1))-MONTH(AL5)-IF(DAY((AO5-1))<MIN(DAY(AL5),DAY(EOMONTH((AO5-1),0))),1,0)))) | BK5: =IF(AK5=0,"",IF(OR(AM5<3,AP5>EOMONTH(AsOfDate,-1)),BI5,IF((AP5-1)<AL5,-1,12*(YEAR((AP5-1))-YEAR(AL5))+MONTH((AP5-1))-MONTH(AL5)-IF(DAY((AP5-1))<MIN(DAY(AL5),DAY(EOMONTH((AP5-1),0))),1,0)))) | BL5: =IF(AK5=0,"",IF(AT5="FT",IF(BJ5<FT_First,0,IF(BJ5<FT_Y5,1+INT((BJ5-FT_First)/FT_Int1),FT_PreY5+FT_PerYear*INT((BJ5-FT_Y5)/12)+FT_AnnivDays+INT(MOD(BJ5-FT_Y5,12)/FT_Int2)-IF(EDATE(AL5,FT_Y5)<PolicyEff,FT_AnnivDays-1,0))),IF(AT5="PT",IF(BJ5<PT_First,0,1+INT((BJ5-PT_First)/PT_Int)),0))+IF(AND(AM5>=2,AO5<=EOMONTH(AsOfDate,-1)),IF(AU5="FT",IF(BK5<FT_First,0,IF(BK5<FT_Y5,1+INT((BK5-FT_First)/FT_Int1),FT_PreY5+FT_PerYear*INT((BK5-FT_Y5)/12)+FT_AnnivDays+INT(MOD(BK5-FT_Y5,12)/FT_Int2)-IF(EDATE(AL5,FT_Y5)<PolicyEff,FT_AnnivDays-1,0))),IF(AU5="PT",IF(BK5<PT_First,0,1+INT((BK5-PT_First)/PT_Int)),0))-IF(AU5="FT",IF(BJ5<FT_First,0,IF(BJ5<FT_Y5,1+INT((BJ5-FT_First)/FT_Int1),FT_PreY5+FT_PerYear*INT((BJ5-FT_Y5)/12)+FT_AnnivDays+INT(MOD(BJ5-FT_Y5,12)/FT_Int2)-IF(EDATE(AL5,FT_Y5)<PolicyEff,FT_AnnivDays-1,0))),IF(AU5="PT",IF(BJ5<PT_First,0,1+INT((BJ5-PT_First)/PT_Int)),0)),0)+IF(AND(AM5>=3,AP5<=EOMONTH(AsOfDate,-1)),IF(AV5="FT",IF(BI5<FT_First,0,IF(BI5<FT_Y5,1+INT((BI5-FT_First)/FT_Int1),FT_PreY5+FT_PerYear*INT((BI5-FT_Y5)/12)+FT_AnnivDays+INT(MOD(BI5-FT_Y5,12)/FT_Int2)-IF(EDATE(AL5,FT_Y5)<PolicyEff,FT_AnnivDays-1,0))),IF(AV5="PT",IF(BI5<PT_First,0,1+INT((BI5-PT_First)/PT_Int)),0))-IF(AV5="FT",IF(BK5<FT_First,0,IF(BK5<FT_Y5,1+INT((BK5-FT_First)/FT_Int1),FT_PreY5+FT_PerYear*INT((BK5-FT_Y5)/12)+FT_AnnivDays+INT(MOD(BK5-FT_Y5,12)/FT_Int2)-IF(EDATE(AL5,FT_Y5)<PolicyEff,FT_AnnivDays-1,0))),IF(AV5="PT",IF(BK5<PT_First,0,1+INT((BK5-PT_First)/PT_Int)),0)),0)) | BM5: =IF(AK5=0,"",IF(AW5="FT",IF(AX5<FT_First,"",IF(AX5<FT_Y5,FT_First+FT_Int1*INT((AX5-FT_First)/FT_Int1),FT_Y5+FT_Int2*INT((AX5-FT_Y5)/FT_Int2))),IF(AW5="PT",IF(AX5<PT_First,"",PT_First+PT_Int*INT((AX5-PT_First)/PT_Int)),""))) | BN5: =IF(AK5=0,"",IF((SchemeStart-1)<AL5,-1,12*(YEAR((SchemeStart-1))-YEAR(AL5))+MONTH((SchemeStart-1))-MONTH(AL5)-IF(DAY((SchemeStart-1))<MIN(DAY(AL5),DAY(EOMONTH((SchemeStart-1),0))),1,0))) | BO5: =IF(AK5=0,"",IF(OR(AM5<2,AO5>(SchemeStart-1)),BN5,IF((AO5-1)<AL5,-1,12*(YEAR((AO5-1))-YEAR(AL5))+MONTH((AO5-1))-MONTH(AL5)-IF(DAY((AO5-1))<MIN(DAY(AL5),DAY(EOMONTH((AO5-1),0))),1,0)))) | BP5: =IF(AK5=0,"",IF(OR(AM5<3,AP5>(SchemeStart-1)),BN5,IF((AP5-1)<AL5,-1,12*(YEAR((AP5-1))-YEAR(AL5))+MONTH((AP5-1))-MONTH(AL5)-IF(DAY((AP5-1))<MIN(DAY(AL5),DAY(EOMONTH((AP5-1),0))),1,0)))) | BQ5: =IF(AK5=0,"",IF(AT5="FT",IF(BO5<FT_First,0,IF(BO5<FT_Y5,1+INT((BO5-FT_First)/FT_Int1),FT_PreY5+FT_PerYear*INT((BO5-FT_Y5)/12)+FT_AnnivDays+INT(MOD(BO5-FT_Y5,12)/FT_Int2)-IF(EDATE(AL5,FT_Y5)<PolicyEff,FT_AnnivDays-1,0))),IF(AT5="PT",IF(BO5<PT_First,0,1+INT((BO5-PT_First)/PT_Int)),0))+IF(AND(AM5>=2,AO5<=(SchemeStart-1)),IF(AU5="FT",IF(BP5<FT_First,0,IF(BP5<FT_Y5,1+INT((BP5-FT_First)/FT_Int1),FT_PreY5+FT_PerYear*INT((BP5-FT_Y5)/12)+FT_AnnivDays+INT(MOD(BP5-FT_Y5,12)/FT_Int2)-IF(EDATE(AL5,FT_Y5)<PolicyEff,FT_AnnivDays-1,0))),IF(AU5="PT",IF(BP5<PT_First,0,1+INT((BP5-PT_First)/PT_Int)),0))-IF(AU5="FT",IF(BO5<FT_First,0,IF(BO5<FT_Y5,1+INT((BO5-FT_First)/FT_Int1),FT_PreY5+FT_PerYear*INT((BO5-FT_Y5)/12)+FT_AnnivDays+INT(MOD(BO5-FT_Y5,12)/FT_Int2)-IF(EDATE(AL5,FT_Y5)<PolicyEff,FT_AnnivDays-1,0))),IF(AU5="PT",IF(BO5<PT_First,0,1+INT((BO5-PT_First)/PT_Int)),0)),0)+IF(AND(AM5>=3,AP5<=(SchemeStart-1)),IF(AV5="FT",IF(BN5<FT_First,0,IF(BN5<FT_Y5,1+INT((BN5-FT_First)/FT_Int1),FT_PreY5+FT_PerYear*INT((BN5-FT_Y5)/12)+FT_AnnivDays+INT(MOD(BN5-FT_Y5,12)/FT_Int2)-IF(EDATE(AL5,FT_Y5)<PolicyEff,FT_AnnivDays-1,0))),IF(AV5="PT",IF(BN5<PT_First,0,1+INT((BN5-PT_First)/PT_Int)),0))-IF(AV5="FT",IF(BP5<FT_First,0,IF(BP5<FT_Y5,1+INT((BP5-FT_First)/FT_Int1),FT_PreY5+FT_PerYear*INT((BP5-FT_Y5)/12)+FT_AnnivDays+INT(MOD(BP5-FT_Y5,12)/FT_Int2)-IF(EDATE(AL5,FT_Y5)<PolicyEff,FT_AnnivDays-1,0))),IF(AV5="PT",IF(BP5<PT_First,0,1+INT((BP5-PT_First)/PT_Int)),0)),0)) | BR5: =IF(LEN($A5&$B5)=0,"",$A5&" "&$B5)
E6: =IF(OR(AK6=0,$D6=""),"",DATE(YEAR(AsOfDate)+IF(DATE(YEAR(AsOfDate),MONTH($D6),DAY($D6))<=AsOfDate,1,0),MONTH($D6),DAY($D6))) | K6: =IF(AK6=0,"",DATE(YEAR(AsOfDate)+IF(DATE(YEAR(AsOfDate),MONTH(AL6),DAY(AL6))<=AsOfDate,1,0),MONTH(AL6),DAY(AL6))) | L6: =IF(AK6=0,"",ROUND((AsOfDate-AL6)/365.25,1)) | M6: =IF(AK6=0,"",IF(AsOfDate<AL6,"-",DATEDIF(AL6,AsOfDate,"y")&"y "&DATEDIF(AL6,AsOfDate,"ym")&"m "&DATEDIF(AL6,AsOfDate,"md")&"d")) | N6: =IF(AK6=0,"",O6*HoursPerDay) | O6: =IF(AK6=0,"",MAX(0,BD6-BQ6)) | Q6: =IF(AK6=0,"",IF(AM6<2,"",AQ6&" to "&AR6&" on "&TEXT(AO6,"dd/mm/yyyy")&IF(AO6>AsOfDate," (future)",IF(AT6=AU6,"",IF(AU6="None"," - STOPPED accruing",IF(AT6="None"," - commencement for Bonus Leave"," - pathway changed"))))&IF(AM6<3,"","; "&AR6&" to "&AS6&" on "&TEXT(AP6,"dd/mm/yyyy")&IF(AP6>AsOfDate," (future)",IF(AU6=AV6,"",IF(AV6="None"," - STOPPED accruing",IF(AU6="None"," - commencement for Bonus Leave"," - pathway changed"))))))) | R6: =IF(AK6=0,"",IF(AW6="None",IF(O6>0,"No longer accruing","Not eligible - "&IF(AND(OR(ISNUMBER(SEARCH("part",$C6)),UPPER(TRIM($C6))="PT",UPPER(TRIM($C6))="PTE"),Apply2026="No"),"part-time (scheme is full-time only)",IF(AND(OR(ISNUMBER(SEARCH("part",$C6)),UPPER(TRIM($C6))="PT",UPPER(TRIM($C6))="PTE"),$P6<>"",N($P6)<PT_MinHours),"under "&PT_MinHours&" hrs",IF(IF($C6="","",IF(OR(ISNUMBER(SEARCH("full",$C6)),UPPER(TRIM($C6))="FT",UPPER(TRIM($C6))="FTE"),"Full-Time",IF(OR(ISNUMBER(SEARCH("part",$C6)),UPPER(TRIM($C6))="PT",UPPER(TRIM($C6))="PTE"),"Part-Time",IF(OR(ISNUMBER(SEARCH("cas",$C6)),UPPER(TRIM($C6))="CAS"),"Casual","Unknown"))))="Unknown","type not recognised",$C6)))),IF(O6>0,"Yes - Accrual Required","Not yet - from "&TEXT(S6,"dd/mm/yyyy")))) | S6: =IF(AK6=0,"",IF(AW6="None","",EDATE(AL6,BF6))) | T6: =IF(AK6=0,"",IF(NOT(LH_Ready),"",IF($F6>PFYDate,0,IF(LH_ColPeriod=0,W6-U6+V6,SUMIFS(INDEX(LH_Data,0,LH_ColAcc),INDEX(LH_Data,0,LH_ColFirst),$A6,INDEX(LH_Data,0,LH_ColSur),$B6,INDEX(LH_Data,0,LH_ColCat),BonusCat,INDEX(LH_Data,0,LH_ColPeriod),LH_OpenLabel)*UnitFactor)))) | U6: =IF(AK6=0,"",IF(NOT(LH_Ready),"",SUMIFS(INDEX(LH_Data,0,LH_ColAcc),INDEX(LH_Data,0,LH_ColFirst),$A6,INDEX(LH_Data,0,LH_ColSur),$B6,INDEX(LH_Data,0,LH_ColCat),BonusCat,INDEX(LH_Data,0,LH_ColStart),">="&AL6)*UnitFactor)) | V6: =IF(AK6=0,"",IF(NOT(LH_Ready),"",SUMIFS(INDEX(LH_Data,0,LH_ColTaken),INDEX(LH_Data,0,LH_ColFirst),$A6,INDEX(LH_Data,0,LH_ColSur),$B6,INDEX(LH_Data,0,LH_ColCat),BonusCat,INDEX(LH_Data,0,LH_ColStart),">="&AL6)*UnitFactor)) | W6: =IF(AK6=0,"",IF(NOT(LH_Ready),"",IF(BH6=0,0,INDEX(INDEX(LH_Data,0,LH_ColClose),BH6-1)*UnitFactor))) | X6: =IF(AK6=0,"",(MAX(0,BD6-BQ6)-MAX(0,BE6-BQ6))*HoursPerDay) | Y6: =IF(AK6=0,"",IF(NOT(LH_Ready),"",IF($AI6="Yes",N(AE6)*HoursPerDay-SUMIFS(INDEX(LH_Data,0,LH_ColAcc),INDEX(LH_Data,0,LH_ColFirst),$A6,INDEX(LH_Data,0,LH_ColSur),$B6,INDEX(LH_Data,0,LH_ColCat),BonusCat,INDEX(LH_Data,0,LH_ColStart),">="&(EOMONTH(AsOfDate,-1)+1),INDEX(LH_Data,0,LH_ColStart),"<="&AsOfDate)*UnitFactor,IF(BG6=0,N6,N6-N(T6)-N(U6))))) | Z6: =IF(OR(AK6=0,Y6=""),"",IF(Y6>0,"Yes","No")) | AA6: =IF(AK6=0,IF(LEN($A6&$B6)=0,"","FIX INPUT - StartDate missing"),IF(AD6<>"","FIX INPUT - "&AD6,IF(NOT(LH_Ready),"Paste Leave History export (Settings must show YES)",IF(AND($AI6="Yes",Y6<=0),"OK - EH balance accepted to date"&IF(N(AH6)>0," (EH holds "&AH6&" hrs over the scheme)","")&"; next day "&TEXT(S6,"dd mmm yy")&IF(N(AE6)>0," ("&AE6&" day(s) for "&UPPER(TEXT(AsOfDate,"mmm yyyy"))&" already in EH)",""),IF(Y6>0,"ACCRUE "&ROUND(Y6,2)&" hrs ("&ROUND(Y6/HoursPerDay,2)&" days): "&IF(N(AE6)>0,AE6&" day(s) for "&UPPER(TEXT(AsOfDate,"mmm yyyy"))&" (milestone "&UPPER(TEXT(AF6,"dd mmm yy"))&")"&IF(Y6/HoursPerDay>AE6+0.001," + "&ROUND(Y6/HoursPerDay-AE6,2)&" day(s) catch-up from earlier months",""),"all catch-up from earlier months, nothing new this month")&IF(BG6=0,"; no Bonus Leave in EH yet",""),IF(Y6<0,"CHECK - EH accrued "&ROUND(-Y6,2)&" hrs more than policy since commencement",IF(N(W6)>O6*HoursPerDay+0.01,"CHECK - EH balance "&ROUND(W6-O6*HoursPerDay,2)&" hrs more than policy entitlement",IF(O6>0,"OK - nothing to add"&IF(N(AE6)>0," ("&AE6&" day(s) for "&UPPER(TEXT(AsOfDate,"mmm yyyy"))&" already in EH)",""),IF(AW6="None",R6,"Not yet - first day on "&TEXT(S6,"dd/mm/yyyy")))))))))) | AB6: =IF(OR(AK6=0,T6=""),"",MAX(0,BE6-BQ6)*HoursPerDay-T6) | AC6: =IF(AK6=0,"",BG6) | AD6: =IF(AK6=0,"",TRIM(IF(OR(ISTEXT($F6),ISTEXT($H6),ISTEXT($I6),ISTEXT($G6),ISTEXT($J6),ISTEXT($D6)),"A date is typed as text - retype it as dd/mm/yyyy. ","")&IF(IF($C6="","",IF(OR(ISNUMBER(SEARCH("full",$C6)),UPPER(TRIM($C6))="FT",UPPER(TRIM($C6))="FTE"),"Full-Time",IF(OR(ISNUMBER(SEARCH("part",$C6)),UPPER(TRIM($C6))="PT",UPPER(TRIM($C6))="PTE"),"Part-Time",IF(OR(ISNUMBER(SEARCH("cas",$C6)),UPPER(TRIM($C6))="CAS"),"Casual","Unknown"))))="Unknown","EmploymentType not recognised - use Full-Time, Part-Time or Casual. ","")&IF(AND(AM6>=1,IF(AM6>=3,AS6,IF(AM6=2,AR6,AQ6))<>IF($C6="","",IF(OR(ISNUMBER(SEARCH("full",$C6)),UPPER(TRIM($C6))="FT",UPPER(TRIM($C6))="FTE"),"Full-Time",IF(OR(ISNUMBER(SEARCH("part",$C6)),UPPER(TRIM($C6))="PT",UPPER(TRIM($C6))="PTE"),"Part-Time",IF(OR(ISNUMBER(SEARCH("cas",$C6)),UPPER(TRIM($C6))="CAS"),"Casual","Unknown"))))),"EmploymentType does not match latest start date ("&IF(AM6>=3,AS6,IF(AM6=2,AR6,AQ6))&"). ","")&IF(AND(AM6>=1,AN6<>$F6),"Earliest type date should equal StartDate. ","")&IF(AND(AM6>=2,AN6=AO6),"Two types start on the same date. ","")&IF(AND(OR(ISNUMBER(SEARCH("part",$C6)),UPPER(TRIM($C6))="PT",UPPER(TRIM($C6))="PTE"),$P6=""),"Part-time: enter PT Hrs/Week (blank = 24+). ",""))) | AE6: =IF(AK6=0,"",O6-MAX(0,BL6-BQ6)) | AF6: =IF(OR(AK6=0,AE6="",N(AE6)=0,BM6=""),"",EDATE(AL6,BM6)) | AG6: =IF(AK6=0,"",MIN(BD6,BQ6)) | AH6: =IF(AK6=0,"",IF(NOT(LH_Ready),"",IF(BG6=0,0,MAX(0,ROUND(N(T6)+N(U6)-N6,2))))) | AK6: =IF(OR(LEN($A6&$B6)=0,$F6=""),0,1) -> 0 | AL6: =IF(AK6=0,"",IF(PreSchemeCounts="No",MAX(SchemeStart,IF($J6<>"",$J6,IF(OR(CasualCounts="Yes",COUNT($G6:$I6)=0),$F6,IF(Apply2026="No",IF($I6="",$F6,$I6),IF(COUNT($H6:$I6)=0,$F6,MIN($H6:$I6)))))),IF($J6<>"",$J6,IF(OR(CasualCounts="Yes",COUNT($G6:$I6)=0),$F6,IF(Apply2026="No",IF($I6="",$F6,$I6),IF(COUNT($H6:$I6)=0,$F6,MIN($H6:$I6))))))) | AM6: =IF(AK6=0,"",COUNT($G6:$I6)) | AN6: =IF(AK6=0,"",IFERROR(SMALL($G6:$I6,1),"")) | AO6: =IF(AK6=0,"",IFERROR(SMALL($G6:$I6,2),"")) | AP6: =IF(AK6=0,"",IFERROR(SMALL($G6:$I6,3),"")) | AQ6: =IF(AK6=0,"",IF(AN6="","",IF(AN6=$H6,"Part-Time",IF(AN6=$I6,"Full-Time","Casual")))) | AR6: =IF(AK6=0,"",IF(AO6="","",IF(AO6=$H6,"Part-Time",IF(AO6=$I6,"Full-Time","Casual")))) | AS6: =IF(AK6=0,"",IF(AP6="","",IF(AP6=$H6,"Part-Time",IF(AP6=$I6,"Full-Time","Casual")))) | AT6: =IF(AK6=0,"",IF(AM6=0,IF(OR(ISNUMBER(SEARCH("full",$C6)),UPPER(TRIM($C6))="FT",UPPER(TRIM($C6))="FTE"),"FT",IF(AND(OR(ISNUMBER(SEARCH("part",$C6)),UPPER(TRIM($C6))="PT",UPPER(TRIM($C6))="PTE"),Apply2026="Yes",OR($P6="",N($P6)>=PT_MinHours)),"PT","None")),IF(OR(ISNUMBER(SEARCH("full",AQ6)),UPPER(TRIM(AQ6))="FT",UPPER(TRIM(AQ6))="FTE"),"FT",IF(AND(OR(ISNUMBER(SEARCH("part",AQ6)),UPPER(TRIM(AQ6))="PT",UPPER(TRIM(AQ6))="PTE"),Apply2026="Yes",OR($P6="",N($P6)>=PT_MinHours)),"PT","None")))) | AU6: =IF(AK6=0,"",IF(AM6<2,"",IF(OR(ISNUMBER(SEARCH("full",AR6)),UPPER(TRIM(AR6))="FT",UPPER(TRIM(AR6))="FTE"),"FT",IF(AND(OR(ISNUMBER(SEARCH("part",AR6)),UPPER(TRIM(AR6))="PT",UPPER(TRIM(AR6))="PTE"),Apply2026="Yes",OR($P6="",N($P6)>=PT_MinHours)),"PT","None")))) | AV6: =IF(AK6=0,"",IF(AM6<3,"",IF(OR(ISNUMBER(SEARCH("full",AS6)),UPPER(TRIM(AS6))="FT",UPPER(TRIM(AS6))="FTE"),"FT",IF(AND(OR(ISNUMBER(SEARCH("part",AS6)),UPPER(TRIM(AS6))="PT",UPPER(TRIM(AS6))="PTE"),Apply2026="Yes",OR($P6="",N($P6)>=PT_MinHours)),"PT","None")))) | AW6: =IF(AK6=0,"",IF(AND(AM6>=3,AP6<=AsOfDate),AV6,IF(AND(AM6>=2,AO6<=AsOfDate),AU6,AT6))) | AX6: =IF(AK6=0,"",IF(AsOfDate<AL6,-1,12*(YEAR(AsOfDate)-YEAR(AL6))+MONTH(AsOfDate)-MONTH(AL6)-IF(DAY(AsOfDate)<MIN(DAY(AL6),DAY(EOMONTH(AsOfDate,0))),1,0))) | AY6: =IF(AK6=0,"",IF(OR(AM6<2,AO6>AsOfDate),AX6,IF((AO6-1)<AL6,-1,12*(YEAR((AO6-1))-YEAR(AL6))+MONTH((AO6-1))-MONTH(AL6)-IF(DAY((AO6-1))<MIN(DAY(AL6),DAY(EOMONTH((AO6-1),0))),1,0)))) | AZ6: =IF(AK6=0,"",IF(OR(AM6<3,AP6>AsOfDate),AX6,IF((AP6-1)<AL6,-1,12*(YEAR((AP6-1))-YEAR(AL6))+MONTH((AP6-1))-MONTH(AL6)-IF(DAY((AP6-1))<MIN(DAY(AL6),DAY(EOMONTH((AP6-1),0))),1,0)))) | BA6: =IF(AK6=0,"",IF(PFYDate<AL6,-1,12*(YEAR(PFYDate)-YEAR(AL6))+MONTH(PFYDate)-MONTH(AL6)-IF(DAY(PFYDate)<MIN(DAY(AL6),DAY(EOMONTH(PFYDate,0))),1,0))) | BB6: =IF(AK6=0,"",IF(OR(AM6<2,AO6>PFYDate),BA6,IF((AO6-1)<AL6,-1,12*(YEAR((AO6-1))-YEAR(AL6))+MONTH((AO6-1))-MONTH(AL6)-IF(DAY((AO6-1))<MIN(DAY(AL6),DAY(EOMONTH((AO6-1),0))),1,0)))) | BC6: =IF(AK6=0,"",IF(OR(AM6<3,AP6>PFYDate),BA6,IF((AP6-1)<AL6,-1,12*(YEAR((AP6-1))-YEAR(AL6))+MONTH((AP6-1))-MONTH(AL6)-IF(DAY((AP6-1))<MIN(DAY(AL6),DAY(EOMONTH((AP6-1),0))),1,0)))) | BD6: =IF(AK6=0,"",IF(AT6="FT",IF(AY6<FT_First,0,IF(AY6<FT_Y5,1+INT((AY6-FT_First)/FT_Int1),FT_PreY5+FT_PerYear*INT((AY6-FT_Y5)/12)+FT_AnnivDays+INT(MOD(AY6-FT_Y5,12)/FT_Int2)-IF(EDATE(AL6,FT_Y5)<PolicyEff,FT_AnnivDays-1,0))),IF(AT6="PT",IF(AY6<PT_First,0,1+INT((AY6-PT_First)/PT_Int)),0))+IF(AND(AM6>=2,AO6<=AsOfDate),IF(AU6="FT",IF(AZ6<FT_First,0,IF(AZ6<FT_Y5,1+INT((AZ6-FT_First)/FT_Int1),FT_PreY5+FT_PerYear*INT((AZ6-FT_Y5)/12)+FT_AnnivDays+INT(MOD(AZ6-FT_Y5,12)/FT_Int2)-IF(EDATE(AL6,FT_Y5)<PolicyEff,FT_AnnivDays-1,0))),IF(AU6="PT",IF(AZ6<PT_First,0,1+INT((AZ6-PT_First)/PT_Int)),0))-IF(AU6="FT",IF(AY6<FT_First,0,IF(AY6<FT_Y5,1+INT((AY6-FT_First)/FT_Int1),FT_PreY5+FT_PerYear*INT((AY6-FT_Y5)/12)+FT_AnnivDays+INT(MOD(AY6-FT_Y5,12)/FT_Int2)-IF(EDATE(AL6,FT_Y5)<PolicyEff,FT_AnnivDays-1,0))),IF(AU6="PT",IF(AY6<PT_First,0,1+INT((AY6-PT_First)/PT_Int)),0)),0)+IF(AND(AM6>=3,AP6<=AsOfDate),IF(AV6="FT",IF(AX6<FT_First,0,IF(AX6<FT_Y5,1+INT((AX6-FT_First)/FT_Int1),FT_PreY5+FT_PerYear*INT((AX6-FT_Y5)/12)+FT_AnnivDays+INT(MOD(AX6-FT_Y5,12)/FT_Int2)-IF(EDATE(AL6,FT_Y5)<PolicyEff,FT_AnnivDays-1,0))),IF(AV6="PT",IF(AX6<PT_First,0,1+INT((AX6-PT_First)/PT_Int)),0))-IF(AV6="FT",IF(AZ6<FT_First,0,IF(AZ6<FT_Y5,1+INT((AZ6-FT_First)/FT_Int1),FT_PreY5+FT_PerYear*INT((AZ6-FT_Y5)/12)+FT_AnnivDays+INT(MOD(AZ6-FT_Y5,12)/FT_Int2)-IF(EDATE(AL6,FT_Y5)<PolicyEff,FT_AnnivDays-1,0))),IF(AV6="PT",IF(AZ6<PT_First,0,1+INT((AZ6-PT_First)/PT_Int)),0)),0)) | BE6: =IF(AK6=0,"",IF(AT6="FT",IF(BB6<FT_First,0,IF(BB6<FT_Y5,1+INT((BB6-FT_First)/FT_Int1),FT_PreY5+FT_PerYear*INT((BB6-FT_Y5)/12)+FT_AnnivDays+INT(MOD(BB6-FT_Y5,12)/FT_Int2)-IF(EDATE(AL6,FT_Y5)<PolicyEff,FT_AnnivDays-1,0))),IF(AT6="PT",IF(BB6<PT_First,0,1+INT((BB6-PT_First)/PT_Int)),0))+IF(AND(AM6>=2,AO6<=PFYDate),IF(AU6="FT",IF(BC6<FT_First,0,IF(BC6<FT_Y5,1+INT((BC6-FT_First)/FT_Int1),FT_PreY5+FT_PerYear*INT((BC6-FT_Y5)/12)+FT_AnnivDays+INT(MOD(BC6-FT_Y5,12)/FT_Int2)-IF(EDATE(AL6,FT_Y5)<PolicyEff,FT_AnnivDays-1,0))),IF(AU6="PT",IF(BC6<PT_First,0,1+INT((BC6-PT_First)/PT_Int)),0))-IF(AU6="FT",IF(BB6<FT_First,0,IF(BB6<FT_Y5,1+INT((BB6-FT_First)/FT_Int1),FT_PreY5+FT_PerYear*INT((BB6-FT_Y5)/12)+FT_AnnivDays+INT(MOD(BB6-FT_Y5,12)/FT_Int2)-IF(EDATE(AL6,FT_Y5)<PolicyEff,FT_AnnivDays-1,0))),IF(AU6="PT",IF(BB6<PT_First,0,1+INT((BB6-PT_First)/PT_Int)),0)),0)+IF(AND(AM6>=3,AP6<=PFYDate),IF(AV6="FT",IF(BA6<FT_First,0,IF(BA6<FT_Y5,1+INT((BA6-FT_First)/FT_Int1),FT_PreY5+FT_PerYear*INT((BA6-FT_Y5)/12)+FT_AnnivDays+INT(MOD(BA6-FT_Y5,12)/FT_Int2)-IF(EDATE(AL6,FT_Y5)<PolicyEff,FT_AnnivDays-1,0))),IF(AV6="PT",IF(BA6<PT_First,0,1+INT((BA6-PT_First)/PT_Int)),0))-IF(AV6="FT",IF(BC6<FT_First,0,IF(BC6<FT_Y5,1+INT((BC6-FT_First)/FT_Int1),FT_PreY5+FT_PerYear*INT((BC6-FT_Y5)/12)+FT_AnnivDays+INT(MOD(BC6-FT_Y5,12)/FT_Int2)-IF(EDATE(AL6,FT_Y5)<PolicyEff,FT_AnnivDays-1,0))),IF(AV6="PT",IF(BC6<PT_First,0,1+INT((BC6-PT_First)/PT_Int)),0)),0)) | BF6: =IF(AK6=0,"",IF(AW6="FT",IF(AX6<FT_First,FT_First,IF(AX6<FT_Y5,MIN(FT_Y5,FT_First+FT_Int1*(INT((AX6-FT_First)/FT_Int1)+1)),FT_Y5+12*INT((AX6-FT_Y5)/12)+FT_Int2*(INT(MOD(AX6-FT_Y5,12)/FT_Int2)+1))),IF(AW6="PT",IF(AX6<PT_First,PT_First,PT_First+PT_Int*(INT((AX6-PT_First)/PT_Int)+1)),""))) | BG6: =IF(AK6=0,"",IF(NOT(LH_Ready),0,COUNTIFS(INDEX(LH_Data,0,LH_ColFirst),$A6,INDEX(LH_Data,0,LH_ColSur),$B6,INDEX(LH_Data,0,LH_ColCat),BonusCat))) | BH6: =IF(AK6=0,"",IF(OR(NOT(LH_Ready),BG6=0),0,SUMPRODUCT(MAX((INDEX(LH_Data,0,LH_ColFirst)=$A6)*(INDEX(LH_Data,0,LH_ColSur)=$B6)*(INDEX(LH_Data,0,LH_ColCat)=BonusCat)*ROW(LH_Data))))) | BI6: =IF(AK6=0,"",IF(EOMONTH(AsOfDate,-1)<AL6,-1,12*(YEAR(EOMONTH(AsOfDate,-1))-YEAR(AL6))+MONTH(EOMONTH(AsOfDate,-1))-MONTH(AL6)-IF(DAY(EOMONTH(AsOfDate,-1))<MIN(DAY(AL6),DAY(EOMONTH(EOMONTH(AsOfDate,-1),0))),1,0))) | BJ6: =IF(AK6=0,"",IF(OR(AM6<2,AO6>EOMONTH(AsOfDate,-1)),BI6,IF((AO6-1)<AL6,-1,12*(YEAR((AO6-1))-YEAR(AL6))+MONTH((AO6-1))-MONTH(AL6)-IF(DAY((AO6-1))<MIN(DAY(AL6),DAY(EOMONTH((AO6-1),0))),1,0)))) | BK6: =IF(AK6=0,"",IF(OR(AM6<3,AP6>EOMONTH(AsOfDate,-1)),BI6,IF((AP6-1)<AL6,-1,12*(YEAR((AP6-1))-YEAR(AL6))+MONTH((AP6-1))-MONTH(AL6)-IF(DAY((AP6-1))<MIN(DAY(AL6),DAY(EOMONTH((AP6-1),0))),1,0)))) | BL6: =IF(AK6=0,"",IF(AT6="FT",IF(BJ6<FT_First,0,IF(BJ6<FT_Y5,1+INT((BJ6-FT_First)/FT_Int1),FT_PreY5+FT_PerYear*INT((BJ6-FT_Y5)/12)+FT_AnnivDays+INT(MOD(BJ6-FT_Y5,12)/FT_Int2)-IF(EDATE(AL6,FT_Y5)<PolicyEff,FT_AnnivDays-1,0))),IF(AT6="PT",IF(BJ6<PT_First,0,1+INT((BJ6-PT_First)/PT_Int)),0))+IF(AND(AM6>=2,AO6<=EOMONTH(AsOfDate,-1)),IF(AU6="FT",IF(BK6<FT_First,0,IF(BK6<FT_Y5,1+INT((BK6-FT_First)/FT_Int1),FT_PreY5+FT_PerYear*INT((BK6-FT_Y5)/12)+FT_AnnivDays+INT(MOD(BK6-FT_Y5,12)/FT_Int2)-IF(EDATE(AL6,FT_Y5)<PolicyEff,FT_AnnivDays-1,0))),IF(AU6="PT",IF(BK6<PT_First,0,1+INT((BK6-PT_First)/PT_Int)),0))-IF(AU6="FT",IF(BJ6<FT_First,0,IF(BJ6<FT_Y5,1+INT((BJ6-FT_First)/FT_Int1),FT_PreY5+FT_PerYear*INT((BJ6-FT_Y5)/12)+FT_AnnivDays+INT(MOD(BJ6-FT_Y5,12)/FT_Int2)-IF(EDATE(AL6,FT_Y5)<PolicyEff,FT_AnnivDays-1,0))),IF(AU6="PT",IF(BJ6<PT_First,0,1+INT((BJ6-PT_First)/PT_Int)),0)),0)+IF(AND(AM6>=3,AP6<=EOMONTH(AsOfDate,-1)),IF(AV6="FT",IF(BI6<FT_First,0,IF(BI6<FT_Y5,1+INT((BI6-FT_First)/FT_Int1),FT_PreY5+FT_PerYear*INT((BI6-FT_Y5)/12)+FT_AnnivDays+INT(MOD(BI6-FT_Y5,12)/FT_Int2)-IF(EDATE(AL6,FT_Y5)<PolicyEff,FT_AnnivDays-1,0))),IF(AV6="PT",IF(BI6<PT_First,0,1+INT((BI6-PT_First)/PT_Int)),0))-IF(AV6="FT",IF(BK6<FT_First,0,IF(BK6<FT_Y5,1+INT((BK6-FT_First)/FT_Int1),FT_PreY5+FT_PerYear*INT((BK6-FT_Y5)/12)+FT_AnnivDays+INT(MOD(BK6-FT_Y5,12)/FT_Int2)-IF(EDATE(AL6,FT_Y5)<PolicyEff,FT_AnnivDays-1,0))),IF(AV6="PT",IF(BK6<PT_First,0,1+INT((BK6-PT_First)/PT_Int)),0)),0)) | BM6: =IF(AK6=0,"",IF(AW6="FT",IF(AX6<FT_First,"",IF(AX6<FT_Y5,FT_First+FT_Int1*INT((AX6-FT_First)/FT_Int1),FT_Y5+FT_Int2*INT((AX6-FT_Y5)/FT_Int2))),IF(AW6="PT",IF(AX6<PT_First,"",PT_First+PT_Int*INT((AX6-PT_First)/PT_Int)),""))) | BN6: =IF(AK6=0,"",IF((SchemeStart-1)<AL6,-1,12*(YEAR((SchemeStart-1))-YEAR(AL6))+MONTH((SchemeStart-1))-MONTH(AL6)-IF(DAY((SchemeStart-1))<MIN(DAY(AL6),DAY(EOMONTH((SchemeStart-1),0))),1,0))) | BO6: =IF(AK6=0,"",IF(OR(AM6<2,AO6>(SchemeStart-1)),BN6,IF((AO6-1)<AL6,-1,12*(YEAR((AO6-1))-YEAR(AL6))+MONTH((AO6-1))-MONTH(AL6)-IF(DAY((AO6-1))<MIN(DAY(AL6),DAY(EOMONTH((AO6-1),0))),1,0)))) | BP6: =IF(AK6=0,"",IF(OR(AM6<3,AP6>(SchemeStart-1)),BN6,IF((AP6-1)<AL6,-1,12*(YEAR((AP6-1))-YEAR(AL6))+MONTH((AP6-1))-MONTH(AL6)-IF(DAY((AP6-1))<MIN(DAY(AL6),DAY(EOMONTH((AP6-1),0))),1,0)))) | BQ6: =IF(AK6=0,"",IF(AT6="FT",IF(BO6<FT_First,0,IF(BO6<FT_Y5,1+INT((BO6-FT_First)/FT_Int1),FT_PreY5+FT_PerYear*INT((BO6-FT_Y5)/12)+FT_AnnivDays+INT(MOD(BO6-FT_Y5,12)/FT_Int2)-IF(EDATE(AL6,FT_Y5)<PolicyEff,FT_AnnivDays-1,0))),IF(AT6="PT",IF(BO6<PT_First,0,1+INT((BO6-PT_First)/PT_Int)),0))+IF(AND(AM6>=2,AO6<=(SchemeStart-1)),IF(AU6="FT",IF(BP6<FT_First,0,IF(BP6<FT_Y5,1+INT((BP6-FT_First)/FT_Int1),FT_PreY5+FT_PerYear*INT((BP6-FT_Y5)/12)+FT_AnnivDays+INT(MOD(BP6-FT_Y5,12)/FT_Int2)-IF(EDATE(AL6,FT_Y5)<PolicyEff,FT_AnnivDays-1,0))),IF(AU6="PT",IF(BP6<PT_First,0,1+INT((BP6-PT_First)/PT_Int)),0))-IF(AU6="FT",IF(BO6<FT_First,0,IF(BO6<FT_Y5,1+INT((BO6-FT_First)/FT_Int1),FT_PreY5+FT_PerYear*INT((BO6-FT_Y5)/12)+FT_AnnivDays+INT(MOD(BO6-FT_Y5,12)/FT_Int2)-IF(EDATE(AL6,FT_Y5)<PolicyEff,FT_AnnivDays-1,0))),IF(AU6="PT",IF(BO6<PT_First,0,1+INT((BO6-PT_First)/PT_Int)),0)),0)+IF(AND(AM6>=3,AP6<=(SchemeStart-1)),IF(AV6="FT",IF(BN6<FT_First,0,IF(BN6<FT_Y5,1+INT((BN6-FT_First)/FT_Int1),FT_PreY5+FT_PerYear*INT((BN6-FT_Y5)/12)+FT_AnnivDays+INT(MOD(BN6-FT_Y5,12)/FT_Int2)-IF(EDATE(AL6,FT_Y5)<PolicyEff,FT_AnnivDays-1,0))),IF(AV6="PT",IF(BN6<PT_First,0,1+INT((BN6-PT_First)/PT_Int)),0))-IF(AV6="FT",IF(BP6<FT_First,0,IF(BP6<FT_Y5,1+INT((BP6-FT_First)/FT_Int1),FT_PreY5+FT_PerYear*INT((BP6-FT_Y5)/12)+FT_AnnivDays+INT(MOD(BP6-FT_Y5,12)/FT_Int2)-IF(EDATE(AL6,FT_Y5)<PolicyEff,FT_AnnivDays-1,0))),IF(AV6="PT",IF(BP6<PT_First,0,1+INT((BP6-PT_First)/PT_Int)),0)),0)) | BR6: =IF(LEN($A6&$B6)=0,"",$A6&" "&$B6)
E7: =IF(OR(AK7=0,$D7=""),"",DATE(YEAR(AsOfDate)+IF(DATE(YEAR(AsOfDate),MONTH($D7),DAY($D7))<=AsOfDate,1,0),MONTH($D7),DAY($D7))) | K7: =IF(AK7=0,"",DATE(YEAR(AsOfDate)+IF(DATE(YEAR(AsOfDate),MONTH(AL7),DAY(AL7))<=AsOfDate,1,0),MONTH(AL7),DAY(AL7))) | L7: =IF(AK7=0,"",ROUND((AsOfDate-AL7)/365.25,1)) | M7: =IF(AK7=0,"",IF(AsOfDate<AL7,"-",DATEDIF(AL7,AsOfDate,"y")&"y "&DATEDIF(AL7,AsOfDate,"ym")&"m "&DATEDIF(AL7,AsOfDate,"md")&"d")) | N7: =IF(AK7=0,"",O7*HoursPerDay) | O7: =IF(AK7=0,"",MAX(0,BD7-BQ7)) | Q7: =IF(AK7=0,"",IF(AM7<2,"",AQ7&" to "&AR7&" on "&TEXT(AO7,"dd/mm/yyyy")&IF(AO7>AsOfDate," (future)",IF(AT7=AU7,"",IF(AU7="None"," - STOPPED accruing",IF(AT7="None"," - commencement for Bonus Leave"," - pathway changed"))))&IF(AM7<3,"","; "&AR7&" to "&AS7&" on "&TEXT(AP7,"dd/mm/yyyy")&IF(AP7>AsOfDate," (future)",IF(AU7=AV7,"",IF(AV7="None"," - STOPPED accruing",IF(AU7="None"," - commencement for Bonus Leave"," - pathway changed"))))))) | R7: =IF(AK7=0,"",IF(AW7="None",IF(O7>0,"No longer accruing","Not eligible - "&IF(AND(OR(ISNUMBER(SEARCH("part",$C7)),UPPER(TRIM($C7))="PT",UPPER(TRIM($C7))="PTE"),Apply2026="No"),"part-time (scheme is full-time only)",IF(AND(OR(ISNUMBER(SEARCH("part",$C7)),UPPER(TRIM($C7))="PT",UPPER(TRIM($C7))="PTE"),$P7<>"",N($P7)<PT_MinHours),"under "&PT_MinHours&" hrs",IF(IF($C7="","",IF(OR(ISNUMBER(SEARCH("full",$C7)),UPPER(TRIM($C7))="FT",UPPER(TRIM($C7))="FTE"),"Full-Time",IF(OR(ISNUMBER(SEARCH("part",$C7)),UPPER(TRIM($C7))="PT",UPPER(TRIM($C7))="PTE"),"Part-Time",IF(OR(ISNUMBER(SEARCH("cas",$C7)),UPPER(TRIM($C7))="CAS"),"Casual","Unknown"))))="Unknown","type not recognised",$C7)))),IF(O7>0,"Yes - Accrual Required","Not yet - from "&TEXT(S7,"dd/mm/yyyy")))) | S7: =IF(AK7=0,"",IF(AW7="None","",EDATE(AL7,BF7))) | T7: =IF(AK7=0,"",IF(NOT(LH_Ready),"",IF($F7>PFYDate,0,IF(LH_ColPeriod=0,W7-U7+V7,SUMIFS(INDEX(LH_Data,0,LH_ColAcc),INDEX(LH_Data,0,LH_ColFirst),$A7,INDEX(LH_Data,0,LH_ColSur),$B7,INDEX(LH_Data,0,LH_ColCat),BonusCat,INDEX(LH_Data,0,LH_ColPeriod),LH_OpenLabel)*UnitFactor)))) | U7: =IF(AK7=0,"",IF(NOT(LH_Ready),"",SUMIFS(INDEX(LH_Data,0,LH_ColAcc),INDEX(LH_Data,0,LH_ColFirst),$A7,INDEX(LH_Data,0,LH_ColSur),$B7,INDEX(LH_Data,0,LH_ColCat),BonusCat,INDEX(LH_Data,0,LH_ColStart),">="&AL7)*UnitFactor)) | V7: =IF(AK7=0,"",IF(NOT(LH_Ready),"",SUMIFS(INDEX(LH_Data,0,LH_ColTaken),INDEX(LH_Data,0,LH_ColFirst),$A7,INDEX(LH_Data,0,LH_ColSur),$B7,INDEX(LH_Data,0,LH_ColCat),BonusCat,INDEX(LH_Data,0,LH_ColStart),">="&AL7)*UnitFactor)) | W7: =IF(AK7=0,"",IF(NOT(LH_Ready),"",IF(BH7=0,0,INDEX(INDEX(LH_Data,0,LH_ColClose),BH7-1)*UnitFactor))) | X7: =IF(AK7=0,"",(MAX(0,BD7-BQ7)-MAX(0,BE7-BQ7))*HoursPerDay) | Y7: =IF(AK7=0,"",IF(NOT(LH_Ready),"",IF($AI7="Yes",N(AE7)*HoursPerDay-SUMIFS(INDEX(LH_Data,0,LH_ColAcc),INDEX(LH_Data,0,LH_ColFirst),$A7,INDEX(LH_Data,0,LH_ColSur),$B7,INDEX(LH_Data,0,LH_ColCat),BonusCat,INDEX(LH_Data,0,LH_ColStart),">="&(EOMONTH(AsOfDate,-1)+1),INDEX(LH_Data,0,LH_ColStart),"<="&AsOfDate)*UnitFactor,IF(BG7=0,N7,N7-N(T7)-N(U7))))) | Z7: =IF(OR(AK7=0,Y7=""),"",IF(Y7>0,"Yes","No")) | AA7: =IF(AK7=0,IF(LEN($A7&$B7)=0,"","FIX INPUT - StartDate missing"),IF(AD7<>"","FIX INPUT - "&AD7,IF(NOT(LH_Ready),"Paste Leave History export (Settings must show YES)",IF(AND($AI7="Yes",Y7<=0),"OK - EH balance accepted to date"&IF(N(AH7)>0," (EH holds "&AH7&" hrs over the scheme)","")&"; next day "&TEXT(S7,"dd mmm yy")&IF(N(AE7)>0," ("&AE7&" day(s) for "&UPPER(TEXT(AsOfDate,"mmm yyyy"))&" already in EH)",""),IF(Y7>0,"ACCRUE "&ROUND(Y7,2)&" hrs ("&ROUND(Y7/HoursPerDay,2)&" days): "&IF(N(AE7)>0,AE7&" day(s) for "&UPPER(TEXT(AsOfDate,"mmm yyyy"))&" (milestone "&UPPER(TEXT(AF7,"dd mmm yy"))&")"&IF(Y7/HoursPerDay>AE7+0.001," + "&ROUND(Y7/HoursPerDay-AE7,2)&" day(s) catch-up from earlier months",""),"all catch-up from earlier months, nothing new this month")&IF(BG7=0,"; no Bonus Leave in EH yet",""),IF(Y7<0,"CHECK - EH accrued "&ROUND(-Y7,2)&" hrs more than policy since commencement",IF(N(W7)>O7*HoursPerDay+0.01,"CHECK - EH balance "&ROUND(W7-O7*HoursPerDay,2)&" hrs more than policy entitlement",IF(O7>0,"OK - nothing to add"&IF(N(AE7)>0," ("&AE7&" day(s) for "&UPPER(TEXT(AsOfDate,"mmm yyyy"))&" already in EH)",""),IF(AW7="None",R7,"Not yet - first day on "&TEXT(S7,"dd/mm/yyyy")))))))))) | AB7: =IF(OR(AK7=0,T7=""),"",MAX(0,BE7-BQ7)*HoursPerDay-T7) | AC7: =IF(AK7=0,"",BG7) | AD7: =IF(AK7=0,"",TRIM(IF(OR(ISTEXT($F7),ISTEXT($H7),ISTEXT($I7),ISTEXT($G7),ISTEXT($J7),ISTEXT($D7)),"A date is typed as text - retype it as dd/mm/yyyy. ","")&IF(IF($C7="","",IF(OR(ISNUMBER(SEARCH("full",$C7)),UPPER(TRIM($C7))="FT",UPPER(TRIM($C7))="FTE"),"Full-Time",IF(OR(ISNUMBER(SEARCH("part",$C7)),UPPER(TRIM($C7))="PT",UPPER(TRIM($C7))="PTE"),"Part-Time",IF(OR(ISNUMBER(SEARCH("cas",$C7)),UPPER(TRIM($C7))="CAS"),"Casual","Unknown"))))="Unknown","EmploymentType not recognised - use Full-Time, Part-Time or Casual. ","")&IF(AND(AM7>=1,IF(AM7>=3,AS7,IF(AM7=2,AR7,AQ7))<>IF($C7="","",IF(OR(ISNUMBER(SEARCH("full",$C7)),UPPER(TRIM($C7))="FT",UPPER(TRIM($C7))="FTE"),"Full-Time",IF(OR(ISNUMBER(SEARCH("part",$C7)),UPPER(TRIM($C7))="PT",UPPER(TRIM($C7))="PTE"),"Part-Time",IF(OR(ISNUMBER(SEARCH("cas",$C7)),UPPER(TRIM($C7))="CAS"),"Casual","Unknown"))))),"EmploymentType does not match latest start date ("&IF(AM7>=3,AS7,IF(AM7=2,AR7,AQ7))&"). ","")&IF(AND(AM7>=1,AN7<>$F7),"Earliest type date should equal StartDate. ","")&IF(AND(AM7>=2,AN7=AO7),"Two types start on the same date. ","")&IF(AND(OR(ISNUMBER(SEARCH("part",$C7)),UPPER(TRIM($C7))="PT",UPPER(TRIM($C7))="PTE"),$P7=""),"Part-time: enter PT Hrs/Week (blank = 24+). ",""))) | AE7: =IF(AK7=0,"",O7-MAX(0,BL7-BQ7)) | AF7: =IF(OR(AK7=0,AE7="",N(AE7)=0,BM7=""),"",EDATE(AL7,BM7)) | AG7: =IF(AK7=0,"",MIN(BD7,BQ7)) | AH7: =IF(AK7=0,"",IF(NOT(LH_Ready),"",IF(BG7=0,0,MAX(0,ROUND(N(T7)+N(U7)-N7,2))))) | AK7: =IF(OR(LEN($A7&$B7)=0,$F7=""),0,1) -> 0 | AL7: =IF(AK7=0,"",IF(PreSchemeCounts="No",MAX(SchemeStart,IF($J7<>"",$J7,IF(OR(CasualCounts="Yes",COUNT($G7:$I7)=0),$F7,IF(Apply2026="No",IF($I7="",$F7,$I7),IF(COUNT($H7:$I7)=0,$F7,MIN($H7:$I7)))))),IF($J7<>"",$J7,IF(OR(CasualCounts="Yes",COUNT($G7:$I7)=0),$F7,IF(Apply2026="No",IF($I7="",$F7,$I7),IF(COUNT($H7:$I7)=0,$F7,MIN($H7:$I7))))))) | AM7: =IF(AK7=0,"",COUNT($G7:$I7)) | AN7: =IF(AK7=0,"",IFERROR(SMALL($G7:$I7,1),"")) | AO7: =IF(AK7=0,"",IFERROR(SMALL($G7:$I7,2),"")) | AP7: =IF(AK7=0,"",IFERROR(SMALL($G7:$I7,3),"")) | AQ7: =IF(AK7=0,"",IF(AN7="","",IF(AN7=$H7,"Part-Time",IF(AN7=$I7,"Full-Time","Casual")))) | AR7: =IF(AK7=0,"",IF(AO7="","",IF(AO7=$H7,"Part-Time",IF(AO7=$I7,"Full-Time","Casual")))) | AS7: =IF(AK7=0,"",IF(AP7="","",IF(AP7=$H7,"Part-Time",IF(AP7=$I7,"Full-Time","Casual")))) | AT7: =IF(AK7=0,"",IF(AM7=0,IF(OR(ISNUMBER(SEARCH("full",$C7)),UPPER(TRIM($C7))="FT",UPPER(TRIM($C7))="FTE"),"FT",IF(AND(OR(ISNUMBER(SEARCH("part",$C7)),UPPER(TRIM($C7))="PT",UPPER(TRIM($C7))="PTE"),Apply2026="Yes",OR($P7="",N($P7)>=PT_MinHours)),"PT","None")),IF(OR(ISNUMBER(SEARCH("full",AQ7)),UPPER(TRIM(AQ7))="FT",UPPER(TRIM(AQ7))="FTE"),"FT",IF(AND(OR(ISNUMBER(SEARCH("part",AQ7)),UPPER(TRIM(AQ7))="PT",UPPER(TRIM(AQ7))="PTE"),Apply2026="Yes",OR($P7="",N($P7)>=PT_MinHours)),"PT","None")))) | AU7: =IF(AK7=0,"",IF(AM7<2,"",IF(OR(ISNUMBER(SEARCH("full",AR7)),UPPER(TRIM(AR7))="FT",UPPER(TRIM(AR7))="FTE"),"FT",IF(AND(OR(ISNUMBER(SEARCH("part",AR7)),UPPER(TRIM(AR7))="PT",UPPER(TRIM(AR7))="PTE"),Apply2026="Yes",OR($P7="",N($P7)>=PT_MinHours)),"PT","None")))) | AV7: =IF(AK7=0,"",IF(AM7<3,"",IF(OR(ISNUMBER(SEARCH("full",AS7)),UPPER(TRIM(AS7))="FT",UPPER(TRIM(AS7))="FTE"),"FT",IF(AND(OR(ISNUMBER(SEARCH("part",AS7)),UPPER(TRIM(AS7))="PT",UPPER(TRIM(AS7))="PTE"),Apply2026="Yes",OR($P7="",N($P7)>=PT_MinHours)),"PT","None")))) | AW7: =IF(AK7=0,"",IF(AND(AM7>=3,AP7<=AsOfDate),AV7,IF(AND(AM7>=2,AO7<=AsOfDate),AU7,AT7))) | AX7: =IF(AK7=0,"",IF(AsOfDate<AL7,-1,12*(YEAR(AsOfDate)-YEAR(AL7))+MONTH(AsOfDate)-MONTH(AL7)-IF(DAY(AsOfDate)<MIN(DAY(AL7),DAY(EOMONTH(AsOfDate,0))),1,0))) | AY7: =IF(AK7=0,"",IF(OR(AM7<2,AO7>AsOfDate),AX7,IF((AO7-1)<AL7,-1,12*(YEAR((AO7-1))-YEAR(AL7))+MONTH((AO7-1))-MONTH(AL7)-IF(DAY((AO7-1))<MIN(DAY(AL7),DAY(EOMONTH((AO7-1),0))),1,0)))) | AZ7: =IF(AK7=0,"",IF(OR(AM7<3,AP7>AsOfDate),AX7,IF((AP7-1)<AL7,-1,12*(YEAR((AP7-1))-YEAR(AL7))+MONTH((AP7-1))-MONTH(AL7)-IF(DAY((AP7-1))<MIN(DAY(AL7),DAY(EOMONTH((AP7-1),0))),1,0)))) | BA7: =IF(AK7=0,"",IF(PFYDate<AL7,-1,12*(YEAR(PFYDate)-YEAR(AL7))+MONTH(PFYDate)-MONTH(AL7)-IF(DAY(PFYDate)<MIN(DAY(AL7),DAY(EOMONTH(PFYDate,0))),1,0))) | BB7: =IF(AK7=0,"",IF(OR(AM7<2,AO7>PFYDate),BA7,IF((AO7-1)<AL7,-1,12*(YEAR((AO7-1))-YEAR(AL7))+MONTH((AO7-1))-MONTH(AL7)-IF(DAY((AO7-1))<MIN(DAY(AL7),DAY(EOMONTH((AO7-1),0))),1,0)))) | BC7: =IF(AK7=0,"",IF(OR(AM7<3,AP7>PFYDate),BA7,IF((AP7-1)<AL7,-1,12*(YEAR((AP7-1))-YEAR(AL7))+MONTH((AP7-1))-MONTH(AL7)-IF(DAY((AP7-1))<MIN(DAY(AL7),DAY(EOMONTH((AP7-1),0))),1,0)))) | BD7: =IF(AK7=0,"",IF(AT7="FT",IF(AY7<FT_First,0,IF(AY7<FT_Y5,1+INT((AY7-FT_First)/FT_Int1),FT_PreY5+FT_PerYear*INT((AY7-FT_Y5)/12)+FT_AnnivDays+INT(MOD(AY7-FT_Y5,12)/FT_Int2)-IF(EDATE(AL7,FT_Y5)<PolicyEff,FT_AnnivDays-1,0))),IF(AT7="PT",IF(AY7<PT_First,0,1+INT((AY7-PT_First)/PT_Int)),0))+IF(AND(AM7>=2,AO7<=AsOfDate),IF(AU7="FT",IF(AZ7<FT_First,0,IF(AZ7<FT_Y5,1+INT((AZ7-FT_First)/FT_Int1),FT_PreY5+FT_PerYear*INT((AZ7-FT_Y5)/12)+FT_AnnivDays+INT(MOD(AZ7-FT_Y5,12)/FT_Int2)-IF(EDATE(AL7,FT_Y5)<PolicyEff,FT_AnnivDays-1,0))),IF(AU7="PT",IF(AZ7<PT_First,0,1+INT((AZ7-PT_First)/PT_Int)),0))-IF(AU7="FT",IF(AY7<FT_First,0,IF(AY7<FT_Y5,1+INT((AY7-FT_First)/FT_Int1),FT_PreY5+FT_PerYear*INT((AY7-FT_Y5)/12)+FT_AnnivDays+INT(MOD(AY7-FT_Y5,12)/FT_Int2)-IF(EDATE(AL7,FT_Y5)<PolicyEff,FT_AnnivDays-1,0))),IF(AU7="PT",IF(AY7<PT_First,0,1+INT((AY7-PT_First)/PT_Int)),0)),0)+IF(AND(AM7>=3,AP7<=AsOfDate),IF(AV7="FT",IF(AX7<FT_First,0,IF(AX7<FT_Y5,1+INT((AX7-FT_First)/FT_Int1),FT_PreY5+FT_PerYear*INT((AX7-FT_Y5)/12)+FT_AnnivDays+INT(MOD(AX7-FT_Y5,12)/FT_Int2)-IF(EDATE(AL7,FT_Y5)<PolicyEff,FT_AnnivDays-1,0))),IF(AV7="PT",IF(AX7<PT_First,0,1+INT((AX7-PT_First)/PT_Int)),0))-IF(AV7="FT",IF(AZ7<FT_First,0,IF(AZ7<FT_Y5,1+INT((AZ7-FT_First)/FT_Int1),FT_PreY5+FT_PerYear*INT((AZ7-FT_Y5)/12)+FT_AnnivDays+INT(MOD(AZ7-FT_Y5,12)/FT_Int2)-IF(EDATE(AL7,FT_Y5)<PolicyEff,FT_AnnivDays-1,0))),IF(AV7="PT",IF(AZ7<PT_First,0,1+INT((AZ7-PT_First)/PT_Int)),0)),0)) | BE7: =IF(AK7=0,"",IF(AT7="FT",IF(BB7<FT_First,0,IF(BB7<FT_Y5,1+INT((BB7-FT_First)/FT_Int1),FT_PreY5+FT_PerYear*INT((BB7-FT_Y5)/12)+FT_AnnivDays+INT(MOD(BB7-FT_Y5,12)/FT_Int2)-IF(EDATE(AL7,FT_Y5)<PolicyEff,FT_AnnivDays-1,0))),IF(AT7="PT",IF(BB7<PT_First,0,1+INT((BB7-PT_First)/PT_Int)),0))+IF(AND(AM7>=2,AO7<=PFYDate),IF(AU7="FT",IF(BC7<FT_First,0,IF(BC7<FT_Y5,1+INT((BC7-FT_First)/FT_Int1),FT_PreY5+FT_PerYear*INT((BC7-FT_Y5)/12)+FT_AnnivDays+INT(MOD(BC7-FT_Y5,12)/FT_Int2)-IF(EDATE(AL7,FT_Y5)<PolicyEff,FT_AnnivDays-1,0))),IF(AU7="PT",IF(BC7<PT_First,0,1+INT((BC7-PT_First)/PT_Int)),0))-IF(AU7="FT",IF(BB7<FT_First,0,IF(BB7<FT_Y5,1+INT((BB7-FT_First)/FT_Int1),FT_PreY5+FT_PerYear*INT((BB7-FT_Y5)/12)+FT_AnnivDays+INT(MOD(BB7-FT_Y5,12)/FT_Int2)-IF(EDATE(AL7,FT_Y5)<PolicyEff,FT_AnnivDays-1,0))),IF(AU7="PT",IF(BB7<PT_First,0,1+INT((BB7-PT_First)/PT_Int)),0)),0)+IF(AND(AM7>=3,AP7<=PFYDate),IF(AV7="FT",IF(BA7<FT_First,0,IF(BA7<FT_Y5,1+INT((BA7-FT_First)/FT_Int1),FT_PreY5+FT_PerYear*INT((BA7-FT_Y5)/12)+FT_AnnivDays+INT(MOD(BA7-FT_Y5,12)/FT_Int2)-IF(EDATE(AL7,FT_Y5)<PolicyEff,FT_AnnivDays-1,0))),IF(AV7="PT",IF(BA7<PT_First,0,1+INT((BA7-PT_First)/PT_Int)),0))-IF(AV7="FT",IF(BC7<FT_First,0,IF(BC7<FT_Y5,1+INT((BC7-FT_First)/FT_Int1),FT_PreY5+FT_PerYear*INT((BC7-FT_Y5)/12)+FT_AnnivDays+INT(MOD(BC7-FT_Y5,12)/FT_Int2)-IF(EDATE(AL7,FT_Y5)<PolicyEff,FT_AnnivDays-1,0))),IF(AV7="PT",IF(BC7<PT_First,0,1+INT((BC7-PT_First)/PT_Int)),0)),0)) | BF7: =IF(AK7=0,"",IF(AW7="FT",IF(AX7<FT_First,FT_First,IF(AX7<FT_Y5,MIN(FT_Y5,FT_First+FT_Int1*(INT((AX7-FT_First)/FT_Int1)+1)),FT_Y5+12*INT((AX7-FT_Y5)/12)+FT_Int2*(INT(MOD(AX7-FT_Y5,12)/FT_Int2)+1))),IF(AW7="PT",IF(AX7<PT_First,PT_First,PT_First+PT_Int*(INT((AX7-PT_First)/PT_Int)+1)),""))) | BG7: =IF(AK7=0,"",IF(NOT(LH_Ready),0,COUNTIFS(INDEX(LH_Data,0,LH_ColFirst),$A7,INDEX(LH_Data,0,LH_ColSur),$B7,INDEX(LH_Data,0,LH_ColCat),BonusCat))) | BH7: =IF(AK7=0,"",IF(OR(NOT(LH_Ready),BG7=0),0,SUMPRODUCT(MAX((INDEX(LH_Data,0,LH_ColFirst)=$A7)*(INDEX(LH_Data,0,LH_ColSur)=$B7)*(INDEX(LH_Data,0,LH_ColCat)=BonusCat)*ROW(LH_Data))))) | BI7: =IF(AK7=0,"",IF(EOMONTH(AsOfDate,-1)<AL7,-1,12*(YEAR(EOMONTH(AsOfDate,-1))-YEAR(AL7))+MONTH(EOMONTH(AsOfDate,-1))-MONTH(AL7)-IF(DAY(EOMONTH(AsOfDate,-1))<MIN(DAY(AL7),DAY(EOMONTH(EOMONTH(AsOfDate,-1),0))),1,0))) | BJ7: =IF(AK7=0,"",IF(OR(AM7<2,AO7>EOMONTH(AsOfDate,-1)),BI7,IF((AO7-1)<AL7,-1,12*(YEAR((AO7-1))-YEAR(AL7))+MONTH((AO7-1))-MONTH(AL7)-IF(DAY((AO7-1))<MIN(DAY(AL7),DAY(EOMONTH((AO7-1),0))),1,0)))) | BK7: =IF(AK7=0,"",IF(OR(AM7<3,AP7>EOMONTH(AsOfDate,-1)),BI7,IF((AP7-1)<AL7,-1,12*(YEAR((AP7-1))-YEAR(AL7))+MONTH((AP7-1))-MONTH(AL7)-IF(DAY((AP7-1))<MIN(DAY(AL7),DAY(EOMONTH((AP7-1),0))),1,0)))) | BL7: =IF(AK7=0,"",IF(AT7="FT",IF(BJ7<FT_First,0,IF(BJ7<FT_Y5,1+INT((BJ7-FT_First)/FT_Int1),FT_PreY5+FT_PerYear*INT((BJ7-FT_Y5)/12)+FT_AnnivDays+INT(MOD(BJ7-FT_Y5,12)/FT_Int2)-IF(EDATE(AL7,FT_Y5)<PolicyEff,FT_AnnivDays-1,0))),IF(AT7="PT",IF(BJ7<PT_First,0,1+INT((BJ7-PT_First)/PT_Int)),0))+IF(AND(AM7>=2,AO7<=EOMONTH(AsOfDate,-1)),IF(AU7="FT",IF(BK7<FT_First,0,IF(BK7<FT_Y5,1+INT((BK7-FT_First)/FT_Int1),FT_PreY5+FT_PerYear*INT((BK7-FT_Y5)/12)+FT_AnnivDays+INT(MOD(BK7-FT_Y5,12)/FT_Int2)-IF(EDATE(AL7,FT_Y5)<PolicyEff,FT_AnnivDays-1,0))),IF(AU7="PT",IF(BK7<PT_First,0,1+INT((BK7-PT_First)/PT_Int)),0))-IF(AU7="FT",IF(BJ7<FT_First,0,IF(BJ7<FT_Y5,1+INT((BJ7-FT_First)/FT_Int1),FT_PreY5+FT_PerYear*INT((BJ7-FT_Y5)/12)+FT_AnnivDays+INT(MOD(BJ7-FT_Y5,12)/FT_Int2)-IF(EDATE(AL7,FT_Y5)<PolicyEff,FT_AnnivDays-1,0))),IF(AU7="PT",IF(BJ7<PT_First,0,1+INT((BJ7-PT_First)/PT_Int)),0)),0)+IF(AND(AM7>=3,AP7<=EOMONTH(AsOfDate,-1)),IF(AV7="FT",IF(BI7<FT_First,0,IF(BI7<FT_Y5,1+INT((BI7-FT_First)/FT_Int1),FT_PreY5+FT_PerYear*INT((BI7-FT_Y5)/12)+FT_AnnivDays+INT(MOD(BI7-FT_Y5,12)/FT_Int2)-IF(EDATE(AL7,FT_Y5)<PolicyEff,FT_AnnivDays-1,0))),IF(AV7="PT",IF(BI7<PT_First,0,1+INT((BI7-PT_First)/PT_Int)),0))-IF(AV7="FT",IF(BK7<FT_First,0,IF(BK7<FT_Y5,1+INT((BK7-FT_First)/FT_Int1),FT_PreY5+FT_PerYear*INT((BK7-FT_Y5)/12)+FT_AnnivDays+INT(MOD(BK7-FT_Y5,12)/FT_Int2)-IF(EDATE(AL7,FT_Y5)<PolicyEff,FT_AnnivDays-1,0))),IF(AV7="PT",IF(BK7<PT_First,0,1+INT((BK7-PT_First)/PT_Int)),0)),0)) | BM7: =IF(AK7=0,"",IF(AW7="FT",IF(AX7<FT_First,"",IF(AX7<FT_Y5,FT_First+FT_Int1*INT((AX7-FT_First)/FT_Int1),FT_Y5+FT_Int2*INT((AX7-FT_Y5)/FT_Int2))),IF(AW7="PT",IF(AX7<PT_First,"",PT_First+PT_Int*INT((AX7-PT_First)/PT_Int)),""))) | BN7: =IF(AK7=0,"",IF((SchemeStart-1)<AL7,-1,12*(YEAR((SchemeStart-1))-YEAR(AL7))+MONTH((SchemeStart-1))-MONTH(AL7)-IF(DAY((SchemeStart-1))<MIN(DAY(AL7),DAY(EOMONTH((SchemeStart-1),0))),1,0))) | BO7: =IF(AK7=0,"",IF(OR(AM7<2,AO7>(SchemeStart-1)),BN7,IF((AO7-1)<AL7,-1,12*(YEAR((AO7-1))-YEAR(AL7))+MONTH((AO7-1))-MONTH(AL7)-IF(DAY((AO7-1))<MIN(DAY(AL7),DAY(EOMONTH((AO7-1),0))),1,0)))) | BP7: =IF(AK7=0,"",IF(OR(AM7<3,AP7>(SchemeStart-1)),BN7,IF((AP7-1)<AL7,-1,12*(YEAR((AP7-1))-YEAR(AL7))+MONTH((AP7-1))-MONTH(AL7)-IF(DAY((AP7-1))<MIN(DAY(AL7),DAY(EOMONTH((AP7-1),0))),1,0)))) | BQ7: =IF(AK7=0,"",IF(AT7="FT",IF(BO7<FT_First,0,IF(BO7<FT_Y5,1+INT((BO7-FT_First)/FT_Int1),FT_PreY5+FT_PerYear*INT((BO7-FT_Y5)/12)+FT_AnnivDays+INT(MOD(BO7-FT_Y5,12)/FT_Int2)-IF(EDATE(AL7,FT_Y5)<PolicyEff,FT_AnnivDays-1,0))),IF(AT7="PT",IF(BO7<PT_First,0,1+INT((BO7-PT_First)/PT_Int)),0))+IF(AND(AM7>=2,AO7<=(SchemeStart-1)),IF(AU7="FT",IF(BP7<FT_First,0,IF(BP7<FT_Y5,1+INT((BP7-FT_First)/FT_Int1),FT_PreY5+FT_PerYear*INT((BP7-FT_Y5)/12)+FT_AnnivDays+INT(MOD(BP7-FT_Y5,12)/FT_Int2)-IF(EDATE(AL7,FT_Y5)<PolicyEff,FT_AnnivDays-1,0))),IF(AU7="PT",IF(BP7<PT_First,0,1+INT((BP7-PT_First)/PT_Int)),0))-IF(AU7="FT",IF(BO7<FT_First,0,IF(BO7<FT_Y5,1+INT((BO7-FT_First)/FT_Int1),FT_PreY5+FT_PerYear*INT((BO7-FT_Y5)/12)+FT_AnnivDays+INT(MOD(BO7-FT_Y5,12)/FT_Int2)-IF(EDATE(AL7,FT_Y5)<PolicyEff,FT_AnnivDays-1,0))),IF(AU7="PT",IF(BO7<PT_First,0,1+INT((BO7-PT_First)/PT_Int)),0)),0)+IF(AND(AM7>=3,AP7<=(SchemeStart-1)),IF(AV7="FT",IF(BN7<FT_First,0,IF(BN7<FT_Y5,1+INT((BN7-FT_First)/FT_Int1),FT_PreY5+FT_PerYear*INT((BN7-FT_Y5)/12)+FT_AnnivDays+INT(MOD(BN7-FT_Y5,12)/FT_Int2)-IF(EDATE(AL7,FT_Y5)<PolicyEff,FT_AnnivDays-1,0))),IF(AV7="PT",IF(BN7<PT_First,0,1+INT((BN7-PT_First)/PT_Int)),0))-IF(AV7="FT",IF(BP7<FT_First,0,IF(BP7<FT_Y5,1+INT((BP7-FT_First)/FT_Int1),FT_PreY5+FT_PerYear*INT((BP7-FT_Y5)/12)+FT_AnnivDays+INT(MOD(BP7-FT_Y5,12)/FT_Int2)-IF(EDATE(AL7,FT_Y5)<PolicyEff,FT_AnnivDays-1,0))),IF(AV7="PT",IF(BP7<PT_First,0,1+INT((BP7-PT_First)/PT_Int)),0)),0)) | BR7: =IF(LEN($A7&$B7)=0,"",$A7&" "&$B7)
