Workbook

Sheet Summary 
A1: TIMESHEET TO PAYROLL RECONCILIATION - Jonathan Hendratno (Employee ID 12414219)
A2: Timesheet hours transcribed from the timesheet screenshots (fortnights ending 07/08/2026, 21/08/2026, 04/09/2026 and 18/09/2026). Paid hours are pulled live by formula from the pay-run tabs in this workbook, matched on work date AND location. Prepared 22/09/2026.
A4: A. QUERY RESPONSE - the 16 hours claimed missing WERE paid. Nothing is owing.
A5: Date | B5: Day | C5: Location / Client | D5: Hours Claimed Missing | E5: Hours Actually Paid | F5: Shortfall (Hrs) | G5: Paid in Pay Run | H5: Where to find it on that tab | I5: Rate $/hr | J5: Gross Paid $ | K5: Outcome
A6: 46258 | B6: Mon | C6: DTTL Mel Tech FT 1 [ONS] | D6: 8 | E6: =SUMIFS('07 Aug 2026'!$G$3:$G$6,'07 Aug 2026'!$S$3:$S$6,$A6,'07 Aug 2026'!$K$3:$K$6,$C6)+SUMIFS('21 Aug 2026'!$G$3:$G$7,'21 Aug 2026'!$S$3:$S$7,$A6,'21 Aug 2026'!$K$3:$K$7,$C6)+SUMIFS('20 Sept 2026 '!$G$3:$G$14,'20 Sept 2026 '!$S$3:$S$14,$A6,'20 Sept 2026 '!$K$3:$K$14,$C6)+SUMIFS('22 Sep 2026'!$G$3:$G$11,'22 Sep 2026'!$S$3:$S$11,$A6,'22 Sep 2026'!$K$3:$K$11,$C6) | F6: =D6-E6 | G6: =IF(SUMIFS('07 Aug 2026'!$G$3:$G$6,'07 Aug 2026'!$S$3:$S$6,$A6,'07 Aug 2026'!$K$3:$K$6,$C6)<>0,"07 Aug 2026",IF(SUMIFS('21 Aug 2026'!$G$3:$G$7,'21 Aug 2026'!$S$3:$S$7,$A6,'21 Aug 2026'!$K$3:$K$7,$C6)<>0,"21 Aug 2026",IF(SUMIFS('20 Sept 2026 '!$G$3:$G$14,'20 Sept 2026 '!$S$3:$S$14,$A6,'20 Sept 2026 '!$K$3:$K$14,$C6)<>0,"20 Sep 2026",IF(SUMIFS('22 Sep 2026'!$G$3:$G$11,'22 Sep 2026'!$S$3:$S$11,$A6,'22 Sep 2026'!$K$3:$K$11,$C6)<>0,"22 Sep 2026","NOT PAID")))) | H6: '20 Sept 2026 ' rows 3 and 4 (3.5 hrs 08:30-12:00 + 4.5 hrs 12:30-17:00) | I6: =IFERROR(J6/E6,"") | J6: =SUMIFS('07 Aug 2026'!$O$3:$O$6,'07 Aug 2026'!$S$3:$S$6,$A6,'07 Aug 2026'!$K$3:$K$6,$C6)+SUMIFS('21 Aug 2026'!$O$3:$O$7,'21 Aug 2026'!$S$3:$S$7,$A6,'21 Aug 2026'!$K$3:$K$7,$C6)+SUMIFS('20 Sept 2026 '!$O$3:$O$14,'20 Sept 2026 '!$S$3:$S$14,$A6,'20 Sept 2026 '!$K$3:$K$14,$C6)+SUMIFS('22 Sep 2026'!$O$3:$O$11,'22 Sep 2026'!$S$3:$S$11,$A6,'22 Sep 2026'!$K$3:$K$11,$C6) | K6: =IF(ROUND(F6,2)=0,"PAID IN FULL - nothing owing","SHORTFALL - investigate")
A7: 46262 | B7: Fri | C7: DTTL Mel Tech FT 1 [ONS] | D7: 8 | E7: =SUMIFS('07 Aug 2026'!$G$3:$G$6,'07 Aug 2026'!$S$3:$S$6,$A7,'07 Aug 2026'!$K$3:$K$6,$C7)+SUMIFS('21 Aug 2026'!$G$3:$G$7,'21 Aug 2026'!$S$3:$S$7,$A7,'21 Aug 2026'!$K$3:$K$7,$C7)+SUMIFS('20 Sept 2026 '!$G$3:$G$14,'20 Sept 2026 '!$S$3:$S$14,$A7,'20 Sept 2026 '!$K$3:$K$14,$C7)+SUMIFS('22 Sep 2026'!$G$3:$G$11,'22 Sep 2026'!$S$3:$S$11,$A7,'22 Sep 2026'!$K$3:$K$11,$C7) | F7: =D7-E7 | G7: =IF(SUMIFS('07 Aug 2026'!$G$3:$G$6,'07 Aug 2026'!$S$3:$S$6,$A7,'07 Aug 2026'!$K$3:$K$6,$C7)<>0,"07 Aug 2026",IF(SUMIFS('21 Aug 2026'!$G$3:$G$7,'21 Aug 2026'!$S$3:$S$7,$A7,'21 Aug 2026'!$K$3:$K$7,$C7)<>0,"21 Aug 2026",IF(SUMIFS('20 Sept 2026 '!$G$3:$G$14,'20 Sept 2026 '!$S$3:$S$14,$A7,'20 Sept 2026 '!$K$3:$K$14,$C7)<>0,"20 Sep 2026",IF(SUMIFS('22 Sep 2026'!$G$3:$G$11,'22 Sep 2026'!$S$3:$S$11,$A7,'22 Sep 2026'!$K$3:$K$11,$C7)<>0,"22 Sep 2026","NOT PAID")))) | H7: '20 Sept 2026 ' rows 5 and 6 (3.5 hrs 08:30-12:00 + 4.5 hrs 12:30-17:00) | I7: =IFERROR(J7/E7,"") | J7: =SUMIFS('07 Aug 2026'!$O$3:$O$6,'07 Aug 2026'!$S$3:$S$6,$A7,'07 Aug 2026'!$K$3:$K$6,$C7)+SUMIFS('21 Aug 2026'!$O$3:$O$7,'21 Aug 2026'!$S$3:$S$7,$A7,'21 Aug 2026'!$K$3:$K$7,$C7)+SUMIFS('20 Sept 2026 '!$O$3:$O$14,'20 Sept 2026 '!$S$3:$S$14,$A7,'20 Sept 2026 '!$K$3:$K$14,$C7)+SUMIFS('22 Sep 2026'!$O$3:$O$11,'22 Sep 2026'!$S$3:$S$11,$A7,'22 Sep 2026'!$K$3:$K$11,$C7) | K7: =IF(ROUND(F7,2)=0,"PAID IN FULL - nothing owing","SHORTFALL - investigate")
A8: TOTAL CLAIMED | D8: =SUM(D6:D7) | E8: =SUM(E6:E7) | F8: =SUM(F6:F7) | J8: =SUM(J6:J7) | K8: =IF(ROUND(F8,2)=0,"NIL OWING - all "&TEXT(D8,"0")&" hrs paid ($"&TEXT(J8,"#,##0.00")&" gross)","AMOUNT OWING - investigate")
A9: WHY IT LOOKED MISSING: (1) Each day is split across two pay lines, either side of the lunch break - 3.5 hrs + 4.5 hrs - so neither line ever shows as "8 hours" when you scan the payslip. (2) Both days sit in the fortnight ending 04/09/2026, but that fortnight was paid across TWO pay runs: the 48 hrs of DTTL work went through the 20 Sep 2026 run, while the 23.5 hrs of PwC work went through the 22 Sep 2026 run. Looking at only one of those payslips shows only part of the fortnight.
A11: B. FORTNIGHT SUMMARY - timesheet hours vs hours actually paid
A12: Fortnight Ending | B12: Timesheets (count) | C12: Timesheet Hours | D12: Paid Hours | E12: Variance (Hrs) | F12: Variance ($ @ $37.50) | G12: Status | H12: Paid in Pay Run(s)
A13: 46241 | B13: =COUNTIFS($C$21:$C$36,$A13) | C13: =SUMIFS($H$21:$H$36,$C$21:$C$36,$A13) | D13: =SUMIFS($I$21:$I$36,$C$21:$C$36,$A13) | E13: =C13-D13 | F13: =E13*37.5 | G13: =IF(ROUND(E13,2)=0,"Reconciled","VARIANCE - investigate") | H13: 07 Aug 2026
A14: 46255 | B14: =COUNTIFS($C$21:$C$36,$A14) | C14: =SUMIFS($H$21:$H$36,$C$21:$C$36,$A14) | D14: =SUMIFS($I$21:$I$36,$C$21:$C$36,$A14) | E14: =C14-D14 | F14: =E14*37.5 | G14: =IF(ROUND(E14,2)=0,"Reconciled","VARIANCE - investigate") | H14: 21 Aug 2026
A15: 46269 | B15: =COUNTIFS($C$21:$C$36,$A15) | C15: =SUMIFS($H$21:$H$36,$C$21:$C$36,$A15) | D15: =SUMIFS($I$21:$I$36,$C$21:$C$36,$A15) | E15: =C15-D15 | F15: =E15*37.5 | G15: =IF(ROUND(E15,2)=0,"Reconciled","VARIANCE - investigate") | H15: 20 Sep 2026 (DTTL 48 hrs) + 22 Sep 2026 (PwC 23.5 hrs)
A16: 46283 | B16: =COUNTIFS($C$21:$C$36,$A16) | C16: =SUMIFS($H$21:$H$36,$C$21:$C$36,$A16) | D16: =SUMIFS($I$21:$I$36,$C$21:$C$36,$A16) | E16: =C16-D16 | F16: =E16*37.5 | G16: =IF(ROUND(E16,2)=0,"Reconciled","VARIANCE - investigate") | H16: 22 Sep 2026
A17: TOTAL | B17: =SUM(B13:B16) | C17: =SUM(C13:C16) | D17: =SUM(D13:D16) | E17: =SUM(E13:E16) | F17: =SUM(F13:F16) | G17: =IF(ROUND(E17,2)=0,"FULLY RECONCILED","VARIANCE - investigate")
A19: C. DAY-BY-DAY RECONCILIATION - every timesheet line matched to the pay run that paid it
A20: Date | B20: Day | C20: Fortnight Ending | D20: Location / Client (per timesheet) | E20: Start | F20: End | G20: Break | H20: Timesheet Hours | I20: Paid Hours | J20: Variance (Hrs) | K20: Paid in Pay Run | L20: Rate Paid $/hr | M20: Gross Paid $ | N20: Rate Check | O20: Notes
A21: 46232 | B21: Wed | C21: 46241 | D21: CBA FT Tech MEL - 12 months [ONS] | E21: 7:00 AM | F21: 4:00 PM | G21: 12:30-1:30 | H21: 8 | I21: =SUMIFS('07 Aug 2026'!$G$3:$G$6,'07 Aug 2026'!$S$3:$S$6,$A21,'07 Aug 2026'!$K$3:$K$6,$D21)+SUMIFS('21 Aug 2026'!$G$3:$G$7,'21 Aug 2026'!$S$3:$S$7,$A21,'21 Aug 2026'!$K$3:$K$7,$D21)+SUMIFS('20 Sept 2026 '!$G$3:$G$14,'20 Sept 2026 '!$S$3:$S$14,$A21,'20 Sept 2026 '!$K$3:$K$14,$D21)+SUMIFS('22 Sep 2026'!$G$3:$G$11,'22 Sep 2026'!$S$3:$S$11,$A21,'22 Sep 2026'!$K$3:$K$11,$D21) | J21: =H21-I21 | K21: =IF(SUMIFS('07 Aug 2026'!$G$3:$G$6,'07 Aug 2026'!$S$3:$S$6,$A21,'07 Aug 2026'!$K$3:$K$6,$D21)<>0,"07 Aug 2026",IF(SUMIFS('21 Aug 2026'!$G$3:$G$7,'21 Aug 2026'!$S$3:$S$7,$A21,'21 Aug 2026'!$K$3:$K$7,$D21)<>0,"21 Aug 2026",IF(SUMIFS('20 Sept 2026 '!$G$3:$G$14,'20 Sept 2026 '!$S$3:$S$14,$A21,'20 Sept 2026 '!$K$3:$K$14,$D21)<>0,"20 Sep 2026",IF(SUMIFS('22 Sep 2026'!$G$3:$G$11,'22 Sep 2026'!$S$3:$S$11,$A21,'22 Sep 2026'!$K$3:$K$11,$D21)<>0,"22 Sep 2026","NOT PAID")))) | L21: =IFERROR(M21/I21,"") | M21: =SUMIFS('07 Aug 2026'!$O$3:$O$6,'07 Aug 2026'!$S$3:$S$6,$A21,'07 Aug 2026'!$K$3:$K$6,$D21)+SUMIFS('21 Aug 2026'!$O$3:$O$7,'21 Aug 2026'!$S$3:$S$7,$A21,'21 Aug 2026'!$K$3:$K$7,$D21)+SUMIFS('20 Sept 2026 '!$O$3:$O$14,'20 Sept 2026 '!$S$3:$S$14,$A21,'20 Sept 2026 '!$K$3:$K$14,$D21)+SUMIFS('22 Sep 2026'!$O$3:$O$11,'22 Sep 2026'!$S$3:$S$11,$A21,'22 Sep 2026'!$K$3:$K$11,$D21) | N21: =IF(I21=0,"",IF(ROUND(L21,2)=37.5,"OK","UNDER - $"&TEXT((37.5-L21)*I21,"0.00"))) | O21: Paid as 5.5 + 2.5 hrs either side of break
A22: 46233 | B22: Thu | C22: 46241 | D22: PWC – MEL Technician [ONS] | E22: 8:00 AM | F22: 12:00 PM | G22: - | H22: 4 | I22: =SUMIFS('07 Aug 2026'!$G$3:$G$6,'07 Aug 2026'!$S$3:$S$6,$A22,'07 Aug 2026'!$K$3:$K$6,$D22)+SUMIFS('21 Aug 2026'!$G$3:$G$7,'21 Aug 2026'!$S$3:$S$7,$A22,'21 Aug 2026'!$K$3:$K$7,$D22)+SUMIFS('20 Sept 2026 '!$G$3:$G$14,'20 Sept 2026 '!$S$3:$S$14,$A22,'20 Sept 2026 '!$K$3:$K$14,$D22)+SUMIFS('22 Sep 2026'!$G$3:$G$11,'22 Sep 2026'!$S$3:$S$11,$A22,'22 Sep 2026'!$K$3:$K$11,$D22) | J22: =H22-I22 | K22: =IF(SUMIFS('07 Aug 2026'!$G$3:$G$6,'07 Aug 2026'!$S$3:$S$6,$A22,'07 Aug 2026'!$K$3:$K$6,$D22)<>0,"07 Aug 2026",IF(SUMIFS('21 Aug 2026'!$G$3:$G$7,'21 Aug 2026'!$S$3:$S$7,$A22,'21 Aug 2026'!$K$3:$K$7,$D22)<>0,"21 Aug 2026",IF(SUMIFS('20 Sept 2026 '!$G$3:$G$14,'20 Sept 2026 '!$S$3:$S$14,$A22,'20 Sept 2026 '!$K$3:$K$14,$D22)<>0,"20 Sep 2026",IF(SUMIFS('22 Sep 2026'!$G$3:$G$11,'22 Sep 2026'!$S$3:$S$11,$A22,'22 Sep 2026'!$K$3:$K$11,$D22)<>0,"22 Sep 2026","NOT PAID")))) | L22: =IFERROR(M22/I22,"") | M22: =SUMIFS('07 Aug 2026'!$O$3:$O$6,'07 Aug 2026'!$S$3:$S$6,$A22,'07 Aug 2026'!$K$3:$K$6,$D22)+SUMIFS('21 Aug 2026'!$O$3:$O$7,'21 Aug 2026'!$S$3:$S$7,$A22,'21 Aug 2026'!$K$3:$K$7,$D22)+SUMIFS('20 Sept 2026 '!$O$3:$O$14,'20 Sept 2026 '!$S$3:$S$14,$A22,'20 Sept 2026 '!$K$3:$K$14,$D22)+SUMIFS('22 Sep 2026'!$O$3:$O$11,'22 Sep 2026'!$S$3:$S$11,$A22,'22 Sep 2026'!$K$3:$K$11,$D22) | N22: =IF(I22=0,"",IF(ROUND(L22,2)=37.5,"OK","UNDER - $"&TEXT((37.5-L22)*I22,"0.00"))) | O22: Two separate timesheets this day - matched by location
A23: 46233 | B23: Thu | C23: 46241 | D23: Aware Super AV Maintenance [ONS] | E23: 2:25 PM | F23: 6:25 PM | G23: - | H23: 4 | I23: =SUMIFS('07 Aug 2026'!$G$3:$G$6,'07 Aug 2026'!$S$3:$S$6,$A23,'07 Aug 2026'!$K$3:$K$6,$D23)+SUMIFS('21 Aug 2026'!$G$3:$G$7,'21 Aug 2026'!$S$3:$S$7,$A23,'21 Aug 2026'!$K$3:$K$7,$D23)+SUMIFS('20 Sept 2026 '!$G$3:$G$14,'20 Sept 2026 '!$S$3:$S$14,$A23,'20 Sept 2026 '!$K$3:$K$14,$D23)+SUMIFS('22 Sep 2026'!$G$3:$G$11,'22 Sep 2026'!$S$3:$S$11,$A23,'22 Sep 2026'!$K$3:$K$11,$D23) | J23: =H23-I23 | K23: =IF(SUMIFS('07 Aug 2026'!$G$3:$G$6,'07 Aug 2026'!$S$3:$S$6,$A23,'07 Aug 2026'!$K$3:$K$6,$D23)<>0,"07 Aug 2026",IF(SUMIFS('21 Aug 2026'!$G$3:$G$7,'21 Aug 2026'!$S$3:$S$7,$A23,'21 Aug 2026'!$K$3:$K$7,$D23)<>0,"21 Aug 2026",IF(SUMIFS('20 Sept 2026 '!$G$3:$G$14,'20 Sept 2026 '!$S$3:$S$14,$A23,'20 Sept 2026 '!$K$3:$K$14,$D23)<>0,"20 Sep 2026",IF(SUMIFS('22 Sep 2026'!$G$3:$G$11,'22 Sep 2026'!$S$3:$S$11,$A23,'22 Sep 2026'!$K$3:$K$11,$D23)<>0,"22 Sep 2026","NOT PAID")))) | L23: =IFERROR(M23/I23,"") | M23: =SUMIFS('07 Aug 2026'!$O$3:$O$6,'07 Aug 2026'!$S$3:$S$6,$A23,'07 Aug 2026'!$K$3:$K$6,$D23)+SUMIFS('21 Aug 2026'!$O$3:$O$7,'21 Aug 2026'!$S$3:$S$7,$A23,'21 Aug 2026'!$K$3:$K$7,$D23)+SUMIFS('20 Sept 2026 '!$O$3:$O$14,'20 Sept 2026 '!$S$3:$S$14,$A23,'20 Sept 2026 '!$K$3:$K$14,$D23)+SUMIFS('22 Sep 2026'!$O$3:$O$11,'22 Sep 2026'!$S$3:$S$11,$A23,'22 Sep 2026'!$K$3:$K$11,$D23) | N23: =IF(I23=0,"",IF(ROUND(L23,2)=37.5,"OK","UNDER - $"&TEXT((37.5-L23)*I23,"0.00"))) | O23: Two separate timesheets this day - matched by location
A24: 46252 | B24: Tue | C24: 46255 | D24: CBA FT Tech MEL - 12 months [ONS] | E24: 7:00 AM | F24: 4:00 PM | G24: 12:00-1:00 | H24: 8 | I24: =SUMIFS('07 Aug 2026'!$G$3:$G$6,'07 Aug 2026'!$S$3:$S$6,$A24,'07 Aug 2026'!$K$3:$K$6,$D24)+SUMIFS('21 Aug 2026'!$G$3:$G$7,'21 Aug 2026'!$S$3:$S$7,$A24,'21 Aug 2026'!$K$3:$K$7,$D24)+SUMIFS('20 Sept 2026 '!$G$3:$G$14,'20 Sept 2026 '!$S$3:$S$14,$A24,'20 Sept 2026 '!$K$3:$K$14,$D24)+SUMIFS('22 Sep 2026'!$G$3:$G$11,'22 Sep 2026'!$S$3:$S$11,$A24,'22 Sep 2026'!$K$3:$K$11,$D24) | J24: =H24-I24 | K24: =IF(SUMIFS('07 Aug 2026'!$G$3:$G$6,'07 Aug 2026'!$S$3:$S$6,$A24,'07 Aug 2026'!$K$3:$K$6,$D24)<>0,"07 Aug 2026",IF(SUMIFS('21 Aug 2026'!$G$3:$G$7,'21 Aug 2026'!$S$3:$S$7,$A24,'21 Aug 2026'!$K$3:$K$7,$D24)<>0,"21 Aug 2026",IF(SUMIFS('20 Sept 2026 '!$G$3:$G$14,'20 Sept 2026 '!$S$3:$S$14,$A24,'20 Sept 2026 '!$K$3:$K$14,$D24)<>0,"20 Sep 2026",IF(SUMIFS('22 Sep 2026'!$G$3:$G$11,'22 Sep 2026'!$S$3:$S$11,$A24,'22 Sep 2026'!$K$3:$K$11,$D24)<>0,"22 Sep 2026","NOT PAID")))) | L24: =IFERROR(M24/I24,"") | M24: =SUMIFS('07 Aug 2026'!$O$3:$O$6,'07 Aug 2026'!$S$3:$S$6,$A24,'07 Aug 2026'!$K$3:$K$6,$D24)+SUMIFS('21 Aug 2026'!$O$3:$O$7,'21 Aug 2026'!$S$3:$S$7,$A24,'21 Aug 2026'!$K$3:$K$7,$D24)+SUMIFS('20 Sept 2026 '!$O$3:$O$14,'20 Sept 2026 '!$S$3:$S$14,$A24,'20 Sept 2026 '!$K$3:$K$14,$D24)+SUMIFS('22 Sep 2026'!$O$3:$O$11,'22 Sep 2026'!$S$3:$S$11,$A24,'22 Sep 2026'!$K$3:$K$11,$D24) | N24: =IF(I24=0,"",IF(ROUND(L24,2)=37.5,"OK","UNDER - $"&TEXT((37.5-L24)*I24,"0.00"))) | O24: Paid as 5 + 3 hrs either side of break
A25: 46254 | B25: Thu | C25: 46255 | D25: PWC National Pool of Hours [ONS] | E25: 1:00 PM | F25: 5:00 PM | G25: - | H25: 4 | I25: =SUMIFS('07 Aug 2026'!$G$3:$G$6,'07 Aug 2026'!$S$3:$S$6,$A25,'07 Aug 2026'!$K$3:$K$6,$D25)+SUMIFS('21 Aug 2026'!$G$3:$G$7,'21 Aug 2026'!$S$3:$S$7,$A25,'21 Aug 2026'!$K$3:$K$7,$D25)+SUMIFS('20 Sept 2026 '!$G$3:$G$14,'20 Sept 2026 '!$S$3:$S$14,$A25,'20 Sept 2026 '!$K$3:$K$14,$D25)+SUMIFS('22 Sep 2026'!$G$3:$G$11,'22 Sep 2026'!$S$3:$S$11,$A25,'22 Sep 2026'!$K$3:$K$11,$D25) | J25: =H25-I25 | K25: =IF(SUMIFS('07 Aug 2026'!$G$3:$G$6,'07 Aug 2026'!$S$3:$S$6,$A25,'07 Aug 2026'!$K$3:$K$6,$D25)<>0,"07 Aug 2026",IF(SUMIFS('21 Aug 2026'!$G$3:$G$7,'21 Aug 2026'!$S$3:$S$7,$A25,'21 Aug 2026'!$K$3:$K$7,$D25)<>0,"21 Aug 2026",IF(SUMIFS('20 Sept 2026 '!$G$3:$G$14,'20 Sept 2026 '!$S$3:$S$14,$A25,'20 Sept 2026 '!$K$3:$K$14,$D25)<>0,"20 Sep 2026",IF(SUMIFS('22 Sep 2026'!$G$3:$G$11,'22 Sep 2026'!$S$3:$S$11,$A25,'22 Sep 2026'!$K$3:$K$11,$D25)<>0,"22 Sep 2026","NOT PAID")))) | L25: =IFERROR(M25/I25,"") | M25: =SUMIFS('07 Aug 2026'!$O$3:$O$6,'07 Aug 2026'!$S$3:$S$6,$A25,'07 Aug 2026'!$K$3:$K$6,$D25)+SUMIFS('21 Aug 2026'!$O$3:$O$7,'21 Aug 2026'!$S$3:$S$7,$A25,'21 Aug 2026'!$K$3:$K$7,$D25)+SUMIFS('20 Sept 2026 '!$O$3:$O$14,'20 Sept 2026 '!$S$3:$S$14,$A25,'20 Sept 2026 '!$K$3:$K$14,$D25)+SUMIFS('22 Sep 2026'!$O$3:$O$11,'22 Sep 2026'!$S$3:$S$11,$A25,'22 Sep 2026'!$K$3:$K$11,$D25) | N25: =IF(I25=0,"",IF(ROUND(L25,2)=37.5,"OK","UNDER - $"&TEXT((37.5-L25)*I25,"0.00")))
A26: 46258 | B26: Mon | C26: 46269 | D26: DTTL Mel Tech FT 1 [ONS] | E26: 8:30 AM | F26: 5:00 PM | G26: 12:00-12:30 | H26: 8 | I26: =SUMIFS('07 Aug 2026'!$G$3:$G$6,'07 Aug 2026'!$S$3:$S$6,$A26,'07 Aug 2026'!$K$3:$K$6,$D26)+SUMIFS('21 Aug 2026'!$G$3:$G$7,'21 Aug 2026'!$S$3:$S$7,$A26,'21 Aug 2026'!$K$3:$K$7,$D26)+SUMIFS('20 Sept 2026 '!$G$3:$G$14,'20 Sept 2026 '!$S$3:$S$14,$A26,'20 Sept 2026 '!$K$3:$K$14,$D26)+SUMIFS('22 Sep 2026'!$G$3:$G$11,'22 Sep 2026'!$S$3:$S$11,$A26,'22 Sep 2026'!$K$3:$K$11,$D26) | J26: =H26-I26 | K26: =IF(SUMIFS('07 Aug 2026'!$G$3:$G$6,'07 Aug 2026'!$S$3:$S$6,$A26,'07 Aug 2026'!$K$3:$K$6,$D26)<>0,"07 Aug 2026",IF(SUMIFS('21 Aug 2026'!$G$3:$G$7,'21 Aug 2026'!$S$3:$S$7,$A26,'21 Aug 2026'!$K$3:$K$7,$D26)<>0,"21 Aug 2026",IF(SUMIFS('20 Sept 2026 '!$G$3:$G$14,'20 Sept 2026 '!$S$3:$S$14,$A26,'20 Sept 2026 '!$K$3:$K$14,$D26)<>0,"20 Sep 2026",IF(SUMIFS('22 Sep 2026'!$G$3:$G$11,'22 Sep 2026'!$S$3:$S$11,$A26,'22 Sep 2026'!$K$3:$K$11,$D26)<>0,"22 Sep 2026","NOT PAID")))) | L26: =IFERROR(M26/I26,"") | M26: =SUMIFS('07 Aug 2026'!$O$3:$O$6,'07 Aug 2026'!$S$3:$S$6,$A26,'07 Aug 2026'!$K$3:$K$6,$D26)+SUMIFS('21 Aug 2026'!$O$3:$O$7,'21 Aug 2026'!$S$3:$S$7,$A26,'21 Aug 2026'!$K$3:$K$7,$D26)+SUMIFS('20 Sept 2026 '!$O$3:$O$14,'20 Sept 2026 '!$S$3:$S$14,$A26,'20 Sept 2026 '!$K$3:$K$14,$D26)+SUMIFS('22 Sep 2026'!$O$3:$O$11,'22 Sep 2026'!$S$3:$S$11,$A26,'22 Sep 2026'!$K$3:$K$11,$D26) | N26: =IF(I26=0,"",IF(ROUND(L26,2)=37.5,"OK","UNDER - $"&TEXT((37.5-L26)*I26,"0.00"))) | O26: QUERY - claimed missing. PAID IN FULL in the 20 Sep 2026 run as 3.5 + 4.5 hrs, $300.00 gross. See Section A.
A27: 46259 | B27: Tue | C27: 46269 | D27: PWC National Pool of Hours [ONS] | E27: 8:00 AM | F27: 5:00 PM | G27: 12:00-1:00 | H27: 8 | I27: =SUMIFS('07 Aug 2026'!$G$3:$G$6,'07 Aug 2026'!$S$3:$S$6,$A27,'07 Aug 2026'!$K$3:$K$6,$D27)+SUMIFS('21 Aug 2026'!$G$3:$G$7,'21 Aug 2026'!$S$3:$S$7,$A27,'21 Aug 2026'!$K$3:$K$7,$D27)+SUMIFS('20 Sept 2026 '!$G$3:$G$14,'20 Sept 2026 '!$S$3:$S$14,$A27,'20 Sept 2026 '!$K$3:$K$14,$D27)+SUMIFS('22 Sep 2026'!$G$3:$G$11,'22 Sep 2026'!$S$3:$S$11,$A27,'22 Sep 2026'!$K$3:$K$11,$D27) | J27: =H27-I27 | K27: =IF(SUMIFS('07 Aug 2026'!$G$3:$G$6,'07 Aug 2026'!$S$3:$S$6,$A27,'07 Aug 2026'!$K$3:$K$6,$D27)<>0,"07 Aug 2026",IF(SUMIFS('21 Aug 2026'!$G$3:$G$7,'21 Aug 2026'!$S$3:$S$7,$A27,'21 Aug 2026'!$K$3:$K$7,$D27)<>0,"21 Aug 2026",IF(SUMIFS('20 Sept 2026 '!$G$3:$G$14,'20 Sept 2026 '!$S$3:$S$14,$A27,'20 Sept 2026 '!$K$3:$K$14,$D27)<>0,"20 Sep 2026",IF(SUMIFS('22 Sep 2026'!$G$3:$G$11,'22 Sep 2026'!$S$3:$S$11,$A27,'22 Sep 2026'!$K$3:$K$11,$D27)<>0,"22 Sep 2026","NOT PAID")))) | L27: =IFERROR(M27/I27,"") | M27: =SUMIFS('07 Aug 2026'!$O$3:$O$6,'07 Aug 2026'!$S$3:$S$6,$A27,'07 Aug 2026'!$K$3:$K$6,$D27)+SUMIFS('21 Aug 2026'!$O$3:$O$7,'21 Aug 2026'!$S$3:$S$7,$A27,'21 Aug 2026'!$K$3:$K$7,$D27)+SUMIFS('20 Sept 2026 '!$O$3:$O$14,'20 Sept 2026 '!$S$3:$S$14,$A27,'20 Sept 2026 '!$K$3:$K$14,$D27)+SUMIFS('22 Sep 2026'!$O$3:$O$11,'22 Sep 2026'!$S$3:$S$11,$A27,'22 Sep 2026'!$K$3:$K$11,$D27) | N27: =IF(I27=0,"",IF(ROUND(L27,2)=37.5,"OK","UNDER - $"&TEXT((37.5-L27)*I27,"0.00"))) | O27: Paid as 4 + 4 hrs
A28: 46260 | B28: Wed | C28: 46269 | D28: PWC National Pool of Hours [ONS] | E28: 8:00 AM | F28: 4:00 PM | G28: 12:00-12:30 | H28: 7.5 | I28: =SUMIFS('07 Aug 2026'!$G$3:$G$6,'07 Aug 2026'!$S$3:$S$6,$A28,'07 Aug 2026'!$K$3:$K$6,$D28)+SUMIFS('21 Aug 2026'!$G$3:$G$7,'21 Aug 2026'!$S$3:$S$7,$A28,'21 Aug 2026'!$K$3:$K$7,$D28)+SUMIFS('20 Sept 2026 '!$G$3:$G$14,'20 Sept 2026 '!$S$3:$S$14,$A28,'20 Sept 2026 '!$K$3:$K$14,$D28)+SUMIFS('22 Sep 2026'!$G$3:$G$11,'22 Sep 2026'!$S$3:$S$11,$A28,'22 Sep 2026'!$K$3:$K$11,$D28) | J28: =H28-I28 | K28: =IF(SUMIFS('07 Aug 2026'!$G$3:$G$6,'07 Aug 2026'!$S$3:$S$6,$A28,'07 Aug 2026'!$K$3:$K$6,$D28)<>0,"07 Aug 2026",IF(SUMIFS('21 Aug 2026'!$G$3:$G$7,'21 Aug 2026'!$S$3:$S$7,$A28,'21 Aug 2026'!$K$3:$K$7,$D28)<>0,"21 Aug 2026",IF(SUMIFS('20 Sept 2026 '!$G$3:$G$14,'20 Sept 2026 '!$S$3:$S$14,$A28,'20 Sept 2026 '!$K$3:$K$14,$D28)<>0,"20 Sep 2026",IF(SUMIFS('22 Sep 2026'!$G$3:$G$11,'22 Sep 2026'!$S$3:$S$11,$A28,'22 Sep 2026'!$K$3:$K$11,$D28)<>0,"22 Sep 2026","NOT PAID")))) | L28: =IFERROR(M28/I28,"") | M28: =SUMIFS('07 Aug 2026'!$O$3:$O$6,'07 Aug 2026'!$S$3:$S$6,$A28,'07 Aug 2026'!$K$3:$K$6,$D28)+SUMIFS('21 Aug 2026'!$O$3:$O$7,'21 Aug 2026'!$S$3:$S$7,$A28,'21 Aug 2026'!$K$3:$K$7,$D28)+SUMIFS('20 Sept 2026 '!$O$3:$O$14,'20 Sept 2026 '!$S$3:$S$14,$A28,'20 Sept 2026 '!$K$3:$K$14,$D28)+SUMIFS('22 Sep 2026'!$O$3:$O$11,'22 Sep 2026'!$S$3:$S$11,$A28,'22 Sep 2026'!$K$3:$K$11,$D28) | N28: =IF(I28=0,"",IF(ROUND(L28,2)=37.5,"OK","UNDER - $"&TEXT((37.5-L28)*I28,"0.00"))) | O28: Paid as 4 + 3.5 hrs
A29: 46261 | B29: Thu | C29: 46269 | D29: PWC National Pool of Hours [ONS] | E29: 8:00 AM | F29: 5:00 PM | G29: 12:00-1:00 | H29: 8 | I29: =SUMIFS('07 Aug 2026'!$G$3:$G$6,'07 Aug 2026'!$S$3:$S$6,$A29,'07 Aug 2026'!$K$3:$K$6,$D29)+SUMIFS('21 Aug 2026'!$G$3:$G$7,'21 Aug 2026'!$S$3:$S$7,$A29,'21 Aug 2026'!$K$3:$K$7,$D29)+SUMIFS('20 Sept 2026 '!$G$3:$G$14,'20 Sept 2026 '!$S$3:$S$14,$A29,'20 Sept 2026 '!$K$3:$K$14,$D29)+SUMIFS('22 Sep 2026'!$G$3:$G$11,'22 Sep 2026'!$S$3:$S$11,$A29,'22 Sep 2026'!$K$3:$K$11,$D29) | J29: =H29-I29 | K29: =IF(SUMIFS('07 Aug 2026'!$G$3:$G$6,'07 Aug 2026'!$S$3:$S$6,$A29,'07 Aug 2026'!$K$3:$K$6,$D29)<>0,"07 Aug 2026",IF(SUMIFS('21 Aug 2026'!$G$3:$G$7,'21 Aug 2026'!$S$3:$S$7,$A29,'21 Aug 2026'!$K$3:$K$7,$D29)<>0,"21 Aug 2026",IF(SUMIFS('20 Sept 2026 '!$G$3:$G$14,'20 Sept 2026 '!$S$3:$S$14,$A29,'20 Sept 2026 '!$K$3:$K$14,$D29)<>0,"20 Sep 2026",IF(SUMIFS('22 Sep 2026'!$G$3:$G$11,'22 Sep 2026'!$S$3:$S$11,$A29,'22 Sep 2026'!$K$3:$K$11,$D29)<>0,"22 Sep 2026","NOT PAID")))) | L29: =IFERROR(M29/I29,"") | M29: =SUMIFS('07 Aug 2026'!$O$3:$O$6,'07 Aug 2026'!$S$3:$S$6,$A29,'07 Aug 2026'!$K$3:$K$6,$D29)+SUMIFS('21 Aug 2026'!$O$3:$O$7,'21 Aug 2026'!$S$3:$S$7,$A29,'21 Aug 2026'!$K$3:$K$7,$D29)+SUMIFS('20 Sept 2026 '!$O$3:$O$14,'20 Sept 2026 '!$S$3:$S$14,$A29,'20 Sept 2026 '!$K$3:$K$14,$D29)+SUMIFS('22 Sep 2026'!$O$3:$O$11,'22 Sep 2026'!$S$3:$S$11,$A29,'22 Sep 2026'!$K$3:$K$11,$D29) | N29: =IF(I29=0,"",IF(ROUND(L29,2)=37.5,"OK","UNDER - $"&TEXT((37.5-L29)*I29,"0.00"))) | O29: Paid as 4 + 4 hrs
A30: 46262 | B30: Fri | C30: 46269 | D30: DTTL Mel Tech FT 1 [ONS] | E30: 8:30 AM | F30: 5:00 PM | G30: 12:00-12:30 | H30: 8 | I30: =SUMIFS('07 Aug 2026'!$G$3:$G$6,'07 Aug 2026'!$S$3:$S$6,$A30,'07 Aug 2026'!$K$3:$K$6,$D30)+SUMIFS('21 Aug 2026'!$G$3:$G$7,'21 Aug 2026'!$S$3:$S$7,$A30,'21 Aug 2026'!$K$3:$K$7,$D30)+SUMIFS('20 Sept 2026 '!$G$3:$G$14,'20 Sept 2026 '!$S$3:$S$14,$A30,'20 Sept 2026 '!$K$3:$K$14,$D30)+SUMIFS('22 Sep 2026'!$G$3:$G$11,'22 Sep 2026'!$S$3:$S$11,$A30,'22 Sep 2026'!$K$3:$K$11,$D30) | J30: =H30-I30 | K30: =IF(SUMIFS('07 Aug 2026'!$G$3:$G$6,'07 Aug 2026'!$S$3:$S$6,$A30,'07 Aug 2026'!$K$3:$K$6,$D30)<>0,"07 Aug 2026",IF(SUMIFS('21 Aug 2026'!$G$3:$G$7,'21 Aug 2026'!$S$3:$S$7,$A30,'21 Aug 2026'!$K$3:$K$7,$D30)<>0,"21 Aug 2026",IF(SUMIFS('20 Sept 2026 '!$G$3:$G$14,'20 Sept 2026 '!$S$3:$S$14,$A30,'20 Sept 2026 '!$K$3:$K$14,$D30)<>0,"20 Sep 2026",IF(SUMIFS('22 Sep 2026'!$G$3:$G$11,'22 Sep 2026'!$S$3:$S$11,$A30,'22 Sep 2026'!$K$3:$K$11,$D30)<>0,"22 Sep 2026","NOT PAID")))) | L30: =IFERROR(M30/I30,"") | M30: =SUMIFS('07 Aug 2026'!$O$3:$O$6,'07 Aug 2026'!$S$3:$S$6,$A30,'07 Aug 2026'!$K$3:$K$6,$D30)+SUMIFS('21 Aug 2026'!$O$3:$O$7,'21 Aug 2026'!$S$3:$S$7,$A30,'21 Aug 2026'!$K$3:$K$7,$D30)+SUMIFS('20 Sept 2026 '!$O$3:$O$14,'20 Sept 2026 '!$S$3:$S$14,$A30,'20 Sept 2026 '!$K$3:$K$14,$D30)+SUMIFS('22 Sep 2026'!$O$3:$O$11,'22 Sep 2026'!$S$3:$S$11,$A30,'22 Sep 2026'!$K$3:$K$11,$D30) | N30: =IF(I30=0,"",IF(ROUND(L30,2)=37.5,"OK","UNDER - $"&TEXT((37.5-L30)*I30,"0.00"))) | O30: QUERY - claimed missing. PAID IN FULL in the 20 Sep 2026 run as 3.5 + 4.5 hrs, $300.00 gross. See Section A.
A31: 46265 | B31: Mon | C31: 46269 | D31: DTTL Mel Tech FT 1 [ONS] | E31: 8:30 AM | F31: 5:00 PM | G31: 12:00-12:30 | H31: 8 | I31: =SUMIFS('07 Aug 2026'!$G$3:$G$6,'07 Aug 2026'!$S$3:$S$6,$A31,'07 Aug 2026'!$K$3:$K$6,$D31)+SUMIFS('21 Aug 2026'!$G$3:$G$7,'21 Aug 2026'!$S$3:$S$7,$A31,'21 Aug 2026'!$K$3:$K$7,$D31)+SUMIFS('20 Sept 2026 '!$G$3:$G$14,'20 Sept 2026 '!$S$3:$S$14,$A31,'20 Sept 2026 '!$K$3:$K$14,$D31)+SUMIFS('22 Sep 2026'!$G$3:$G$11,'22 Sep 2026'!$S$3:$S$11,$A31,'22 Sep 2026'!$K$3:$K$11,$D31) | J31: =H31-I31 | K31: =IF(SUMIFS('07 Aug 2026'!$G$3:$G$6,'07 Aug 2026'!$S$3:$S$6,$A31,'07 Aug 2026'!$K$3:$K$6,$D31)<>0,"07 Aug 2026",IF(SUMIFS('21 Aug 2026'!$G$3:$G$7,'21 Aug 2026'!$S$3:$S$7,$A31,'21 Aug 2026'!$K$3:$K$7,$D31)<>0,"21 Aug 2026",IF(SUMIFS('20 Sept 2026 '!$G$3:$G$14,'20 Sept 2026 '!$S$3:$S$14,$A31,'20 Sept 2026 '!$K$3:$K$14,$D31)<>0,"20 Sep 2026",IF(SUMIFS('22 Sep 2026'!$G$3:$G$11,'22 Sep 2026'!$S$3:$S$11,$A31,'22 Sep 2026'!$K$3:$K$11,$D31)<>0,"22 Sep 2026","NOT PAID")))) | L31: =IFERROR(M31/I31,"") | M31: =SUMIFS('07 Aug 2026'!$O$3:$O$6,'07 Aug 2026'!$S$3:$S$6,$A31,'07 Aug 2026'!$K$3:$K$6,$D31)+SUMIFS('21 Aug 2026'!$O$3:$O$7,'21 Aug 2026'!$S$3:$S$7,$A31,'21 Aug 2026'!$K$3:$K$7,$D31)+SUMIFS('20 Sept 2026 '!$O$3:$O$14,'20 Sept 2026 '!$S$3:$S$14,$A31,'20 Sept 2026 '!$K$3:$K$14,$D31)+SUMIFS('22 Sep 2026'!$O$3:$O$11,'22 Sep 2026'!$S$3:$S$11,$A31,'22 Sep 2026'!$K$3:$K$11,$D31) | N31: =IF(I31=0,"",IF(ROUND(L31,2)=37.5,"OK","UNDER - $"&TEXT((37.5-L31)*I31,"0.00"))) | O31: Paid as 3.5 + 4.5 hrs
A32: 46266 | B32: Tue | C32: 46269 | D32: DTTL Mel Tech FT 1 [ONS] | E32: 9:00 AM | F32: 5:30 PM | G32: 12:00-12:30 | H32: 8 | I32: =SUMIFS('07 Aug 2026'!$G$3:$G$6,'07 Aug 2026'!$S$3:$S$6,$A32,'07 Aug 2026'!$K$3:$K$6,$D32)+SUMIFS('21 Aug 2026'!$G$3:$G$7,'21 Aug 2026'!$S$3:$S$7,$A32,'21 Aug 2026'!$K$3:$K$7,$D32)+SUMIFS('20 Sept 2026 '!$G$3:$G$14,'20 Sept 2026 '!$S$3:$S$14,$A32,'20 Sept 2026 '!$K$3:$K$14,$D32)+SUMIFS('22 Sep 2026'!$G$3:$G$11,'22 Sep 2026'!$S$3:$S$11,$A32,'22 Sep 2026'!$K$3:$K$11,$D32) | J32: =H32-I32 | K32: =IF(SUMIFS('07 Aug 2026'!$G$3:$G$6,'07 Aug 2026'!$S$3:$S$6,$A32,'07 Aug 2026'!$K$3:$K$6,$D32)<>0,"07 Aug 2026",IF(SUMIFS('21 Aug 2026'!$G$3:$G$7,'21 Aug 2026'!$S$3:$S$7,$A32,'21 Aug 2026'!$K$3:$K$7,$D32)<>0,"21 Aug 2026",IF(SUMIFS('20 Sept 2026 '!$G$3:$G$14,'20 Sept 2026 '!$S$3:$S$14,$A32,'20 Sept 2026 '!$K$3:$K$14,$D32)<>0,"20 Sep 2026",IF(SUMIFS('22 Sep 2026'!$G$3:$G$11,'22 Sep 2026'!$S$3:$S$11,$A32,'22 Sep 2026'!$K$3:$K$11,$D32)<>0,"22 Sep 2026","NOT PAID")))) | L32: =IFERROR(M32/I32,"") | M32: =SUMIFS('07 Aug 2026'!$O$3:$O$6,'07 Aug 2026'!$S$3:$S$6,$A32,'07 Aug 2026'!$K$3:$K$6,$D32)+SUMIFS('21 Aug 2026'!$O$3:$O$7,'21 Aug 2026'!$S$3:$S$7,$A32,'21 Aug 2026'!$K$3:$K$7,$D32)+SUMIFS('20 Sept 2026 '!$O$3:$O$14,'20 Sept 2026 '!$S$3:$S$14,$A32,'20 Sept 2026 '!$K$3:$K$14,$D32)+SUMIFS('22 Sep 2026'!$O$3:$O$11,'22 Sep 2026'!$S$3:$S$11,$A32,'22 Sep 2026'!$K$3:$K$11,$D32) | N32: =IF(I32=0,"",IF(ROUND(L32,2)=37.5,"OK","UNDER - $"&TEXT((37.5-L32)*I32,"0.00"))) | O32: Paid as 3 + 5 hrs
A33: 46267 | B33: Wed | C33: 46269 | D33: DTTL Mel Tech FT 1 [ONS] | E33: 9:00 AM | F33: 5:30 PM | G33: 12:00-12:30 | H33: 8 | I33: =SUMIFS('07 Aug 2026'!$G$3:$G$6,'07 Aug 2026'!$S$3:$S$6,$A33,'07 Aug 2026'!$K$3:$K$6,$D33)+SUMIFS('21 Aug 2026'!$G$3:$G$7,'21 Aug 2026'!$S$3:$S$7,$A33,'21 Aug 2026'!$K$3:$K$7,$D33)+SUMIFS('20 Sept 2026 '!$G$3:$G$14,'20 Sept 2026 '!$S$3:$S$14,$A33,'20 Sept 2026 '!$K$3:$K$14,$D33)+SUMIFS('22 Sep 2026'!$G$3:$G$11,'22 Sep 2026'!$S$3:$S$11,$A33,'22 Sep 2026'!$K$3:$K$11,$D33) | J33: =H33-I33 | K33: =IF(SUMIFS('07 Aug 2026'!$G$3:$G$6,'07 Aug 2026'!$S$3:$S$6,$A33,'07 Aug 2026'!$K$3:$K$6,$D33)<>0,"07 Aug 2026",IF(SUMIFS('21 Aug 2026'!$G$3:$G$7,'21 Aug 2026'!$S$3:$S$7,$A33,'21 Aug 2026'!$K$3:$K$7,$D33)<>0,"21 Aug 2026",IF(SUMIFS('20 Sept 2026 '!$G$3:$G$14,'20 Sept 2026 '!$S$3:$S$14,$A33,'20 Sept 2026 '!$K$3:$K$14,$D33)<>0,"20 Sep 2026",IF(SUMIFS('22 Sep 2026'!$G$3:$G$11,'22 Sep 2026'!$S$3:$S$11,$A33,'22 Sep 2026'!$K$3:$K$11,$D33)<>0,"22 Sep 2026","NOT PAID")))) | L33: =IFERROR(M33/I33,"") | M33: =SUMIFS('07 Aug 2026'!$O$3:$O$6,'07 Aug 2026'!$S$3:$S$6,$A33,'07 Aug 2026'!$K$3:$K$6,$D33)+SUMIFS('21 Aug 2026'!$O$3:$O$7,'21 Aug 2026'!$S$3:$S$7,$A33,'21 Aug 2026'!$K$3:$K$7,$D33)+SUMIFS('20 Sept 2026 '!$O$3:$O$14,'20 Sept 2026 '!$S$3:$S$14,$A33,'20 Sept 2026 '!$K$3:$K$14,$D33)+SUMIFS('22 Sep 2026'!$O$3:$O$11,'22 Sep 2026'!$S$3:$S$11,$A33,'22 Sep 2026'!$K$3:$K$11,$D33) | N33: =IF(I33=0,"",IF(ROUND(L33,2)=37.5,"OK","UNDER - $"&TEXT((37.5-L33)*I33,"0.00"))) | O33: Paid as 3 + 5 hrs
A34: 46269 | B34: Fri | C34: 46269 | D34: DTTL Mel Tech FT 1 [ONS] | E34: 8:30 AM | F34: 5:00 PM | G34: 12:00-12:30 | H34: 8 | I34: =SUMIFS('07 Aug 2026'!$G$3:$G$6,'07 Aug 2026'!$S$3:$S$6,$A34,'07 Aug 2026'!$K$3:$K$6,$D34)+SUMIFS('21 Aug 2026'!$G$3:$G$7,'21 Aug 2026'!$S$3:$S$7,$A34,'21 Aug 2026'!$K$3:$K$7,$D34)+SUMIFS('20 Sept 2026 '!$G$3:$G$14,'20 Sept 2026 '!$S$3:$S$14,$A34,'20 Sept 2026 '!$K$3:$K$14,$D34)+SUMIFS('22 Sep 2026'!$G$3:$G$11,'22 Sep 2026'!$S$3:$S$11,$A34,'22 Sep 2026'!$K$3:$K$11,$D34) | J34: =H34-I34 | K34: =IF(SUMIFS('07 Aug 2026'!$G$3:$G$6,'07 Aug 2026'!$S$3:$S$6,$A34,'07 Aug 2026'!$K$3:$K$6,$D34)<>0,"07 Aug 2026",IF(SUMIFS('21 Aug 2026'!$G$3:$G$7,'21 Aug 2026'!$S$3:$S$7,$A34,'21 Aug 2026'!$K$3:$K$7,$D34)<>0,"21 Aug 2026",IF(SUMIFS('20 Sept 2026 '!$G$3:$G$14,'20 Sept 2026 '!$S$3:$S$14,$A34,'20 Sept 2026 '!$K$3:$K$14,$D34)<>0,"20 Sep 2026",IF(SUMIFS('22 Sep 2026'!$G$3:$G$11,'22 Sep 2026'!$S$3:$S$11,$A34,'22 Sep 2026'!$K$3:$K$11,$D34)<>0,"22 Sep 2026","NOT PAID")))) | L34: =IFERROR(M34/I34,"") | M34: =SUMIFS('07 Aug 2026'!$O$3:$O$6,'07 Aug 2026'!$S$3:$S$6,$A34,'07 Aug 2026'!$K$3:$K$6,$D34)+SUMIFS('21 Aug 2026'!$O$3:$O$7,'21 Aug 2026'!$S$3:$S$7,$A34,'21 Aug 2026'!$K$3:$K$7,$D34)+SUMIFS('20 Sept 2026 '!$O$3:$O$14,'20 Sept 2026 '!$S$3:$S$14,$A34,'20 Sept 2026 '!$K$3:$K$14,$D34)+SUMIFS('22 Sep 2026'!$O$3:$O$11,'22 Sep 2026'!$S$3:$S$11,$A34,'22 Sep 2026'!$K$3:$K$11,$D34) | N34: =IF(I34=0,"",IF(ROUND(L34,2)=37.5,"OK","UNDER - $"&TEXT((37.5-L34)*I34,"0.00"))) | O34: Paid as 3.5 + 4.5 hrs
A35: 46275 | B35: Thu | C35: 46283 | D35: PWC National Pool of Hours [ONS] | E35: 8:00 AM | F35: 5:00 PM | G35: 12:00-1:00 | H35: 8 | I35: =SUMIFS('07 Aug 2026'!$G$3:$G$6,'07 Aug 2026'!$S$3:$S$6,$A35,'07 Aug 2026'!$K$3:$K$6,$D35)+SUMIFS('21 Aug 2026'!$G$3:$G$7,'21 Aug 2026'!$S$3:$S$7,$A35,'21 Aug 2026'!$K$3:$K$7,$D35)+SUMIFS('20 Sept 2026 '!$G$3:$G$14,'20 Sept 2026 '!$S$3:$S$14,$A35,'20 Sept 2026 '!$K$3:$K$14,$D35)+SUMIFS('22 Sep 2026'!$G$3:$G$11,'22 Sep 2026'!$S$3:$S$11,$A35,'22 Sep 2026'!$K$3:$K$11,$D35) | J35: =H35-I35 | K35: =IF(SUMIFS('07 Aug 2026'!$G$3:$G$6,'07 Aug 2026'!$S$3:$S$6,$A35,'07 Aug 2026'!$K$3:$K$6,$D35)<>0,"07 Aug 2026",IF(SUMIFS('21 Aug 2026'!$G$3:$G$7,'21 Aug 2026'!$S$3:$S$7,$A35,'21 Aug 2026'!$K$3:$K$7,$D35)<>0,"21 Aug 2026",IF(SUMIFS('20 Sept 2026 '!$G$3:$G$14,'20 Sept 2026 '!$S$3:$S$14,$A35,'20 Sept 2026 '!$K$3:$K$14,$D35)<>0,"20 Sep 2026",IF(SUMIFS('22 Sep 2026'!$G$3:$G$11,'22 Sep 2026'!$S$3:$S$11,$A35,'22 Sep 2026'!$K$3:$K$11,$D35)<>0,"22 Sep 2026","NOT PAID")))) | L35: =IFERROR(M35/I35,"") | M35: =SUMIFS('07 Aug 2026'!$O$3:$O$6,'07 Aug 2026'!$S$3:$S$6,$A35,'07 Aug 2026'!$K$3:$K$6,$D35)+SUMIFS('21 Aug 2026'!$O$3:$O$7,'21 Aug 2026'!$S$3:$S$7,$A35,'21 Aug 2026'!$K$3:$K$7,$D35)+SUMIFS('20 Sept 2026 '!$O$3:$O$14,'20 Sept 2026 '!$S$3:$S$14,$A35,'20 Sept 2026 '!$K$3:$K$14,$D35)+SUMIFS('22 Sep 2026'!$O$3:$O$11,'22 Sep 2026'!$S$3:$S$11,$A35,'22 Sep 2026'!$K$3:$K$11,$D35) | N35: =IF(I35=0,"",IF(ROUND(L35,2)=37.5,"OK","UNDER - $"&TEXT((37.5-L35)*I35,"0.00"))) | O35: Paid as 4 + 4 hrs
A36: 46282 | B36: Thu | C36: 46283 | D36: Aware Super AV Maintenance [ONS] | E36: 11:30 AM | F36: 3:30 PM | G36: - | H36: 4 | I36: =SUMIFS('07 Aug 2026'!$G$3:$G$6,'07 Aug 2026'!$S$3:$S$6,$A36,'07 Aug 2026'!$K$3:$K$6,$D36)+SUMIFS('21 Aug 2026'!$G$3:$G$7,'21 Aug 2026'!$S$3:$S$7,$A36,'21 Aug 2026'!$K$3:$K$7,$D36)+SUMIFS('20 Sept 2026 '!$G$3:$G$14,'20 Sept 2026 '!$S$3:$S$14,$A36,'20 Sept 2026 '!$K$3:$K$14,$D36)+SUMIFS('22 Sep 2026'!$G$3:$G$11,'22 Sep 2026'!$S$3:$S$11,$A36,'22 Sep 2026'!$K$3:$K$11,$D36) | J36: =H36-I36 | K36: =IF(SUMIFS('07 Aug 2026'!$G$3:$G$6,'07 Aug 2026'!$S$3:$S$6,$A36,'07 Aug 2026'!$K$3:$K$6,$D36)<>0,"07 Aug 2026",IF(SUMIFS('21 Aug 2026'!$G$3:$G$7,'21 Aug 2026'!$S$3:$S$7,$A36,'21 Aug 2026'!$K$3:$K$7,$D36)<>0,"21 Aug 2026",IF(SUMIFS('20 Sept 2026 '!$G$3:$G$14,'20 Sept 2026 '!$S$3:$S$14,$A36,'20 Sept 2026 '!$K$3:$K$14,$D36)<>0,"20 Sep 2026",IF(SUMIFS('22 Sep 2026'!$G$3:$G$11,'22 Sep 2026'!$S$3:$S$11,$A36,'22 Sep 2026'!$K$3:$K$11,$D36)<>0,"22 Sep 2026","NOT PAID")))) | L36: =IFERROR(M36/I36,"") | M36: =SUMIFS('07 Aug 2026'!$O$3:$O$6,'07 Aug 2026'!$S$3:$S$6,$A36,'07 Aug 2026'!$K$3:$K$6,$D36)+SUMIFS('21 Aug 2026'!$O$3:$O$7,'21 Aug 2026'!$S$3:$S$7,$A36,'21 Aug 2026'!$K$3:$K$7,$D36)+SUMIFS('20 Sept 2026 '!$O$3:$O$14,'20 Sept 2026 '!$S$3:$S$14,$A36,'20 Sept 2026 '!$K$3:$K$14,$D36)+SUMIFS('22 Sep 2026'!$O$3:$O$11,'22 Sep 2026'!$S$3:$S$11,$A36,'22 Sep 2026'!$K$3:$K$11,$D36) | N36: =IF(I36=0,"",IF(ROUND(L36,2)=37.5,"OK","UNDER - $"&TEXT((37.5-L36)*I36,"0.00")))
A37: TOTAL | H37: =SUM(H21:H36) | I37: =SUM(I21:I36) | J37: =SUM(J21:J36) | M37: =SUM(M21:M36) | N37: =IF(ROUND(J37,2)=0,"HOURS AGREE","VARIANCE")
A39: D. PAY RATE ERROR AND CORRECTION - fortnight ending 07/08/2026
A40: Item | B40: Pay Run | C40: Hours | D40: Rate $/hr | E40: Gross $ | F40: Comment
A41: Paid at incorrect rate | B41: 07 Aug 2026 | C41: ='07 Aug 2026'!G3+'07 Aug 2026'!G4+'07 Aug 2026'!G5+'07 Aug 2026'!G6 | D41: 35.15 | E41: =SUM('07 Aug 2026'!O3:O6) | F41: Original payment - rate used was $35.15/hr
A42: Should have been paid | B42: 07 Aug 2026 | C42: =C41 | D42: 37.5 | E42: =C42*D42 | F42: Correct casual ordinary rate is $37.50/hr
A43: Underpayment | E43: =E42-E41 | F43: Shortfall on the first fortnight
A44: Reversal of incorrect rate | B44: 21 Aug 2026 | C44: ='21 Aug 2026'!G3 | D44: ='21 Aug 2026'!M3 | E44: ='21 Aug 2026'!O3 | F44: Payroll reversed the full 16 hrs at $35.15
...

Sheet 22 Sep 2026
A1: Earnings Details
A2: Employee Id | B2: Employee External Id | C2: Employee Name | D2: Pay Category Id | E2: Pay Category External Id | F2: Pay Category Name | G2: Units | H2: Unit Type | I2: Location Id | J2: Location External Id | K2: Location Name | L2: Notes | M2: Rate | N2: Rate Type | O2: Gross Earnings | P2: Taxable Earnings | Q2: SG Super | S2: Work Date (helper) | T2: Matched to Timesheet?
A3: 12414219 | C3: Jonathan Hendratno | D3: 2856297 | E3: 2286634 | F3: Casual Ordinary Hours | G3: 4 | H3: Hours | I3: 731888 | J3: 20250731 | K3: PWC National Pool of Hours [ONS] | L3: 25/08/2026 - 08:00 to 12:00 | M3: 37.5 | N3: per Hour | O3: 150 | P3: 150 | Q3: 18 | S3: =IFERROR(DATE(VALUE(MID(L3,FIND("/",L3,FIND("/",L3)+1)+1,4)),VALUE(MID(L3,FIND("/",L3)+1,FIND("/",L3,FIND("/",L3)+1)-FIND("/",L3)-1)),VALUE(LEFT(L3,FIND("/",L3)-1))),IF(ISNUMBER(L3),L3,"")) | T3: =IF(S3="","No - adjustment/reversal (no work date)",IF(COUNTIFS('Summary '!$A$21:$A$36,S3,'Summary '!$D$21:$D$36,K3)>0,"Yes","NO MATCH - INVESTIGATE"))
A4: 12414219 | C4: Jonathan Hendratno | D4: 2856297 | E4: 2286634 | F4: Casual Ordinary Hours | G4: 4 | H4: Hours | I4: 731888 | J4: 20250731 | K4: PWC National Pool of Hours [ONS] | L4: 25/08/2026 - 13:00 to 17:00 | M4: 37.5 | N4: per Hour | O4: 150 | P4: 150 | Q4: 18 | S4: =IFERROR(DATE(VALUE(MID(L4,FIND("/",L4,FIND("/",L4)+1)+1,4)),VALUE(MID(L4,FIND("/",L4)+1,FIND("/",L4,FIND("/",L4)+1)-FIND("/",L4)-1)),VALUE(LEFT(L4,FIND("/",L4)-1))),IF(ISNUMBER(L4),L4,"")) | T4: =IF(S4="","No - adjustment/reversal (no work date)",IF(COUNTIFS('Summary '!$A$21:$A$36,S4,'Summary '!$D$21:$D$36,K4)>0,"Yes","NO MATCH - INVESTIGATE"))
A5: 12414219 | C5: Jonathan Hendratno | D5: 2856297 | E5: 2286634 | F5: Casual Ordinary Hours | G5: 4 | H5: Hours | I5: 731888 | J5: 20250731 | K5: PWC National Pool of Hours [ONS] | L5: 26/08/2026 - 08:00 to 12:00 | M5: 37.5 | N5: per Hour | O5: 150 | P5: 150 | Q5: 18 | S5: =IFERROR(DATE(VALUE(MID(L5,FIND("/",L5,FIND("/",L5)+1)+1,4)),VALUE(MID(L5,FIND("/",L5)+1,FIND("/",L5,FIND("/",L5)+1)-FIND("/",L5)-1)),VALUE(LEFT(L5,FIND("/",L5)-1))),IF(ISNUMBER(L5),L5,"")) | T5: =IF(S5="","No - adjustment/reversal (no work date)",IF(COUNTIFS('Summary '!$A$21:$A$36,S5,'Summary '!$D$21:$D$36,K5)>0,"Yes","NO MATCH - INVESTIGATE"))
A6: 12414219 | C6: Jonathan Hendratno | D6: 2856297 | E6: 2286634 | F6: Casual Ordinary Hours | G6: 3.5 | H6: Hours | I6: 731888 | J6: 20250731 | K6: PWC National Pool of Hours [ONS] | L6: 26/08/2026 - 12:30 to 16:00 | M6: 37.5 | N6: per Hour | O6: 131.25 | P6: 131.25 | Q6: 15.75 | S6: =IFERROR(DATE(VALUE(MID(L6,FIND("/",L6,FIND("/",L6)+1)+1,4)),VALUE(MID(L6,FIND("/",L6)+1,FIND("/",L6,FIND("/",L6)+1)-FIND("/",L6)-1)),VALUE(LEFT(L6,FIND("/",L6)-1))),IF(ISNUMBER(L6),L6,"")) | T6: =IF(S6="","No - adjustment/reversal (no work date)",IF(COUNTIFS('Summary '!$A$21:$A$36,S6,'Summary '!$D$21:$D$36,K6)>0,"Yes","NO MATCH - INVESTIGATE"))
A7: 12414219 | C7: Jonathan Hendratno | D7: 2856297 | E7: 2286634 | F7: Casual Ordinary Hours | G7: 4 | H7: Hours | I7: 731888 | J7: 20250731 | K7: PWC National Pool of Hours [ONS] | L7: 27/08/2026 - 08:00 to 12:00 | M7: 37.5 | N7: per Hour | O7: 150 | P7: 150 | Q7: 18 | S7: =IFERROR(DATE(VALUE(MID(L7,FIND("/",L7,FIND("/",L7)+1)+1,4)),VALUE(MID(L7,FIND("/",L7)+1,FIND("/",L7,FIND("/",L7)+1)-FIND("/",L7)-1)),VALUE(LEFT(L7,FIND("/",L7)-1))),IF(ISNUMBER(L7),L7,"")) | T7: =IF(S7="","No - adjustment/reversal (no work date)",IF(COUNTIFS('Summary '!$A$21:$A$36,S7,'Summary '!$D$21:$D$36,K7)>0,"Yes","NO MATCH - INVESTIGATE"))
A8: 12414219 | C8: Jonathan Hendratno | D8: 2856297 | E8: 2286634 | F8: Casual Ordinary Hours | G8: 4 | H8: Hours | I8: 731888 | J8: 20250731 | K8: PWC National Pool of Hours [ONS] | L8: 27/08/2026 - 13:00 to 17:00 | M8: 37.5 | N8: per Hour | O8: 150 | P8: 150 | Q8: 18 | S8: =IFERROR(DATE(VALUE(MID(L8,FIND("/",L8,FIND("/",L8)+1)+1,4)),VALUE(MID(L8,FIND("/",L8)+1,FIND("/",L8,FIND("/",L8)+1)-FIND("/",L8)-1)),VALUE(LEFT(L8,FIND("/",L8)-1))),IF(ISNUMBER(L8),L8,"")) | T8: =IF(S8="","No - adjustment/reversal (no work date)",IF(COUNTIFS('Summary '!$A$21:$A$36,S8,'Summary '!$D$21:$D$36,K8)>0,"Yes","NO MATCH - INVESTIGATE"))
A9: 12414219 | C9: Jonathan Hendratno | D9: 2856297 | E9: 2286634 | F9: Casual Ordinary Hours | G9: 4 | H9: Hours | I9: 731888 | J9: 20250731 | K9: PWC National Pool of Hours [ONS] | L9: 10/09/2026 - 08:00 to 12:00 | M9: 37.5 | N9: per Hour | O9: 150 | P9: 150 | Q9: 18 | S9: =IFERROR(DATE(VALUE(MID(L9,FIND("/",L9,FIND("/",L9)+1)+1,4)),VALUE(MID(L9,FIND("/",L9)+1,FIND("/",L9,FIND("/",L9)+1)-FIND("/",L9)-1)),VALUE(LEFT(L9,FIND("/",L9)-1))),IF(ISNUMBER(L9),L9,"")) | T9: =IF(S9="","No - adjustment/reversal (no work date)",IF(COUNTIFS('Summary '!$A$21:$A$36,S9,'Summary '!$D$21:$D$36,K9)>0,"Yes","NO MATCH - INVESTIGATE"))
A10: 12414219 | C10: Jonathan Hendratno | D10: 2856297 | E10: 2286634 | F10: Casual Ordinary Hours | G10: 4 | H10: Hours | I10: 731888 | J10: 20250731 | K10: PWC National Pool of Hours [ONS] | L10: 10/09/2026 - 13:00 to 17:00 | M10: 37.5 | N10: per Hour | O10: 150 | P10: 150 | Q10: 18 | S10: =IFERROR(DATE(VALUE(MID(L10,FIND("/",L10,FIND("/",L10)+1)+1,4)),VALUE(MID(L10,FIND("/",L10)+1,FIND("/",L10,FIND("/",L10)+1)-FIND("/",L10)-1)),VALUE(LEFT(L10,FIND("/",L10)-1))),IF(ISNUMBER(L10),L10,"")) | T10: =IF(S10="","No - adjustment/reversal (no work date)",IF(COUNTIFS('Summary '!$A$21:$A$36,S10,'Summary '!$D$21:$D$36,K10)>0,"Yes","NO MATCH - INVESTIGATE"))
A11: 12414219 | C11: Jonathan Hendratno | D11: 2856297 | E11: 2286634 | F11: Casual Ordinary Hours | G11: 4 | H11: Hours | I11: 777409 | J11: 26022301 | K11: Aware Super AV Maintenance [ONS] | L11: 17/09/2026 - 11:30 to 15:30 | M11: 37.5 | N11: per Hour | O11: 150 | P11: 150 | Q11: 18 | S11: =IFERROR(DATE(VALUE(MID(L11,FIND("/",L11,FIND("/",L11)+1)+1,4)),VALUE(MID(L11,FIND("/",L11)+1,FIND("/",L11,FIND("/",L11)+1)-FIND("/",L11)-1)),VALUE(LEFT(L11,FIND("/",L11)-1))),IF(ISNUMBER(L11),L11,"")) | T11: =IF(S11="","No - adjustment/reversal (no work date)",IF(COUNTIFS('Summary '!$A$21:$A$36,S11,'Summary '!$D$21:$D$36,K11)>0,"Yes","NO MATCH - INVESTIGATE"))

Sheet 20 Sept 2026 
A1: Earnings Details
A2: Employee Id | B2: Employee External Id | C2: Employee Name | D2: Pay Category Id | E2: Pay Category External Id | F2: Pay Category Name | G2: Units | H2: Unit Type | I2: Location Id | J2: Location External Id | K2: Location Name | L2: Notes | M2: Rate | N2: Rate Type | O2: Gross Earnings | P2: Taxable Earnings | Q2: SG Super | S2: Work Date (helper) | T2: Matched to Timesheet?
A3: 12414219 | C3: Jonathan Hendratno | D3: 2856297 | E3: 2286634 | F3: Casual Ordinary Hours | G3: 3.5 | H3: Hours | I3: 441224 | J3: 725 | K3: DTTL Mel Tech FT 1 [ONS] | L3: 24/08/2026 - 08:30 to 12:00 | M3: 37.5 | N3: per Hour | O3: 131.25 | P3: 131.25 | Q3: 15.75 | S3: =IFERROR(DATE(VALUE(MID(L3,FIND("/",L3,FIND("/",L3)+1)+1,4)),VALUE(MID(L3,FIND("/",L3)+1,FIND("/",L3,FIND("/",L3)+1)-FIND("/",L3)-1)),VALUE(LEFT(L3,FIND("/",L3)-1))),IF(ISNUMBER(L3),L3,"")) | T3: =IF(S3="","No - adjustment/reversal (no work date)",IF(COUNTIFS('Summary '!$A$21:$A$36,S3,'Summary '!$D$21:$D$36,K3)>0,"Yes","NO MATCH - INVESTIGATE"))
A4: 12414219 | C4: Jonathan Hendratno | D4: 2856297 | E4: 2286634 | F4: Casual Ordinary Hours | G4: 4.5 | H4: Hours | I4: 441224 | J4: 725 | K4: DTTL Mel Tech FT 1 [ONS] | L4: 24/08/2026 - 12:30 to 17:00 | M4: 37.5 | N4: per Hour | O4: 168.75 | P4: 168.75 | Q4: 20.25 | S4: =IFERROR(DATE(VALUE(MID(L4,FIND("/",L4,FIND("/",L4)+1)+1,4)),VALUE(MID(L4,FIND("/",L4)+1,FIND("/",L4,FIND("/",L4)+1)-FIND("/",L4)-1)),VALUE(LEFT(L4,FIND("/",L4)-1))),IF(ISNUMBER(L4),L4,"")) | T4: =IF(S4="","No - adjustment/reversal (no work date)",IF(COUNTIFS('Summary '!$A$21:$A$36,S4,'Summary '!$D$21:$D$36,K4)>0,"Yes","NO MATCH - INVESTIGATE"))
A5: 12414219 | C5: Jonathan Hendratno | D5: 2856297 | E5: 2286634 | F5: Casual Ordinary Hours | G5: 3.5 | H5: Hours | I5: 441224 | J5: 725 | K5: DTTL Mel Tech FT 1 [ONS] | L5: 28/08/2026 - 08:30 to 12:00 | M5: 37.5 | N5: per Hour | O5: 131.25 | P5: 131.25 | Q5: 15.75 | S5: =IFERROR(DATE(VALUE(MID(L5,FIND("/",L5,FIND("/",L5)+1)+1,4)),VALUE(MID(L5,FIND("/",L5)+1,FIND("/",L5,FIND("/",L5)+1)-FIND("/",L5)-1)),VALUE(LEFT(L5,FIND("/",L5)-1))),IF(ISNUMBER(L5),L5,"")) | T5: =IF(S5="","No - adjustment/reversal (no work date)",IF(COUNTIFS('Summary '!$A$21:$A$36,S5,'Summary '!$D$21:$D$36,K5)>0,"Yes","NO MATCH - INVESTIGATE"))
A6: 12414219 | C6: Jonathan Hendratno | D6: 2856297 | E6: 2286634 | F6: Casual Ordinary Hours | G6: 4.5 | H6: Hours | I6: 441224 | J6: 725 | K6: DTTL Mel Tech FT 1 [ONS] | L6: 28/08/2026 - 12:30 to 17:00 | M6: 37.5 | N6: per Hour | O6: 168.75 | P6: 168.75 | Q6: 20.25 | S6: =IFERROR(DATE(VALUE(MID(L6,FIND("/",L6,FIND("/",L6)+1)+1,4)),VALUE(MID(L6,FIND("/",L6)+1,FIND("/",L6,FIND("/",L6)+1)-FIND("/",L6)-1)),VALUE(LEFT(L6,FIND("/",L6)-1))),IF(ISNUMBER(L6),L6,"")) | T6: =IF(S6="","No - adjustment/reversal (no work date)",IF(COUNTIFS('Summary '!$A$21:$A$36,S6,'Summary '!$D$21:$D$36,K6)>0,"Yes","NO MATCH - INVESTIGATE"))
A7: 12414219 | C7: Jonathan Hendratno | D7: 2856297 | E7: 2286634 | F7: Casual Ordinary Hours | G7: 3.5 | H7: Hours | I7: 441224 | J7: 725 | K7: DTTL Mel Tech FT 1 [ONS] | L7: 31/08/2026 - 08:30 to 12:00 | M7: 37.5 | N7: per Hour | O7: 131.25 | P7: 131.25 | Q7: 15.75 | S7: =IFERROR(DATE(VALUE(MID(L7,FIND("/",L7,FIND("/",L7)+1)+1,4)),VALUE(MID(L7,FIND("/",L7)+1,FIND("/",L7,FIND("/",L7)+1)-FIND("/",L7)-1)),VALUE(LEFT(L7,FIND("/",L7)-1))),IF(ISNUMBER(L7),L7,"")) | T7: =IF(S7="","No - adjustment/reversal (no work date)",IF(COUNTIFS('Summary '!$A$21:$A$36,S7,'Summary '!$D$21:$D$36,K7)>0,"Yes","NO MATCH - INVESTIGATE"))
A8: 12414219 | C8: Jonathan Hendratno | D8: 2856297 | E8: 2286634 | F8: Casual Ordinary Hours | G8: 4.5 | H8: Hours | I8: 441224 | J8: 725 | K8: DTTL Mel Tech FT 1 [ONS] | L8: 31/08/2026 - 12:30 to 17:00 | M8: 37.5 | N8: per Hour | O8: 168.75 | P8: 168.75 | Q8: 20.25 | S8: =IFERROR(DATE(VALUE(MID(L8,FIND("/",L8,FIND("/",L8)+1)+1,4)),VALUE(MID(L8,FIND("/",L8)+1,FIND("/",L8,FIND("/",L8)+1)-FIND("/",L8)-1)),VALUE(LEFT(L8,FIND("/",L8)-1))),IF(ISNUMBER(L8),L8,"")) | T8: =IF(S8="","No - adjustment/reversal (no work date)",IF(COUNTIFS('Summary '!$A$21:$A$36,S8,'Summary '!$D$21:$D$36,K8)>0,"Yes","NO MATCH - INVESTIGATE"))
A9: 12414219 | C9: Jonathan Hendratno | D9: 2856297 | E9: 2286634 | F9: Casual Ordinary Hours | G9: 3 | H9: Hours | I9: 441224 | J9: 725 | K9: DTTL Mel Tech FT 1 [ONS] | L9: 1/09/2026 - 09:00 to 12:00 | M9: 37.5 | N9: per Hour | O9: 112.5 | P9: 112.5 | Q9: 13.5 | S9: =IFERROR(DATE(VALUE(MID(L9,FIND("/",L9,FIND("/",L9)+1)+1,4)),VALUE(MID(L9,FIND("/",L9)+1,FIND("/",L9,FIND("/",L9)+1)-FIND("/",L9)-1)),VALUE(LEFT(L9,FIND("/",L9)-1))),IF(ISNUMBER(L9),L9,"")) | T9: =IF(S9="","No - adjustment/reversal (no work date)",IF(COUNTIFS('Summary '!$A$21:$A$36,S9,'Summary '!$D$21:$D$36,K9)>0,"Yes","NO MATCH - INVESTIGATE"))
A10: 12414219 | C10: Jonathan Hendratno | D10: 2856297 | E10: 2286634 | F10: Casual Ordinary Hours | G10: 5 | H10: Hours | I10: 441224 | J10: 725 | K10: DTTL Mel Tech FT 1 [ONS] | L10: 1/09/2026 - 12:30 to 17:30 | M10: 37.5 | N10: per Hour | O10: 187.5 | P10: 187.5 | Q10: 22.5 | S10: =IFERROR(DATE(VALUE(MID(L10,FIND("/",L10,FIND("/",L10)+1)+1,4)),VALUE(MID(L10,FIND("/",L10)+1,FIND("/",L10,FIND("/",L10)+1)-FIND("/",L10)-1)),VALUE(LEFT(L10,FIND("/",L10)-1))),IF(ISNUMBER(L10),L10,"")) | T10: =IF(S10="","No - adjustment/reversal (no work date)",IF(COUNTIFS('Summary '!$A$21:$A$36,S10,'Summary '!$D$21:$D$36,K10)>0,"Yes","NO MATCH - INVESTIGATE"))
A11: 12414219 | C11: Jonathan Hendratno | D11: 2856297 | E11: 2286634 | F11: Casual Ordinary Hours | G11: 3 | H11: Hours | I11: 441224 | J11: 725 | K11: DTTL Mel Tech FT 1 [ONS] | L11: 2/09/2026 - 09:00 to 12:00 | M11: 37.5 | N11: per Hour | O11: 112.5 | P11: 112.5 | Q11: 13.5 | S11: =IFERROR(DATE(VALUE(MID(L11,FIND("/",L11,FIND("/",L11)+1)+1,4)),VALUE(MID(L11,FIND("/",L11)+1,FIND("/",L11,FIND("/",L11)+1)-FIND("/",L11)-1)),VALUE(LEFT(L11,FIND("/",L11)-1))),IF(ISNUMBER(L11),L11,"")) | T11: =IF(S11="","No - adjustment/reversal (no work date)",IF(COUNTIFS('Summary '!$A$21:$A$36,S11,'Summary '!$D$21:$D$36,K11)>0,"Yes","NO MATCH - INVESTIGATE"))
A12: 12414219 | C12: Jonathan Hendratno | D12: 2856297 | E12: 2286634 | F12: Casual Ordinary Hours | G12: 5 | H12: Hours | I12: 441224 | J12: 725 | K12: DTTL Mel Tech FT 1 [ONS] | L12: 2/09/2026 - 12:30 to 17:30 | M12: 37.5 | N12: per Hour | O12: 187.5 | P12: 187.5 | Q12: 22.5 | S12: =IFERROR(DATE(VALUE(MID(L12,FIND("/",L12,FIND("/",L12)+1)+1,4)),VALUE(MID(L12,FIND("/",L12)+1,FIND("/",L12,FIND("/",L12)+1)-FIND("/",L12)-1)),VALUE(LEFT(L12,FIND("/",L12)-1))),IF(ISNUMBER(L12),L12,"")) | T12: =IF(S12="","No - adjustment/reversal (no work date)",IF(COUNTIFS('Summary '!$A$21:$A$36,S12,'Summary '!$D$21:$D$36,K12)>0,"Yes","NO MATCH - INVESTIGATE"))
A13: 12414219 | C13: Jonathan Hendratno | D13: 2856297 | E13: 2286634 | F13: Casual Ordinary Hours | G13: 3.5 | H13: Hours | I13: 441224 | J13: 725 | K13: DTTL Mel Tech FT 1 [ONS] | L13: 4/09/2026 - 08:30 to 12:00 | M13: 37.5 | N13: per Hour | O13: 131.25 | P13: 131.25 | Q13: 15.75 | S13: =IFERROR(DATE(VALUE(MID(L13,FIND("/",L13,FIND("/",L13)+1)+1,4)),VALUE(MID(L13,FIND("/",L13)+1,FIND("/",L13,FIND("/",L13)+1)-FIND("/",L13)-1)),VALUE(LEFT(L13,FIND("/",L13)-1))),IF(ISNUMBER(L13),L13,"")) | T13: =IF(S13="","No - adjustment/reversal (no work date)",IF(COUNTIFS('Summary '!$A$21:$A$36,S13,'Summary '!$D$21:$D$36,K13)>0,"Yes","NO MATCH - INVESTIGATE"))
A14: 12414219 | C14: Jonathan Hendratno | D14: 2856297 | E14: 2286634 | F14: Casual Ordinary Hours | G14: 4.5 | H14: Hours | I14: 441224 | J14: 725 | K14: DTTL Mel Tech FT 1 [ONS] | L14: 4/09/2026 - 12:30 to 17:00 | M14: 37.5 | N14: per Hour | O14: 168.75 | P14: 168.75 | Q14: 20.25 | S14: =IFERROR(DATE(VALUE(MID(L14,FIND("/",L14,FIND("/",L14)+1)+1,4)),VALUE(MID(L14,FIND("/",L14)+1,FIND("/",L14,FIND("/",L14)+1)-FIND("/",L14)-1)),VALUE(LEFT(L14,FIND("/",L14)-1))),IF(ISNUMBER(L14),L14,"")) | T14: =IF(S14="","No - adjustment/reversal (no work date)",IF(COUNTIFS('Summary '!$A$21:$A$36,S14,'Summary '!$D$21:$D$36,K14)>0,"Yes","NO MATCH - INVESTIGATE"))

Sheet 21 Aug 2026
A1: Earnings Details
A2: Employee Id | B2: Employee External Id | C2: Employee Name | D2: Pay Category Id | E2: Pay Category External Id | F2: Pay Category Name | G2: Units | H2: Unit Type | I2: Location Id | J2: Location External Id | K2: Location Name | L2: Notes | M2: Rate | N2: Rate Type | O2: Gross Earnings | P2: Taxable Earnings | Q2: SG Super | S2: Work Date (helper) | T2: Matched to Timesheet?
A3: 12414219 | C3: Jonathan Hendratno | D3: 2856297 | E3: 2286634 | F3: Casual Ordinary Hours | G3: -16 | H3: Hours | I3: 770681 | J3: 26043001 | K3: CBA FT Tech MEL - 12 months [ONS] | L3: Reversal of incorrect rate for fortnight ending 07/08/2026 | M3: 35.15 | N3: per Hour | O3: -562.4 | P3: -562.4 | Q3: -67.48569 | S3: =IFERROR(DATE(VALUE(MID(L3,FIND("/",L3,FIND("/",L3)+1)+1,4)),VALUE(MID(L3,FIND("/",L3)+1,FIND("/",L3,FIND("/",L3)+1)-FIND("/",L3)-1)),VALUE(LEFT(L3,FIND("/",L3)-1))),IF(ISNUMBER(L3),L3,"")) | T3: =IF(S3="","No - adjustment/reversal (no work date)",IF(COUNTIFS('Summary '!$A$21:$A$36,S3,'Summary '!$D$21:$D$36,K3)>0,"Yes","NO MATCH - INVESTIGATE"))
A4: 12414219 | C4: Jonathan Hendratno | D4: 2856297 | E4: 2286634 | F4: Casual Ordinary Hours | G4: 16 | H4: Hours | I4: 770681 | J4: 26043001 | K4: CBA FT Tech MEL - 12 months [ONS] | L4: Reversal of incorrect rate for fortnight ending 07/08/2026 | M4: 37.5 | N4: per Hour | O4: 600 | P4: 600 | Q4: 71.99754 | S4: =IFERROR(DATE(VALUE(MID(L4,FIND("/",L4,FIND("/",L4)+1)+1,4)),VALUE(MID(L4,FIND("/",L4)+1,FIND("/",L4,FIND("/",L4)+1)-FIND("/",L4)-1)),VALUE(LEFT(L4,FIND("/",L4)-1))),IF(ISNUMBER(L4),L4,"")) | T4: =IF(S4="","No - adjustment/reversal (no work date)",IF(COUNTIFS('Summary '!$A$21:$A$36,S4,'Summary '!$D$21:$D$36,K4)>0,"Yes","NO MATCH - INVESTIGATE"))
A5: 12414219 | C5: Jonathan Hendratno | D5: 2856297 | E5: 2286634 | F5: Casual Ordinary Hours | G5: 5 | H5: Hours | I5: 770681 | J5: 26043001 | K5: CBA FT Tech MEL - 12 months [ONS] | L5: 18/08/2026 - 07:00 to 12:00. 435 Bourke St - CBA | M5: 37.5 | N5: per Hour | O5: 187.5 | P5: 187.5 | Q5: 22.49923 | S5: =IFERROR(DATE(VALUE(MID(L5,FIND("/",L5,FIND("/",L5)+1)+1,4)),VALUE(MID(L5,FIND("/",L5)+1,FIND("/",L5,FIND("/",L5)+1)-FIND("/",L5)-1)),VALUE(LEFT(L5,FIND("/",L5)-1))),IF(ISNUMBER(L5),L5,"")) | T5: =IF(S5="","No - adjustment/reversal (no work date)",IF(COUNTIFS('Summary '!$A$21:$A$36,S5,'Summary '!$D$21:$D$36,K5)>0,"Yes","NO MATCH - INVESTIGATE"))
A6: 12414219 | C6: Jonathan Hendratno | D6: 2856297 | E6: 2286634 | F6: Casual Ordinary Hours | G6: 3 | H6: Hours | I6: 770681 | J6: 26043001 | K6: CBA FT Tech MEL - 12 months [ONS] | L6: 18/08/2026 - 13:00 to 16:00. 435 Bourke St - CBA | M6: 37.5 | N6: per Hour | O6: 112.5 | P6: 112.5 | Q6: 13.49954 | S6: =IFERROR(DATE(VALUE(MID(L6,FIND("/",L6,FIND("/",L6)+1)+1,4)),VALUE(MID(L6,FIND("/",L6)+1,FIND("/",L6,FIND("/",L6)+1)-FIND("/",L6)-1)),VALUE(LEFT(L6,FIND("/",L6)-1))),IF(ISNUMBER(L6),L6,"")) | T6: =IF(S6="","No - adjustment/reversal (no work date)",IF(COUNTIFS('Summary '!$A$21:$A$36,S6,'Summary '!$D$21:$D$36,K6)>0,"Yes","NO MATCH - INVESTIGATE"))
A7: 12414219 | C7: Jonathan Hendratno | D7: 2856297 | E7: 2286634 | F7: Casual Ordinary Hours | G7: 4 | H7: Hours | I7: 731888 | J7: 20250731 | K7: PWC National Pool of Hours [ONS] | L7: 20/08/2026 - 13:00 to 17:00 | M7: 37.5 | N7: per Hour | O7: 150 | P7: 150 | Q7: 17.99938 | S7: =IFERROR(DATE(VALUE(MID(L7,FIND("/",L7,FIND("/",L7)+1)+1,4)),VALUE(MID(L7,FIND("/",L7)+1,FIND("/",L7,FIND("/",L7)+1)-FIND("/",L7)-1)),VALUE(LEFT(L7,FIND("/",L7)-1))),IF(ISNUMBER(L7),L7,"")) | T7: =IF(S7="","No - adjustment/reversal (no work date)",IF(COUNTIFS('Summary '!$A$21:$A$36,S7,'Summary '!$D$21:$D$36,K7)>0,"Yes","NO MATCH - INVESTIGATE"))

Sheet 07 Aug 2026
A1: Earnings Details
A2: Employee Id | B2: Employee External Id | C2: Employee Name | D2: Pay Category Id | E2: Pay Category External Id | F2: Pay Category Name | G2: Units | H2: Unit Type | I2: Location Id | J2: Location External Id | K2: Location Name | L2: Notes | M2: Rate | N2: Rate Type | O2: Gross Earnings | P2: Taxable Earnings | Q2: SG Super | S2: Work Date (helper) | T2: Matched to Timesheet?
A3: 12414219 | C3: Jonathan Hendratno | D3: 2856297 | E3: 2286634 | F3: Casual Ordinary Hours | G3: 5.5 | H3: Hours | I3: 770681 | J3: 26043001 | K3: CBA FT Tech MEL - 12 months [ONS] | L3: 46232 | M3: 35.15 | N3: per Hour | O3: 193.32 | P3: 193.325 | Q3: 23.19969 | S3: =IFERROR(DATE(VALUE(MID(L3,FIND("/",L3,FIND("/",L3)+1)+1,4)),VALUE(MID(L3,FIND("/",L3)+1,FIND("/",L3,FIND("/",L3)+1)-FIND("/",L3)-1)),VALUE(LEFT(L3,FIND("/",L3)-1))),IF(ISNUMBER(L3),L3,"")) | T3: =IF(S3="","No - adjustment/reversal (no work date)",IF(COUNTIFS('Summary '!$A$21:$A$36,S3,'Summary '!$D$21:$D$36,K3)>0,"Yes","NO MATCH - INVESTIGATE"))
A4: 12414219 | C4: Jonathan Hendratno | D4: 2856297 | E4: 2286634 | F4: Casual Ordinary Hours | G4: 2.5 | H4: Hours | I4: 770681 | J4: 26043001 | K4: CBA FT Tech MEL - 12 months [ONS] | L4: 46232 | M4: 35.15 | N4: per Hour | O4: 87.88 | P4: 87.875 | Q4: 10.54531 | S4: =IFERROR(DATE(VALUE(MID(L4,FIND("/",L4,FIND("/",L4)+1)+1,4)),VALUE(MID(L4,FIND("/",L4)+1,FIND("/",L4,FIND("/",L4)+1)-FIND("/",L4)-1)),VALUE(LEFT(L4,FIND("/",L4)-1))),IF(ISNUMBER(L4),L4,"")) | T4: =IF(S4="","No - adjustment/reversal (no work date)",IF(COUNTIFS('Summary '!$A$21:$A$36,S4,'Summary '!$D$21:$D$36,K4)>0,"Yes","NO MATCH - INVESTIGATE"))
A5: 12414219 | C5: Jonathan Hendratno | D5: 2856297 | E5: 2286634 | F5: Casual Ordinary Hours | G5: 4 | H5: Hours | I5: 441184 | J5: 2392 | K5: PWC – MEL Technician [ONS] | L5: 46233 | M5: 35.15 | N5: per Hour | O5: 140.6 | P5: 140.6 | Q5: 16.8725 | S5: =IFERROR(DATE(VALUE(MID(L5,FIND("/",L5,FIND("/",L5)+1)+1,4)),VALUE(MID(L5,FIND("/",L5)+1,FIND("/",L5,FIND("/",L5)+1)-FIND("/",L5)-1)),VALUE(LEFT(L5,FIND("/",L5)-1))),IF(ISNUMBER(L5),L5,"")) | T5: =IF(S5="","No - adjustment/reversal (no work date)",IF(COUNTIFS('Summary '!$A$21:$A$36,S5,'Summary '!$D$21:$D$36,K5)>0,"Yes","NO MATCH - INVESTIGATE"))
A6: 12414219 | C6: Jonathan Hendratno | D6: 2856297 | E6: 2286634 | F6: Casual Ordinary Hours | G6: 4 | H6: Hours | I6: 777409 | J6: 26022301 | K6: Aware Super AV Maintenance [ONS] | L6: 46233 | M6: 35.15 | N6: per Hour | O6: 140.6 | P6: 140.6 | Q6: 16.8725 | S6: =IFERROR(DATE(VALUE(MID(L6,FIND("/",L6,FIND("/",L6)+1)+1,4)),VALUE(MID(L6,FIND("/",L6)+1,FIND("/",L6,FIND("/",L6)+1)-FIND("/",L6)-1)),VALUE(LEFT(L6,FIND("/",L6)-1))),IF(ISNUMBER(L6),L6,"")) | T6: =IF(S6="","No - adjustment/reversal (no work date)",IF(COUNTIFS('Summary '!$A$21:$A$36,S6,'Summary '!$D$21:$D$36,K6)>0,"Yes","NO MATCH - INVESTIGATE"))
