Workbook

Sheet Read Me
B2: CTS P&L Reporting
B3: Corporate Technology Services Pty Ltd Financial year 1 July to 30 June AUD
B5: The one rule
B6: You only ever type into two sheets: Actuals and Budget. Every other sheet is calculated and will update itself. If you find yourself typing a number anywhere else, something has gone wrong.
B8: Adding a month
B9: 1. In Xero, run the Profit and Loss report for the month and export it to Excel.
B10: 2. Open the Actuals sheet here and find the column for that month.
B11: 3. Paste the figures into the yellow cells in that column, matching account to account.
B12: 4. That is it. Every other sheet has already updated.
B14: Checking your paste worked
B15: The Summary sheet ends with a Reconciliation Check. It compares the workbook's FY26 totals against the figures pulled straight from Xero on 3 September 2026. Once FY26 is pasted in, the Difference column should read zero. Anything else means the paste is incomplete or a row has slipped out of alignment.
B17: What is on each sheet
... B35: This workbook holds FY26 and FY27. When FY28 begins, send it back to me and I will roll it forward rather than you rebuilding it by hand.

Sheet Summary
A1: Summary: FY27
A2: Everything here is calculated. The only sheets you type into are Actuals and Budget.
A4: MONTHLY
B5: Jul-26 | C5: Aug-26 | D5: Sep-26 | E5: Oct-26 | F5: Nov-26 | G5: Dec-26 | H5: Jan-27 | I5: Feb-27 | J5: Mar-27 | K5: Apr-27 | L5: May-27 | M5: Jun-27 | N5: FY27 Total
A6: Total Income | B6: ='This Year'!B40 | C6: ='This Year'!C40 | D6: ='This Year'!D40 | E6: ='This Year'!E40 | F6: ='This Year'!F40 | G6: ='This Year'!G40 | H6: ='This Year'!H40 | I6: ='This Year'!I40 | ... N6: ='This Year'!N40
A7: Total Cost of Sales | B7: ='This Year'!B109 | C7: ='This Year'!C109 | D7: ='This Year'!D109 | E7: ='This Year'!E109 | F7: ='This Year'!F109 | G7: ='This Year'!G109 | H7: ='This Year'!H109 | I7: ='This Year'!I109 | ... N7: ='This Year'!N109
A8: Gross Profit | B8: ='This Year'!B111 | C8: ='This Year'!C111 | D8: ='This Year'!D111 | E8: ='This Year'!E111 | F8: ='This Year'!F111 | G8: ='This Year'!G111 | H8: ='This Year'!H111 | I8: ='This Year'!I111 | ... N8: ='This Year'!N111
A9: Gross Profit % | B9: ='This Year'!B112 | C9: ='This Year'!C112 | D9: ='This Year'!D112 | E9: ='This Year'!E112 | F9: ='This Year'!F112 | G9: ='This Year'!G112 | H9: ='This Year'!H112 | I9: ='This Year'!I112 | ... N9: ='This Year'!N112
A10: Total Other Income | B10: ='This Year'!B124 | C10: ='This Year'!C124 | D10: ='This Year'!D124 | E10: ='This Year'!E124 | F10: ='This Year'!F124 | G10: ='This Year'!G124 | H10: ='This Year'!H124 | I10: ='This Year'!I124 | ... N10: ='This Year'!N124
A11: Total Expenses | B11: ='This Year'!B207 | C11: ='This Year'!C207 | D11: ='This Year'!D207 | E11: ='This Year'!E207 | F11: ='This Year'!F207 | G11: ='This Year'!G207 | H11: ='This Year'!H207 | I11: ='This Year'!I207 | ... N11: ='This Year'!N207
A12: Net Profit | B12: ='This Year'!B209 | C12: ='This Year'!C209 | D12: ='This Year'!D209 | E12: ='This Year'!E209 | F12: ='This Year'!F209 | G12: ='This Year'!G209 | H12: ='This Year'!H209 | I12: ='This Year'!I209 | ... N12: ='This Year'!N209
A13: Net Profit % | B13: ='This Year'!B210 | C13: ='This Year'!C210 | D13: ='This Year'!D210 | E13: ='This Year'!E210 | F13: ='This Year'!F210 | G13: ='This Year'!G210 | H13: ='This Year'!H210 | I13: ='This Year'!I210 | ... N13: ='This Year'!N210
A16: QUARTERLY
B17: Q1 Jul-Sep | C17: Q2 Oct-Dec | D17: Q3 Jan-Mar | E17: Q4 Apr-Jun | F17: FY27 Total
A18: Total Income | B18: =SUM(B6:D6) | C18: =SUM(E6:G6) | D18: =SUM(H6:J6) | E18: =SUM(K6:M6) | N18: ='This Year'!N40
A19: Total Cost of Sales | B19: =SUM(B7:D7) | C19: =SUM(E7:G7) | D19: =SUM(H7:J7) | E19: =SUM(K7:M7) | N19: ='This Year'!N109
A20: Gross Profit | B20: =SUM(B8:D8) | C20: =SUM(E8:G8) | D20: =SUM(H8:J8) | E20: =SUM(K8:M8) | N20: ='This Year'!N111
A21: Gross Profit % | B21: =IFERROR(SUM(B8:D8)/SUM(B6:D6),0) | C21: =IFERROR(SUM(E8:G8)/SUM(E6:G6),0) | D21: =IFERROR(SUM(H8:J8)/SUM(H6:J6),0) | E21: =IFERROR(SUM(K8:M8)/SUM(K6:M6),0) | N21: ='This Year'!N112
A22: Total Other Income | B22: =SUM(B10:D10) | C22: =SUM(E10:G10) | D22: =SUM(H10:J10) | E22: =SUM(K10:M10) | N22: ='This Year'!N124
A23: Total Expenses | B23: =SUM(B11:D11) | C23: =SUM(E11:G11) | D23: =SUM(H11:J11) | E23: =SUM(K11:M11) | N23: ='This Year'!N207
A24: Net Profit | B24: =SUM(B12:D12) | C24: =SUM(E12:G12) | D24: =SUM(H12:J12) | E24: =SUM(K12:M12) | N24: ='This Year'!N209
A25: Net Profit % | B25: =IFERROR(SUM(B12:D12)/SUM(B6:D6),0) | C25: =IFERROR(SUM(E12:G12)/SUM(E6:G6),0) | D25: =IFERROR(SUM(H12:J12)/SUM(H6:J6),0) | E25: =IFERROR(SUM(K12:M12)/SUM(K6:M6),0) | N25: ='This Year'!N210
A28: YEAR ON YEAR
B29: FY27 | C29: FY26 | D29: Variance $ | E29: Variance %
A30: Total Income | B30: ='This Year'!N40 | C30: ='Last Year'!N40 | D30: =B30-C30 | E30: =IFERROR(D30/ABS(C30),0)
A31: Total Cost of Sales | B31: ='This Year'!N109 | C31: ='Last Year'!N109 | D31: =B31-C31 | E31: =IFERROR(D31/ABS(C31),0)
A32: Gross Profit | B32: ='This Year'!N111 | C32: ='Last Year'!N111 | D32: =B32-C32 | E32: =IFERROR(D32/ABS(C32),0)
A33: Gross Profit % | B33: ='This Year'!N112 | C33: ='Last Year'!N112 | D33: =B33-C33
A34: Total Other Income | B34: ='This Year'!N124 | C34: ='Last Year'!N124 | D34: =B34-C34 | E34: =IFERROR(D34/ABS(C34),0)
A35: Total Expenses | B35: ='This Year'!N207 | C35: ='Last Year'!N207 | D35: =B35-C35 | E35: =IFERROR(D35/ABS(C35),0)
A36: Net Profit | B36: ='This Year'!N209 | C36: ='Last Year'!N209 | D36: =B36-C36 | E36: =IFERROR(D36/ABS(C36),0)
A37: Net Profit % | B37: ='This Year'!N210 | C37: ='Last Year'!N210 | D37: =B37-C37
A40: RECONCILIATION CHECK
A41: FY26 figures pulled directly from Xero on 3 September 2026. Once you have pasted FY26 into Actuals, the difference column should read zero. Anything else means the paste is incomplete or misaligned.
B42: Workbook FY26 | C42: Xero FY26 | D42: Difference
A43: Total Income | B43: ='Last Year'!N40 | C43: 6113186 | D43: =ROUND(B43-C43,2)
A44: Total Cost of Sales | B44: ='Last Year'!N109 | C44: 3497093.8 | D44: =ROUND(B44-C44,2)
A45: Gross Profit | B45: ='Last Year'!N111 | C45: 2616092.2 | D45: =ROUND(B45-C45,2)
A46: Total Other Income | B46: ='Last Year'!N124 | C46: 13413.68 | D46: =ROUND(B46-C46,2)
A47: Total Expenses | B47: ='Last Year'!N207 | C47: 2380879.2 | D47: =ROUND(B47-C47,2)
...

Sheet Actuals
A1: Actuals: paste your Xero export here
A2: Yellow cells only. Paste each month's figures from your Xero P&L export into the matching column. Nothing else on this sheet should be edited, and no other sheet should be typed into at all.
A3: Account | B3: Group | C3: Division | D3: Jul-25 | E3: Aug-25 | F3: Sep-25 | G3: Oct-25 | H3: Nov-25 | I3: Dec-25 | J3: Jan-26 | K3: Feb-26 | L3: Mar-26 | M3: Apr-26 | N3: May-26 | O3: Jun-26 | P3: Jul-26 | Q3: Aug-26 | R3: Sep-26 | S3: Oct-26 | T3: Nov-26 | U3: Dec-26 | V3: Jan-27 | W3: Feb-27 | X3: Mar-27 | Y3: Apr-27 | Z3: May-27 | AA3: Jun-27
A4: Ad Hoc Service Labour | B4: Income | C4: Unallocated
A5: Closing Work in Progress | B5: Income | C5: Unallocated
A6: Conference Call Charge | B6: Income | C6: Unallocated
A7: Contract Help Desk | B7: Income | C7: Unallocated
A8: Contract Maintenance | B8: Income | C8: Unallocated
A9: Contract Support Staff | B9: Income | C9: Unallocated
A10: Credit Card Collected - CONS | B10: Income | C10: Consulting
A11: Credit Card Collected - ONS | B11: Income | C11: Onsite
A12: Credit Card Collected - PRD | B12: Income | C12: Production
A13: Credit Card Collected - VID | B13: Income | C13: Video
A14: Credit Card Collected-INTEGRATION | B14: Income | C14: Integration
A15: Credit Card Fees - ADMIN | B15: Income | C15: Admin
... A193: Workers' Compensation | B193: Expenses | C193: Unallocated

Sheet Budget
A1: Budget: paste your Xero export here
A2: Yellow cells only. Enter the budget for each account by month, in the same layout as Actuals.
A3: Account | B3: Group | C3: Division | D3: Jul-25 | E3: Aug-25 | F3: Sep-25 | G3: Oct-25 | H3: Nov-25 | I3: Dec-25 | J3: Jan-26 | K3: Feb-26 | L3: Mar-26 | M3: Apr-26 | N3: May-26 | O3: Jun-26 | P3: Jul-26 | Q3: Aug-26 | R3: Sep-26 | S3: Oct-26 | T3: Nov-26 | U3: Dec-26 | V3: Jan-27 | W3: Feb-27 | X3: Mar-27 | Y3: Apr-27 | Z3: May-27 | AA3: Jun-27
A4: Ad Hoc Service Labour | B4: Income | C4: Unallocated
A5: Closing Work in Progress | B5: Income | C5: Unallocated
A6: Conference Call Charge | B6: Income | C6: Unallocated
A7: Contract Help Desk | B7: Income | C7: Unallocated
A8: Contract Maintenance | B8: Income | C8: Unallocated
A9: Contract Support Staff | B9: Income | C9: Unallocated
A10: Credit Card Collected - CONS | B10: Income | C10: Consulting
A11: Credit Card Collected - ONS | B11: Income | C11: Onsite
A12: Credit Card Collected - PRD | B12: Income | C12: Production
A13: Credit Card Collected - VID | B13: Income | C13: Video
A14: Credit Card Collected-INTEGRATION | B14: Income | C14: Integration
A15: Credit Card Fees - ADMIN | B15: Income | C15: Admin
... A193: Workers' Compensation | B193: Expenses | C193: Unallocated

Sheet This Year
A1: This Year: FY27 Profit & Loss
A2: Calculated from the Actuals sheet. Do not type here.
A3: Account | B3: Jul-26 | C3: Aug-26 | D3: Sep-26 | E3: Oct-26 | F3: Nov-26 | G3: Dec-26 | H3: Jan-27 | I3: Feb-27 | J3: Mar-27 | K3: Apr-27 | L3: May-27 | M3: Jun-27 | N3: FY27 Total
A4: INCOME
A5: Ad Hoc Service Labour | B5: =SUMIFS(Actuals!$P:$P,Actuals!$A:$A,$A5) | C5: =SUMIFS(Actuals!$Q:$Q,Actuals!$A:$A,$A5) | D5: =SUMIFS(Actuals!$R:$R,Actuals!$A:$A,$A5) | E5: =SUMIFS(Actuals!$S:$S,Actuals!$A:$A,$A5) | F5: =SUMIFS(Actuals!$T:$T,Actuals!$A:$A,$A5) | G5: =SUMIFS(Actuals!$U:$U,Actuals!$A:$A,$A5) | H5: =SUMIFS(Actuals!$V:$V,Actuals!$A:$A,$A5) | I5: =SUMIFS(Actuals!$W:$W,Actuals!$A:$A,$A5) | J5: =SUMIFS(Actuals!$X:$X,Actuals!$A:$A,$A5) | K5: =SUMIFS(Actuals!$Y:$Y,Actuals!$A:$A,$A5) | L5: =SUMIFS(Actuals!$Z:$Z,Actuals!$A:$A,$A5) | M5: =SUMIFS(Actuals!$AA:$AA,Actuals!$A:$A,$A5) | N5: =SUM(B5:M5)
A6: Closing Work in Progress | B6: =SUMIFS(Actuals!$P:$P,Actuals!$A:$A,$A6) | C6: =SUMIFS(Actuals!$Q:$Q,Actuals!$A:$A,$A6) | D6: =SUMIFS(Actuals!$R:$R,Actuals!$A:$A,$A6) | E6: =SUMIFS(Actuals!$S:$S,Actuals!$A:$A,$A6) | F6: =SUMIFS(Actuals!$T:$T,Actuals!$A:$A,$A6) | G6: =SUMIFS(Actuals!$U:$U,Actuals!$A:$A,$A6) | H6: =SUMIFS(Actuals!$V:$V,Actuals!$A:$A,$A6) | I6: =SUMIFS(Actuals!$W:$W,Actuals!$A:$A,$A6) | J6: =SUMIFS(Actuals!$X:$X,Actuals!$A:$A,$A6) | K6: =SUMIFS(Actuals!$Y:$Y,Actuals!$A:$A,$A6) | L6: =SUMIFS(Actuals!$Z:$Z,Actuals!$A:$A,$A6) | M6: =SUMIFS(Actuals!$AA:$AA,Actuals!$A:$A,$A6) | N6: =SUM(B6:M6)
A7: Conference Call Charge | B7: =SUMIFS(Actuals!$P:$P,Actuals!$A:$A,$A7) | C7: =SUMIFS(Actuals!$Q:$Q,Actuals!$A:$A,$A7) | D7: =SUMIFS(Actuals!$R:$R,Actuals!$A:$A,$A7) | E7: =SUMIFS(Actuals!$S:$S,Actuals!$A:$A,$A7) | F7: =SUMIFS(Actuals!$T:$T,Actuals!$A:$A,$A7) | G7: =SUMIFS(Actuals!$U:$U,Actuals!$A:$A,$A7) | H7: =SUMIFS(Actuals!$V:$V,Actuals!$A:$A,$A7) | I7: =SUMIFS(Actuals!$W:$W,Actuals!$A:$A,$A7) | J7: =SUMIFS(Actuals!$X:$X,Actuals!$A:$A,$A7) | K7: =SUMIFS(Actuals!$Y:$Y,Actuals!$A:$A,$A7) | L7: =SUMIFS(Actuals!$Z:$Z,Actuals!$A:$A,$A7) | M7: =SUMIFS(Actuals!$AA:$AA,Actuals!$A:$A,$A7) | N7: =SUM(B7:M7)
A8: Contract Help Desk | B8: =SUMIFS(Actuals!$P:$P,Actuals!$A:$A,$A8) | C8: =SUMIFS(Actuals!$Q:$Q,Actuals!$A:$A,$A8) | D8: =SUMIFS(Actuals!$R:$R,Actuals!$A:$A,$A8) | E8: =SUMIFS(Actuals!$S:$S,Actuals!$A:$A,$A8) | F8: =SUMIFS(Actuals!$T:$T,Actuals!$A:$A,$A8) | G8: =SUMIFS(Actuals!$U:$U,Actuals!$A:$A,$A8) | H8: =SUMIFS(Actuals!$V:$V,Actuals!$A:$A,$A8) | I8: =SUMIFS(Actuals!$W:$W,Actuals!$A:$A,$A8) | J8: =SUMIFS(Actuals!$X:$X,Actuals!$A:$A,$A8) | K8: =SUMIFS(Actuals!$Y:$Y,Actuals!$A:$A,$A8) | L8: =SUMIFS(Actuals!$Z:$Z,Actuals!$A:$A,$A8) | M8: =SUMIFS(Actuals!$AA:$AA,Actuals!$A:$A,$A8) | N8: =SUM(B8:M8)
A9: Contract Maintenance | B9: =SUMIFS(Actuals!$P:$P,Actuals!$A:$A,$A9) | C9: =SUMIFS(Actuals!$Q:$Q,Actuals!$A:$A,$A9) | D9: =SUMIFS(Actuals!$R:$R,Actuals!$A:$A,$A9) | E9: =SUMIFS(Actuals!$S:$S,Actuals!$A:$A,$A9) | F9: =SUMIFS(Actuals!$T:$T,Actuals!$A:$A,$A9) | G9: =SUMIFS(Actuals!$U:$U,Actuals!$A:$A,$A9) | H9: =SUMIFS(Actuals!$V:$V,Actuals!$A:$A,$A9) | I9: =SUMIFS(Actuals!$W:$W,Actuals!$A:$A,$A9) | J9: =SUMIFS(Actuals!$X:$X,Actuals!$A:$A,$A9) | K9: =SUMIFS(Actuals!$Y:$Y,Actuals!$A:$A,$A9) | L9: =SUMIFS(Actuals!$Z:$Z,Actuals!$A:$A,$A9) | M9: =SUMIFS(Actuals!$AA:$AA,Actuals!$A:$A,$A9) | N9: =SUM(B9:M9)
A10: Contract Support Staff | B10: =SUMIFS(Actuals!$P:$P,Actuals!$A:$A,$A10) | C10: =SUMIFS(Actuals!$Q:$Q,Actuals!$A:$A,$A10) | D10: =SUMIFS(Actuals!$R:$R,Actuals!$A:$A,$A10) | E10: =SUMIFS(Actuals!$S:$S,Actuals!$A:$A,$A10) | F10: =SUMIFS(Actuals!$T:$T,Actuals!$A:$A,$A10) | G10: =SUMIFS(Actuals!$U:$U,Actuals!$A:$A,$A10) | H10: =SUMIFS(Actuals!$V:$V,Actuals!$A:$A,$A10) | I10: =SUMIFS(Actuals!$W:$W,Actuals!$A:$A,$A10) | J10: =SUMIFS(Actuals!$X:$X,Actuals!$A:$A,$A10) | K10: =SUMIFS(Actuals!$Y:$Y,Actuals!$A:$A,$A10) | L10: =SUMIFS(Actuals!$Z:$Z,Actuals!$A:$A,$A10) | M10: =SUMIFS(Actuals!$AA:$AA,Actuals!$A:$A,$A10) | N10: =SUM(B10:M10)
A11: Credit Card Collected - CONS | B11: =SUMIFS(Actuals!$P:$P,Actuals!$A:$A,$A11) | C11: =SUMIFS(Actuals!$Q:$Q,Actuals!$A:$A,$A11) | D11: =SUMIFS(Actuals!$R:$R,Actuals!$A:$A,$A11) | E11: =SUMIFS(Actuals!$S:$S,Actuals!$A:$A,$A11) | F11: =SUMIFS(Actuals!$T:$T,Actuals!$A:$A,$A11) | G11: =SUMIFS(Actuals!$U:$U,Actuals!$A:$A,$A11) | H11: =SUMIFS(Actuals!$V:$V,Actuals!$A:$A,$A11) | I11: =SUMIFS(Actuals!$W:$W,Actuals!$A:$A,$A11) | J11: =SUMIFS(Actuals!$X:$X,Actuals!$A:$A,$A11) | K11: =SUMIFS(Actuals!$Y:$Y,Actuals!$A:$A,$A11) | L11: =SUMIFS(Actuals!$Z:$Z,Actuals!$A:$A,$A11) | M11: =SUMIFS(Actuals!$AA:$AA,Actuals!$A:$A,$A11) | N11: =SUM(B11:M11)
A12: Credit Card Collected - ONS | B12: =SUMIFS(Actuals!$P:$P,Actuals!$A:$A,$A12) | C12: =SUMIFS(Actuals!$Q:$Q,Actuals!$A:$A,$A12) | D12: =SUMIFS(Actuals!$R:$R,Actuals!$A:$A,$A12) | E12: =SUMIFS(Actuals!$S:$S,Actuals!$A:$A,$A12) | F12: =SUMIFS(Actuals!$T:$T,Actuals!$A:$A,$A12) | G12: =SUMIFS(Actuals!$U:$U,Actuals!$A:$A,$A12) | H12: =SUMIFS(Actuals!$V:$V,Actuals!$A:$A,$A12) | I12: =SUMIFS(Actuals!$W:$W,Actuals!$A:$A,$A12) | J12: =SUMIFS(Actuals!$X:$X,Actuals!$A:$A,$A12) | K12: =SUMIFS(Actuals!$Y:$Y,Actuals!$A:$A,$A12) | L12: =SUMIFS(Actuals!$Z:$Z,Actuals!$A:$A,$A12) | M12: =SUMIFS(Actuals!$AA:$AA,Actuals!$A:$A,$A12) | N12: =SUM(B12:M12)
A13: Credit Card Collected - PRD | B13: =SUMIFS(Actuals!$P:$P,Actuals!$A:$A,$A13) | C13: =SUMIFS(Actuals!$Q:$Q,Actuals!$A:$A,$A13) | D13: =SUMIFS(Actuals!$R:$R,Actuals!$A:$A,$A13) | E13: =SUMIFS(Actuals!$S:$S,Actuals!$A:$A,$A13) | F13: =SUMIFS(Actuals!$T:$T,Actuals!$A:$A,$A13) | G13: =SUMIFS(Actuals!$U:$U,Actuals!$A:$A,$A13) | H13: =SUMIFS(Actuals!$V:$V,Actuals!$A:$A,$A13) | I13: =SUMIFS(Actuals!$W:$W,Actuals!$A:$A,$A13) | J13: =SUMIFS(Actuals!$X:$X,Actuals!$A:$A,$A13) | K13: =SUMIFS(Actuals!$Y:$Y,Actuals!$A:$A,$A13) | L13: =SUMIFS(Actuals!$Z:$Z,Actuals!$A:$A,$A13) | M13: =SUMIFS(Actuals!$AA:$AA,Actuals!$A:$A,$A13) | N13: =SUM(B13:M13)
A14: Credit Card Collected - VID | B14: =SUMIFS(Actuals!$P:$P,Actuals!$A:$A,$A14) | C14: =SUMIFS(Actuals!$Q:$Q,Actuals!$A:$A,$A14) | D14: =SUMIFS(Actuals!$R:$R,Actuals!$A:$A,$A14) | E14: =SUMIFS(Actuals!$S:$S,Actuals!$A:$A,$A14) | F14: =SUMIFS(Actuals!$T:$T,Actuals!$A:$A,$A14) | G14: =SUMIFS(Actuals!$U:$U,Actuals!$A:$A,$A14) | H14: =SUMIFS(Actuals!$V:$V,Actuals!$A:$A,$A14) | I14: =SUMIFS(Actuals!$W:$W,Actuals!$A:$A,$A14) | J14: =SUMIFS(Actuals!$X:$X,Actuals!$A:$A,$A14) | K14: =SUMIFS(Actuals!$Y:$Y,Actuals!$A:$A,$A14) | L14: =SUMIFS(Actuals!$Z:$Z,Actuals!$A:$A,$A14) | M14: =SUMIFS(Actuals!$AA:$AA,Actuals!$A:$A,$A14) | N14: =SUM(B14:M14)
A15: Credit Card Collected-INTEGRATION | B15: =SUMIFS(Actuals!$P:$P,Actuals!$A:$A,$A15) | C15: =SUMIFS(Actuals!$Q:$Q,Actuals!$A:$A,$A15) | D15: =SUMIFS(Actuals!$R:$R,Actuals!$A:$A,$A15) | E15: =SUMIFS(Actuals!$S:$S,Actuals!$A:$A,$A15) | F15: =SUMIFS(Actuals!$T:$T,Actuals!$A:$A,$A15) | G15: =SUMIFS(Actuals!$U:$U,Actuals!$A:$A,$A15) | H15: =SUMIFS(Actuals!$V:$V,Actuals!$A:$A,$A15) | I15: =SUMIFS(Actuals!$W:$W,Actuals!$A:$A,$A15) | J15: =SUMIFS(Actuals!$X:$X,Actuals!$A:$A,$A15) | K15: =SUMIFS(Actuals!$Y:$Y,Actuals!$A:$A,$A15) | L15: =SUMIFS(Actuals!$Z:$Z,Actuals!$A:$A,$A15) | M15: =SUMIFS(Actuals!$AA:$AA,Actuals!$A:$A,$A15) | N15: =SUM(B15:M15)
A16: Credit Card Fees - ADMIN | B16: =SUMIFS(Actuals!$P:$P,Actuals!$A:$A,$A16) | C16: =SUMIFS(Actuals!$Q:$Q,Actuals!$A:$A,$A16) | D16: =SUMIFS(Actuals!$R:$R,Actuals!$A:$A,$A16) | E16: =SUMIFS(Actuals!$S:$S,Actuals!$A:$A,$A16) | F16: =SUMIFS(Actuals!$T:$T,Actuals!$A:$A,$A16) | G16: =SUMIFS(Actuals!$U:$U,Actuals!$A:$A,$A16) | H16: =SUMIFS(Actuals!$V:$V,Actuals!$A:$A,$A16) | I16: =SUMIFS(Actuals!$W:$W,Actuals!$A:$A,$A16) | J16: =SUMIFS(Actuals!$X:$X,Actuals!$A:$A,$A16) | K16: =SUMIFS(Actuals!$Y:$Y,Actuals!$A:$A,$A16) | L16: =SUMIFS(Actuals!$Z:$Z,Actuals!$A:$A,$A16) | M16: =SUMIFS(Actuals!$AA:$AA,Actuals!$A:$A,$A16) | N16: =SUM(B16:M16)
... A39: Video Labour | B39: =SUMIFS(Actuals!$P:$P,Actuals!$A:$A,$A39) | C39: =SUMIFS(Actuals!$Q:$Q,Actuals!$A:$A,$A39) | D39: =SUMIFS(Actuals!$R:$R,Actuals!$A:$A,$A39) | E39: =SUMIFS(Actuals!$S:$S,Actuals!$A:$A,$A39) | F39: =SUMIFS(Actuals!$T:$T,Actuals!$A:$A,$A39) | G39: =SUMIFS(Actuals!$U:$U,Actuals!$A:$A,$A39) | H39: =SUMIFS(Actuals!$V:$V,Actuals!$A:$A,$A39) | I39: =SUMIFS(Actuals!$W:$W,Actuals!$A:$A,$A39) | J39: =SUMIFS(Actuals!$X:$X,Actuals!$A:$A,$A39) | K39: =SUMIFS(Actuals!$Y:$Y,Actuals!$A:$A,$A39) | L39: =SUMIFS(Actuals!$Z:$Z,Actuals!$A:$A,$A39) | M39: =SUMIFS(Actuals!$AA:$AA,Actuals!$A:$A,$A39) | N39: =SUM(B39:M39)
A40: Total Income | B40: =SUM(B5:B39) | C40: =SUM(C5:C39) | D40: =SUM(D5:D39) | E40: =SUM(E5:E39) | F40: =SUM(F5:F39) | G40: =SUM(G5:G39) | H40: =SUM(H5:H39) | I40: =SUM(I5:I39) | ... M40: =SUM(M5:M39) | N40: =SUM(B40:M40)
A42: COST OF SALES
A43: Credit Card Paid - ADMIN | B43: =SUMIFS(Actuals!$P:$P,Actuals!$A:$A,$A43) | C43: =SUMIFS(Actuals!$Q:$Q,Actuals!$A:$A,$A43) | D43: =SUMIFS(Actuals!$R:$R,Actuals!$A:$A,$A43) | E43: =SUMIFS(Actuals!$S:$S,Actuals!$A:$A,$A43) | F43: =SUMIFS(Actuals!$T:$T,Actuals!$A:$A,$A43) | G43: =SUMIFS(Actuals!$U:$U,Actuals!$A:$A,$A43) | H43: =SUMIFS(Actuals!$V:$V,Actuals!$A:$A,$A43) | I43: =SUMIFS(Actuals!$W:$W,Actuals!$A:$A,$A43) | J43: =SUMIFS(Actuals!$X:$X,Actuals!$A:$A,$A43) | K43: =SUMIFS(Actuals!$Y:$Y,Actuals!$A:$A,$A43) | L43: =SUMIFS(Actuals!$Z:$Z,Actuals!$A:$A,$A43) | M43: =SUMIFS(Actuals!$AA:$AA,Actuals!$A:$A,$A43) | N43: =SUM(B43:M43)
A44: Credit Card Paid - CONS | B44: =SUMIFS(Actuals!$P:$P,Actuals!$A:$A,$A44) | C44: =SUMIFS(Actuals!$Q:$Q,Actuals!$A:$A,$A44) | D44: =SUMIFS(Actuals!$R:$R,Actuals!$A:$A,$A44) | E44: =SUMIFS(Actuals!$S:$S,Actuals!$A:$A,$A44) | F44: =SUMIFS(Actuals!$T:$T,Actuals!$A:$A,$A44) | G44: =SUMIFS(Actuals!$U:$U,Actuals!$A:$A,$A44) | H44: =SUMIFS(Actuals!$V:$V,Actuals!$A:$A,$A44) | I44: =SUMIFS(Actuals!$W:$W,Actuals!$A:$A,$A44) | J44: =SUMIFS(Actuals!$X:$X,Actuals!$A:$A,$A44) | K44: =SUMIFS(Actuals!$Y:$Y,Actuals!$A:$A,$A44) | L44: =SUMIFS(Actuals!$Z:$Z,Actuals!$A:$A,$A44) | M44: =SUMIFS(Actuals!$AA:$AA,Actuals!$A:$A,$A44) | N44: =SUM(B44:M44)
A45: Credit Card Paid - INTEGRATION | B45: =SUMIFS(Actuals!$P:$P,Actuals!$A:$A,$A45) | C45: =SUMIFS(Actuals!$Q:$Q,Actuals!$A:$A,$A45) | D45: =SUMIFS(Actuals!$R:$R,Actuals!$A:$A,$A45) | E45: =SUMIFS(Actuals!$S:$S,Actuals!$A:$A,$A45) | F45: =SUMIFS(Actuals!$T:$T,Actuals!$A:$A,$A45) | G45: =SUMIFS(Actuals!$U:$U,Actuals!$A:$A,$A45) | H45: =SUMIFS(Actuals!$V:$V,Actuals!$A:$A,$A45) | I45: =SUMIFS(Actuals!$W:$W,Actuals!$A:$A,$A45) | J45: =SUMIFS(Actuals!$X:$X,Actuals!$A:$A,$A45) | K45: =SUMIFS(Actuals!$Y:$Y,Actuals!$A:$A,$A45) | L45: =SUMIFS(Actuals!$Z:$Z,Actuals!$A:$A,$A45) | M45: =SUMIFS(Actuals!$AA:$AA,Actuals!$A:$A,$A45) | N45: =SUM(B45:M45)
A46: Credit Card Paid - ONS | B46: =SUMIFS(Actuals!$P:$P,Actuals!$A:$A,$A46) | C46: =SUMIFS(Actuals!$Q:$Q,Actuals!$A:$A,$A46) | D46: =SUMIFS(Actuals!$R:$R,Actuals!$A:$A,$A46) | E46: =SUMIFS(Actuals!$S:$S,Actuals!$A:$A,$A46) | F46: =SUMIFS(Actuals!$T:$T,Actuals!$A:$A,$A46) | G46: =SUMIFS(Actuals!$U:$U,Actuals!$A:$A,$A46) | H46: =SUMIFS(Actuals!$V:$V,Actuals!$A:$A,$A46) | I46: =SUMIFS(Actuals!$W:$W,Actuals!$A:$A,$A46) | J46: =SUMIFS(Actuals!$X:$X,Actuals!$A:$A,$A46) | K46: =SUMIFS(Actuals!$Y:$Y,Actuals!$A:$A,$A46) | L46: =SUMIFS(Actuals!$Z:$Z,Actuals!$A:$A,$A46) | M46: =SUMIFS(Actuals!$AA:$AA,Actuals!$A:$A,$A46) | N46: =SUM(B46:M46)
A47: Credit Card Paid - PRD | B47: =SUMIFS(Actuals!$P:$P,Actuals!$A:$A,$A47) | C47: =SUMIFS(Actuals!$Q:$Q,Actuals!$A:$A,$A47) | D47: =SUMIFS(Actuals!$R:$R,Actuals!$A:$A,$A47) | E47: =SUMIFS(Actuals!$S:$S,Actuals!$A:$A,$A47) | F47: =SUMIFS(Actuals!$T:$T,Actuals!$A:$A,$A47) | G47: =SUMIFS(Actuals!$U:$U,Actuals!$A:$A,$A47) | H47: =SUMIFS(Actuals!$V:$V,Actuals!$A:$A,$A47) | I47: =SUMIFS(Actuals!$W:$W,Actuals!$A:$A,$A47) | J47: =SUMIFS(Actuals!$X:$X,Actuals!$A:$A,$A47) | K47: =SUMIFS(Actuals!$Y:$Y,Actuals!$A:$A,$A47) | L47: =SUMIFS(Actuals!$Z:$Z,Actuals!$A:$A,$A47) | M47: =SUMIFS(Actuals!$AA:$AA,Actuals!$A:$A,$A47) | N47: =SUM(B47:M47)
A48: Credit Card Paid - VID | B48: =SUMIFS(Actuals!$P:$P,Actuals!$A:$A,$A48) | C48: =SUMIFS(Actuals!$Q:$Q,Actuals!$A:$A,$A48) | D48: =SUMIFS(Actuals!$R:$R,Actuals!$A:$A,$A48) | E48: =SUMIFS(Actuals!$S:$S,Actuals!$A:$A,$A48) | F48: =SUMIFS(Actuals!$T:$T,Actuals!$A:$A,$A48) | G48: =SUMIFS(Actuals!$U:$U,Actuals!$A:$A,$A48) | H48: =SUMIFS(Actuals!$V:$V,Actuals!$A:$A,$A48) | I48: =SUMIFS(Actuals!$W:$W,Actuals!$A:$A,$A48) | J48: =SUMIFS(Actuals!$X:$X,Actuals!$A:$A,$A48) | K48: =SUMIFS(Actuals!$Y:$Y,Actuals!$A:$A,$A48) | L48: =SUMIFS(Actuals!$Z:$Z,Actuals!$A:$A,$A48) | M48: =SUMIFS(Actuals!$AA:$AA,Actuals!$A:$A,$A48) | N48: =SUM(B48:M48)
A49: Damage Waiver | B49: =SUMIFS(Actuals!$P:$P,Actuals!$A:$A,$A49) | C49: =SUMIFS(Actuals!$Q:$Q,Actuals!$A:$A,$A49) | D49: =SUMIFS(Actuals!$R:$R,Actuals!$A:$A,$A49) | E49: =SUMIFS(Actuals!$S:$S,Actuals!$A:$A,$A49) | F49: =SUMIFS(Actuals!$T:$T,Actuals!$A:$A,$A49) | G49: =SUMIFS(Actuals!$U:$U,Actuals!$A:$A,$A49) | H49: =SUMIFS(Actuals!$V:$V,Actuals!$A:$A,$A49) | I49: =SUMIFS(Actuals!$W:$W,Actuals!$A:$A,$A49) | J49: =SUMIFS(Actuals!$X:$X,Actuals!$A:$A,$A49) | K49: =SUMIFS(Actuals!$Y:$Y,Actuals!$A:$A,$A49) | L49: =SUMIFS(Actuals!$Z:$Z,Actuals!$A:$A,$A49) | M49: =SUMIFS(Actuals!$AA:$AA,Actuals!$A:$A,$A49) | N49: =SUM(B49:M49)
A50: Direct Freight - ADMIN | B50: =SUMIFS(Actuals!$P:$P,Actuals!$A:$A,$A50) | C50: =SUMIFS(Actuals!$Q:$Q,Actuals!$A:$A,$A50) | D50: =SUMIFS(Actuals!$R:$R,Actuals!$A:$A,$A50) | E50: =SUMIFS(Actuals!$S:$S,Actuals!$A:$A,$A50) | F50: =SUMIFS(Actuals!$T:$T,Actuals!$A:$A,$A50) | G50: =SUMIFS(Actuals!$U:$U,Actuals!$A:$A,$A50) | H50: =SUMIFS(Actuals!$V:$V,Actuals!$A:$A,$A50) | I50: =SUMIFS(Actuals!$W:$W,Actuals!$A:$A,$A50) | J50: =SUMIFS(Actuals!$X:$X,Actuals!$A:$A,$A50) | K50: =SUMIFS(Actuals!$Y:$Y,Actuals!$A:$A,$A50) | L50: =SUMIFS(Actuals!$Z:$Z,Actuals!$A:$A,$A50) | M50: =SUMIFS(Actuals!$AA:$AA,Actuals!$A:$A,$A50) | N50: =SUM(B50:M50)
A51: Direct Freight - CONS | B51: =SUMIFS(Actuals!$P:$P,Actuals!$A:$A,$A51) | C51: =SUMIFS(Actuals!$Q:$Q,Actuals!$A:$A,$A51) | D51: =SUMIFS(Actuals!$R:$R,Actuals!$A:$A,$A51) | E51: =SUMIFS(Actuals!$S:$S,Actuals!$A:$A,$A51) | F51: =SUMIFS(Actuals!$T:$T,Actuals!$A:$A,$A51) | G51: =SUMIFS(Actuals!$U:$U,Actuals!$A:$A,$A51) | H51: =SUMIFS(Actuals!$V:$V,Actuals!$A:$A,$A51) | I51: =SUMIFS(Actuals!$W:$W,Actuals!$A:$A,$A51) | J51: =SUMIFS(Actuals!$X:$X,Actuals!$A:$A,$A51) | K51: =SUMIFS(Actuals!$Y:$Y,Actuals!$A:$A,$A51) | L51: =SUMIFS(Actuals!$Z:$Z,Actuals!$A:$A,$A51) | M51: =SUMIFS(Actuals!$AA:$AA,Actuals!$A:$A,$A51) | N51: =SUM(B51:M51)
A52: Direct Freight - INTEGRATION | B52: =SUMIFS(Actuals!$P:$P,Actuals!$A:$A,$A52) | C52: =SUMIFS(Actuals!$Q:$Q,Actuals!$A:$A,$A52) | D52: =SUMIFS(Actuals!$R:$R,Actuals!$A:$A,$A52) | E52: =SUMIFS(Actuals!$S:$S,Actuals!$A:$A,$A52) | F52: =SUMIFS(Actuals!$T:$T,Actuals!$A:$A,$A52) | G52: =SUMIFS(Actuals!$U:$U,Actuals!$A:$A,$A52) | H52: =SUMIFS(Actuals!$V:$V,Actuals!$A:$A,$A52) | I52: =SUMIFS(Actuals!$W:$W,Actuals!$A:$A,$A52) | J52: =SUMIFS(Actuals!$X:$X,Actuals!$A:$A,$A52) | K52: =SUMIFS(Actuals!$Y:$Y,Actuals!$A:$A,$A52) | L52: =SUMIFS(Actuals!$Z:$Z,Actuals!$A:$A,$A52) | M52: =SUMIFS(Actuals!$AA:$AA,Actuals!$A:$A,$A52) | N52: =SUM(B52:M52)
A53: Direct Freight - ONS | B53: =SUMIFS(Actuals!$P:$P,Actuals!$A:$A,$A53) | C53: =SUMIFS(Actuals!$Q:$Q,Actuals!$A:$A,$A53) | D53: =SUMIFS(Actuals!$R:$R,Actuals!$A:$A,$A53) | E53: =SUMIFS(Actuals!$S:$S,Actuals!$A:$A,$A53) | F53: =SUMIFS(Actuals!$T:$T,Actuals!$A:$A,$A53) | G53: =SUMIFS(Actuals!$U:$U,Actuals!$A:$A,$A53) | H53: =SUMIFS(Actuals!$V:$V,Actuals!$A:$A,$A53) | I53: =SUMIFS(Actuals!$W:$W,Actuals!$A:$A,$A53) | J53: =SUMIFS(Actuals!$X:$X,Actuals!$A:$A,$A53) | K53: =SUMIFS(Actuals!$Y:$Y,Actuals!$A:$A,$A53) | L53: =SUMIFS(Actuals!$Z:$Z,Actuals!$A:$A,$A53) | M53: =SUMIFS(Actuals!$AA:$AA,Actuals!$A:$A,$A53) | N53: =SUM(B53:M53)
A54: Direct Freight - PRD | B54: =SUMIFS(Actuals!$P:$P,Actuals!$A:$A,$A54) | C54: =SUMIFS(Actuals!$Q:$Q,Actuals!$A:$A,$A54) | D54: =SUMIFS(Actuals!$R:$R,Actuals!$A:$A,$A54) | E54: =SUMIFS(Actuals!$S:$S,Actuals!$A:$A,$A54) | F54: =SUMIFS(Actuals!$T:$T,Actuals!$A:$A,$A54) | G54: =SUMIFS(Actuals!$U:$U,Actuals!$A:$A,$A54) | H54: =SUMIFS(Actuals!$V:$V,Actuals!$A:$A,$A54) | I54: =SUMIFS(Actuals!$W:$W,Actuals!$A:$A,$A54) | J54: =SUMIFS(Actuals!$X:$X,Actuals!$A:$A,$A54) | K54: =SUMIFS(Actuals!$Y:$Y,Actuals!$A:$A,$A54) | L54: =SUMIFS(Actuals!$Z:$Z,Actuals!$A:$A,$A54) | M54: =SUMIFS(Actuals!$AA:$AA,Actuals!$A:$A,$A54) | N54: =SUM(B54:M54)
... A108: Supplier Per Diems - VID | B108: =SUMIFS(Actuals!$P:$P,Actuals!$A:$A,$A108) | C108: =SUMIFS(Actuals!$Q:$Q,Actuals!$A:$A,$A108) | D108: =SUMIFS(Actuals!$R:$R,Actuals!$A:$A,$A108) | E108: =SUMIFS(Actuals!$S:$S,Actuals!$A:$A,$A108) | F108: =SUMIFS(Actuals!$T:$T,Actuals!$A:$A,$A108) | G108: =SUMIFS(Actuals!$U:$U,Actuals!$A:$A,$A108) | H108: =SUMIFS(Actuals!$V:$V,Actuals!$A:$A,$A108) | I108: =SUMIFS(Actuals!$W:$W,Actuals!$A:$A,$A108) | J108: =SUMIFS(Actuals!$X:$X,Actuals!$A:$A,$A108) | K108: =SUMIFS(Actuals!$Y:$Y,Actuals!$A:$A,$A108) | L108: =SUMIFS(Actuals!$Z:$Z,Actuals!$A:$A,$A108) | M108: =SUMIFS(Actuals!$AA:$AA,Actuals!$A:$A,$A108) | N108: =SUM(B108:M108)
A109: Total Cost of Sales | B109: =SUM(B43:B108) | C109: =SUM(C43:C108) | D109: =SUM(D43:D108) | E109: =SUM(E43:E108) | F109: =SUM(F43:F108) | G109: =SUM(G43:G108) | H109: =SUM(H43:H108) | I109: =SUM(I43:I108) | ... M109: =SUM(M43:M108) | N109: =SUM(B109:M109)
A111: GROSS PROFIT | B111: =B40-B109 | C111: =C40-C109 | D111: =D40-D109 | E111: =E40-E109 | F111: =F40-F109 | G111: =G40-G109 | H111: =H40-H109 | I111: =I40-I109 | ... M111: =M40-M109 | N111: =SUM(B111:M111)
A112: Gross Profit % | B112: =IFERROR(B111/B40,0) | C112: =IFERROR(C111/C40,0) | D112: =IFERROR(D111/D40,0) | E112: =IFERROR(E111/E40,0) | F112: =IFERROR(F111/F40,0) | G112: =IFERROR(G111/G40,0) | H112: =IFERROR(H111/H40,0) | I112: =IFERROR(I111/I40,0) | ... M112: =IFERROR(M111/M40,0) | N112: =SUM(B112:M112)
A114: OTHER INCOME
A115: Cash Flow Boost | B115: =SUMIFS(Actuals!$P:$P,Actuals!$A:$A,$A115) | C115: =SUMIFS(Actuals!$Q:$Q,Actuals!$A:$A,$A115) | D115: =SUMIFS(Actuals!$R:$R,Actuals!$A:$A,$A115) | E115: =SUMIFS(Actuals!$S:$S,Actuals!$A:$A,$A115) | F115: =SUMIFS(Actuals!$T:$T,Actuals!$A:$A,$A115) | G115: =SUMIFS(Actuals!$U:$U,Actuals!$A:$A,$A115) | H115: =SUMIFS(Actuals!$V:$V,Actuals!$A:$A,$A115) | I115: =SUMIFS(Actuals!$W:$W,Actuals!$A:$A,$A115) | J115: =SUMIFS(Actuals!$X:$X,Actuals!$A:$A,$A115) | K115: =SUMIFS(Actuals!$Y:$Y,Actuals!$A:$A,$A115) | L115: =SUMIFS(Actuals!$Z:$Z,Actuals!$A:$A,$A115) | M115: =SUMIFS(Actuals!$AA:$AA,Actuals!$A:$A,$A115) | N115: =SUM(B115:M115)
A116: Employee FBT Contribtution | B116: =SUMIFS(Actuals!$P:$P,Actuals!$A:$A,$A116) | C116: =SUMIFS(Actuals!$Q:$Q,Actuals!$A:$A,$A116) | D116: =SUMIFS(Actuals!$R:$R,Actuals!$A:$A,$A116) | E116: =SUMIFS(Actuals!$S:$S,Actuals!$A:$A,$A116) | F116: =SUMIFS(Actuals!$T:$T,Actuals!$A:$A,$A116) | G116: =SUMIFS(Actuals!$U:$U,Actuals!$A:$A,$A116) | H116: =SUMIFS(Actuals!$V:$V,Actuals!$A:$A,$A116) | I116: =SUMIFS(Actuals!$W:$W,Actuals!$A:$A,$A116) | J116: =SUMIFS(Actuals!$X:$X,Actuals!$A:$A,$A116) | K116: =SUMIFS(Actuals!$Y:$Y,Actuals!$A:$A,$A116) | L116: =SUMIFS(Actuals!$Z:$Z,Actuals!$A:$A,$A116) | M116: =SUMIFS(Actuals!$AA:$AA,Actuals!$A:$A,$A116) | N116: =SUM(B116:M116)
A117: Gain on lease termination | B117: =SUMIFS(Actuals!$P:$P,Actuals!$A:$A,$A117) | C117: =SUMIFS(Actuals!$Q:$Q,Actuals!$A:$A,$A117) | D117: =SUMIFS(Actuals!$R:$R,Actuals!$A:$A,$A117) | E117: =SUMIFS(Actuals!$S:$S,Actuals!$A:$A,$A117) | F117: =SUMIFS(Actuals!$T:$T,Actuals!$A:$A,$A117) | G117: =SUMIFS(Actuals!$U:$U,Actuals!$A:$A,$A117) | H117: =SUMIFS(Actuals!$V:$V,Actuals!$A:$A,$A117) | I117: =SUMIFS(Actuals!$W:$W,Actuals!$A:$A,$A117) | J117: =SUMIFS(Actuals!$X:$X,Actuals!$A:$A,$A117) | K117: =SUMIFS(Actuals!$Y:$Y,Actuals!$A:$A,$A117) | L117: =SUMIFS(Actuals!$Z:$Z,Actuals!$A:$A,$A117) | M117: =SUMIFS(Actuals!$AA:$AA,Actuals!$A:$A,$A117) | N117: =SUM(B117:M117)
A118: Income Other | B118: =SUMIFS(Actuals!$P:$P,Actuals!$A:$A,$A118) | C118: =SUMIFS(Actuals!$Q:$Q,Actuals!$A:$A,$A118) | D118: =SUMIFS(Actuals!$R:$R,Actuals!$A:$A,$A118) | E118: =SUMIFS(Actuals!$S:$S,Actuals!$A:$A,$A118) | F118: =SUMIFS(Actuals!$T:$T,Actuals!$A:$A,$A118) | G118: =SUMIFS(Actuals!$U:$U,Actuals!$A:$A,$A118) | H118: =SUMIFS(Actuals!$V:$V,Actuals!$A:$A,$A118) | I118: =SUMIFS(Actuals!$W:$W,Actuals!$A:$A,$A118) | J118: =SUMIFS(Actuals!$X:$X,Actuals!$A:$A,$A118) | K118: =SUMIFS(Actuals!$Y:$Y,Actuals!$A:$A,$A118) | L118: =SUMIFS(Actuals!$Z:$Z,Actuals!$A:$A,$A118) | M118: =SUMIFS(Actuals!$AA:$AA,Actuals!$A:$A,$A118) | N118: =SUM(B118:M118)
...

Sheet Last Year
A1: Last Year: FY26 Profit & Loss
A2: Calculated from the Actuals sheet. Do not type here.
A3: Account | B3: Jul-25 | C3: Aug-25 | D3: Sep-25 | E3: Oct-25 | F3: Nov-25 | G3: Dec-25 | H3: Jan-26 | I3: Feb-26 | J3: Mar-26 | K3: Apr-26 | L3: May-26 | M3: Jun-26 | N3: FY26 Total
A4: INCOME
A5: Ad Hoc Service Labour | B5: =SUMIFS(Actuals!$D:$D,Actuals!$A:$A,$A5) | C5: =SUMIFS(Actuals!$E:$E,Actuals!$A:$A,$A5) | D5: =SUMIFS(Actuals!$F:$F,Actuals!$A:$A,$A5) | E5: =SUMIFS(Actuals!$G:$G,Actuals!$A:$A,$A5) | F5: =SUMIFS(Actuals!$H:$H,Actuals!$A:$A,$A5) | G5: =SUMIFS(Actuals!$I:$I,Actuals!$A:$A,$A5) | H5: =SUMIFS(Actuals!$J:$J,Actuals!$A:$A,$A5) | I5: =SUMIFS(Actuals!$K:$K,Actuals!$A:$A,$A5) | J5: =SUMIFS(Actuals!$L:$L,Actuals!$A:$A,$A5) | K5: =SUMIFS(Actuals!$M:$M,Actuals!$A:$A,$A5) | L5: =SUMIFS(Actuals!$N:$N,Actuals!$A:$A,$A5) | M5: =SUMIFS(Actuals!$O:$O,Actuals!$A:$A,$A5) | N5: =SUM(B5:M5)
A6: Closing Work in Progress | B6: =SUMIFS(Actuals!$D:$D,Actuals!$A:$A,$A6) | C6: =SUMIFS(Actuals!$E:$E,Actuals!$A:$A,$A6) | D6: =SUMIFS(Actuals!$F:$F,Actuals!$A:$A,$A6) | E6: =SUMIFS(Actuals!$G:$G,Actuals!$A:$A,$A6) | F6: =SUMIFS(Actuals!$H:$H,Actuals!$A:$A,$A6) | G6: =SUMIFS(Actuals!$I:$I,Actuals!$A:$A,$A6) | H6: =SUMIFS(Actuals!$J:$J,Actuals!$A:$A,$A6) | I6: =SUMIFS(Actuals!$K:$K,Actuals!$A:$A,$A6) | J6: =SUMIFS(Actuals!$L:$L,Actuals!$A:$A,$A6) | K6: =SUMIFS(Actuals!$M:$M,Actuals!$A:$A,$A6) | L6: =SUMIFS(Actuals!$N:$N,Actuals!$A:$A,$A6) | M6: =SUMIFS(Actuals!$O:$O,Actuals!$A:$A,$A6) | N6: =SUM(B6:M6)
A7: Conference Call Charge | B7: =SUMIFS(Actuals!$D:$D,Actuals!$A:$A,$A7) | C7: =SUMIFS(Actuals!$E:$E,Actuals!$A:$A,$A7) | D7: =SUMIFS(Actuals!$F:$F,Actuals!$A:$A,$A7) | E7: =SUMIFS(Actuals!$G:$G,Actuals!$A:$A,$A7) | F7: =SUMIFS(Actuals!$H:$H,Actuals!$A:$A,$A7) | G7: =SUMIFS(Actuals!$I:$I,Actuals!$A:$A,$A7) | H7: =SUMIFS(Actuals!$J:$J,Actuals!$A:$A,$A7) | I7: =SUMIFS(Actuals!$K:$K,Actuals!$A:$A,$A7) | J7: =SUMIFS(Actuals!$L:$L,Actuals!$A:$A,$A7) | K7: =SUMIFS(Actuals!$M:$M,Actuals!$A:$A,$A7) | L7: =SUMIFS(Actuals!$N:$N,Actuals!$A:$A,$A7) | M7: =SUMIFS(Actuals!$O:$O,Actuals!$A:$A,$A7) | N7: =SUM(B7:M7)
A8: Contract Help Desk | B8: =SUMIFS(Actuals!$D:$D,Actuals!$A:$A,$A8) | C8: =SUMIFS(Actuals!$E:$E,Actuals!$A:$A,$A8) | D8: =SUMIFS(Actuals!$F:$F,Actuals!$A:$A,$A8) | E8: =SUMIFS(Actuals!$G:$G,Actuals!$A:$A,$A8) | F8: =SUMIFS(Actuals!$H:$H,Actuals!$A:$A,$A8) | G8: =SUMIFS(Actuals!$I:$I,Actuals!$A:$A,$A8) | H8: =SUMIFS(Actuals!$J:$J,Actuals!$A:$A,$A8) | I8: =SUMIFS(Actuals!$K:$K,Actuals!$A:$A,$A8) | J8: =SUMIFS(Actuals!$L:$L,Actuals!$A:$A,$A8) | K8: =SUMIFS(Actuals!$M:$M,Actuals!$A:$A,$A8) | L8: =SUMIFS(Actuals!$N:$N,Actuals!$A:$A,$A8) | M8: =SUMIFS(Actuals!$O:$O,Actuals!$A:$A,$A8) | N8: =SUM(B8:M8)
A9: Contract Maintenance | B9: =SUMIFS(Actuals!$D:$D,Actuals!$A:$A,$A9) | C9: =SUMIFS(Actuals!$E:$E,Actuals!$A:$A,$A9) | D9: =SUMIFS(Actuals!$F:$F,Actuals!$A:$A,$A9) | E9: =SUMIFS(Actuals!$G:$G,Actuals!$A:$A,$A9) | F9: =SUMIFS(Actuals!$H:$H,Actuals!$A:$A,$A9) | G9: =SUMIFS(Actuals!$I:$I,Actuals!$A:$A,$A9) | H9: =SUMIFS(Actuals!$J:$J,Actuals!$A:$A,$A9) | I9: =SUMIFS(Actuals!$K:$K,Actuals!$A:$A,$A9) | J9: =SUMIFS(Actuals!$L:$L,Actuals!$A:$A,$A9) | K9: =SUMIFS(Actuals!$M:$M,Actuals!$A:$A,$A9) | L9: =SUMIFS(Actuals!$N:$N,Actuals!$A:$A,$A9) | M9: =SUMIFS(Actuals!$O:$O,Actuals!$A:$A,$A9) | N9: =SUM(B9:M9)
A10: Contract Support Staff | B10: =SUMIFS(Actuals!$D:$D,Actuals!$A:$A,$A10) | C10: =SUMIFS(Actuals!$E:$E,Actuals!$A:$A,$A10) | D10: =SUMIFS(Actuals!$F:$F,Actuals!$A:$A,$A10) | E10: =SUMIFS(Actuals!$G:$G,Actuals!$A:$A,$A10) | F10: =SUMIFS(Actuals!$H:$H,Actuals!$A:$A,$A10) | G10: =SUMIFS(Actuals!$I:$I,Actuals!$A:$A,$A10) | H10: =SUMIFS(Actuals!$J:$J,Actuals!$A:$A,$A10) | I10: =SUMIFS(Actuals!$K:$K,Actuals!$A:$A,$A10) | J10: =SUMIFS(Actuals!$L:$L,Actuals!$A:$A,$A10) | K10: =SUMIFS(Actuals!$M:$M,Actuals!$A:$A,$A10) | L10: =SUMIFS(Actuals!$N:$N,Actuals!$A:$A,$A10) | M10: =SUMIFS(Actuals!$O:$O,Actuals!$A:$A,$A10) | N10: =SUM(B10:M10)
A11: Credit Card Collected - CONS | B11: =SUMIFS(Actuals!$D:$D,Actuals!$A:$A,$A11) | C11: =SUMIFS(Actuals!$E:$E,Actuals!$A:$A,$A11) | D11: =SUMIFS(Actuals!$F:$F,Actuals!$A:$A,$A11) | E11: =SUMIFS(Actuals!$G:$G,Actuals!$A:$A,$A11) | F11: =SUMIFS(Actuals!$H:$H,Actuals!$A:$A,$A11) | G11: =SUMIFS(Actuals!$I:$I,Actuals!$A:$A,$A11) | H11: =SUMIFS(Actuals!$J:$J,Actuals!$A:$A,$A11) | I11: =SUMIFS(Actuals!$K:$K,Actuals!$A:$A,$A11) | J11: =SUMIFS(Actuals!$L:$L,Actuals!$A:$A,$A11) | K11: =SUMIFS(Actuals!$M:$M,Actuals!$A:$A,$A11) | L11: =SUMIFS(Actuals!$N:$N,Actuals!$A:$A,$A11) | M11: =SUMIFS(Actuals!$O:$O,Actuals!$A:$A,$A11) | N11: =SUM(B11:M11)
A12: Credit Card Collected - ONS | B12: =SUMIFS(Actuals!$D:$D,Actuals!$A:$A,$A12) | C12: =SUMIFS(Actuals!$E:$E,Actuals!$A:$A,$A12) | D12: =SUMIFS(Actuals!$F:$F,Actuals!$A:$A,$A12) | E12: =SUMIFS(Actuals!$G:$G,Actuals!$A:$A,$A12) | F12: =SUMIFS(Actuals!$H:$H,Actuals!$A:$A,$A12) | G12: =SUMIFS(Actuals!$I:$I,Actuals!$A:$A,$A12) | H12: =SUMIFS(Actuals!$J:$J,Actuals!$A:$A,$A12) | I12: =SUMIFS(Actuals!$K:$K,Actuals!$A:$A,$A12) | J12: =SUMIFS(Actuals!$L:$L,Actuals!$A:$A,$A12) | K12: =SUMIFS(Actuals!$M:$M,Actuals!$A:$A,$A12) | L12: =SUMIFS(Actuals!$N:$N,Actuals!$A:$A,$A12) | M12: =SUMIFS(Actuals!$O:$O,Actuals!$A:$A,$A12) | N12: =SUM(B12:M12)
A13: Credit Card Collected - PRD | B13: =SUMIFS(Actuals!$D:$D,Actuals!$A:$A,$A13) | C13: =SUMIFS(Actuals!$E:$E,Actuals!$A:$A,$A13) | D13: =SUMIFS(Actuals!$F:$F,Actuals!$A:$A,$A13) | E13: =SUMIFS(Actuals!$G:$G,Actuals!$A:$A,$A13) | F13: =SUMIFS(Actuals!$H:$H,Actuals!$A:$A,$A13) | G13: =SUMIFS(Actuals!$I:$I,Actuals!$A:$A,$A13) | H13: =SUMIFS(Actuals!$J:$J,Actuals!$A:$A,$A13) | I13: =SUMIFS(Actuals!$K:$K,Actuals!$A:$A,$A13) | J13: =SUMIFS(Actuals!$L:$L,Actuals!$A:$A,$A13) | K13: =SUMIFS(Actuals!$M:$M,Actuals!$A:$A,$A13) | L13: =SUMIFS(Actuals!$N:$N,Actuals!$A:$A,$A13) | M13: =SUMIFS(Actuals!$O:$O,Actuals!$A:$A,$A13) | N13: =SUM(B13:M13)
A14: Credit Card Collected - VID | B14: =SUMIFS(Actuals!$D:$D,Actuals!$A:$A,$A14) | C14: =SUMIFS(Actuals!$E:$E,Actuals!$A:$A,$A14) | D14: =SUMIFS(Actuals!$F:$F,Actuals!$A:$A,$A14) | E14: =SUMIFS(Actuals!$G:$G,Actuals!$A:$A,$A14) | F14: =SUMIFS(Actuals!$H:$H,Actuals!$A:$A,$A14) | G14: =SUMIFS(Actuals!$I:$I,Actuals!$A:$A,$A14) | H14: =SUMIFS(Actuals!$J:$J,Actuals!$A:$A,$A14) | I14: =SUMIFS(Actuals!$K:$K,Actuals!$A:$A,$A14) | J14: =SUMIFS(Actuals!$L:$L,Actuals!$A:$A,$A14) | K14: =SUMIFS(Actuals!$M:$M,Actuals!$A:$A,$A14) | L14: =SUMIFS(Actuals!$N:$N,Actuals!$A:$A,$A14) | M14: =SUMIFS(Actuals!$O:$O,Actuals!$A:$A,$A14) | N14: =SUM(B14:M14)
A15: Credit Card Collected-INTEGRATION | B15: =SUMIFS(Actuals!$D:$D,Actuals!$A:$A,$A15) | C15: =SUMIFS(Actuals!$E:$E,Actuals!$A:$A,$A15) | D15: =SUMIFS(Actuals!$F:$F,Actuals!$A:$A,$A15) | E15: =SUMIFS(Actuals!$G:$G,Actuals!$A:$A,$A15) | F15: =SUMIFS(Actuals!$H:$H,Actuals!$A:$A,$A15) | G15: =SUMIFS(Actuals!$I:$I,Actuals!$A:$A,$A15) | H15: =SUMIFS(Actuals!$J:$J,Actuals!$A:$A,$A15) | I15: =SUMIFS(Actuals!$K:$K,Actuals!$A:$A,$A15) | J15: =SUMIFS(Actuals!$L:$L,Actuals!$A:$A,$A15) | K15: =SUMIFS(Actuals!$M:$M,Actuals!$A:$A,$A15) | L15: =SUMIFS(Actuals!$N:$N,Actuals!$A:$A,$A15) | M15: =SUMIFS(Actuals!$O:$O,Actuals!$A:$A,$A15) | N15: =SUM(B15:M15)
A16: Credit Card Fees - ADMIN | B16: =SUMIFS(Actuals!$D:$D,Actuals!$A:$A,$A16) | C16: =SUMIFS(Actuals!$E:$E,Actuals!$A:$A,$A16) | D16: =SUMIFS(Actuals!$F:$F,Actuals!$A:$A,$A16) | E16: =SUMIFS(Actuals!$G:$G,Actuals!$A:$A,$A16) | F16: =SUMIFS(Actuals!$H:$H,Actuals!$A:$A,$A16) | G16: =SUMIFS(Actuals!$I:$I,Actuals!$A:$A,$A16) | H16: =SUMIFS(Actuals!$J:$J,Actuals!$A:$A,$A16) | I16: =SUMIFS(Actuals!$K:$K,Actuals!$A:$A,$A16) | J16: =SUMIFS(Actuals!$L:$L,Actuals!$A:$A,$A16) | K16: =SUMIFS(Actuals!$M:$M,Actuals!$A:$A,$A16) | L16: =SUMIFS(Actuals!$N:$N,Actuals!$A:$A,$A16) | M16: =SUMIFS(Actuals!$O:$O,Actuals!$A:$A,$A16) | N16: =SUM(B16:M16)
... A39: Video Labour | B39: =SUMIFS(Actuals!$D:$D,Actuals!$A:$A,$A39) | C39: =SUMIFS(Actuals!$E:$E,Actuals!$A:$A,$A39) | D39: =SUMIFS(Actuals!$F:$F,Actuals!$A:$A,$A39) | E39: =SUMIFS(Actuals!$G:$G,Actuals!$A:$A,$A39) | F39: =SUMIFS(Actuals!$H:$H,Actuals!$A:$A,$A39) | G39: =SUMIFS(Actuals!$I:$I,Actuals!$A:$A,$A39) | H39: =SUMIFS(Actuals!$J:$J,Actuals!$A:$A,$A39) | I39: =SUMIFS(Actuals!$K:$K,Actuals!$A:$A,$A39) | J39: =SUMIFS(Actuals!$L:$L,Actuals!$A:$A,$A39) | K39: =SUMIFS(Actuals!$M:$M,Actuals!$A:$A,$A39) | L39: =SUMIFS(Actuals!$N:$N,Actuals!$A:$A,$A39) | M39: =SUMIFS(Actuals!$O:$O,Actuals!$A:$A,$A39) | N39: =SUM(B39:M39)
A40: Total Income | B40: =SUM(B5:B39) | C40: =SUM(C5:C39) | D40: =SUM(D5:D39) | E40: =SUM(E5:E39) | F40: =SUM(F5:F39) | G40: =SUM(G5:G39) | H40: =SUM(H5:H39) | I40: =SUM(I5:I39) | ... M40: =SUM(M5:M39) | N40: =SUM(B40:M40)
A42: COST OF SALES
A43: Credit Card Paid - ADMIN | B43: =SUMIFS(Actuals!$D:$D,Actuals!$A:$A,$A43) | C43: =SUMIFS(Actuals!$E:$E,Actuals!$A:$A,$A43) | D43: =SUMIFS(Actuals!$F:$F,Actuals!$A:$A,$A43) | E43: =SUMIFS(Actuals!$G:$G,Actuals!$A:$A,$A43) | F43: =SUMIFS(Actuals!$H:$H,Actuals!$A:$A,$A43) | G43: =SUMIFS(Actuals!$I:$I,Actuals!$A:$A,$A43) | H43: =SUMIFS(Actuals!$J:$J,Actuals!$A:$A,$A43) | I43: =SUMIFS(Actuals!$K:$K,Actuals!$A:$A,$A43) | J43: =SUMIFS(Actuals!$L:$L,Actuals!$A:$A,$A43) | K43: =SUMIFS(Actuals!$M:$M,Actuals!$A:$A,$A43) | L43: =SUMIFS(Actuals!$N:$N,Actuals!$A:$A,$A43) | M43: =SUMIFS(Actuals!$O:$O,Actuals!$A:$A,$A43) | N43: =SUM(B43:M43)
A44: Credit Card Paid - CONS | B44: =SUMIFS(Actuals!$D:$D,Actuals!$A:$A,$A44) | C44: =SUMIFS(Actuals!$E:$E,Actuals!$A:$A,$A44) | D44: =SUMIFS(Actuals!$F:$F,Actuals!$A:$A,$A44) | E44: =SUMIFS(Actuals!$G:$G,Actuals!$A:$A,$A44) | F44: =SUMIFS(Actuals!$H:$H,Actuals!$A:$A,$A44) | G44: =SUMIFS(Actuals!$I:$I,Actuals!$A:$A,$A44) | H44: =SUMIFS(Actuals!$J:$J,Actuals!$A:$A,$A44) | I44: =SUMIFS(Actuals!$K:$K,Actuals!$A:$A,$A44) | J44: =SUMIFS(Actuals!$L:$L,Actuals!$A:$A,$A44) | K44: =SUMIFS(Actuals!$M:$M,Actuals!$A:$A,$A44) | L44: =SUMIFS(Actuals!$N:$N,Actuals!$A:$A,$A44) | M44: =SUMIFS(Actuals!$O:$O,Actuals!$A:$A,$A44) | N44: =SUM(B44:M44)
A45: Credit Card Paid - INTEGRATION | B45: =SUMIFS(Actuals!$D:$D,Actuals!$A:$A,$A45) | C45: =SUMIFS(Actuals!$E:$E,Actuals!$A:$A,$A45) | D45: =SUMIFS(Actuals!$F:$F,Actuals!$A:$A,$A45) | E45: =SUMIFS(Actuals!$G:$G,Actuals!$A:$A,$A45) | F45: =SUMIFS(Actuals!$H:$H,Actuals!$A:$A,$A45) | G45: =SUMIFS(Actuals!$I:$I,Actuals!$A:$A,$A45) | H45: =SUMIFS(Actuals!$J:$J,Actuals!$A:$A,$A45) | I45: =SUMIFS(Actuals!$K:$K,Actuals!$A:$A,$A45) | J45: =SUMIFS(Actuals!$L:$L,Actuals!$A:$A,$A45) | K45: =SUMIFS(Actuals!$M:$M,Actuals!$A:$A,$A45) | L45: =SUMIFS(Actuals!$N:$N,Actuals!$A:$A,$A45) | M45: =SUMIFS(Actuals!$O:$O,Actuals!$A:$A,$A45) | N45: =SUM(B45:M45)
A46: Credit Card Paid - ONS | B46: =SUMIFS(Actuals!$D:$D,Actuals!$A:$A,$A46) | C46: =SUMIFS(Actuals!$E:$E,Actuals!$A:$A,$A46) | D46: =SUMIFS(Actuals!$F:$F,Actuals!$A:$A,$A46) | E46: =SUMIFS(Actuals!$G:$G,Actuals!$A:$A,$A46) | F46: =SUMIFS(Actuals!$H:$H,Actuals!$A:$A,$A46) | G46: =SUMIFS(Actuals!$I:$I,Actuals!$A:$A,$A46) | H46: =SUMIFS(Actuals!$J:$J,Actuals!$A:$A,$A46) | I46: =SUMIFS(Actuals!$K:$K,Actuals!$A:$A,$A46) | J46: =SUMIFS(Actuals!$L:$L,Actuals!$A:$A,$A46) | K46: =SUMIFS(Actuals!$M:$M,Actuals!$A:$A,$A46) | L46: =SUMIFS(Actuals!$N:$N,Actuals!$A:$A,$A46) | M46: =SUMIFS(Actuals!$O:$O,Actuals!$A:$A,$A46) | N46: =SUM(B46:M46)
A47: Credit Card Paid - PRD | B47: =SUMIFS(Actuals!$D:$D,Actuals!$A:$A,$A47) | C47: =SUMIFS(Actuals!$E:$E,Actuals!$A:$A,$A47) | D47: =SUMIFS(Actuals!$F:$F,Actuals!$A:$A,$A47) | E47: =SUMIFS(Actuals!$G:$G,Actuals!$A:$A,$A47) | F47: =SUMIFS(Actuals!$H:$H,Actuals!$A:$A,$A47) | G47: =SUMIFS(Actuals!$I:$I,Actuals!$A:$A,$A47) | H47: =SUMIFS(Actuals!$J:$J,Actuals!$A:$A,$A47) | I47: =SUMIFS(Actuals!$K:$K,Actuals!$A:$A,$A47) | J47: =SUMIFS(Actuals!$L:$L,Actuals!$A:$A,$A47) | K47: =SUMIFS(Actuals!$M:$M,Actuals!$A:$A,$A47) | L47: =SUMIFS(Actuals!$N:$N,Actuals!$A:$A,$A47) | M47: =SUMIFS(Actuals!$O:$O,Actuals!$A:$A,$A47) | N47: =SUM(B47:M47)
A48: Credit Card Paid - VID | B48: =SUMIFS(Actuals!$D:$D,Actuals!$A:$A,$A48) | C48: =SUMIFS(Actuals!$E:$E,Actuals!$A:$A,$A48) | D48: =SUMIFS(Actuals!$F:$F,Actuals!$A:$A,$A48) | E48: =SUMIFS(Actuals!$G:$G,Actuals!$A:$A,$A48) | F48: =SUMIFS(Actuals!$H:$H,Actuals!$A:$A,$A48) | G48: =SUMIFS(Actuals!$I:$I,Actuals!$A:$A,$A48) | H48: =SUMIFS(Actuals!$J:$J,Actuals!$A:$A,$A48) | I48: =SUMIFS(Actuals!$K:$K,Actuals!$A:$A,$A48) | J48: =SUMIFS(Actuals!$L:$L,Actuals!$A:$A,$A48) | K48: =SUMIFS(Actuals!$M:$M,Actuals!$A:$A,$A48) | L48: =SUMIFS(Actuals!$N:$N,Actuals!$A:$A,$A48) | M48: =SUMIFS(Actuals!$O:$O,Actuals!$A:$A,$A48) | N48: =SUM(B48:M48)
A49: Damage Waiver | B49: =SUMIFS(Actuals!$D:$D,Actuals!$A:$A,$A49) | C49: =SUMIFS(Actuals!$E:$E,Actuals!$A:$A,$A49) | D49: =SUMIFS(Actuals!$F:$F,Actuals!$A:$A,$A49) | E49: =SUMIFS(Actuals!$G:$G,Actuals!$A:$A,$A49) | F49: =SUMIFS(Actuals!$H:$H,Actuals!$A:$A,$A49) | G49: =SUMIFS(Actuals!$I:$I,Actuals!$A:$A,$A49) | H49: =SUMIFS(Actuals!$J:$J,Actuals!$A:$A,$A49) | I49: =SUMIFS(Actuals!$K:$K,Actuals!$A:$A,$A49) | J49: =SUMIFS(Actuals!$L:$L,Actuals!$A:$A,$A49) | K49: =SUMIFS(Actuals!$M:$M,Actuals!$A:$A,$A49) | L49: =SUMIFS(Actuals!$N:$N,Actuals!$A:$A,$A49) | M49: =SUMIFS(Actuals!$O:$O,Actuals!$A:$A,$A49) | N49: =SUM(B49:M49)
A50: Direct Freight - ADMIN | B50: =SUMIFS(Actuals!$D:$D,Actuals!$A:$A,$A50) | C50: =SUMIFS(Actuals!$E:$E,Actuals!$A:$A,$A50) | D50: =SUMIFS(Actuals!$F:$F,Actuals!$A:$A,$A50) | E50: =SUMIFS(Actuals!$G:$G,Actuals!$A:$A,$A50) | F50: =SUMIFS(Actuals!$H:$H,Actuals!$A:$A,$A50) | G50: =SUMIFS(Actuals!$I:$I,Actuals!$A:$A,$A50) | H50: =SUMIFS(Actuals!$J:$J,Actuals!$A:$A,$A50) | I50: =SUMIFS(Actuals!$K:$K,Actuals!$A:$A,$A50) | J50: =SUMIFS(Actuals!$L:$L,Actuals!$A:$A,$A50) | K50: =SUMIFS(Actuals!$M:$M,Actuals!$A:$A,$A50) | L50: =SUMIFS(Actuals!$N:$N,Actuals!$A:$A,$A50) | M50: =SUMIFS(Actuals!$O:$O,Actuals!$A:$A,$A50) | N50: =SUM(B50:M50)
A51: Direct Freight - CONS | B51: =SUMIFS(Actuals!$D:$D,Actuals!$A:$A,$A51) | C51: =SUMIFS(Actuals!$E:$E,Actuals!$A:$A,$A51) | D51: =SUMIFS(Actuals!$F:$F,Actuals!$A:$A,$A51) | E51: =SUMIFS(Actuals!$G:$G,Actuals!$A:$A,$A51) | F51: =SUMIFS(Actuals!$H:$H,Actuals!$A:$A,$A51) | G51: =SUMIFS(Actuals!$I:$I,Actuals!$A:$A,$A51) | H51: =SUMIFS(Actuals!$J:$J,Actuals!$A:$A,$A51) | I51: =SUMIFS(Actuals!$K:$K,Actuals!$A:$A,$A51) | J51: =SUMIFS(Actuals!$L:$L,Actuals!$A:$A,$A51) | K51: =SUMIFS(Actuals!$M:$M,Actuals!$A:$A,$A51) | L51: =SUMIFS(Actuals!$N:$N,Actuals!$A:$A,$A51) | M51: =SUMIFS(Actuals!$O:$O,Actuals!$A:$A,$A51) | N51: =SUM(B51:M51)
A52: Direct Freight - INTEGRATION | B52: =SUMIFS(Actuals!$D:$D,Actuals!$A:$A,$A52) | C52: =SUMIFS(Actuals!$E:$E,Actuals!$A:$A,$A52) | D52: =SUMIFS(Actuals!$F:$F,Actuals!$A:$A,$A52) | E52: =SUMIFS(Actuals!$G:$G,Actuals!$A:$A,$A52) | F52: =SUMIFS(Actuals!$H:$H,Actuals!$A:$A,$A52) | G52: =SUMIFS(Actuals!$I:$I,Actuals!$A:$A,$A52) | H52: =SUMIFS(Actuals!$J:$J,Actuals!$A:$A,$A52) | I52: =SUMIFS(Actuals!$K:$K,Actuals!$A:$A,$A52) | J52: =SUMIFS(Actuals!$L:$L,Actuals!$A:$A,$A52) | K52: =SUMIFS(Actuals!$M:$M,Actuals!$A:$A,$A52) | L52: =SUMIFS(Actuals!$N:$N,Actuals!$A:$A,$A52) | M52: =SUMIFS(Actuals!$O:$O,Actuals!$A:$A,$A52) | N52: =SUM(B52:M52)
A53: Direct Freight - ONS | B53: =SUMIFS(Actuals!$D:$D,Actuals!$A:$A,$A53) | C53: =SUMIFS(Actuals!$E:$E,Actuals!$A:$A,$A53) | D53: =SUMIFS(Actuals!$F:$F,Actuals!$A:$A,$A53) | E53: =SUMIFS(Actuals!$G:$G,Actuals!$A:$A,$A53) | F53: =SUMIFS(Actuals!$H:$H,Actuals!$A:$A,$A53) | G53: =SUMIFS(Actuals!$I:$I,Actuals!$A:$A,$A53) | H53: =SUMIFS(Actuals!$J:$J,Actuals!$A:$A,$A53) | I53: =SUMIFS(Actuals!$K:$K,Actuals!$A:$A,$A53) | J53: =SUMIFS(Actuals!$L:$L,Actuals!$A:$A,$A53) | K53: =SUMIFS(Actuals!$M:$M,Actuals!$A:$A,$A53) | L53: =SUMIFS(Actuals!$N:$N,Actuals!$A:$A,$A53) | M53: =SUMIFS(Actuals!$O:$O,Actuals!$A:$A,$A53) | N53: =SUM(B53:M53)
A54: Direct Freight - PRD | B54: =SUMIFS(Actuals!$D:$D,Actuals!$A:$A,$A54) | C54: =SUMIFS(Actuals!$E:$E,Actuals!$A:$A,$A54) | D54: =SUMIFS(Actuals!$F:$F,Actuals!$A:$A,$A54) | E54: =SUMIFS(Actuals!$G:$G,Actuals!$A:$A,$A54) | F54: =SUMIFS(Actuals!$H:$H,Actuals!$A:$A,$A54) | G54: =SUMIFS(Actuals!$I:$I,Actuals!$A:$A,$A54) | H54: =SUMIFS(Actuals!$J:$J,Actuals!$A:$A,$A54) | I54: =SUMIFS(Actuals!$K:$K,Actuals!$A:$A,$A54) | J54: =SUMIFS(Actuals!$L:$L,Actuals!$A:$A,$A54) | K54: =SUMIFS(Actuals!$M:$M,Actuals!$A:$A,$A54) | L54: =SUMIFS(Actuals!$N:$N,Actuals!$A:$A,$A54) | M54: =SUMIFS(Actuals!$O:$O,Actuals!$A:$A,$A54) | N54: =SUM(B54:M54)
... A108: Supplier Per Diems - VID | B108: =SUMIFS(Actuals!$D:$D,Actuals!$A:$A,$A108) | C108: =SUMIFS(Actuals!$E:$E,Actuals!$A:$A,$A108) | D108: =SUMIFS(Actuals!$F:$F,Actuals!$A:$A,$A108) | E108: =SUMIFS(Actuals!$G:$G,Actuals!$A:$A,$A108) | F108: =SUMIFS(Actuals!$H:$H,Actuals!$A:$A,$A108) | G108: =SUMIFS(Actuals!$I:$I,Actuals!$A:$A,$A108) | H108: =SUMIFS(Actuals!$J:$J,Actuals!$A:$A,$A108) | I108: =SUMIFS(Actuals!$K:$K,Actuals!$A:$A,$A108) | J108: =SUMIFS(Actuals!$L:$L,Actuals!$A:$A,$A108) | K108: =SUMIFS(Actuals!$M:$M,Actuals!$A:$A,$A108) | L108: =SUMIFS(Actuals!$N:$N,Actuals!$A:$A,$A108) | M108: =SUMIFS(Actuals!$O:$O,Actuals!$A:$A,$A108) | N108: =SUM(B108:M108)
A109: Total Cost of Sales | B109: =SUM(B43:B108) | C109: =SUM(C43:C108) | D109: =SUM(D43:D108) | E109: =SUM(E43:E108) | F109: =SUM(F43:F108) | G109: =SUM(G43:G108) | H109: =SUM(H43:H108) | I109: =SUM(I43:I108) | ... M109: =SUM(M43:M108) | N109: =SUM(B109:M109)
A111: GROSS PROFIT | B111: =B40-B109 | C111: =C40-C109 | D111: =D40-D109 | E111: =E40-E109 | F111: =F40-F109 | G111: =G40-G109 | H111: =H40-H109 | I111: =I40-I109 | ... M111: =M40-M109 | N111: =SUM(B111:M111)
A112: Gross Profit % | B112: =IFERROR(B111/B40,0) | C112: =IFERROR(C111/C40,0) | D112: =IFERROR(D111/D40,0) | E112: =IFERROR(E111/E40,0) | F112: =IFERROR(F111/F40,0) | G112: =IFERROR(G111/G40,0) | H112: =IFERROR(H111/H40,0) | I112: =IFERROR(I111/I40,0) | ... M112: =IFERROR(M111/M40,0) | N112: =SUM(B112:M112)
A114: OTHER INCOME
A115: Cash Flow Boost | B115: =SUMIFS(Actuals!$D:$D,Actuals!$A:$A,$A115) | C115: =SUMIFS(Actuals!$E:$E,Actuals!$A:$A,$A115) | D115: =SUMIFS(Actuals!$F:$F,Actuals!$A:$A,$A115) | E115: =SUMIFS(Actuals!$G:$G,Actuals!$A:$A,$A115) | F115: =SUMIFS(Actuals!$H:$H,Actuals!$A:$A,$A115) | G115: =SUMIFS(Actuals!$I:$I,Actuals!$A:$A,$A115) | H115: =SUMIFS(Actuals!$J:$J,Actuals!$A:$A,$A115) | I115: =SUMIFS(Actuals!$K:$K,Actuals!$A:$A,$A115) | J115: =SUMIFS(Actuals!$L:$L,Actuals!$A:$A,$A115) | K115: =SUMIFS(Actuals!$M:$M,Actuals!$A:$A,$A115) | L115: =SUMIFS(Actuals!$N:$N,Actuals!$A:$A,$A115) | M115: =SUMIFS(Actuals!$O:$O,Actuals!$A:$A,$A115) | N115: =SUM(B115:M115)
A116: Employee FBT Contribtution | B116: =SUMIFS(Actuals!$D:$D,Actuals!$A:$A,$A116) | C116: =SUMIFS(Actuals!$E:$E,Actuals!$A:$A,$A116) | D116: =SUMIFS(Actuals!$F:$F,Actuals!$A:$A,$A116) | E116: =SUMIFS(Actuals!$G:$G,Actuals!$A:$A,$A116) | F116: =SUMIFS(Actuals!$H:$H,Actuals!$A:$A,$A116) | G116: =SUMIFS(Actuals!$I:$I,Actuals!$A:$A,$A116) | H116: =SUMIFS(Actuals!$J:$J,Actuals!$A:$A,$A116) | I116: =SUMIFS(Actuals!$K:$K,Actuals!$A:$A,$A116) | J116: =SUMIFS(Actuals!$L:$L,Actuals!$A:$A,$A116) | K116: =SUMIFS(Actuals!$M:$M,Actuals!$A:$A,$A116) | L116: =SUMIFS(Actuals!$N:$N,Actuals!$A:$A,$A116) | M116: =SUMIFS(Actuals!$O:$O,Actuals!$A:$A,$A116) | N116: =SUM(B116:M116)
A117: Gain on lease termination | B117: =SUMIFS(Actuals!$D:$D,Actuals!$A:$A,$A117) | C117: =SUMIFS(Actuals!$E:$E,Actuals!$A:$A,$A117) | D117: =SUMIFS(Actuals!$F:$F,Actuals!$A:$A,$A117) | E117: =SUMIFS(Actuals!$G:$G,Actuals!$A:$A,$A117) | F117: =SUMIFS(Actuals!$H:$H,Actuals!$A:$A,$A117) | G117: =SUMIFS(Actuals!$I:$I,Actuals!$A:$A,$A117) | H117: =SUMIFS(Actuals!$J:$J,Actuals!$A:$A,$A117) | I117: =SUMIFS(Actuals!$K:$K,Actuals!$A:$A,$A117) | J117: =SUMIFS(Actuals!$L:$L,Actuals!$A:$A,$A117) | K117: =SUMIFS(Actuals!$M:$M,Actuals!$A:$A,$A117) | L117: =SUMIFS(Actuals!$N:$N,Actuals!$A:$A,$A117) | M117: =SUMIFS(Actuals!$O:$O,Actuals!$A:$A,$A117) | N117: =SUM(B117:M117)
A118: Income Other | B118: =SUMIFS(Actuals!$D:$D,Actuals!$A:$A,$A118) | C118: =SUMIFS(Actuals!$E:$E,Actuals!$A:$A,$A118) | D118: =SUMIFS(Actuals!$F:$F,Actuals!$A:$A,$A118) | E118: =SUMIFS(Actuals!$G:$G,Actuals!$A:$A,$A118) | F118: =SUMIFS(Actuals!$H:$H,Actuals!$A:$A,$A118) | G118: =SUMIFS(Actuals!$I:$I,Actuals!$A:$A,$A118) | H118: =SUMIFS(Actuals!$J:$J,Actuals!$A:$A,$A118) | I118: =SUMIFS(Actuals!$K:$K,Actuals!$A:$A,$A118) | J118: =SUMIFS(Actuals!$L:$L,Actuals!$A:$A,$A118) | K118: =SUMIFS(Actuals!$M:$M,Actuals!$A:$A,$A118) | L118: =SUMIFS(Actuals!$N:$N,Actuals!$A:$A,$A118) | M118: =SUMIFS(Actuals!$O:$O,Actuals!$A:$A,$A118) | N118: =SUM(B118:M118)
...

Sheet Year on Year
A1: Year on Year
A2: FY27 against FY26, account by account. Calculated from the two P&L sheets.
A3: Account | B3: FY27 | C3: FY26 | D3: Variance $ | E3: Variance %
A4: INCOME | B4: ='This Year'!N4 | C4: ='Last Year'!N4 | D4: =B4-C4 | E4: =IFERROR(D4/ABS(C4),0)
A5: Ad Hoc Service Labour | B5: ='This Year'!N5 | C5: ='Last Year'!N5 | D5: =B5-C5 | E5: =IFERROR(D5/ABS(C5),0)
A6: Closing Work in Progress | B6: ='This Year'!N6 | C6: ='Last Year'!N6 | D6: =B6-C6 | E6: =IFERROR(D6/ABS(C6),0)
A7: Conference Call Charge | B7: ='This Year'!N7 | C7: ='Last Year'!N7 | D7: =B7-C7 | E7: =IFERROR(D7/ABS(C7),0)
A8: Contract Help Desk | B8: ='This Year'!N8 | C8: ='Last Year'!N8 | D8: =B8-C8 | E8: =IFERROR(D8/ABS(C8),0)
A9: Contract Maintenance | B9: ='This Year'!N9 | C9: ='Last Year'!N9 | D9: =B9-C9 | E9: =IFERROR(D9/ABS(C9),0)
A10: Contract Support Staff | B10: ='This Year'!N10 | C10: ='Last Year'!N10 | D10: =B10-C10 | E10: =IFERROR(D10/ABS(C10),0)
A11: Credit Card Collected - CONS | B11: ='This Year'!N11 | C11: ='Last Year'!N11 | D11: =B11-C11 | E11: =IFERROR(D11/ABS(C11),0)
A12: Credit Card Collected - ONS | B12: ='This Year'!N12 | C12: ='Last Year'!N12 | D12: =B12-C12 | E12: =IFERROR(D12/ABS(C12),0)
A13: Credit Card Collected - PRD | B13: ='This Year'!N13 | C13: ='Last Year'!N13 | D13: =B13-C13 | E13: =IFERROR(D13/ABS(C13),0)
A14: Credit Card Collected - VID | B14: ='This Year'!N14 | C14: ='Last Year'!N14 | D14: =B14-C14 | E14: =IFERROR(D14/ABS(C14),0)
A15: Credit Card Collected-INTEGRATION | B15: ='This Year'!N15 | C15: ='Last Year'!N15 | D15: =B15-C15 | E15: =IFERROR(D15/ABS(C15),0)
... A111: GROSS PROFIT | B111: ='This Year'!N111 | C111: ='Last Year'!N111 | D111: =B111-C111 | E111: =IFERROR(D111/ABS(C111),0)
A112: Gross Profit % | B112: ='This Year'!N112 | C112: ='Last Year'!N112 | D112: =B112-C112
A114: OTHER INCOME | B114: ='This Year'!N114 | C114: ='Last Year'!N114 | D114: =B114-C114 | E114: =IFERROR(D114/ABS(C114),0)
A115: Cash Flow Boost | B115: ='This Year'!N115 | C115: ='Last Year'!N115 | D115: =B115-C115 | E115: =IFERROR(D115/ABS(C115),0)
A116: Employee FBT Contribtution | B116: ='This Year'!N116 | C116: ='Last Year'!N116 | D116: =B116-C116 | E116: =IFERROR(D116/ABS(C116),0)
A117: Gain on lease termination | B117: ='This Year'!N117 | C117: ='Last Year'!N117 | D117: =B117-C117 | E117: =IFERROR(D117/ABS(C117),0)
A118: Income Other | B118: ='This Year'!N118 | C118: ='Last Year'!N118 | D118: =B118-C118 | E118: =IFERROR(D118/ABS(C118),0)
A119: Interest Income | B119: ='This Year'!N119 | C119: ='Last Year'!N119 | D119: =B119-C119 | E119: =IFERROR(D119/ABS(C119),0)
A120: Interest Received | B120: ='This Year'!N120 | C120: ='Last Year'!N120 | D120: =B120-C120 | E120: =IFERROR(D120/ABS(C120),0)
A121: JobKeeper Subsidy | B121: ='This Year'!N121 | C121: ='Last Year'!N121 | D121: =B121-C121 | E121: =IFERROR(D121/ABS(C121),0)
A122: JobSaver Subsidy | B122: ='This Year'!N122 | C122: ='Last Year'!N122 | D122: =B122-C122 | E122: =IFERROR(D122/ABS(C122),0)
A123: Rental Income | B123: ='This Year'!N123 | C123: ='Last Year'!N123 | D123: =B123-C123 | E123: =IFERROR(D123/ABS(C123),0)
A124: Total Other Income | B124: ='This Year'!N124 | C124: ='Last Year'!N124 | D124: =B124-C124 | E124: =IFERROR(D124/ABS(C124),0)
A126: EXPENSES | B126: ='This Year'!N126 | C126: ='Last Year'!N126 | D126: =B126-C126 | E126: =IFERROR(D126/ABS(C126),0)
... A209: NET PROFIT | B209: ='This Year'!N209 | C209: ='Last Year'!N209 | D209: =B209-C209 | E209: =IFERROR(D209/ABS(C209),0)
A210: Net Profit % | B210: ='This Year'!N210 | C210: ='Last Year'!N210 | D210: =B210-C210

Sheet By Division
A1: By Division: FY27
A2: Division is taken from each account's suffix (ONS, PRD, VID, CONS, INTEGRATION, ADMIN). Unallocated covers shared overheads that carry no division in the account name.
A3: Division | B3: Jul-26 | C3: Aug-26 | D3: Sep-26 | E3: Oct-26 | F3: Nov-26 | G3: Dec-26 | H3: Jan-27 | I3: Feb-27 | J3: Mar-27 | K3: Apr-27 | L3: May-27 | M3: Jun-27 | N3: FY27 Total
A4: INCOME
A5: Onsite | B5: =SUMIFS(Actuals!$P:$P,Actuals!$B:$B,"Income",Actuals!$C:$C,$A5) | C5: =SUMIFS(Actuals!$Q:$Q,Actuals!$B:$B,"Income",Actuals!$C:$C,$A5) | D5: =SUMIFS(Actuals!$R:$R,Actuals!$B:$B,"Income",Actuals!$C:$C,$A5) | E5: =SUMIFS(Actuals!$S:$S,Actuals!$B:$B,"Income",Actuals!$C:$C,$A5) | F5: =SUMIFS(Actuals!$T:$T,Actuals!$B:$B,"Income",Actuals!$C:$C,$A5) | G5: =SUMIFS(Actuals!$U:$U,Actuals!$B:$B,"Income",Actuals!$C:$C,$A5) | H5: =SUMIFS(Actuals!$V:$V,Actuals!$B:$B,"Income",Actuals!$C:$C,$A5) | I5: =SUMIFS(Actuals!$W:$W,Actuals!$B:$B,"Income",Actuals!$C:$C,$A5) | J5: =SUMIFS(Actuals!$X:$X,Actuals!$B:$B,"Income",Actuals!$C:$C,$A5) | K5: =SUMIFS(Actuals!$Y:$Y,Actuals!$B:$B,"Income",Actuals!$C:$C,$A5) | L5: =SUMIFS(Actuals!$Z:$Z,Actuals!$B:$B,"Income",Actuals!$C:$C,$A5) | M5: =SUMIFS(Actuals!$AA:$AA,Actuals!$B:$B,"Income",Actuals!$C:$C,$A5) | N5: =SUM(B5:M5)
A6: Production | B6: =SUMIFS(Actuals!$P:$P,Actuals!$B:$B,"Income",Actuals!$C:$C,$A6) | C6: =SUMIFS(Actuals!$Q:$Q,Actuals!$B:$B,"Income",Actuals!$C:$C,$A6) | D6: =SUMIFS(Actuals!$R:$R,Actuals!$B:$B,"Income",Actuals!$C:$C,$A6) | E6: =SUMIFS(Actuals!$S:$S,Actuals!$B:$B,"Income",Actuals!$C:$C,$A6) | F6: =SUMIFS(Actuals!$T:$T,Actuals!$B:$B,"Income",Actuals!$C:$C,$A6) | G6: =SUMIFS(Actuals!$U:$U,Actuals!$B:$B,"Income",Actuals!$C:$C,$A6) | H6: =SUMIFS(Actuals!$V:$V,Actuals!$B:$B,"Income",Actuals!$C:$C,$A6) | I6: =SUMIFS(Actuals!$W:$W,Actuals!$B:$B,"Income",Actuals!$C:$C,$A6) | J6: =SUMIFS(Actuals!$X:$X,Actuals!$B:$B,"Income",Actuals!$C:$C,$A6) | K6: =SUMIFS(Actuals!$Y:$Y,Actuals!$B:$B,"Income",Actuals!$C:$C,$A6) | L6: =SUMIFS(Actuals!$Z:$Z,Actuals!$B:$B,"Income",Actuals!$C:$C,$A6) | M6: =SUMIFS(Actuals!$AA:$AA,Actuals!$B:$B,"Income",Actuals!$C:$C,$A6) | N6: =SUM(B6:M6)
A7: Video | B7: =SUMIFS(Actuals!$P:$P,Actuals!$B:$B,"Income",Actuals!$C:$C,$A7) | C7: =SUMIFS(Actuals!$Q:$Q,Actuals!$B:$B,"Income",Actuals!$C:$C,$A7) | D7: =SUMIFS(Actuals!$R:$R,Actuals!$B:$B,"Income",Actuals!$C:$C,$A7) | E7: =SUMIFS(Actuals!$S:$S,Actuals!$B:$B,"Income",Actuals!$C:$C,$A7) | F7: =SUMIFS(Actuals!$T:$T,Actuals!$B:$B,"Income",Actuals!$C:$C,$A7) | G7: =SUMIFS(Actuals!$U:$U,Actuals!$B:$B,"Income",Actuals!$C:$C,$A7) | H7: =SUMIFS(Actuals!$V:$V,Actuals!$B:$B,"Income",Actuals!$C:$C,$A7) | I7: =SUMIFS(Actuals!$W:$W,Actuals!$B:$B,"Income",Actuals!$C:$C,$A7) | J7: =SUMIFS(Actuals!$X:$X,Actuals!$B:$B,"Income",Actuals!$C:$C,$A7) | K7: =SUMIFS(Actuals!$Y:$Y,Actuals!$B:$B,"Income",Actuals!$C:$C,$A7) | L7: =SUMIFS(Actuals!$Z:$Z,Actuals!$B:$B,"Income",Actuals!$C:$C,$A7) | M7: =SUMIFS(Actuals!$AA:$AA,Actuals!$B:$B,"Income",Actuals!$C:$C,$A7) | N7: =SUM(B7:M7)
A8: Consulting | B8: =SUMIFS(Actuals!$P:$P,Actuals!$B:$B,"Income",Actuals!$C:$C,$A8) | C8: =SUMIFS(Actuals!$Q:$Q,Actuals!$B:$B,"Income",Actuals!$C:$C,$A8) | D8: =SUMIFS(Actuals!$R:$R,Actuals!$B:$B,"Income",Actuals!$C:$C,$A8) | E8: =SUMIFS(Actuals!$S:$S,Actuals!$B:$B,"Income",Actuals!$C:$C,$A8) | F8: =SUMIFS(Actuals!$T:$T,Actuals!$B:$B,"Income",Actuals!$C:$C,$A8) | G8: =SUMIFS(Actuals!$U:$U,Actuals!$B:$B,"Income",Actuals!$C:$C,$A8) | H8: =SUMIFS(Actuals!$V:$V,Actuals!$B:$B,"Income",Actuals!$C:$C,$A8) | I8: =SUMIFS(Actuals!$W:$W,Actuals!$B:$B,"Income",Actuals!$C:$C,$A8) | J8: =SUMIFS(Actuals!$X:$X,Actuals!$B:$B,"Income",Actuals!$C:$C,$A8) | K8: =SUMIFS(Actuals!$Y:$Y,Actuals!$B:$B,"Income",Actuals!$C:$C,$A8) | L8: =SUMIFS(Actuals!$Z:$Z,Actuals!$B:$B,"Income",Actuals!$C:$C,$A8) | M8: =SUMIFS(Actuals!$AA:$AA,Actuals!$B:$B,"Income",Actuals!$C:$C,$A8) | N8: =SUM(B8:M8)
A9: Integration | B9: =SUMIFS(Actuals!$P:$P,Actuals!$B:$B,"Income",Actuals!$C:$C,$A9) | C9: =SUMIFS(Actuals!$Q:$Q,Actuals!$B:$B,"Income",Actuals!$C:$C,$A9) | D9: =SUMIFS(Actuals!$R:$R,Actuals!$B:$B,"Income",Actuals!$C:$C,$A9) | E9: =SUMIFS(Actuals!$S:$S,Actuals!$B:$B,"Income",Actuals!$C:$C,$A9) | F9: =SUMIFS(Actuals!$T:$T,Actuals!$B:$B,"Income",Actuals!$C:$C,$A9) | G9: =SUMIFS(Actuals!$U:$U,Actuals!$B:$B,"Income",Actuals!$C:$C,$A9) | H9: =SUMIFS(Actuals!$V:$V,Actuals!$B:$B,"Income",Actuals!$C:$C,$A9) | I9: =SUMIFS(Actuals!$W:$W,Actuals!$B:$B,"Income",Actuals!$C:$C,$A9) | J9: =SUMIFS(Actuals!$X:$X,Actuals!$B:$B,"Income",Actuals!$C:$C,$A9) | K9: =SUMIFS(Actuals!$Y:$Y,Actuals!$B:$B,"Income",Actuals!$C:$C,$A9) | L9: =SUMIFS(Actuals!$Z:$Z,Actuals!$B:$B,"Income",Actuals!$C:$C,$A9) | M9: =SUMIFS(Actuals!$AA:$AA,Actuals!$B:$B,"Income",Actuals!$C:$C,$A9) | N9: =SUM(B9:M9)
A10: Admin | B10: =SUMIFS(Actuals!$P:$P,Actuals!$B:$B,"Income",Actuals!$C:$C,$A10) | C10: =SUMIFS(Actuals!$Q:$Q,Actuals!$B:$B,"Income",Actuals!$C:$C,$A10) | D10: =SUMIFS(Actuals!$R:$R,Actuals!$B:$B,"Income",Actuals!$C:$C,$A10) | E10: =SUMIFS(Actuals!$S:$S,Actuals!$B:$B,"Income",Actuals!$C:$C,$A10) | F10: =SUMIFS(Actuals!$T:$T,Actuals!$B:$B,"Income",Actuals!$C:$C,$A10) | G10: =SUMIFS(Actuals!$U:$U,Actuals!$B:$B,"Income",Actuals!$C:$C,$A10) | H10: =SUMIFS(Actuals!$V:$V,Actuals!$B:$B,"Income",Actuals!$C:$C,$A10) | I10: =SUMIFS(Actuals!$W:$W,Actuals!$B:$B,"Income",Actuals!$C:$C,$A10) | J10: =SUMIFS(Actuals!$X:$X,Actuals!$B:$B,"Income",Actuals!$C:$C,$A10) | K10: =SUMIFS(Actuals!$Y:$Y,Actuals!$B:$B,"Income",Actuals!$C:$C,$A10) | L10: =SUMIFS(Actuals!$Z:$Z,Actuals!$B:$B,"Income",Actuals!$C:$C,$A10) | M10: =SUMIFS(Actuals!$AA:$AA,Actuals!$B:$B,"Income",Actuals!$C:$C,$A10) | N10: =SUM(B10:M10)
