Workbook
Name lst_CostCentre: Lists!$A$5:$A$10
Name lst_InvoiceType: Lists!$B$5:$B$14
Name lst_TaxCode: Lists!$C$5:$C$8
Name lst_Status: Lists!$D$5:$D$13
Name lst_YN: Lists!$E$5:$E$7
Name lst_Ariba: Lists!$F$5:$F$10
Name lst_WIPType: Lists!$G$5:$G$10
Name lst_WIPGL: Lists!$H$5:$H$7
Name lst_Team: Lists!$I$5:$I$8
Name set_GSTRate: Lists!$U$8
Name set_QwilrBase: Lists!$U$5
Name set_RMSBase: Lists!$U$6
Name lst_RevGL: Lists!$K$5:$K$39
Name lst_Months: Lists!$N$5:$N$100
Name lst_Jobs: Lists!$P$5:$P$1500
Name lst_JobName: Lists!$Q$5:$Q$1500
Name lst_JobCC: Lists!$R$5:$R$1500

Sheet Read Me
B2: FY27 Revenue Tracker
B4: Corporate Technology Services Pty Ltd - replaces FY27_Revenue_Tracker_v2.xlsm
B6: WHO TYPES WHERE
C7: Finance types on the Finance sheet. Nowhere else. Every invoice line, every month.
C8: Each department types on its own sheet. Nowhere else. One row per job number.
C9: The two meet on Job Number, which is a real Xero tracking category and is checked against the live job list as you type. Nothing has to be kept lined up by hand.
B11: HOW IT FITS TOGETHER
B12: Finance | C12: The invoice register, and the only source of revenue. One row per invoice LINE, coded to one cost centre, exactly as Xero holds it. Filter the Issue column to see everything that needs fixing.
B13: Onsite / Production / Consulting | C13: One row per job. Client, invoice count and revenue come from Finance automatically; the department fills in its own costs, hours and references.
B14: WIP Movements | C14: Manual journals between the P&L and GL 11300 Work in Progress. Anything with a defer start and end on Finance does not belong here - it is handled automatically.
B15: Deferred Revenue | C15: The workings behind the automatic deferrals. Nothing is typed here; it mirrors the Finance lines that carry a defer start and end.
B16: Month-End | C16: The close: revenue by cost centre against Xero, the WIP reconciliation, fifteen data checks and a sign-off box.
B17: WIP Summary | C17: WIP opening / movement / closing for every job, to tie job by job back to the WIP Schedule file.
B18: Lists | C18: Every dropdown. Cost centres, job numbers and revenue GL codes came straight out of your Xero organisation, so they already match.
B20: DEFERRED REVENUE - it releases itself
C21: Put a Defer Start and a Defer End on a Finance line and the revenue spreads evenly across those months instead of landing all in the month you invoiced. Leave both blank for an ordinary one-off invoice.
C22: In the month invoiced: one month is recognised, the rest goes to WIP.
C23: Every month after: one more month is released, automatically.
C24: Worked example - $12,000 invoiced 15 Sep 2025 for Sep 2025 to Aug 2026. September recognises $1,000 and defers $11,000. Each month after releases $1,000. By August 2026 the balance is nil. Nothing is typed each month and no journal is needed.
C25: The Deferred Revenue sheet shows the workings line by line, and Month-End and WIP Summary already include it. One warning: a deferred line must not ALSO have a manual row on WIP Movements or it counts twice - Month-End checks for that.
B27: VIDEO REVENUE
C28: There is no video split column any more, and nothing to keep honest. In Xero a cost centre sits on the invoice LINE, so a job invoiced part production and part video is simply two lines on the Finance sheet - one coded PRODUCTION, one coded VIDEO. The VIDEO figure at month-end is then a plain sum of the lines coded VIDEO, and it ties to the Xero VIDEO cost centre without any adjustment.
C29: The 26 migrated invoices that carried a video amount were split into two lines each on the way across. Ex GST in total is unchanged.
C30: The Production sheet carries a Video Revenue column beside the expenses, and Video % of Revenue next to it. Both read the Finance lines coded VIDEO, so nothing is typed. Job by job they reproduce the old Video Total column to the cent - 38,484.75 in total across 28 jobs.
B32: WHY THIS VERSION IS NOT SLOW, AND WHY IT OPENS
C33: The v2 file was slow because of its macro: every keystroke copied 26 columns by 200 rows into hidden storage, and it was capped at 200 rows per department. There are no macros here at all, and it is a .xlsx, so no macro warning and nothing blocked on SharePoint.
C34: There are also no dynamic array formulas - no VSTACK, FILTER, SORT, UNIQUE or XLOOKUP. Every sheet is a real Excel Table or a plain SUMIFS grid, which means the filter buttons, sorting and PivotTables all work normally, and every formula runs in any version of Excel.
B36: MONTH-END, IN ORDER
C37: 1. Chase the departments until every invoice for the month is on the Finance sheet and Posted to Xero is Y.
C38: 2. Open Month-End and set the month.
C39: 3. Work section 3 first. Every count must be zero. Fix on the Finance sheet, or filter the Issue column there, which lists the same problems row by row.
C40: 4. Section 1: run the Xero P&L for the month by Cost Centre and type the revenue into the yellow column. Each line should read Reconciled.
C41: 5. Section 2: type the WIP Schedule closing balance and the Xero GL 11300 balance.
C42: 6. Breaks in section 2 - open WIP Summary, paste the WIP Schedule balances into column G and the variance column shows which job is out.
C43: 7. Sign off in section 4.
B45: THE WIP SIGN RULE
C46: One signed Amount column does both jobs, because GL 11300 nets accrued and deferred revenue. Positive = revenue recognised this month (work done but not yet invoiced, or a deferral released). Negative = revenue pushed out of this month (invoiced in advance). So revenue recognised = invoiced Ex GST + WIP movement, and the running total of the Amount column is the GL 11300 balance.
B48: LOCKED CELLS, LINKS AND TOTALS
C49: Every sheet is protected with no password. Only the cells you are meant to fill are open; the grey calculated ones are locked so a stray keystroke cannot wipe a formula. To turn it off: Review, Unprotect Sheet. Sorting and filtering still work.
C50: Qwilr quotes and Current RMS numbers are clickable. Paste a full web address and it is used as it stands; type a bare number and it is added to the base address on the Lists sheet. The Qwilr base is already set, and Current RMS on the Production sheet now works exactly the same way - paste the whole Current RMS address into the Current RMS No cell and it links straight away. Only fill in Lists column U row 6 if you would rather type the bare opportunity number.
...

Sheet Read Me (Easy Read)
B2: FY27 Revenue Tracker
B3: Corporate Technology Services Pty Ltd - replaces FY27_Revenue_Tracker_v2.xlsm
B5: Who types where
C6: Finance types on the Finance sheet.
C7: Nowhere else.
C8: Every invoice line, every month.
C10: Each department types on its own sheet.
C11: Nowhere else.
C12: One row per job number.
C14: The two meet on Job Number, which is a real Xero tracking category and is checked against the live job list as you type.
C15: Nothing has to be kept lined up by hand.
B18: How it fits together
B19: Finance | C19: The invoice register, and the only source of revenue. One row per invoice line, coded to one cost centre, exactly as Xero holds it. Filter the Issue column to see everything that needs fixing.
B20: Onsite / Production / Consulting | C20: One row per job. Client, invoice count and revenue come from Finance automatically; the department fills in its own costs, hours and references.
B21: WIP Movements | C21: Manual journals between the P&L and GL 11300 Work in Progress. Anything with a defer start and end on Finance does not belong here - it is handled automatically.
B22: Deferred Revenue | C22: The workings behind the automatic deferrals. Nothing is typed here; it mirrors the Finance lines that carry a defer start and end.
B23: Month-End | C23: The close: revenue by cost centre against Xero, the WIP reconciliation, fifteen data checks and a sign-off box.
B24: WIP Summary | C24: WIP opening / movement / closing for every job, to tie job by job back to the WIP Schedule file.
B25: Lists | C25: Every dropdown. Cost centres, job numbers and revenue GL codes came straight out of your Xero organisation, so they already match.
B27: Deferred revenue - it releases itself
C28: Put a Defer Start and a Defer End on a Finance line and the revenue spreads evenly across those months instead of landing all in the month you invoiced.
C29: Leave both blank for an ordinary one-off invoice.
C31: In the month invoiced: one month is recognised, the rest goes to WIP.
C33: Every month after: one more month is released, automatically.
C35: Worked example - $12,000 invoiced 15 Sep 2025 for Sep 2025 to Aug 2026.
C36: September recognises $1,000 and defers $11,000.
C37: Each month after releases $1,000.
C38: By August 2026 the balance is nil.
C39: Nothing is typed each month and no journal is needed.
C41: The Deferred Revenue sheet shows the workings line by line, and Month-End and WIP Summary already include it.
C42: One warning: a deferred line must not also have a manual row on WIP Movements or it counts twice - Month-End checks for that.
B45: Video revenue
C46: There is no video split column any more, and nothing to keep honest.
C47: In Xero a cost centre sits on the invoice line, so a job invoiced part production and part video is simply two lines on the Finance sheet - one coded PRODUCTION, one coded VIDEO.
C48: The VIDEO figure at month-end is then a plain sum of the lines coded VIDEO, and it ties to the Xero VIDEO cost centre without any adjustment.
C50: The 26 migrated invoices that carried a video amount were split into two lines each on the way across.
C51: Ex GST in total is unchanged.
C53: The Production sheet carries a Video Revenue column beside the expenses, and Video % of Revenue next to it.
C54: Both read the Finance lines coded VIDEO, so nothing is typed.
C55: Job by job they reproduce the old Video Total column to the cent - 38,484.75 in total across 28 jobs.
...

Sheet Finance
A1: Finance - Invoice Register
A2: One row per invoice line, coded to one cost centre, the same way Xero holds it. Finance types here and nowhere else. A job invoiced part production and part video is two lines. Filter the Issue column to see what needs fixing.
A3: ="Ex GST "&TEXT(SUBTOTAL(109,tbl_Finance[Ex GST]),"$#,##0.00")&" "&"GST "&TEXT(SUBTOTAL(109,tbl_Finance[GST]),"$#,##0.00")&" "&"Inc GST "&TEXT(SUBTOTAL(109,tbl_Finance[Inc GST]),"$#,##0.00")
A4: Date | B4: Month | C4: Xero Invoice No | D4: Client | E4: Job Number | F4: Job in Xero? | G4: Description | H4: Team | I4: Cost Centre | J4: Invoice Type | K4: Tax Code | L4: Ex GST | M4: GST | N4: Inc GST | O4: Revenue GL | P4: Posted to Xero | Q4: To WIP | R4: Defer Start | S4: Defer End | T4: Status | U4: Notes | V4: Issue | W4: Job Name (Xero) | X4: Lines on this Job | Y4: Job Total Ex GST | Z4: Job Invoiced | AA4: Job To Invoice | AB4: Job Quote / Ref | AC4: Open Quote | AD4: Job Expense | AE4: Job Margin | AF4: Job Margin % | AG4: Dept Notes
A5: 46234 | B5: =IF(A5="","",EOMONTH(A5,0)) | C5: INV-10525 | D5: CBA | E5: 1350 | F5: =IF(E5="","",IF(COUNTIF(lst_Jobs,E5&"")>0,"OK","CHECK")) | G5: CBA BNE July 2026 | H5: Onsite | I5: ONSITE | J5: Contract | K5: GST 10% | L5: 8588.45 | M5: =IF(L5="","",IF(K5="GST 10%",ROUND(L5*set_GSTRate,2),0)) | N5: =IF(L5="","",L5+M5) | O5: 41100 | P5: Y | Q5: N | T5: Invoiced | U5: 174.05 hours | V5: =IF(COUNTA(A5,D5,C5,L5)=0,"",IF(A5="","No date - sits outside every month",IF(E5="","No job number",IF(F5="CHECK","Job number is not in the Xero job list",IF(I5="","No cost centre",IF(AND(P5="Y",C5=""),"Marked posted to Xero but has no invoice number",IF(AND(L5<>"",K5=""),"No tax code",IF(AND(L5<>"",O5=""),"No revenue GL code","")))))))) | W5: =IF(E5="","",IFERROR(INDEX(lst_JobName,MATCH(E5&"",lst_Jobs,0)),"")) | X5: =IF(E5="","",COUNTIFS(tbl_Finance[Job Number],E5&"",tbl_Finance[Ex GST],"<>")) | Y5: =IF(E5="","",SUMIFS(tbl_Finance[Ex GST],tbl_Finance[Job Number],E5&"")) | Z5: =IF(E5="","",SUMIFS(tbl_Finance[Ex GST],tbl_Finance[Job Number],E5&"",tbl_Finance[Xero Invoice No],"<>")) | AA5: =IF(E5="","",Y5-Z5) | AB5: =IF(E5="","",IF(H5="Onsite",IFERROR(INDEX(tbl_Onsite[Qwilr Quote],MATCH(E5&"",tbl_Onsite[Job Number],0)),""),IF(H5="Production",IFERROR(IF(INDEX(tbl_Production[Current RMS No],MATCH(E5&"",tbl_Production[Job Number],0))="",INDEX(tbl_Production[Qwilr Quote],MATCH(E5&"",tbl_Production[Job Number],0)),INDEX(tbl_Production[Current RMS No],MATCH(E5&"",tbl_Production[Job Number],0))),""),IF(H5="Consulting",IFERROR(INDEX(tbl_Consulting[Qwilr Quote],MATCH(E5&"",tbl_Consulting[Job Number],0)),""),"")))) | AC5: =IF(AB5="","",IF(AND(LEFT(AB5,4)<>"http",IF(H5="Production",set_RMSBase,set_QwilrBase)=""),"",HYPERLINK(IF(LEFT(AB5,4)="http",AB5,IF(H5="Production",set_RMSBase,set_QwilrBase)&AB5),"Open"))) | AD5: =IF(E5="","",IF(H5="Production",IFERROR(INDEX(tbl_Production[Total Expense],MATCH(E5&"",tbl_Production[Job Number],0)),0),IF(H5="Consulting",IFERROR(INDEX(tbl_Consulting[Total Expense],MATCH(E5&"",tbl_Consulting[Job Number],0)),0),0))) | AE5: =IF(E5="","",Y5-N(AD5)) | AF5: =IFERROR(AE5/Y5,"") | AG5: =IF(E5="","",IF(H5="Onsite",IFERROR(INDEX(tbl_Onsite[Notes],MATCH(E5&"",tbl_Onsite[Job Number],0)),""),IF(H5="Production",IFERROR(INDEX(tbl_Production[Notes],MATCH(E5&"",tbl_Production[Job Number],0)),""),IF(H5="Consulting",IFERROR(INDEX(tbl_Consulting[Notes],MATCH(E5&"",tbl_Consulting[Job Number],0)),""),""))))
A6: 46234 | B6: =IF(A6="","",EOMONTH(A6,0)) | C6: INV-10526 | D6: CBA | E6: 585/586/1755 | F6: =IF(E6="","",IF(COUNTIF(lst_Jobs,E6&"")>0,"OK","CHECK")) | G6: CBP July 2026 | H6: Onsite | I6: ONSITE | J6: Contract | K6: GST 10% | L6: 22120.57 | M6: =IF(L6="","",IF(K6="GST 10%",ROUND(L6*set_GSTRate,2),0)) | N6: =IF(L6="","",L6+M6) | O6: 41100 | P6: Y | Q6: N | T6: Invoiced | U6: Deduct 3hrs for TN 01/07 & 6hrs for NP 14/07 | V6: =IF(COUNTA(A6,D6,C6,L6)=0,"",IF(A6="","No date - sits outside every month",IF(E6="","No job number",IF(F6="CHECK","Job number is not in the Xero job list",IF(I6="","No cost centre",IF(AND(P6="Y",C6=""),"Marked posted to Xero but has no invoice number",IF(AND(L6<>"",K6=""),"No tax code",IF(AND(L6<>"",O6=""),"No revenue GL code","")))))))) | W6: =IF(E6="","",IFERROR(INDEX(lst_JobName,MATCH(E6&"",lst_Jobs,0)),"")) | X6: =IF(E6="","",COUNTIFS(tbl_Finance[Job Number],E6&"",tbl_Finance[Ex GST],"<>")) | Y6: =IF(E6="","",SUMIFS(tbl_Finance[Ex GST],tbl_Finance[Job Number],E6&"")) | Z6: =IF(E6="","",SUMIFS(tbl_Finance[Ex GST],tbl_Finance[Job Number],E6&"",tbl_Finance[Xero Invoice No],"<>")) | AA6: =IF(E6="","",Y6-Z6) | AB6: =IF(E6="","",IF(H6="Onsite",IFERROR(INDEX(tbl_Onsite[Qwilr Quote],MATCH(E6&"",tbl_Onsite[Job Number],0)),""),IF(H6="Production",IFERROR(IF(INDEX(tbl_Production[Current RMS No],MATCH(E6&"",tbl_Production[Job Number],0))="",INDEX(tbl_Production[Qwilr Quote],MATCH(E6&"",tbl_Production[Job Number],0)),INDEX(tbl_Production[Current RMS No],MATCH(E6&"",tbl_Production[Job Number],0))),""),IF(H6="Consulting",IFERROR(INDEX(tbl_Consulting[Qwilr Quote],MATCH(E6&"",tbl_Consulting[Job Number],0)),""),"")))) | AC6: =IF(AB6="","",IF(AND(LEFT(AB6,4)<>"http",IF(H6="Production",set_RMSBase,set_QwilrBase)=""),"",HYPERLINK(IF(LEFT(AB6,4)="http",AB6,IF(H6="Production",set_RMSBase,set_QwilrBase)&AB6),"Open"))) | AD6: =IF(E6="","",IF(H6="Production",IFERROR(INDEX(tbl_Production[Total Expense],MATCH(E6&"",tbl_Production[Job Number],0)),0),IF(H6="Consulting",IFERROR(INDEX(tbl_Consulting[Total Expense],MATCH(E6&"",tbl_Consulting[Job Number],0)),0),0))) | AE6: =IF(E6="","",Y6-N(AD6)) | AF6: =IFERROR(AE6/Y6,"") | AG6: =IF(E6="","",IF(H6="Onsite",IFERROR(INDEX(tbl_Onsite[Notes],MATCH(E6&"",tbl_Onsite[Job Number],0)),""),IF(H6="Production",IFERROR(INDEX(tbl_Production[Notes],MATCH(E6&"",tbl_Production[Job Number],0)),""),IF(H6="Consulting",IFERROR(INDEX(tbl_Consulting[Notes],MATCH(E6&"",tbl_Consulting[Job Number],0)),""),""))))
A7: 46234 | B7: =IF(A7="","",EOMONTH(A7,0)) | C7: INV-10527 | D7: CBA | E7: 587 | F7: =IF(E7="","",IF(COUNTIF(lst_Jobs,E7&"")>0,"OK","CHECK")) | G7: CBS July 2026 | H7: Onsite | I7: ONSITE | J7: Contract | K7: GST 10% | L7: 10720 | M7: =IF(L7="","",IF(K7="GST 10%",ROUND(L7*set_GSTRate,2),0)) | N7: =IF(L7="","",L7+M7) | O7: 41100 | P7: Y | Q7: N | T7: Invoiced | V7: =IF(COUNTA(A7,D7,C7,L7)=0,"",IF(A7="","No date - sits outside every month",IF(E7="","No job number",IF(F7="CHECK","Job number is not in the Xero job list",IF(I7="","No cost centre",IF(AND(P7="Y",C7=""),"Marked posted to Xero but has no invoice number",IF(AND(L7<>"",K7=""),"No tax code",IF(AND(L7<>"",O7=""),"No revenue GL code","")))))))) | W7: =IF(E7="","",IFERROR(INDEX(lst_JobName,MATCH(E7&"",lst_Jobs,0)),"")) | X7: =IF(E7="","",COUNTIFS(tbl_Finance[Job Number],E7&"",tbl_Finance[Ex GST],"<>")) | Y7: =IF(E7="","",SUMIFS(tbl_Finance[Ex GST],tbl_Finance[Job Number],E7&"")) | Z7: =IF(E7="","",SUMIFS(tbl_Finance[Ex GST],tbl_Finance[Job Number],E7&"",tbl_Finance[Xero Invoice No],"<>")) | AA7: =IF(E7="","",Y7-Z7) | AB7: =IF(E7="","",IF(H7="Onsite",IFERROR(INDEX(tbl_Onsite[Qwilr Quote],MATCH(E7&"",tbl_Onsite[Job Number],0)),""),IF(H7="Production",IFERROR(IF(INDEX(tbl_Production[Current RMS No],MATCH(E7&"",tbl_Production[Job Number],0))="",INDEX(tbl_Production[Qwilr Quote],MATCH(E7&"",tbl_Production[Job Number],0)),INDEX(tbl_Production[Current RMS No],MATCH(E7&"",tbl_Production[Job Number],0))),""),IF(H7="Consulting",IFERROR(INDEX(tbl_Consulting[Qwilr Quote],MATCH(E7&"",tbl_Consulting[Job Number],0)),""),"")))) | AC7: =IF(AB7="","",IF(AND(LEFT(AB7,4)<>"http",IF(H7="Production",set_RMSBase,set_QwilrBase)=""),"",HYPERLINK(IF(LEFT(AB7,4)="http",AB7,IF(H7="Production",set_RMSBase,set_QwilrBase)&AB7),"Open"))) | AD7: =IF(E7="","",IF(H7="Production",IFERROR(INDEX(tbl_Production[Total Expense],MATCH(E7&"",tbl_Production[Job Number],0)),0),IF(H7="Consulting",IFERROR(INDEX(tbl_Consulting[Total Expense],MATCH(E7&"",tbl_Consulting[Job Number],0)),0),0))) | AE7: =IF(E7="","",Y7-N(AD7)) | AF7: =IFERROR(AE7/Y7,"") | AG7: =IF(E7="","",IF(H7="Onsite",IFERROR(INDEX(tbl_Onsite[Notes],MATCH(E7&"",tbl_Onsite[Job Number],0)),""),IF(H7="Production",IFERROR(INDEX(tbl_Production[Notes],MATCH(E7&"",tbl_Production[Job Number],0)),""),IF(H7="Consulting",IFERROR(INDEX(tbl_Consulting[Notes],MATCH(E7&"",tbl_Consulting[Job Number],0)),""),""))))
A8: 46234 | B8: =IF(A8="","",EOMONTH(A8,0)) | C8: INV-10528 | D8: DTTL | E8: 2846/1401/725/1400/1530/1862/2402/2849/974 | F8: =IF(E8="","",IF(COUNTIF(lst_Jobs,E8&"")>0,"OK","CHECK")) | G8: DTTL Contract July 2026 | H8: Onsite | I8: ONSITE | J8: Contract | K8: GST 10% | L8: 103625.44 | M8: =IF(L8="","",IF(K8="GST 10%",ROUND(L8*set_GSTRate,2),0)) | N8: =IF(L8="","",L8+M8) | O8: 41100 | P8: Y | Q8: N | T8: Invoiced | V8: =IF(COUNTA(A8,D8,C8,L8)=0,"",IF(A8="","No date - sits outside every month",IF(E8="","No job number",IF(F8="CHECK","Job number is not in the Xero job list",IF(I8="","No cost centre",IF(AND(P8="Y",C8=""),"Marked posted to Xero but has no invoice number",IF(AND(L8<>"",K8=""),"No tax code",IF(AND(L8<>"",O8=""),"No revenue GL code","")))))))) | W8: =IF(E8="","",IFERROR(INDEX(lst_JobName,MATCH(E8&"",lst_Jobs,0)),"")) | X8: =IF(E8="","",COUNTIFS(tbl_Finance[Job Number],E8&"",tbl_Finance[Ex GST],"<>")) | Y8: =IF(E8="","",SUMIFS(tbl_Finance[Ex GST],tbl_Finance[Job Number],E8&"")) | Z8: =IF(E8="","",SUMIFS(tbl_Finance[Ex GST],tbl_Finance[Job Number],E8&"",tbl_Finance[Xero Invoice No],"<>")) | AA8: =IF(E8="","",Y8-Z8) | AB8: =IF(E8="","",IF(H8="Onsite",IFERROR(INDEX(tbl_Onsite[Qwilr Quote],MATCH(E8&"",tbl_Onsite[Job Number],0)),""),IF(H8="Production",IFERROR(IF(INDEX(tbl_Production[Current RMS No],MATCH(E8&"",tbl_Production[Job Number],0))="",INDEX(tbl_Production[Qwilr Quote],MATCH(E8&"",tbl_Production[Job Number],0)),INDEX(tbl_Production[Current RMS No],MATCH(E8&"",tbl_Production[Job Number],0))),""),IF(H8="Consulting",IFERROR(INDEX(tbl_Consulting[Qwilr Quote],MATCH(E8&"",tbl_Consulting[Job Number],0)),""),"")))) | AC8: =IF(AB8="","",IF(AND(LEFT(AB8,4)<>"http",IF(H8="Production",set_RMSBase,set_QwilrBase)=""),"",HYPERLINK(IF(LEFT(AB8,4)="http",AB8,IF(H8="Production",set_RMSBase,set_QwilrBase)&AB8),"Open"))) | AD8: =IF(E8="","",IF(H8="Production",IFERROR(INDEX(tbl_Production[Total Expense],MATCH(E8&"",tbl_Production[Job Number],0)),0),IF(H8="Consulting",IFERROR(INDEX(tbl_Consulting[Total Expense],MATCH(E8&"",tbl_Consulting[Job Number],0)),0),0))) | AE8: =IF(E8="","",Y8-N(AD8)) | AF8: =IFERROR(AE8/Y8,"") | AG8: =IF(E8="","",IF(H8="Onsite",IFERROR(INDEX(tbl_Onsite[Notes],MATCH(E8&"",tbl_Onsite[Job Number],0)),""),IF(H8="Production",IFERROR(INDEX(tbl_Production[Notes],MATCH(E8&"",tbl_Production[Job Number],0)),""),IF(H8="Consulting",IFERROR(INDEX(tbl_Consulting[Notes],MATCH(E8&"",tbl_Consulting[Job Number],0)),""),""))))
A9: 46234 | B9: =IF(A9="","",EOMONTH(A9,0)) | C9: INV-10529 | D9: BW | E9: 732/1144 | F9: =IF(E9="","",IF(COUNTIF(lst_Jobs,E9&"")>0,"OK","CHECK")) | G9: BW Contract July 2026 | H9: Onsite | I9: ONSITE | J9: Contract | K9: GST 10% | L9: 19427.5 | M9: =IF(L9="","",IF(K9="GST 10%",ROUND(L9*set_GSTRate,2),0)) | N9: =IF(L9="","",L9+M9) | O9: 41100 | P9: Y | Q9: N | T9: Invoiced | V9: =IF(COUNTA(A9,D9,C9,L9)=0,"",IF(A9="","No date - sits outside every month",IF(E9="","No job number",IF(F9="CHECK","Job number is not in the Xero job list",IF(I9="","No cost centre",IF(AND(P9="Y",C9=""),"Marked posted to Xero but has no invoice number",IF(AND(L9<>"",K9=""),"No tax code",IF(AND(L9<>"",O9=""),"No revenue GL code","")))))))) | W9: =IF(E9="","",IFERROR(INDEX(lst_JobName,MATCH(E9&"",lst_Jobs,0)),"")) | X9: =IF(E9="","",COUNTIFS(tbl_Finance[Job Number],E9&"",tbl_Finance[Ex GST],"<>")) | Y9: =IF(E9="","",SUMIFS(tbl_Finance[Ex GST],tbl_Finance[Job Number],E9&"")) | Z9: =IF(E9="","",SUMIFS(tbl_Finance[Ex GST],tbl_Finance[Job Number],E9&"",tbl_Finance[Xero Invoice No],"<>")) | AA9: =IF(E9="","",Y9-Z9) | AB9: =IF(E9="","",IF(H9="Onsite",IFERROR(INDEX(tbl_Onsite[Qwilr Quote],MATCH(E9&"",tbl_Onsite[Job Number],0)),""),IF(H9="Production",IFERROR(IF(INDEX(tbl_Production[Current RMS No],MATCH(E9&"",tbl_Production[Job Number],0))="",INDEX(tbl_Production[Qwilr Quote],MATCH(E9&"",tbl_Production[Job Number],0)),INDEX(tbl_Production[Current RMS No],MATCH(E9&"",tbl_Production[Job Number],0))),""),IF(H9="Consulting",IFERROR(INDEX(tbl_Consulting[Qwilr Quote],MATCH(E9&"",tbl_Consulting[Job Number],0)),""),"")))) | AC9: =IF(AB9="","",IF(AND(LEFT(AB9,4)<>"http",IF(H9="Production",set_RMSBase,set_QwilrBase)=""),"",HYPERLINK(IF(LEFT(AB9,4)="http",AB9,IF(H9="Production",set_RMSBase,set_QwilrBase)&AB9),"Open"))) | AD9: =IF(E9="","",IF(H9="Production",IFERROR(INDEX(tbl_Production[Total Expense],MATCH(E9&"",tbl_Production[Job Number],0)),0),IF(H9="Consulting",IFERROR(INDEX(tbl_Consulting[Total Expense],MATCH(E9&"",tbl_Consulting[Job Number],0)),0),0))) | AE9: =IF(E9="","",Y9-N(AD9)) | AF9: =IFERROR(AE9/Y9,"") | AG9: =IF(E9="","",IF(H9="Onsite",IFERROR(INDEX(tbl_Onsite[Notes],MATCH(E9&"",tbl_Onsite[Job Number],0)),""),IF(H9="Production",IFERROR(INDEX(tbl_Production[Notes],MATCH(E9&"",tbl_Production[Job Number],0)),""),IF(H9="Consulting",IFERROR(INDEX(tbl_Consulting[Notes],MATCH(E9&"",tbl_Consulting[Job Number],0)),""),""))))
A10: 46234 | B10: =IF(A10="","",EOMONTH(A10,0)) | C10: INV-10530 | D10: BW | E10: 2192 | F10: =IF(E10="","",IF(COUNTIF(lst_Jobs,E10&"")>0,"OK","CHECK")) | G10: BW Additionals July 2026 | H10: Onsite | I10: ONSITE | J10: Contract | K10: GST 10% | L10: 1120 | M10: =IF(L10="","",IF(K10="GST 10%",ROUND(L10*set_GSTRate,2),0)) | N10: =IF(L10="","",L10+M10) | O10: 41100 | P10: Y | Q10: N | T10: Invoiced | V10: =IF(COUNTA(A10,D10,C10,L10)=0,"",IF(A10="","No date - sits outside every month",IF(E10="","No job number",IF(F10="CHECK","Job number is not in the Xero job list",IF(I10="","No cost centre",IF(AND(P10="Y",C10=""),"Marked posted to Xero but has no invoice number",IF(AND(L10<>"",K10=""),"No tax code",IF(AND(L10<>"",O10=""),"No revenue GL code","")))))))) | W10: =IF(E10="","",IFERROR(INDEX(lst_JobName,MATCH(E10&"",lst_Jobs,0)),"")) | X10: =IF(E10="","",COUNTIFS(tbl_Finance[Job Number],E10&"",tbl_Finance[Ex GST],"<>")) | Y10: =IF(E10="","",SUMIFS(tbl_Finance[Ex GST],tbl_Finance[Job Number],E10&"")) | Z10: =IF(E10="","",SUMIFS(tbl_Finance[Ex GST],tbl_Finance[Job Number],E10&"",tbl_Finance[Xero Invoice No],"<>")) | AA10: =IF(E10="","",Y10-Z10) | AB10: =IF(E10="","",IF(H10="Onsite",IFERROR(INDEX(tbl_Onsite[Qwilr Quote],MATCH(E10&"",tbl_Onsite[Job Number],0)),""),IF(H10="Production",IFERROR(IF(INDEX(tbl_Production[Current RMS No],MATCH(E10&"",tbl_Production[Job Number],0))="",INDEX(tbl_Production[Qwilr Quote],MATCH(E10&"",tbl_Production[Job Number],0)),INDEX(tbl_Production[Current RMS No],MATCH(E10&"",tbl_Production[Job Number],0))),""),IF(H10="Consulting",IFERROR(INDEX(tbl_Consulting[Qwilr Quote],MATCH(E10&"",tbl_Consulting[Job Number],0)),""),"")))) | AC10: =IF(AB10="","",IF(AND(LEFT(AB10,4)<>"http",IF(H10="Production",set_RMSBase,set_QwilrBase)=""),"",HYPERLINK(IF(LEFT(AB10,4)="http",AB10,IF(H10="Production",set_RMSBase,set_QwilrBase)&AB10),"Open"))) | AD10: =IF(E10="","",IF(H10="Production",IFERROR(INDEX(tbl_Production[Total Expense],MATCH(E10&"",tbl_Production[Job Number],0)),0),IF(H10="Consulting",IFERROR(INDEX(tbl_Consulting[Total Expense],MATCH(E10&"",tbl_Consulting[Job Number],0)),0),0))) | AE10: =IF(E10="","",Y10-N(AD10)) | AF10: =IFERROR(AE10/Y10,"") | AG10: =IF(E10="","",IF(H10="Onsite",IFERROR(INDEX(tbl_Onsite[Notes],MATCH(E10&"",tbl_Onsite[Job Number],0)),""),IF(H10="Production",IFERROR(INDEX(tbl_Production[Notes],MATCH(E10&"",tbl_Production[Job Number],0)),""),IF(H10="Consulting",IFERROR(INDEX(tbl_Consulting[Notes],MATCH(E10&"",tbl_Consulting[Job Number],0)),""),""))))
A11: 46234 | B11: =IF(A11="","",EOMONTH(A11,0)) | C11: INV-10531 | D11: PWC | E11: 2488 | F11: =IF(E11="","",IF(COUNTIF(lst_Jobs,E11&"")>0,"OK","CHECK")) | G11: PWC Brisbane July 2026 | H11: Onsite | I11: ONSITE | J11: Contract | K11: GST 10% | L11: 7150 | M11: =IF(L11="","",IF(K11="GST 10%",ROUND(L11*set_GSTRate,2),0)) | N11: =IF(L11="","",L11+M11) | O11: 41100 | P11: Y | Q11: N | T11: Invoiced | V11: =IF(COUNTA(A11,D11,C11,L11)=0,"",IF(A11="","No date - sits outside every month",IF(E11="","No job number",IF(F11="CHECK","Job number is not in the Xero job list",IF(I11="","No cost centre",IF(AND(P11="Y",C11=""),"Marked posted to Xero but has no invoice number",IF(AND(L11<>"",K11=""),"No tax code",IF(AND(L11<>"",O11=""),"No revenue GL code","")))))))) | W11: =IF(E11="","",IFERROR(INDEX(lst_JobName,MATCH(E11&"",lst_Jobs,0)),"")) | X11: =IF(E11="","",COUNTIFS(tbl_Finance[Job Number],E11&"",tbl_Finance[Ex GST],"<>")) | Y11: =IF(E11="","",SUMIFS(tbl_Finance[Ex GST],tbl_Finance[Job Number],E11&"")) | Z11: =IF(E11="","",SUMIFS(tbl_Finance[Ex GST],tbl_Finance[Job Number],E11&"",tbl_Finance[Xero Invoice No],"<>")) | AA11: =IF(E11="","",Y11-Z11) | AB11: =IF(E11="","",IF(H11="Onsite",IFERROR(INDEX(tbl_Onsite[Qwilr Quote],MATCH(E11&"",tbl_Onsite[Job Number],0)),""),IF(H11="Production",IFERROR(IF(INDEX(tbl_Production[Current RMS No],MATCH(E11&"",tbl_Production[Job Number],0))="",INDEX(tbl_Production[Qwilr Quote],MATCH(E11&"",tbl_Production[Job Number],0)),INDEX(tbl_Production[Current RMS No],MATCH(E11&"",tbl_Production[Job Number],0))),""),IF(H11="Consulting",IFERROR(INDEX(tbl_Consulting[Qwilr Quote],MATCH(E11&"",tbl_Consulting[Job Number],0)),""),"")))) | AC11: =IF(AB11="","",IF(AND(LEFT(AB11,4)<>"http",IF(H11="Production",set_RMSBase,set_QwilrBase)=""),"",HYPERLINK(IF(LEFT(AB11,4)="http",AB11,IF(H11="Production",set_RMSBase,set_QwilrBase)&AB11),"Open"))) | AD11: =IF(E11="","",IF(H11="Production",IFERROR(INDEX(tbl_Production[Total Expense],MATCH(E11&"",tbl_Production[Job Number],0)),0),IF(H11="Consulting",IFERROR(INDEX(tbl_Consulting[Total Expense],MATCH(E11&"",tbl_Consulting[Job Number],0)),0),0))) | AE11: =IF(E11="","",Y11-N(AD11)) | AF11: =IFERROR(AE11/Y11,"") | AG11: =IF(E11="","",IF(H11="Onsite",IFERROR(INDEX(tbl_Onsite[Notes],MATCH(E11&"",tbl_Onsite[Job Number],0)),""),IF(H11="Production",IFERROR(INDEX(tbl_Production[Notes],MATCH(E11&"",tbl_Production[Job Number],0)),""),IF(H11="Consulting",IFERROR(INDEX(tbl_Consulting[Notes],MATCH(E11&"",tbl_Consulting[Job Number],0)),""),""))))
A12: 46234 | B12: =IF(A12="","",EOMONTH(A12,0)) | C12: INV-10532 | D12: Gen-E | E12: 26021602 | F12: =IF(E12="","",IF(COUNTIF(lst_Jobs,E12&"")>0,"OK","CHECK")) | G12: Gen-E ABS July 2026 | H12: Onsite | I12: ONSITE | J12: Contract | K12: GST 10% | L12: 12388.8 | M12: =IF(L12="","",IF(K12="GST 10%",ROUND(L12*set_GSTRate,2),0)) | N12: =IF(L12="","",L12+M12) | O12: 41100 | P12: Y | Q12: N | T12: Invoiced | V12: =IF(COUNTA(A12,D12,C12,L12)=0,"",IF(A12="","No date - sits outside every month",IF(E12="","No job number",IF(F12="CHECK","Job number is not in the Xero job list",IF(I12="","No cost centre",IF(AND(P12="Y",C12=""),"Marked posted to Xero but has no invoice number",IF(AND(L12<>"",K12=""),"No tax code",IF(AND(L12<>"",O12=""),"No revenue GL code","")))))))) | W12: =IF(E12="","",IFERROR(INDEX(lst_JobName,MATCH(E12&"",lst_Jobs,0)),"")) | X12: =IF(E12="","",COUNTIFS(tbl_Finance[Job Number],E12&"",tbl_Finance[Ex GST],"<>")) | Y12: =IF(E12="","",SUMIFS(tbl_Finance[Ex GST],tbl_Finance[Job Number],E12&"")) | Z12: =IF(E12="","",SUMIFS(tbl_Finance[Ex GST],tbl_Finance[Job Number],E12&"",tbl_Finance[Xero Invoice No],"<>")) | AA12: =IF(E12="","",Y12-Z12) | AB12: =IF(E12="","",IF(H12="Onsite",IFERROR(INDEX(tbl_Onsite[Qwilr Quote],MATCH(E12&"",tbl_Onsite[Job Number],0)),""),IF(H12="Production",IFERROR(IF(INDEX(tbl_Production[Current RMS No],MATCH(E12&"",tbl_Production[Job Number],0))="",INDEX(tbl_Production[Qwilr Quote],MATCH(E12&"",tbl_Production[Job Number],0)),INDEX(tbl_Production[Current RMS No],MATCH(E12&"",tbl_Production[Job Number],0))),""),IF(H12="Consulting",IFERROR(INDEX(tbl_Consulting[Qwilr Quote],MATCH(E12&"",tbl_Consulting[Job Number],0)),""),"")))) | AC12: =IF(AB12="","",IF(AND(LEFT(AB12,4)<>"http",IF(H12="Production",set_RMSBase,set_QwilrBase)=""),"",HYPERLINK(IF(LEFT(AB12,4)="http",AB12,IF(H12="Production",set_RMSBase,set_QwilrBase)&AB12),"Open"))) | AD12: =IF(E12="","",IF(H12="Production",IFERROR(INDEX(tbl_Production[Total Expense],MATCH(E12&"",tbl_Production[Job Number],0)),0),IF(H12="Consulting",IFERROR(INDEX(tbl_Consulting[Total Expense],MATCH(E12&"",tbl_Consulting[Job Number],0)),0),0))) | AE12: =IF(E12="","",Y12-N(AD12)) | AF12: =IFERROR(AE12/Y12,"") | AG12: =IF(E12="","",IF(H12="Onsite",IFERROR(INDEX(tbl_Onsite[Notes],MATCH(E12&"",tbl_Onsite[Job Number],0)),""),IF(H12="Production",IFERROR(INDEX(tbl_Production[Notes],MATCH(E12&"",tbl_Production[Job Number],0)),""),IF(H12="Consulting",IFERROR(INDEX(tbl_Consulting[Notes],MATCH(E12&"",tbl_Consulting[Job Number],0)),""),""))))
A13: 46234 | B13: =IF(A13="","",EOMONTH(A13,0)) | C13: INV-10534 | D13: CBA | E13: 26043001 | F13: =IF(E13="","",IF(COUNTIF(lst_Jobs,E13&"")>0,"OK","CHECK")) | G13: CBA Mel July 2026 | H13: Onsite | I13: ONSITE | J13: Contract | K13: GST 10% | L13: 11377.12 | M13: =IF(L13="","",IF(K13="GST 10%",ROUND(L13*set_GSTRate,2),0)) | N13: =IF(L13="","",L13+M13) | O13: 41100 | P13: Y | Q13: N | T13: Invoiced | U13: Deduct 8hrs CN for 03/07 | V13: =IF(COUNTA(A13,D13,C13,L13)=0,"",IF(A13="","No date - sits outside every month",IF(E13="","No job number",IF(F13="CHECK","Job number is not in the Xero job list",IF(I13="","No cost centre",IF(AND(P13="Y",C13=""),"Marked posted to Xero but has no invoice number",IF(AND(L13<>"",K13=""),"No tax code",IF(AND(L13<>"",O13=""),"No revenue GL code","")))))))) | W13: =IF(E13="","",IFERROR(INDEX(lst_JobName,MATCH(E13&"",lst_Jobs,0)),"")) | X13: =IF(E13="","",COUNTIFS(tbl_Finance[Job Number],E13&"",tbl_Finance[Ex GST],"<>")) | Y13: =IF(E13="","",SUMIFS(tbl_Finance[Ex GST],tbl_Finance[Job Number],E13&"")) | Z13: =IF(E13="","",SUMIFS(tbl_Finance[Ex GST],tbl_Finance[Job Number],E13&"",tbl_Finance[Xero Invoice No],"<>")) | AA13: =IF(E13="","",Y13-Z13) | AB13: =IF(E13="","",IF(H13="Onsite",IFERROR(INDEX(tbl_Onsite[Qwilr Quote],MATCH(E13&"",tbl_Onsite[Job Number],0)),""),IF(H13="Production",IFERROR(IF(INDEX(tbl_Production[Current RMS No],MATCH(E13&"",tbl_Production[Job Number],0))="",INDEX(tbl_Production[Qwilr Quote],MATCH(E13&"",tbl_Production[Job Number],0)),INDEX(tbl_Production[Current RMS No],MATCH(E13&"",tbl_Production[Job Number],0))),""),IF(H13="Consulting",IFERROR(INDEX(tbl_Consulting[Qwilr Quote],MATCH(E13&"",tbl_Consulting[Job Number],0)),""),"")))) | AC13: =IF(AB13="","",IF(AND(LEFT(AB13,4)<>"http",IF(H13="Production",set_RMSBase,set_QwilrBase)=""),"",HYPERLINK(IF(LEFT(AB13,4)="http",AB13,IF(H13="Production",set_RMSBase,set_QwilrBase)&AB13),"Open"))) | AD13: =IF(E13="","",IF(H13="Production",IFERROR(INDEX(tbl_Production[Total Expense],MATCH(E13&"",tbl_Production[Job Number],0)),0),IF(H13="Consulting",IFERROR(INDEX(tbl_Consulting[Total Expense],MATCH(E13&"",tbl_Consulting[Job Number],0)),0),0))) | AE13: =IF(E13="","",Y13-N(AD13)) | AF13: =IFERROR(AE13/Y13,"") | AG13: =IF(E13="","",IF(H13="Onsite",IFERROR(INDEX(tbl_Onsite[Notes],MATCH(E13&"",tbl_Onsite[Job Number],0)),""),IF(H13="Production",IFERROR(INDEX(tbl_Production[Notes],MATCH(E13&"",tbl_Production[Job Number],0)),""),IF(H13="Consulting",IFERROR(INDEX(tbl_Consulting[Notes],MATCH(E13&"",tbl_Consulting[Job Number],0)),""),""))))
A14: 46234 | B14: =IF(A14="","",EOMONTH(A14,0)) | C14: INV-10535 | D14: PWC | E14: 25101301B | F14: =IF(E14="","",IF(COUNTIF(lst_Jobs,E14&"")>0,"OK","CHECK")) | G14: PWC Sydney IT July 2026 | H14: Onsite | I14: ONSITE | J14: Contract | K14: GST 10% | L14: 11907 | M14: =IF(L14="","",IF(K14="GST 10%",ROUND(L14*set_GSTRate,2),0)) | N14: =IF(L14="","",L14+M14) | O14: 41100 | P14: Y | Q14: N | T14: Invoiced | V14: =IF(COUNTA(A14,D14,C14,L14)=0,"",IF(A14="","No date - sits outside every month",IF(E14="","No job number",IF(F14="CHECK","Job number is not in the Xero job list",IF(I14="","No cost centre",IF(AND(P14="Y",C14=""),"Marked posted to Xero but has no invoice number",IF(AND(L14<>"",K14=""),"No tax code",IF(AND(L14<>"",O14=""),"No revenue GL code","")))))))) | W14: =IF(E14="","",IFERROR(INDEX(lst_JobName,MATCH(E14&"",lst_Jobs,0)),"")) | X14: =IF(E14="","",COUNTIFS(tbl_Finance[Job Number],E14&"",tbl_Finance[Ex GST],"<>")) | Y14: =IF(E14="","",SUMIFS(tbl_Finance[Ex GST],tbl_Finance[Job Number],E14&"")) | Z14: =IF(E14="","",SUMIFS(tbl_Finance[Ex GST],tbl_Finance[Job Number],E14&"",tbl_Finance[Xero Invoice No],"<>")) | AA14: =IF(E14="","",Y14-Z14) | AB14: =IF(E14="","",IF(H14="Onsite",IFERROR(INDEX(tbl_Onsite[Qwilr Quote],MATCH(E14&"",tbl_Onsite[Job Number],0)),""),IF(H14="Production",IFERROR(IF(INDEX(tbl_Production[Current RMS No],MATCH(E14&"",tbl_Production[Job Number],0))="",INDEX(tbl_Production[Qwilr Quote],MATCH(E14&"",tbl_Production[Job Number],0)),INDEX(tbl_Production[Current RMS No],MATCH(E14&"",tbl_Production[Job Number],0))),""),IF(H14="Consulting",IFERROR(INDEX(tbl_Consulting[Qwilr Quote],MATCH(E14&"",tbl_Consulting[Job Number],0)),""),"")))) | AC14: =IF(AB14="","",IF(AND(LEFT(AB14,4)<>"http",IF(H14="Production",set_RMSBase,set_QwilrBase)=""),"",HYPERLINK(IF(LEFT(AB14,4)="http",AB14,IF(H14="Production",set_RMSBase,set_QwilrBase)&AB14),"Open"))) | AD14: =IF(E14="","",IF(H14="Production",IFERROR(INDEX(tbl_Production[Total Expense],MATCH(E14&"",tbl_Production[Job Number],0)),0),IF(H14="Consulting",IFERROR(INDEX(tbl_Consulting[Total Expense],MATCH(E14&"",tbl_Consulting[Job Number],0)),0),0))) | AE14: =IF(E14="","",Y14-N(AD14)) | AF14: =IFERROR(AE14/Y14,"") | AG14: =IF(E14="","",IF(H14="Onsite",IFERROR(INDEX(tbl_Onsite[Notes],MATCH(E14&"",tbl_Onsite[Job Number],0)),""),IF(H14="Production",IFERROR(INDEX(tbl_Production[Notes],MATCH(E14&"",tbl_Production[Job Number],0)),""),IF(H14="Consulting",IFERROR(INDEX(tbl_Consulting[Notes],MATCH(E14&"",tbl_Consulting[Job Number],0)),""),""))))
A15: 46234 | B15: =IF(A15="","",EOMONTH(A15,0)) | C15: INV-10536 | D15: RICOH | E15: 2880 | F15: =IF(E15="","",IF(COUNTIF(lst_Jobs,E15&"")>0,"OK","CHECK")) | G15: Ricoh Contract July 2026 | H15: Onsite | I15: ONSITE | J15: Contract | K15: GST 10% | L15: 11860.5 | M15: =IF(L15="","",IF(K15="GST 10%",ROUND(L15*set_GSTRate,2),0)) | N15: =IF(L15="","",L15+M15) | O15: 41100 | P15: Y | Q15: N | T15: Invoiced | U15: 2 months extension | V15: =IF(COUNTA(A15,D15,C15,L15)=0,"",IF(A15="","No date - sits outside every month",IF(E15="","No job number",IF(F15="CHECK","Job number is not in the Xero job list",IF(I15="","No cost centre",IF(AND(P15="Y",C15=""),"Marked posted to Xero but has no invoice number",IF(AND(L15<>"",K15=""),"No tax code",IF(AND(L15<>"",O15=""),"No revenue GL code","")))))))) | W15: =IF(E15="","",IFERROR(INDEX(lst_JobName,MATCH(E15&"",lst_Jobs,0)),"")) | X15: =IF(E15="","",COUNTIFS(tbl_Finance[Job Number],E15&"",tbl_Finance[Ex GST],"<>")) | Y15: =IF(E15="","",SUMIFS(tbl_Finance[Ex GST],tbl_Finance[Job Number],E15&"")) | Z15: =IF(E15="","",SUMIFS(tbl_Finance[Ex GST],tbl_Finance[Job Number],E15&"",tbl_Finance[Xero Invoice No],"<>")) | AA15: =IF(E15="","",Y15-Z15) | AB15: =IF(E15="","",IF(H15="Onsite",IFERROR(INDEX(tbl_Onsite[Qwilr Quote],MATCH(E15&"",tbl_Onsite[Job Number],0)),""),IF(H15="Production",IFERROR(IF(INDEX(tbl_Production[Current RMS No],MATCH(E15&"",tbl_Production[Job Number],0))="",INDEX(tbl_Production[Qwilr Quote],MATCH(E15&"",tbl_Production[Job Number],0)),INDEX(tbl_Production[Current RMS No],MATCH(E15&"",tbl_Production[Job Number],0))),""),IF(H15="Consulting",IFERROR(INDEX(tbl_Consulting[Qwilr Quote],MATCH(E15&"",tbl_Consulting[Job Number],0)),""),"")))) | AC15: =IF(AB15="","",IF(AND(LEFT(AB15,4)<>"http",IF(H15="Production",set_RMSBase,set_QwilrBase)=""),"",HYPERLINK(IF(LEFT(AB15,4)="http",AB15,IF(H15="Production",set_RMSBase,set_QwilrBase)&AB15),"Open"))) | AD15: =IF(E15="","",IF(H15="Production",IFERROR(INDEX(tbl_Production[Total Expense],MATCH(E15&"",tbl_Production[Job Number],0)),0),IF(H15="Consulting",IFERROR(INDEX(tbl_Consulting[Total Expense],MATCH(E15&"",tbl_Consulting[Job Number],0)),0),0))) | AE15: =IF(E15="","",Y15-N(AD15)) | AF15: =IFERROR(AE15/Y15,"") | AG15: =IF(E15="","",IF(H15="Onsite",IFERROR(INDEX(tbl_Onsite[Notes],MATCH(E15&"",tbl_Onsite[Job Number],0)),""),IF(H15="Production",IFERROR(INDEX(tbl_Production[Notes],MATCH(E15&"",tbl_Production[Job Number],0)),""),IF(H15="Consulting",IFERROR(INDEX(tbl_Consulting[Notes],MATCH(E15&"",tbl_Consulting[Job Number],0)),""),""))))
A16: 46234 | B16: =IF(A16="","",EOMONTH(A16,0)) | C16: INV-10537 | D16: PWC | F16: =IF(E16="","",IF(COUNTIF(lst_Jobs,E16&"")>0,"OK","CHECK")) | G16: PWC Dedicated Tech 29/07/2026 | H16: Onsite | I16: ONSITE | J16: Contract | K16: GST 10% | L16: 340 | M16: =IF(L16="","",IF(K16="GST 10%",ROUND(L16*set_GSTRate,2),0)) | N16: =IF(L16="","",L16+M16) | O16: 41100 | P16: Y | Q16: N | T16: Invoiced | U16: 29/07/2026 4hours | V16: =IF(COUNTA(A16,D16,C16,L16)=0,"",IF(A16="","No date - sits outside every month",IF(E16="","No job number",IF(F16="CHECK","Job number is not in the Xero job list",IF(I16="","No cost centre",IF(AND(P16="Y",C16=""),"Marked posted to Xero but has no invoice number",IF(AND(L16<>"",K16=""),"No tax code",IF(AND(L16<>"",O16=""),"No revenue GL code","")))))))) | W16: =IF(E16="","",IFERROR(INDEX(lst_JobName,MATCH(E16&"",lst_Jobs,0)),"")) | X16: =IF(E16="","",COUNTIFS(tbl_Finance[Job Number],E16&"",tbl_Finance[Ex GST],"<>")) | Y16: =IF(E16="","",SUMIFS(tbl_Finance[Ex GST],tbl_Finance[Job Number],E16&"")) | Z16: =IF(E16="","",SUMIFS(tbl_Finance[Ex GST],tbl_Finance[Job Number],E16&"",tbl_Finance[Xero Invoice No],"<>")) | AA16: =IF(E16="","",Y16-Z16) | AB16: =IF(E16="","",IF(H16="Onsite",IFERROR(INDEX(tbl_Onsite[Qwilr Quote],MATCH(E16&"",tbl_Onsite[Job Number],0)),""),IF(H16="Production",IFERROR(IF(INDEX(tbl_Production[Current RMS No],MATCH(E16&"",tbl_Production[Job Number],0))="",INDEX(tbl_Production[Qwilr Quote],MATCH(E16&"",tbl_Production[Job Number],0)),INDEX(tbl_Production[Current RMS No],MATCH(E16&"",tbl_Production[Job Number],0))),""),IF(H16="Consulting",IFERROR(INDEX(tbl_Consulting[Qwilr Quote],MATCH(E16&"",tbl_Consulting[Job Number],0)),""),"")))) | AC16: =IF(AB16="","",IF(AND(LEFT(AB16,4)<>"http",IF(H16="Production",set_RMSBase,set_QwilrBase)=""),"",HYPERLINK(IF(LEFT(AB16,4)="http",AB16,IF(H16="Production",set_RMSBase,set_QwilrBase)&AB16),"Open"))) | AD16: =IF(E16="","",IF(H16="Production",IFERROR(INDEX(tbl_Production[Total Expense],MATCH(E16&"",tbl_Production[Job Number],0)),0),IF(H16="Consulting",IFERROR(INDEX(tbl_Consulting[Total Expense],MATCH(E16&"",tbl_Consulting[Job Number],0)),0),0))) | AE16: =IF(E16="","",Y16-N(AD16)) | AF16: =IFERROR(AE16/Y16,"") | AG16: =IF(E16="","",IF(H16="Onsite",IFERROR(INDEX(tbl_Onsite[Notes],MATCH(E16&"",tbl_Onsite[Job Number],0)),""),IF(H16="Production",IFERROR(INDEX(tbl_Production[Notes],MATCH(E16&"",tbl_Production[Job Number],0)),""),IF(H16="Consulting",IFERROR(INDEX(tbl_Consulting[Notes],MATCH(E16&"",tbl_Consulting[Job Number],0)),""),""))))
A17: 46234 | B17: =IF(A17="","",EOMONTH(A17,0)) | C17: INV-10541 | D17: APN | E17: 3056 | F17: =IF(E17="","",IF(COUNTIF(lst_Jobs,E17&"")>0,"OK","CHECK")) | G17: APN Tech Support July 22 & 24 | H17: Onsite | I17: ONSITE | J17: Contract | K17: GST 10% | L17: 680 | M17: =IF(L17="","",IF(K17="GST 10%",ROUND(L17*set_GSTRate,2),0)) | N17: =IF(L17="","",L17+M17) | O17: 41100 | P17: Y | Q17: N | T17: Invoiced | V17: =IF(COUNTA(A17,D17,C17,L17)=0,"",IF(A17="","No date - sits outside every month",IF(E17="","No job number",IF(F17="CHECK","Job number is not in the Xero job list",IF(I17="","No cost centre",IF(AND(P17="Y",C17=""),"Marked posted to Xero but has no invoice number",IF(AND(L17<>"",K17=""),"No tax code",IF(AND(L17<>"",O17=""),"No revenue GL code","")))))))) | W17: =IF(E17="","",IFERROR(INDEX(lst_JobName,MATCH(E17&"",lst_Jobs,0)),"")) | X17: =IF(E17="","",COUNTIFS(tbl_Finance[Job Number],E17&"",tbl_Finance[Ex GST],"<>")) | Y17: =IF(E17="","",SUMIFS(tbl_Finance[Ex GST],tbl_Finance[Job Number],E17&"")) | Z17: =IF(E17="","",SUMIFS(tbl_Finance[Ex GST],tbl_Finance[Job Number],E17&"",tbl_Finance[Xero Invoice No],"<>")) | AA17: =IF(E17="","",Y17-Z17) | AB17: =IF(E17="","",IF(H17="Onsite",IFERROR(INDEX(tbl_Onsite[Qwilr Quote],MATCH(E17&"",tbl_Onsite[Job Number],0)),""),IF(H17="Production",IFERROR(IF(INDEX(tbl_Production[Current RMS No],MATCH(E17&"",tbl_Production[Job Number],0))="",INDEX(tbl_Production[Qwilr Quote],MATCH(E17&"",tbl_Production[Job Number],0)),INDEX(tbl_Production[Current RMS No],MATCH(E17&"",tbl_Production[Job Number],0))),""),IF(H17="Consulting",IFERROR(INDEX(tbl_Consulting[Qwilr Quote],MATCH(E17&"",tbl_Consulting[Job Number],0)),""),"")))) | AC17: =IF(AB17="","",IF(AND(LEFT(AB17,4)<>"http",IF(H17="Production",set_RMSBase,set_QwilrBase)=""),"",HYPERLINK(IF(LEFT(AB17,4)="http",AB17,IF(H17="Production",set_RMSBase,set_QwilrBase)&AB17),"Open"))) | AD17: =IF(E17="","",IF(H17="Production",IFERROR(INDEX(tbl_Production[Total Expense],MATCH(E17&"",tbl_Production[Job Number],0)),0),IF(H17="Consulting",IFERROR(INDEX(tbl_Consulting[Total Expense],MATCH(E17&"",tbl_Consulting[Job Number],0)),0),0))) | AE17: =IF(E17="","",Y17-N(AD17)) | AF17: =IFERROR(AE17/Y17,"") | AG17: =IF(E17="","",IF(H17="Onsite",IFERROR(INDEX(tbl_Onsite[Notes],MATCH(E17&"",tbl_Onsite[Job Number],0)),""),IF(H17="Production",IFERROR(INDEX(tbl_Production[Notes],MATCH(E17&"",tbl_Production[Job Number],0)),""),IF(H17="Consulting",IFERROR(INDEX(tbl_Consulting[Notes],MATCH(E17&"",tbl_Consulting[Job Number],0)),""),""))))
A18: 46234 | B18: =IF(A18="","",EOMONTH(A18,0)) | C18: INV-10539 | D18: PWC | E18: 20250731 | F18: =IF(E18="","",IF(COUNTIF(lst_Jobs,E18&"")>0,"OK","CHECK")) | G18: PWC Pool of Hours (50 hours) | H18: Onsite | I18: ONSITE | J18: Contract | K18: GST 10% | L18: 4250 | M18: =IF(L18="","",IF(K18="GST 10%",ROUND(L18*set_GSTRate,2),0)) | N18: =IF(L18="","",L18+M18) | O18: 41100 | P18: Y | Q18: N | T18: Invoiced | U18: PO2601703215 | V18: =IF(COUNTA(A18,D18,C18,L18)=0,"",IF(A18="","No date - sits outside every month",IF(E18="","No job number",IF(F18="CHECK","Job number is not in the Xero job list",IF(I18="","No cost centre",IF(AND(P18="Y",C18=""),"Marked posted to Xero but has no invoice number",IF(AND(L18<>"",K18=""),"No tax code",IF(AND(L18<>"",O18=""),"No revenue GL code","")))))))) | W18: =IF(E18="","",IFERROR(INDEX(lst_JobName,MATCH(E18&"",lst_Jobs,0)),"")) | X18: =IF(E18="","",COUNTIFS(tbl_Finance[Job Number],E18&"",tbl_Finance[Ex GST],"<>")) | Y18: =IF(E18="","",SUMIFS(tbl_Finance[Ex GST],tbl_Finance[Job Number],E18&"")) | Z18: =IF(E18="","",SUMIFS(tbl_Finance[Ex GST],tbl_Finance[Job Number],E18&"",tbl_Finance[Xero Invoice No],"<>")) | AA18: =IF(E18="","",Y18-Z18) | AB18: =IF(E18="","",IF(H18="Onsite",IFERROR(INDEX(tbl_Onsite[Qwilr Quote],MATCH(E18&"",tbl_Onsite[Job Number],0)),""),IF(H18="Production",IFERROR(IF(INDEX(tbl_Production[Current RMS No],MATCH(E18&"",tbl_Production[Job Number],0))="",INDEX(tbl_Production[Qwilr Quote],MATCH(E18&"",tbl_Production[Job Number],0)),INDEX(tbl_Production[Current RMS No],MATCH(E18&"",tbl_Production[Job Number],0))),""),IF(H18="Consulting",IFERROR(INDEX(tbl_Consulting[Qwilr Quote],MATCH(E18&"",tbl_Consulting[Job Number],0)),""),"")))) | AC18: =IF(AB18="","",IF(AND(LEFT(AB18,4)<>"http",IF(H18="Production",set_RMSBase,set_QwilrBase)=""),"",HYPERLINK(IF(LEFT(AB18,4)="http",AB18,IF(H18="Production",set_RMSBase,set_QwilrBase)&AB18),"Open"))) | AD18: =IF(E18="","",IF(H18="Production",IFERROR(INDEX(tbl_Production[Total Expense],MATCH(E18&"",tbl_Production[Job Number],0)),0),IF(H18="Consulting",IFERROR(INDEX(tbl_Consulting[Total Expense],MATCH(E18&"",tbl_Consulting[Job Number],0)),0),0))) | AE18: =IF(E18="","",Y18-N(AD18)) | AF18: =IFERROR(AE18/Y18,"") | AG18: =IF(E18="","",IF(H18="Onsite",IFERROR(INDEX(tbl_Onsite[Notes],MATCH(E18&"",tbl_Onsite[Job Number],0)),""),IF(H18="Production",IFERROR(INDEX(tbl_Production[Notes],MATCH(E18&"",tbl_Production[Job Number],0)),""),IF(H18="Consulting",IFERROR(INDEX(tbl_Consulting[Notes],MATCH(E18&"",tbl_Consulting[Job Number],0)),""),""))))
A19: 46234 | B19: =IF(A19="","",EOMONTH(A19,0)) | C19: INV-10542 | D19: CBA | E19: 1668 | F19: =IF(E19="","",IF(COUNTIF(lst_Jobs,E19&"")>0,"OK","CHECK")) | G19: AH Support 02/07/2026 | H19: Onsite | I19: ONSITE | J19: Contract | K19: GST 10% | L19: 180 | M19: =IF(L19="","",IF(K19="GST 10%",ROUND(L19*set_GSTRate,2),0)) | N19: =IF(L19="","",L19+M19) | O19: 41100 | P19: Y | Q19: N | T19: Invoiced | V19: =IF(COUNTA(A19,D19,C19,L19)=0,"",IF(A19="","No date - sits outside every month",IF(E19="","No job number",IF(F19="CHECK","Job number is not in the Xero job list",IF(I19="","No cost centre",IF(AND(P19="Y",C19=""),"Marked posted to Xero but has no invoice number",IF(AND(L19<>"",K19=""),"No tax code",IF(AND(L19<>"",O19=""),"No revenue GL code","")))))))) | W19: =IF(E19="","",IFERROR(INDEX(lst_JobName,MATCH(E19&"",lst_Jobs,0)),"")) | X19: =IF(E19="","",COUNTIFS(tbl_Finance[Job Number],E19&"",tbl_Finance[Ex GST],"<>")) | Y19: =IF(E19="","",SUMIFS(tbl_Finance[Ex GST],tbl_Finance[Job Number],E19&"")) | Z19: =IF(E19="","",SUMIFS(tbl_Finance[Ex GST],tbl_Finance[Job Number],E19&"",tbl_Finance[Xero Invoice No],"<>")) | AA19: =IF(E19="","",Y19-Z19) | AB19: =IF(E19="","",IF(H19="Onsite",IFERROR(INDEX(tbl_Onsite[Qwilr Quote],MATCH(E19&"",tbl_Onsite[Job Number],0)),""),IF(H19="Production",IFERROR(IF(INDEX(tbl_Production[Current RMS No],MATCH(E19&"",tbl_Production[Job Number],0))="",INDEX(tbl_Production[Qwilr Quote],MATCH(E19&"",tbl_Production[Job Number],0)),INDEX(tbl_Production[Current RMS No],MATCH(E19&"",tbl_Production[Job Number],0))),""),IF(H19="Consulting",IFERROR(INDEX(tbl_Consulting[Qwilr Quote],MATCH(E19&"",tbl_Consulting[Job Number],0)),""),"")))) | AC19: =IF(AB19="","",IF(AND(LEFT(AB19,4)<>"http",IF(H19="Production",set_RMSBase,set_QwilrBase)=""),"",HYPERLINK(IF(LEFT(AB19,4)="http",AB19,IF(H19="Production",set_RMSBase,set_QwilrBase)&AB19),"Open"))) | AD19: =IF(E19="","",IF(H19="Production",IFERROR(INDEX(tbl_Production[Total Expense],MATCH(E19&"",tbl_Production[Job Number],0)),0),IF(H19="Consulting",IFERROR(INDEX(tbl_Consulting[Total Expense],MATCH(E19&"",tbl_Consulting[Job Number],0)),0),0))) | AE19: =IF(E19="","",Y19-N(AD19)) | AF19: =IFERROR(AE19/Y19,"") | AG19: =IF(E19="","",IF(H19="Onsite",IFERROR(INDEX(tbl_Onsite[Notes],MATCH(E19&"",tbl_Onsite[Job Number],0)),""),IF(H19="Production",IFERROR(INDEX(tbl_Production[Notes],MATCH(E19&"",tbl_Production[Job Number],0)),""),IF(H19="Consulting",IFERROR(INDEX(tbl_Consulting[Notes],MATCH(E19&"",tbl_Consulting[Job Number],0)),""),""))))
A20: 46234 | B20: =IF(A20="","",EOMONTH(A20,0)) | C20: INV-10543 | D20: CBA | E20: 1668 | F20: =IF(E20="","",IF(COUNTIF(lst_Jobs,E20&"")>0,"OK","CHECK")) | G20: DT Support 02/07/2026 | H20: Onsite | I20: ONSITE | J20: Contract | K20: GST 10% | L20: 425 | M20: =IF(L20="","",IF(K20="GST 10%",ROUND(L20*set_GSTRate,2),0)) | N20: =IF(L20="","",L20+M20) | O20: 41100 | P20: Y | Q20: N | T20: Invoiced | V20: =IF(COUNTA(A20,D20,C20,L20)=0,"",IF(A20="","No date - sits outside every month",IF(E20="","No job number",IF(F20="CHECK","Job number is not in the Xero job list",IF(I20="","No cost centre",IF(AND(P20="Y",C20=""),"Marked posted to Xero but has no invoice number",IF(AND(L20<>"",K20=""),"No tax code",IF(AND(L20<>"",O20=""),"No revenue GL code","")))))))) | W20: =IF(E20="","",IFERROR(INDEX(lst_JobName,MATCH(E20&"",lst_Jobs,0)),"")) | X20: =IF(E20="","",COUNTIFS(tbl_Finance[Job Number],E20&"",tbl_Finance[Ex GST],"<>")) | Y20: =IF(E20="","",SUMIFS(tbl_Finance[Ex GST],tbl_Finance[Job Number],E20&"")) | Z20: =IF(E20="","",SUMIFS(tbl_Finance[Ex GST],tbl_Finance[Job Number],E20&"",tbl_Finance[Xero Invoice No],"<>")) | AA20: =IF(E20="","",Y20-Z20) | AB20: =IF(E20="","",IF(H20="Onsite",IFERROR(INDEX(tbl_Onsite[Qwilr Quote],MATCH(E20&"",tbl_Onsite[Job Number],0)),""),IF(H20="Production",IFERROR(IF(INDEX(tbl_Production[Current RMS No],MATCH(E20&"",tbl_Production[Job Number],0))="",INDEX(tbl_Production[Qwilr Quote],MATCH(E20&"",tbl_Production[Job Number],0)),INDEX(tbl_Production[Current RMS No],MATCH(E20&"",tbl_Production[Job Number],0))),""),IF(H20="Consulting",IFERROR(INDEX(tbl_Consulting[Qwilr Quote],MATCH(E20&"",tbl_Consulting[Job Number],0)),""),"")))) | AC20: =IF(AB20="","",IF(AND(LEFT(AB20,4)<>"http",IF(H20="Production",set_RMSBase,set_QwilrBase)=""),"",HYPERLINK(IF(LEFT(AB20,4)="http",AB20,IF(H20="Production",set_RMSBase,set_QwilrBase)&AB20),"Open"))) | AD20: =IF(E20="","",IF(H20="Production",IFERROR(INDEX(tbl_Production[Total Expense],MATCH(E20&"",tbl_Production[Job Number],0)),0),IF(H20="Consulting",IFERROR(INDEX(tbl_Consulting[Total Expense],MATCH(E20&"",tbl_Consulting[Job Number],0)),0),0))) | AE20: =IF(E20="","",Y20-N(AD20)) | AF20: =IFERROR(AE20/Y20,"") | AG20: =IF(E20="","",IF(H20="Onsite",IFERROR(INDEX(tbl_Onsite[Notes],MATCH(E20&"",tbl_Onsite[Job Number],0)),""),IF(H20="Production",IFERROR(INDEX(tbl_Production[Notes],MATCH(E20&"",tbl_Production[Job Number],0)),""),IF(H20="Consulting",IFERROR(INDEX(tbl_Consulting[Notes],MATCH(E20&"",tbl_Consulting[Job Number],0)),""),""))))
A21: 46234 | B21: =IF(A21="","",EOMONTH(A21,0)) | C21: INV-10544 | D21: CBA | E21: 1668 | F21: =IF(E21="","",IF(COUNTIF(lst_Jobs,E21&"")>0,"OK","CHECK")) | G21: DT Support 23/07/2026 | H21: Onsite | I21: ONSITE | J21: Contract | K21: GST 10% | L21: 510 | M21: =IF(L21="","",IF(K21="GST 10%",ROUND(L21*set_GSTRate,2),0)) | N21: =IF(L21="","",L21+M21) | O21: 41100 | P21: Y | Q21: N | T21: Invoiced | V21: =IF(COUNTA(A21,D21,C21,L21)=0,"",IF(A21="","No date - sits outside every month",IF(E21="","No job number",IF(F21="CHECK","Job number is not in the Xero job list",IF(I21="","No cost centre",IF(AND(P21="Y",C21=""),"Marked posted to Xero but has no invoice number",IF(AND(L21<>"",K21=""),"No tax code",IF(AND(L21<>"",O21=""),"No revenue GL code","")))))))) | W21: =IF(E21="","",IFERROR(INDEX(lst_JobName,MATCH(E21&"",lst_Jobs,0)),"")) | X21: =IF(E21="","",COUNTIFS(tbl_Finance[Job Number],E21&"",tbl_Finance[Ex GST],"<>")) | Y21: =IF(E21="","",SUMIFS(tbl_Finance[Ex GST],tbl_Finance[Job Number],E21&"")) | Z21: =IF(E21="","",SUMIFS(tbl_Finance[Ex GST],tbl_Finance[Job Number],E21&"",tbl_Finance[Xero Invoice No],"<>")) | AA21: =IF(E21="","",Y21-Z21) | AB21: =IF(E21="","",IF(H21="Onsite",IFERROR(INDEX(tbl_Onsite[Qwilr Quote],MATCH(E21&"",tbl_Onsite[Job Number],0)),""),IF(H21="Production",IFERROR(IF(INDEX(tbl_Production[Current RMS No],MATCH(E21&"",tbl_Production[Job Number],0))="",INDEX(tbl_Production[Qwilr Quote],MATCH(E21&"",tbl_Production[Job Number],0)),INDEX(tbl_Production[Current RMS No],MATCH(E21&"",tbl_Production[Job Number],0))),""),IF(H21="Consulting",IFERROR(INDEX(tbl_Consulting[Qwilr Quote],MATCH(E21&"",tbl_Consulting[Job Number],0)),""),"")))) | AC21: =IF(AB21="","",IF(AND(LEFT(AB21,4)<>"http",IF(H21="Production",set_RMSBase,set_QwilrBase)=""),"",HYPERLINK(IF(LEFT(AB21,4)="http",AB21,IF(H21="Production",set_RMSBase,set_QwilrBase)&AB21),"Open"))) | AD21: =IF(E21="","",IF(H21="Production",IFERROR(INDEX(tbl_Production[Total Expense],MATCH(E21&"",tbl_Production[Job Number],0)),0),IF(H21="Consulting",IFERROR(INDEX(tbl_Consulting[Total Expense],MATCH(E21&"",tbl_Consulting[Job Number],0)),0),0))) | AE21: =IF(E21="","",Y21-N(AD21)) | AF21: =IFERROR(AE21/Y21,"") | AG21: =IF(E21="","",IF(H21="Onsite",IFERROR(INDEX(tbl_Onsite[Notes],MATCH(E21&"",tbl_Onsite[Job Number],0)),""),IF(H21="Production",IFERROR(INDEX(tbl_Production[Notes],MATCH(E21&"",tbl_Production[Job Number],0)),""),IF(H21="Consulting",IFERROR(INDEX(tbl_Consulting[Notes],MATCH(E21&"",tbl_Consulting[Job Number],0)),""),""))))
A22: 46233 | B22: =IF(A22="","",EOMONTH(A22,0)) | C22: INV-10545 | D22: PWC | E22: 2540 | F22: =IF(E22="","",IF(COUNTIF(lst_Jobs,E22&"")>0,"OK","CHECK")) | G22: PWC Dedicated Tech 30/07/2026 | H22: Onsite | I22: ONSITE | J22: Contract | K22: GST 10% | L22: 340 | M22: =IF(L22="","",IF(K22="GST 10%",ROUND(L22*set_GSTRate,2),0)) | N22: =IF(L22="","",L22+M22) | O22: 41100 | P22: Y | Q22: N | T22: Invoiced | U22: PO2601703274 | V22: =IF(COUNTA(A22,D22,C22,L22)=0,"",IF(A22="","No date - sits outside every month",IF(E22="","No job number",IF(F22="CHECK","Job number is not in the Xero job list",IF(I22="","No cost centre",IF(AND(P22="Y",C22=""),"Marked posted to Xero but has no invoice number",IF(AND(L22<>"",K22=""),"No tax code",IF(AND(L22<>"",O22=""),"No revenue GL code","")))))))) | W22: =IF(E22="","",IFERROR(INDEX(lst_JobName,MATCH(E22&"",lst_Jobs,0)),"")) | X22: =IF(E22="","",COUNTIFS(tbl_Finance[Job Number],E22&"",tbl_Finance[Ex GST],"<>")) | Y22: =IF(E22="","",SUMIFS(tbl_Finance[Ex GST],tbl_Finance[Job Number],E22&"")) | Z22: =IF(E22="","",SUMIFS(tbl_Finance[Ex GST],tbl_Finance[Job Number],E22&"",tbl_Finance[Xero Invoice No],"<>")) | AA22: =IF(E22="","",Y22-Z22) | AB22: =IF(E22="","",IF(H22="Onsite",IFERROR(INDEX(tbl_Onsite[Qwilr Quote],MATCH(E22&"",tbl_Onsite[Job Number],0)),""),IF(H22="Production",IFERROR(IF(INDEX(tbl_Production[Current RMS No],MATCH(E22&"",tbl_Production[Job Number],0))="",INDEX(tbl_Production[Qwilr Quote],MATCH(E22&"",tbl_Production[Job Number],0)),INDEX(tbl_Production[Current RMS No],MATCH(E22&"",tbl_Production[Job Number],0))),""),IF(H22="Consulting",IFERROR(INDEX(tbl_Consulting[Qwilr Quote],MATCH(E22&"",tbl_Consulting[Job Number],0)),""),"")))) | AC22: =IF(AB22="","",IF(AND(LEFT(AB22,4)<>"http",IF(H22="Production",set_RMSBase,set_QwilrBase)=""),"",HYPERLINK(IF(LEFT(AB22,4)="http",AB22,IF(H22="Production",set_RMSBase,set_QwilrBase)&AB22),"Open"))) | AD22: =IF(E22="","",IF(H22="Production",IFERROR(INDEX(tbl_Production[Total Expense],MATCH(E22&"",tbl_Production[Job Number],0)),0),IF(H22="Consulting",IFERROR(INDEX(tbl_Consulting[Total Expense],MATCH(E22&"",tbl_Consulting[Job Number],0)),0),0))) | AE22: =IF(E22="","",Y22-N(AD22)) | AF22: =IFERROR(AE22/Y22,"") | AG22: =IF(E22="","",IF(H22="Onsite",IFERROR(INDEX(tbl_Onsite[Notes],MATCH(E22&"",tbl_Onsite[Job Number],0)),""),IF(H22="Production",IFERROR(INDEX(tbl_Production[Notes],MATCH(E22&"",tbl_Production[Job Number],0)),""),IF(H22="Consulting",IFERROR(INDEX(tbl_Consulting[Notes],MATCH(E22&"",tbl_Consulting[Job Number],0)),""),""))))
A23: 46233 | B23: =IF(A23="","",EOMONTH(A23,0)) | C23: INV-10546 | D23: DTTL | E23: 26062501/2347 | F23: =IF(E23="","",IF(COUNTIF(lst_Jobs,E23&"")>0,"OK","CHECK")) | G23: DH Travel 06-07/07 & Ad-hoc Tech Support 30/07 & Market Shapers | H23: Onsite | I23: ONSITE | J23: Contract | K23: GST 10% | L23: 1672.5 | M23: =IF(L23="","",IF(K23="GST 10%",ROUND(L23*set_GSTRate,2),0)) | N23: =IF(L23="","",L23+M23) | O23: 41100 | P23: Y | Q23: N | T23: Invoiced | V23: =IF(COUNTA(A23,D23,C23,L23)=0,"",IF(A23="","No date - sits outside every month",IF(E23="","No job number",IF(F23="CHECK","Job number is not in the Xero job list",IF(I23="","No cost centre",IF(AND(P23="Y",C23=""),"Marked posted to Xero but has no invoice number",IF(AND(L23<>"",K23=""),"No tax code",IF(AND(L23<>"",O23=""),"No revenue GL code","")))))))) | W23: =IF(E23="","",IFERROR(INDEX(lst_JobName,MATCH(E23&"",lst_Jobs,0)),"")) | X23: =IF(E23="","",COUNTIFS(tbl_Finance[Job Number],E23&"",tbl_Finance[Ex GST],"<>")) | Y23: =IF(E23="","",SUMIFS(tbl_Finance[Ex GST],tbl_Finance[Job Number],E23&"")) | Z23: =IF(E23="","",SUMIFS(tbl_Finance[Ex GST],tbl_Finance[Job Number],E23&"",tbl_Finance[Xero Invoice No],"<>")) | AA23: =IF(E23="","",Y23-Z23) | AB23: =IF(E23="","",IF(H23="Onsite",IFERROR(INDEX(tbl_Onsite[Qwilr Quote],MATCH(E23&"",tbl_Onsite[Job Number],0)),""),IF(H23="Production",IFERROR(IF(INDEX(tbl_Production[Current RMS No],MATCH(E23&"",tbl_Production[Job Number],0))="",INDEX(tbl_Production[Qwilr Quote],MATCH(E23&"",tbl_Production[Job Number],0)),INDEX(tbl_Production[Current RMS No],MATCH(E23&"",tbl_Production[Job Number],0))),""),IF(H23="Consulting",IFERROR(INDEX(tbl_Consulting[Qwilr Quote],MATCH(E23&"",tbl_Consulting[Job Number],0)),""),"")))) | AC23: =IF(AB23="","",IF(AND(LEFT(AB23,4)<>"http",IF(H23="Production",set_RMSBase,set_QwilrBase)=""),"",HYPERLINK(IF(LEFT(AB23,4)="http",AB23,IF(H23="Production",set_RMSBase,set_QwilrBase)&AB23),"Open"))) | AD23: =IF(E23="","",IF(H23="Production",IFERROR(INDEX(tbl_Production[Total Expense],MATCH(E23&"",tbl_Production[Job Number],0)),0),IF(H23="Consulting",IFERROR(INDEX(tbl_Consulting[Total Expense],MATCH(E23&"",tbl_Consulting[Job Number],0)),0),0))) | AE23: =IF(E23="","",Y23-N(AD23)) | AF23: =IFERROR(AE23/Y23,"") | AG23: =IF(E23="","",IF(H23="Onsite",IFERROR(INDEX(tbl_Onsite[Notes],MATCH(E23&"",tbl_Onsite[Job Number],0)),""),IF(H23="Production",IFERROR(INDEX(tbl_Production[Notes],MATCH(E23&"",tbl_Production[Job Number],0)),""),IF(H23="Consulting",IFERROR(INDEX(tbl_Consulting[Notes],MATCH(E23&"",tbl_Consulting[Job Number],0)),""),""))))
