Workbook
Name lst_CostCentre: Lists!$A$5:$A$10
Name lst_InvoiceType: Lists!$B$5:$B$14
Name lst_TaxCode: Lists!$C$5:$C$8
Name lst_Status: Lists!$D$5:$D$13
Name lst_YN: Lists!$E$5:$E$7
Name lst_Ariba: Lists!$F$5:$F$10
Name lst_WIPType: Lists!$G$5:$G$13
Name lst_WIPGL: Lists!$H$5:$H$7
Name lst_Team: Lists!$I$5:$I$8
Name lst_RevCost: Lists!$J$5:$J$6
Name lst_WonSource: Lists!$M$5:$M$8
Name lst_WonStatus: Lists!$O$5:$O$8
Name set_GSTRate: Lists!$U$8
Name set_QwilrBase: Lists!$U$5
Name set_RMSBase: Lists!$U$6
Name set_WIPAsset: Lists!$U$9
Name set_WIPIncome: Lists!$U$10
Name lst_RevGL: Lists!$K$5:$K$39
Name lst_Months: Lists!$N$5:$N$100
Name lst_Jobs: Lists!$P$5:$P$1500
Name lst_JobName: Lists!$Q$5:$Q$1500
Name lst_JobCC: Lists!$R$5:$R$1500

Sheet Read Me
B2: FY27 Revenue Tracker
B4: Corporate Technology Services Pty Ltd - replaces FY27_Revenue_Tracker_v2.xlsm
B6: WHO TYPES WHERE
C7: Finance types on the Finance sheet. Nowhere else. Every invoice line, every month.
C8: Each department types on its own sheet. Nowhere else. One row per job number.
C9: The two meet on Job Number, which is a real Xero tracking category and is checked against the live job list as you type. Nothing has to be kept lined up by hand.
B11: HOW IT FITS TOGETHER
B12: Finance | C12: The invoice register, and the only source of revenue. One row per invoice LINE, coded to one cost centre, exactly as Xero holds it. Filter the Issue column to see everything that needs fixing.
B13: Onsite / Production / Consulting | C13: One row per job. Client, invoice count and revenue come from Finance automatically; the department fills in its own costs, hours and references.
B14: WIP Movements | C14: Manual journals between the P&L and GL 11300 Work in Progress. Anything with a defer start and end on Finance does not belong here - it is handled automatically.
B15: Deferred Revenue | C15: The workings behind the automatic deferrals. Nothing is typed here; it mirrors the Finance lines that carry a defer start and end.
B16: Month-End | C16: The close: revenue by cost centre against Xero, the WIP reconciliation, fifteen data checks and a sign-off box.
B17: WIP Summary | C17: WIP opening / movement / closing for every job, to tie job by job back to the WIP Schedule file.
B18: Lists | C18: Every dropdown. Cost centres, job numbers and revenue GL codes came straight out of your Xero organisation, so they already match.
B20: DEFERRED REVENUE - it releases itself
C21: Put a Defer Start and a Defer End on a Finance line and the revenue spreads evenly across those months instead of landing all in the month you invoiced. Leave both blank for an ordinary one-off invoice.
C22: In the month invoiced: one month is recognised, the rest goes to WIP.
C23: Every month after: one more month is released, automatically.
C24: Worked example - $12,000 invoiced 15 Sep 2025 for Sep 2025 to Aug 2026. September recognises $1,000 and defers $11,000. Each month after releases $1,000. By August 2026 the balance is nil. Nothing is typed each month and no journal is needed.
C25: The Deferred Revenue sheet shows the workings line by line, and Month-End and WIP Summary already include it. One warning: a deferred line must not ALSO have a manual row on WIP Movements or it counts twice - Month-End checks for that.
C26: A cost can be deferred the same way, and it belongs on WIP Movements rather than Finance because it comes off a supplier bill, not an invoice. Type the bill amount as a positive, set Revenue or Cost to Cost, fill the two defer dates and put the expense account in P&L Account. It then spreads by month in the second block of the Deferred Revenue sheet exactly like revenue does.
C27: GL 11300 nets the two against each other, so Xero shows one figure and cannot tell you what it is made of. Month-End section 2 splits it: Total, Deferred / accrued revenue, Deferred / accrued cost. Compare only the Total column to Xero. Deferred cost never counts as revenue - section 1 leaves it out.
B29: VIDEO REVENUE
C30: There is no video split column any more, and nothing to keep honest. In Xero a cost centre sits on the invoice LINE, so a job invoiced part production and part video is simply two lines on the Finance sheet - one coded PRODUCTION, one coded VIDEO. The VIDEO figure at month-end is then a plain sum of the lines coded VIDEO, and it ties to the Xero VIDEO cost centre without any adjustment.
C31: The 26 migrated invoices that carried a video amount were split into two lines each on the way across. Ex GST in total is unchanged.
C32: The Production sheet carries a Video Revenue column beside the expenses, and Video % of Revenue next to it. Both read the Finance lines coded VIDEO, so nothing is typed. Job by job they reproduce the old Video Total column to the cent - 38,484.75 in total across 28 jobs.
B34: WHY THIS VERSION IS NOT SLOW, AND WHY IT OPENS
C35: The v2 file was slow because of its macro: every keystroke copied 26 columns by 200 rows into hidden storage, and it was capped at 200 rows per department. There are no macros here at all, and it is a .xlsx, so no macro warning and nothing blocked on SharePoint.
C36: There are also no dynamic array formulas - no VSTACK, FILTER, SORT, UNIQUE or XLOOKUP. Every sheet is a real Excel Table or a plain SUMIFS grid, which means the filter buttons, sorting and PivotTables all work normally, and every formula runs in any version of Excel.
B38: WORK WON - ZOHO, CURRENT RMS AND QWILR
C39: Paste the month's won opportunities onto the Work Won sheet, one row each, with the source, the value and the job number where you have it. Month-End section 5 totals them by source and puts them next to what was actually invoiced.
C40: It is a sense check and nothing else. No revenue ever comes off this sheet. What it catches is work won and never invoiced, and invoicing with no opportunity behind it. Put a job number on a row and it also tells you what has been raised against that job so far.
C41: Month-End section 6 turns the same sheet into the forecast. It adds two things that have no invoice against them: a Finance line carrying a value but no invoice number, and work marked Won less everything Finance already holds against that job. Subtracting all of it is what stops the same work being counted twice. Open opportunities and deferred revenue still to release sit underneath as memos, deliberately outside the total.
B43: MONTH-END, IN ORDER
C44: 1. Chase the departments until every invoice for the month is on the Finance sheet and Posted to Xero is Y.
C45: 2. Open Month-End and set the month.
C46: 3. Work section 3 first. Every count must be zero. Fix on the Finance sheet, or filter the Issue column there, which lists the same problems row by row.
C47: 4. Section 1: run the Xero P&L for the month by Cost Centre and type the revenue into the yellow column. Each line should read Reconciled.
C48: 5. Section 2: type the WIP Schedule closing balance and the Xero GL 11300 balance.
C49: 6. Breaks in section 2 - open WIP Summary, paste the WIP Schedule balances into column G and the variance column shows which job is out.
...

Sheet Read Me (Easy Read)
B2: FY27 Revenue Tracker
B3: Corporate Technology Services Pty Ltd - replaces FY27_Revenue_Tracker_v2.xlsm
B5: Who types where
C6: Finance types on the Finance sheet.
C7: Nowhere else.
C8: Every invoice line, every month.
C10: Each department types on its own sheet.
C11: Nowhere else.
C12: One row per job number.
C14: The two meet on Job Number, which is a real Xero tracking category and is checked against the live job list as you type.
C15: Nothing has to be kept lined up by hand.
B18: How it fits together
B19: Finance | C19: The invoice register, and the only source of revenue. One row per invoice line, coded to one cost centre, exactly as Xero holds it. Filter the Issue column to see everything that needs fixing.
B20: Onsite / Production / Consulting | C20: One row per job. Client, invoice count and revenue come from Finance automatically; the department fills in its own costs, hours and references.
B21: WIP Movements | C21: Manual journals between the P&L and GL 11300 Work in Progress. Anything with a defer start and end on Finance does not belong here - it is handled automatically.
B22: Deferred Revenue | C22: The workings behind the automatic deferrals. Nothing is typed here; it mirrors the Finance lines that carry a defer start and end.
B23: Month-End | C23: The close: revenue by cost centre against Xero, the WIP reconciliation, fifteen data checks and a sign-off box.
B24: WIP Summary | C24: WIP opening / movement / closing for every job, to tie job by job back to the WIP Schedule file.
B25: Lists | C25: Every dropdown. Cost centres, job numbers and revenue GL codes came straight out of your Xero organisation, so they already match.
B27: Deferred revenue - it releases itself
C28: Put a Defer Start and a Defer End on a Finance line and the revenue spreads evenly across those months instead of landing all in the month you invoiced.
C29: Leave both blank for an ordinary one-off invoice.
C31: In the month invoiced: one month is recognised, the rest goes to WIP.
C33: Every month after: one more month is released, automatically.
C35: Worked example - $12,000 invoiced 15 Sep 2025 for Sep 2025 to Aug 2026.
C36: September recognises $1,000 and defers $11,000.
C37: Each month after releases $1,000.
C38: By August 2026 the balance is nil.
C39: Nothing is typed each month and no journal is needed.
C41: The Deferred Revenue sheet shows the workings line by line, and Month-End and WIP Summary already include it.
C42: One warning: a deferred line must not also have a manual row on WIP Movements or it counts twice - Month-End checks for that.
C44: A cost can be deferred the same way, and it belongs on WIP Movements rather than Finance because it comes off a supplier bill, not an invoice.
... C51: Deferred cost never counts as revenue - section 1 leaves it out.
B54: Video revenue
C55: There is no video split column any more, and nothing to keep honest.
C56: In Xero a cost centre sits on the invoice line, so a job invoiced part production and part video is simply two lines on the Finance sheet - one coded PRODUCTION, one coded VIDEO.
C57: The VIDEO figure at month-end is then a plain sum of the lines coded VIDEO, and it ties to the Xero VIDEO cost centre without any adjustment.
C59: The 26 migrated invoices that carried a video amount were split into two lines each on the way across.
C60: Ex GST in total is unchanged.
C62: The Production sheet carries a Video Revenue column beside the expenses, and Video % of Revenue next to it.
...

Sheet Finance
A1: Finance - Invoice Register
A2: One row per invoice line, coded to one cost centre, the same way Xero holds it. Finance types here and nowhere else. A job invoiced part production and part video is two lines. Filter the Issue column to see what needs fixing.
A3: ="Ex GST "&TEXT(SUBTOTAL(109,tbl_Finance[Ex GST]),"$#,##0.00")&" "&"GST "&TEXT(SUBTOTAL(109,tbl_Finance[GST]),"$#,##0.00")&" "&"Inc GST "&TEXT(SUBTOTAL(109,tbl_Finance[Inc GST]),"$#,##0.00")
A4: Date | B4: Month | C4: Xero Invoice No | D4: Client | E4: Job Number | F4: Job in Xero? | G4: Description | H4: Team | I4: Cost Centre | J4: Invoice Type | K4: Tax Code | L4: Ex GST | M4: GST | N4: Inc GST | O4: Revenue GL | P4: Posted to Xero | Q4: To WIP | R4: Defer Start | S4: Defer End | T4: Status | U4: Notes | V4: Issue | W4: On Dept Sheet | X4: Job Name (Xero) | Y4: Lines on this Job | Z4: Job Total Ex GST | AA4: Job Invoiced | AB4: Job To Invoice | AC4: Job Quote / Ref | AD4: Open Quote | AE4: Job Expense | AF4: Job Margin | AG4: Job Margin % | AH4: Dept Notes
B5: =IF(A5="","",EOMONTH(A5,0)) | F5: =IF(E5="","",IF(COUNTIF(lst_Jobs,E5&"")>0,"OK","CHECK")) | M5: =IF(L5="","",IF(K5="GST 10%",ROUND(L5*set_GSTRate,2),0)) | N5: =IF(L5="","",L5+M5) | V5: =IF(COUNTA(A5,D5,C5,L5)=0,"",IF(A5="","No date - sits outside every month",IF(E5="","No job number",IF(F5="CHECK","Job number is not in the Xero job list",IF(I5="","No cost centre",IF(AND(P5="Y",C5=""),"Marked posted to Xero but has no invoice number",IF(AND(L5<>"",K5=""),"No tax code",IF(AND(L5<>"",O5=""),"No revenue GL code","")))))))) | W5: =IF(E5="","",IF(COUNTIF(tbl_Onsite[Job Number],E5&"")>0,"Onsite",IF(COUNTIF(tbl_Production[Job Number],E5&"")>0,"Production",IF(COUNTIF(tbl_Consulting[Job Number],E5&"")>0,"Consulting","not set up yet")))) | X5: =IF(E5="","",IFERROR(INDEX(lst_JobName,MATCH(E5&"",lst_Jobs,0)),"")) | Y5: =IF(E5="","",COUNTIFS(tbl_Finance[Job Number],E5&"",tbl_Finance[Ex GST],"<>")) | Z5: =IF(E5="","",SUMIFS(tbl_Finance[Ex GST],tbl_Finance[Job Number],E5&"")) | AA5: =IF(E5="","",SUMIFS(tbl_Finance[Ex GST],tbl_Finance[Job Number],E5&"",tbl_Finance[Xero Invoice No],"<>")) | AB5: =IF(E5="","",Z5-AA5) | AC5: =IF(E5="","",IFERROR(IF(INDEX(tbl_Onsite[Qwilr Quote],MATCH(E5&"",tbl_Onsite[Job Number],0))="","",INDEX(tbl_Onsite[Qwilr Quote],MATCH(E5&"",tbl_Onsite[Job Number],0))),IFERROR(IF(IF(INDEX(tbl_Production[Current RMS No],MATCH(E5&"",tbl_Production[Job Number],0))="",INDEX(tbl_Production[Qwilr Quote],MATCH(E5&"",tbl_Production[Job Number],0)),INDEX(tbl_Production[Current RMS No],MATCH(E5&"",tbl_Production[Job Number],0)))="","",IF(INDEX(tbl_Production[Current RMS No],MATCH(E5&"",tbl_Production[Job Number],0))="",INDEX(tbl_Production[Qwilr Quote],MATCH(E5&"",tbl_Production[Job Number],0)),INDEX(tbl_Production[Current RMS No],MATCH(E5&"",tbl_Production[Job Number],0)))),IFERROR(IF(INDEX(tbl_Consulting[Qwilr Quote],MATCH(E5&"",tbl_Consulting[Job Number],0))="","",INDEX(tbl_Consulting[Qwilr Quote],MATCH(E5&"",tbl_Consulting[Job Number],0))),"")))) | AD5: =IF(AC5="","",IF(AND(LEFT(AC5,4)<>"http",IF(H5="Production",set_RMSBase,set_QwilrBase)=""),"",HYPERLINK(IF(LEFT(AC5,4)="http",AC5,IF(H5="Production",set_RMSBase,set_QwilrBase)&AC5),"Open"))) | AE5: =IF(E5="","",IFERROR(INDEX(tbl_Production[Total Expense],MATCH(E5&"",tbl_Production[Job Number],0)),IFERROR(INDEX(tbl_Consulting[Total Expense],MATCH(E5&"",tbl_Consulting[Job Number],0)),0))) | AF5: =IF(E5="","",Z5-N(AE5)) | AG5: =IFERROR(AF5/Z5,"") | AH5: =IF(E5="","",IFERROR(IF(INDEX(tbl_Onsite[Notes],MATCH(E5&"",tbl_Onsite[Job Number],0))="","",INDEX(tbl_Onsite[Notes],MATCH(E5&"",tbl_Onsite[Job Number],0))),IFERROR(IF(INDEX(tbl_Production[Notes],MATCH(E5&"",tbl_Production[Job Number],0))="","",INDEX(tbl_Production[Notes],MATCH(E5&"",tbl_Production[Job Number],0))),IFERROR(IF(INDEX(tbl_Consulting[Notes],MATCH(E5&"",tbl_Consulting[Job Number],0))="","",INDEX(tbl_Consulting[Notes],MATCH(E5&"",tbl_Consulting[Job Number],0))),""))))
B6: =IF(A6="","",EOMONTH(A6,0)) | F6: =IF(E6="","",IF(COUNTIF(lst_Jobs,E6&"")>0,"OK","CHECK")) | M6: =IF(L6="","",IF(K6="GST 10%",ROUND(L6*set_GSTRate,2),0)) | N6: =IF(L6="","",L6+M6) | V6: =IF(COUNTA(A6,D6,C6,L6)=0,"",IF(A6="","No date - sits outside every month",IF(E6="","No job number",IF(F6="CHECK","Job number is not in the Xero job list",IF(I6="","No cost centre",IF(AND(P6="Y",C6=""),"Marked posted to Xero but has no invoice number",IF(AND(L6<>"",K6=""),"No tax code",IF(AND(L6<>"",O6=""),"No revenue GL code","")))))))) | W6: =IF(E6="","",IF(COUNTIF(tbl_Onsite[Job Number],E6&"")>0,"Onsite",IF(COUNTIF(tbl_Production[Job Number],E6&"")>0,"Production",IF(COUNTIF(tbl_Consulting[Job Number],E6&"")>0,"Consulting","not set up yet")))) | X6: =IF(E6="","",IFERROR(INDEX(lst_JobName,MATCH(E6&"",lst_Jobs,0)),"")) | Y6: =IF(E6="","",COUNTIFS(tbl_Finance[Job Number],E6&"",tbl_Finance[Ex GST],"<>")) | Z6: =IF(E6="","",SUMIFS(tbl_Finance[Ex GST],tbl_Finance[Job Number],E6&"")) | AA6: =IF(E6="","",SUMIFS(tbl_Finance[Ex GST],tbl_Finance[Job Number],E6&"",tbl_Finance[Xero Invoice No],"<>")) | AB6: =IF(E6="","",Z6-AA6) | AC6: =IF(E6="","",IFERROR(IF(INDEX(tbl_Onsite[Qwilr Quote],MATCH(E6&"",tbl_Onsite[Job Number],0))="","",INDEX(tbl_Onsite[Qwilr Quote],MATCH(E6&"",tbl_Onsite[Job Number],0))),IFERROR(IF(IF(INDEX(tbl_Production[Current RMS No],MATCH(E6&"",tbl_Production[Job Number],0))="",INDEX(tbl_Production[Qwilr Quote],MATCH(E6&"",tbl_Production[Job Number],0)),INDEX(tbl_Production[Current RMS No],MATCH(E6&"",tbl_Production[Job Number],0)))="","",IF(INDEX(tbl_Production[Current RMS No],MATCH(E6&"",tbl_Production[Job Number],0))="",INDEX(tbl_Production[Qwilr Quote],MATCH(E6&"",tbl_Production[Job Number],0)),INDEX(tbl_Production[Current RMS No],MATCH(E6&"",tbl_Production[Job Number],0)))),IFERROR(IF(INDEX(tbl_Consulting[Qwilr Quote],MATCH(E6&"",tbl_Consulting[Job Number],0))="","",INDEX(tbl_Consulting[Qwilr Quote],MATCH(E6&"",tbl_Consulting[Job Number],0))),"")))) | AD6: =IF(AC6="","",IF(AND(LEFT(AC6,4)<>"http",IF(H6="Production",set_RMSBase,set_QwilrBase)=""),"",HYPERLINK(IF(LEFT(AC6,4)="http",AC6,IF(H6="Production",set_RMSBase,set_QwilrBase)&AC6),"Open"))) | AE6: =IF(E6="","",IFERROR(INDEX(tbl_Production[Total Expense],MATCH(E6&"",tbl_Production[Job Number],0)),IFERROR(INDEX(tbl_Consulting[Total Expense],MATCH(E6&"",tbl_Consulting[Job Number],0)),0))) | AF6: =IF(E6="","",Z6-N(AE6)) | AG6: =IFERROR(AF6/Z6,"") | AH6: =IF(E6="","",IFERROR(IF(INDEX(tbl_Onsite[Notes],MATCH(E6&"",tbl_Onsite[Job Number],0))="","",INDEX(tbl_Onsite[Notes],MATCH(E6&"",tbl_Onsite[Job Number],0))),IFERROR(IF(INDEX(tbl_Production[Notes],MATCH(E6&"",tbl_Production[Job Number],0))="","",INDEX(tbl_Production[Notes],MATCH(E6&"",tbl_Production[Job Number],0))),IFERROR(IF(INDEX(tbl_Consulting[Notes],MATCH(E6&"",tbl_Consulting[Job Number],0))="","",INDEX(tbl_Consulting[Notes],MATCH(E6&"",tbl_Consulting[Job Number],0))),""))))
B7: =IF(A7="","",EOMONTH(A7,0)) | F7: =IF(E7="","",IF(COUNTIF(lst_Jobs,E7&"")>0,"OK","CHECK")) | M7: =IF(L7="","",IF(K7="GST 10%",ROUND(L7*set_GSTRate,2),0)) | N7: =IF(L7="","",L7+M7) | V7: =IF(COUNTA(A7,D7,C7,L7)=0,"",IF(A7="","No date - sits outside every month",IF(E7="","No job number",IF(F7="CHECK","Job number is not in the Xero job list",IF(I7="","No cost centre",IF(AND(P7="Y",C7=""),"Marked posted to Xero but has no invoice number",IF(AND(L7<>"",K7=""),"No tax code",IF(AND(L7<>"",O7=""),"No revenue GL code","")))))))) | W7: =IF(E7="","",IF(COUNTIF(tbl_Onsite[Job Number],E7&"")>0,"Onsite",IF(COUNTIF(tbl_Production[Job Number],E7&"")>0,"Production",IF(COUNTIF(tbl_Consulting[Job Number],E7&"")>0,"Consulting","not set up yet")))) | X7: =IF(E7="","",IFERROR(INDEX(lst_JobName,MATCH(E7&"",lst_Jobs,0)),"")) | Y7: =IF(E7="","",COUNTIFS(tbl_Finance[Job Number],E7&"",tbl_Finance[Ex GST],"<>")) | Z7: =IF(E7="","",SUMIFS(tbl_Finance[Ex GST],tbl_Finance[Job Number],E7&"")) | AA7: =IF(E7="","",SUMIFS(tbl_Finance[Ex GST],tbl_Finance[Job Number],E7&"",tbl_Finance[Xero Invoice No],"<>")) | AB7: =IF(E7="","",Z7-AA7) | AC7: =IF(E7="","",IFERROR(IF(INDEX(tbl_Onsite[Qwilr Quote],MATCH(E7&"",tbl_Onsite[Job Number],0))="","",INDEX(tbl_Onsite[Qwilr Quote],MATCH(E7&"",tbl_Onsite[Job Number],0))),IFERROR(IF(IF(INDEX(tbl_Production[Current RMS No],MATCH(E7&"",tbl_Production[Job Number],0))="",INDEX(tbl_Production[Qwilr Quote],MATCH(E7&"",tbl_Production[Job Number],0)),INDEX(tbl_Production[Current RMS No],MATCH(E7&"",tbl_Production[Job Number],0)))="","",IF(INDEX(tbl_Production[Current RMS No],MATCH(E7&"",tbl_Production[Job Number],0))="",INDEX(tbl_Production[Qwilr Quote],MATCH(E7&"",tbl_Production[Job Number],0)),INDEX(tbl_Production[Current RMS No],MATCH(E7&"",tbl_Production[Job Number],0)))),IFERROR(IF(INDEX(tbl_Consulting[Qwilr Quote],MATCH(E7&"",tbl_Consulting[Job Number],0))="","",INDEX(tbl_Consulting[Qwilr Quote],MATCH(E7&"",tbl_Consulting[Job Number],0))),"")))) | AD7: =IF(AC7="","",IF(AND(LEFT(AC7,4)<>"http",IF(H7="Production",set_RMSBase,set_QwilrBase)=""),"",HYPERLINK(IF(LEFT(AC7,4)="http",AC7,IF(H7="Production",set_RMSBase,set_QwilrBase)&AC7),"Open"))) | AE7: =IF(E7="","",IFERROR(INDEX(tbl_Production[Total Expense],MATCH(E7&"",tbl_Production[Job Number],0)),IFERROR(INDEX(tbl_Consulting[Total Expense],MATCH(E7&"",tbl_Consulting[Job Number],0)),0))) | AF7: =IF(E7="","",Z7-N(AE7)) | AG7: =IFERROR(AF7/Z7,"") | AH7: =IF(E7="","",IFERROR(IF(INDEX(tbl_Onsite[Notes],MATCH(E7&"",tbl_Onsite[Job Number],0))="","",INDEX(tbl_Onsite[Notes],MATCH(E7&"",tbl_Onsite[Job Number],0))),IFERROR(IF(INDEX(tbl_Production[Notes],MATCH(E7&"",tbl_Production[Job Number],0))="","",INDEX(tbl_Production[Notes],MATCH(E7&"",tbl_Production[Job Number],0))),IFERROR(IF(INDEX(tbl_Consulting[Notes],MATCH(E7&"",tbl_Consulting[Job Number],0))="","",INDEX(tbl_Consulting[Notes],MATCH(E7&"",tbl_Consulting[Job Number],0))),""))))
B8: =IF(A8="","",EOMONTH(A8,0)) | F8: =IF(E8="","",IF(COUNTIF(lst_Jobs,E8&"")>0,"OK","CHECK")) | M8: =IF(L8="","",IF(K8="GST 10%",ROUND(L8*set_GSTRate,2),0)) | N8: =IF(L8="","",L8+M8) | V8: =IF(COUNTA(A8,D8,C8,L8)=0,"",IF(A8="","No date - sits outside every month",IF(E8="","No job number",IF(F8="CHECK","Job number is not in the Xero job list",IF(I8="","No cost centre",IF(AND(P8="Y",C8=""),"Marked posted to Xero but has no invoice number",IF(AND(L8<>"",K8=""),"No tax code",IF(AND(L8<>"",O8=""),"No revenue GL code","")))))))) | W8: =IF(E8="","",IF(COUNTIF(tbl_Onsite[Job Number],E8&"")>0,"Onsite",IF(COUNTIF(tbl_Production[Job Number],E8&"")>0,"Production",IF(COUNTIF(tbl_Consulting[Job Number],E8&"")>0,"Consulting","not set up yet")))) | X8: =IF(E8="","",IFERROR(INDEX(lst_JobName,MATCH(E8&"",lst_Jobs,0)),"")) | Y8: =IF(E8="","",COUNTIFS(tbl_Finance[Job Number],E8&"",tbl_Finance[Ex GST],"<>")) | Z8: =IF(E8="","",SUMIFS(tbl_Finance[Ex GST],tbl_Finance[Job Number],E8&"")) | AA8: =IF(E8="","",SUMIFS(tbl_Finance[Ex GST],tbl_Finance[Job Number],E8&"",tbl_Finance[Xero Invoice No],"<>")) | AB8: =IF(E8="","",Z8-AA8) | AC8: =IF(E8="","",IFERROR(IF(INDEX(tbl_Onsite[Qwilr Quote],MATCH(E8&"",tbl_Onsite[Job Number],0))="","",INDEX(tbl_Onsite[Qwilr Quote],MATCH(E8&"",tbl_Onsite[Job Number],0))),IFERROR(IF(IF(INDEX(tbl_Production[Current RMS No],MATCH(E8&"",tbl_Production[Job Number],0))="",INDEX(tbl_Production[Qwilr Quote],MATCH(E8&"",tbl_Production[Job Number],0)),INDEX(tbl_Production[Current RMS No],MATCH(E8&"",tbl_Production[Job Number],0)))="","",IF(INDEX(tbl_Production[Current RMS No],MATCH(E8&"",tbl_Production[Job Number],0))="",INDEX(tbl_Production[Qwilr Quote],MATCH(E8&"",tbl_Production[Job Number],0)),INDEX(tbl_Production[Current RMS No],MATCH(E8&"",tbl_Production[Job Number],0)))),IFERROR(IF(INDEX(tbl_Consulting[Qwilr Quote],MATCH(E8&"",tbl_Consulting[Job Number],0))="","",INDEX(tbl_Consulting[Qwilr Quote],MATCH(E8&"",tbl_Consulting[Job Number],0))),"")))) | AD8: =IF(AC8="","",IF(AND(LEFT(AC8,4)<>"http",IF(H8="Production",set_RMSBase,set_QwilrBase)=""),"",HYPERLINK(IF(LEFT(AC8,4)="http",AC8,IF(H8="Production",set_RMSBase,set_QwilrBase)&AC8),"Open"))) | AE8: =IF(E8="","",IFERROR(INDEX(tbl_Production[Total Expense],MATCH(E8&"",tbl_Production[Job Number],0)),IFERROR(INDEX(tbl_Consulting[Total Expense],MATCH(E8&"",tbl_Consulting[Job Number],0)),0))) | AF8: =IF(E8="","",Z8-N(AE8)) | AG8: =IFERROR(AF8/Z8,"") | AH8: =IF(E8="","",IFERROR(IF(INDEX(tbl_Onsite[Notes],MATCH(E8&"",tbl_Onsite[Job Number],0))="","",INDEX(tbl_Onsite[Notes],MATCH(E8&"",tbl_Onsite[Job Number],0))),IFERROR(IF(INDEX(tbl_Production[Notes],MATCH(E8&"",tbl_Production[Job Number],0))="","",INDEX(tbl_Production[Notes],MATCH(E8&"",tbl_Production[Job Number],0))),IFERROR(IF(INDEX(tbl_Consulting[Notes],MATCH(E8&"",tbl_Consulting[Job Number],0))="","",INDEX(tbl_Consulting[Notes],MATCH(E8&"",tbl_Consulting[Job Number],0))),""))))
B9: =IF(A9="","",EOMONTH(A9,0)) | F9: =IF(E9="","",IF(COUNTIF(lst_Jobs,E9&"")>0,"OK","CHECK")) | M9: =IF(L9="","",IF(K9="GST 10%",ROUND(L9*set_GSTRate,2),0)) | N9: =IF(L9="","",L9+M9) | V9: =IF(COUNTA(A9,D9,C9,L9)=0,"",IF(A9="","No date - sits outside every month",IF(E9="","No job number",IF(F9="CHECK","Job number is not in the Xero job list",IF(I9="","No cost centre",IF(AND(P9="Y",C9=""),"Marked posted to Xero but has no invoice number",IF(AND(L9<>"",K9=""),"No tax code",IF(AND(L9<>"",O9=""),"No revenue GL code","")))))))) | W9: =IF(E9="","",IF(COUNTIF(tbl_Onsite[Job Number],E9&"")>0,"Onsite",IF(COUNTIF(tbl_Production[Job Number],E9&"")>0,"Production",IF(COUNTIF(tbl_Consulting[Job Number],E9&"")>0,"Consulting","not set up yet")))) | X9: =IF(E9="","",IFERROR(INDEX(lst_JobName,MATCH(E9&"",lst_Jobs,0)),"")) | Y9: =IF(E9="","",COUNTIFS(tbl_Finance[Job Number],E9&"",tbl_Finance[Ex GST],"<>")) | Z9: =IF(E9="","",SUMIFS(tbl_Finance[Ex GST],tbl_Finance[Job Number],E9&"")) | AA9: =IF(E9="","",SUMIFS(tbl_Finance[Ex GST],tbl_Finance[Job Number],E9&"",tbl_Finance[Xero Invoice No],"<>")) | AB9: =IF(E9="","",Z9-AA9) | AC9: =IF(E9="","",IFERROR(IF(INDEX(tbl_Onsite[Qwilr Quote],MATCH(E9&"",tbl_Onsite[Job Number],0))="","",INDEX(tbl_Onsite[Qwilr Quote],MATCH(E9&"",tbl_Onsite[Job Number],0))),IFERROR(IF(IF(INDEX(tbl_Production[Current RMS No],MATCH(E9&"",tbl_Production[Job Number],0))="",INDEX(tbl_Production[Qwilr Quote],MATCH(E9&"",tbl_Production[Job Number],0)),INDEX(tbl_Production[Current RMS No],MATCH(E9&"",tbl_Production[Job Number],0)))="","",IF(INDEX(tbl_Production[Current RMS No],MATCH(E9&"",tbl_Production[Job Number],0))="",INDEX(tbl_Production[Qwilr Quote],MATCH(E9&"",tbl_Production[Job Number],0)),INDEX(tbl_Production[Current RMS No],MATCH(E9&"",tbl_Production[Job Number],0)))),IFERROR(IF(INDEX(tbl_Consulting[Qwilr Quote],MATCH(E9&"",tbl_Consulting[Job Number],0))="","",INDEX(tbl_Consulting[Qwilr Quote],MATCH(E9&"",tbl_Consulting[Job Number],0))),"")))) | AD9: =IF(AC9="","",IF(AND(LEFT(AC9,4)<>"http",IF(H9="Production",set_RMSBase,set_QwilrBase)=""),"",HYPERLINK(IF(LEFT(AC9,4)="http",AC9,IF(H9="Production",set_RMSBase,set_QwilrBase)&AC9),"Open"))) | AE9: =IF(E9="","",IFERROR(INDEX(tbl_Production[Total Expense],MATCH(E9&"",tbl_Production[Job Number],0)),IFERROR(INDEX(tbl_Consulting[Total Expense],MATCH(E9&"",tbl_Consulting[Job Number],0)),0))) | AF9: =IF(E9="","",Z9-N(AE9)) | AG9: =IFERROR(AF9/Z9,"") | AH9: =IF(E9="","",IFERROR(IF(INDEX(tbl_Onsite[Notes],MATCH(E9&"",tbl_Onsite[Job Number],0))="","",INDEX(tbl_Onsite[Notes],MATCH(E9&"",tbl_Onsite[Job Number],0))),IFERROR(IF(INDEX(tbl_Production[Notes],MATCH(E9&"",tbl_Production[Job Number],0))="","",INDEX(tbl_Production[Notes],MATCH(E9&"",tbl_Production[Job Number],0))),IFERROR(IF(INDEX(tbl_Consulting[Notes],MATCH(E9&"",tbl_Consulting[Job Number],0))="","",INDEX(tbl_Consulting[Notes],MATCH(E9&"",tbl_Consulting[Job Number],0))),""))))
B10: =IF(A10="","",EOMONTH(A10,0)) | F10: =IF(E10="","",IF(COUNTIF(lst_Jobs,E10&"")>0,"OK","CHECK")) | M10: =IF(L10="","",IF(K10="GST 10%",ROUND(L10*set_GSTRate,2),0)) | N10: =IF(L10="","",L10+M10) | V10: =IF(COUNTA(A10,D10,C10,L10)=0,"",IF(A10="","No date - sits outside every month",IF(E10="","No job number",IF(F10="CHECK","Job number is not in the Xero job list",IF(I10="","No cost centre",IF(AND(P10="Y",C10=""),"Marked posted to Xero but has no invoice number",IF(AND(L10<>"",K10=""),"No tax code",IF(AND(L10<>"",O10=""),"No revenue GL code","")))))))) | W10: =IF(E10="","",IF(COUNTIF(tbl_Onsite[Job Number],E10&"")>0,"Onsite",IF(COUNTIF(tbl_Production[Job Number],E10&"")>0,"Production",IF(COUNTIF(tbl_Consulting[Job Number],E10&"")>0,"Consulting","not set up yet")))) | X10: =IF(E10="","",IFERROR(INDEX(lst_JobName,MATCH(E10&"",lst_Jobs,0)),"")) | Y10: =IF(E10="","",COUNTIFS(tbl_Finance[Job Number],E10&"",tbl_Finance[Ex GST],"<>")) | Z10: =IF(E10="","",SUMIFS(tbl_Finance[Ex GST],tbl_Finance[Job Number],E10&"")) | AA10: =IF(E10="","",SUMIFS(tbl_Finance[Ex GST],tbl_Finance[Job Number],E10&"",tbl_Finance[Xero Invoice No],"<>")) | AB10: =IF(E10="","",Z10-AA10) | AC10: =IF(E10="","",IFERROR(IF(INDEX(tbl_Onsite[Qwilr Quote],MATCH(E10&"",tbl_Onsite[Job Number],0))="","",INDEX(tbl_Onsite[Qwilr Quote],MATCH(E10&"",tbl_Onsite[Job Number],0))),IFERROR(IF(IF(INDEX(tbl_Production[Current RMS No],MATCH(E10&"",tbl_Production[Job Number],0))="",INDEX(tbl_Production[Qwilr Quote],MATCH(E10&"",tbl_Production[Job Number],0)),INDEX(tbl_Production[Current RMS No],MATCH(E10&"",tbl_Production[Job Number],0)))="","",IF(INDEX(tbl_Production[Current RMS No],MATCH(E10&"",tbl_Production[Job Number],0))="",INDEX(tbl_Production[Qwilr Quote],MATCH(E10&"",tbl_Production[Job Number],0)),INDEX(tbl_Production[Current RMS No],MATCH(E10&"",tbl_Production[Job Number],0)))),IFERROR(IF(INDEX(tbl_Consulting[Qwilr Quote],MATCH(E10&"",tbl_Consulting[Job Number],0))="","",INDEX(tbl_Consulting[Qwilr Quote],MATCH(E10&"",tbl_Consulting[Job Number],0))),"")))) | AD10: =IF(AC10="","",IF(AND(LEFT(AC10,4)<>"http",IF(H10="Production",set_RMSBase,set_QwilrBase)=""),"",HYPERLINK(IF(LEFT(AC10,4)="http",AC10,IF(H10="Production",set_RMSBase,set_QwilrBase)&AC10),"Open"))) | AE10: =IF(E10="","",IFERROR(INDEX(tbl_Production[Total Expense],MATCH(E10&"",tbl_Production[Job Number],0)),IFERROR(INDEX(tbl_Consulting[Total Expense],MATCH(E10&"",tbl_Consulting[Job Number],0)),0))) | AF10: =IF(E10="","",Z10-N(AE10)) | AG10: =IFERROR(AF10/Z10,"") | AH10: =IF(E10="","",IFERROR(IF(INDEX(tbl_Onsite[Notes],MATCH(E10&"",tbl_Onsite[Job Number],0))="","",INDEX(tbl_Onsite[Notes],MATCH(E10&"",tbl_Onsite[Job Number],0))),IFERROR(IF(INDEX(tbl_Production[Notes],MATCH(E10&"",tbl_Production[Job Number],0))="","",INDEX(tbl_Production[Notes],MATCH(E10&"",tbl_Production[Job Number],0))),IFERROR(IF(INDEX(tbl_Consulting[Notes],MATCH(E10&"",tbl_Consulting[Job Number],0))="","",INDEX(tbl_Consulting[Notes],MATCH(E10&"",tbl_Consulting[Job Number],0))),""))))
B11: =IF(A11="","",EOMONTH(A11,0)) | F11: =IF(E11="","",IF(COUNTIF(lst_Jobs,E11&"")>0,"OK","CHECK")) | M11: =IF(L11="","",IF(K11="GST 10%",ROUND(L11*set_GSTRate,2),0)) | N11: =IF(L11="","",L11+M11) | V11: =IF(COUNTA(A11,D11,C11,L11)=0,"",IF(A11="","No date - sits outside every month",IF(E11="","No job number",IF(F11="CHECK","Job number is not in the Xero job list",IF(I11="","No cost centre",IF(AND(P11="Y",C11=""),"Marked posted to Xero but has no invoice number",IF(AND(L11<>"",K11=""),"No tax code",IF(AND(L11<>"",O11=""),"No revenue GL code","")))))))) | W11: =IF(E11="","",IF(COUNTIF(tbl_Onsite[Job Number],E11&"")>0,"Onsite",IF(COUNTIF(tbl_Production[Job Number],E11&"")>0,"Production",IF(COUNTIF(tbl_Consulting[Job Number],E11&"")>0,"Consulting","not set up yet")))) | X11: =IF(E11="","",IFERROR(INDEX(lst_JobName,MATCH(E11&"",lst_Jobs,0)),"")) | Y11: =IF(E11="","",COUNTIFS(tbl_Finance[Job Number],E11&"",tbl_Finance[Ex GST],"<>")) | Z11: =IF(E11="","",SUMIFS(tbl_Finance[Ex GST],tbl_Finance[Job Number],E11&"")) | AA11: =IF(E11="","",SUMIFS(tbl_Finance[Ex GST],tbl_Finance[Job Number],E11&"",tbl_Finance[Xero Invoice No],"<>")) | AB11: =IF(E11="","",Z11-AA11) | AC11: =IF(E11="","",IFERROR(IF(INDEX(tbl_Onsite[Qwilr Quote],MATCH(E11&"",tbl_Onsite[Job Number],0))="","",INDEX(tbl_Onsite[Qwilr Quote],MATCH(E11&"",tbl_Onsite[Job Number],0))),IFERROR(IF(IF(INDEX(tbl_Production[Current RMS No],MATCH(E11&"",tbl_Production[Job Number],0))="",INDEX(tbl_Production[Qwilr Quote],MATCH(E11&"",tbl_Production[Job Number],0)),INDEX(tbl_Production[Current RMS No],MATCH(E11&"",tbl_Production[Job Number],0)))="","",IF(INDEX(tbl_Production[Current RMS No],MATCH(E11&"",tbl_Production[Job Number],0))="",INDEX(tbl_Production[Qwilr Quote],MATCH(E11&"",tbl_Production[Job Number],0)),INDEX(tbl_Production[Current RMS No],MATCH(E11&"",tbl_Production[Job Number],0)))),IFERROR(IF(INDEX(tbl_Consulting[Qwilr Quote],MATCH(E11&"",tbl_Consulting[Job Number],0))="","",INDEX(tbl_Consulting[Qwilr Quote],MATCH(E11&"",tbl_Consulting[Job Number],0))),"")))) | AD11: =IF(AC11="","",IF(AND(LEFT(AC11,4)<>"http",IF(H11="Production",set_RMSBase,set_QwilrBase)=""),"",HYPERLINK(IF(LEFT(AC11,4)="http",AC11,IF(H11="Production",set_RMSBase,set_QwilrBase)&AC11),"Open"))) | AE11: =IF(E11="","",IFERROR(INDEX(tbl_Production[Total Expense],MATCH(E11&"",tbl_Production[Job Number],0)),IFERROR(INDEX(tbl_Consulting[Total Expense],MATCH(E11&"",tbl_Consulting[Job Number],0)),0))) | AF11: =IF(E11="","",Z11-N(AE11)) | AG11: =IFERROR(AF11/Z11,"") | AH11: =IF(E11="","",IFERROR(IF(INDEX(tbl_Onsite[Notes],MATCH(E11&"",tbl_Onsite[Job Number],0))="","",INDEX(tbl_Onsite[Notes],MATCH(E11&"",tbl_Onsite[Job Number],0))),IFERROR(IF(INDEX(tbl_Production[Notes],MATCH(E11&"",tbl_Production[Job Number],0))="","",INDEX(tbl_Production[Notes],MATCH(E11&"",tbl_Production[Job Number],0))),IFERROR(IF(INDEX(tbl_Consulting[Notes],MATCH(E11&"",tbl_Consulting[Job Number],0))="","",INDEX(tbl_Consulting[Notes],MATCH(E11&"",tbl_Consulting[Job Number],0))),""))))
B12: =IF(A12="","",EOMONTH(A12,0)) | F12: =IF(E12="","",IF(COUNTIF(lst_Jobs,E12&"")>0,"OK","CHECK")) | M12: =IF(L12="","",IF(K12="GST 10%",ROUND(L12*set_GSTRate,2),0)) | N12: =IF(L12="","",L12+M12) | V12: =IF(COUNTA(A12,D12,C12,L12)=0,"",IF(A12="","No date - sits outside every month",IF(E12="","No job number",IF(F12="CHECK","Job number is not in the Xero job list",IF(I12="","No cost centre",IF(AND(P12="Y",C12=""),"Marked posted to Xero but has no invoice number",IF(AND(L12<>"",K12=""),"No tax code",IF(AND(L12<>"",O12=""),"No revenue GL code","")))))))) | W12: =IF(E12="","",IF(COUNTIF(tbl_Onsite[Job Number],E12&"")>0,"Onsite",IF(COUNTIF(tbl_Production[Job Number],E12&"")>0,"Production",IF(COUNTIF(tbl_Consulting[Job Number],E12&"")>0,"Consulting","not set up yet")))) | X12: =IF(E12="","",IFERROR(INDEX(lst_JobName,MATCH(E12&"",lst_Jobs,0)),"")) | Y12: =IF(E12="","",COUNTIFS(tbl_Finance[Job Number],E12&"",tbl_Finance[Ex GST],"<>")) | Z12: =IF(E12="","",SUMIFS(tbl_Finance[Ex GST],tbl_Finance[Job Number],E12&"")) | AA12: =IF(E12="","",SUMIFS(tbl_Finance[Ex GST],tbl_Finance[Job Number],E12&"",tbl_Finance[Xero Invoice No],"<>")) | AB12: =IF(E12="","",Z12-AA12) | AC12: =IF(E12="","",IFERROR(IF(INDEX(tbl_Onsite[Qwilr Quote],MATCH(E12&"",tbl_Onsite[Job Number],0))="","",INDEX(tbl_Onsite[Qwilr Quote],MATCH(E12&"",tbl_Onsite[Job Number],0))),IFERROR(IF(IF(INDEX(tbl_Production[Current RMS No],MATCH(E12&"",tbl_Production[Job Number],0))="",INDEX(tbl_Production[Qwilr Quote],MATCH(E12&"",tbl_Production[Job Number],0)),INDEX(tbl_Production[Current RMS No],MATCH(E12&"",tbl_Production[Job Number],0)))="","",IF(INDEX(tbl_Production[Current RMS No],MATCH(E12&"",tbl_Production[Job Number],0))="",INDEX(tbl_Production[Qwilr Quote],MATCH(E12&"",tbl_Production[Job Number],0)),INDEX(tbl_Production[Current RMS No],MATCH(E12&"",tbl_Production[Job Number],0)))),IFERROR(IF(INDEX(tbl_Consulting[Qwilr Quote],MATCH(E12&"",tbl_Consulting[Job Number],0))="","",INDEX(tbl_Consulting[Qwilr Quote],MATCH(E12&"",tbl_Consulting[Job Number],0))),"")))) | AD12: =IF(AC12="","",IF(AND(LEFT(AC12,4)<>"http",IF(H12="Production",set_RMSBase,set_QwilrBase)=""),"",HYPERLINK(IF(LEFT(AC12,4)="http",AC12,IF(H12="Production",set_RMSBase,set_QwilrBase)&AC12),"Open"))) | AE12: =IF(E12="","",IFERROR(INDEX(tbl_Production[Total Expense],MATCH(E12&"",tbl_Production[Job Number],0)),IFERROR(INDEX(tbl_Consulting[Total Expense],MATCH(E12&"",tbl_Consulting[Job Number],0)),0))) | AF12: =IF(E12="","",Z12-N(AE12)) | AG12: =IFERROR(AF12/Z12,"") | AH12: =IF(E12="","",IFERROR(IF(INDEX(tbl_Onsite[Notes],MATCH(E12&"",tbl_Onsite[Job Number],0))="","",INDEX(tbl_Onsite[Notes],MATCH(E12&"",tbl_Onsite[Job Number],0))),IFERROR(IF(INDEX(tbl_Production[Notes],MATCH(E12&"",tbl_Production[Job Number],0))="","",INDEX(tbl_Production[Notes],MATCH(E12&"",tbl_Production[Job Number],0))),IFERROR(IF(INDEX(tbl_Consulting[Notes],MATCH(E12&"",tbl_Consulting[Job Number],0))="","",INDEX(tbl_Consulting[Notes],MATCH(E12&"",tbl_Consulting[Job Number],0))),""))))
B13: =IF(A13="","",EOMONTH(A13,0)) | F13: =IF(E13="","",IF(COUNTIF(lst_Jobs,E13&"")>0,"OK","CHECK")) | M13: =IF(L13="","",IF(K13="GST 10%",ROUND(L13*set_GSTRate,2),0)) | N13: =IF(L13="","",L13+M13) | V13: =IF(COUNTA(A13,D13,C13,L13)=0,"",IF(A13="","No date - sits outside every month",IF(E13="","No job number",IF(F13="CHECK","Job number is not in the Xero job list",IF(I13="","No cost centre",IF(AND(P13="Y",C13=""),"Marked posted to Xero but has no invoice number",IF(AND(L13<>"",K13=""),"No tax code",IF(AND(L13<>"",O13=""),"No revenue GL code","")))))))) | W13: =IF(E13="","",IF(COUNTIF(tbl_Onsite[Job Number],E13&"")>0,"Onsite",IF(COUNTIF(tbl_Production[Job Number],E13&"")>0,"Production",IF(COUNTIF(tbl_Consulting[Job Number],E13&"")>0,"Consulting","not set up yet")))) | X13: =IF(E13="","",IFERROR(INDEX(lst_JobName,MATCH(E13&"",lst_Jobs,0)),"")) | Y13: =IF(E13="","",COUNTIFS(tbl_Finance[Job Number],E13&"",tbl_Finance[Ex GST],"<>")) | Z13: =IF(E13="","",SUMIFS(tbl_Finance[Ex GST],tbl_Finance[Job Number],E13&"")) | AA13: =IF(E13="","",SUMIFS(tbl_Finance[Ex GST],tbl_Finance[Job Number],E13&"",tbl_Finance[Xero Invoice No],"<>")) | AB13: =IF(E13="","",Z13-AA13) | AC13: =IF(E13="","",IFERROR(IF(INDEX(tbl_Onsite[Qwilr Quote],MATCH(E13&"",tbl_Onsite[Job Number],0))="","",INDEX(tbl_Onsite[Qwilr Quote],MATCH(E13&"",tbl_Onsite[Job Number],0))),IFERROR(IF(IF(INDEX(tbl_Production[Current RMS No],MATCH(E13&"",tbl_Production[Job Number],0))="",INDEX(tbl_Production[Qwilr Quote],MATCH(E13&"",tbl_Production[Job Number],0)),INDEX(tbl_Production[Current RMS No],MATCH(E13&"",tbl_Production[Job Number],0)))="","",IF(INDEX(tbl_Production[Current RMS No],MATCH(E13&"",tbl_Production[Job Number],0))="",INDEX(tbl_Production[Qwilr Quote],MATCH(E13&"",tbl_Production[Job Number],0)),INDEX(tbl_Production[Current RMS No],MATCH(E13&"",tbl_Production[Job Number],0)))),IFERROR(IF(INDEX(tbl_Consulting[Qwilr Quote],MATCH(E13&"",tbl_Consulting[Job Number],0))="","",INDEX(tbl_Consulting[Qwilr Quote],MATCH(E13&"",tbl_Consulting[Job Number],0))),"")))) | AD13: =IF(AC13="","",IF(AND(LEFT(AC13,4)<>"http",IF(H13="Production",set_RMSBase,set_QwilrBase)=""),"",HYPERLINK(IF(LEFT(AC13,4)="http",AC13,IF(H13="Production",set_RMSBase,set_QwilrBase)&AC13),"Open"))) | AE13: =IF(E13="","",IFERROR(INDEX(tbl_Production[Total Expense],MATCH(E13&"",tbl_Production[Job Number],0)),IFERROR(INDEX(tbl_Consulting[Total Expense],MATCH(E13&"",tbl_Consulting[Job Number],0)),0))) | AF13: =IF(E13="","",Z13-N(AE13)) | AG13: =IFERROR(AF13/Z13,"") | AH13: =IF(E13="","",IFERROR(IF(INDEX(tbl_Onsite[Notes],MATCH(E13&"",tbl_Onsite[Job Number],0))="","",INDEX(tbl_Onsite[Notes],MATCH(E13&"",tbl_Onsite[Job Number],0))),IFERROR(IF(INDEX(tbl_Production[Notes],MATCH(E13&"",tbl_Production[Job Number],0))="","",INDEX(tbl_Production[Notes],MATCH(E13&"",tbl_Production[Job Number],0))),IFERROR(IF(INDEX(tbl_Consulting[Notes],MATCH(E13&"",tbl_Consulting[Job Number],0))="","",INDEX(tbl_Consulting[Notes],MATCH(E13&"",tbl_Consulting[Job Number],0))),""))))
B14: =IF(A14="","",EOMONTH(A14,0)) | F14: =IF(E14="","",IF(COUNTIF(lst_Jobs,E14&"")>0,"OK","CHECK")) | M14: =IF(L14="","",IF(K14="GST 10%",ROUND(L14*set_GSTRate,2),0)) | N14: =IF(L14="","",L14+M14) | V14: =IF(COUNTA(A14,D14,C14,L14)=0,"",IF(A14="","No date - sits outside every month",IF(E14="","No job number",IF(F14="CHECK","Job number is not in the Xero job list",IF(I14="","No cost centre",IF(AND(P14="Y",C14=""),"Marked posted to Xero but has no invoice number",IF(AND(L14<>"",K14=""),"No tax code",IF(AND(L14<>"",O14=""),"No revenue GL code","")))))))) | W14: =IF(E14="","",IF(COUNTIF(tbl_Onsite[Job Number],E14&"")>0,"Onsite",IF(COUNTIF(tbl_Production[Job Number],E14&"")>0,"Production",IF(COUNTIF(tbl_Consulting[Job Number],E14&"")>0,"Consulting","not set up yet")))) | X14: =IF(E14="","",IFERROR(INDEX(lst_JobName,MATCH(E14&"",lst_Jobs,0)),"")) | Y14: =IF(E14="","",COUNTIFS(tbl_Finance[Job Number],E14&"",tbl_Finance[Ex GST],"<>")) | Z14: =IF(E14="","",SUMIFS(tbl_Finance[Ex GST],tbl_Finance[Job Number],E14&"")) | AA14: =IF(E14="","",SUMIFS(tbl_Finance[Ex GST],tbl_Finance[Job Number],E14&"",tbl_Finance[Xero Invoice No],"<>")) | AB14: =IF(E14="","",Z14-AA14) | AC14: =IF(E14="","",IFERROR(IF(INDEX(tbl_Onsite[Qwilr Quote],MATCH(E14&"",tbl_Onsite[Job Number],0))="","",INDEX(tbl_Onsite[Qwilr Quote],MATCH(E14&"",tbl_Onsite[Job Number],0))),IFERROR(IF(IF(INDEX(tbl_Production[Current RMS No],MATCH(E14&"",tbl_Production[Job Number],0))="",INDEX(tbl_Production[Qwilr Quote],MATCH(E14&"",tbl_Production[Job Number],0)),INDEX(tbl_Production[Current RMS No],MATCH(E14&"",tbl_Production[Job Number],0)))="","",IF(INDEX(tbl_Production[Current RMS No],MATCH(E14&"",tbl_Production[Job Number],0))="",INDEX(tbl_Production[Qwilr Quote],MATCH(E14&"",tbl_Production[Job Number],0)),INDEX(tbl_Production[Current RMS No],MATCH(E14&"",tbl_Production[Job Number],0)))),IFERROR(IF(INDEX(tbl_Consulting[Qwilr Quote],MATCH(E14&"",tbl_Consulting[Job Number],0))="","",INDEX(tbl_Consulting[Qwilr Quote],MATCH(E14&"",tbl_Consulting[Job Number],0))),"")))) | AD14: =IF(AC14="","",IF(AND(LEFT(AC14,4)<>"http",IF(H14="Production",set_RMSBase,set_QwilrBase)=""),"",HYPERLINK(IF(LEFT(AC14,4)="http",AC14,IF(H14="Production",set_RMSBase,set_QwilrBase)&AC14),"Open"))) | AE14: =IF(E14="","",IFERROR(INDEX(tbl_Production[Total Expense],MATCH(E14&"",tbl_Production[Job Number],0)),IFERROR(INDEX(tbl_Consulting[Total Expense],MATCH(E14&"",tbl_Consulting[Job Number],0)),0))) | AF14: =IF(E14="","",Z14-N(AE14)) | AG14: =IFERROR(AF14/Z14,"") | AH14: =IF(E14="","",IFERROR(IF(INDEX(tbl_Onsite[Notes],MATCH(E14&"",tbl_Onsite[Job Number],0))="","",INDEX(tbl_Onsite[Notes],MATCH(E14&"",tbl_Onsite[Job Number],0))),IFERROR(IF(INDEX(tbl_Production[Notes],MATCH(E14&"",tbl_Production[Job Number],0))="","",INDEX(tbl_Production[Notes],MATCH(E14&"",tbl_Production[Job Number],0))),IFERROR(IF(INDEX(tbl_Consulting[Notes],MATCH(E14&"",tbl_Consulting[Job Number],0))="","",INDEX(tbl_Consulting[Notes],MATCH(E14&"",tbl_Consulting[Job Number],0))),""))))
B15: =IF(A15="","",EOMONTH(A15,0)) | F15: =IF(E15="","",IF(COUNTIF(lst_Jobs,E15&"")>0,"OK","CHECK")) | M15: =IF(L15="","",IF(K15="GST 10%",ROUND(L15*set_GSTRate,2),0)) | N15: =IF(L15="","",L15+M15) | V15: =IF(COUNTA(A15,D15,C15,L15)=0,"",IF(A15="","No date - sits outside every month",IF(E15="","No job number",IF(F15="CHECK","Job number is not in the Xero job list",IF(I15="","No cost centre",IF(AND(P15="Y",C15=""),"Marked posted to Xero but has no invoice number",IF(AND(L15<>"",K15=""),"No tax code",IF(AND(L15<>"",O15=""),"No revenue GL code","")))))))) | W15: =IF(E15="","",IF(COUNTIF(tbl_Onsite[Job Number],E15&"")>0,"Onsite",IF(COUNTIF(tbl_Production[Job Number],E15&"")>0,"Production",IF(COUNTIF(tbl_Consulting[Job Number],E15&"")>0,"Consulting","not set up yet")))) | X15: =IF(E15="","",IFERROR(INDEX(lst_JobName,MATCH(E15&"",lst_Jobs,0)),"")) | Y15: =IF(E15="","",COUNTIFS(tbl_Finance[Job Number],E15&"",tbl_Finance[Ex GST],"<>")) | Z15: =IF(E15="","",SUMIFS(tbl_Finance[Ex GST],tbl_Finance[Job Number],E15&"")) | AA15: =IF(E15="","",SUMIFS(tbl_Finance[Ex GST],tbl_Finance[Job Number],E15&"",tbl_Finance[Xero Invoice No],"<>")) | AB15: =IF(E15="","",Z15-AA15) | AC15: =IF(E15="","",IFERROR(IF(INDEX(tbl_Onsite[Qwilr Quote],MATCH(E15&"",tbl_Onsite[Job Number],0))="","",INDEX(tbl_Onsite[Qwilr Quote],MATCH(E15&"",tbl_Onsite[Job Number],0))),IFERROR(IF(IF(INDEX(tbl_Production[Current RMS No],MATCH(E15&"",tbl_Production[Job Number],0))="",INDEX(tbl_Production[Qwilr Quote],MATCH(E15&"",tbl_Production[Job Number],0)),INDEX(tbl_Production[Current RMS No],MATCH(E15&"",tbl_Production[Job Number],0)))="","",IF(INDEX(tbl_Production[Current RMS No],MATCH(E15&"",tbl_Production[Job Number],0))="",INDEX(tbl_Production[Qwilr Quote],MATCH(E15&"",tbl_Production[Job Number],0)),INDEX(tbl_Production[Current RMS No],MATCH(E15&"",tbl_Production[Job Number],0)))),IFERROR(IF(INDEX(tbl_Consulting[Qwilr Quote],MATCH(E15&"",tbl_Consulting[Job Number],0))="","",INDEX(tbl_Consulting[Qwilr Quote],MATCH(E15&"",tbl_Consulting[Job Number],0))),"")))) | AD15: =IF(AC15="","",IF(AND(LEFT(AC15,4)<>"http",IF(H15="Production",set_RMSBase,set_QwilrBase)=""),"",HYPERLINK(IF(LEFT(AC15,4)="http",AC15,IF(H15="Production",set_RMSBase,set_QwilrBase)&AC15),"Open"))) | AE15: =IF(E15="","",IFERROR(INDEX(tbl_Production[Total Expense],MATCH(E15&"",tbl_Production[Job Number],0)),IFERROR(INDEX(tbl_Consulting[Total Expense],MATCH(E15&"",tbl_Consulting[Job Number],0)),0))) | AF15: =IF(E15="","",Z15-N(AE15)) | AG15: =IFERROR(AF15/Z15,"") | AH15: =IF(E15="","",IFERROR(IF(INDEX(tbl_Onsite[Notes],MATCH(E15&"",tbl_Onsite[Job Number],0))="","",INDEX(tbl_Onsite[Notes],MATCH(E15&"",tbl_Onsite[Job Number],0))),IFERROR(IF(INDEX(tbl_Production[Notes],MATCH(E15&"",tbl_Production[Job Number],0))="","",INDEX(tbl_Production[Notes],MATCH(E15&"",tbl_Production[Job Number],0))),IFERROR(IF(INDEX(tbl_Consulting[Notes],MATCH(E15&"",tbl_Consulting[Job Number],0))="","",INDEX(tbl_Consulting[Notes],MATCH(E15&"",tbl_Consulting[Job Number],0))),""))))
B16: =IF(A16="","",EOMONTH(A16,0)) | F16: =IF(E16="","",IF(COUNTIF(lst_Jobs,E16&"")>0,"OK","CHECK")) | M16: =IF(L16="","",IF(K16="GST 10%",ROUND(L16*set_GSTRate,2),0)) | N16: =IF(L16="","",L16+M16) | V16: =IF(COUNTA(A16,D16,C16,L16)=0,"",IF(A16="","No date - sits outside every month",IF(E16="","No job number",IF(F16="CHECK","Job number is not in the Xero job list",IF(I16="","No cost centre",IF(AND(P16="Y",C16=""),"Marked posted to Xero but has no invoice number",IF(AND(L16<>"",K16=""),"No tax code",IF(AND(L16<>"",O16=""),"No revenue GL code","")))))))) | W16: =IF(E16="","",IF(COUNTIF(tbl_Onsite[Job Number],E16&"")>0,"Onsite",IF(COUNTIF(tbl_Production[Job Number],E16&"")>0,"Production",IF(COUNTIF(tbl_Consulting[Job Number],E16&"")>0,"Consulting","not set up yet")))) | X16: =IF(E16="","",IFERROR(INDEX(lst_JobName,MATCH(E16&"",lst_Jobs,0)),"")) | Y16: =IF(E16="","",COUNTIFS(tbl_Finance[Job Number],E16&"",tbl_Finance[Ex GST],"<>")) | Z16: =IF(E16="","",SUMIFS(tbl_Finance[Ex GST],tbl_Finance[Job Number],E16&"")) | AA16: =IF(E16="","",SUMIFS(tbl_Finance[Ex GST],tbl_Finance[Job Number],E16&"",tbl_Finance[Xero Invoice No],"<>")) | AB16: =IF(E16="","",Z16-AA16) | AC16: =IF(E16="","",IFERROR(IF(INDEX(tbl_Onsite[Qwilr Quote],MATCH(E16&"",tbl_Onsite[Job Number],0))="","",INDEX(tbl_Onsite[Qwilr Quote],MATCH(E16&"",tbl_Onsite[Job Number],0))),IFERROR(IF(IF(INDEX(tbl_Production[Current RMS No],MATCH(E16&"",tbl_Production[Job Number],0))="",INDEX(tbl_Production[Qwilr Quote],MATCH(E16&"",tbl_Production[Job Number],0)),INDEX(tbl_Production[Current RMS No],MATCH(E16&"",tbl_Production[Job Number],0)))="","",IF(INDEX(tbl_Production[Current RMS No],MATCH(E16&"",tbl_Production[Job Number],0))="",INDEX(tbl_Production[Qwilr Quote],MATCH(E16&"",tbl_Production[Job Number],0)),INDEX(tbl_Production[Current RMS No],MATCH(E16&"",tbl_Production[Job Number],0)))),IFERROR(IF(INDEX(tbl_Consulting[Qwilr Quote],MATCH(E16&"",tbl_Consulting[Job Number],0))="","",INDEX(tbl_Consulting[Qwilr Quote],MATCH(E16&"",tbl_Consulting[Job Number],0))),"")))) | AD16: =IF(AC16="","",IF(AND(LEFT(AC16,4)<>"http",IF(H16="Production",set_RMSBase,set_QwilrBase)=""),"",HYPERLINK(IF(LEFT(AC16,4)="http",AC16,IF(H16="Production",set_RMSBase,set_QwilrBase)&AC16),"Open"))) | AE16: =IF(E16="","",IFERROR(INDEX(tbl_Production[Total Expense],MATCH(E16&"",tbl_Production[Job Number],0)),IFERROR(INDEX(tbl_Consulting[Total Expense],MATCH(E16&"",tbl_Consulting[Job Number],0)),0))) | AF16: =IF(E16="","",Z16-N(AE16)) | AG16: =IFERROR(AF16/Z16,"") | AH16: =IF(E16="","",IFERROR(IF(INDEX(tbl_Onsite[Notes],MATCH(E16&"",tbl_Onsite[Job Number],0))="","",INDEX(tbl_Onsite[Notes],MATCH(E16&"",tbl_Onsite[Job Number],0))),IFERROR(IF(INDEX(tbl_Production[Notes],MATCH(E16&"",tbl_Production[Job Number],0))="","",INDEX(tbl_Production[Notes],MATCH(E16&"",tbl_Production[Job Number],0))),IFERROR(IF(INDEX(tbl_Consulting[Notes],MATCH(E16&"",tbl_Consulting[Job Number],0))="","",INDEX(tbl_Consulting[Notes],MATCH(E16&"",tbl_Consulting[Job Number],0))),""))))
... B404: =IF(A404="","",EOMONTH(A404,0)) | F404: =IF(E404="","",IF(COUNTIF(lst_Jobs,E404&"")>0,"OK","CHECK")) | M404: =IF(L404="","",IF(K404="GST 10%",ROUND(L404*set_GSTRate,2),0)) | N404: =IF(L404="","",L404+M404) | V404: =IF(COUNTA(A404,D404,C404,L404)=0,"",IF(A404="","No date - sits outside every month",IF(E404="","No job number",IF(F404="CHECK","Job number is not in the Xero job list",IF(I404="","No cost centre",IF(AND(P404="Y",C404=""),"Marked posted to Xero but has no invoice number",IF(AND(L404<>"",K404=""),"No tax code",IF(AND(L404<>"",O404=""),"No revenue GL code","")))))))) | W404: =IF(E404="","",IF(COUNTIF(tbl_Onsite[Job Number],E404&"")>0,"Onsite",IF(COUNTIF(tbl_Production[Job Number],E404&"")>0,"Production",IF(COUNTIF(tbl_Consulting[Job Number],E404&"")>0,"Consulting","not set up yet")))) | X404: =IF(E404="","",IFERROR(INDEX(lst_JobName,MATCH(E404&"",lst_Jobs,0)),"")) | Y404: =IF(E404="","",COUNTIFS(tbl_Finance[Job Number],E404&"",tbl_Finance[Ex GST],"<>")) | Z404: =IF(E404="","",SUMIFS(tbl_Finance[Ex GST],tbl_Finance[Job Number],E404&"")) | AA404: =IF(E404="","",SUMIFS(tbl_Finance[Ex GST],tbl_Finance[Job Number],E404&"",tbl_Finance[Xero Invoice No],"<>")) | AB404: =IF(E404="","",Z404-AA404) | AC404: =IF(E404="","",IFERROR(IF(INDEX(tbl_Onsite[Qwilr Quote],MATCH(E404&"",tbl_Onsite[Job Number],0))="","",INDEX(tbl_Onsite[Qwilr Quote],MATCH(E404&"",tbl_Onsite[Job Number],0))),IFERROR(IF(IF(INDEX(tbl_Production[Current RMS No],MATCH(E404&"",tbl_Production[Job Number],0))="",INDEX(tbl_Production[Qwilr Quote],MATCH(E404&"",tbl_Production[Job Number],0)),INDEX(tbl_Production[Current RMS No],MATCH(E404&"",tbl_Production[Job Number],0)))="","",IF(INDEX(tbl_Production[Current RMS No],MATCH(E404&"",tbl_Production[Job Number],0))="",INDEX(tbl_Production[Qwilr Quote],MATCH(E404&"",tbl_Production[Job Number],0)),INDEX(tbl_Production[Current RMS No],MATCH(E404&"",tbl_Production[Job Number],0)))),IFERROR(IF(INDEX(tbl_Consulting[Qwilr Quote],MATCH(E404&"",tbl_Consulting[Job Number],0))="","",INDEX(tbl_Consulting[Qwilr Quote],MATCH(E404&"",tbl_Consulting[Job Number],0))),"")))) | AD404: =IF(AC404="","",IF(AND(LEFT(AC404,4)<>"http",IF(H404="Production",set_RMSBase,set_QwilrBase)=""),"",HYPERLINK(IF(LEFT(AC404,4)="http",AC404,IF(H404="Production",set_RMSBase,set_QwilrBase)&AC404),"Open"))) | AE404: =IF(E404="","",IFERROR(INDEX(tbl_Production[Total Expense],MATCH(E404&"",tbl_Production[Job Number],0)),IFERROR(INDEX(tbl_Consulting[Total Expense],MATCH(E404&"",tbl_Consulting[Job Number],0)),0))) | AF404: =IF(E404="","",Z404-N(AE404)) | AG404: =IFERROR(AF404/Z404,"") | AH404: =IF(E404="","",IFERROR(IF(INDEX(tbl_Onsite[Notes],MATCH(E404&"",tbl_Onsite[Job Number],0))="","",INDEX(tbl_Onsite[Notes],MATCH(E404&"",tbl_Onsite[Job Number],0))),IFERROR(IF(INDEX(tbl_Production[Notes],MATCH(E404&"",tbl_Production[Job Number],0))="","",INDEX(tbl_Production[Notes],MATCH(E404&"",tbl_Production[Job Number],0))),IFERROR(IF(INDEX(tbl_Consulting[Notes],MATCH(E404&"",tbl_Consulting[Job Number],0))="","",INDEX(tbl_Consulting[Notes],MATCH(E404&"",tbl_Consulting[Job Number],0))),""))))

Sheet Month-End
A1: Month-End Revenue Close
A2: Pick the month, type the Xero figures into the yellow cells, and work down. Everything white or grey calculates itself.
A4: Month being closed | C4: 46265 | D4: <- month end date
A6: 1. REVENUE BY COST CENTRE - tracker vs Xero
A7: Cost Centre | B7: Invoiced Ex GST | C7: GST | D7: Inc GST | E7: WIP Movement | F7: Revenue Recognised | G7: Xero Revenue (type in) | H7: Variance | I7: Check
A8: ONSITE | B8: =SUMIFS(tbl_Finance[Ex GST],tbl_Finance[Month],$C$4,tbl_Finance[Cost Centre],$A8) | C8: =SUMIFS(tbl_Finance[GST],tbl_Finance[Month],$C$4,tbl_Finance[Cost Centre],$A8) | D8: =B8+C8 | E8: =SUMIFS(tbl_WIP[Amount],tbl_WIP[Month],$C$4,tbl_WIP[Cost Centre],$A8,tbl_WIP[Revenue or Cost],"<>Cost",tbl_WIP[Defer Start],"")+SUMIFS('Deferred Revenue'!$Q$6:$Q$607,'Deferred Revenue'!$F$6:$F$607,$A8,'Deferred Revenue'!$T$6:$T$607,"<>Cost") | F8: =B8+E8 | H8: =IF($G8="","",$F8-$G8) | I8: =IF($G8="","Enter Xero figure",IF(ROUND($H8,2)=0,"Reconciled","CHECK - "&TEXT($H8,"$#,##0.00")))
A9: PRODUCTION | B9: =SUMIFS(tbl_Finance[Ex GST],tbl_Finance[Month],$C$4,tbl_Finance[Cost Centre],$A9) | C9: =SUMIFS(tbl_Finance[GST],tbl_Finance[Month],$C$4,tbl_Finance[Cost Centre],$A9) | D9: =B9+C9 | E9: =SUMIFS(tbl_WIP[Amount],tbl_WIP[Month],$C$4,tbl_WIP[Cost Centre],$A9,tbl_WIP[Revenue or Cost],"<>Cost",tbl_WIP[Defer Start],"")+SUMIFS('Deferred Revenue'!$Q$6:$Q$607,'Deferred Revenue'!$F$6:$F$607,$A9,'Deferred Revenue'!$T$6:$T$607,"<>Cost") | F9: =B9+E9 | H9: =IF($G9="","",$F9-$G9) | I9: =IF($G9="","Enter Xero figure",IF(ROUND($H9,2)=0,"Reconciled","CHECK - "&TEXT($H9,"$#,##0.00")))
A10: VIDEO | B10: =SUMIFS(tbl_Finance[Ex GST],tbl_Finance[Month],$C$4,tbl_Finance[Cost Centre],$A10) | C10: =SUMIFS(tbl_Finance[GST],tbl_Finance[Month],$C$4,tbl_Finance[Cost Centre],$A10) | D10: =B10+C10 | E10: =SUMIFS(tbl_WIP[Amount],tbl_WIP[Month],$C$4,tbl_WIP[Cost Centre],$A10,tbl_WIP[Revenue or Cost],"<>Cost",tbl_WIP[Defer Start],"")+SUMIFS('Deferred Revenue'!$Q$6:$Q$607,'Deferred Revenue'!$F$6:$F$607,$A10,'Deferred Revenue'!$T$6:$T$607,"<>Cost") | F10: =B10+E10 | H10: =IF($G10="","",$F10-$G10) | I10: =IF($G10="","Enter Xero figure",IF(ROUND($H10,2)=0,"Reconciled","CHECK - "&TEXT($H10,"$#,##0.00")))
A11: INTEGRATION | B11: =SUMIFS(tbl_Finance[Ex GST],tbl_Finance[Month],$C$4,tbl_Finance[Cost Centre],$A11) | C11: =SUMIFS(tbl_Finance[GST],tbl_Finance[Month],$C$4,tbl_Finance[Cost Centre],$A11) | D11: =B11+C11 | E11: =SUMIFS(tbl_WIP[Amount],tbl_WIP[Month],$C$4,tbl_WIP[Cost Centre],$A11,tbl_WIP[Revenue or Cost],"<>Cost",tbl_WIP[Defer Start],"")+SUMIFS('Deferred Revenue'!$Q$6:$Q$607,'Deferred Revenue'!$F$6:$F$607,$A11,'Deferred Revenue'!$T$6:$T$607,"<>Cost") | F11: =B11+E11 | H11: =IF($G11="","",$F11-$G11) | I11: =IF($G11="","Enter Xero figure",IF(ROUND($H11,2)=0,"Reconciled","CHECK - "&TEXT($H11,"$#,##0.00")))
A12: CONSULTING | B12: =SUMIFS(tbl_Finance[Ex GST],tbl_Finance[Month],$C$4,tbl_Finance[Cost Centre],$A12) | C12: =SUMIFS(tbl_Finance[GST],tbl_Finance[Month],$C$4,tbl_Finance[Cost Centre],$A12) | D12: =B12+C12 | E12: =SUMIFS(tbl_WIP[Amount],tbl_WIP[Month],$C$4,tbl_WIP[Cost Centre],$A12,tbl_WIP[Revenue or Cost],"<>Cost",tbl_WIP[Defer Start],"")+SUMIFS('Deferred Revenue'!$Q$6:$Q$607,'Deferred Revenue'!$F$6:$F$607,$A12,'Deferred Revenue'!$T$6:$T$607,"<>Cost") | F12: =B12+E12 | H12: =IF($G12="","",$F12-$G12) | I12: =IF($G12="","Enter Xero figure",IF(ROUND($H12,2)=0,"Reconciled","CHECK - "&TEXT($H12,"$#,##0.00")))
A13: CTS | B13: =SUMIFS(tbl_Finance[Ex GST],tbl_Finance[Month],$C$4,tbl_Finance[Cost Centre],$A13) | C13: =SUMIFS(tbl_Finance[GST],tbl_Finance[Month],$C$4,tbl_Finance[Cost Centre],$A13) | D13: =B13+C13 | E13: =SUMIFS(tbl_WIP[Amount],tbl_WIP[Month],$C$4,tbl_WIP[Cost Centre],$A13,tbl_WIP[Revenue or Cost],"<>Cost",tbl_WIP[Defer Start],"")+SUMIFS('Deferred Revenue'!$Q$6:$Q$607,'Deferred Revenue'!$F$6:$F$607,$A13,'Deferred Revenue'!$T$6:$T$607,"<>Cost") | F13: =B13+E13 | H13: =IF($G13="","",$F13-$G13) | I13: =IF($G13="","Enter Xero figure",IF(ROUND($H13,2)=0,"Reconciled","CHECK - "&TEXT($H13,"$#,##0.00")))
A14: TOTAL | B14: =SUM(B8:B13) | C14: =SUM(C8:C13) | D14: =SUM(D8:D13) | E14: =SUM(E8:E13) | F14: =SUM(F8:F13) | G14: =SUM(G8:G13) | H14: =SUM(H8:H13) | I14: =IF(COUNT($G8:$G13)=0,"Enter Xero figures",IF(ROUND($H14,2)=0,"Reconciled","CHECK - "&TEXT($H14,"$#,##0.00")))
A15: Every line on the Finance sheet carries one cost centre, so these add to the month's invoicing exactly.
A17: 2. WORK IN PROGRESS - GL 11300
B18: Total | C18: Deferred / accrued revenue | D18: Deferred / accrued cost | I18: Check
A19: Opening WIP balance (all months before this one) | B19: =C19+D19 | C19: =SUMIFS(tbl_WIP[Amount],tbl_WIP[Month],"<>",tbl_WIP[Month],"<"&$C$4,tbl_WIP[Revenue or Cost],"<>Cost",tbl_WIP[Defer Start],"")+SUMIFS('Deferred Revenue'!$P$6:$P$607,'Deferred Revenue'!$T$6:$T$607,"<>Cost") | D19: =SUMIFS(tbl_WIP[Amount],tbl_WIP[Month],"<>",tbl_WIP[Month],"<"&$C$4,tbl_WIP[Revenue or Cost],"Cost",tbl_WIP[Defer Start],"")+SUMIFS('Deferred Revenue'!$P$6:$P$607,'Deferred Revenue'!$T$6:$T$607,"Cost")
A20: Movement this month | B20: =C20+D20 | C20: =SUMIFS(tbl_WIP[Amount],tbl_WIP[Month],$C$4,tbl_WIP[Revenue or Cost],"<>Cost",tbl_WIP[Defer Start],"")+SUMIFS('Deferred Revenue'!$Q$6:$Q$607,'Deferred Revenue'!$T$6:$T$607,"<>Cost") | D20: =SUMIFS(tbl_WIP[Amount],tbl_WIP[Month],$C$4,tbl_WIP[Revenue or Cost],"Cost",tbl_WIP[Defer Start],"")+SUMIFS('Deferred Revenue'!$Q$6:$Q$607,'Deferred Revenue'!$T$6:$T$607,"Cost")
A21: Closing WIP balance per this tracker | B21: =B19+B20 | C21: =C19+C20 | D21: =D19+D20
A22: Closing balance per the WIP Schedule file
A23: Variance - tracker vs WIP Schedule | B23: =IF(B22="","",B21-B22) | I23: =IF(B22="","Enter WIP Schedule figure",IF(ROUND(B23,2)=0,"Reconciled","CHECK"))
A24: Closing balance per Xero GL 11300
A25: Variance - tracker vs Xero | B25: =IF(B24="","",B21-B24) | I25: =IF(B24="","Enter Xero 11300 balance",IF(ROUND(B25,2)=0,"Reconciled","CHECK"))
A26: GL 11300 nets deferred revenue against deferred cost, so Xero shows one figure and cannot split it. The Revenue or Cost column on WIP Movements splits it here. Only the Total column should be compared to Xero.
A28: 3. DATA CHECKS - every count should be zero before you close
A29: Check | B29: Count | I29: Status
A30: Invoice lines with an amount but no date | B30: =SUMPRODUCT(--(tbl_Finance[Date]=""),--(tbl_Finance[Ex GST]<>"")) | I30: =IF(B30=0,"Clear","REVIEW")
A31: Invoice lines with an amount but no job number | B31: =COUNTIFS(tbl_Finance[Ex GST],"<>",tbl_Finance[Job Number],"") | I31: =IF(B31=0,"Clear","REVIEW")
A32: Job numbers not found in the Xero job list | B32: =COUNTIF(tbl_Finance[Job in Xero?],"CHECK") | I32: =IF(B32=0,"Clear","REVIEW")
A33: Marked posted to Xero but no invoice number | B33: =COUNTIFS(tbl_Finance[Posted to Xero],"Y",tbl_Finance[Xero Invoice No],"") | I33: =IF(B33=0,"Clear","REVIEW")
A34: Invoice lines with an amount but no cost centre | B34: =COUNTIFS(tbl_Finance[Ex GST],"<>",tbl_Finance[Cost Centre],"") | I34: =IF(B34=0,"Clear","REVIEW")
A35: Invoice lines with an amount but no tax code | B35: =COUNTIFS(tbl_Finance[Ex GST],"<>",tbl_Finance[Tax Code],"") | I35: =IF(B35=0,"Clear","REVIEW")
A36: Invoice lines with an amount but no revenue GL code | B36: =COUNTIFS(tbl_Finance[Ex GST],"<>",tbl_Finance[Revenue GL],"") | I36: =IF(B36=0,"Clear","REVIEW")
A37: Anything flagged in the Issue column | B37: =COUNTIF(tbl_Finance[Issue],"?*") | I37: =IF(B37=0,"Clear","REVIEW")
A38: Flagged "To WIP = Y" but no matching WIP movement | B38: =SUMPRODUCT(--(tbl_Finance[To WIP]="Y"),--(tbl_Finance[Xero Invoice No]<>""),--(COUNTIF(tbl_WIP[Xero Invoice No],tbl_Finance[Xero Invoice No]&"")=0)) | I38: =IF(B38=0,"Clear","REVIEW")
A39: WIP movements with an amount but no month or no job | B39: =COUNTIFS(tbl_WIP[Month],"",tbl_WIP[Amount],"<>")+COUNTIFS(tbl_WIP[Job Number],"",tbl_WIP[Amount],"<>") | I39: =IF(B39=0,"Clear","REVIEW")
A40: WIP job numbers not found in the Xero job list | B40: =COUNTIF(tbl_WIP[Job in Xero?],"CHECK") | I40: =IF(B40=0,"Clear","REVIEW")
A41: Consulting revenue split does not equal the job revenue | B41: =COUNTIF(tbl_Consulting[Revenue Split Check],"MISMATCH") | I41: =IF(B41=0,"Clear","REVIEW")
A42: Invoiced jobs not set up on any department sheet | B42: =COUNTIF(tbl_Finance[On Dept Sheet],"not set up yet") | I42: =IF(B42=0,"Clear","REVIEW")
A43: Job numbers sitting on more than one department sheet | B43: =SUMPRODUCT(--(tbl_Onsite[Job Number]<>""),--(COUNTIF(tbl_Production[Job Number],tbl_Onsite[Job Number]&"")>0))+SUMPRODUCT(--(tbl_Onsite[Job Number]<>""),--(COUNTIF(tbl_Consulting[Job Number],tbl_Onsite[Job Number]&"")>0))+SUMPRODUCT(--(tbl_Production[Job Number]<>""),--(COUNTIF(tbl_Consulting[Job Number],tbl_Production[Job Number]&"")>0)) | I43: =IF(B43=0,"Clear","REVIEW")
A44: Jobs on a department sheet with no invoice yet | B44: =COUNTIFS(tbl_Onsite[Job Number],"<>",tbl_Onsite[Lines on Job],0)+COUNTIFS(tbl_Production[Job Number],"<>",tbl_Production[Lines on Job],0)+COUNTIFS(tbl_Consulting[Job Number],"<>",tbl_Consulting[Lines on Job],0) | I44: =IF(B44=0,"Clear","REVIEW")
...

Sheet WIP Summary
A1: WIP Balance by Job
A2: Job-level WIP for the month selected on the Month-End sheet. Paste the matching balance from the WIP Schedule file into column G and the variance column finds the breaks. Filter column F to hide the nil rows.
A4: Month | C4: ='Month-End'!C4 | D4: <- set this on the Month-End sheet
