Workbook

Sheet Read Me
B2: FY 2026-27 Revenue Tracker
B3: Rebuilt from FY27_Revenue_Tracker_v2.xlsm. Your original file has not been changed.
B5: How a record works
B6: Every record needs two things: a Type and a Department. Between them they decide which Dashboard
B7: column the money lands in.
B9: Type Invoice or WIP. Pick WIP for a work-in-progress movement, Invoice for everything else.
B10: Department Consulting, Integration, Onsite, Other, Production, Support or Video.
B11: Amount One column, always. For a WIP record this is the movement, and it can be negative.
B13: "Reports as" is calculated for you and shows which Dashboard column the record feeds. Type WIP always
B14: reports as WIP whatever the department. Otherwise the department decides: Support goes to Support,
B15: Consulting and Integration go to Consulting, and Production, Video, Other and Onsite go to Production.
B16: That mapping is on the Lists tab if you ever need to change it.
... B53: Everything here is calculated fresh, so July and August Production read lower. The lower ones are correct.

Sheet Lists
A1: Control values — edit here and every dropdown, check and report line follows
A3: Financial year start | B3: 46204 | D3: Type | F3: Department | G3: Reports as | I3: Status | K3: Yes / No
A4: Financial year end (excl.) | B4: 46569 | D4: Invoice | F4: Consulting | G4: Consulting | I4: In Progress | K4: Y
D5: WIP | F5: Integration | G5: Consulting | I5: Completed | K5: N
F6: Onsite | G6: Production | I6: Cancelled
F7: Other | G7: Production | I7: Closed
F8: Production | G8: Production
F9: Support | G9: Support
F10: Video | G10: Production
F12: A record whose Type is WIP always reports as WIP, whatever its department.

Sheet Data
A1: No. | B1: Type | C1: Date | D1: Department | E1: Reports as | F1: Status | G1: Client | H1: Job Number | I1: Description | J1: Invoice Number | K1: Amount | L1: Net Revenue | M1: Margin | N1: Margin % | O1: Date Check | P1: Duplicate Check | Q1: Notes | R1: Client Email | S1: Event Date | T1: Zoho Number | U1: Current Number | V1: Closed | W1: Invoice Posted to Xero | X1: Video Filming | Y1: Video Editing | Z1: Project Management | AA1: Video Project Management | AB1: Production Labour Hours | AC1: Video Total | AD1: Discounts Included | AE1: Discounts as % of Net | AF1: Cross Hire Expense | AG1: Labour Expense (Internal) | AH1: Qwilr Link | AI1: Labour Revenue | AJ1: Equipment Revenue | AK1: Subscription Revenue | AL1: Labour Expense (External) | AM1: Equipment Expense (Internal) | AN1: Subscription & Licences Expense
A2: =IF(COUNTA($B2:$K2)=0,"",ROW()-1) | B2: Invoice | C2: 46234 | D2: Support | E2: =IF($B2="","",IF($B2="WIP","WIP",IFERROR(INDEX(Lists!$G$4:$G$10,MATCH($D2,Lists!$F$4:$F$10,0)),"Unmapped"))) | G2: CBA | H2: 1350 | I2: CBA BNE July 2026 | J2: INV-10525 | K2: 8588.45 | L2: =IF($K2="","",IF($E2="Production",$K2-N($AD2),$K2)) | M2: =IF($E2="Production",IF($K2="","",$K2-(N($AF2)+N($AG2))),IF($E2="Consulting",IF($K2="","",$K2-(N($AL2)+N($AM2)+N($AN2))),"")) | N2: =IFERROR($M2/$K2,"") | O2: =IF(COUNTA($B2:$K2)=0,"",IF($C2="","No date",IF(AND($C2>=Lists!$B$3,$C2<Lists!$B$4),"In FY27","Outside FY27"))) | P2: =IF($E2<>"WIP","",IF($H2="","",IF(COUNTIFS($E$2:$E$20000,"<>WIP",$H$2:$H$20000,$H2)>0,"Job already invoiced",""))) | Q2: 174.05 hours | AE2: =IF($E2<>"Production","",IFERROR($AD2/$L2,""))
A3: =IF(COUNTA($B3:$K3)=0,"",ROW()-1) | B3: Invoice | C3: 46234 | D3: Support | E3: =IF($B3="","",IF($B3="WIP","WIP",IFERROR(INDEX(Lists!$G$4:$G$10,MATCH($D3,Lists!$F$4:$F$10,0)),"Unmapped"))) | G3: CBA | H3: 585/586/1755 | I3: CBP July 2026 | J3: INV-10526 | K3: 22120.57 | L3: =IF($K3="","",IF($E3="Production",$K3-N($AD3),$K3)) | M3: =IF($E3="Production",IF($K3="","",$K3-(N($AF3)+N($AG3))),IF($E3="Consulting",IF($K3="","",$K3-(N($AL3)+N($AM3)+N($AN3))),"")) | N3: =IFERROR($M3/$K3,"") | O3: =IF(COUNTA($B3:$K3)=0,"",IF($C3="","No date",IF(AND($C3>=Lists!$B$3,$C3<Lists!$B$4),"In FY27","Outside FY27"))) | P3: =IF($E3<>"WIP","",IF($H3="","",IF(COUNTIFS($E$2:$E$20000,"<>WIP",$H$2:$H$20000,$H3)>0,"Job already invoiced",""))) | Q3: Deduct 3hrs for TN 01/07 & 6hrs for NP 14/07 | AE3: =IF($E3<>"Production","",IFERROR($AD3/$L3,""))
A4: =IF(COUNTA($B4:$K4)=0,"",ROW()-1) | B4: Invoice | C4: 46234 | D4: Support | E4: =IF($B4="","",IF($B4="WIP","WIP",IFERROR(INDEX(Lists!$G$4:$G$10,MATCH($D4,Lists!$F$4:$F$10,0)),"Unmapped"))) | G4: CBA | H4: 587 | I4: CBS July 2026 | J4: INV-10527 | K4: 10720 | L4: =IF($K4="","",IF($E4="Production",$K4-N($AD4),$K4)) | M4: =IF($E4="Production",IF($K4="","",$K4-(N($AF4)+N($AG4))),IF($E4="Consulting",IF($K4="","",$K4-(N($AL4)+N($AM4)+N($AN4))),"")) | N4: =IFERROR($M4/$K4,"") | O4: =IF(COUNTA($B4:$K4)=0,"",IF($C4="","No date",IF(AND($C4>=Lists!$B$3,$C4<Lists!$B$4),"In FY27","Outside FY27"))) | P4: =IF($E4<>"WIP","",IF($H4="","",IF(COUNTIFS($E$2:$E$20000,"<>WIP",$H$2:$H$20000,$H4)>0,"Job already invoiced",""))) | AE4: =IF($E4<>"Production","",IFERROR($AD4/$L4,""))
A5: =IF(COUNTA($B5:$K5)=0,"",ROW()-1) | B5: Invoice | C5: 46234 | D5: Support | E5: =IF($B5="","",IF($B5="WIP","WIP",IFERROR(INDEX(Lists!$G$4:$G$10,MATCH($D5,Lists!$F$4:$F$10,0)),"Unmapped"))) | G5: DTTL | H5: 2846/1401/725/1400/1530/1862/2402/2849/974 | I5: DTTL Contract July 2026 | J5: INV-10528 | K5: 103625.44 | L5: =IF($K5="","",IF($E5="Production",$K5-N($AD5),$K5)) | M5: =IF($E5="Production",IF($K5="","",$K5-(N($AF5)+N($AG5))),IF($E5="Consulting",IF($K5="","",$K5-(N($AL5)+N($AM5)+N($AN5))),"")) | N5: =IFERROR($M5/$K5,"") | O5: =IF(COUNTA($B5:$K5)=0,"",IF($C5="","No date",IF(AND($C5>=Lists!$B$3,$C5<Lists!$B$4),"In FY27","Outside FY27"))) | P5: =IF($E5<>"WIP","",IF($H5="","",IF(COUNTIFS($E$2:$E$20000,"<>WIP",$H$2:$H$20000,$H5)>0,"Job already invoiced",""))) | AE5: =IF($E5<>"Production","",IFERROR($AD5/$L5,""))
A6: =IF(COUNTA($B6:$K6)=0,"",ROW()-1) | B6: Invoice | C6: 46234 | D6: Support | E6: =IF($B6="","",IF($B6="WIP","WIP",IFERROR(INDEX(Lists!$G$4:$G$10,MATCH($D6,Lists!$F$4:$F$10,0)),"Unmapped"))) | G6: BW | H6: 732/1144 | I6: BW Contract July 2026 | J6: INV-10529 | K6: 19427.5 | L6: =IF($K6="","",IF($E6="Production",$K6-N($AD6),$K6)) | M6: =IF($E6="Production",IF($K6="","",$K6-(N($AF6)+N($AG6))),IF($E6="Consulting",IF($K6="","",$K6-(N($AL6)+N($AM6)+N($AN6))),"")) | N6: =IFERROR($M6/$K6,"") | O6: =IF(COUNTA($B6:$K6)=0,"",IF($C6="","No date",IF(AND($C6>=Lists!$B$3,$C6<Lists!$B$4),"In FY27","Outside FY27"))) | P6: =IF($E6<>"WIP","",IF($H6="","",IF(COUNTIFS($E$2:$E$20000,"<>WIP",$H$2:$H$20000,$H6)>0,"Job already invoiced",""))) | AE6: =IF($E6<>"Production","",IFERROR($AD6/$L6,""))
A7: =IF(COUNTA($B7:$K7)=0,"",ROW()-1) | B7: Invoice | C7: 46234 | D7: Support | E7: =IF($B7="","",IF($B7="WIP","WIP",IFERROR(INDEX(Lists!$G$4:$G$10,MATCH($D7,Lists!$F$4:$F$10,0)),"Unmapped"))) | G7: BW | H7: 2192 | I7: BW Additionals July 2026 | J7: INV-10530 | K7: 1120 | L7: =IF($K7="","",IF($E7="Production",$K7-N($AD7),$K7)) | M7: =IF($E7="Production",IF($K7="","",$K7-(N($AF7)+N($AG7))),IF($E7="Consulting",IF($K7="","",$K7-(N($AL7)+N($AM7)+N($AN7))),"")) | N7: =IFERROR($M7/$K7,"") | O7: =IF(COUNTA($B7:$K7)=0,"",IF($C7="","No date",IF(AND($C7>=Lists!$B$3,$C7<Lists!$B$4),"In FY27","Outside FY27"))) | P7: =IF($E7<>"WIP","",IF($H7="","",IF(COUNTIFS($E$2:$E$20000,"<>WIP",$H$2:$H$20000,$H7)>0,"Job already invoiced",""))) | AE7: =IF($E7<>"Production","",IFERROR($AD7/$L7,""))
A8: =IF(COUNTA($B8:$K8)=0,"",ROW()-1) | B8: Invoice | C8: 46234 | D8: Support | E8: =IF($B8="","",IF($B8="WIP","WIP",IFERROR(INDEX(Lists!$G$4:$G$10,MATCH($D8,Lists!$F$4:$F$10,0)),"Unmapped"))) | G8: PWC | H8: 2488 | I8: PWC Brisbane July 2026 | J8: INV-10531 | K8: 7150 | L8: =IF($K8="","",IF($E8="Production",$K8-N($AD8),$K8)) | M8: =IF($E8="Production",IF($K8="","",$K8-(N($AF8)+N($AG8))),IF($E8="Consulting",IF($K8="","",$K8-(N($AL8)+N($AM8)+N($AN8))),"")) | N8: =IFERROR($M8/$K8,"") | O8: =IF(COUNTA($B8:$K8)=0,"",IF($C8="","No date",IF(AND($C8>=Lists!$B$3,$C8<Lists!$B$4),"In FY27","Outside FY27"))) | P8: =IF($E8<>"WIP","",IF($H8="","",IF(COUNTIFS($E$2:$E$20000,"<>WIP",$H$2:$H$20000,$H8)>0,"Job already invoiced",""))) | AE8: =IF($E8<>"Production","",IFERROR($AD8/$L8,""))
A9: =IF(COUNTA($B9:$K9)=0,"",ROW()-1) | B9: Invoice | C9: 46234 | D9: Support | E9: =IF($B9="","",IF($B9="WIP","WIP",IFERROR(INDEX(Lists!$G$4:$G$10,MATCH($D9,Lists!$F$4:$F$10,0)),"Unmapped"))) | G9: Gen-E | H9: 26021602 | I9: Gen-E ABS July 2026 | J9: INV-10532 | K9: 12388.8 | L9: =IF($K9="","",IF($E9="Production",$K9-N($AD9),$K9)) | M9: =IF($E9="Production",IF($K9="","",$K9-(N($AF9)+N($AG9))),IF($E9="Consulting",IF($K9="","",$K9-(N($AL9)+N($AM9)+N($AN9))),"")) | N9: =IFERROR($M9/$K9,"") | O9: =IF(COUNTA($B9:$K9)=0,"",IF($C9="","No date",IF(AND($C9>=Lists!$B$3,$C9<Lists!$B$4),"In FY27","Outside FY27"))) | P9: =IF($E9<>"WIP","",IF($H9="","",IF(COUNTIFS($E$2:$E$20000,"<>WIP",$H$2:$H$20000,$H9)>0,"Job already invoiced",""))) | AE9: =IF($E9<>"Production","",IFERROR($AD9/$L9,""))
A10: =IF(COUNTA($B10:$K10)=0,"",ROW()-1) | B10: Invoice | C10: 46234 | D10: Support | E10: =IF($B10="","",IF($B10="WIP","WIP",IFERROR(INDEX(Lists!$G$4:$G$10,MATCH($D10,Lists!$F$4:$F$10,0)),"Unmapped"))) | G10: CBA | H10: 26043001 | I10: CBA Mel July 2026 | J10: INV-10534 | K10: 11377.12 | L10: =IF($K10="","",IF($E10="Production",$K10-N($AD10),$K10)) | M10: =IF($E10="Production",IF($K10="","",$K10-(N($AF10)+N($AG10))),IF($E10="Consulting",IF($K10="","",$K10-(N($AL10)+N($AM10)+N($AN10))),"")) | N10: =IFERROR($M10/$K10,"") | O10: =IF(COUNTA($B10:$K10)=0,"",IF($C10="","No date",IF(AND($C10>=Lists!$B$3,$C10<Lists!$B$4),"In FY27","Outside FY27"))) | P10: =IF($E10<>"WIP","",IF($H10="","",IF(COUNTIFS($E$2:$E$20000,"<>WIP",$H$2:$H$20000,$H10)>0,"Job already invoiced",""))) | Q10: Deduct 8hrs CN for 03/07 | AE10: =IF($E10<>"Production","",IFERROR($AD10/$L10,""))
A11: =IF(COUNTA($B11:$K11)=0,"",ROW()-1) | B11: Invoice | C11: 46234 | D11: Support | E11: =IF($B11="","",IF($B11="WIP","WIP",IFERROR(INDEX(Lists!$G$4:$G$10,MATCH($D11,Lists!$F$4:$F$10,0)),"Unmapped"))) | G11: PWC | H11: 25101301B | I11: PWC Sydney IT July 2026 | J11: INV-10535 | K11: 11907 | L11: =IF($K11="","",IF($E11="Production",$K11-N($AD11),$K11)) | M11: =IF($E11="Production",IF($K11="","",$K11-(N($AF11)+N($AG11))),IF($E11="Consulting",IF($K11="","",$K11-(N($AL11)+N($AM11)+N($AN11))),"")) | N11: =IFERROR($M11/$K11,"") | O11: =IF(COUNTA($B11:$K11)=0,"",IF($C11="","No date",IF(AND($C11>=Lists!$B$3,$C11<Lists!$B$4),"In FY27","Outside FY27"))) | P11: =IF($E11<>"WIP","",IF($H11="","",IF(COUNTIFS($E$2:$E$20000,"<>WIP",$H$2:$H$20000,$H11)>0,"Job already invoiced",""))) | AE11: =IF($E11<>"Production","",IFERROR($AD11/$L11,""))
A12: =IF(COUNTA($B12:$K12)=0,"",ROW()-1) | B12: Invoice | C12: 46234 | D12: Support | E12: =IF($B12="","",IF($B12="WIP","WIP",IFERROR(INDEX(Lists!$G$4:$G$10,MATCH($D12,Lists!$F$4:$F$10,0)),"Unmapped"))) | G12: RICOH | H12: 2880 | I12: Ricoh Contract July 2026 | J12: INV-10536 | K12: 11860.5 | L12: =IF($K12="","",IF($E12="Production",$K12-N($AD12),$K12)) | M12: =IF($E12="Production",IF($K12="","",$K12-(N($AF12)+N($AG12))),IF($E12="Consulting",IF($K12="","",$K12-(N($AL12)+N($AM12)+N($AN12))),"")) | N12: =IFERROR($M12/$K12,"") | O12: =IF(COUNTA($B12:$K12)=0,"",IF($C12="","No date",IF(AND($C12>=Lists!$B$3,$C12<Lists!$B$4),"In FY27","Outside FY27"))) | P12: =IF($E12<>"WIP","",IF($H12="","",IF(COUNTIFS($E$2:$E$20000,"<>WIP",$H$2:$H$20000,$H12)>0,"Job already invoiced",""))) | Q12: 2 months extension | AE12: =IF($E12<>"Production","",IFERROR($AD12/$L12,""))
A13: =IF(COUNTA($B13:$K13)=0,"",ROW()-1) | B13: Invoice | C13: 46234 | D13: Support | E13: =IF($B13="","",IF($B13="WIP","WIP",IFERROR(INDEX(Lists!$G$4:$G$10,MATCH($D13,Lists!$F$4:$F$10,0)),"Unmapped"))) | G13: PWC | I13: PWC Dedicated Tech 29/07/2026 | J13: INV-10537 | K13: 340 | L13: =IF($K13="","",IF($E13="Production",$K13-N($AD13),$K13)) | M13: =IF($E13="Production",IF($K13="","",$K13-(N($AF13)+N($AG13))),IF($E13="Consulting",IF($K13="","",$K13-(N($AL13)+N($AM13)+N($AN13))),"")) | N13: =IFERROR($M13/$K13,"") | O13: =IF(COUNTA($B13:$K13)=0,"",IF($C13="","No date",IF(AND($C13>=Lists!$B$3,$C13<Lists!$B$4),"In FY27","Outside FY27"))) | P13: =IF($E13<>"WIP","",IF($H13="","",IF(COUNTIFS($E$2:$E$20000,"<>WIP",$H$2:$H$20000,$H13)>0,"Job already invoiced",""))) | Q13: 29/07/2026 4hours | AE13: =IF($E13<>"Production","",IFERROR($AD13/$L13,""))
A14: =IF(COUNTA($B14:$K14)=0,"",ROW()-1) | B14: Invoice | C14: 46234 | D14: Support | E14: =IF($B14="","",IF($B14="WIP","WIP",IFERROR(INDEX(Lists!$G$4:$G$10,MATCH($D14,Lists!$F$4:$F$10,0)),"Unmapped"))) | G14: APN | H14: 3056 | I14: APN Tech Support July 22 & 24 | J14: INV-10541 | K14: 680 | L14: =IF($K14="","",IF($E14="Production",$K14-N($AD14),$K14)) | M14: =IF($E14="Production",IF($K14="","",$K14-(N($AF14)+N($AG14))),IF($E14="Consulting",IF($K14="","",$K14-(N($AL14)+N($AM14)+N($AN14))),"")) | N14: =IFERROR($M14/$K14,"") | O14: =IF(COUNTA($B14:$K14)=0,"",IF($C14="","No date",IF(AND($C14>=Lists!$B$3,$C14<Lists!$B$4),"In FY27","Outside FY27"))) | P14: =IF($E14<>"WIP","",IF($H14="","",IF(COUNTIFS($E$2:$E$20000,"<>WIP",$H$2:$H$20000,$H14)>0,"Job already invoiced",""))) | AE14: =IF($E14<>"Production","",IFERROR($AD14/$L14,""))
A15: =IF(COUNTA($B15:$K15)=0,"",ROW()-1) | B15: Invoice | C15: 46234 | D15: Support | E15: =IF($B15="","",IF($B15="WIP","WIP",IFERROR(INDEX(Lists!$G$4:$G$10,MATCH($D15,Lists!$F$4:$F$10,0)),"Unmapped"))) | G15: PWC | H15: 20250731 | I15: PWC Pool of Hours (50 hours) | J15: INV-10539 | K15: 4250 | L15: =IF($K15="","",IF($E15="Production",$K15-N($AD15),$K15)) | M15: =IF($E15="Production",IF($K15="","",$K15-(N($AF15)+N($AG15))),IF($E15="Consulting",IF($K15="","",$K15-(N($AL15)+N($AM15)+N($AN15))),"")) | N15: =IFERROR($M15/$K15,"") | O15: =IF(COUNTA($B15:$K15)=0,"",IF($C15="","No date",IF(AND($C15>=Lists!$B$3,$C15<Lists!$B$4),"In FY27","Outside FY27"))) | P15: =IF($E15<>"WIP","",IF($H15="","",IF(COUNTIFS($E$2:$E$20000,"<>WIP",$H$2:$H$20000,$H15)>0,"Job already invoiced",""))) | Q15: PO2601703215 | AE15: =IF($E15<>"Production","",IFERROR($AD15/$L15,""))
A16: =IF(COUNTA($B16:$K16)=0,"",ROW()-1) | B16: Invoice | C16: 46234 | D16: Support | E16: =IF($B16="","",IF($B16="WIP","WIP",IFERROR(INDEX(Lists!$G$4:$G$10,MATCH($D16,Lists!$F$4:$F$10,0)),"Unmapped"))) | G16: CBA | H16: 1668 | I16: AH Support 02/07/2026 | J16: INV-10542 | K16: 180 | L16: =IF($K16="","",IF($E16="Production",$K16-N($AD16),$K16)) | M16: =IF($E16="Production",IF($K16="","",$K16-(N($AF16)+N($AG16))),IF($E16="Consulting",IF($K16="","",$K16-(N($AL16)+N($AM16)+N($AN16))),"")) | N16: =IFERROR($M16/$K16,"") | O16: =IF(COUNTA($B16:$K16)=0,"",IF($C16="","No date",IF(AND($C16>=Lists!$B$3,$C16<Lists!$B$4),"In FY27","Outside FY27"))) | P16: =IF($E16<>"WIP","",IF($H16="","",IF(COUNTIFS($E$2:$E$20000,"<>WIP",$H$2:$H$20000,$H16)>0,"Job already invoiced",""))) | AE16: =IF($E16<>"Production","",IFERROR($AD16/$L16,""))
A17: =IF(COUNTA($B17:$K17)=0,"",ROW()-1) | B17: Invoice | C17: 46234 | D17: Support | E17: =IF($B17="","",IF($B17="WIP","WIP",IFERROR(INDEX(Lists!$G$4:$G$10,MATCH($D17,Lists!$F$4:$F$10,0)),"Unmapped"))) | G17: CBA | H17: 1668 | I17: DT Support 02/07/2026 | J17: INV-10543 | K17: 425 | L17: =IF($K17="","",IF($E17="Production",$K17-N($AD17),$K17)) | M17: =IF($E17="Production",IF($K17="","",$K17-(N($AF17)+N($AG17))),IF($E17="Consulting",IF($K17="","",$K17-(N($AL17)+N($AM17)+N($AN17))),"")) | N17: =IFERROR($M17/$K17,"") | O17: =IF(COUNTA($B17:$K17)=0,"",IF($C17="","No date",IF(AND($C17>=Lists!$B$3,$C17<Lists!$B$4),"In FY27","Outside FY27"))) | P17: =IF($E17<>"WIP","",IF($H17="","",IF(COUNTIFS($E$2:$E$20000,"<>WIP",$H$2:$H$20000,$H17)>0,"Job already invoiced",""))) | AE17: =IF($E17<>"Production","",IFERROR($AD17/$L17,""))
A18: =IF(COUNTA($B18:$K18)=0,"",ROW()-1) | B18: Invoice | C18: 46234 | D18: Support | E18: =IF($B18="","",IF($B18="WIP","WIP",IFERROR(INDEX(Lists!$G$4:$G$10,MATCH($D18,Lists!$F$4:$F$10,0)),"Unmapped"))) | G18: CBA | H18: 1668 | I18: DT Support 23/07/2026 | J18: INV-10544 | K18: 510 | L18: =IF($K18="","",IF($E18="Production",$K18-N($AD18),$K18)) | M18: =IF($E18="Production",IF($K18="","",$K18-(N($AF18)+N($AG18))),IF($E18="Consulting",IF($K18="","",$K18-(N($AL18)+N($AM18)+N($AN18))),"")) | N18: =IFERROR($M18/$K18,"") | O18: =IF(COUNTA($B18:$K18)=0,"",IF($C18="","No date",IF(AND($C18>=Lists!$B$3,$C18<Lists!$B$4),"In FY27","Outside FY27"))) | P18: =IF($E18<>"WIP","",IF($H18="","",IF(COUNTIFS($E$2:$E$20000,"<>WIP",$H$2:$H$20000,$H18)>0,"Job already invoiced",""))) | AE18: =IF($E18<>"Production","",IFERROR($AD18/$L18,""))
A19: =IF(COUNTA($B19:$K19)=0,"",ROW()-1) | B19: Invoice | C19: 46233 | D19: Support | E19: =IF($B19="","",IF($B19="WIP","WIP",IFERROR(INDEX(Lists!$G$4:$G$10,MATCH($D19,Lists!$F$4:$F$10,0)),"Unmapped"))) | G19: PWC | H19: 2540 | I19: PWC Dedicated Tech 30/07/2026 | J19: INV-10545 | K19: 340 | L19: =IF($K19="","",IF($E19="Production",$K19-N($AD19),$K19)) | M19: =IF($E19="Production",IF($K19="","",$K19-(N($AF19)+N($AG19))),IF($E19="Consulting",IF($K19="","",$K19-(N($AL19)+N($AM19)+N($AN19))),"")) | N19: =IFERROR($M19/$K19,"") | O19: =IF(COUNTA($B19:$K19)=0,"",IF($C19="","No date",IF(AND($C19>=Lists!$B$3,$C19<Lists!$B$4),"In FY27","Outside FY27"))) | P19: =IF($E19<>"WIP","",IF($H19="","",IF(COUNTIFS($E$2:$E$20000,"<>WIP",$H$2:$H$20000,$H19)>0,"Job already invoiced",""))) | Q19: PO2601703274 | AE19: =IF($E19<>"Production","",IFERROR($AD19/$L19,""))
A20: =IF(COUNTA($B20:$K20)=0,"",ROW()-1) | B20: Invoice | C20: 46233 | D20: Support | E20: =IF($B20="","",IF($B20="WIP","WIP",IFERROR(INDEX(Lists!$G$4:$G$10,MATCH($D20,Lists!$F$4:$F$10,0)),"Unmapped"))) | G20: DTTL | H20: 26062501/2347 | I20: DH Travel 06-07/07 & Ad-hoc Tech Support 30/07 & Market Shapers | J20: INV-10546 | K20: 1672.5 | L20: =IF($K20="","",IF($E20="Production",$K20-N($AD20),$K20)) | M20: =IF($E20="Production",IF($K20="","",$K20-(N($AF20)+N($AG20))),IF($E20="Consulting",IF($K20="","",$K20-(N($AL20)+N($AM20)+N($AN20))),"")) | N20: =IFERROR($M20/$K20,"") | O20: =IF(COUNTA($B20:$K20)=0,"",IF($C20="","No date",IF(AND($C20>=Lists!$B$3,$C20<Lists!$B$4),"In FY27","Outside FY27"))) | P20: =IF($E20<>"WIP","",IF($H20="","",IF(COUNTIFS($E$2:$E$20000,"<>WIP",$H$2:$H$20000,$H20)>0,"Job already invoiced",""))) | AE20: =IF($E20<>"Production","",IFERROR($AD20/$L20,""))
A21: =IF(COUNTA($B21:$K21)=0,"",ROW()-1) | B21: Invoice | C21: 46233 | D21: Support | E21: =IF($B21="","",IF($B21="WIP","WIP",IFERROR(INDEX(Lists!$G$4:$G$10,MATCH($D21,Lists!$F$4:$F$10,0)),"Unmapped"))) | G21: APN | H21: 2026021101 | I21: APN Quarterly AV Support | J21: INV-10550 | K21: 1670 | L21: =IF($K21="","",IF($E21="Production",$K21-N($AD21),$K21)) | M21: =IF($E21="Production",IF($K21="","",$K21-(N($AF21)+N($AG21))),IF($E21="Consulting",IF($K21="","",$K21-(N($AL21)+N($AM21)+N($AN21))),"")) | N21: =IFERROR($M21/$K21,"") | O21: =IF(COUNTA($B21:$K21)=0,"",IF($C21="","No date",IF(AND($C21>=Lists!$B$3,$C21<Lists!$B$4),"In FY27","Outside FY27"))) | P21: =IF($E21<>"WIP","",IF($H21="","",IF(COUNTIFS($E$2:$E$20000,"<>WIP",$H$2:$H$20000,$H21)>0,"Job already invoiced",""))) | Q21: Invoice 1/2 | AE21: =IF($E21<>"Production","",IFERROR($AD21/$L21,""))
A22: =IF(COUNTA($B22:$K22)=0,"",ROW()-1) | B22: Invoice | C22: 46234 | D22: Support | E22: =IF($B22="","",IF($B22="WIP","WIP",IFERROR(INDEX(Lists!$G$4:$G$10,MATCH($D22,Lists!$F$4:$F$10,0)),"Unmapped"))) | G22: Aware Super | H22: 26022301 | I22: Aware Super Contract July 2026 | J22: INV-10551 | K22: 11000 | L22: =IF($K22="","",IF($E22="Production",$K22-N($AD22),$K22)) | M22: =IF($E22="Production",IF($K22="","",$K22-(N($AF22)+N($AG22))),IF($E22="Consulting",IF($K22="","",$K22-(N($AL22)+N($AM22)+N($AN22))),"")) | N22: =IFERROR($M22/$K22,"") | O22: =IF(COUNTA($B22:$K22)=0,"",IF($C22="","No date",IF(AND($C22>=Lists!$B$3,$C22<Lists!$B$4),"In FY27","Outside FY27"))) | P22: =IF($E22<>"WIP","",IF($H22="","",IF(COUNTIFS($E$2:$E$20000,"<>WIP",$H$2:$H$20000,$H22)>0,"Job already invoiced",""))) | AE22: =IF($E22<>"Production","",IFERROR($AD22/$L22,""))
A23: =IF(COUNTA($B23:$K23)=0,"",ROW()-1) | B23: Invoice | C23: 46265 | D23: Support | E23: =IF($B23="","",IF($B23="WIP","WIP",IFERROR(INDEX(Lists!$G$4:$G$10,MATCH($D23,Lists!$F$4:$F$10,0)),"Unmapped"))) | G23: DTTL | H23: 2608502 | I23: DTTL Additionals August 2026 | J23: INV-10597 | K23: 8419.62 | L23: =IF($K23="","",IF($E23="Production",$K23-N($AD23),$K23)) | M23: =IF($E23="Production",IF($K23="","",$K23-(N($AF23)+N($AG23))),IF($E23="Consulting",IF($K23="","",$K23-(N($AL23)+N($AM23)+N($AN23))),"")) | N23: =IFERROR($M23/$K23,"") | O23: =IF(COUNTA($B23:$K23)=0,"",IF($C23="","No date",IF(AND($C23>=Lists!$B$3,$C23<Lists!$B$4),"In FY27","Outside FY27"))) | P23: =IF($E23<>"WIP","",IF($H23="","",IF(COUNTIFS($E$2:$E$20000,"<>WIP",$H$2:$H$20000,$H23)>0,"Job already invoiced",""))) | AE23: =IF($E23<>"Production","",IFERROR($AD23/$L23,""))
A24: =IF(COUNTA($B24:$K24)=0,"",ROW()-1) | B24: Invoice | D24: Support | E24: =IF($B24="","",IF($B24="WIP","WIP",IFERROR(INDEX(Lists!$G$4:$G$10,MATCH($D24,Lists!$F$4:$F$10,0)),"Unmapped"))) | G24: PWC | H24: 26073102 | I24: Pool of Hours - National AV/IT Support | J24: INV-10598 | K24: 8500 | L24: =IF($K24="","",IF($E24="Production",$K24-N($AD24),$K24)) | M24: =IF($E24="Production",IF($K24="","",$K24-(N($AF24)+N($AG24))),IF($E24="Consulting",IF($K24="","",$K24-(N($AL24)+N($AM24)+N($AN24))),"")) | N24: =IFERROR($M24/$K24,"") | O24: =IF(COUNTA($B24:$K24)=0,"",IF($C24="","No date",IF(AND($C24>=Lists!$B$3,$C24<Lists!$B$4),"In FY27","Outside FY27"))) | P24: =IF($E24<>"WIP","",IF($H24="","",IF(COUNTIFS($E$2:$E$20000,"<>WIP",$H$2:$H$20000,$H24)>0,"Job already invoiced",""))) | Q24: PO2601703509 | AE24: =IF($E24<>"Production","",IFERROR($AD24/$L24,""))
A25: =IF(COUNTA($B25:$K25)=0,"",ROW()-1) | B25: Invoice | D25: Support | E25: =IF($B25="","",IF($B25="WIP","WIP",IFERROR(INDEX(Lists!$G$4:$G$10,MATCH($D25,Lists!$F$4:$F$10,0)),"Unmapped"))) | G25: CBA | H25: 1350 | I25: CBA BNE August 2026 | J25: INV-10565 | K25: 5940 | L25: =IF($K25="","",IF($E25="Production",$K25-N($AD25),$K25)) | M25: =IF($E25="Production",IF($K25="","",$K25-(N($AF25)+N($AG25))),IF($E25="Consulting",IF($K25="","",$K25-(N($AL25)+N($AM25)+N($AN25))),"")) | N25: =IFERROR($M25/$K25,"") | O25: =IF(COUNTA($B25:$K25)=0,"",IF($C25="","No date",IF(AND($C25>=Lists!$B$3,$C25<Lists!$B$4),"In FY27","Outside FY27"))) | P25: =IF($E25<>"WIP","",IF($H25="","",IF(COUNTIFS($E$2:$E$20000,"<>WIP",$H$2:$H$20000,$H25)>0,"Job already invoiced",""))) | AE25: =IF($E25<>"Production","",IFERROR($AD25/$L25,""))
A26: =IF(COUNTA($B26:$K26)=0,"",ROW()-1) | B26: Invoice | D26: Support | E26: =IF($B26="","",IF($B26="WIP","WIP",IFERROR(INDEX(Lists!$G$4:$G$10,MATCH($D26,Lists!$F$4:$F$10,0)),"Unmapped"))) | G26: CBA | H26: 585/586/1755 | I26: CBP August 2026 | J26: INV-10566 | K26: 22708 | L26: =IF($K26="","",IF($E26="Production",$K26-N($AD26),$K26)) | M26: =IF($E26="Production",IF($K26="","",$K26-(N($AF26)+N($AG26))),IF($E26="Consulting",IF($K26="","",$K26-(N($AL26)+N($AM26)+N($AN26))),"")) | N26: =IFERROR($M26/$K26,"") | O26: =IF(COUNTA($B26:$K26)=0,"",IF($C26="","No date",IF(AND($C26>=Lists!$B$3,$C26<Lists!$B$4),"In FY27","Outside FY27"))) | P26: =IF($E26<>"WIP","",IF($H26="","",IF(COUNTIFS($E$2:$E$20000,"<>WIP",$H$2:$H$20000,$H26)>0,"Job already invoiced",""))) | AE26: =IF($E26<>"Production","",IFERROR($AD26/$L26,""))
A27: =IF(COUNTA($B27:$K27)=0,"",ROW()-1) | B27: Invoice | D27: Support | E27: =IF($B27="","",IF($B27="WIP","WIP",IFERROR(INDEX(Lists!$G$4:$G$10,MATCH($D27,Lists!$F$4:$F$10,0)),"Unmapped"))) | G27: CBA | H27: 587 | I27: CBS August 2026 | J27: INV-10568 | K27: 10720 | L27: =IF($K27="","",IF($E27="Production",$K27-N($AD27),$K27)) | M27: =IF($E27="Production",IF($K27="","",$K27-(N($AF27)+N($AG27))),IF($E27="Consulting",IF($K27="","",$K27-(N($AL27)+N($AM27)+N($AN27))),"")) | N27: =IFERROR($M27/$K27,"") | O27: =IF(COUNTA($B27:$K27)=0,"",IF($C27="","No date",IF(AND($C27>=Lists!$B$3,$C27<Lists!$B$4),"In FY27","Outside FY27"))) | P27: =IF($E27<>"WIP","",IF($H27="","",IF(COUNTIFS($E$2:$E$20000,"<>WIP",$H$2:$H$20000,$H27)>0,"Job already invoiced",""))) | AE27: =IF($E27<>"Production","",IFERROR($AD27/$L27,""))
A28: =IF(COUNTA($B28:$K28)=0,"",ROW()-1) | B28: Invoice | C28: 46265 | D28: Support | E28: =IF($B28="","",IF($B28="WIP","WIP",IFERROR(INDEX(Lists!$G$4:$G$10,MATCH($D28,Lists!$F$4:$F$10,0)),"Unmapped"))) | G28: DTTL | H28: 2846/1401/725/1400/1530/1862/2402/2849/974 | I28: DTTL Contract August 2026 | J28: INV-10569 | K28: 103625.44 | L28: =IF($K28="","",IF($E28="Production",$K28-N($AD28),$K28)) | M28: =IF($E28="Production",IF($K28="","",$K28-(N($AF28)+N($AG28))),IF($E28="Consulting",IF($K28="","",$K28-(N($AL28)+N($AM28)+N($AN28))),"")) | N28: =IFERROR($M28/$K28,"") | O28: =IF(COUNTA($B28:$K28)=0,"",IF($C28="","No date",IF(AND($C28>=Lists!$B$3,$C28<Lists!$B$4),"In FY27","Outside FY27"))) | P28: =IF($E28<>"WIP","",IF($H28="","",IF(COUNTIFS($E$2:$E$20000,"<>WIP",$H$2:$H$20000,$H28)>0,"Job already invoiced",""))) | AE28: =IF($E28<>"Production","",IFERROR($AD28/$L28,""))
A29: =IF(COUNTA($B29:$K29)=0,"",ROW()-1) | B29: Invoice | D29: Support | E29: =IF($B29="","",IF($B29="WIP","WIP",IFERROR(INDEX(Lists!$G$4:$G$10,MATCH($D29,Lists!$F$4:$F$10,0)),"Unmapped"))) | G29: BW | H29: 732/1144 | I29: BW Contract August 2026 | J29: INV-10570 | K29: 15113.75 | L29: =IF($K29="","",IF($E29="Production",$K29-N($AD29),$K29)) | M29: =IF($E29="Production",IF($K29="","",$K29-(N($AF29)+N($AG29))),IF($E29="Consulting",IF($K29="","",$K29-(N($AL29)+N($AM29)+N($AN29))),"")) | N29: =IFERROR($M29/$K29,"") | O29: =IF(COUNTA($B29:$K29)=0,"",IF($C29="","No date",IF(AND($C29>=Lists!$B$3,$C29<Lists!$B$4),"In FY27","Outside FY27"))) | P29: =IF($E29<>"WIP","",IF($H29="","",IF(COUNTIFS($E$2:$E$20000,"<>WIP",$H$2:$H$20000,$H29)>0,"Job already invoiced",""))) | AE29: =IF($E29<>"Production","",IFERROR($AD29/$L29,""))
A30: =IF(COUNTA($B30:$K30)=0,"",ROW()-1) | B30: Invoice | D30: Support | E30: =IF($B30="","",IF($B30="WIP","WIP",IFERROR(INDEX(Lists!$G$4:$G$10,MATCH($D30,Lists!$F$4:$F$10,0)),"Unmapped"))) | G30: BW | H30: 2192 | I30: BW Additionals August 2026 | J30: INV-10571 | K30: 2080 | L30: =IF($K30="","",IF($E30="Production",$K30-N($AD30),$K30)) | M30: =IF($E30="Production",IF($K30="","",$K30-(N($AF30)+N($AG30))),IF($E30="Consulting",IF($K30="","",$K30-(N($AL30)+N($AM30)+N($AN30))),"")) | N30: =IFERROR($M30/$K30,"") | O30: =IF(COUNTA($B30:$K30)=0,"",IF($C30="","No date",IF(AND($C30>=Lists!$B$3,$C30<Lists!$B$4),"In FY27","Outside FY27"))) | P30: =IF($E30<>"WIP","",IF($H30="","",IF(COUNTIFS($E$2:$E$20000,"<>WIP",$H$2:$H$20000,$H30)>0,"Job already invoiced",""))) | AE30: =IF($E30<>"Production","",IFERROR($AD30/$L30,""))
A31: =IF(COUNTA($B31:$K31)=0,"",ROW()-1) | B31: Invoice | D31: Support | E31: =IF($B31="","",IF($B31="WIP","WIP",IFERROR(INDEX(Lists!$G$4:$G$10,MATCH($D31,Lists!$F$4:$F$10,0)),"Unmapped"))) | G31: PWC | H31: 2488 | I31: PWC Brisbane August 2026 | J31: INV-10572 | K31: 7150 | L31: =IF($K31="","",IF($E31="Production",$K31-N($AD31),$K31)) | M31: =IF($E31="Production",IF($K31="","",$K31-(N($AF31)+N($AG31))),IF($E31="Consulting",IF($K31="","",$K31-(N($AL31)+N($AM31)+N($AN31))),"")) | N31: =IFERROR($M31/$K31,"") | O31: =IF(COUNTA($B31:$K31)=0,"",IF($C31="","No date",IF(AND($C31>=Lists!$B$3,$C31<Lists!$B$4),"In FY27","Outside FY27"))) | P31: =IF($E31<>"WIP","",IF($H31="","",IF(COUNTIFS($E$2:$E$20000,"<>WIP",$H$2:$H$20000,$H31)>0,"Job already invoiced",""))) | AE31: =IF($E31<>"Production","",IFERROR($AD31/$L31,""))
A32: =IF(COUNTA($B32:$K32)=0,"",ROW()-1) | B32: Invoice | D32: Support | E32: =IF($B32="","",IF($B32="WIP","WIP",IFERROR(INDEX(Lists!$G$4:$G$10,MATCH($D32,Lists!$F$4:$F$10,0)),"Unmapped"))) | G32: Gen-E | H32: 26021602 | I32: Gen-E ABS August 2026 | J32: INV-10573 | K32: 12388.8 | L32: =IF($K32="","",IF($E32="Production",$K32-N($AD32),$K32)) | M32: =IF($E32="Production",IF($K32="","",$K32-(N($AF32)+N($AG32))),IF($E32="Consulting",IF($K32="","",$K32-(N($AL32)+N($AM32)+N($AN32))),"")) | N32: =IFERROR($M32/$K32,"") | O32: =IF(COUNTA($B32:$K32)=0,"",IF($C32="","No date",IF(AND($C32>=Lists!$B$3,$C32<Lists!$B$4),"In FY27","Outside FY27"))) | P32: =IF($E32<>"WIP","",IF($H32="","",IF(COUNTIFS($E$2:$E$20000,"<>WIP",$H$2:$H$20000,$H32)>0,"Job already invoiced",""))) | AE32: =IF($E32<>"Production","",IFERROR($AD32/$L32,""))
A33: =IF(COUNTA($B33:$K33)=0,"",ROW()-1) | B33: Invoice | D33: Support | E33: =IF($B33="","",IF($B33="WIP","WIP",IFERROR(INDEX(Lists!$G$4:$G$10,MATCH($D33,Lists!$F$4:$F$10,0)),"Unmapped"))) | G33: CBA | H33: 26043001 | I33: CBA Mel August 2026 | J33: INV-10582 | K33: 11377.12 | L33: =IF($K33="","",IF($E33="Production",$K33-N($AD33),$K33)) | M33: =IF($E33="Production",IF($K33="","",$K33-(N($AF33)+N($AG33))),IF($E33="Consulting",IF($K33="","",$K33-(N($AL33)+N($AM33)+N($AN33))),"")) | N33: =IFERROR($M33/$K33,"") | O33: =IF(COUNTA($B33:$K33)=0,"",IF($C33="","No date",IF(AND($C33>=Lists!$B$3,$C33<Lists!$B$4),"In FY27","Outside FY27"))) | P33: =IF($E33<>"WIP","",IF($H33="","",IF(COUNTIFS($E$2:$E$20000,"<>WIP",$H$2:$H$20000,$H33)>0,"Job already invoiced",""))) | AE33: =IF($E33<>"Production","",IFERROR($AD33/$L33,""))
A34: =IF(COUNTA($B34:$K34)=0,"",ROW()-1) | B34: Invoice | C34: 46265 | D34: Support | E34: =IF($B34="","",IF($B34="WIP","WIP",IFERROR(INDEX(Lists!$G$4:$G$10,MATCH($D34,Lists!$F$4:$F$10,0)),"Unmapped"))) | G34: Aware Super | H34: 26022301 | I34: Aware Super Contract August 2026 | J34: INV-10583 | K34: 11000 | L34: =IF($K34="","",IF($E34="Production",$K34-N($AD34),$K34)) | M34: =IF($E34="Production",IF($K34="","",$K34-(N($AF34)+N($AG34))),IF($E34="Consulting",IF($K34="","",$K34-(N($AL34)+N($AM34)+N($AN34))),"")) | N34: =IFERROR($M34/$K34,"") | O34: =IF(COUNTA($B34:$K34)=0,"",IF($C34="","No date",IF(AND($C34>=Lists!$B$3,$C34<Lists!$B$4),"In FY27","Outside FY27"))) | P34: =IF($E34<>"WIP","",IF($H34="","",IF(COUNTIFS($E$2:$E$20000,"<>WIP",$H$2:$H$20000,$H34)>0,"Job already invoiced",""))) | Q34: Split TBC | AE34: =IF($E34<>"Production","",IFERROR($AD34/$L34,""))
A35: =IF(COUNTA($B35:$K35)=0,"",ROW()-1) | B35: Invoice | D35: Support | E35: =IF($B35="","",IF($B35="WIP","WIP",IFERROR(INDEX(Lists!$G$4:$G$10,MATCH($D35,Lists!$F$4:$F$10,0)),"Unmapped"))) | G35: PWC | H35: 25101301B | I35: PWC Sydney IT August 2026 | J35: INV-10585 | K35: 11907 | L35: =IF($K35="","",IF($E35="Production",$K35-N($AD35),$K35)) | M35: =IF($E35="Production",IF($K35="","",$K35-(N($AF35)+N($AG35))),IF($E35="Consulting",IF($K35="","",$K35-(N($AL35)+N($AM35)+N($AN35))),"")) | N35: =IFERROR($M35/$K35,"") | O35: =IF(COUNTA($B35:$K35)=0,"",IF($C35="","No date",IF(AND($C35>=Lists!$B$3,$C35<Lists!$B$4),"In FY27","Outside FY27"))) | P35: =IF($E35<>"WIP","",IF($H35="","",IF(COUNTIFS($E$2:$E$20000,"<>WIP",$H$2:$H$20000,$H35)>0,"Job already invoiced",""))) | AE35: =IF($E35<>"Production","",IFERROR($AD35/$L35,""))
A36: =IF(COUNTA($B36:$K36)=0,"",ROW()-1) | B36: Invoice | D36: Support | E36: =IF($B36="","",IF($B36="WIP","WIP",IFERROR(INDEX(Lists!$G$4:$G$10,MATCH($D36,Lists!$F$4:$F$10,0)),"Unmapped"))) | G36: TWG | H36: 26081301 | I36: EY Support Technician BNE | K36: 3740 | L36: =IF($K36="","",IF($E36="Production",$K36-N($AD36),$K36)) | M36: =IF($E36="Production",IF($K36="","",$K36-(N($AF36)+N($AG36))),IF($E36="Consulting",IF($K36="","",$K36-(N($AL36)+N($AM36)+N($AN36))),"")) | N36: =IFERROR($M36/$K36,"") | O36: =IF(COUNTA($B36:$K36)=0,"",IF($C36="","No date",IF(AND($C36>=Lists!$B$3,$C36<Lists!$B$4),"In FY27","Outside FY27"))) | P36: =IF($E36<>"WIP","",IF($H36="","",IF(COUNTIFS($E$2:$E$20000,"<>WIP",$H$2:$H$20000,$H36)>0,"Job already invoiced",""))) | Q36: November | AE36: =IF($E36<>"Production","",IFERROR($AD36/$L36,""))
A37: =IF(COUNTA($B37:$K37)=0,"",ROW()-1) | B37: Invoice | C37: 46205 | D37: Production | E37: =IF($B37="","",IF($B37="WIP","WIP",IFERROR(INDEX(Lists!$G$4:$G$10,MATCH($D37,Lists!$F$4:$F$10,0)),"Unmapped"))) | G37: Elkiem | H37: 2602309 | I37: Studio Support | 1.7.26 | J37: INV-10513 | K37: 380 | L37: =IF($K37="","",IF($E37="Production",$K37-N($AD37),$K37)) | M37: =IF($E37="Production",IF($K37="","",$K37-(N($AF37)+N($AG37))),IF($E37="Consulting",IF($K37="","",$K37-(N($AL37)+N($AM37)+N($AN37))),"")) | N37: =IFERROR($M37/$K37,"") | O37: =IF(COUNTA($B37:$K37)=0,"",IF($C37="","No date",IF(AND($C37>=Lists!$B$3,$C37<Lists!$B$4),"In FY27","Outside FY27"))) | P37: =IF($E37<>"WIP","",IF($H37="","",IF(COUNTIFS($E$2:$E$20000,"<>WIP",$H$2:$H$20000,$H37)>0,"Job already invoiced",""))) | R37: Ben.woodlock@elkiem.com | S37: 7/1/2026 | T37: 2602309 | U37: 5879 | V37: Y | W37: Y | AB37: 4 | AE37: =IF($E37<>"Production","",IFERROR($AD37/$L37,""))
A38: =IF(COUNTA($B38:$K38)=0,"",ROW()-1) | B38: Invoice | C38: 46210 | D38: Production | E38: =IF($B38="","",IF($B38="WIP","WIP",IFERROR(INDEX(Lists!$G$4:$G$10,MATCH($D38,Lists!$F$4:$F$10,0)),"Unmapped"))) | G38: RSNSW | H38: 26032301 | I38: Ordinary General Meeting | 1.7.26 | J38: INV-10519 | K38: 3071 | L38: =IF($K38="","",IF($E38="Production",$K38-N($AD38),$K38)) | M38: =IF($E38="Production",IF($K38="","",$K38-(N($AF38)+N($AG38))),IF($E38="Consulting",IF($K38="","",$K38-(N($AL38)+N($AM38)+N($AN38))),"")) | N38: =IFERROR($M38/$K38,"") | O38: =IF(COUNTA($B38:$K38)=0,"",IF($C38="","No date",IF(AND($C38>=Lists!$B$3,$C38<Lists!$B$4),"In FY27","Outside FY27"))) | P38: =IF($E38<>"WIP","",IF($H38="","",IF(COUNTIFS($E$2:$E$20000,"<>WIP",$H$2:$H$20000,$H38)>0,"Job already invoiced",""))) | R38: lindsay.botten@outlook.com | S38: 7/1/2026 | T38: 26032301 | U38: 5924 | V38: Y | W38: Y | X38: 4 | AB38: 10 | AC38: 1029 | AD38: 334 | AE38: =IF($E38<>"Production","",IFERROR($AD38/$L38,""))
A39: =IF(COUNTA($B39:$K39)=0,"",ROW()-1) | B39: Invoice | C39: 46210 | D39: Production | E39: =IF($B39="","",IF($B39="WIP","WIP",IFERROR(INDEX(Lists!$G$4:$G$10,MATCH($D39,Lists!$F$4:$F$10,0)),"Unmapped"))) | G39: PWC | H39: 26062201 | I39: Tax and Legal Webcast 2.7.26 | J39: INV-10515 | K39: 1925 | L39: =IF($K39="","",IF($E39="Production",$K39-N($AD39),$K39)) | M39: =IF($E39="Production",IF($K39="","",$K39-(N($AF39)+N($AG39))),IF($E39="Consulting",IF($K39="","",$K39-(N($AL39)+N($AM39)+N($AN39))),"")) | N39: =IFERROR($M39/$K39,"") | O39: =IF(COUNTA($B39:$K39)=0,"",IF($C39="","No date",IF(AND($C39>=Lists!$B$3,$C39<Lists!$B$4),"In FY27","Outside FY27"))) | P39: =IF($E39<>"WIP","",IF($H39="","",IF(COUNTIFS($E$2:$E$20000,"<>WIP",$H$2:$H$20000,$H39)>0,"Job already invoiced",""))) | R39: libby.kovac@au.pwc.com | S39: 7/2/2026 | T39: 26062201 | U39: 6076 | V39: Y | W39: Y | X39: 8 | Z39: 1 | AB39: 8 | AC39: 970 | AE39: =IF($E39<>"Production","",IFERROR($AD39/$L39,""))
A40: =IF(COUNTA($B40:$K40)=0,"",ROW()-1) | B40: Invoice | C40: 46219 | D40: Production | E40: =IF($B40="","",IF($B40="WIP","WIP",IFERROR(INDEX(Lists!$G$4:$G$10,MATCH($D40,Lists!$F$4:$F$10,0)),"Unmapped"))) | G40: Elkiem - PM** Cancelled | H40: 2605802 | I40: Elkiem Studio Support | 15.7.26 | J40: INV-10524 | K40: 261.25 | L40: =IF($K40="","",IF($E40="Production",$K40-N($AD40),$K40)) | M40: =IF($E40="Production",IF($K40="","",$K40-(N($AF40)+N($AG40))),IF($E40="Consulting",IF($K40="","",$K40-(N($AL40)+N($AM40)+N($AN40))),"")) | N40: =IFERROR($M40/$K40,"") | O40: =IF(COUNTA($B40:$K40)=0,"",IF($C40="","No date",IF(AND($C40>=Lists!$B$3,$C40<Lists!$B$4),"In FY27","Outside FY27"))) | P40: =IF($E40<>"WIP","",IF($H40="","",IF(COUNTIFS($E$2:$E$20000,"<>WIP",$H$2:$H$20000,$H40)>0,"Job already invoiced",""))) | R40: Ben.woodlock@elkiem.com | S40: 7/15/2026 | T40: 2605802 | U40: 6013 | V40: Y | W40: Y | Z40: 2 | AB40: 4 | AE40: =IF($E40<>"Production","",IFERROR($AD40/$L40,""))
...

Sheet Dashboard
A1: FY 2026-27 — Monthly revenue by report line
A2: Month | B2: Support | C2: Production | D2: Consulting | E2: WIP | F2: Total Revenue | G2: P&L Total | H2: Variance
A3: 46204 | B3: =SUMIFS(Data!$L$2:$L$20000,Data!$E$2:$E$20000,B$2,Data!$C$2:$C$20000,">="&$A3,Data!$C$2:$C$20000,"<"&EDATE($A3,1)) | C3: =SUMIFS(Data!$L$2:$L$20000,Data!$E$2:$E$20000,C$2,Data!$C$2:$C$20000,">="&$A3,Data!$C$2:$C$20000,"<"&EDATE($A3,1)) | D3: =SUMIFS(Data!$L$2:$L$20000,Data!$E$2:$E$20000,D$2,Data!$C$2:$C$20000,">="&$A3,Data!$C$2:$C$20000,"<"&EDATE($A3,1)) | E3: =SUMIFS(Data!$L$2:$L$20000,Data!$E$2:$E$20000,E$2,Data!$C$2:$C$20000,">="&$A3,Data!$C$2:$C$20000,"<"&EDATE($A3,1)) | F3: =SUM($B3:$E3) | H3: =IF($G3="","",IF(ABS($F3-$G3)<0.99,"Reconciled",$F3-$G3))
A4: 46235 | B4: =SUMIFS(Data!$L$2:$L$20000,Data!$E$2:$E$20000,B$2,Data!$C$2:$C$20000,">="&$A4,Data!$C$2:$C$20000,"<"&EDATE($A4,1)) | C4: =SUMIFS(Data!$L$2:$L$20000,Data!$E$2:$E$20000,C$2,Data!$C$2:$C$20000,">="&$A4,Data!$C$2:$C$20000,"<"&EDATE($A4,1)) | D4: =SUMIFS(Data!$L$2:$L$20000,Data!$E$2:$E$20000,D$2,Data!$C$2:$C$20000,">="&$A4,Data!$C$2:$C$20000,"<"&EDATE($A4,1)) | E4: =SUMIFS(Data!$L$2:$L$20000,Data!$E$2:$E$20000,E$2,Data!$C$2:$C$20000,">="&$A4,Data!$C$2:$C$20000,"<"&EDATE($A4,1)) | F4: =SUM($B4:$E4) | H4: =IF($G4="","",IF(ABS($F4-$G4)<0.99,"Reconciled",$F4-$G4))
A5: 46266 | B5: =SUMIFS(Data!$L$2:$L$20000,Data!$E$2:$E$20000,B$2,Data!$C$2:$C$20000,">="&$A5,Data!$C$2:$C$20000,"<"&EDATE($A5,1)) | C5: =SUMIFS(Data!$L$2:$L$20000,Data!$E$2:$E$20000,C$2,Data!$C$2:$C$20000,">="&$A5,Data!$C$2:$C$20000,"<"&EDATE($A5,1)) | D5: =SUMIFS(Data!$L$2:$L$20000,Data!$E$2:$E$20000,D$2,Data!$C$2:$C$20000,">="&$A5,Data!$C$2:$C$20000,"<"&EDATE($A5,1)) | E5: =SUMIFS(Data!$L$2:$L$20000,Data!$E$2:$E$20000,E$2,Data!$C$2:$C$20000,">="&$A5,Data!$C$2:$C$20000,"<"&EDATE($A5,1)) | F5: =SUM($B5:$E5) | H5: =IF($G5="","",IF(ABS($F5-$G5)<0.99,"Reconciled",$F5-$G5))
A6: 46296 | B6: =SUMIFS(Data!$L$2:$L$20000,Data!$E$2:$E$20000,B$2,Data!$C$2:$C$20000,">="&$A6,Data!$C$2:$C$20000,"<"&EDATE($A6,1)) | C6: =SUMIFS(Data!$L$2:$L$20000,Data!$E$2:$E$20000,C$2,Data!$C$2:$C$20000,">="&$A6,Data!$C$2:$C$20000,"<"&EDATE($A6,1)) | D6: =SUMIFS(Data!$L$2:$L$20000,Data!$E$2:$E$20000,D$2,Data!$C$2:$C$20000,">="&$A6,Data!$C$2:$C$20000,"<"&EDATE($A6,1)) | E6: =SUMIFS(Data!$L$2:$L$20000,Data!$E$2:$E$20000,E$2,Data!$C$2:$C$20000,">="&$A6,Data!$C$2:$C$20000,"<"&EDATE($A6,1)) | F6: =SUM($B6:$E6) | H6: =IF($G6="","",IF(ABS($F6-$G6)<0.99,"Reconciled",$F6-$G6))
A7: 46327 | B7: =SUMIFS(Data!$L$2:$L$20000,Data!$E$2:$E$20000,B$2,Data!$C$2:$C$20000,">="&$A7,Data!$C$2:$C$20000,"<"&EDATE($A7,1)) | C7: =SUMIFS(Data!$L$2:$L$20000,Data!$E$2:$E$20000,C$2,Data!$C$2:$C$20000,">="&$A7,Data!$C$2:$C$20000,"<"&EDATE($A7,1)) | D7: =SUMIFS(Data!$L$2:$L$20000,Data!$E$2:$E$20000,D$2,Data!$C$2:$C$20000,">="&$A7,Data!$C$2:$C$20000,"<"&EDATE($A7,1)) | E7: =SUMIFS(Data!$L$2:$L$20000,Data!$E$2:$E$20000,E$2,Data!$C$2:$C$20000,">="&$A7,Data!$C$2:$C$20000,"<"&EDATE($A7,1)) | F7: =SUM($B7:$E7) | H7: =IF($G7="","",IF(ABS($F7-$G7)<0.99,"Reconciled",$F7-$G7))
A8: 46357 | B8: =SUMIFS(Data!$L$2:$L$20000,Data!$E$2:$E$20000,B$2,Data!$C$2:$C$20000,">="&$A8,Data!$C$2:$C$20000,"<"&EDATE($A8,1)) | C8: =SUMIFS(Data!$L$2:$L$20000,Data!$E$2:$E$20000,C$2,Data!$C$2:$C$20000,">="&$A8,Data!$C$2:$C$20000,"<"&EDATE($A8,1)) | D8: =SUMIFS(Data!$L$2:$L$20000,Data!$E$2:$E$20000,D$2,Data!$C$2:$C$20000,">="&$A8,Data!$C$2:$C$20000,"<"&EDATE($A8,1)) | E8: =SUMIFS(Data!$L$2:$L$20000,Data!$E$2:$E$20000,E$2,Data!$C$2:$C$20000,">="&$A8,Data!$C$2:$C$20000,"<"&EDATE($A8,1)) | F8: =SUM($B8:$E8) | H8: =IF($G8="","",IF(ABS($F8-$G8)<0.99,"Reconciled",$F8-$G8))
A9: 46388 | B9: =SUMIFS(Data!$L$2:$L$20000,Data!$E$2:$E$20000,B$2,Data!$C$2:$C$20000,">="&$A9,Data!$C$2:$C$20000,"<"&EDATE($A9,1)) | C9: =SUMIFS(Data!$L$2:$L$20000,Data!$E$2:$E$20000,C$2,Data!$C$2:$C$20000,">="&$A9,Data!$C$2:$C$20000,"<"&EDATE($A9,1)) | D9: =SUMIFS(Data!$L$2:$L$20000,Data!$E$2:$E$20000,D$2,Data!$C$2:$C$20000,">="&$A9,Data!$C$2:$C$20000,"<"&EDATE($A9,1)) | E9: =SUMIFS(Data!$L$2:$L$20000,Data!$E$2:$E$20000,E$2,Data!$C$2:$C$20000,">="&$A9,Data!$C$2:$C$20000,"<"&EDATE($A9,1)) | F9: =SUM($B9:$E9) | H9: =IF($G9="","",IF(ABS($F9-$G9)<0.99,"Reconciled",$F9-$G9))
A10: 46419 | B10: =SUMIFS(Data!$L$2:$L$20000,Data!$E$2:$E$20000,B$2,Data!$C$2:$C$20000,">="&$A10,Data!$C$2:$C$20000,"<"&EDATE($A10,1)) | C10: =SUMIFS(Data!$L$2:$L$20000,Data!$E$2:$E$20000,C$2,Data!$C$2:$C$20000,">="&$A10,Data!$C$2:$C$20000,"<"&EDATE($A10,1)) | D10: =SUMIFS(Data!$L$2:$L$20000,Data!$E$2:$E$20000,D$2,Data!$C$2:$C$20000,">="&$A10,Data!$C$2:$C$20000,"<"&EDATE($A10,1)) | E10: =SUMIFS(Data!$L$2:$L$20000,Data!$E$2:$E$20000,E$2,Data!$C$2:$C$20000,">="&$A10,Data!$C$2:$C$20000,"<"&EDATE($A10,1)) | F10: =SUM($B10:$E10) | H10: =IF($G10="","",IF(ABS($F10-$G10)<0.99,"Reconciled",$F10-$G10))
A11: 46447 | B11: =SUMIFS(Data!$L$2:$L$20000,Data!$E$2:$E$20000,B$2,Data!$C$2:$C$20000,">="&$A11,Data!$C$2:$C$20000,"<"&EDATE($A11,1)) | C11: =SUMIFS(Data!$L$2:$L$20000,Data!$E$2:$E$20000,C$2,Data!$C$2:$C$20000,">="&$A11,Data!$C$2:$C$20000,"<"&EDATE($A11,1)) | D11: =SUMIFS(Data!$L$2:$L$20000,Data!$E$2:$E$20000,D$2,Data!$C$2:$C$20000,">="&$A11,Data!$C$2:$C$20000,"<"&EDATE($A11,1)) | E11: =SUMIFS(Data!$L$2:$L$20000,Data!$E$2:$E$20000,E$2,Data!$C$2:$C$20000,">="&$A11,Data!$C$2:$C$20000,"<"&EDATE($A11,1)) | F11: =SUM($B11:$E11) | H11: =IF($G11="","",IF(ABS($F11-$G11)<0.99,"Reconciled",$F11-$G11))
A12: 46478 | B12: =SUMIFS(Data!$L$2:$L$20000,Data!$E$2:$E$20000,B$2,Data!$C$2:$C$20000,">="&$A12,Data!$C$2:$C$20000,"<"&EDATE($A12,1)) | C12: =SUMIFS(Data!$L$2:$L$20000,Data!$E$2:$E$20000,C$2,Data!$C$2:$C$20000,">="&$A12,Data!$C$2:$C$20000,"<"&EDATE($A12,1)) | D12: =SUMIFS(Data!$L$2:$L$20000,Data!$E$2:$E$20000,D$2,Data!$C$2:$C$20000,">="&$A12,Data!$C$2:$C$20000,"<"&EDATE($A12,1)) | E12: =SUMIFS(Data!$L$2:$L$20000,Data!$E$2:$E$20000,E$2,Data!$C$2:$C$20000,">="&$A12,Data!$C$2:$C$20000,"<"&EDATE($A12,1)) | F12: =SUM($B12:$E12) | H12: =IF($G12="","",IF(ABS($F12-$G12)<0.99,"Reconciled",$F12-$G12))
A13: 46508 | B13: =SUMIFS(Data!$L$2:$L$20000,Data!$E$2:$E$20000,B$2,Data!$C$2:$C$20000,">="&$A13,Data!$C$2:$C$20000,"<"&EDATE($A13,1)) | C13: =SUMIFS(Data!$L$2:$L$20000,Data!$E$2:$E$20000,C$2,Data!$C$2:$C$20000,">="&$A13,Data!$C$2:$C$20000,"<"&EDATE($A13,1)) | D13: =SUMIFS(Data!$L$2:$L$20000,Data!$E$2:$E$20000,D$2,Data!$C$2:$C$20000,">="&$A13,Data!$C$2:$C$20000,"<"&EDATE($A13,1)) | E13: =SUMIFS(Data!$L$2:$L$20000,Data!$E$2:$E$20000,E$2,Data!$C$2:$C$20000,">="&$A13,Data!$C$2:$C$20000,"<"&EDATE($A13,1)) | F13: =SUM($B13:$E13) | H13: =IF($G13="","",IF(ABS($F13-$G13)<0.99,"Reconciled",$F13-$G13))
A14: 46539 | B14: =SUMIFS(Data!$L$2:$L$20000,Data!$E$2:$E$20000,B$2,Data!$C$2:$C$20000,">="&$A14,Data!$C$2:$C$20000,"<"&EDATE($A14,1)) | C14: =SUMIFS(Data!$L$2:$L$20000,Data!$E$2:$E$20000,C$2,Data!$C$2:$C$20000,">="&$A14,Data!$C$2:$C$20000,"<"&EDATE($A14,1)) | D14: =SUMIFS(Data!$L$2:$L$20000,Data!$E$2:$E$20000,D$2,Data!$C$2:$C$20000,">="&$A14,Data!$C$2:$C$20000,"<"&EDATE($A14,1)) | E14: =SUMIFS(Data!$L$2:$L$20000,Data!$E$2:$E$20000,E$2,Data!$C$2:$C$20000,">="&$A14,Data!$C$2:$C$20000,"<"&EDATE($A14,1)) | F14: =SUM($B14:$E14) | H14: =IF($G14="","",IF(ABS($F14-$G14)<0.99,"Reconciled",$F14-$G14))
A15: Total | B15: =SUM(B3:B14) | C15: =SUM(C3:C14) | D15: =SUM(D3:D14) | E15: =SUM(E3:E14) | F15: =SUM(F3:F14) | G15: =SUM(G3:G14) | H15: =IF(COUNT($G$3:$G$14)=0,"",IF(ABS(SUMPRODUCT(($G$3:$G$14<>"")*$F$3:$F$14)-SUM($G$3:$G$14))<0.99,"Reconciled",SUMPRODUCT(($G$3:$G$14<>"")*$F$3:$F$14)-SUM($G$3:$G$14)))
A17: P&L Total (yellow) is the only figure you type here. Variance reads "Reconciled" under $0.99.
A18: The Total row measures only the months where a P&L Total has been entered, so a part-year shows no false gap.
A21: Reconciliation — is every record reaching the monthly view?
A22: Report line | B22: Total in tracker | C22: In FY27 months | D22: No date | E22: Dated outside FY27 | F22: Adds up?
A23: Support | B23: =SUMIF(Data!$E$2:$E$20000,$A23,Data!$L$2:$L$20000) | C23: =SUMIFS(Data!$L$2:$L$20000,Data!$E$2:$E$20000,$A23,Data!$O$2:$O$20000,"In FY27") | D23: =SUMIFS(Data!$L$2:$L$20000,Data!$E$2:$E$20000,$A23,Data!$O$2:$O$20000,"No date") | E23: =SUMIFS(Data!$L$2:$L$20000,Data!$E$2:$E$20000,$A23,Data!$O$2:$O$20000,"Outside FY27") | F23: =IF(ABS($B23-SUM($C23:$E23))<0.01,"OK","Check")
A24: Production | B24: =SUMIF(Data!$E$2:$E$20000,$A24,Data!$L$2:$L$20000) | C24: =SUMIFS(Data!$L$2:$L$20000,Data!$E$2:$E$20000,$A24,Data!$O$2:$O$20000,"In FY27") | D24: =SUMIFS(Data!$L$2:$L$20000,Data!$E$2:$E$20000,$A24,Data!$O$2:$O$20000,"No date") | E24: =SUMIFS(Data!$L$2:$L$20000,Data!$E$2:$E$20000,$A24,Data!$O$2:$O$20000,"Outside FY27") | F24: =IF(ABS($B24-SUM($C24:$E24))<0.01,"OK","Check")
A25: Consulting | B25: =SUMIF(Data!$E$2:$E$20000,$A25,Data!$L$2:$L$20000) | C25: =SUMIFS(Data!$L$2:$L$20000,Data!$E$2:$E$20000,$A25,Data!$O$2:$O$20000,"In FY27") | D25: =SUMIFS(Data!$L$2:$L$20000,Data!$E$2:$E$20000,$A25,Data!$O$2:$O$20000,"No date") | E25: =SUMIFS(Data!$L$2:$L$20000,Data!$E$2:$E$20000,$A25,Data!$O$2:$O$20000,"Outside FY27") | F25: =IF(ABS($B25-SUM($C25:$E25))<0.01,"OK","Check")
A26: WIP | B26: =SUMIF(Data!$E$2:$E$20000,$A26,Data!$L$2:$L$20000) | C26: =SUMIFS(Data!$L$2:$L$20000,Data!$E$2:$E$20000,$A26,Data!$O$2:$O$20000,"In FY27") | D26: =SUMIFS(Data!$L$2:$L$20000,Data!$E$2:$E$20000,$A26,Data!$O$2:$O$20000,"No date") | E26: =SUMIFS(Data!$L$2:$L$20000,Data!$E$2:$E$20000,$A26,Data!$O$2:$O$20000,"Outside FY27") | F26: =IF(ABS($B26-SUM($C26:$E26))<0.01,"OK","Check")
A27: Total | B27: =SUM(B23:B26) | C27: =SUM(C23:C26) | D27: =SUM(D23:D26) | E27: =SUM(E23:E26) | F27: =IF(ABS($C$27-$F$15)<0.01,"Matches monthly grid","Does not match monthly grid")
A29: "No date" and "Dated outside FY27" are different problems. A blank date needs filling in. A date outside FY27 is a real date from another financial year.

Sheet Checks
A1: Data quality checks
A2: Live formulas — they update the moment you change anything on the Data tab.
A4: # | B4: What is being checked | C4: Records | D4: Value | E4: Status | F4: What to do
A5: 1 | B5: Records with no date | C5: =COUNTIF(Data!$O$2:$O$20000,"No date") | D5: =SUMIF(Data!$O$2:$O$20000,"No date",Data!$L$2:$L$20000) | E5: =IF(AND(N($C5)=0,ROUND(N($D5),2)=0),"OK","Review") | F5: Filter Date Check to "No date" on the Data tab and fill them in. This money is in no month until you do.
A6: 2 | B6: Records dated outside FY 2026-27 | C6: =COUNTIF(Data!$O$2:$O$20000,"Outside FY27") | D6: =SUMIF(Data!$O$2:$O$20000,"Outside FY27",Data!$L$2:$L$20000) | E6: =IF(AND(N($C6)=0,ROUND(N($D6),2)=0),"OK","Review") | F6: Real dates from another financial year. Decide whether they belong in this tracker at all.
A7: 3 | B7: WIP jobs that have also been invoiced | C7: =COUNTIF(Data!$P$2:$P$20000,"Job already invoiced") | D7: =SUMIF(Data!$P$2:$P$20000,"Job already invoiced",Data!$L$2:$L$20000) | E7: =IF(AND(N($C7)=0,ROUND(N($D7),2)=0),"OK","Review") | F7: Filter Duplicate Check on the Data tab. Each needs a reversing WIP entry or it is double counted.
A8: 4 | B8: Departments that do not map to a report line | C8: =COUNTIF(Data!$E$2:$E$20000,"Unmapped") | E8: =IF(AND(N($C8)=0,ROUND(N($D8),2)=0),"OK","Review") | F8: The department is not on the Lists tab. Correct the record, or add the department and its report line.
A9: 5 | B9: Records with a Type but no Department | C9: =SUMPRODUCT((Data!$B$2:$B$20000<>"")*(Data!$D$2:$D$20000="")) | E9: =IF(AND(N($C9)=0,ROUND(N($D9),2)=0),"OK","Review") | F9: Every record needs a department so it lands on the right report line.
A10: 6 | B10: Records with money but no client | C10: =SUMPRODUCT((Data!$K$2:$K$20000<>0)*(Data!$K$2:$K$20000<>"")*(Data!$G$2:$G$20000="")) | E10: =IF(AND(N($C10)=0,ROUND(N($D10),2)=0),"OK","Review") | F10: A revenue line with no client cannot be traced back to anything.
A11: 7 | B11: Records with money but no job number | C11: =SUMPRODUCT((Data!$K$2:$K$20000<>0)*(Data!$K$2:$K$20000<>"")*(Data!$H$2:$H$20000="")) | E11: =IF(AND(N($C11)=0,ROUND(N($D11),2)=0),"OK","Review") | F11: Without a job number the WIP duplicate check cannot see this record.
A12: 8 | B12: Monthly grid vs total in tracker | D12: =Dashboard!$F$15-Dashboard!$C$27 | E12: =IF(AND(N($C12)=0,ROUND(N($D12),2)=0),"OK","Review") | F12: Should be zero. Anything else means the Dashboard and the Data tab disagree.
A15: WIP jobs that already appear on an invoiced record
A16: Snapshot from the rebuild. The live version is the Duplicate Check column on the Data tab.
A17: Job Number | B17: Client | C17: WIP Amount | D17: Invoiced dept | E17: Invoiced Amount
A18: 26043001 | B18: CBA | C18: -5950 | D18: Support | E18: 11377.12
A19: 26043001 | B19: CBA | C19: -5950 | D19: Support | E19: 11377.12
A20: 2604704 | B20: Aware Super | C20: 1821.25 | D20: Integration | E20: 202647
A21: 2606101 | B21: APA | C21: -4205 | D21: Integration | E21: 4205
A22: 26061108 | B22: APA | C22: -600 | D22: Production | E22: 12600.6
A23: 26061108 | B23: APA | C23: -237.5 | D23: Production | E23: 12600.6
A24: 26061108 | B24: APA | C24: -5413.6 | D24: Production | E24: 12600.6
A25: 26061108 | B25: APA | C25: -4520 | D25: Production | E25: 12600.6
A26: 26061108 | B26: APA | C26: -300 | D26: Production | E26: 12600.6
A27: 26061108 | B27: APA | C27: -690 | D27: Production | E27: 12600.6
A28: 2603104 | B28: Cochlear | C28: 172.5 | D28: Production | E28: 10540.5
A29: 2512804 | B29: RSNSW | C29: 115 | D29: Production | E29: 3261
A30: 26061108 | B30: APA | C30: 172.5 | D30: Production | E30: 12600.6

Sheet Legacy Notes
A1: Notes and comments recovered from the old workbook
A2: In the old file these were Excel comments stuck to cell positions, not to jobs. The macro swapped the data
A3: underneath them every time you changed department, so they had already drifted off the records they describe.
A4: They are listed here with their original cell reference. Paste each into the Notes column on the Data tab
A5: against the right record. Nothing has been guessed — no note has been assigned to a record for you.
A7: Original cell | B7: Type | C7: Author | D7: Date | E7: Note text
A8: U17 | B8: Note | C8: tc={64CAFEA6-7403-473A-A07F-D5B46206835A} | E8: <t xml:space="preserve">[Threaded comment] Your version of Excel allows you to read this threaded comment; however, any edits to it will get removed if the file is opened in a newer version of Excel. Learn more: https://go.microsoft.com/fwlink/?linkid=870924 Comment: PO: BlueChip PO-00016878 Accrued (Y/N & Date): Invoice #: SOR-1395622
A9: V17 | B9: Note | C9: tc={EE0E9B4C-B60C-49C0-8F08-349C412BAFC8} | E9: <t xml:space="preserve">[Threaded comment] Your version of Excel allows you to read this threaded comment; however, any edits to it will get removed if the file is opened in a newer version of Excel. Learn more: https://go.microsoft.com/fwlink/?linkid=870924 Comment: PO: BlueChip PO-00016878 Accrued (Y/N & Date): Invoice #: SOR-1395622
A10: V18 | B10: Threaded | C10: Gianmaria Gonzales-Yao | D10: 2026-08-04 | E10: PO: Barco PO-00016890 Accrued (Y/N & Date): Y & June 2026 Invoice #:
A11: V18 | B11: Note | C11: tc={7E633869-2C05-4011-93DA-CE274E40F652} | E11: <t>[Threaded comment] Your version of Excel allows you to read this threaded comment; however, any edits to it will get removed if the file is opened in a newer version of Excel. Learn more: https://go.microsoft.com/fwlink/?linkid=870924 Comment: PO: Barco PO-00016890 Accrued (Y/N & Date): Y & June 2026 Invoice #:
A12: U19 | B12: Note | C12: tc={C3AFA031-D315-42CB-955F-559A0953C2F6} | E12: <t xml:space="preserve">[Threaded comment] Your version of Excel allows you to read this threaded comment; however, any edits to it will get removed if the file is opened in a newer version of Excel. Learn more: https://go.microsoft.com/fwlink/?linkid=870924 Comment: PO: The Avit Group PO-00016884 The Avit Group PO-00016883 Accrued (Y/N & Date): Y & 30/06/2026 Invoice #:
A13: V19 | B13: Note | C13: tc={B1A6549A-741E-48A0-93A8-3D72C4F6B6CD} | E13: <t xml:space="preserve">[Threaded comment] Your version of Excel allows you to read this threaded comment; however, any edits to it will get removed if the file is opened in a newer version of Excel. Learn more: https://go.microsoft.com/fwlink/?linkid=870924 Comment: PO: The Avit Group PO-00016884 The Avit Group PO-00016883 Accrued (Y/N & Date): Y & 30/06/2026 Invoice #:
A14: U20 | B14: Threaded | C14: Gianmaria Gonzales-Yao | D14: 2026-08-04 | E14: PO: PO-00016891 Accrued (Y/N & Date): Y & June 2026 Invoice #: Videoguys SVG-18021
A15: U20 | B15: Note | C15: tc={432278A5-4123-4995-88E4-681666009693} | E15: <t>[Threaded comment] Your version of Excel allows you to read this threaded comment; however, any edits to it will get removed if the file is opened in a newer version of Excel. Learn more: https://go.microsoft.com/fwlink/?linkid=870924 Comment: PO: PO-00016891 Accrued (Y/N & Date): Y & June 2026 Invoice #: Videoguys SVG-18021
A16: V20 | B16: Threaded | C16: Gianmaria Gonzales-Yao | D16: 2026-08-04 | E16: PO: PO-00016891 Accrued (Y/N & Date): Y & June 2026 Invoice #: Videoguys SVG-18021
A17: V20 | B17: Note | C17: tc={C95DCE37-33FF-4A28-8E75-6667F197CCE1} | E17: <t>[Threaded comment] Your version of Excel allows you to read this threaded comment; however, any edits to it will get removed if the file is opened in a newer version of Excel. Learn more: https://go.microsoft.com/fwlink/?linkid=870924 Comment: PO: PO-00016891 Accrued (Y/N & Date): Y & June 2026 Invoice #: Videoguys SVG-18021
A18: U21 | B18: Note | C18: tc={D5B423E1-891A-42E0-AB10-E5B34B26421D} | E18: <t xml:space="preserve">[Threaded comment] Your version of Excel allows you to read this threaded comment; however, any edits to it will get removed if the file is opened in a newer version of Excel. Learn more: https://go.microsoft.com/fwlink/?linkid=870924 Comment: Videoguys invoice SVG-18021
A19: V21 | B19: Note | C19: tc={E5112070-2700-4FA6-A16E-E69A2CC631FC} | E19: <t xml:space="preserve">[Threaded comment] Your version of Excel allows you to read this threaded comment; however, any edits to it will get removed if the file is opened in a newer version of Excel. Learn more: https://go.microsoft.com/fwlink/?linkid=870924 Comment: Videoguys invoice SVG-18021
A20: U22 | B20: Note | C20: tc={F645B815-BC54-4739-8F08-E26362FA348E} | E20: <t xml:space="preserve">[Threaded comment] Your version of Excel allows you to read this threaded comment; however, any edits to it will get removed if the file is opened in a newer version of Excel. Learn more: https://go.microsoft.com/fwlink/?linkid=870924 Comment: PO: Fredon PO-00016852 Accrued (Y/N & Date): Y & April 2026 Invoice #:
A21: V22 | B21: Note | C21: tc={464F0CEA-A369-43EC-8D87-09E13085EAF9} | E21: <t xml:space="preserve">[Threaded comment] Your version of Excel allows you to read this threaded comment; however, any edits to it will get removed if the file is opened in a newer version of Excel. Learn more: https://go.microsoft.com/fwlink/?linkid=870924 Comment: PO: Fredon PO-00016852 Accrued (Y/N & Date): Y & April 2026 Invoice #:
A22: U23 | B22: Note | C22: tc={88B86C69-7FD4-4F41-92D1-98518D7CBDC0} | E22: <t xml:space="preserve">[Threaded comment] Your version of Excel allows you to read this threaded comment; however, any edits to it will get removed if the file is opened in a newer version of Excel. Learn more: https://go.microsoft.com/fwlink/?linkid=870924 Comment: PO: Fredon Fredon - PO-00016855 Accrued (Y/N & Date): Y & 30/06/2026 Invoice #:
A23: V23 | B23: Threaded | C23: Gianmaria Gonzales-Yao | D23: 2026-08-19 | E23: Bill received on 14/08/2026 Inv 198300267
A24: V23 | B24: Note | C24: tc={580A4F97-8784-4209-89E5-D2BEA6549D1C} | E24: <t>[Threaded comment] Your version of Excel allows you to read this threaded comment; however, any edits to it will get removed if the file is opened in a newer version of Excel. Learn more: https://go.microsoft.com/fwlink/?linkid=870924 Comment: PO: Fredon Fredon - PO-00016855 Accrued (Y/N & Date): Y & 30/06/2026 Invoice #: Reply: Bill received on 14/08/2026 Inv 198300267
A25: U24 | B25: Note | C25: tc={6ECBC017-4130-435D-BF00-5BE2F45103A6} | E25: <t xml:space="preserve">[Threaded comment] Your version of Excel allows you to read this threaded comment; however, any edits to it will get removed if the file is opened in a newer version of Excel. Learn more: https://go.microsoft.com/fwlink/?linkid=870924 Comment: PO: Fredon Fredon - PO-00016855 Accrued (Y/N & Date): Y & 30/06/2026 Invoice #: Reply: Fredon INV11S-26080021
A26: V24 | B26: Note | C26: tc={A15634CA-358E-4BDB-8CDC-5487C2A57F2E} | E26: <t xml:space="preserve">[Threaded comment] Your version of Excel allows you to read this threaded comment; however, any edits to it will get removed if the file is opened in a newer version of Excel. Learn more: https://go.microsoft.com/fwlink/?linkid=870924 Comment: PO: Fredon - PO-00016856 Accrued (Y/N & Date): Y & 30/06/2026 Invoice #: INV11S-26080021
A27: U25 | B27: Note | C27: tc={E8AFBB0D-66C7-43D8-AC34-ADEAC8B82E3A} | E27: <t xml:space="preserve">[Threaded comment] Your version of Excel allows you to read this threaded comment; however, any edits to it will get removed if the file is opened in a newer version of Excel. Learn more: https://go.microsoft.com/fwlink/?linkid=870924 Comment: PO: Fredon - PO-00016857 Accrued (Y/N & Date): Y & 30/06/2026 Invoice #:
A28: V25 | B28: Note | C28: tc={12399B37-19EB-49AC-9FC8-419497837192} | E28: <t xml:space="preserve">[Threaded comment] Your version of Excel allows you to read this threaded comment; however, any edits to it will get removed if the file is opened in a newer version of Excel. Learn more: https://go.microsoft.com/fwlink/?linkid=870924 Comment: PO: Fredon - PO-00016857 Accrued (Y/N & Date): Y & 30/06/2026 Invoice #:
A29: U26 | B29: Threaded | C29: Emelda Waiya | D29: 2026-08-04 | E29: Fredon INV11S-26080019 WIP: Reverse
A30: U26 | B30: Note | C30: tc={3C7D3A40-B297-4077-BD0A-F71143DF873E} | E30: <t>[Threaded comment] Your version of Excel allows you to read this threaded comment; however, any edits to it will get removed if the file is opened in a newer version of Excel. Learn more: https://go.microsoft.com/fwlink/?linkid=870924 Comment: Fredon INV11S-26080019 WIP: Reverse
A31: V26 | B31: Threaded | C31: Emelda Waiya | D31: 2026-08-04 | E31: Fredon INV11S-26080019 WIP: Reverse
A32: V26 | B32: Note | C32: tc={D8C53BB3-AEDA-4676-9B21-8B249A5025E3} | E32: <t>[Threaded comment] Your version of Excel allows you to read this threaded comment; however, any edits to it will get removed if the file is opened in a newer version of Excel. Learn more: https://go.microsoft.com/fwlink/?linkid=870924 Comment: Fredon INV11S-26080019 WIP: Reverse
A33: V27 | B33: Note | C33: tc={F9AAE1E7-E84D-4BCB-863D-5B44FA57F6DD} | E33: <t xml:space="preserve">[Threaded comment] Your version of Excel allows you to read this threaded comment; however, any edits to it will get removed if the file is opened in a newer version of Excel. Learn more: https://go.microsoft.com/fwlink/?linkid=870924 Comment: PO: Fredon PO-00016897 Accrued (Y/N & Date): Invoice #:
A34: U29 | B34: Note | C34: tc={7905AD5A-56E7-4172-BD87-D176F2E31C49} | E34: <t xml:space="preserve">[Threaded comment] Your version of Excel allows you to read this threaded comment; however, any edits to it will get removed if the file is opened in a newer version of Excel. Learn more: https://go.microsoft.com/fwlink/?linkid=870924 Comment: PO: no PO yet Accrued (Y/N & Date): Y & July 2026 Invoice #:
A35: V29 | B35: Note | C35: tc={9E2FFBE7-3071-479A-A6E8-09A0840A6836} | E35: <t xml:space="preserve">[Threaded comment] Your version of Excel allows you to read this threaded comment; however, any edits to it will get removed if the file is opened in a newer version of Excel. Learn more: https://go.microsoft.com/fwlink/?linkid=870924 Comment: Invoice: Harvey Norman INV31004114902 - $5,529.10 PO: Crestron PO-00016909 $20,678.00 Reply: Dicker Data INV7697713 $1,403.28
A36: V30 | B36: Threaded | C36: Emelda Waiya | D36: 2026-08-04 | E36: Invoice SOR-1404815 Full invoice recieved
A37: V30 | B37: Note | C37: tc={BB87ACD6-893B-495E-B563-7829733592A3} | E37: <t>[Threaded comment] Your version of Excel allows you to read this threaded comment; however, any edits to it will get removed if the file is opened in a newer version of Excel. Learn more: https://go.microsoft.com/fwlink/?linkid=870924 Comment: Invoice SOR-1404815 Full invoice recieved
