Workbook

Sheet Summary
A1: CTS forecast FY27
A3: July to September are actual, taken from the controller pack, which is the Xero GL.
A4: The overhead charged to each department uses the controller pack's split, the same three keys that drive the ONS, PRD and CONS management pages.
A5: October to June are her budget, carried over unchanged from the forecast workbook.
A6: October has not been closed. There is a Xero snapshot of it further down, at company level only.
A8: 1. THE THREE GROUPS, BY MONTH
A9: Group | B9: July | C9: August | D9: September | E9: October | F9: November | G9: December | H9: January | I9: February | J9: March | K9: April | L9: May | M9: June | N9: Total | O9: YTD actual
A10: Total Revenue
A11: ONS | B11: =ONS!B9 -> 235402.94 | C11: =ONS!C9 -> 240235.93 | D11: =ONS!D9 -> 242948.43 | E11: =ONS!E9 -> 263046.77 | F11: =ONS!F9 -> 262366.77 | G11: =ONS!G9 -> 251316.77 | H11: =ONS!H9 -> 262366.77 | I11: =ONS!I9 -> 262366.77 | ... M11: =ONS!M9 -> 242443.11 | N11: =SUM(B11:M11) -> 3035727.9 | O11: =SUM(B11:D11) -> 718587.3
A12: PRD | B12: =PRD!B6 -> 110842.53 | C12: =PRD!C6 -> 268942.12 | D12: =PRD!D6 -> 80606.62 | E12: =PRD!E6 -> 587307.02 | F12: =PRD!F6 -> 241601.02 | G12: =PRD!G6 -> 62316.02 | H12: =PRD!H6 -> 64261.94 | I12: =PRD!I6 -> 281912.02 | ... M12: =PRD!M6 -> 82637.02 | N12: =SUM(B12:M12) -> 2143572.3 | O12: =SUM(B12:D12) -> 460391.27
A13: CONS | B13: =CONS!B6 -> 112803.24 | C13: =CONS!C6 -> 94288.49 | D13: =CONS!D6 -> 238389.48 | E13: =CONS!E6 -> 100061.89 | F13: =CONS!F6 -> 36337.39 | G13: =CONS!G6 -> 31337.39 | H13: =CONS!H6 -> 27340.65 | I13: =CONS!I6 -> 32340.65 | ... M13: =CONS!M6 -> 8035.07 | N13: =SUM(B13:M13) -> 753650.62 | O13: =SUM(B13:D13) -> 445481.21
A14: CTS | B14: =SUM(B11:B13) -> 459048.71 | C14: =SUM(C11:C13) -> 603466.54 | D14: =SUM(D11:D13) -> 561944.53 | E14: =SUM(E11:E13) -> 950415.68 | F14: =SUM(F11:F13) -> 540305.18 | G14: =SUM(G11:G13) -> 344970.18 | H14: =SUM(H11:H13) -> 353969.36 | I14: =SUM(I11:I13) -> 576619.44 | ... O14: =SUM(O11:O13) -> 1624459.8
A16: Total COGs
A17: ONS | B17: =ONS!B17 -> -131411.69 | C17: =ONS!C17 -> -134597.55 | D17: =ONS!D17 -> -141658.68 | E17: =ONS!E17 -> -130158.67 | F17: =ONS!F17 -> -127598.95 | G17: =ONS!G17 -> -134912.18 | H17: =ONS!H17 -> -112466.56 | I17: =ONS!I17 -> -116012.63 | ... M17: =ONS!M17 -> -139270 | N17: =SUM(B17:M17) -> -1586577.9 | O17: =SUM(B17:D17) -> -407667.92
A18: PRD | B18: =PRD!B18 -> -44738.1 | C18: =PRD!C18 -> -125113.08 | D18: =PRD!D18 -> -17912.33 | E18: =PRD!E18 -> -285683.94 | F18: =PRD!F18 -> -104223.85 | G18: =PRD!G18 -> -83048.46 | H18: =PRD!H18 -> -45343.16 | I18: =PRD!I18 -> -109744.54 | ... M18: =PRD!M18 -> -85630.23 | N18: =SUM(B18:M18) -> -1069421 | O18: =SUM(B18:D18) -> -187763.51
A19: CONS | B19: =CONS!B12 -> -106364.37 | C19: =CONS!C12 -> -75775.53 | D19: =CONS!D12 -> -214559.11 | E19: =CONS!E12 -> -58336.61 | F19: =CONS!F12 -> -27394.36 | G19: =CONS!G12 -> -23963.88 | H19: =CONS!H12 -> -21263.51 | I19: =CONS!I12 -> -24080.81 | ... M19: =CONS!M12 -> -17919.3 | N19: =SUM(B19:M19) -> -631560.87 | O19: =SUM(B19:D19) -> -396699.01
A20: CTS | B20: =SUM(B17:B19) -> -282514.16 | C20: =SUM(C17:C19) -> -335486.16 | D20: =SUM(D17:D19) -> -374130.12 | E20: =SUM(E17:E19) -> -474179.22 | F20: =SUM(F17:F19) -> -259217.16 | G20: =SUM(G17:G19) -> -241924.52 | H20: =SUM(H17:H19) -> -179073.23 | I20: =SUM(I17:I19) -> -249837.98 | ... O20: =SUM(O17:O19) -> -992130.44
A22: Total overhead
A23: ONS | B23: =ONS!B24 -> -70735.47 | C23: =ONS!C24 -> -88990.44 | D23: =ONS!D24 -> -80457.84 | E23: =ONS!E24 -> -93854.08 | F23: =ONS!F24 -> -91774.56 | G23: =ONS!G24 -> -92814.32 | H23: =ONS!H24 -> -91774.56 | I23: =ONS!I24 -> -91774.56 | ... M23: =ONS!M24 -> -92814.32 | N23: =SUM(B23:M23) -> -1073433.1 | O23: =SUM(B23:D23) -> -240183.75
A24: PRD | B24: =PRD!B25 -> -110189.34 | C24: =PRD!C25 -> -99694.18 | D24: =PRD!D25 -> -115816.62 | E24: =PRD!E25 -> -97172.11 | F24: =PRD!F25 -> -98147.41 | G24: =PRD!G25 -> -94037.61 | H24: =PRD!H25 -> -93018.7 | I24: =PRD!I25 -> -93018.7 | ... M24: =PRD!M25 -> -94037.61 | N24: =SUM(B24:M24) -> -1177245.1 | O24: =SUM(B24:D24) -> -325700.14
A25: CONS | B25: =CONS!B19 -> -21473.13 | C25: =CONS!C19 -> -20221.4 | D25: =CONS!D19 -> -33958.91 | E25: =CONS!E19 -> -29303.29 | F25: =CONS!F19 -> -28574.37 | G25: =CONS!G19 -> -28938.83 | H25: =CONS!H19 -> -28574.37 | I25: =CONS!I19 -> -28574.37 | ... M25: =CONS!M19 -> -28938.83 | N25: =SUM(B25:M25) -> -335373.99 | O25: =SUM(B25:D25) -> -75653.44
A26: CTS | B26: =SUM(B23:B25) -> -202397.94 | C26: =SUM(C23:C25) -> -208906.02 | D26: =SUM(D23:D25) -> -230233.37 | E26: =SUM(E23:E25) -> -220329.48 | F26: =SUM(F23:F25) -> -218496.34 | G26: =SUM(G23:G25) -> -215790.76 | H26: =SUM(H23:H25) -> -213367.63 | I26: =SUM(I23:I25) -> -213367.63 | ... O26: =SUM(O23:O25) -> -641537.33
A28: Net Profit
A29: ONS | B29: =ONS!B29 -> 33255.78 | C29: =ONS!C29 -> 16647.94 | D29: =ONS!D29 -> 20831.91 | E29: =ONS!E29 -> 39034.02 | F29: =ONS!F29 -> 42993.26 | G29: =ONS!G29 -> 23590.27 | H29: =ONS!H29 -> 58125.65 | I29: =ONS!I29 -> 54579.58 | ... M29: =ONS!M29 -> 10358.79 | N29: =SUM(B29:M29) -> 375716.91 | O29: =SUM(B29:D29) -> 70735.63
A30: PRD | B30: =PRD!B30 -> -44084.91 | C30: =PRD!C30 -> 44134.86 | D30: =PRD!D30 -> -53122.33 | E30: =PRD!E30 -> 204450.97 | F30: =PRD!F30 -> 39229.76 | G30: =PRD!G30 -> -114770.05 | H30: =PRD!H30 -> -74099.92 | I30: =PRD!I30 -> 79148.78 | ... M30: =PRD!M30 -> -97030.82 | N30: =SUM(B30:M30) -> -103093.79 | O30: =SUM(B30:D30) -> -53072.38
A31: CONS | B31: =CONS!B24 -> -15034.26 | C31: =CONS!C24 -> -1708.44 | D31: =CONS!D24 -> -10128.54 | E31: =CONS!E24 -> 12421.99 | F31: =CONS!F24 -> -19631.34 | G31: =CONS!G24 -> -21565.32 | H31: =CONS!H24 -> -22497.23 | I31: =CONS!I24 -> -20314.53 | ... M31: =CONS!M24 -> -38823.06 | N31: =SUM(B31:M31) -> -213284.24 | O31: =SUM(B31:D31) -> -26871.24
A32: CTS | B32: =SUM(B29:B31) -> -25863.39 | C32: =SUM(C29:C31) -> 59074.36 | D32: =SUM(D29:D31) -> -42418.96 | E32: =SUM(E29:E31) -> 255906.98 | F32: =SUM(F29:F31) -> 62591.68 | G32: =SUM(G29:G31) -> -112745.1 | H32: =SUM(H29:H31) -> -38471.5 | I32: =SUM(I29:I31) -> 113413.83 | ... O32: =SUM(O29:O31) -> -9207.99
A34: 2. OCTOBER SNAPSHOT FROM XERO, 1 TO 26 OCTOBER 2026
A35: This is not a closed month and not a forecast input.
A36: The month's invoicing is not raised, so revenue is well short. The Xero report data was last refreshed 23 October 2026.
A38: Line | B38: Per Xero | C38: October budget | D38: Difference
A39: Total income | B39: 96489.15 | C39: =ONS!E9+PRD!E6+CONS!E6 -> 950415.68 | D39: =B39-C39 -> -853926.53
A40: Cost of sales | B40: -267594.63 | C40: =ONS!E17+PRD!E18+CONS!E12 -> -474179.22 | D40: =B40-C40 -> 206584.59
A41: Overheads | B41: -126105.28 | C41: =ONS!E24+PRD!E25+CONS!E19 -> -220329.48 | D41: =B41-C41 -> 94224.2
A42: Other income | B42: 430.17
A43: Net profit | B43: -296780.59 | C43: =ONS!E29+PRD!E30+CONS!E24 -> 255906.98 | D43: =B43-C43 -> -552687.57
A46: 3. WHAT IS NOT IN THE ACTUAL MONTHS
A47: Four forecast lines carry nothing in July to September, because nothing in the GL identifies them on its own:
A48: ONS, PWC IT Nat. Pool of Hrs COS. It is a job number, not an account.
A49: ONS, Discretionary Bonuses.
...

Sheet ONS
A1: ONS forecast FY27
A2: July to September are actual, from the controller pack. October to June are her budget, unchanged.
A4: Line | B4: July | C4: August | D4: September | E4: October | F4: November | G4: December | H4: January | I4: February | J4: March | K4: April | L4: May | M4: June | N4: Total | O4: YTD actual
A5: Mobile | B5: 1182.5 | C5: 1110 | D5: 820 | E5: 780 | F5: 780 | G5: 780 | H5: 780 | I5: 780 | J5: 780 | K5: 780 | L5: 780 | M5: 780 | N5: =SUM(B5:M5) -> 10132.5 | O5: =SUM(B5:D5) -> 3112.5
A6: Hotline | B6: 0 | C6: 0 | D6: 0 | E6: 100 | F6: 100 | G6: 100 | H6: 100 | I6: 100 | J6: 100 | K6: 100 | L6: 100 | M6: 100 | N6: =SUM(B6:M6) -> 900 | O6: =SUM(B6:D6) -> 0
A7: Spotify | B7: 0 | C7: 0 | D7: 0 | E7: 28 | F7: 28 | G7: 28 | H7: 28 | I7: 28 | J7: 28 | K7: 28 | L7: 28 | M7: 28 | N7: =SUM(B7:M7) -> 252 | O7: =SUM(B7:D7) -> 0
A8: Revenue | B8: 234220.44 | C8: 239125.93 | D8: 242128.43 | E8: 262138.77 | F8: 261458.77 | G8: 250408.77 | H8: 261458.77 | I8: 261458.77 | J8: 252108.77 | K8: 260358.77 | L8: 258042.11 | M8: 241535.11 | N8: =SUM(B8:M8) -> 3024443.4 | O8: =SUM(B8:D8) -> 715474.8
A9: Total Revenue | B9: =B5+B6+B7+B8 -> 235402.94 | C9: =C5+C6+C7+C8 -> 240235.93 | D9: =D5+D6+D7+D8 -> 242948.43 | E9: =E5+E6+E7+E8 -> 263046.77 | F9: =F5+F6+F7+F8 -> 262366.77 | G9: =G5+G6+G7+G8 -> 251316.77 | H9: =H5+H6+H7+H8 -> 262366.77 | I9: =I5+I6+I7+I8 -> 262366.77 | ... M9: =M5+M6+M7+M8 -> 242443.11 | N9: =SUM(B9:M9) -> 3035727.9 | O9: =SUM(B9:D9) -> 718587.3
A10: Direct Salaries | B10: -86363.88 | C10: -92093.64 | D10: -73977.83 | E10: -85762.77 | F10: -77966.16 | G10: -81864.46 | H10: -77966.16 | I10: -77966.16 | J10: -85762.77 | K10: -77966.16 | L10: -81864.46 | M10: -81864.46 | N10: =SUM(B10:M10) -> -981418.91 | O10: =SUM(B10:D10) -> -252435.35
A11: Direct Superannuation | B11: -13094.97 | C11: -12480.57 | D11: -14911.46 | E11: -10291.53 | F11: -9355.94 | G11: -9823.74 | H11: -9355.94 | I11: -9355.94 | J11: -10291.53 | K11: -9355.94 | L11: -9823.74 | M11: -9823.74 | N11: =SUM(B11:M11) -> -127965.04 | O11: =SUM(B11:D11) -> -40487
A12: PWC IT Nat. Pool of Hrs COS | B12: 0 | C12: 0 | D12: 0 | E12: -4250 | F12: -4250 | G12: 0 | H12: -4250 | I12: -4250 | J12: -4250 | K12: -4250 | L12: -4250 | M12: -4250 | N12: =SUM(B12:M12) -> -34000 | O12: =SUM(B12:D12) -> 0
A13: Salaries (Casual + Super + Spacera) | B13: -24965.6 | C13: -24208.11 | D13: -38879.44 | E13: -26997.24 | F13: -34656.33 | G13: -41853.48 | H13: -19439.65 | I13: -23070.02 | J13: -40473.32 | K13: -41813.69 | L13: -44203.24 | M13: -42143.71 | N13: =SUM(B13:M13) -> -402703.83 | O13: =SUM(B13:D13) -> -88053.15
A14: Discretionary Bonuses | B14: 0 | C14: 0 | D14: 0 | E14: -200 | F14: -200 | G14: -200 | H14: -200 | I14: -200 | J14: -200 | K14: -200 | L14: -200 | M14: -200 | N14: =SUM(B14:M14) -> -1800 | O14: =SUM(B14:D14) -> 0
A15: Equipment & Services | B15: -5866.01 | C15: -5332.62 | D15: -5893.5 | E15: -1026.67 | F15: -1170.52 | G15: -1170.5 | H15: -1254.81 | I15: -1170.51 | J15: -1104.34 | K15: -1104.44 | L15: -1070.77 | M15: -988.09 | N15: =SUM(B15:M15) -> -27152.78 | O15: =SUM(B15:D15) -> -17092.13
A16: Transport | B16: -1121.23 | C16: -482.61 | D16: -7996.45 | E16: -1630.46 | F16: 0 | G16: 0 | H16: 0 | I16: 0 | J16: -124.81 | K16: -113.88 | L16: -67.89 | M16: 0 | N16: =SUM(B16:M16) -> -11537.33 | O16: =SUM(B16:D16) -> -9600.29
A17: Total COGs | B17: =B10+B11+B12+B13+B14+B15+B16 -> -131411.69 | C17: =C10+C11+C12+C13+C14+C15+C16 -> -134597.55 | D17: =D10+D11+D12+D13+D14+D15+D16 -> -141658.68 | E17: =E10+E11+E12+E13+E14+E15+E16 -> -130158.67 | F17: =F10+F11+F12+F13+F14+F15+F16 -> -127598.95 | G17: =G10+G11+G12+G13+G14+G15+G16 -> -134912.18 | H17: =H10+H11+H12+H13+H14+H15+H16 -> -112466.56 | I17: =I10+I11+I12+I13+I14+I15+I16 -> -116012.63 | ... M17: =M10+M11+M12+M13+M14+M15+M16 -> -139270 | N17: =SUM(B17:M17) -> -1586577.9 | O17: =SUM(B17:D17) -> -407667.92
A19: OVERHEAD CHARGED TO THE DEPARTMENT
A20: Business Insurances | B20: -1923.67 | C20: -1870.84 | D20: -4121.99 | E20: -1229.15 | F20: -1229.15 | G20: -1229.15 | H20: -1229.15 | I20: -1229.15 | J20: -1229.15 | K20: -1229.15 | L20: -1229.15 | M20: -1229.15 | N20: =SUM(B20:M20) -> -18978.85 | O20: =SUM(B20:D20) -> -7916.5
A21: Employment Expenses | B21: -44895.42 | C21: -65554.35 | D21: -51784.73 | E21: -71289.72 | F21: -69210.2 | G21: -70249.96 | H21: -69210.2 | I21: -69210.2 | J21: -71289.72 | K21: -69210.2 | L21: -70249.96 | M21: -70249.96 | N21: =SUM(B21:M21) -> -792404.62 | O21: =SUM(B21:D21) -> -162234.5
A22: General & Administrative Exp | B22: -6229.43 | C22: -6426.32 | D22: -11233.31 | E22: -9644.73 | F22: -9644.73 | G22: -9644.73 | H22: -9644.73 | I22: -9644.73 | J22: -9644.73 | K22: -9644.73 | L22: -9644.73 | M22: -9644.73 | N22: =SUM(B22:M22) -> -110691.63 | O22: =SUM(B22:D22) -> -23889.06
A23: Operating Expenses | B23: -17686.95 | C23: -15138.93 | D23: -13317.81 | E23: -11690.48 | F23: -11690.48 | G23: -11690.48 | H23: -11690.48 | I23: -11690.48 | J23: -11690.48 | K23: -11690.48 | L23: -11690.48 | M23: -11690.48 | N23: =SUM(B23:M23) -> -151358.01 | O23: =SUM(B23:D23) -> -46143.69
A24: Total overhead | B24: =B20+B21+B22+B23 -> -70735.47 | C24: =C20+C21+C22+C23 -> -88990.44 | D24: =D20+D21+D22+D23 -> -80457.84 | E24: =E20+E21+E22+E23 -> -93854.08 | F24: =F20+F21+F22+F23 -> -91774.56 | G24: =G20+G21+G22+G23 -> -92814.32 | H24: =H20+H21+H22+H23 -> -91774.56 | I24: =I20+I21+I22+I23 -> -91774.56 | ... M24: =M20+M21+M22+M23 -> -92814.32 | N24: =SUM(B24:M24) -> -1073433.1 | O24: =SUM(B24:D24) -> -240183.75
A26: RESULT
A27: Gross Profit | B27: =B9+B17 -> 103991.25 | C27: =C9+C17 -> 105638.38 | D27: =D9+D17 -> 101289.75 | E27: =E9+E17 -> 132888.1 | F27: =F9+F17 -> 134767.82 | G27: =G9+G17 -> 116404.59 | H27: =H9+H17 -> 149900.21 | I27: =I9+I17 -> 146354.14 | ... M27: =M9+M17 -> 103173.11 | N27: =SUM(B27:M27) -> 1449150 | O27: =SUM(B27:D27) -> 310919.38
A28: Gross Profit Margin | B28: =IFERROR((B9+B17)/B9,"") -> 0.4417585 | C28: =IFERROR((C9+C17)/C9,"") -> 0.43972765 | D28: =IFERROR((D9+D17)/D9,"") -> 0.41691873 | E28: =IFERROR((E9+E17)/E9,"") -> 0.50518811 | F28: =IFERROR((F9+F17)/F9,"") -> 0.51366192 | G28: =IFERROR((G9+G17)/G9,"") -> 0.46317876 | H28: =IFERROR((H9+H17)/H9,"") -> 0.5713384 | I28: =IFERROR((I9+I17)/I9,"") -> 0.5578227 | ... M28: =IFERROR((M9+M17)/M9,"") -> 0.42555596 | N28: =IFERROR(N27/N9,"") -> 0.47736492 | O28: =IFERROR(O27/O9,"") -> 0.43268143
A29: Net Profit | B29: =B9+B17+B24 -> 33255.78 | C29: =C9+C17+C24 -> 16647.94 | D29: =D9+D17+D24 -> 20831.91 | E29: =E9+E17+E24 -> 39034.02 | F29: =F9+F17+F24 -> 42993.26 | G29: =G9+G17+G24 -> 23590.27 | H29: =H9+H17+H24 -> 58125.65 | I29: =I9+I17+I24 -> 54579.58 | ... M29: =M9+M17+M24 -> 10358.79 | N29: =SUM(B29:M29) -> 375716.91 | O29: =SUM(B29:D29) -> 70735.63
A30: Net Profit Margin | B30: =IFERROR((B9+B17+B24)/B9,"") -> 0.14127173 | C30: =IFERROR((C9+C17+C24)/C9,"") -> 0.069298294 | D30: =IFERROR((D9+D17+D24)/D9,"") -> 0.085746222 | E30: =IFERROR((E9+E17+E24)/E9,"") -> 0.14839194 | F30: =IFERROR((F9+F17+F24)/F9,"") -> 0.16386702 | G30: =IFERROR((G9+G17+G24)/G9,"") -> 0.093866677 | H30: =IFERROR((H9+H17+H24)/H9,"") -> 0.22154349 | I30: =IFERROR((I9+I17+I24)/I9,"") -> 0.20802779 | ... M30: =IFERROR((M9+M17+M24)/M9,"") -> 0.042726683 | N30: =IFERROR(N29/N9,"") -> 0.12376501 | O30: =IFERROR(O29/O9,"") -> 0.098437072

Sheet PRD
A1: PRD forecast FY27
A2: July to September are actual, from the controller pack. October to June are her budget, unchanged.
A4: Line | B4: July | C4: August | D4: September | E4: October | F4: November | G4: December | H4: January | I4: February | J4: March | K4: April | L4: May | M4: June | N4: Total | O4: YTD actual
A5: Revenue | B5: 110842.53 | C5: 268942.12 | D5: 80606.62 | E5: 587307.02 | F5: 241601.02 | G5: 62316.02 | H5: 64261.94 | I5: 281912.02 | J5: 128882.02 | K5: 98752.02 | L5: 135511.94 | M5: 82637.02 | N5: =SUM(B5:M5) -> 2143572.3 | O5: =SUM(B5:D5) -> 460391.27
A6: Total Revenue | B6: =B5 -> 110842.53 | C6: =C5 -> 268942.12 | D6: =D5 -> 80606.62 | E6: =E5 -> 587307.02 | F6: =F5 -> 241601.02 | G6: =G5 -> 62316.02 | H6: =H5 -> 64261.94 | I6: =I5 -> 281912.02 | ... M6: =M5 -> 82637.02 | N6: =SUM(B6:M6) -> 2143572.3 | O6: =SUM(B6:D6) -> 460391.27
A7: Direct Salaries (Production) | B7: -10096.74 | C7: -29119.07 | D7: -5791.88 | E7: -20870.24 | F7: -18972.95 | G7: -19921.59 | H7: -18972.95 | I7: -18972.95 | J7: -20870.24 | K7: -18972.95 | L7: -19921.59 | M7: -19921.59 | N7: =SUM(B7:M7) -> -222404.74 | O7: =SUM(B7:D7) -> -45007.69
A8: Direct Salaries (Video) | B8: -424.53 | C8: -3502.18 | D8: -774.69 | E8: -9418.83 | F8: -15240.57 | G8: -4783.56 | H8: -4555.77 | I8: -4555.77 | J8: -5011.35 | K8: -4555.77 | L8: -4783.56 | M8: -4783.56 | N8: =SUM(B8:M8) -> -62390.14 | O8: =SUM(B8:D8) -> -4701.4
A9: Direct Superannuation (Production) | B9: -1611.44 | C9: -5026.96 | D9: -3381.07 | E9: -2504.43 | F9: -2276.75 | G9: -2390.59 | H9: -2276.75 | I9: -2276.75 | J9: -2504.43 | K9: -2276.75 | L9: -2390.59 | M9: -2390.59 | N9: =SUM(B9:M9) -> -31307.1 | O9: =SUM(B9:D9) -> -10019.47
A10: Direct Superannuation (Video) | B10: -331.62 | C10: -507.42 | D10: -978.23 | E10: -1130.26 | F10: -1828.87 | G10: -574.03 | H10: -546.69 | I10: -546.69 | J10: -601.36 | K10: -546.69 | L10: -574.03 | M10: -574.03 | N10: =SUM(B10:M10) -> -8739.92 | O10: =SUM(B10:D10) -> -1817.27
A11: Salaries FT Fixed Term (Gross + Super) | B11: 0 | C11: 0 | D11: 0 | E11: -3326.4 | F11: -8064 | G11: 0 | H11: 0 | I11: 0 | J11: 0 | K11: 0 | L11: 0 | M11: 0 | N11: =SUM(B11:M11) -> -11390.4 | O11: =SUM(B11:D11) -> 0
A12: Salaries Casual Production (Gross + Super) | B12: -3414.34 | C12: -14287.98 | D12: -2131.06 | E12: -6531.41 | F12: -4420.73 | G12: -21556.22 | H12: -500 | I12: -12506.42 | J12: -4362.73 | K12: -2129.49 | L12: -8377.21 | M12: -19210.92 | N12: =SUM(B12:M12) -> -99428.51 | O12: =SUM(B12:D12) -> -19833.38
A13: Salaries Casual Video (Gross + Super) | B13: -2339.02 | C13: -820.37 | D13: 263.6 | E13: 0 | F13: -497.15 | G13: -497.15 | H13: -189.39 | I13: -4188.15 | J13: -2651.03 | K13: 0 | L13: -1127.48 | M13: -1874.67 | N13: =SUM(B13:M13) -> -13920.81 | O13: =SUM(B13:D13) -> -2895.79
A14: Equipment (Production) | B14: -22897.92 | C14: -64436.16 | D14: -2861.3 | E14: -222259.63 | F14: -47487.38 | G14: -29486.69 | H14: -17314.12 | I14: -58917.73 | J14: -19339.16 | K14: -18365.51 | L14: -21368.11 | M14: -32615.71 | N14: =SUM(B14:M14) -> -557349.42 | O14: =SUM(B14:D14) -> -90195.38
A15: Equipment (Video) | B15: 0 | C15: -95 | D15: 0 | E15: -1258.67 | F15: -346.41 | G15: -893.95 | H15: -460.65 | I15: -1133.99 | J15: -446.84 | K15: -345 | L15: -345 | M15: -345 | N15: =SUM(B15:M15) -> -5670.51 | O15: =SUM(B15:D15) -> -95
A16: Transportation (Production) | B16: -3622.49 | C16: -7317.94 | D16: -2257.7 | E16: -18324.81 | F16: -4971.24 | G16: -2944.68 | H16: -526.84 | I16: -6582.96 | J16: -3452.44 | K16: -782.63 | L16: -1663.82 | M16: -3866.46 | N16: =SUM(B16:M16) -> -56314.01 | O16: =SUM(B16:D16) -> -13198.13
A17: Transportation (Video) | B17: 0 | C17: 0 | D17: 0 | E17: -59.26 | F17: -117.8 | G17: 0 | H17: 0 | I17: -63.13 | J17: -73.8 | K17: -143.72 | L17: 0 | M17: -47.7 | N17: =SUM(B17:M17) -> -505.41 | O17: =SUM(B17:D17) -> 0
A18: Total COGs | B18: =B7+B8+B9+B10+B11+B12+B13+B14+B15+B16+B17 -> -44738.1 | C18: =C7+C8+C9+C10+C11+C12+C13+C14+C15+C16+C17 -> -125113.08 | D18: =D7+D8+D9+D10+D11+D12+D13+D14+D15+D16+D17 -> -17912.33 | E18: =E7+E8+E9+E10+E11+E12+E13+E14+E15+E16+E17 -> -285683.94 | F18: =F7+F8+F9+F10+F11+F12+F13+F14+F15+F16+F17 -> -104223.85 | G18: =G7+G8+G9+G10+G11+G12+G13+G14+G15+G16+G17 -> -83048.46 | H18: =H7+H8+H9+H10+H11+H12+H13+H14+H15+H16+H17 -> -45343.16 | I18: =I7+I8+I9+I10+I11+I12+I13+I14+I15+I16+I17 -> -109744.54 | ... M18: =M7+M8+M9+M10+M11+M12+M13+M14+M15+M16+M17 -> -85630.23 | N18: =SUM(B18:M18) -> -1069421 | O18: =SUM(B18:D18) -> -187763.51
A20: OVERHEAD CHARGED TO THE DEPARTMENT
A21: Business Insurances | B21: -2433.51 | C21: -1628.91 | D21: -4889.08 | E21: -1824.91 | F21: -1824.91 | G21: -1824.91 | H21: -1824.91 | I21: -1824.91 | J21: -1824.91 | K21: -1824.91 | L21: -1824.91 | M21: -1824.91 | N21: =SUM(B21:M21) -> -25375.69 | O21: =SUM(B21:D21) -> -8951.5
A22: Employment Expenses | B22: -59287.64 | C22: -56244.15 | D22: -56843.99 | E22: -57798.28 | F22: -58773.58 | G22: -54663.78 | H22: -53644.87 | I22: -53644.87 | J22: -55682.69 | K22: -53644.87 | L22: -54663.78 | M22: -54663.78 | N22: =SUM(B22:M22) -> -669556.28 | O22: =SUM(B22:D22) -> -172375.78
A23: General & Administrative Exp | B23: -11944.33 | C23: -7367.77 | D23: -17886.68 | E23: -12988.16 | F23: -12988.16 | G23: -12988.16 | H23: -12988.16 | I23: -12988.16 | J23: -12988.16 | K23: -12988.16 | L23: -12988.16 | M23: -12988.16 | N23: =SUM(B23:M23) -> -154092.22 | O23: =SUM(B23:D23) -> -37198.78
A24: Operating Expenses | B24: -36523.86 | C24: -34453.35 | D24: -36196.87 | E24: -24560.76 | F24: -24560.76 | G24: -24560.76 | H24: -24560.76 | I24: -24560.76 | J24: -24560.76 | K24: -24560.76 | L24: -24560.76 | M24: -24560.76 | N24: =SUM(B24:M24) -> -328220.92 | O24: =SUM(B24:D24) -> -107174.08
A25: Total overhead | B25: =B21+B22+B23+B24 -> -110189.34 | C25: =C21+C22+C23+C24 -> -99694.18 | D25: =D21+D22+D23+D24 -> -115816.62 | E25: =E21+E22+E23+E24 -> -97172.11 | F25: =F21+F22+F23+F24 -> -98147.41 | G25: =G21+G22+G23+G24 -> -94037.61 | H25: =H21+H22+H23+H24 -> -93018.7 | I25: =I21+I22+I23+I24 -> -93018.7 | ... M25: =M21+M22+M23+M24 -> -94037.61 | N25: =SUM(B25:M25) -> -1177245.1 | O25: =SUM(B25:D25) -> -325700.14
A27: RESULT
A28: Gross Profit | B28: =B6+B18 -> 66104.43 | C28: =C6+C18 -> 143829.04 | D28: =D6+D18 -> 62694.29 | E28: =E6+E18 -> 301623.08 | F28: =F6+F18 -> 137377.17 | G28: =G6+G18 -> -20732.44 | H28: =H6+H18 -> 18918.78 | I28: =I6+I18 -> 172167.48 | ... M28: =M6+M18 -> -2993.21 | N28: =SUM(B28:M28) -> 1074151.3 | O28: =SUM(B28:D28) -> 272627.76
A29: Gross Profit Margin | B29: =IFERROR((B6+B18)/B6,"") -> 0.59638146 | C29: =IFERROR((C6+C18)/C6,"") -> 0.53479552 | D29: =IFERROR((D6+D18)/D6,"") -> 0.77778091 | E29: =IFERROR((E6+E18)/E6,"") -> 0.51356968 | F29: =IFERROR((F6+F18)/F6,"") -> 0.56861171 | G29: =IFERROR((G6+G18)/G6,"") -> -0.3326984 | H29: =IFERROR((H6+H18)/H6,"") -> 0.29440101 | I29: =IFERROR((I6+I18)/I6,"") -> 0.61071351 | ... M29: =IFERROR((M6+M18)/M6,"") -> -0.036221175 | N29: =IFERROR(N28/N6,"") -> 0.50110338 | O29: =IFERROR(O28/O6,"") -> 0.59216536
A30: Net Profit | B30: =B6+B18+B25 -> -44084.91 | C30: =C6+C18+C25 -> 44134.86 | D30: =D6+D18+D25 -> -53122.33 | E30: =E6+E18+E25 -> 204450.97 | F30: =F6+F18+F25 -> 39229.76 | G30: =G6+G18+G25 -> -114770.05 | H30: =H6+H18+H25 -> -74099.92 | I30: =I6+I18+I25 -> 79148.78 | ... M30: =M6+M18+M25 -> -97030.82 | N30: =SUM(B30:M30) -> -103093.79 | O30: =SUM(B30:D30) -> -53072.38
A31: Net Profit Margin | B31: =IFERROR((B6+B18+B25)/B6,"") -> -0.39772558 | C31: =IFERROR((C6+C18+C25)/C6,"") -> 0.16410542 | D31: =IFERROR((D6+D18+D25)/D6,"") -> -0.65903185 | E31: =IFERROR((E6+E18+E25)/E6,"") -> 0.348116 | F31: =IFERROR((F6+F18+F25)/F6,"") -> 0.16237415 | G31: =IFERROR((G6+G18+G25)/G6,"") -> -1.8417423 | H31: =IFERROR((H6+H18+H25)/H6,"") -> -1.1530919 | I31: =IFERROR((I6+I18+I25)/I6,"") -> 0.28075702 | ... M31: =IFERROR((M6+M18+M25)/M6,"") -> -1.174181 | N31: =IFERROR(N30/N6,"") -> -0.048094385 | O31: =IFERROR(O30/O6,"") -> -0.11527669

Sheet CONS
A1: CONS forecast FY27
A2: July to September are actual, from the controller pack. October to June are her budget, unchanged.
A4: Line | B4: July | C4: August | D4: September | E4: October | F4: November | G4: December | H4: January | I4: February | J4: March | K4: April | L4: May | M4: June | N4: Total | O4: YTD actual
A5: Revenue | B5: 112803.24 | C5: 94288.49 | D5: 238389.48 | E5: 100061.89 | F5: 36337.39 | G5: 31337.39 | H5: 27340.65 | I5: 32340.65 | J5: 32340.65 | K5: 32340.65 | L5: 8035.07 | M5: 8035.07 | N5: =SUM(B5:M5) -> 753650.62 | O5: =SUM(B5:D5) -> 445481.21
A6: Total Revenue | B6: =B5 -> 112803.24 | C6: =C5 -> 94288.49 | D6: =D5 -> 238389.48 | E6: =E5 -> 100061.89 | F6: =F5 -> 36337.39 | G6: =G5 -> 31337.39 | H6: =H5 -> 27340.65 | I6: =I5 -> 32340.65 | ... M6: =M5 -> 8035.07 | N6: =SUM(B6:M6) -> 753650.62 | O6: =SUM(B6:D6) -> 445481.21
A7: Direct Salaries | B7: -6593.62 | C7: -6058 | D7: -202.41 | E7: -7159.07 | F7: -6508.24 | G7: -6833.65 | H7: -6508.24 | I7: -6508.24 | J7: -7159.07 | K7: -6508.24 | L7: -6833.65 | M7: -6833.65 | N7: =SUM(B7:M7) -> -73706.08 | O7: =SUM(B7:D7) -> -12854.03
A8: Direct Superannuation | B8: -849.03 | C8: -711.83 | D8: -355 | E8: -859.09 | F8: -780.99 | G8: -820.04 | H8: -780.99 | I8: -780.99 | J8: -859.09 | K8: -780.99 | L8: -820.04 | M8: -820.04 | N8: =SUM(B8:M8) -> -9218.12 | O8: =SUM(B8:D8) -> -1915.86
A9: INT- Equip/Sub-Contract/Licenses | B9: -98640.79 | C9: -68727.42 | D9: -213242.37 | E9: -50030.95 | F9: -18168.7 | G9: -15668.7 | H9: -13670.33 | I9: -16170.33 | J9: -16170.33 | K9: -16170.33 | L9: -4017.54 | M9: -4017.54 | N9: =SUM(B9:M9) -> -534695.33 | O9: =SUM(B9:D9) -> -380610.58
A10: Aware Super (COS) | B10: 0 | C10: 0 | D10: 0 | E10: -287.5 | F10: -287.5 | G10: -287.5 | H10: -287.5 | I10: -287.5 | J10: -287.5 | K10: -287.5 | L10: -287.5 | M10: -287.5 | N10: =SUM(B10:M10) -> -2587.5 | O10: =SUM(B10:D10) -> 0
A11: Transport (INT & CONS) | B11: -280.93 | C11: -278.28 | D11: -759.33 | E11: 0 | F11: -1648.93 | G11: -353.99 | H11: -16.45 | I11: -333.75 | J11: -586.93 | K11: -576.26 | L11: -558.42 | M11: -5960.57 | N11: =SUM(B11:M11) -> -11353.84 | O11: =SUM(B11:D11) -> -1318.54
A12: Total COGs | B12: =B7+B8+B9+B10+B11 -> -106364.37 | C12: =C7+C8+C9+C10+C11 -> -75775.53 | D12: =D7+D8+D9+D10+D11 -> -214559.11 | E12: =E7+E8+E9+E10+E11 -> -58336.61 | F12: =F7+F8+F9+F10+F11 -> -27394.36 | G12: =G7+G8+G9+G10+G11 -> -23963.88 | H12: =H7+H8+H9+H10+H11 -> -21263.51 | I12: =I7+I8+I9+I10+I11 -> -24080.81 | ... M12: =M7+M8+M9+M10+M11 -> -17919.3 | N12: =SUM(B12:M12) -> -631560.87 | O12: =SUM(B12:D12) -> -396699.01
A14: OVERHEAD CHARGED TO THE DEPARTMENT
A15: Business Insurances | B15: -2192.62 | C15: -1617.74 | D15: -4549.04 | E15: -1569.03 | F15: -1569.03 | G15: -1569.03 | H15: -1569.03 | I15: -1569.03 | J15: -1569.03 | K15: -1569.03 | L15: -1569.03 | M15: -1569.03 | N15: =SUM(B15:M15) -> -22480.67 | O15: =SUM(B15:D15) -> -8359.4
A16: Employment Expenses | B16: -9939.18 | C16: -9055.2 | D16: -15861.72 | E16: -9445.32 | F16: -8716.4 | G16: -9080.86 | H16: -8716.4 | I16: -8716.4 | J16: -9445.32 | K16: -8716.4 | L16: -9080.86 | M16: -9080.86 | N16: =SUM(B16:M16) -> -115854.92 | O16: =SUM(B16:D16) -> -34856.1
A17: General & Administrative Exp | B17: -4550.12 | C17: -4274.76 | D17: -6059.7 | E17: -5229.41 | F17: -5229.41 | G17: -5229.41 | H17: -5229.41 | I17: -5229.41 | J17: -5229.41 | K17: -5229.41 | L17: -5229.41 | M17: -5229.41 | N17: =SUM(B17:M17) -> -61949.27 | O17: =SUM(B17:D17) -> -14884.58
A18: Operating Expenses | B18: -4791.21 | C18: -5273.7 | D18: -7488.45 | E18: -13059.53 | F18: -13059.53 | G18: -13059.53 | H18: -13059.53 | I18: -13059.53 | J18: -13059.53 | K18: -13059.53 | L18: -13059.53 | M18: -13059.53 | N18: =SUM(B18:M18) -> -135089.13 | O18: =SUM(B18:D18) -> -17553.36
A19: Total overhead | B19: =B15+B16+B17+B18 -> -21473.13 | C19: =C15+C16+C17+C18 -> -20221.4 | D19: =D15+D16+D17+D18 -> -33958.91 | E19: =E15+E16+E17+E18 -> -29303.29 | F19: =F15+F16+F17+F18 -> -28574.37 | G19: =G15+G16+G17+G18 -> -28938.83 | H19: =H15+H16+H17+H18 -> -28574.37 | I19: =I15+I16+I17+I18 -> -28574.37 | ... M19: =M15+M16+M17+M18 -> -28938.83 | N19: =SUM(B19:M19) -> -335373.99 | O19: =SUM(B19:D19) -> -75653.44
A21: RESULT
A22: Gross Profit | B22: =B6+B12 -> 6438.87 | C22: =C6+C12 -> 18512.96 | D22: =D6+D12 -> 23830.37 | E22: =E6+E12 -> 41725.28 | F22: =F6+F12 -> 8943.03 | G22: =G6+G12 -> 7373.51 | H22: =H6+H12 -> 6077.14 | I22: =I6+I12 -> 8259.84 | ... M22: =M6+M12 -> -9884.23 | N22: =SUM(B22:M22) -> 122089.75 | O22: =SUM(B22:D22) -> 48782.2
A23: Gross Profit Margin | B23: =IFERROR((B6+B12)/B6,"") -> 0.057080541 | C23: =IFERROR((C6+C12)/C6,"") -> 0.1963438 | D23: =IFERROR((D6+D12)/D6,"") -> 0.099964017 | E23: =IFERROR((E6+E12)/E6,"") -> 0.41699472 | F23: =IFERROR((F6+F12)/F6,"") -> 0.24611096 | G23: =IFERROR((G6+G12)/G6,"") -> 0.23529432 | H23: =IFERROR((H6+H12)/H6,"") -> 0.22227489 | I23: =IFERROR((I6+I12)/I6,"") -> 0.25540117 | ... M23: =IFERROR((M6+M12)/M6,"") -> -1.2301361 | N23: =IFERROR(N22/N6,"") -> 0.16199781 | O23: =IFERROR(O22/O6,"") -> 0.10950451
A24: Net Profit | B24: =B6+B12+B19 -> -15034.26 | C24: =C6+C12+C19 -> -1708.44 | D24: =D6+D12+D19 -> -10128.54 | E24: =E6+E12+E19 -> 12421.99 | F24: =F6+F12+F19 -> -19631.34 | G24: =G6+G12+G19 -> -21565.32 | H24: =H6+H12+H19 -> -22497.23 | I24: =I6+I12+I19 -> -20314.53 | ... M24: =M6+M12+M19 -> -38823.06 | N24: =SUM(B24:M24) -> -213284.24 | O24: =SUM(B24:D24) -> -26871.24
A25: Net Profit Margin | B25: =IFERROR((B6+B12+B19)/B6,"") -> -0.13327862 | C25: =IFERROR((C6+C12+C19)/C6,"") -> -0.018119285 | D25: =IFERROR((D6+D12+D19)/D6,"") -> -0.042487361 | E25: =IFERROR((E6+E12+E19)/E6,"") -> 0.12414307 | F25: =IFERROR((F6+F12+F19)/F6,"") -> -0.54025179 | G25: =IFERROR((G6+G12+G19)/G6,"") -> -0.6881658 | H25: =IFERROR((H6+H12+H19)/H6,"") -> -0.82284913 | I25: =IFERROR((I6+I12+I19)/I6,"") -> -0.62814229 | ... M25: =IFERROR((M6+M12+M19)/M6,"") -> -4.8317015 | N25: =IFERROR(N24/N6,"") -> -0.28300148 | O25: =IFERROR(O24/O6,"") -> -0.060319581
