Workbook

Sheet Cash Flow
A1: Corporate Technology Services Pty Ltd
A2: Weekly Cash Flow Forecast vs Actual - 28 September to 1 November 2026
A3: How this works: the Forecast columns are formulas off the Receivables, Payables, Payroll and Assumptions tabs. Each week, put the actual movements in the yellow Actual column, type in the closing bank balance from CommBiz, and set 'Actuals entered' to 1. The next week then starts from the real bank balance and the difference row shows anything that's been missed.
B5: Week 1 | D5: Week 2 | F5: Week 3 | H5: Week 4 | J5: Week 5 | L5: Total | N5: Variance | O5: Notes
B6: =TEXT(Assumptions!$B$44,"d mmm")&" - "&TEXT(Assumptions!$C$44,"d mmm") -> 28 Sep - 7 Oct | D6: =TEXT(Assumptions!$B$45,"d mmm")&" - "&TEXT(Assumptions!$C$45,"d mmm") -> 8 Oct - 14 Oct | F6: =TEXT(Assumptions!$B$46,"d mmm")&" - "&TEXT(Assumptions!$C$46,"d mmm") -> 15 Oct - 21 Oct | H6: =TEXT(Assumptions!$B$47,"d mmm")&" - "&TEXT(Assumptions!$C$47,"d mmm") -> 22 Oct - 28 Oct | J6: =TEXT(Assumptions!$B$48,"d mmm")&" - "&TEXT(Assumptions!$C$48,"d mmm") -> 29 Oct - 4 Nov | N6: (weeks with
A7: $ AUD (GST inclusive) | B7: Forecast | C7: Actual | D7: Forecast | E7: Actual | F7: Forecast | G7: Actual | H7: Forecast | I7: Actual | J7: Forecast | K7: Actual | L7: Forecast | M7: Actual | N7: actuals)
A8: Actuals entered for this week? (1 = yes) | C8: 0 | E8: 0 | G8: 0 | I8: 0 | K8: 0
A10: OPENING BANK BALANCE | B10: =Assumptions!$B$6 -> 435155 | C10: =B10 -> 435155 | D10: =IF(C$8=1,C58,B57) -> 274893.63 | E10: =D10 -> 274893.63 | F10: =IF(E$8=1,E58,D57) -> 731075.62 | G10: =F10 -> 731075.62 | H10: =IF(G$8=1,G58,F57) -> 666474.23 | I10: =H10 -> 666474.23 | J10: =IF(I$8=1,I58,H57) -> 500476.16 | K10: =J10 -> 500476.16 | L10: =B10 -> 435155 | M10: =C10 -> 435155
A12: INCOME
A13: Trading income - customer receipts (invoices) | B13: =SUMIFS(Receivables!$F$5:$F$52,Receivables!$H$5:$H$52,">="&Assumptions!$B$44,Receivables!$H$5:$H$52,"<="&Assumptions!$C$44) -> 158974.55 | D13: =SUMIFS(Receivables!$F$5:$F$52,Receivables!$H$5:$H$52,">="&Assumptions!$B$45,Receivables!$H$5:$H$52,"<="&Assumptions!$C$45) -> 489026.1 | F13: =SUMIFS(Receivables!$F$5:$F$52,Receivables!$H$5:$H$52,">="&Assumptions!$B$46,Receivables!$H$5:$H$52,"<="&Assumptions!$C$46)+Assumptions!$B$39/3 -> 90207.737 | H13: =SUMIFS(Receivables!$F$5:$F$52,Receivables!$H$5:$H$52,">="&Assumptions!$B$47,Receivables!$H$5:$H$52,"<="&Assumptions!$C$47)+Assumptions!$B$39/3 -> 12626.467 | J13: =SUMIFS(Receivables!$F$5:$F$52,Receivables!$H$5:$H$52,">="&Assumptions!$B$48,Receivables!$H$5:$H$52,"<="&Assumptions!$C$48)+Assumptions!$B$39/3 -> 29899.057 | L13: =SUM(B13,D13,F13,H13,J13) -> 780733.91 | M13: =SUM(C13,E13,G13,I13,K13) -> 0 | N13: =(C13-B13)*C$8+(E13-D13)*E$8+(G13-F13)*G$8+(I13-H13)*I$8+(K13-J13)*K$8 -> 0
A14: Other income - interest received | B14: =0 -> 0 | D14: =0 -> 0 | F14: =0 -> 0 | H14: =0 -> 0 | J14: =Assumptions!$B$40 -> 600 | L14: =SUM(B14,D14,F14,H14,J14) -> 600 | M14: =SUM(C14,E14,G14,I14,K14) -> 0 | N14: =(C14-B14)*C$8+(E14-D14)*E$8+(G14-F14)*G$8+(I14-H14)*I$8+(K14-J14)*K$8 -> 0 | O14: Savings interest, month end.
A15: TOTAL INCOME | B15: =B13+B14 -> 158974.55 | C15: =C13+C14 -> 0 | D15: =D13+D14 -> 489026.1 | E15: =E13+E14 -> 0 | F15: =F13+F14 -> 90207.737 | G15: =G13+G14 -> 0 | H15: =H13+H14 -> 12626.467 | I15: =I13+I14 -> 0 | ... N15: =N13+N14 -> 0
A17: OPERATING EXPENSES
A18: Employment
A19: Salaries & wages (net pay) | B19: =SUMIFS(Payroll!$E$5:$E$7,Payroll!$C$5:$C$7,">="&Assumptions!$B$44,Payroll!$C$5:$C$7,"<="&Assumptions!$C$44) -> 85248 | D19: =SUMIFS(Payroll!$E$5:$E$7,Payroll!$C$5:$C$7,">="&Assumptions!$B$45,Payroll!$C$5:$C$7,"<="&Assumptions!$C$45) -> 0 | F19: =SUMIFS(Payroll!$E$5:$E$7,Payroll!$C$5:$C$7,">="&Assumptions!$B$46,Payroll!$C$5:$C$7,"<="&Assumptions!$C$46) -> 85248 | H19: =SUMIFS(Payroll!$E$5:$E$7,Payroll!$C$5:$C$7,">="&Assumptions!$B$47,Payroll!$C$5:$C$7,"<="&Assumptions!$C$47) -> 0 | J19: =SUMIFS(Payroll!$E$5:$E$7,Payroll!$C$5:$C$7,">="&Assumptions!$B$48,Payroll!$C$5:$C$7,"<="&Assumptions!$C$48) -> 85248 | L19: =SUM(B19,D19,F19,H19,J19) -> 255744 | M19: =SUM(C19,E19,G19,I19,K19) -> 0 | N19: =(C19-B19)*C$8+(E19-D19)*E$8+(G19-F19)*G$8+(I19-H19)*I$8+(K19-J19)*K$8 -> 0 | O19: Payroll tab - gross x net %. Pay runs Tue 6 Oct, Tue 20 Oct and Tue 3 Nov (ABA through CommBiz).
A20: Superannuation | B20: =SUMIFS(Payroll!$G$5:$G$7,Payroll!$C$5:$C$7,">="&Assumptions!$B$44,Payroll!$C$5:$C$7,"<="&Assumptions!$C$44) -> 13320 | D20: =SUMIFS(Payroll!$G$5:$G$7,Payroll!$C$5:$C$7,">="&Assumptions!$B$45,Payroll!$C$5:$C$7,"<="&Assumptions!$C$45) -> 0 | F20: =SUMIFS(Payroll!$G$5:$G$7,Payroll!$C$5:$C$7,">="&Assumptions!$B$46,Payroll!$C$5:$C$7,"<="&Assumptions!$C$46) -> 13320 | H20: =SUMIFS(Payroll!$G$5:$G$7,Payroll!$C$5:$C$7,">="&Assumptions!$B$47,Payroll!$C$5:$C$7,"<="&Assumptions!$C$47) -> 0 | J20: =SUMIFS(Payroll!$G$5:$G$7,Payroll!$C$5:$C$7,">="&Assumptions!$B$48,Payroll!$C$5:$C$7,"<="&Assumptions!$C$48) -> 13320 | L20: =SUM(B20,D20,F20,H20,J20) -> 39960 | M20: =SUM(C20,E20,G20,I20,K20) -> 0 | N20: =(C20-B20)*C$8+(E20-D20)*E$8+(G20-F20)*G$8+(I20-H20)*I$8+(K20-J20)*K$8 -> 0 | O20: Gross x 12%. EH direct debits it in the pay run week.
A21: PAYG withholding - monthly IAS | B21: =0 -> 0 | D21: =0 -> 0 | F21: =0 -> 0 | H21: =0 -> 0 | J21: =0 -> 0 | L21: =SUM(B21,D21,F21,H21,J21) -> 0 | M21: =SUM(C21,E21,G21,I21,K21) -> 0 | N21: =(C21-B21)*C$8+(E21-D21)*E$8+(G21-F21)*G$8+(I21-H21)*I$8+(K21-J21)*K$8 -> 0 | O21: Nothing in Oct - Jul and Aug were paid 21 Aug and 21 Sep, Sep goes on the Q1 BAS (see the BAS line).
A22: Payroll tax (NSW + other states) | B22: =IF(AND(Assumptions!$B$19>=Assumptions!$B$44,Assumptions!$B$19<=Assumptions!$C$44),Assumptions!$B$17+Assumptions!$B$18,0) -> 8995 | D22: =IF(AND(Assumptions!$B$19>=Assumptions!$B$45,Assumptions!$B$19<=Assumptions!$C$45),Assumptions!$B$17+Assumptions!$B$18,0) -> 0 | F22: =IF(AND(Assumptions!$B$19>=Assumptions!$B$46,Assumptions!$B$19<=Assumptions!$C$46),Assumptions!$B$17+Assumptions!$B$18,0) -> 0 | H22: =IF(AND(Assumptions!$B$19>=Assumptions!$B$47,Assumptions!$B$19<=Assumptions!$C$47),Assumptions!$B$17+Assumptions!$B$18,0) -> 0 | J22: =IF(AND(Assumptions!$B$19>=Assumptions!$B$48,Assumptions!$B$19<=Assumptions!$C$48),Assumptions!$B$17+Assumptions!$B$18,0) -> 0 | L22: =SUM(B22,D22,F22,H22,J22) -> 8995 | M22: =SUM(C22,E22,G22,I22,K22) -> 0 | N22: =(C22-B22)*C$8+(E22-D22)*E$8+(G22-F22)*G$8+(I22-H22)*I$8+(K22-J22)*K$8 -> 0 | O22: Sep wages, due 7 Oct. Aug numbers used until the Sep return is lodged ($6,295 NSW + $2,700 other states).
A23: Employee reimbursements (expense claims) | B23: =SUMIFS(Payroll!$H$5:$H$7,Payroll!$C$5:$C$7,">="&Assumptions!$B$44,Payroll!$C$5:$C$7,"<="&Assumptions!$C$44) -> 1000 | D23: =SUMIFS(Payroll!$H$5:$H$7,Payroll!$C$5:$C$7,">="&Assumptions!$B$45,Payroll!$C$5:$C$7,"<="&Assumptions!$C$45) -> 0 | F23: =SUMIFS(Payroll!$H$5:$H$7,Payroll!$C$5:$C$7,">="&Assumptions!$B$46,Payroll!$C$5:$C$7,"<="&Assumptions!$C$46) -> 1000 | H23: =SUMIFS(Payroll!$H$5:$H$7,Payroll!$C$5:$C$7,">="&Assumptions!$B$47,Payroll!$C$5:$C$7,"<="&Assumptions!$C$47) -> 0 | J23: =SUMIFS(Payroll!$H$5:$H$7,Payroll!$C$5:$C$7,">="&Assumptions!$B$48,Payroll!$C$5:$C$7,"<="&Assumptions!$C$48) -> 1000 | L23: =SUM(B23,D23,F23,H23,J23) -> 3000 | M23: =SUM(C23,E23,G23,I23,K23) -> 0 | N23: =(C23-B23)*C$8+(E23-D23)*E$8+(G23-F23)*G$8+(I23-H23)*I$8+(K23-J23)*K$8 -> 0
A24: Subtotal employment | B24: =B19+B20+B21+B22+B23 -> 108563 | C24: =C19+C20+C21+C22+C23 -> 0 | D24: =D19+D20+D21+D22+D23 -> 0 | E24: =E19+E20+E21+E22+E23 -> 0 | F24: =F19+F20+F21+F22+F23 -> 99568 | G24: =G19+G20+G21+G22+G23 -> 0 | H24: =H19+H20+H21+H22+H23 -> 0 | I24: =I19+I20+I21+I22+I23 -> 0 | ... N24: =N19+N20+N21+N22+N23 -> 0
A26: Cost of sales (client jobs)
A27: Project equipment & installation | B27: =SUMIFS(Payables!$D$19:$D$60,Payables!$G$19:$G$60,">="&Assumptions!$B$44,Payables!$G$19:$G$60,"<="&Assumptions!$C$44,Payables!$E$19:$E$60,"<>Card",Payables!$F$19:$F$60,"Equipment purchases")+Assumptions!$B$29/5 -> 164871.48 | D27: =SUMIFS(Payables!$D$19:$D$60,Payables!$G$19:$G$60,">="&Assumptions!$B$45,Payables!$G$19:$G$60,"<="&Assumptions!$C$45,Payables!$E$19:$E$60,"<>Card",Payables!$F$19:$F$60,"Equipment purchases")+Assumptions!$B$29/5 -> 4000 | F27: =SUMIFS(Payables!$D$19:$D$60,Payables!$G$19:$G$60,">="&Assumptions!$B$46,Payables!$G$19:$G$60,"<="&Assumptions!$C$46,Payables!$E$19:$E$60,"<>Card",Payables!$F$19:$F$60,"Equipment purchases")+Assumptions!$B$29/5 -> 11103.26 | H27: =SUMIFS(Payables!$D$19:$D$60,Payables!$G$19:$G$60,">="&Assumptions!$B$47,Payables!$G$19:$G$60,"<="&Assumptions!$C$47,Payables!$E$19:$E$60,"<>Card",Payables!$F$19:$F$60,"Equipment purchases")+Assumptions!$B$29/5 -> 4000 | J27: =SUMIFS(Payables!$D$19:$D$60,Payables!$G$19:$G$60,">="&Assumptions!$B$48,Payables!$G$19:$G$60,"<="&Assumptions!$C$48,Payables!$E$19:$E$60,"<>Card",Payables!$F$19:$F$60,"Equipment purchases")+Assumptions!$B$29/5 -> 4000 | L27: =SUM(B27,D27,F27,H27,J27) -> 187974.74 | M27: =SUM(C27,E27,G27,I27,K27) -> 0 | N27: =(C27-B27)*C$8+(E27-D27)*E$8+(G27-F27)*G$8+(I27-H27)*I$8+(K27-J27)*K$8 -> 0 | O27: Payables tab - Complete AV materials $136,163 (this week, see the Complete AV tab), Fredon $24,708, Crestron $7,103 - plus the unbilled estimate. Complete AV labour $41,956 is held past the end of the forecast.
A28: Sub-contract labour | B28: =Assumptions!$B$27/5 -> 8000 | D28: =Assumptions!$B$27/5 -> 8000 | F28: =Assumptions!$B$27/5 -> 8000 | H28: =Assumptions!$B$27/5 -> 8000 | J28: =Assumptions!$B$27/5 -> 8000 | L28: =SUM(B28,D28,F28,H28,J28) -> 40000 | M28: =SUM(C28,E28,G28,I28,K28) -> 0 | N28: =(C28-B28)*C$8+(E28-D28)*E$8+(G28-F28)*G$8+(I28-H28)*I$8+(K28-J28)*K$8 -> 0 | O28: Estimate (Sep was ~$39k), spread evenly.
A29: Equipment & service hires | B29: =Assumptions!$B$28/5 -> 6000 | D29: =Assumptions!$B$28/5 -> 6000 | F29: =Assumptions!$B$28/5 -> 6000 | H29: =Assumptions!$B$28/5 -> 6000 | J29: =Assumptions!$B$28/5 -> 6000 | L29: =SUM(B29,D29,F29,H29,J29) -> 30000 | M29: =SUM(C29,E29,G29,I29,K29) -> 0 | N29: =(C29-B29)*C$8+(E29-D29)*E$8+(G29-F29)*G$8+(I29-H29)*I$8+(K29-J29)*K$8 -> 0 | O29: Estimate (Sep was ~$29k), spread evenly.
A30: Subscriptions & licences (client) | B30: =SUMIFS(Payables!$D$19:$D$60,Payables!$G$19:$G$60,">="&Assumptions!$B$44,Payables!$G$19:$G$60,"<="&Assumptions!$C$44,Payables!$E$19:$E$60,"<>Card",Payables!$F$19:$F$60,"Client subscriptions")+Assumptions!$B$31/5 -> 9955.84 | D30: =SUMIFS(Payables!$D$19:$D$60,Payables!$G$19:$G$60,">="&Assumptions!$B$45,Payables!$G$19:$G$60,"<="&Assumptions!$C$45,Payables!$E$19:$E$60,"<>Card",Payables!$F$19:$F$60,"Client subscriptions")+Assumptions!$B$31/5 -> 2085 | F30: =SUMIFS(Payables!$D$19:$D$60,Payables!$G$19:$G$60,">="&Assumptions!$B$46,Payables!$G$19:$G$60,"<="&Assumptions!$C$46,Payables!$E$19:$E$60,"<>Card",Payables!$F$19:$F$60,"Client subscriptions")+Assumptions!$B$31/5 -> 600 | H30: =SUMIFS(Payables!$D$19:$D$60,Payables!$G$19:$G$60,">="&Assumptions!$B$47,Payables!$G$19:$G$60,"<="&Assumptions!$C$47,Payables!$E$19:$E$60,"<>Card",Payables!$F$19:$F$60,"Client subscriptions")+Assumptions!$B$31/5 -> 21585.43 | J30: =SUMIFS(Payables!$D$19:$D$60,Payables!$G$19:$G$60,">="&Assumptions!$B$48,Payables!$G$19:$G$60,"<="&Assumptions!$C$48,Payables!$E$19:$E$60,"<>Card",Payables!$F$19:$F$60,"Client subscriptions")+Assumptions!$B$31/5 -> 6328.8 | L30: =SUM(B30,D30,F30,H30,J30) -> 40555.07 | M30: =SUM(C30,E30,G30,I30,K30) -> 0 | N30: =(C30-B30)*C$8+(E30-D30)*E$8+(G30-F30)*G$8+(I30-H30)*I$8+(K30-J30)*K$8 -> 0 | O30: Payables tab (Appspace, Spacera, Eptura, LiveU) plus the unbilled estimate.
A31: Direct travel & freight | B31: =SUMIFS(Payables!$D$19:$D$60,Payables!$G$19:$G$60,">="&Assumptions!$B$44,Payables!$G$19:$G$60,"<="&Assumptions!$C$44,Payables!$E$19:$E$60,"<>Card",Payables!$F$19:$F$60,"Direct travel & freight")+Assumptions!$B$30/5 -> 1400 | D31: =SUMIFS(Payables!$D$19:$D$60,Payables!$G$19:$G$60,">="&Assumptions!$B$45,Payables!$G$19:$G$60,"<="&Assumptions!$C$45,Payables!$E$19:$E$60,"<>Card",Payables!$F$19:$F$60,"Direct travel & freight")+Assumptions!$B$30/5 -> 1400 | F31: =SUMIFS(Payables!$D$19:$D$60,Payables!$G$19:$G$60,">="&Assumptions!$B$46,Payables!$G$19:$G$60,"<="&Assumptions!$C$46,Payables!$E$19:$E$60,"<>Card",Payables!$F$19:$F$60,"Direct travel & freight")+Assumptions!$B$30/5 -> 1400 | H31: =SUMIFS(Payables!$D$19:$D$60,Payables!$G$19:$G$60,">="&Assumptions!$B$47,Payables!$G$19:$G$60,"<="&Assumptions!$C$47,Payables!$E$19:$E$60,"<>Card",Payables!$F$19:$F$60,"Direct travel & freight")+Assumptions!$B$30/5 -> 1400 | J31: =SUMIFS(Payables!$D$19:$D$60,Payables!$G$19:$G$60,">="&Assumptions!$B$48,Payables!$G$19:$G$60,"<="&Assumptions!$C$48,Payables!$E$19:$E$60,"<>Card",Payables!$F$19:$F$60,"Direct travel & freight")+Assumptions!$B$30/5 -> 1400 | L31: =SUM(B31,D31,F31,H31,J31) -> 7000 | M31: =SUM(C31,E31,G31,I31,K31) -> 0 | N31: =(C31-B31)*C$8+(E31-D31)*E$8+(G31-F31)*G$8+(I31-H31)*I$8+(K31-J31)*K$8 -> 0 | O31: Estimate and Payables tab (non-card) - Flights and accommodation on the card sit in the credit card line.
A32: Subtotal cost of sales | B32: =B27+B28+B29+B30+B31 -> 190227.32 | C32: =C27+C28+C29+C30+C31 -> 0 | D32: =D27+D28+D29+D30+D31 -> 21485 | E32: =E27+E28+E29+E30+E31 -> 0 | F32: =F27+F28+F29+F30+F31 -> 27103.26 | G32: =G27+G28+G29+G30+G31 -> 0 | H32: =H27+H28+H29+H30+H31 -> 40985.43 | I32: =I27+I28+I29+I30+I31 -> 0 | ... N32: =N27+N28+N29+N30+N31 -> 0
A34: Overheads
A35: Rent & outgoings | B35: =SUMIFS(Payables!$D$19:$D$60,Payables!$G$19:$G$60,">="&Assumptions!$B$44,Payables!$G$19:$G$60,"<="&Assumptions!$C$44,Payables!$E$19:$E$60,"<>Card",Payables!$F$19:$F$60,"Rent") -> 0 | D35: =SUMIFS(Payables!$D$19:$D$60,Payables!$G$19:$G$60,">="&Assumptions!$B$45,Payables!$G$19:$G$60,"<="&Assumptions!$C$45,Payables!$E$19:$E$60,"<>Card",Payables!$F$19:$F$60,"Rent") -> 0 | F35: =SUMIFS(Payables!$D$19:$D$60,Payables!$G$19:$G$60,">="&Assumptions!$B$46,Payables!$G$19:$G$60,"<="&Assumptions!$C$46,Payables!$E$19:$E$60,"<>Card",Payables!$F$19:$F$60,"Rent") -> 0 | H35: =SUMIFS(Payables!$D$19:$D$60,Payables!$G$19:$G$60,">="&Assumptions!$B$47,Payables!$G$19:$G$60,"<="&Assumptions!$C$47,Payables!$E$19:$E$60,"<>Card",Payables!$F$19:$F$60,"Rent") -> 29280.72 | J35: =SUMIFS(Payables!$D$19:$D$60,Payables!$G$19:$G$60,">="&Assumptions!$B$48,Payables!$G$19:$G$60,"<="&Assumptions!$C$48,Payables!$E$19:$E$60,"<>Card",Payables!$F$19:$F$60,"Rent") -> 0 | L35: =SUM(B35,D35,F35,H35,J35) -> 29280.72 | M35: =SUM(C35,E35,G35,I35,K35) -> 0 | N35: =(C35-B35)*C$8+(E35-D35)*E$8+(G35-F35)*G$8+(I35-H35)*I$8+(K35-J35)*K$8 -> 0 | O35: Investa Sep rent $29,281 due 22 Oct. Oct rent falls in Nov.
A36: IT network service & support | B36: =SUMIFS(Payables!$D$19:$D$60,Payables!$G$19:$G$60,">="&Assumptions!$B$44,Payables!$G$19:$G$60,"<="&Assumptions!$C$44,Payables!$E$19:$E$60,"<>Card",Payables!$F$19:$F$60,"IT support") -> 0 | D36: =SUMIFS(Payables!$D$19:$D$60,Payables!$G$19:$G$60,">="&Assumptions!$B$45,Payables!$G$19:$G$60,"<="&Assumptions!$C$45,Payables!$E$19:$E$60,"<>Card",Payables!$F$19:$F$60,"IT support") -> 0 | F36: =SUMIFS(Payables!$D$19:$D$60,Payables!$G$19:$G$60,">="&Assumptions!$B$46,Payables!$G$19:$G$60,"<="&Assumptions!$C$46,Payables!$E$19:$E$60,"<>Card",Payables!$F$19:$F$60,"IT support") -> 14466.27 | H36: =SUMIFS(Payables!$D$19:$D$60,Payables!$G$19:$G$60,">="&Assumptions!$B$47,Payables!$G$19:$G$60,"<="&Assumptions!$C$47,Payables!$E$19:$E$60,"<>Card",Payables!$F$19:$F$60,"IT support") -> 0 | J36: =SUMIFS(Payables!$D$19:$D$60,Payables!$G$19:$G$60,">="&Assumptions!$B$48,Payables!$G$19:$G$60,"<="&Assumptions!$C$48,Payables!$E$19:$E$60,"<>Card",Payables!$F$19:$F$60,"IT support") -> 0 | L36: =SUM(B36,D36,F36,H36,J36) -> 14466.27 | M36: =SUM(C36,E36,G36,I36,K36) -> 0 | N36: =(C36-B36)*C$8+(E36-D36)*E$8+(G36-F36)*G$8+(I36-H36)*I$8+(K36-J36)*K$8 -> 0 | O36: First Focus CORE + Azure, DD around 16 Oct.
A37: Advertising & marketing | B37: =SUMIFS(Payables!$D$19:$D$60,Payables!$G$19:$G$60,">="&Assumptions!$B$44,Payables!$G$19:$G$60,"<="&Assumptions!$C$44,Payables!$E$19:$E$60,"<>Card",Payables!$F$19:$F$60,"Advertising") -> 6600 | D37: =SUMIFS(Payables!$D$19:$D$60,Payables!$G$19:$G$60,">="&Assumptions!$B$45,Payables!$G$19:$G$60,"<="&Assumptions!$C$45,Payables!$E$19:$E$60,"<>Card",Payables!$F$19:$F$60,"Advertising") -> 0 | F37: =SUMIFS(Payables!$D$19:$D$60,Payables!$G$19:$G$60,">="&Assumptions!$B$46,Payables!$G$19:$G$60,"<="&Assumptions!$C$46,Payables!$E$19:$E$60,"<>Card",Payables!$F$19:$F$60,"Advertising") -> 4675 | H37: =SUMIFS(Payables!$D$19:$D$60,Payables!$G$19:$G$60,">="&Assumptions!$B$47,Payables!$G$19:$G$60,"<="&Assumptions!$C$47,Payables!$E$19:$E$60,"<>Card",Payables!$F$19:$F$60,"Advertising") -> 0 | J37: =SUMIFS(Payables!$D$19:$D$60,Payables!$G$19:$G$60,">="&Assumptions!$B$48,Payables!$G$19:$G$60,"<="&Assumptions!$C$48,Payables!$E$19:$E$60,"<>Card",Payables!$F$19:$F$60,"Advertising") -> 0 | L37: =SUM(B37,D37,F37,H37,J37) -> 11275 | M37: =SUM(C37,E37,G37,I37,K37) -> 0 | N37: =(C37-B37)*C$8+(E37-D37)*E$8+(G37-F37)*G$8+(I37-H37)*I$8+(K37-J37)*K$8 -> 0 | O37: RJW website balance $6,600 (check with DL first) and RJW digital marketing $4,675.
A38: Accounting, legal & advisory | B38: =SUMIFS(Payables!$D$19:$D$60,Payables!$G$19:$G$60,">="&Assumptions!$B$44,Payables!$G$19:$G$60,"<="&Assumptions!$C$44,Payables!$E$19:$E$60,"<>Card",Payables!$F$19:$F$60,"Professional fees")+Assumptions!$B$33/5 -> 6410 | D38: =SUMIFS(Payables!$D$19:$D$60,Payables!$G$19:$G$60,">="&Assumptions!$B$45,Payables!$G$19:$G$60,"<="&Assumptions!$C$45,Payables!$E$19:$E$60,"<>Card",Payables!$F$19:$F$60,"Professional fees")+Assumptions!$B$33/5 -> 800 | F38: =SUMIFS(Payables!$D$19:$D$60,Payables!$G$19:$G$60,">="&Assumptions!$B$46,Payables!$G$19:$G$60,"<="&Assumptions!$C$46,Payables!$E$19:$E$60,"<>Card",Payables!$F$19:$F$60,"Professional fees")+Assumptions!$B$33/5 -> 800 | H38: =SUMIFS(Payables!$D$19:$D$60,Payables!$G$19:$G$60,">="&Assumptions!$B$47,Payables!$G$19:$G$60,"<="&Assumptions!$C$47,Payables!$E$19:$E$60,"<>Card",Payables!$F$19:$F$60,"Professional fees")+Assumptions!$B$33/5 -> 800 | J38: =SUMIFS(Payables!$D$19:$D$60,Payables!$G$19:$G$60,">="&Assumptions!$B$48,Payables!$G$19:$G$60,"<="&Assumptions!$C$48,Payables!$E$19:$E$60,"<>Card",Payables!$F$19:$F$60,"Professional fees")+Assumptions!$B$33/5 -> 800 | L38: =SUM(B38,D38,F38,H38,J38) -> 9610 | M38: =SUM(C38,E38,G38,I38,K38) -> 0 | N38: =(C38-B38)*C$8+(E38-D38)*E$8+(G38-F38)*G$8+(I38-H38)*I$8+(K38-J38)*K$8 -> 0 | O38: 8020 Advisors retainer and Employsure, plus the estimate for accounting / legal.
A39: Dues & subscriptions | B39: =SUMIFS(Payables!$D$19:$D$60,Payables!$G$19:$G$60,">="&Assumptions!$B$44,Payables!$G$19:$G$60,"<="&Assumptions!$C$44,Payables!$E$19:$E$60,"<>Card",Payables!$F$19:$F$60,"Dues & subscriptions") -> 0 | D39: =SUMIFS(Payables!$D$19:$D$60,Payables!$G$19:$G$60,">="&Assumptions!$B$45,Payables!$G$19:$G$60,"<="&Assumptions!$C$45,Payables!$E$19:$E$60,"<>Card",Payables!$F$19:$F$60,"Dues & subscriptions") -> 2310 | F39: =SUMIFS(Payables!$D$19:$D$60,Payables!$G$19:$G$60,">="&Assumptions!$B$46,Payables!$G$19:$G$60,"<="&Assumptions!$C$46,Payables!$E$19:$E$60,"<>Card",Payables!$F$19:$F$60,"Dues & subscriptions") -> 0 | H39: =SUMIFS(Payables!$D$19:$D$60,Payables!$G$19:$G$60,">="&Assumptions!$B$47,Payables!$G$19:$G$60,"<="&Assumptions!$C$47,Payables!$E$19:$E$60,"<>Card",Payables!$F$19:$F$60,"Dues & subscriptions") -> 0 | J39: =SUMIFS(Payables!$D$19:$D$60,Payables!$G$19:$G$60,">="&Assumptions!$B$48,Payables!$G$19:$G$60,"<="&Assumptions!$C$48,Payables!$E$19:$E$60,"<>Card",Payables!$F$19:$F$60,"Dues & subscriptions") -> 0 | L39: =SUM(B39,D39,F39,H39,J39) -> 2310 | M39: =SUM(C39,E39,G39,I39,K39) -> 0 | N39: =(C39-B39)*C$8+(E39-D39)*E$8+(G39-F39)*G$8+(I39-H39)*I$8+(K39-J39)*K$8 -> 0 | O39: Non-card only (CEO Institute quarterly). Card subscriptions are in the credit card line.
A40: Telephone & internet | B40: =SUMIFS(Payables!$D$19:$D$60,Payables!$G$19:$G$60,">="&Assumptions!$B$44,Payables!$G$19:$G$60,"<="&Assumptions!$C$44,Payables!$E$19:$E$60,"<>Card",Payables!$F$19:$F$60,"Telephone & internet") -> 0 | D40: =SUMIFS(Payables!$D$19:$D$60,Payables!$G$19:$G$60,">="&Assumptions!$B$45,Payables!$G$19:$G$60,"<="&Assumptions!$C$45,Payables!$E$19:$E$60,"<>Card",Payables!$F$19:$F$60,"Telephone & internet") -> 804.11 | F40: =SUMIFS(Payables!$D$19:$D$60,Payables!$G$19:$G$60,">="&Assumptions!$B$46,Payables!$G$19:$G$60,"<="&Assumptions!$C$46,Payables!$E$19:$E$60,"<>Card",Payables!$F$19:$F$60,"Telephone & internet") -> 0 | H40: =SUMIFS(Payables!$D$19:$D$60,Payables!$G$19:$G$60,">="&Assumptions!$B$47,Payables!$G$19:$G$60,"<="&Assumptions!$C$47,Payables!$E$19:$E$60,"<>Card",Payables!$F$19:$F$60,"Telephone & internet") -> 0 | J40: =SUMIFS(Payables!$D$19:$D$60,Payables!$G$19:$G$60,">="&Assumptions!$B$48,Payables!$G$19:$G$60,"<="&Assumptions!$C$48,Payables!$E$19:$E$60,"<>Card",Payables!$F$19:$F$60,"Telephone & internet") -> 130 | L40: =SUM(B40,D40,F40,H40,J40) -> 934.11 | M40: =SUM(C40,E40,G40,I40,K40) -> 0 | N40: =(C40-B40)*C$8+(E40-D40)*E$8+(G40-F40)*G$8+(I40-H40)*I$8+(K40-J40)*K$8 -> 0 | O40: Optus mobiles BPAY, Telstra Nighthawk. Optus internet is on the card.
A41: Recruitment | B41: =SUMIFS(Payables!$D$19:$D$60,Payables!$G$19:$G$60,">="&Assumptions!$B$44,Payables!$G$19:$G$60,"<="&Assumptions!$C$44,Payables!$E$19:$E$60,"<>Card",Payables!$F$19:$F$60,"Recruitment")+Assumptions!$B$32/5 -> 1000 | D41: =SUMIFS(Payables!$D$19:$D$60,Payables!$G$19:$G$60,">="&Assumptions!$B$45,Payables!$G$19:$G$60,"<="&Assumptions!$C$45,Payables!$E$19:$E$60,"<>Card",Payables!$F$19:$F$60,"Recruitment")+Assumptions!$B$32/5 -> 1000 | F41: =SUMIFS(Payables!$D$19:$D$60,Payables!$G$19:$G$60,">="&Assumptions!$B$46,Payables!$G$19:$G$60,"<="&Assumptions!$C$46,Payables!$E$19:$E$60,"<>Card",Payables!$F$19:$F$60,"Recruitment")+Assumptions!$B$32/5 -> 1000 | H41: =SUMIFS(Payables!$D$19:$D$60,Payables!$G$19:$G$60,">="&Assumptions!$B$47,Payables!$G$19:$G$60,"<="&Assumptions!$C$47,Payables!$E$19:$E$60,"<>Card",Payables!$F$19:$F$60,"Recruitment")+Assumptions!$B$32/5 -> 1000 | J41: =SUMIFS(Payables!$D$19:$D$60,Payables!$G$19:$G$60,">="&Assumptions!$B$48,Payables!$G$19:$G$60,"<="&Assumptions!$C$48,Payables!$E$19:$E$60,"<>Card",Payables!$F$19:$F$60,"Recruitment")+Assumptions!$B$32/5 -> 1000 | L41: =SUM(B41,D41,F41,H41,J41) -> 5000 | M41: =SUM(C41,E41,G41,I41,K41) -> 0 | N41: =(C41-B41)*C$8+(E41-D41)*E$8+(G41-F41)*G$8+(I41-H41)*I$8+(K41-J41)*K$8 -> 0 | O41: Estimate. Seek ads go on the card.
A42: Insurance | B42: =Assumptions!$B$34/5 -> 600 | D42: =Assumptions!$B$34/5 -> 600 | F42: =Assumptions!$B$34/5 -> 600 | H42: =Assumptions!$B$34/5 -> 600 | J42: =Assumptions!$B$34/5 -> 600 | L42: =SUM(B42,D42,F42,H42,J42) -> 3000 | M42: =SUM(C42,E42,G42,I42,K42) -> 0 | N42: =(C42-B42)*C$8+(E42-D42)*E$8+(G42-F42)*G$8+(I42-H42)*I$8+(K42-J42)*K$8 -> 0 | O42: Estimate, ~$2.5k a month.
A43: Office, printing & amenities | B43: =SUMIFS(Payables!$D$19:$D$60,Payables!$G$19:$G$60,">="&Assumptions!$B$44,Payables!$G$19:$G$60,"<="&Assumptions!$C$44,Payables!$E$19:$E$60,"<>Card",Payables!$F$19:$F$60,"Office")+Assumptions!$B$35/5 -> 635.6 | D43: =SUMIFS(Payables!$D$19:$D$60,Payables!$G$19:$G$60,">="&Assumptions!$B$45,Payables!$G$19:$G$60,"<="&Assumptions!$C$45,Payables!$E$19:$E$60,"<>Card",Payables!$F$19:$F$60,"Office")+Assumptions!$B$35/5 -> 645 | F43: =SUMIFS(Payables!$D$19:$D$60,Payables!$G$19:$G$60,">="&Assumptions!$B$46,Payables!$G$19:$G$60,"<="&Assumptions!$C$46,Payables!$E$19:$E$60,"<>Card",Payables!$F$19:$F$60,"Office")+Assumptions!$B$35/5 -> 400 | H43: =SUMIFS(Payables!$D$19:$D$60,Payables!$G$19:$G$60,">="&Assumptions!$B$47,Payables!$G$19:$G$60,"<="&Assumptions!$C$47,Payables!$E$19:$E$60,"<>Card",Payables!$F$19:$F$60,"Office")+Assumptions!$B$35/5 -> 400 | J43: =SUMIFS(Payables!$D$19:$D$60,Payables!$G$19:$G$60,">="&Assumptions!$B$48,Payables!$G$19:$G$60,"<="&Assumptions!$C$48,Payables!$E$19:$E$60,"<>Card",Payables!$F$19:$F$60,"Office")+Assumptions!$B$35/5 -> 400 | L43: =SUM(B43,D43,F43,H43,J43) -> 2480.6 | M43: =SUM(C43,E43,G43,I43,K43) -> 0 | N43: =(C43-B43)*C$8+(E43-D43)*E$8+(G43-F43)*G$8+(I43-H43)*I$8+(K43-J43)*K$8 -> 0 | O43: Ricoh printing DD, Posh plants, plus the estimate.
A44: Electricity | B44: =SUMIFS(Payables!$D$19:$D$60,Payables!$G$19:$G$60,">="&Assumptions!$B$44,Payables!$G$19:$G$60,"<="&Assumptions!$C$44,Payables!$E$19:$E$60,"<>Card",Payables!$F$19:$F$60,"Electricity") -> 0 | D44: =SUMIFS(Payables!$D$19:$D$60,Payables!$G$19:$G$60,">="&Assumptions!$B$45,Payables!$G$19:$G$60,"<="&Assumptions!$C$45,Payables!$E$19:$E$60,"<>Card",Payables!$F$19:$F$60,"Electricity") -> 0 | F44: =SUMIFS(Payables!$D$19:$D$60,Payables!$G$19:$G$60,">="&Assumptions!$B$46,Payables!$G$19:$G$60,"<="&Assumptions!$C$46,Payables!$E$19:$E$60,"<>Card",Payables!$F$19:$F$60,"Electricity") -> 0 | H44: =SUMIFS(Payables!$D$19:$D$60,Payables!$G$19:$G$60,">="&Assumptions!$B$47,Payables!$G$19:$G$60,"<="&Assumptions!$C$47,Payables!$E$19:$E$60,"<>Card",Payables!$F$19:$F$60,"Electricity") -> 0 | J44: =SUMIFS(Payables!$D$19:$D$60,Payables!$G$19:$G$60,">="&Assumptions!$B$48,Payables!$G$19:$G$60,"<="&Assumptions!$C$48,Payables!$E$19:$E$60,"<>Card",Payables!$F$19:$F$60,"Electricity") -> 0 | L44: =SUM(B44,D44,F44,H44,J44) -> 0 | M44: =SUM(C44,E44,G44,I44,K44) -> 0 | N44: =(C44-B44)*C$8+(E44-D44)*E$8+(G44-F44)*G$8+(I44-H44)*I$8+(K44-J44)*K$8 -> 0 | O44: Energy Australia DDs the PL card so it shows in the credit card line, not here.
A45: Bank & merchant fees | B45: =Assumptions!$B$36/5 -> 200 | D45: =Assumptions!$B$36/5 -> 200 | F45: =Assumptions!$B$36/5 -> 200 | H45: =Assumptions!$B$36/5 -> 200 | J45: =Assumptions!$B$36/5 -> 200 | L45: =SUM(B45,D45,F45,H45,J45) -> 1000 | M45: =SUM(C45,E45,G45,I45,K45) -> 0 | N45: =(C45-B45)*C$8+(E45-D45)*E$8+(G45-F45)*G$8+(I45-H45)*I$8+(K45-J45)*K$8 -> 0 | O45: Estimate - bank charges and Stripe.
A46: Credit card settlements (card spend, all categories) | B46: =Assumptions!$B$37/5 -> 5000 | D46: =Assumptions!$B$37/5 -> 5000 | F46: =Assumptions!$B$37/5 -> 5000 | H46: =Assumptions!$B$37/5 -> 5000 | J46: =Assumptions!$B$37/5 -> 5000 | L46: =SUM(B46,D46,F46,H46,J46) -> 25000 | M46: =SUM(C46,E46,G46,I46,K46) -> 0 | N46: =(C46-B46)*C$8+(E46-D46)*E$8+(G46-F46)*G$8+(I46-H46)*I$8+(K46-J46)*K$8 -> 0 | O46: ~$25k a month transferred to the PL and DL cards. Covers every Card row on the Payables tab (subscriptions, travel, electricity, Seek, Goget, EH).
...

Sheet Assumptions
A1: CTS Cash Flow Forecast - Assumptions & Inputs
A2: Blue = change it if you need to. Black = formula, leave it alone. Bright yellow = the ones I still want to double check. Everything is GST inclusive because that's what actually hits the bank.
A4: TIMING & OPENING POSITION
A5: Forecast start (Monday of this week) | B5: 46293 | C5: Mon 28 Sep. Week 1 runs through to Wed 7 Oct so it picks up the pay run and payroll tax, then it's weekly from there (Thu to Wed). Week table is at the bottom of this tab.
A6: Opening bank balance - cheque + savings | B6: =25155+410000 -> 435155 | C6: Cheque $25,155 + savings $410,000 at 28 Sep. Not counting the other accounts - they're not there for day to day. Payroll comes out of cheque, topped up from savings, so check the cheque balance before every pay run.
A7: Number of weeks | B7: 5 | C7: Each week has a Forecast and an Actual column on the Cash Flow tab.
A8: PAYROLL (fortnightly, paid Tuesday of processing week)
A9: Gross wages per fortnight | B9: 111000 | C9: Average of the last three runs we know: 11 Aug $108,325, 25 Aug $115,340 (GL journals #69396, #69669) and the two Sep runs $217,062 between them (Xero cash P&L to 28 Sep). Detail on the Payroll tab.
A10: Net pay as % of gross | B10: 0.768 | C10: 25 Aug run - gross $115.3k, ABA file $88.5k = 76.8% (Part 6 video, 03:16-04:12). The gap is PAYG and sal sac.
A11: PAYG withheld as % of gross | B11: =1-B10 -> 0.232 | C11: 1 less net %. Goes to the ATO with the IAS/BAS, not on pay day.
A12: Superannuation as % of gross | B12: 0.12 | C12: SG is 12%. 25 Aug: $13,677 SG on $115,340 gross. Sal sac super (~$1k a run) goes out in the same super batch but comes off gross, so it's not added on here.
A13: Employee reimbursements per pay run (expense claims) | B13: 1000 | C13: Placeholder - I can't see expense claims in Xero. Per diems ($75 a night) go through payroll so they're already in net pay. Put the usual expense claim amount in here.
A14: Pay date - run 1 (fortnight ending Fri 2 Oct) | B14: 46301 | C14: Always the Tuesday of processing week (Part 2 video, Checklist step 13). Mon 5 Oct is a PH so run 1 has to be done and uploaded on Fri 2 Oct. Super direct debits the same week (step 69) - payday super since 1 Jul 26.
A15: Pay date - run 2 (fortnight ending Fri 16 Oct) | B15: 46315 | C15: Tue 20 Oct.
A16: Pay date - run 3 (fortnight ending Fri 30 Oct) | B16: 46329 | C16: Tue 3 Nov (FE 30 Oct). Only hits the forecast if the week table runs that far - it does at the moment.
A17: Payroll tax NSW - September return (due 7 Oct) | B17: 6295 | C17: Sep return isn't lodged yet so I've used Aug: $6,120.40 + $174.67 (GL #69671, #70351). Due the 7th of the following month. Update once it's lodged.
A18: Payroll tax other states (ACT/QLD/SA/VIC/WA) - Sep (due 7 Oct) | B18: 2700 | C18: Aug actual $2,700 (GL #69670), July was $3,000. All due on the 7th too.
A19: Payroll tax payment date | B19: 46302 | C19: Wed 7 Oct.
A20: BAS / PAYG WITHHOLDING
A21: Q1 BAS paid inside this forecast? (1 = yes, 0 = no) | B21: 1 | C21: 1 = we lodge it ourselves and pay 28 Oct (week 4). 0 = through the agent, 25 Nov, outside the forecast.
A22: Sep PAYG withholding (goes on the Q1 BAS) | B22: =B11*217062 -> 50358.384 | C22: PAYG % x Sep gross $217,062 (Xero cash P&L). Jul and Aug went on the IAS (21 Aug, 21 Sep) so nothing falls in Oct.
A23: Net GST payable for Sep quarter - ESTIMATE | B23: 50000 | C23: Rough guess - GST on ~$1.5m in, less GST on ~$1.0m out. Replace with the activity statement figure from Xero.
A24: PAYG income-tax instalment for Sep quarter | B24: 0 | C24: Can't see this in Xero. Put the ATO instalment in here if there is one.
A25: BAS payment date if paid in October | B25: 46323 | C25: 28 Oct as we lodge it ourselves.
A26: COSTS NOT BILLED YET - MONTHLY ESTIMATES (spread over the 5 weeks)
A27: Sub-contract labour | B27: 40000 | C27: Sep cash P&L: Integration $31,990 + PRD $7,154. Oct work that gets billed and paid inside the month.
A28: Equipment & service hires | B28: 30000 | C28: Sep cash P&L: service hires $17,344 + equipment hires $11,427.
A29: Project equipment purchases (not yet billed) | B29: 20000 | C29: On top of the Complete AV / Crestron / Fredon bills already listed. Oct is a big Production month in the budget ($587k income) so this could easily be higher.
A30: Direct travel & freight (client jobs) | B30: 7000 | C30: Sep: ONS travel $4,120 + PRD $1,572 + ~$1,300 freight.
A31: Client subscriptions & licences (not yet billed) | B31: 3000 | C31: Sep: $3,573 outside the Appspace / Spacera / Eptura bills.
A32: Recruitment (Seek, LinkedIn, agency) | B32: 5000 | C32: Sep was $11,742 with the casual concierge campaign. I've assumed half that.
A33: Accounting, legal & advisory (beyond the 8020 retainer) | B33: 4000 | C33: Jun-Aug: accounting $7,733 + legal $2,900 over 3 months.
A34: Insurance | B34: 3000 | C34: Jun-Aug: other insurance $5,073 + workers comp $2,336 over 3 months, call it $2.5k a month.
A35: Office, amenities & entertainment | B35: 2000 | C35: Jun-Aug ran ~$4k a month across amenities, supplies and staff entertainment. Sep was lower.
A36: Bank & merchant fees | B36: 1000 | C36: Sep: bank charges $2,311 + Stripe $271, but Sep had a one-off in it.
A37: Credit card settlements per month (PL + DL cards) | B37: 25000 | C37: Sep transfers to the cards: $15,000 + $4,224.75 (PL) + $5,718.88 (DL) = $24,944. Covers every bill marked paid via CC - those are left out of the Payables totals so nothing gets counted twice.
A38: RECEIPTS - ESTIMATES
A39: October-dated invoices collected within October | B39: 20000 | C39: Sep: invoices raised and paid in the same month (Ubank $10,867, RSNSW $3,587, CSIRO $1,971, Garvan, Elkiem, Bankwest event, St Vincent's) came to ~$20k. Spread over weeks 3-5.
A40: Interest received on savings | B40: 600 | C40: Sep was $648.92. Lands at month end.
A42: WEEK TABLE (calculated)
...

Sheet Payroll
A1: Payroll schedule - October 2026
A2: Fortnightly. Pay date is the Tuesday of processing week. Super direct debits the same week. PAYG goes later with the IAS/BAS.
A4: Pay run | B4: Fortnight ending | C4: Pay date | D4: Gross wages | E4: Net pay (ABA file) | F4: PAYG withheld | G4: Super (direct debit) | H4: Reimbursements | I4: Cash out on payday (net + super + reimb.) | J4: Notes
A5: Run 1 - Oct | B5: 46297 | C5: =Assumptions!$B$14 -> 46301 | D5: =Assumptions!$B$9 -> 111000 | E5: =D5*Assumptions!$B$10 -> 85248 | F5: =D5*Assumptions!$B$11 -> 25752 | G5: =D5*Assumptions!$B$12 -> 13320 | H5: =Assumptions!$B$13 -> 1000 | I5: =E5+G5+H5 -> 99568 | J5: FE Fri 2 Oct. Mon 5 Oct is a PH so the whole thing gets done on Fri 2 Oct - chase approvals first thing, reconcile, finalise with Graham, ABA into CommBiz, payroll email to Duncan. Move the funds from savings on the Friday. Paid Tue 6 Oct.
A6: Run 2 - Oct | B6: 46311 | C6: =Assumptions!$B$15 -> 46315 | D6: =Assumptions!$B$9 -> 111000 | E6: =D6*Assumptions!$B$10 -> 85248 | F6: =D6*Assumptions!$B$11 -> 25752 | G6: =D6*Assumptions!$B$12 -> 13320 | H6: =Assumptions!$B$13 -> 1000 | I6: =E6+G6+H6 -> 99568 | J6: Last run of the month - accrue bonus leave (Checklist step 48). No cash effect.
A7: Run 3 - Nov | B7: 46325 | C7: =Assumptions!$B$16 -> 46329 | D7: =Assumptions!$B$9 -> 111000 | E7: =D7*Assumptions!$B$10 -> 85248 | F7: =D7*Assumptions!$B$11 -> 25752 | G7: =D7*Assumptions!$B$12 -> 13320 | H7: =Assumptions!$B$13 -> 1000 | I7: =E7+G7+H7 -> 99568 | J7: FE 30 Oct, paid Tue 3 Nov. Only counts if the week table runs to 3 Nov.
A8: Total pay runs listed | D8: =SUM(D5:D7) -> 333000 | E8: =SUM(E5:E7) -> 255744 | F8: =SUM(F5:F7) -> 77256 | G8: =SUM(G5:G7) -> 39960 | H8: =SUM(H5:H7) -> 3000 | I8: =SUM(I5:I7) -> 298704
A9: Payroll tax for September wages (paid October)
A10: NSW - due 7 Oct | B10: =Assumptions!$B$17 -> 6295 | C10: =Assumptions!$B$19 -> 46302
A11: Other states - due 7 Oct | B11: =Assumptions!$B$18 -> 2700 | C11: =Assumptions!$B$19 -> 46302
A12: Total payroll tax | B12: =B10+B11 -> 8995
A13: Payroll tax on Oct wages is due 7 Nov - after this forecast.
A15: Reference - actual pay runs this financial year
A16: Pay run | B16: Pay date | C16: Gross wages | D16: Super batch (SG + salary sacrifice) | E16: Batch % of gross | F16: Source
A17: FE 10 Jul | B17: 46217 | C17: 104335.03 | D17: 13289.41 | E17: =IF(C17=0,0,D17/C17) -> 0.12737247 | F17: Controller Pack GL_Paste journals #69527 / #69434
A18: FE 24 Jul | B18: 46231 | C18: 101030.18 | D18: 13068.87 | E18: =IF(C18=0,0,D18/C18) -> 0.1293561 | F18: GL journals #68743 / #68744
A19: FE 7 Aug | B19: 46245 | C19: 108324.58 | D19: 13783.25 | E19: =IF(C19=0,0,D19/C19) -> 0.12724028 | F19: GL journals #69396 / #69397
A20: FE 21 Aug | B20: 46259 | C20: 115339.8 | D20: 14677.93 | E20: =IF(C20=0,0,D20/C20) -> 0.12725815 | F20: GL journals #69669 / #69663 (the run in the training videos)
A21: FE 4 Sep + FE 18 Sep (two runs) | B21: 46287 | C21: 217061.76 | D21: 27815.63 | E21: =IF(C21=0,0,D21/C21) -> 0.12814616 | F21: Xero cash P&L 1-28 Sep: all salaries & wages accounts; direct + indirect super
A22: Average gross per fortnight (last 4 fortnights) | B22: =(C19+C20+C21)/4 -> 110181.54 | C22: Aug runs plus the two Sep runs, over four fortnights
A23: SG is 12%. The batch % above is higher because the GL super accounts include sal sac super (25 Aug: $13,677 SG + $1,052 sal sac). Forecast uses 12% - the sal sac part comes off gross so it isn't counted twice.
A25: Reference - payroll tax accruals this financial year
A26: Month | B26: NSW | C26: Other states | D26: Total | E26: Source
A27: July 2026 | B27: 5170.8 | C27: 3000 | D27: =B27+C27 -> 8170.8 | E27: GL journals #68926 (NSW) and #68927 (other states)
A28: August 2026 | B28: 6295.07 | C28: 2700 | D28: =B28+C28 -> 8995.07 | E28: GL journals #69671 + #70351 (NSW) and #69670 (other states)
A29: Budget has payroll tax at ~$7.4k a month but actuals are running ~$9k, so I've used actuals.

Sheet Receivables
A1: Receivables - every open invoice and when the cash is expected
A2: Xero aged receivables at 28 Sep ($580,292.39, 38 invoices) plus the Sep contract invoices we still have to raise (from the repeating templates). Expected date (blue) is my call based on how each customer has been paying - change it and the forecast moves.
A4: Customer | B4: Invoice | C4: Reference | D4: Invoice date | E4: Due date | F4: Amount (incl GST) | G4: Status | H4: Expected receipt date | I4: Days after due | J4: Week | K4: Why that date
A5: APT Management Services (APA) | B5: INV-10622 | C5: PO-00030884 | D5: 46275 | E5: 46305 | F5: 4352.45 | G5: Current | H5: 46304 | I5: =H5-E5 -> -1 | J5: =IF(H5<Assumptions!$B$5,"Before",IF(H5>Assumptions!$C$48,"After",INT((H5-Assumptions!$B$5)/7)+1)) -> 2 | K5: APA paid the last one the day after we sent it
A6: APT Management Services (APA) | B6: INV-10628 | C6: APA RUOK Event 10.09.2026 | D6: 46281 | E6: 46311 | F6: 627 | G6: Current | H6: 46311 | I6: =H6-E6 -> 0 | J6: =IF(H6<Assumptions!$B$5,"Before",IF(H6>Assumptions!$C$48,"After",INT((H6-Assumptions!$B$5)/7)+1)) -> 3 | K6: On the due date
A7: ASX Operations | B7: INV-10599 | C7: ASX Employee Town Hall 13.08.2026 | D7: 46261 | E7: 46291 | F7: 1661 | G7: Overdue | H7: 46297 | I7: =H7-E7 -> 6 | J7: =IF(H7<Assumptions!$B$5,"Before",IF(H7>Assumptions!$C$48,"After",INT((H7-Assumptions!$B$5)/7)+1)) -> 1 | K7: ASX paid the Aug ones ~4 days late
A8: ASX Operations | B8: INV-10624 | C8: ASX CEO Connect Series 01.09.2026 | D8: 46280 | E8: 46310 | F8: 4591.4 | G8: Current | H8: 46311 | I8: =H8-E8 -> 1 | J8: =IF(H8<Assumptions!$B$5,"Before",IF(H8>Assumptions!$C$48,"After",INT((H8-Assumptions!$B$5)/7)+1)) -> 3 | K8: Due date plus a day
A9: ASX Operations | B9: INV-10623 | C9: ASX Live 01.09.2026 | D9: 46280 | E9: 46310 | F9: 8544.8 | G9: Current | H9: 46311 | I9: =H9-E9 -> 1 | J9: =IF(H9<Assumptions!$B$5,"Before",IF(H9>Assumptions!$C$48,"After",INT((H9-Assumptions!$B$5)/7)+1)) -> 3 | K9: Due date plus a day
A10: Australian Payments Network | B10: INV-10574 | C10: Logitech room licence renewal | D10: 46254 | E10: 46284 | F10: 1092.3 | G10: Overdue | H10: 46297 | I10: =H10-E10 -> 13 | J10: =IF(H10<Assumptions!$B$5,"Before",IF(H10>Assumptions!$C$48,"After",INT((H10-Assumptions!$B$5)/7)+1)) -> 1 | K10: Small and overdue - chase this week
A11: Aware Super | B11: INV-10583 | C11: Annual National Maintenance (Aug) | D11: 46265 | E11: 46295 | F11: 12100 | G11: Current | H11: 46295 | I11: =H11-E11 -> 0 | J11: =IF(H11<Assumptions!$B$5,"Before",IF(H11>Assumptions!$C$48,"After",INT((H11-Assumptions!$B$5)/7)+1)) -> 1 | K11: Aware pay on the due date
A12: Aware Super | B12: INV-10596 | C12: Seminar Room AV Upgrade | D12: 46274 | E12: 46304 | F12: 225887.4 | G12: Current | H12: 46304 | I12: =H12-E12 -> 0 | J12: =IF(H12<Assumptions!$B$5,"Before",IF(H12>Assumptions!$C$48,"After",INT((H12-Assumptions!$B$5)/7)+1)) -> 2 | K12: THE BIG ONE. Complete AV materials ($136,163) is going out this week ahead of it - chase Aware so it lands on time.
A13: Aware Super | B13: INV-10635 | C13: Appspace licensing subscription (12 months) | D13: 46283 | E13: 46313 | F13: 23317.11 | G13: Current | H13: 46311 | I13: =H13-E13 -> -2 | J13: =IF(H13<Assumptions!$B$5,"Before",IF(H13>Assumptions!$C$48,"After",INT((H13-Assumptions!$B$5)/7)+1)) -> 3 | K13: Due Sun 18 Oct so Fri 16 Oct. Covers the Appspace bill ($20,985) due 24 Oct.
A14: Aware Super | B14: INV-10646 | C14: Perth office BYOD USB-C replacement | D14: 46289 | E14: 46319 | F14: 3252.7 | G14: Current | H14: 46318 | I14: =H14-E14 -> -1 | J14: =IF(H14<Assumptions!$B$5,"Before",IF(H14>Assumptions!$C$48,"After",INT((H14-Assumptions!$B$5)/7)+1)) -> 4 | K14: Due Sat 24 Oct - call it Fri 23 Oct
A15: Aware Super | B15: INV-10619 | C15: Sydney 24.16 UC Engine remediation variation | D15: 46290 | E15: 46320 | F15: 738.1 | G15: Current | H15: 46318 | I15: =H15-E15 -> -2 | J15: =IF(H15<Assumptions!$B$5,"Before",IF(H15>Assumptions!$C$48,"After",INT((H15-Assumptions!$B$5)/7)+1)) -> 4 | K15: Due Sun 25 Oct - call it Fri 23 Oct
A16: Downer EDI | B16: INV-10587 | C16: Full Year Results Briefing 20.08.2026 | D16: 46259 | E16: 46289 | F16: 12808.69 | G16: Overdue | H16: 46297 | I16: =H16-E16 -> 8 | J16: =IF(H16<Assumptions!$B$5,"Before",IF(H16>Assumptions!$C$48,"After",INT((H16-Assumptions!$B$5)/7)+1)) -> 1 | K16: 4 days overdue - should land this week
... A52: Aware Super | B52: TBR | C52: Annual National Maintenance - September | D52: 46295 | E52: 46325 | F52: 12100 | G52: To be raised | H52: 46325 | I52: =H52-E52 -> 0 | J52: =IF(H52<Assumptions!$B$5,"Before",IF(H52>Assumptions!$C$48,"After",INT((H52-Assumptions!$B$5)/7)+1)) -> 5 | K52: Aware pay on the due date
A53: TOTAL | F53: =SUM(F5:F52) -> 806505.13
A54: of which open in Xero at 28 Sep (should be $580,292.39) | F54: =SUMIFS(F5:F52,G5:G52,"<>To be raised") -> 580292.39
A55: of which expected inside the forecast | F55: =SUMIFS(F5:F52,H5:H52,">="&Assumptions!$B$5,H5:H52,"<="&Assumptions!$C$48) -> 760733.91
A56: of which pushed past the forecast (PwC Sep invoices, Meet Magic, Property NSW) | F56: =F53-F55 -> 45771.22

Sheet Payables
A1: Payables - every open bill, plus October's recurring bills not yet in Xero
A2: Xero aged payables at 28 Sep ($283,042.53, 24 bills - Complete AV split per the 28 Sep meeting) plus the repeating bill templates for Oct. Card rows get paid on the PL/DL cards and sit in the credit card line on the Cash Flow tab, so they're left out of the category totals. The P&L category decides which line each bill lands on.
A4: PAYMENTS THIS WEEK (28 Sep - 7 Oct)
A5: Supplier | B5: Bill / reference | C5: Due date | D5: Amount (incl GST) | E5: Method | F5: Status | G5: Pay on | J5: Notes
A6: =A20 -> Complete AV Solutions | B6: =B20 -> INV41565 - Aware seminar room: MATERIALS portion (hardware, cables, freight, waste, net of the $4,848.68 claim-balance reduction) | C6: =C20 -> 46291 | D6: =D20 -> 136163.28 | E6: =E20 -> EFT | F6: AGREED - PAY | G6: =G20 -> 46295 | J6: Agreed 28 Sep meeting. Pay date comes from the Complete AV tab.
A7: =A23 -> Employsure | B7: =B23 -> 41 of 60 | C7: =C23 -> 46271 | D7: =D23 -> 880 | E7: =E23 -> EFT | F7: Due this week | G7: =G23 -> 46296 | J7: Routine - on the due date
A8: =A26 -> Eptura Australia | B8: =B26 -> INV-85230 - Proxyclick renewal APA VMS yr 2 | C8: =C26 -> 46296 | D8: =D26 -> 3627.04 | E8: =E26 -> EFT | F8: Due this week | G8: =G26 -> 46296 | J8: Routine - on the due date
A9: =A28 -> Fredon Technology | B9: =B28 -> INV11S-26080021 - DTTL 8PSQ Dream Big microphones | C9: =C28 -> 46288 | D9: =D28 -> 24708.2 | E9: =E28 -> EFT | F9: AWAITING DH | G9: =G28 -> 46302 | J9: Bill says DH to confirm - don't pay until he does.
A10: =A35 -> Ricoh Australia | B10: =B35 -> INV15759052 - printing Aug | C10: =C35 -> 46295 | D10: =D35 -> 235.6 | E10: =E35 -> DD | F10: Due this week | G10: =G35 -> 46295 | J10: Routine - on the due date
A11: =A36 -> RJW Group Holdings | B11: =B36 -> INV-0048 - website design balance | C11: =C36 -> 46295 | D11: =D36 -> 6600 | E11: =E36 -> EFT | F11: AWAITING DL | G11: =G36 -> 46297 | J11: Bill says check with DL before paying.
A12: =A38 -> SPACERA | B12: =B38 -> INV-0056 - Aware Super national support (Sep) | C12: =C38 -> 46296 | D12: =D38 -> 5728.8 | E12: =E38 -> EFT | F12: Due this week | G12: =G38 -> 46296 | J12: Routine - on the due date
A13: =A47 -> Cleveland Partners (8020 Advisors) | B13: =B47 -> Monthly advisory fees | C13: =C47 -> 46302 | D13: =D47 -> 3850 | E13: =E47 -> EFT | F13: Due this week | G13: =G47 -> 46302 | J13: Routine - on the due date
A14: =A50 -> Employsure | B14: =B50 -> 42 of 60 - October | C14: =C50 -> 46300 | D14: =D50 -> 880 | E14: =E50 -> EFT | F14: Due this week | G14: =G50 -> 46300 | J14: Routine - on the due date
A15: Total this week | D15: =SUM(D6:D14) -> 182672.92
A16: of which agreed / routine (excludes the two awaiting sign-off) | D16: =SUMIFS(D6:D14,F6:F14,"AGREED - PAY")+SUMIFS(D6:D14,F6:F14,"Due this week") -> 151364.72
A17: ALL OPEN BILLS AND OCTOBER TEMPLATES
A18: Supplier | B18: Bill / reference | C18: Due date | D18: Amount (incl GST) | E18: Method | F18: P&L category | G18: Planned payment date | H18: Week | I18: Source | J18: Notes
A19: Appspace, Inc. | B19: INV00133660 - Appspace licensing for Aware Super | C19: 46319 | D19: 20985.43 | E19: EFT | F19: Client subscriptions | G19: 46318 | H19: =IF(G19<Assumptions!$B$5,"Before",IF(G19>Assumptions!$C$48,"After",INT((G19-Assumptions!$B$5)/7)+1)) -> 4 | I19: Xero bill | J19: Pay once Aware's Appspace invoice INV-10635 ($23,317) is in (expected 16 Oct)
A20: Complete AV Solutions | B20: INV41565 - Aware seminar room: MATERIALS portion (hardware, cables, freight, waste, net of the $4,848.68 claim-balance reduction) | C20: 46291 | D20: ='Complete AV'!$D$44 -> 136163.28 | E20: EFT | F20: Equipment purchases | G20: ='Complete AV'!$D$46 -> 46295 | H20: =IF(G20<Assumptions!$B$5,"Before",IF(G20>Assumptions!$C$48,"After",INT((G20-Assumptions!$B$5)/7)+1)) -> 1 | I20: Xero bill | J20: AGREED 28 Sep (Graham / Jordan): pay the materials now, hold labour until Aware sign off. Build-up is on the Complete AV tab - amount and date come from there.
A21: Complete AV Solutions | B21: INV41565 - Aware seminar room: LABOUR & PROGRAMMING portion - HELD | C21: 46291 | D21: ='Complete AV'!$D$55 -> 41955.98 | E21: EFT | F21: Equipment purchases | G21: 46356 | H21: =IF(G21<Assumptions!$B$5,"Before",IF(G21>Assumptions!$C$48,"After",INT((G21-Assumptions!$B$5)/7)+1)) -> After | I21: Xero bill | J21: HELD until Aware sign off and we get the handover docs (marked up drawings, training docs). Detail on the Complete AV tab. Dated past the forecast so it's excluded.
A22: Crestron ANZ | B22: INV950936412 - Aware SYD 28.06 equipment | C22: 46314 | D22: 7103.26 | E22: EFT | F22: Equipment purchases | G22: 46314 | H22: =IF(G22<Assumptions!$B$5,"Before",IF(G22>Assumptions!$C$48,"After",INT((G22-Assumptions!$B$5)/7)+1)) -> 4 | I22: Xero bill | J22: On the due date
A23: Employsure | B23: 41 of 60 | C23: 46271 | D23: 880 | E23: EFT | F23: Professional fees | G23: 46296 | H23: =IF(G23<Assumptions!$B$5,"Before",IF(G23>Assumptions!$C$48,"After",INT((G23-Assumptions!$B$5)/7)+1)) -> 1 | I23: Xero bill | J23: Overdue - pay this week
A24: Energy Australia | B24: INV260382065288 - energy 23 Jul-22 Aug | C24: 46294 | D24: 377.13 | E24: Card | F24: Electricity | G24: 46294 | H24: =IF(G24<Assumptions!$B$5,"Before",IF(G24>Assumptions!$C$48,"After",INT((G24-Assumptions!$B$5)/7)+1)) -> 1 | I24: Xero bill | J24: DD via the PL card
A25: Energy Australia | B25: INV260412412804 - electricity 23 Aug-21 Sep | C25: 46309 | D25: 696.25 | E25: Card | F25: Electricity | G25: 46309 | H25: =IF(G25<Assumptions!$B$5,"Before",IF(G25>Assumptions!$C$48,"After",INT((G25-Assumptions!$B$5)/7)+1)) -> 3 | I25: Xero bill | J25: DD via the PL card
A26: Eptura Australia | B26: INV-85230 - Proxyclick renewal APA VMS yr 2 | C26: 46296 | D26: 3627.04 | E26: EFT | F26: Client subscriptions | G26: 46296 | H26: =IF(G26<Assumptions!$B$5,"Before",IF(G26>Assumptions!$C$48,"After",INT((G26-Assumptions!$B$5)/7)+1)) -> 1 | I26: Xero bill | J26: On the due date
A27: Expedia | B27: ITN73550041732636 - accommodation D Hurley | C27: 46287 | D27: 808.95 | E27: Card | F27: Direct travel & freight | G27: 46287 | H27: =IF(G27<Assumptions!$B$5,"Before",IF(G27>Assumptions!$C$48,"After",INT((G27-Assumptions!$B$5)/7)+1)) -> Before | I27: Xero bill | J27: Went on the PL card last time
A28: Fredon Technology | B28: INV11S-26080021 - DTTL 8PSQ Dream Big microphones | C28: 46288 | D28: 24708.2 | E28: EFT | F28: Equipment purchases | G28: 46302 | H28: =IF(G28<Assumptions!$B$5,"Before",IF(G28>Assumptions!$C$48,"After",INT((G28-Assumptions!$B$5)/7)+1)) -> 2 | I28: Xero bill | J28: Overdue - DH to confirm. Assume it's released week 2
A29: Investa Asset Management | B29: INV5310034149 - Rent September 2026 (incl. pest) | C29: 46317 | D29: 29280.72 | E29: EFT | F29: Rent | G29: 46317 | H29: =IF(G29<Assumptions!$B$5,"Before",IF(G29>Assumptions!$C$48,"After",INT((G29-Assumptions!$B$5)/7)+1)) -> 4 | I29: Xero bill | J29: On the due date. Oct rent gets invoiced ~22 Oct, due ~22 Nov
A30: Mailchimp | B30: MC27286583 - September | C30: 46283 | D30: 37.62 | E30: Card | F30: Dues & subscriptions | G30: 46283 | H30: =IF(G30<Assumptions!$B$5,"Before",IF(G30>Assumptions!$C$48,"After",INT((G30-Assumptions!$B$5)/7)+1)) -> Before | I30: Xero bill | J30: PL card
A31: Optus | B31: INV000594614144 - office internet & landline Sep | C31: 46288 | D31: 629.66 | E31: Card | F31: Telephone & internet | G31: 46288 | H31: =IF(G31<Assumptions!$B$5,"Before",IF(G31>Assumptions!$C$48,"After",INT((G31-Assumptions!$B$5)/7)+1)) -> Before | I31: Xero bill | J31: PL card
A32: Optus | B32: INV000594999543 - staff mobiles Sep | C32: 46307 | D32: 804.11 | E32: BPAY | F32: Telephone & internet | G32: 46307 | H32: =IF(G32<Assumptions!$B$5,"Before",IF(G32>Assumptions!$C$48,"After",INT((G32-Assumptions!$B$5)/7)+1)) -> 3 | I32: Xero bill | J32: BPAY on the due date
A33: Persona Health | B33: INV-18315 - fitness for duty assessment | C33: 46275 | D33: 996.6 | E33: EFT | F33: Other | G33: 46316 | H33: =IF(G33<Assumptions!$B$5,"Before",IF(G33>Assumptions!$C$48,"After",INT((G33-Assumptions!$B$5)/7)+1)) -> 4 | I33: Xero bill | J33: GC said hold until he confirms. Assumed released week 4
... A60: Optus | B60: Staff mobiles - October | C60: 46334 | D60: 804.06 | E60: BPAY | F60: Telephone & internet | G60: 46334 | H60: =IF(G60<Assumptions!$B$5,"Before",IF(G60>Assumptions!$C$48,"After",INT((G60-Assumptions!$B$5)/7)+1)) -> After | I60: Repeating template | J60: Due 8 Nov - after this forecast
A61: TOTAL open bills in Xero (should be $283,042.53) | D61: =SUMIFS(D19:D60,I19:I60,"Xero bill") -> 283042.54
A62: of which paid by card (left out - see the credit card line) | D62: =SUMIFS(D19:D60,E19:E60,"Card",I19:I60,"Xero bill") -> 3728.52
A63: Templates (non-card) inside the forecast | D63: =SUMIFS(D19:D60,I19:I60,"Repeating template",E19:E60,"<>Card",G19:G60,">="&Assumptions!$B$5,G19:G60,"<="&Assumptions!$C$48) -> 33525.07
A64: Non-card bills dated past the forecast (Complete AV labour hold, Oct rent, Oct mobiles) | D64: =SUMIFS(D19:D60,E19:E60,"<>Card",G19:G60,">"&Assumptions!$C$48) -> 72040.76

Sheet Complete AV
A1: Complete AV Solutions - INV41565 - what we're paying and what's held
A2: Aware Super seminar room audio upgrade (Q-12140v1, PO-00016902). Bill total $178,119.25 inc GST, dated 1 Sep, due 26 Sep. Agreed 28 Sep (Graham / Jordan): pay the materials now, hold labour and programming until Aware sign off and we get the handover docs. Line items are straight off the bill in Xero.
A4: Line on the bill | B4: Qty | C4: Unit (ex GST) | D4: Amount (ex GST) | E4: Notes
A5: Hardware
A6: Crestron DM-NVX-E30 4K network AV encoder | B6: 6 | C6: 1345.56 | D6: =B6*C6 -> 8073.36
A7: Crestron DM-NVX-385 AV-over-IP switcher | B7: 2 | C7: 3390.25 | D7: =B7*C7 -> 6780.5
A8: Crestron DM-NVX-360 encoder/decoder | B8: 8 | C8: 2144.14 | D8: =B8*C8 -> 17153.12
A9: Panasonic AW-UE40 4K integrated camera | B9: 4 | C9: 4063.96 | D9: =B9*C9 -> 16255.84
A10: Crestron UC-C100-T Teams Rooms integrator kit | B10: 2 | C10: 5350.41 | D10: =B10*C10 -> 10700.82
A11: Q-SYS Core 24f DSP | B11: 2 | C11: 8295.67 | D11: =B11*C11 -> 16591.34
A12: Crestron DM-NAX Bluetooth audio wall plate | B12: 2 | C12: 815.49 | D12: =B12*C12 -> 1630.98
A13: Crestron FP-G1-B-T face plate | B13: 2 | C13: 21 | D13: =B13*C13 -> 42
A14: Crestron TSS-880 room scheduling touch screen | B14: 2 | C14: 1223.23 | D14: =B14*C14 -> 2446.46
A15: Crestron TSW-1080 wall mount touch screen | B15: 2 | C15: 3186.38 | D15: =B15*C15 -> 6372.76
A16: Crestron CP4N control system | B16: 1 | C16: 3032.23 | D16: =B16*C16 -> 3032.23
A17: Netgear M4250 PoE+ managed switch | B17: 2 | C17: 3179.58 | D17: =B17*C17 -> 6359.16
... A30: Less: removed camera Crestron decoder | B30: 1 | C30: -4600.2 | D30: =B30*C30 -> -4600.2
A31: Hardware subtotal | D31: =SUM(D6:D30) -> 124463.51
A32: Consumables and delivery
A33: Cables, fixings and hardware (4 lines: $1,515.30 + $696.24 + $934.08 + $691.60) | D33: 3837.22
A34: Freight & handling (3 lines: $100.00 + $53.20 + $59.85) | D34: 213.05
A35: E-waste / waste management (3 lines: $59.85 + $39.90 + $19.95) | D35: 119.7
A36: Consumables subtotal | D36: =SUM(D33:D35) -> 4169.97
A40: Materials subtotal (ex GST) | D40: =D31+D36 -> 128633.48
A41: Less: Complete AV's own line 'Remaining claim balance $4,848.68 to be invoiced' | D41: -4848.68 | E41: Their reduction, not allocated to anything. Taken off the part we're paying now - conservative. If you'd rather take it off the held labour, pay $141,496.83 and hold $36,622.43.
A42: Materials net (ex GST) | D42: =D40+D41 -> 123784.8
A43: GST 10% | D43: =ROUND(D42*0.1,2) -> 12378.48
A44: PAYING NOW (incl GST) | D44: =D42+D43 -> 136163.28
A46: Pay on | D46: 46295
A48: HELD - labour and programming (until Aware sign off + handover docs)
A49: Labour & programming | D49: 23320
A50: Labour | D50: 7196
A51: Labour | D51: 6561.8
A52: Lighting integration programming (coded to equipment in Xero, but it's programming) | D52: 1064
A53: Held (ex GST) | D53: =SUM(D49:D52) -> 38141.8
A54: GST 10% | D54: =ROUND(D53*0.1,2) -> 3814.18
A55: HELD (incl GST) | D55: =D53+D54 -> 41955.98
A57: Check
A58: Paying now + held | D58: =D44+D55 -> 178119.26
A59: Bill total per Xero | D59: 178119.25
...
