Workbook

Sheet Basis of Preparation
A1: Corporate Technology Services Pty Ltd
A2: Basis of Preparation
A3: Discretionary technology spend - FY2027 year to date (1 July 2026 to 31 August 2026)
A5: Entity | B5: Corporate Technology Services Pty Ltd.
A6: Reporting period | B6: 1 July 2026 to 31 August 2026. This is 2 months of the FY2027 financial year (1 July 2026 to 30 June 2027). Actual amounts in this report are for those 2 months only and are not annual figures.
A7: Source of actuals | B7: General ledger transaction export from Xero, being the same export used for the entity's monthly management reporting. The export covers 3,771 ledger lines for the period, of which 247 lines relate to the accounts within the scope of this report.
A8: Accounting basis | B8: Accrual. Amounts are exclusive of GST, consistent with the general ledger.
A9: Scope | B9: Seven general ledger accounts identified by management as discretionary technology spend, listed on the Summary schedule. No other accounts have been included, and no allocation, apportionment or estimate has been applied.
A10: Presentation of amounts | B10: The general ledger records amounts as credit less debit. Costs are therefore negative in the ledger and have been presented here as positive expenditure. Debit and credit as recorded are shown unchanged on the Transaction Listing so that each line can be agreed back to the ledger.
A11: Budget figures | B11: Budget amounts are management's FY2027 annual budget for each account, as provided. They are unaudited and are included for comparison only. The year-to-date budget shown is the annual budget apportioned evenly across twelve months and multiplied by 2; no seasonality has been applied.
A12: Completeness | B12: Every ledger line coded to the seven accounts in the period is listed on the Transaction Listing. No line has been excluded, summarised or netted. The Reconciliation schedule agrees the listing to the summary and to the ledger.
A13: Matters noted | B13: Two matters are disclosed on the Summary schedule: an arithmetic overstatement in the budget total as originally presented to us, and expenditure recorded without a supplier name. Both are described where they arise.
A14: Prepared | B14: Prepared from the general ledger export by the finance function. Figures are unaudited.

Sheet Summary
A1: Corporate Technology Services Pty Ltd
A2: Summary by account
A3: Discretionary technology spend - FY2027 year to date (1 July 2026 to 31 August 2026)
A5: Grouping | B5: General ledger account | C5: Annual budget FY2027 | D5: Budget 2 months | E5: Actual 2 months | F5: Variance | G5: Lines | H5: Annualised run rate | I5: Run rate vs budget
A6: Core technology | B6: IT Network Service & Support | C6: 149160 | D6: 24860 | E6: 30218.74 | F6: =E6-D6 -> 5358.74 | G6: 20 | H6: =E6/2*12 -> 181312.44 | I6: =IF(C6=0,"n/a",H6/C6-1) -> 0.21555672
A7: Core technology | B7: Dues & Subscriptions | C7: 86544 | D7: 14424 | E7: 20672.16 | F7: =E7-D7 -> 6248.16 | G7: 139 | H7: =E7/2*12 -> 124032.96 | I7: =IF(C7=0,"n/a",H7/C7-1) -> 0.43317804
A8: Core technology | B8: Instant Asset Write Off | C8: 60000 | D8: 10000 | E8: 5000 | F8: =E8-D8 -> -5000 | G8: 22 | H8: =E8/2*12 -> 30000 | I8: =IF(C8=0,"n/a",H8/C8-1) -> -0.5
A9: Telecommunications | B9: Internet | C9: 4814 | D9: 802.33 | E9: 727.64 | F9: =E9-D9 -> -74.69 | G9: 4 | H9: =E9/2*12 -> 4365.84 | I9: =IF(C9=0,"n/a",H9/C9-1) -> -0.093095139
A10: Telecommunications | B10: Mobile Phones | C10: 3300 | D10: 550 | E10: 1286.29 | F10: =E10-D10 -> 736.29 | G10: 53 | H10: =E10/2*12 -> 7717.74 | I10: =IF(C10=0,"n/a",H10/C10-1) -> 1.3387091
A11: Telecommunications | B11: Office Phones | C11: 2400 | D11: 400 | E11: 343.42 | F11: =E11-D11 -> -56.58 | G11: 3 | H11: =E11/2*12 -> 2060.52 | I11: =IF(C11=0,"n/a",H11/C11-1) -> -0.14145
A12: Telecommunications | B12: 1300 Number | C12: 780 | D12: 130 | E12: 171.33 | F12: =E12-D12 -> 41.33 | G12: 6 | H12: =E12/2*12 -> 1027.98 | I12: =IF(C12=0,"n/a",H12/C12-1) -> 0.31792308
B13: Subtotal - core technology | C13: =C6+C7+C8 -> 295704 | D13: =D6+D7+D8 -> 49284 | E13: =E6+E7+E8 -> 55890.9 | F13: =F6+F7+F8 -> 6606.9 | G13: =G6+G7+G8 -> 181 | H13: =H6+H7+H8 -> 335345.4 | I13: =IF(C13=0,"n/a",H13/C13-1) -> 0.13405771
B14: Subtotal - telecommunications | C14: =C9+C10+C11+C12 -> 11294 | D14: =D9+D10+D11+D12 -> 1882.33 | E14: =E9+E10+E11+E12 -> 2528.68 | F14: =F9+F10+F11+F12 -> 646.35 | G14: =G9+G10+G11+G12 -> 66 | H14: =H9+H10+H11+H12 -> 15172.08 | I14: =IF(C14=0,"n/a",H14/C14-1) -> 0.34337524
B15: Total discretionary technology spend | C15: =C13+C14 -> 306998 | D15: =D13+D14 -> 51166.33 | E15: =E13+E14 -> 58419.58 | F15: =F13+F14 -> 7253.25 | G15: =G13+G14 -> 247 | H15: =H13+H14 -> 350517.48 | I15: =IF(C15=0,"n/a",H15/C15-1) -> 0.14175819
A17: Note 1 - budget total | B17: The budget schedule provided to us showed a total of $602,702. That figure adds a 'standard' subtotal of $295,704 (the three core technology accounts) to a 'broad' subtotal of $306,998, where the broad subtotal already contains the standard subtotal. The three core accounts are therefore counted twice and the total is overstated by $295,704. The annual budget for the seven accounts, each counted once, is $306,998 as shown above.
A18: Note 2 - expenditure with no supplier recorded | B18: $9,568.78 of the expenditure in the period, being 16.4% of the total, is recorded on ledger lines that carry no contact or supplier name. These lines are listed in full on the Transaction Listing and are shown as a separate line on the Supplier Analysis schedule.
A19: Note 3 - supplier concentration | B19: One supplier, First Focus IT Pty Ltd, accounts for $37,799.82 of expenditure in the period, being 64.7% of the total. That expenditure is recorded across two accounts, IT Network Service & Support and Dues & Subscriptions. See the Supplier Analysis schedule.
A20: Note 4 - period covered | B20: These figures cover July and August only, which is 2 months of a twelve month year. The annualised run rate column takes what has been spent so far, divides it by 2 and multiplies by twelve, so it assumes the rest of the year looks like the first 2 months. It makes no allowance for quieter or busier periods, for annual renewals that fall due later in the year, or for spending already committed but not yet incurred. Treat it as a rough indicator, not a forecast.

Sheet Supplier Analysis
A1: Corporate Technology Services Pty Ltd
A2: Supplier analysis
A3: Discretionary technology spend - FY2027 year to date (1 July 2026 to 31 August 2026) - use the + and - buttons in the left margin to open a supplier down to its ledger lines
A5: Supplier / account / transaction date | B5: Amount | C5: % of total | D5: Lines | E5: Description | F5: Invoice no. | G5: Reference | H5: Job number | I5: Cost centre | J5: Source
A6: First Focus IT Pty Ltd | B6: =B7+B28 -> 37799.82 | C6: =B6/$B$326 -> 0.64704026 | D6: 43
A7: IT Network Service & Support | B7: =B8+B9+B10+B11+B12+B13+B14+B15+B16+B17+B18+B19+B20+B21+B22+B23+B24+B25+B26+B27 -> 30218.74 | D7: 20
A8: 46204 | B8: 9953 | E8: First Focus IT Pty Ltd - CORE Intelligent Managed Services | F8: INV167160 - MSA: CORE Intelligent Managed Services: CORE Intelligent Managed Services July 2026 [paid via DD] To recieve credits for the interest charged | G8: INV167160 - MSA: CORE Intelligent Managed Services: CORE Intelligent Managed Services July 2026 [paid via DD] To recieve credits for the interest charged | H8: 9000 - OFFICE / ADMIN [CTS] | I8: CTS | J8: Payable Invoice
A9: 46204 | B9: 403.5 | E9: First Focus IT Pty Ltd - CORE Intelligent Managed Services Email Only User 75% discount | F9: INV167160 - MSA: CORE Intelligent Managed Services: CORE Intelligent Managed Services July 2026 [paid via DD] To recieve credits for the interest charged | G9: INV167160 - MSA: CORE Intelligent Managed Services: CORE Intelligent Managed Services July 2026 [paid via DD] To recieve credits for the interest charged | H9: 9000 - OFFICE / ADMIN [CTS] | I9: CTS | J9: Payable Invoice
A10: 46204 | B10: 1247 | E10: First Focus IT Pty Ltd - CORE - Hatz AI Multi-LLM Platform | F10: INV167160 - MSA: CORE Intelligent Managed Services: CORE Intelligent Managed Services July 2026 [paid via DD] To recieve credits for the interest charged | G10: INV167160 - MSA: CORE Intelligent Managed Services: CORE Intelligent Managed Services July 2026 [paid via DD] To recieve credits for the interest charged | H10: 9000 - OFFICE / ADMIN [CTS] | I10: CTS | J10: Payable Invoice
A11: 46204 | B11: -430 | E11: First Focus IT Pty Ltd - CORE Early Sign Up Discount Hatz (12 month) | F11: INV167160 - MSA: CORE Intelligent Managed Services: CORE Intelligent Managed Services July 2026 [paid via DD] To recieve credits for the interest charged | G11: INV167160 - MSA: CORE Intelligent Managed Services: CORE Intelligent Managed Services July 2026 [paid via DD] To recieve credits for the interest charged | H11: 9000 - OFFICE / ADMIN [CTS] | I11: CTS | J11: Payable Invoice
A12: 46204 | B12: 100 | E12: First Focus IT Pty Ltd - DMARC Email Security Management: Per Domain | F12: INV167160 - MSA: CORE Intelligent Managed Services: CORE Intelligent Managed Services July 2026 [paid via DD] To recieve credits for the interest charged | G12: INV167160 - MSA: CORE Intelligent Managed Services: CORE Intelligent Managed Services July 2026 [paid via DD] To recieve credits for the interest charged | H12: 9000 - OFFICE / ADMIN [CTS] | I12: CTS | J12: Payable Invoice
A13: 46204 | B13: 325 | E13: First Focus IT Pty Ltd - Managed SD-WAN Firewall (1Gbps max) | F13: INV167160 - MSA: CORE Intelligent Managed Services: CORE Intelligent Managed Services July 2026 [paid via DD] To recieve credits for the interest charged | G13: INV167160 - MSA: CORE Intelligent Managed Services: CORE Intelligent Managed Services July 2026 [paid via DD] To recieve credits for the interest charged | H13: 9000 - OFFICE / ADMIN [CTS] | I13: CTS | J13: Payable Invoice
A14: 46204 | B14: 28.8 | E14: First Focus IT Pty Ltd - Exchange Online (Plan 1) (NCE COM 1MTH) Serial Number(s): S365L | F14: INV167160 - MSA: CORE Intelligent Managed Services: CORE Intelligent Managed Services July 2026 [paid via DD] To recieve credits for the interest charged | G14: INV167160 - MSA: CORE Intelligent Managed Services: CORE Intelligent Managed Services July 2026 [paid via DD] To recieve credits for the interest charged | H14: 9000 - OFFICE / ADMIN [CTS] | I14: CTS | J14: Payable Invoice
A15: 46204 | B15: 198.58 | E15: First Focus IT Pty Ltd - Interest on late payments 162027 164522 162627 (To be credited) | F15: INV167160 - MSA: CORE Intelligent Managed Services: CORE Intelligent Managed Services July 2026 [paid via DD] To recieve credits for the interest charged | G15: INV167160 - MSA: CORE Intelligent Managed Services: CORE Intelligent Managed Services July 2026 [paid via DD] To recieve credits for the interest charged | H15: 9000 - OFFICE / ADMIN [CTS] | I15: CTS | J15: Payable Invoice
A16: 46219 | B16: -198.58 | E16: First Focus IT Pty Ltd - Interest on late payments 162027 164522 162627 | F16: INV168824 - Interest Charges on INV167160 for May 2026 invoices (to apply in August invoice) | G16: INV168824 - Interest Charges on INV167160 for May 2026 invoices (to apply in August invoice) | H16: 9000 - OFFICE / ADMIN [CTS] | I16: CTS | J16: Payable Credit Note
A17: 46234 | B17: 18325.73 | E17: First Focus IT Pty Ltd - Fixed Fee Project | F17: INV171598 - Completion of CORE Intelligent Managed Services One-Time Project - Balance Fee [PO-00016880] pay via EFT | G17: INV171598 - Completion of CORE Intelligent Managed Services One-Time Project - Balance Fee [PO-00016880] pay via EFT | H17: 9000 - OFFICE / ADMIN [CTS] | I17: CTS | J17: Payable Invoice
A18: 46234 | B18: -7330.29 | E18: First Focus IT Pty Ltd - CORE Early Sign Up Discount At cost transitions project Offer valid for agreements signed prior to 15/04 | F18: INV171598 - Completion of CORE Intelligent Managed Services One-Time Project - Balance Fee [PO-00016880] pay via EFT | G18: INV171598 - Completion of CORE Intelligent Managed Services One-Time Project - Balance Fee [PO-00016880] pay via EFT | H18: 9000 - OFFICE / ADMIN [CTS] | I18: CTS | J18: Payable Invoice
A19: 46234 | B19: -2451 | E19: First Focus IT Pty Ltd - CORE Early Sign Up Discount Hatz | F19: INV171598 - Completion of CORE Intelligent Managed Services One-Time Project - Balance Fee [PO-00016880] pay via EFT | G19: INV171598 - Completion of CORE Intelligent Managed Services One-Time Project - Balance Fee [PO-00016880] pay via EFT | H19: 9000 - OFFICE / ADMIN [CTS] | I19: CTS | J19: Payable Invoice
... A27: 46237 | B27: 609.7 | E27: First Focus IT Pty Ltd - Replacement for NAS Hard Drive Seagate IronWolf 8 TB Hard Drive - 3.5" Internal - SATA (SATA/600) - 7200rpm 256 MB Buffer - 3 Year Warranty | F27: INV170542 - Replacement for NAS Hard Drive [Q-034252v1 - PO-00016911] GC App (Pay by EFT) | G27: INV170542 - Replacement for NAS Hard Drive [Q-034252v1 - PO-00016911] GC App (Pay by EFT) | H27: 9000 - OFFICE / ADMIN [CTS] | I27: CTS | J27: Payable Invoice
A28: Dues & Subscriptions | B28: =B29+B30+B31+B32+B33+B34+B35+B36+B37+B38+B39+B40+B41+B42+B43+B44+B45+B46+B47+B48+B49+B50+B51 -> 7581.08 | D28: 23
A29: 46204 | B29: 616.89 | E29: First Focus IT Pty Ltd - Microsoft Azure Consumption | F29: INV168585: MSA: Managed Services: Managed Services - Azure July 2026 [paid via DD] | G29: INV168585: MSA: Managed Services: Managed Services - Azure July 2026 [paid via DD] | H29: 9000 - OFFICE / ADMIN [CTS] | I29: CTS | J29: Payable Invoice
A30: 46204 | B30: 79.92 | E30: First Focus IT Pty Ltd - Exchange Online (Plan 2) (NCE COM 1MTH) Serial Number(s): S365L | F30: INV167160 - MSA: CORE Intelligent Managed Services: CORE Intelligent Managed Services July 2026 [paid via DD] To recieve credits for the interest charged | G30: INV167160 - MSA: CORE Intelligent Managed Services: CORE Intelligent Managed Services July 2026 [paid via DD] To recieve credits for the interest charged | H30: 9000 - OFFICE / ADMIN [CTS] | I30: CTS | J30: Payable Invoice
A31: 46204 | B31: 57.6 | E31: First Focus IT Pty Ltd - Microsoft Defender for Office 365 (Plan 1) (NCE COM 1MTH) | F31: INV167160 - MSA: CORE Intelligent Managed Services: CORE Intelligent Managed Services July 2026 [paid via DD] To recieve credits for the interest charged | G31: INV167160 - MSA: CORE Intelligent Managed Services: CORE Intelligent Managed Services July 2026 [paid via DD] To recieve credits for the interest charged | H31: 9000 - OFFICE / ADMIN [CTS] | I31: CTS | J31: Payable Invoice
A32: 46204 | B32: 9 | E32: First Focus IT Pty Ltd - Microsoft Defender for Office 365 (Plan 2) (NCE COM 1MTH) | F32: INV167160 - MSA: CORE Intelligent Managed Services: CORE Intelligent Managed Services July 2026 [paid via DD] To recieve credits for the interest charged | G32: INV167160 - MSA: CORE Intelligent Managed Services: CORE Intelligent Managed Services July 2026 [paid via DD] To recieve credits for the interest charged | H32: 9000 - OFFICE / ADMIN [CTS] | I32: CTS | J32: Payable Invoice
A33: 46204 | B33: 917.28 | E33: First Focus IT Pty Ltd - Office 365 Extra File Storage (NCE Product) (NCE COM 1MTH | F33: INV167160 - MSA: CORE Intelligent Managed Services: CORE Intelligent Managed Services July 2026 [paid via DD] To recieve credits for the interest charged | G33: INV167160 - MSA: CORE Intelligent Managed Services: CORE Intelligent Managed Services July 2026 [paid via DD] To recieve credits for the interest charged | H33: 9000 - OFFICE / ADMIN [CTS] | I33: CTS | J33: Payable Invoice
A34: 46204 | B34: 104.1 | E34: First Focus IT Pty Ltd - Planner and Project Plan 3 (NCE COM 1MTH) Serial Number(s): S365L | F34: INV167160 - MSA: CORE Intelligent Managed Services: CORE Intelligent Managed Services July 2026 [paid via DD] To recieve credits for the interest charged | G34: INV167160 - MSA: CORE Intelligent Managed Services: CORE Intelligent Managed Services July 2026 [paid via DD] To recieve credits for the interest charged | H34: 9000 - OFFICE / ADMIN [CTS] | I34: CTS | J34: Payable Invoice
A35: 46204 | B35: 215.04 | E35: First Focus IT Pty Ltd - Visio Plan 2 (NCE COM 1MTH) Serial Number(s): S365L | F35: INV167160 - MSA: CORE Intelligent Managed Services: CORE Intelligent Managed Services July 2026 [paid via DD] To recieve credits for the interest charged | G35: INV167160 - MSA: CORE Intelligent Managed Services: CORE Intelligent Managed Services July 2026 [paid via DD] To recieve credits for the interest charged | H35: 9000 - OFFICE / ADMIN [CTS] | I35: CTS | J35: Payable Invoice
A36: 46204 | B36: 157.12 | E36: First Focus IT Pty Ltd - Microsoft 365 Business Standard (NCE COM 1YR MTH) Serial Number(s): S365L | F36: INV167160 - MSA: CORE Intelligent Managed Services: CORE Intelligent Managed Services July 2026 [paid via DD] To recieve credits for the interest charged | G36: INV167160 - MSA: CORE Intelligent Managed Services: CORE Intelligent Managed Services July 2026 [paid via DD] To recieve credits for the interest charged | H36: 9000 - OFFICE / ADMIN [CTS] | I36: CTS | J36: Payable Invoice
A37: 46204 | B37: 274.05 | E37: First Focus IT Pty Ltd - Microsoft 365 Business Basic (NCE COM 1YR MTH) Serial Number(s): S365L | F37: INV167160 - MSA: CORE Intelligent Managed Services: CORE Intelligent Managed Services July 2026 [paid via DD] To recieve credits for the interest charged | G37: INV167160 - MSA: CORE Intelligent Managed Services: CORE Intelligent Managed Services July 2026 [paid via DD] To recieve credits for the interest charged | H37: 9000 - OFFICE / ADMIN [CTS] | I37: CTS | J37: Payable Invoice
A38: 46204 | B38: 1071.05 | E38: First Focus IT Pty Ltd - Microsoft 365 Business Premium (NCE COM 1YR MTH) Serial Number(s): S365L | F38: INV167160 - MSA: CORE Intelligent Managed Services: CORE Intelligent Managed Services July 2026 [paid via DD] To recieve credits for the interest charged | G38: INV167160 - MSA: CORE Intelligent Managed Services: CORE Intelligent Managed Services July 2026 [paid via DD] To recieve credits for the interest charged | H38: 9000 - OFFICE / ADMIN [CTS] | I38: CTS | J38: Payable Invoice
A39: 46204 | B39: 15.76 | E39: First Focus IT Pty Ltd - Microsoft 365 Business Basic (NCE COM 1YR MTH) This item has been prorated with a start date of: 06/06/2026 | F39: INV167160 - MSA: CORE Intelligent Managed Services: CORE Intelligent Managed Services July 2026 [paid via DD] To recieve credits for the interest charged | G39: INV167160 - MSA: CORE Intelligent Managed Services: CORE Intelligent Managed Services July 2026 [paid via DD] To recieve credits for the interest charged | H39: 9000 - OFFICE / ADMIN [CTS] | I39: CTS | J39: Payable Invoice
A40: 46204 | B40: 265.36 | E40: First Focus IT Pty Ltd - Datto SAAS Protection for Microsoft 365 (CSP COM 3YR MTH) | F40: INV167160 - MSA: CORE Intelligent Managed Services: CORE Intelligent Managed Services July 2026 [paid via DD] To recieve credits for the interest charged | G40: INV167160 - MSA: CORE Intelligent Managed Services: CORE Intelligent Managed Services July 2026 [paid via DD] To recieve credits for the interest charged | H40: 9000 - OFFICE / ADMIN [CTS] | I40: CTS | J40: Payable Invoice
... A51: 46235 | B51: 265.36 | E51: First Focus IT Pty Ltd - Datto SAAS Protection for Microsoft 365 (CSP COM 3YR MTH) | F51: INV170755 - MSA: CORE Intelligent Managed Services: CORE Intelligent Managed Services August 2026 [paid via DD] | G51: INV170755 - MSA: CORE Intelligent Managed Services: CORE Intelligent Managed Services August 2026 [paid via DD] | H51: 9000 - OFFICE / ADMIN [CTS] | I51: CTS | J51: Payable Invoice
A52: (no supplier name recorded on the ledger line) | B52: =B53+B108 -> 9568.78 | C52: =B52/$B$326 -> 0.16379406 | D52: 56
A53: Dues & Subscriptions | B53: =B54+B55+B56+B57+B58+B59+B60+B61+B62+B63+B64+B65+B66+B67+B68+B69+B70+B71+B72+B73+B74+B75+B76+B77+B78+B79+B80+B81+B82+B83+B84+B85+B86+B87+B88+B89+B90+B91+B92+B93+B94+B95+B96+B97+B98+B99+B100+B101+B102+B103+B104+B105+B106+B107 -> 9876.52 | D53: 54
A54: 46234 | B54: 38.75 | E54: Prepayments July 2026 - Inv6115846AA|27/03|Dicker Data| | G54: #69222 | H54: 2910 - Office Move 2024 [CTS] | I54: CTS | J54: Manual Journal
A55: 46234 | B55: 12.5 | E55: Prepayments July 2026 - Inv58586033|10/02|Crazy Domains (website renewal)| | G55: #69222 | H55: 9350 - MARKETING (external) [CTS] | I55: CTS | J55: Manual Journal
A56: 46234 | B56: 35.36 | E56: Prepayments July 2026 - Inv1753767723|29/07|Webflow.com| | G56: #69222 | H56: 9350 - MARKETING (external) [CTS] | I56: CTS | J56: Manual Journal
A57: 46234 | B57: 348.89 | E57: Prepayments July 2026 - Inv415083|06/08|PigeonLab Pte Ltd| | G57: #69222 | H57: 9100 - PRODUCTION [PRD] | I57: PRODUCTION | J57: Manual Journal
A58: 46234 | B58: 38.59 | E58: Prepayments July 2026 - Inv88AD1D8F-0004|15/08|Plumsail Inc| | G58: #69222 | H58: 9100 - PRODUCTION [PRD] | I58: PRODUCTION | J58: Manual Journal
...

Sheet Monthly Analysis
A1: Corporate Technology Services Pty Ltd
A2: Monthly analysis by account
A3: Discretionary technology spend - FY2027 year to date (1 July 2026 to 31 August 2026)
A5: General ledger account | B5: Jul 2026 | C5: Aug 2026 | D5: Total
A6: IT Network Service & Support | B6: 20171.74 | C6: 10047 | D6: =SUM(B6:C6) -> 30218.74
A7: Dues & Subscriptions | B7: 10445.04 | C7: 10227.12 | D7: =SUM(B7:C7) -> 20672.16
A8: Instant Asset Write Off | B8: 5000 | C8: 0 | D8: =SUM(B8:C8) -> 5000
A9: Internet | B9: 363.82 | C9: 363.82 | D9: =SUM(B9:C9) -> 727.64
A10: Mobile Phones | B10: 695.29 | C10: 591 | D10: =SUM(B10:C10) -> 1286.29
A11: Office Phones | B11: 171.71 | C11: 171.71 | D11: =SUM(B11:C11) -> 343.42
A12: 1300 Number | B12: 81.09 | C12: 90.24 | D12: =SUM(B12:C12) -> 171.33
A13: Total | B13: =SUM(B6:B12) -> 36928.69 | C13: =SUM(C6:C12) -> 21490.89 | D13: =SUM(D6:D12) -> 58419.58

Sheet Transaction Listing
A1: Corporate Technology Services Pty Ltd
A2: Transaction listing
A3: Discretionary technology spend - FY2027 year to date (1 July 2026 to 31 August 2026) - every ledger line coded to the seven accounts, 247 lines
A5: Date | B5: Acct code | C5: General ledger account | D5: Source | E5: Supplier / contact | F5: Description | G5: Invoice no. | H5: Reference | I5: Job number | J5: Cost centre | K5: Debit | L5: Credit | M5: Expenditure
A6: 46210 | B6: 64510 | C6: 1300 Number | D6: Payable Invoice | E6: Optus Billing Services Pty Ltd | F6: Optus Billing Services Pty Ltd - 1300 283 247 | G6: INV000583847765 - Office Internet and Phone Service Charges July 2026 [paid via PL CC] | H6: INV000583847765 - Office Internet and Phone Service Charges July 2026 [paid via PL CC] | I6: 9000 - OFFICE / ADMIN [CTS] | J6: CTS | K6: 26.29 | L6: 0 | M6: 26.29
A7: 46210 | B7: 64510 | C7: 1300 Number | D7: Payable Invoice | E7: Optus Billing Services Pty Ltd | F7: Optus Billing Services Pty Ltd - 1300 388 528 (DTTL Phone) | G7: INV000583847765 - Office Internet and Phone Service Charges July 2026 [paid via PL CC] | H7: INV000583847765 - Office Internet and Phone Service Charges July 2026 [paid via PL CC] | I7: 974 - DTTL 1300 Number [ONS] | J7: ONSITE | K7: 25.85 | L7: 0 | M7: 25.85
A8: 46210 | B8: 64510 | C8: 1300 Number | D8: Payable Invoice | E8: Optus Billing Services Pty Ltd | F8: Optus Billing Services Pty Ltd - 1800 225 528 | G8: INV000583847765 - Office Internet and Phone Service Charges July 2026 [paid via PL CC] | H8: INV000583847765 - Office Internet and Phone Service Charges July 2026 [paid via PL CC] | I8: 9000 - OFFICE / ADMIN [CTS] | J8: CTS | K8: 28.95 | L8: 0 | M8: 28.95
A9: 46241 | B9: 64510 | C9: 1300 Number | D9: Payable Invoice | E9: Optus Billing Services Pty Ltd | F9: Optus Billing Services Pty Ltd - 1300 283 247 | G9: INV000589213447 - Office Internet and Phone Service Charges August 2026 [paid via PL CC] | H9: INV000589213447 - Office Internet and Phone Service Charges August 2026 [paid via PL CC] | I9: 9000 - OFFICE / ADMIN [CTS] | J9: CTS | K9: 26.31 | L9: 0 | M9: 26.31
A10: 46241 | B10: 64510 | C10: 1300 Number | D10: Payable Invoice | E10: Optus Billing Services Pty Ltd | F10: Optus Billing Services Pty Ltd - 1300 388 528 (DTTL Phone) | G10: INV000589213447 - Office Internet and Phone Service Charges August 2026 [paid via PL CC] | H10: INV000589213447 - Office Internet and Phone Service Charges August 2026 [paid via PL CC] | I10: 974 - DTTL 1300 Number [ONS] | J10: ONSITE | K10: 25.71 | L10: 0 | M10: 25.71
A11: 46241 | B11: 64510 | C11: 1300 Number | D11: Payable Invoice | E11: Optus Billing Services Pty Ltd | F11: Optus Billing Services Pty Ltd - 1800 225 528 | G11: INV000589213447 - Office Internet and Phone Service Charges August 2026 [paid via PL CC] | H11: INV000589213447 - Office Internet and Phone Service Charges August 2026 [paid via PL CC] | I11: 9000 - OFFICE / ADMIN [CTS] | J11: CTS | K11: 38.22 | L11: 0 | M11: 38.22
A12: 46204 | B12: 61400 | C12: Dues & Subscriptions | D12: Payable Invoice | E12: First Focus IT Pty Ltd | F12: First Focus IT Pty Ltd - Microsoft Azure Consumption | G12: INV168585: MSA: Managed Services: Managed Services - Azure July 2026 [paid via DD] | H12: INV168585: MSA: Managed Services: Managed Services - Azure July 2026 [paid via DD] | I12: 9000 - OFFICE / ADMIN [CTS] | J12: CTS | K12: 616.89 | L12: 0 | M12: 616.89
A13: 46204 | B13: 61400 | C13: Dues & Subscriptions | D13: Payable Invoice | E13: First Focus IT Pty Ltd | F13: First Focus IT Pty Ltd - Exchange Online (Plan 2) (NCE COM 1MTH) Serial Number(s): S365L | G13: INV167160 - MSA: CORE Intelligent Managed Services: CORE Intelligent Managed Services July 2026 [paid via DD] To recieve credits for the interest charged | H13: INV167160 - MSA: CORE Intelligent Managed Services: CORE Intelligent Managed Services July 2026 [paid via DD] To recieve credits for the interest charged | I13: 9000 - OFFICE / ADMIN [CTS] | J13: CTS | K13: 79.92 | L13: 0 | M13: 79.92
A14: 46204 | B14: 61400 | C14: Dues & Subscriptions | D14: Payable Invoice | E14: First Focus IT Pty Ltd | F14: First Focus IT Pty Ltd - Microsoft Defender for Office 365 (Plan 1) (NCE COM 1MTH) | G14: INV167160 - MSA: CORE Intelligent Managed Services: CORE Intelligent Managed Services July 2026 [paid via DD] To recieve credits for the interest charged | H14: INV167160 - MSA: CORE Intelligent Managed Services: CORE Intelligent Managed Services July 2026 [paid via DD] To recieve credits for the interest charged | I14: 9000 - OFFICE / ADMIN [CTS] | J14: CTS | K14: 57.6 | L14: 0 | M14: 57.6
A15: 46204 | B15: 61400 | C15: Dues & Subscriptions | D15: Payable Invoice | E15: First Focus IT Pty Ltd | F15: First Focus IT Pty Ltd - Microsoft Defender for Office 365 (Plan 2) (NCE COM 1MTH) | G15: INV167160 - MSA: CORE Intelligent Managed Services: CORE Intelligent Managed Services July 2026 [paid via DD] To recieve credits for the interest charged | H15: INV167160 - MSA: CORE Intelligent Managed Services: CORE Intelligent Managed Services July 2026 [paid via DD] To recieve credits for the interest charged | I15: 9000 - OFFICE / ADMIN [CTS] | J15: CTS | K15: 9 | L15: 0 | M15: 9
A16: 46204 | B16: 61400 | C16: Dues & Subscriptions | D16: Payable Invoice | E16: First Focus IT Pty Ltd | F16: First Focus IT Pty Ltd - Office 365 Extra File Storage (NCE Product) (NCE COM 1MTH | G16: INV167160 - MSA: CORE Intelligent Managed Services: CORE Intelligent Managed Services July 2026 [paid via DD] To recieve credits for the interest charged | H16: INV167160 - MSA: CORE Intelligent Managed Services: CORE Intelligent Managed Services July 2026 [paid via DD] To recieve credits for the interest charged | I16: 9000 - OFFICE / ADMIN [CTS] | J16: CTS | K16: 917.28 | L16: 0 | M16: 917.28
A17: 46204 | B17: 61400 | C17: Dues & Subscriptions | D17: Payable Invoice | E17: First Focus IT Pty Ltd | F17: First Focus IT Pty Ltd - Planner and Project Plan 3 (NCE COM 1MTH) Serial Number(s): S365L | G17: INV167160 - MSA: CORE Intelligent Managed Services: CORE Intelligent Managed Services July 2026 [paid via DD] To recieve credits for the interest charged | H17: INV167160 - MSA: CORE Intelligent Managed Services: CORE Intelligent Managed Services July 2026 [paid via DD] To recieve credits for the interest charged | I17: 9000 - OFFICE / ADMIN [CTS] | J17: CTS | K17: 104.1 | L17: 0 | M17: 104.1
... A61: 46233 | B61: 61400 | C61: Dues & Subscriptions | D61: Payable Invoice | E61: LIVEU INC - US & INTERNATIONAL | F61: LIVEU INC - US & INTERNATIONAL - 1 × Monthly (at $45.00 US Dollars / month) July 31, 2026 to August 31, 2026 Serial number: 202120-23123 | G61: AF983502-0245 - LiveU Monthly Plan for 202120-23123 | H61: AF983502-0245 - LiveU Monthly Plan for 202120-23123 | I61: 9100 - PRODUCTION [PRD] | J61: PRODUCTION | K61: 65.03 | L61: 0 | M61: 65.03
A62: 46234 | B62: 61400 | C62: Dues & Subscriptions | D62: Manual Journal | E62: (no supplier name recorded) | F62: Prepayments July 2026 - Inv6115846AA|27/03|Dicker Data| | H62: #69222 | I62: 2910 - Office Move 2024 [CTS] | J62: CTS | K62: 38.75 | L62: 0 | M62: 38.75
A63: 46234 | B63: 61400 | C63: Dues & Subscriptions | D63: Manual Journal | E63: (no supplier name recorded) | F63: Prepayments July 2026 - Inv58586033|10/02|Crazy Domains (website renewal)| | H63: #69222 | I63: 9350 - MARKETING (external) [CTS] | J63: CTS | K63: 12.5 | L63: 0 | M63: 12.5
A64: 46234 | B64: 61400 | C64: Dues & Subscriptions | D64: Manual Journal | E64: (no supplier name recorded) | F64: Prepayments July 2026 - Inv1753767723|29/07|Webflow.com| | H64: #69222 | I64: 9350 - MARKETING (external) [CTS] | J64: CTS | K64: 35.36 | L64: 0 | M64: 35.36
A65: 46234 | B65: 61400 | C65: Dues & Subscriptions | D65: Manual Journal | E65: (no supplier name recorded) | F65: Prepayments July 2026 - Inv415083|06/08|PigeonLab Pte Ltd| | H65: #69222 | I65: 9100 - PRODUCTION [PRD] | J65: PRODUCTION | K65: 348.89 | L65: 0 | M65: 348.89
A66: 46234 | B66: 61400 | C66: Dues & Subscriptions | D66: Manual Journal | E66: (no supplier name recorded) | F66: Prepayments July 2026 - Inv88AD1D8F-0004|15/08|Plumsail Inc| | H66: #69222 | I66: 9100 - PRODUCTION [PRD] | J66: PRODUCTION | K66: 38.59 | L66: 0 | M66: 38.59
A67: 46234 | B67: 61400 | C67: Dues & Subscriptions | D67: Manual Journal | E67: (no supplier name recorded) | F67: Prepayments July 2026 - Inv51110652883|01/09|Linkedin Singapore| | H67: #69222 | I67: 9300 - HUMAN RESOURCES [CTS] | J67: CTS | K67: 530 | L67: 0 | M67: 530
A68: 46234 | B68: 61400 | C68: Dues & Subscriptions | D68: Manual Journal | E68: (no supplier name recorded) | F68: Prepayments July 2026 - Inv721699|22/09|Qantas Airways Limited| | H68: #69222 | I68: 3059 - CBA AGM 2025 [PRD] | J68: PRODUCTION | K68: 44.28 | L68: 0 | M68: 44.28
A69: 46234 | B69: 61400 | C69: Dues & Subscriptions | D69: Manual Journal | E69: (no supplier name recorded) | F69: Prepayments July 2026 - Inv356325|08/09|AddEvent Inc| | H69: #69222 | I69: 9100 - PRODUCTION [PRD] | J69: PRODUCTION | K69: 44.33 | L69: 0 | M69: 44.33
A70: 46234 | B70: 61400 | C70: Dues & Subscriptions | D70: Manual Journal | E70: (no supplier name recorded) | F70: Prepayments July 2026 - Inv50BB48DA-0011|06/10|Qwilr Pty Ltd| | H70: #69222 | I70: 9105 - ONSITE (including PROD backup) | J70: ONSITE | K70: 79.75 | L70: 0 | M70: 79.75
A71: 46234 | B71: 61400 | C71: Dues & Subscriptions | D71: Manual Journal | E71: (no supplier name recorded) | F71: Prepayments July 2026 - Inv50BB48DA-0011|06/10|Qwilr Pty Ltd| | H71: #69222 | I71: 9200 - INTEGRATION [INT] | J71: INTEGRATION | K71: 39.88 | L71: 0 | M71: 39.88
A72: 46234 | B72: 61400 | C72: Dues & Subscriptions | D72: Manual Journal | E72: (no supplier name recorded) | F72: Prepayments July 2026 - Inv50BB48DA-0011|06/10|Qwilr Pty Ltd| | H72: #69222 | I72: 9400 - CONSULTING [CONS] | J72: CONSULTING | K72: 39.88 | L72: 0 | M72: 39.88
A73: 46234 | B73: 61400 | C73: Dues & Subscriptions | D73: Manual Journal | E73: (no supplier name recorded) | F73: Prepayments July 2026 - Inv3435939|11/11|AVIXA (Formerly InfoComm International)| | H73: #69222 | I73: 9000 - OFFICE / ADMIN [CTS] | J73: CTS | K73: 237.5 | L73: 0 | M73: 237.5
... A87: 46234 | B87: 61400 | C87: Dues & Subscriptions | D87: Manual Journal | E87: (no supplier name recorded) | F87: Prepayments July 2026 - InvINV20611845 |06/07|Lucid| | H87: #69222 | I87: 9000 - OFFICE / ADMIN [CTS] | J87: CTS | K87: 43.36 | L87: 0 | M87: 43.36
A88: 46234 | B88: 61400 | C88: Dues & Subscriptions | D88: Payable Invoice | E88: LIVEU INC - US & INTERNATIONAL | F88: LIVEU INC - US & INTERNATIONAL - 1 × Monthly (at $45.00 US Dollars / month) August 1, 2026 to September 1, 2026 Serial number: 202120-23120 | G88: AF983502-0246 - LiveU Monthly Plan for 202120-23120 | H88: AF983502-0246 - LiveU Monthly Plan for 202120-23120 | I88: 9100 - PRODUCTION [PRD] | J88: PRODUCTION | K88: 64.39 | L88: 0 | M88: 64.39
A89: 46235 | B89: 61400 | C89: Dues & Subscriptions | D89: Payable Invoice | E89: First Focus IT Pty Ltd | F89: First Focus IT Pty Ltd - Microsoft Azure Consumption | G89: INV173381: MSA: Managed Services: Managed Services - Azure August 2026 [paid via DD] | H89: INV173381: MSA: Managed Services: Managed Services - Azure August 2026 [paid via DD] | I89: 9000 - OFFICE / ADMIN [CTS] | J89: CTS | K89: 643.73 | L89: 0 | M89: 643.73
A90: 46235 | B90: 61400 | C90: Dues & Subscriptions | D90: Payable Invoice | E90: First Focus IT Pty Ltd | F90: First Focus IT Pty Ltd - Exchange Online (Plan 2) (NCE COM 1MTH) Serial Number(s): S365L | G90: INV170755 - MSA: CORE Intelligent Managed Services: CORE Intelligent Managed Services August 2026 [paid via DD] | H90: INV170755 - MSA: CORE Intelligent Managed Services: CORE Intelligent Managed Services August 2026 [paid via DD] | I90: 9000 - OFFICE / ADMIN [CTS] | J90: CTS | K90: 79.92 | L90: 0 | M90: 79.92
A91: 46235 | B91: 61400 | C91: Dues & Subscriptions | D91: Payable Invoice | E91: First Focus IT Pty Ltd | F91: First Focus IT Pty Ltd - Microsoft Defender for Office 365 (Plan 1) (NCE COM 1MTH) | G91: INV170755 - MSA: CORE Intelligent Managed Services: CORE Intelligent Managed Services August 2026 [paid via DD] | H91: INV170755 - MSA: CORE Intelligent Managed Services: CORE Intelligent Managed Services August 2026 [paid via DD] | I91: 9000 - OFFICE / ADMIN [CTS] | J91: CTS | K91: 57.6 | L91: 0 | M91: 57.6
A92: 46235 | B92: 61400 | C92: Dues & Subscriptions | D92: Payable Invoice | E92: First Focus IT Pty Ltd | F92: First Focus IT Pty Ltd - Microsoft Defender for Office 365 (Plan 2) (NCE COM 1MTH) | G92: INV170755 - MSA: CORE Intelligent Managed Services: CORE Intelligent Managed Services August 2026 [paid via DD] | H92: INV170755 - MSA: CORE Intelligent Managed Services: CORE Intelligent Managed Services August 2026 [paid via DD] | I92: 9000 - OFFICE / ADMIN [CTS] | J92: CTS | K92: 9 | L92: 0 | M92: 9
A93: 46235 | B93: 61400 | C93: Dues & Subscriptions | D93: Payable Invoice | E93: First Focus IT Pty Ltd | F93: First Focus IT Pty Ltd - Office 365 Extra File Storage (NCE Product) (NCE COM 1MTH | G93: INV170755 - MSA: CORE Intelligent Managed Services: CORE Intelligent Managed Services August 2026 [paid via DD] | H93: INV170755 - MSA: CORE Intelligent Managed Services: CORE Intelligent Managed Services August 2026 [paid via DD] | I93: 9000 - OFFICE / ADMIN [CTS] | J93: CTS | K93: 917.28 | L93: 0 | M93: 917.28
A94: 46235 | B94: 61400 | C94: Dues & Subscriptions | D94: Payable Invoice | E94: First Focus IT Pty Ltd | F94: First Focus IT Pty Ltd - Planner and Project Plan 3 (NCE COM 1MTH) Serial Number(s): S365L | G94: INV170755 - MSA: CORE Intelligent Managed Services: CORE Intelligent Managed Services August 2026 [paid via DD] | H94: INV170755 - MSA: CORE Intelligent Managed Services: CORE Intelligent Managed Services August 2026 [paid via DD] | I94: 9000 - OFFICE / ADMIN [CTS] | J94: CTS | K94: 107.76 | L94: 0 | M94: 107.76
A95: 46235 | B95: 61400 | C95: Dues & Subscriptions | D95: Payable Invoice | E95: First Focus IT Pty Ltd | F95: First Focus IT Pty Ltd - Visio Plan 2 (NCE COM 1MTH) Serial Number(s): S365L | G95: INV170755 - MSA: CORE Intelligent Managed Services: CORE Intelligent Managed Services August 2026 [paid via DD] | H95: INV170755 - MSA: CORE Intelligent Managed Services: CORE Intelligent Managed Services August 2026 [paid via DD] | I95: 9000 - OFFICE / ADMIN [CTS] | J95: CTS | K95: 215.04 | L95: 0 | M95: 215.04
A96: 46235 | B96: 61400 | C96: Dues & Subscriptions | D96: Payable Invoice | E96: First Focus IT Pty Ltd | F96: First Focus IT Pty Ltd - Microsoft 365 Business Standard (NCE COM 1YR MTH) Serial Number(s): S365L | G96: INV170755 - MSA: CORE Intelligent Managed Services: CORE Intelligent Managed Services August 2026 [paid via DD] | H96: INV170755 - MSA: CORE Intelligent Managed Services: CORE Intelligent Managed Services August 2026 [paid via DD] | I96: 9000 - OFFICE / ADMIN [CTS] | J96: CTS | K96: 157.12 | L96: 0 | M96: 157.12
A97: 46235 | B97: 61400 | C97: Dues & Subscriptions | D97: Payable Invoice | E97: First Focus IT Pty Ltd | F97: First Focus IT Pty Ltd - Microsoft 365 Business Basic (NCE COM 1YR MTH) Serial Number(s): S365L | G97: INV170755 - MSA: CORE Intelligent Managed Services: CORE Intelligent Managed Services August 2026 [paid via DD] | H97: INV170755 - MSA: CORE Intelligent Managed Services: CORE Intelligent Managed Services August 2026 [paid via DD] | I97: 9000 - OFFICE / ADMIN [CTS] | J97: CTS | K97: 274.05 | L97: 0 | M97: 274.05
...

Sheet Reconciliation
A1: Corporate Technology Services Pty Ltd
A2: Reconciliation
A3: Discretionary technology spend - FY2027 year to date (1 July 2026 to 31 August 2026)
A5: Ref | B5: Reconciling item | C5: Amount | D5: Agrees | E5: Basis
A6: R1 | B6: Total expenditure per the Transaction Listing | C6: ='Transaction Listing'!M253 -> 58419.58 | E6: Sum of 247 ledger lines.
A7: R2 | B7: Total expenditure per the Summary schedule | C7: =Summary!E15 -> 58419.58 | E7: Sum of the seven accounts.
A8: R3 | B8: Difference, R1 less R2 | C8: =C6-C7 -> 0 | D8: =IF(ROUND(C8,2)=0,"Yes","NO") -> Yes | E8: Must be nil. The two schedules are built from the same lines.
A9: R4 | B9: Total expenditure per the Supplier Analysis schedule | C9: ='Supplier Analysis'!B326 -> 58419.58 | E9: Sum of all suppliers, including lines with no supplier recorded.
A10: R5 | B10: Difference, R1 less R4 | C10: =C6-C9 -> 0 | D10: =IF(ROUND(C10,2)=0,"Yes","NO") -> Yes | E10: Must be nil.
A11: R6 | B11: Total expenditure per the Monthly Analysis schedule | C11: ='Monthly Analysis'!D13 -> 58419.58 | E11: Sum of all months.
A12: R7 | B12: Difference, R1 less R6 | C12: =C6-C11 -> 0 | D12: =IF(ROUND(C12,2)=0,"Yes","NO") -> Yes | E12: Must be nil.
A13: R8 | B13: Line count per the Transaction Listing | C13: 247 | E13: Against 3,771 lines in the full ledger export for the period.
A14: R9 | B14: Debits less credits per the Transaction Listing | C14: ='Transaction Listing'!K253-'Transaction Listing'!L253 -> 58419.58 | E14: Equals total expenditure, confirming these are expense lines with no credits netted off.
A15: R10 | B15: Difference, R9 less R1 | C15: =C14-C6 -> 0 | D15: =IF(ROUND(C15,2)=0,"Yes","NO") -> Yes | E15: Must be nil.
