Workbook
Name set_AsAt: Settings!$B$5
Name set_FYStart: Settings!$B$6
Name set_DealShare: Settings!$B$7
Name set_BigValue: Settings!$B$8
Name set_EarlyProb: Settings!$B$9
Name set_ClientHigh: Settings!$B$10
Name set_Top5High: Settings!$B$11
Name set_ScoreHigh: Settings!$B$12
Name set_ScoreMed: Settings!$B$13
Name rev_Amt: 'Data - Revenue'!$AD$2:$AD$4501
Name rev_Date: 'Data - Revenue'!$AE$2:$AE$4501
Name rev_Cnt: 'Data - Revenue'!$AF$2:$AF$4501
Name rev_Month: 'Data - Revenue'!$AG$2:$AG$4501
Name rev_Client: 'Data - Revenue'!$AH$2:$AH$4501
Name rev_CC: 'Data - Revenue'!$AI$2:$AI$4501
Name rev_FY: 'Data - Revenue'!$AJ$2:$AJ$4501
Name rev_New: 'Data - Revenue'!$AK$2:$AK$4501
Name p_Status: 'Data - Pipeline'!$T$2:$T$601
Name p_Value: 'Data - Pipeline'!$U$2:$U$601
Name p_Has: 'Data - Pipeline'!$V$2:$V$601
Name p_Prob: 'Data - Pipeline'!$W$2:$W$601
Name p_Weighted: 'Data - Pipeline'!$X$2:$X$601
Name p_Still: 'Data - Pipeline'!$Y$2:$Y$601
Name p_Month: 'Data - Pipeline'!$Z$2:$Z$601
Name p_CC: 'Data - Pipeline'!$AA$2:$AA$601
Name p_Stage: 'Data - Pipeline'!$AB$2:$AB$601
Name p_Client: 'Data - Pipeline'!$AC$2:$AC$601
Name p_Deal: 'Data - Pipeline'!$AD$2:$AD$601
Name p_Job: 'Data - Pipeline'!$AE$2:$AE$601
Name p_Score: 'Data - Pipeline'!$AL$2:$AL$601
Name p_Rating: 'Data - Pipeline'!$AM$2:$AM$601
Name p_Reg: 'Data - Pipeline'!$AN$2:$AN$601
Name p_Risk: 'Data - Pipeline'!$AO$2:$AO$601
Name p_Key: 'Data - Pipeline'!$AP$2:$AP$601
Name p_Flags: 'Data - Pipeline'!$AQ$2:$AQ$601

Sheet Dashboard
A1: Revenue Risk Profile - FY27
A2: ="Corporate Technology Services - data as at "&TEXT(set_AsAt,"d mmmm yyyy")&". Actual revenue from Xero via the revenue tracker; won, lost and pipeline from Zoho."
B4: Invoiced FYTD | E4: Won - still to invoice | H4: Weighted open pipeline | K4: Full-year forecast | N4: Win rate (value) | Q4: Largest client share
B5: =Departments!B13 | E5: =Departments!G13 | H5: =Departments!I13 | K5: =Monthly!E17 | N5: =Departments!F13 | Q5: ='Client Concentration'!C32
B7: RISK REGISTER SUMMARY | C7: Items | D7: Revenue at risk | G7: Rating | H7: Deal | N7: Revenue at risk | P7: Why
B8: High | C8: =COUNTIFS(p_Reg,1,p_Rating,B8) | D8: =SUMIFS(p_Risk,p_Reg,1,p_Rating,B8) | G8: ='Risk Register'!B5 | H8: ='Risk Register'!E5&" - "&'Risk Register'!F5 | N8: ='Risk Register'!L5 | P8: ='Risk Register'!N5
B9: Medium | C9: =COUNTIFS(p_Reg,1,p_Rating,B9) | D9: =SUMIFS(p_Risk,p_Reg,1,p_Rating,B9) | G9: ='Risk Register'!B6 | H9: ='Risk Register'!E6&" - "&'Risk Register'!F6 | N9: ='Risk Register'!L6 | P9: ='Risk Register'!N6
B10: Low | C10: =COUNTIFS(p_Reg,1,p_Rating,B10) | D10: =SUMIFS(p_Risk,p_Reg,1,p_Rating,B10) | G10: ='Risk Register'!B7 | H10: ='Risk Register'!E7&" - "&'Risk Register'!F7 | N10: ='Risk Register'!L7 | P10: ='Risk Register'!N7
G11: ='Risk Register'!B8 | H11: ='Risk Register'!E8&" - "&'Risk Register'!F8 | N11: ='Risk Register'!L8 | P11: ='Risk Register'!N8
G12: ='Risk Register'!B9 | H12: ='Risk Register'!E9&" - "&'Risk Register'!F9 | N12: ='Risk Register'!L9 | P12: ='Risk Register'!N9
B13: Weighted pipeline uses assumed stage probabilities. Forecast = invoiced + won still to invoice + weighted pipeline. See Risk Register for every item and Settings for thresholds.

Sheet Read Me
A1: How this workbook works
A2: Revenue Risk Profile - built from the FY27 Revenue Tracker.
B4: WHAT IT SHOWS
B5: Dashboard - the headline numbers, the risk summary, the five biggest risks and five charts.
B6: Monthly - actual invoiced revenue by month, plus won work still to invoice and weighted pipeline by expected invoice month, and the full-year forecast.
B7: Departments - invoiced, won, lost, win rate, still to invoice and pipeline by cost centre, and the open pipeline by stage.
B8: Client Concentration - top 20 clients by invoiced revenue, their share and cumulative share, and three concentration measures with a High/Medium/Low rating.
B9: Risk Register - every open deal and every won deal not fully invoiced, scored and sorted worst first, with the reason.
B10: Settings - the thresholds behind every rating. Change them there.
B12: REFRESH IT EACH MONTH (two copy / paste-values)
B13: 1. In the revenue tracker, do the Zoho dump and make sure it has recalculated (open it in Excel and save).
B14: 2. Tracker Finance sheet: select A6:AB4506, Ctrl+C. Here: Data - Revenue, click A1, Paste Special - Values.
B15: 3. Tracker Work Won sheet: select A4:R604, Ctrl+C. Here: Data - Pipeline, click A1, Paste Special - Values.
B16: 4. Settings: change 'Data as at' to the date the tracker data is as at. Everything else, charts included, updates by itself.
... B23: Open deals dated outside this financial year are in the Risk Register but not in the monthly grid.

Sheet Monthly
A1: Monthly Revenue and Forecast
A2: Actual invoiced (Xero via Finance) plus won work still to invoice and the weighted open pipeline, by expected invoice month.
A4: Month | B4: Invoiced (actual) | C4: Won - still to invoice | D4: Open pipeline - weighted | E4: Forecast | F4: Open pipeline - full | G4: Cumulative actual | H4: Cumulative forecast
A5: =EOMONTH(set_FYStart,0) | B5: =SUMIFS(rev_Amt,rev_Cnt,1,rev_Month,$A5) | C5: =SUMIFS(p_Still,p_Status,"Won",p_Month,$A5,p_Still,">0") | D5: =SUMIFS(p_Weighted,p_Status,"Open",p_Month,$A5) | E5: =B5+C5+D5 | F5: =SUMIFS(p_Value,p_Status,"Open",p_Month,$A5) | G5: =IF($A5<=EOMONTH(set_AsAt,0),SUM($B$5:B5),) | H5: =SUM($E$5:E5)
A6: =EOMONTH(set_FYStart,1) | B6: =SUMIFS(rev_Amt,rev_Cnt,1,rev_Month,$A6) | C6: =SUMIFS(p_Still,p_Status,"Won",p_Month,$A6,p_Still,">0") | D6: =SUMIFS(p_Weighted,p_Status,"Open",p_Month,$A6) | E6: =B6+C6+D6 | F6: =SUMIFS(p_Value,p_Status,"Open",p_Month,$A6) | G6: =IF($A6<=EOMONTH(set_AsAt,0),SUM($B$5:B6),) | H6: =SUM($E$5:E6)
A7: =EOMONTH(set_FYStart,2) | B7: =SUMIFS(rev_Amt,rev_Cnt,1,rev_Month,$A7) | C7: =SUMIFS(p_Still,p_Status,"Won",p_Month,$A7,p_Still,">0") | D7: =SUMIFS(p_Weighted,p_Status,"Open",p_Month,$A7) | E7: =B7+C7+D7 | F7: =SUMIFS(p_Value,p_Status,"Open",p_Month,$A7) | G7: =IF($A7<=EOMONTH(set_AsAt,0),SUM($B$5:B7),) | H7: =SUM($E$5:E7)
A8: =EOMONTH(set_FYStart,3) | B8: =SUMIFS(rev_Amt,rev_Cnt,1,rev_Month,$A8) | C8: =SUMIFS(p_Still,p_Status,"Won",p_Month,$A8,p_Still,">0") | D8: =SUMIFS(p_Weighted,p_Status,"Open",p_Month,$A8) | E8: =B8+C8+D8 | F8: =SUMIFS(p_Value,p_Status,"Open",p_Month,$A8) | G8: =IF($A8<=EOMONTH(set_AsAt,0),SUM($B$5:B8),) | H8: =SUM($E$5:E8)
A9: =EOMONTH(set_FYStart,4) | B9: =SUMIFS(rev_Amt,rev_Cnt,1,rev_Month,$A9) | C9: =SUMIFS(p_Still,p_Status,"Won",p_Month,$A9,p_Still,">0") | D9: =SUMIFS(p_Weighted,p_Status,"Open",p_Month,$A9) | E9: =B9+C9+D9 | F9: =SUMIFS(p_Value,p_Status,"Open",p_Month,$A9) | G9: =IF($A9<=EOMONTH(set_AsAt,0),SUM($B$5:B9),) | H9: =SUM($E$5:E9)
A10: =EOMONTH(set_FYStart,5) | B10: =SUMIFS(rev_Amt,rev_Cnt,1,rev_Month,$A10) | C10: =SUMIFS(p_Still,p_Status,"Won",p_Month,$A10,p_Still,">0") | D10: =SUMIFS(p_Weighted,p_Status,"Open",p_Month,$A10) | E10: =B10+C10+D10 | F10: =SUMIFS(p_Value,p_Status,"Open",p_Month,$A10) | G10: =IF($A10<=EOMONTH(set_AsAt,0),SUM($B$5:B10),) | H10: =SUM($E$5:E10)
A11: =EOMONTH(set_FYStart,6) | B11: =SUMIFS(rev_Amt,rev_Cnt,1,rev_Month,$A11) | C11: =SUMIFS(p_Still,p_Status,"Won",p_Month,$A11,p_Still,">0") | D11: =SUMIFS(p_Weighted,p_Status,"Open",p_Month,$A11) | E11: =B11+C11+D11 | F11: =SUMIFS(p_Value,p_Status,"Open",p_Month,$A11) | G11: =IF($A11<=EOMONTH(set_AsAt,0),SUM($B$5:B11),) | H11: =SUM($E$5:E11)
A12: =EOMONTH(set_FYStart,7) | B12: =SUMIFS(rev_Amt,rev_Cnt,1,rev_Month,$A12) | C12: =SUMIFS(p_Still,p_Status,"Won",p_Month,$A12,p_Still,">0") | D12: =SUMIFS(p_Weighted,p_Status,"Open",p_Month,$A12) | E12: =B12+C12+D12 | F12: =SUMIFS(p_Value,p_Status,"Open",p_Month,$A12) | G12: =IF($A12<=EOMONTH(set_AsAt,0),SUM($B$5:B12),) | H12: =SUM($E$5:E12)
A13: =EOMONTH(set_FYStart,8) | B13: =SUMIFS(rev_Amt,rev_Cnt,1,rev_Month,$A13) | C13: =SUMIFS(p_Still,p_Status,"Won",p_Month,$A13,p_Still,">0") | D13: =SUMIFS(p_Weighted,p_Status,"Open",p_Month,$A13) | E13: =B13+C13+D13 | F13: =SUMIFS(p_Value,p_Status,"Open",p_Month,$A13) | G13: =IF($A13<=EOMONTH(set_AsAt,0),SUM($B$5:B13),) | H13: =SUM($E$5:E13)
A14: =EOMONTH(set_FYStart,9) | B14: =SUMIFS(rev_Amt,rev_Cnt,1,rev_Month,$A14) | C14: =SUMIFS(p_Still,p_Status,"Won",p_Month,$A14,p_Still,">0") | D14: =SUMIFS(p_Weighted,p_Status,"Open",p_Month,$A14) | E14: =B14+C14+D14 | F14: =SUMIFS(p_Value,p_Status,"Open",p_Month,$A14) | G14: =IF($A14<=EOMONTH(set_AsAt,0),SUM($B$5:B14),) | H14: =SUM($E$5:E14)
A15: =EOMONTH(set_FYStart,10) | B15: =SUMIFS(rev_Amt,rev_Cnt,1,rev_Month,$A15) | C15: =SUMIFS(p_Still,p_Status,"Won",p_Month,$A15,p_Still,">0") | D15: =SUMIFS(p_Weighted,p_Status,"Open",p_Month,$A15) | E15: =B15+C15+D15 | F15: =SUMIFS(p_Value,p_Status,"Open",p_Month,$A15) | G15: =IF($A15<=EOMONTH(set_AsAt,0),SUM($B$5:B15),) | H15: =SUM($E$5:E15)
A16: =EOMONTH(set_FYStart,11) | B16: =SUMIFS(rev_Amt,rev_Cnt,1,rev_Month,$A16) | C16: =SUMIFS(p_Still,p_Status,"Won",p_Month,$A16,p_Still,">0") | D16: =SUMIFS(p_Weighted,p_Status,"Open",p_Month,$A16) | E16: =B16+C16+D16 | F16: =SUMIFS(p_Value,p_Status,"Open",p_Month,$A16) | G16: =IF($A16<=EOMONTH(set_AsAt,0),SUM($B$5:B16),) | H16: =SUM($E$5:E16)
A17: TOTAL | B17: =SUM(B5:B16) | C17: =SUM(C5:C16) | D17: =SUM(D5:D16) | E17: =SUM(E5:E16) | F17: =SUM(F5:F16)
A19: Won - still to invoice counts only positive balances. In months already gone it is billing to chase, not future revenue. Weighted = deal value x stage probability (tracker Lists AA:AB - assumptions). Open deals dated outside this FY are not in the grid.

Sheet Departments
A1: By Cost Centre and Pipeline Stage
A2: Where the revenue comes from and where the pipeline sits.
A4: 1. BY COST CENTRE - financial year to date
A5: Cost Centre | B5: Invoiced FYTD | C5: Share | D5: Won (FY) | E5: Lost (FY) | F5: Win rate (value) | G5: Won - still to invoice | H5: Open pipeline | I5: Weighted pipeline | J5: Rest-of-year forecast
A6: ONSITE | B6: =SUMIFS(rev_Amt,rev_FY,1,rev_CC,$A6) | C6: =IFERROR(B6/$B$13,0) | D6: =SUMIFS(p_Value,p_Status,"Won",p_CC,$A6) | E6: =SUMIFS(p_Value,p_Status,"Lost",p_CC,$A6) | F6: =IFERROR(D6/(D6+E6),"") | G6: =SUMIFS(p_Still,p_Status,"Won",p_Still,">0",p_CC,$A6) | H6: =SUMIFS(p_Value,p_Status,"Open",p_CC,$A6) | I6: =SUMIFS(p_Weighted,p_Status,"Open",p_CC,$A6) | J6: =G6+I6
A7: PRODUCTION | B7: =SUMIFS(rev_Amt,rev_FY,1,rev_CC,$A7) | C7: =IFERROR(B7/$B$13,0) | D7: =SUMIFS(p_Value,p_Status,"Won",p_CC,$A7) | E7: =SUMIFS(p_Value,p_Status,"Lost",p_CC,$A7) | F7: =IFERROR(D7/(D7+E7),"") | G7: =SUMIFS(p_Still,p_Status,"Won",p_Still,">0",p_CC,$A7) | H7: =SUMIFS(p_Value,p_Status,"Open",p_CC,$A7) | I7: =SUMIFS(p_Weighted,p_Status,"Open",p_CC,$A7) | J7: =G7+I7
A8: VIDEO | B8: =SUMIFS(rev_Amt,rev_FY,1,rev_CC,$A8) | C8: =IFERROR(B8/$B$13,0) | D8: =SUMIFS(p_Value,p_Status,"Won",p_CC,$A8) | E8: =SUMIFS(p_Value,p_Status,"Lost",p_CC,$A8) | F8: =IFERROR(D8/(D8+E8),"") | G8: =SUMIFS(p_Still,p_Status,"Won",p_Still,">0",p_CC,$A8) | H8: =SUMIFS(p_Value,p_Status,"Open",p_CC,$A8) | I8: =SUMIFS(p_Weighted,p_Status,"Open",p_CC,$A8) | J8: =G8+I8
A9: INTEGRATION | B9: =SUMIFS(rev_Amt,rev_FY,1,rev_CC,$A9) | C9: =IFERROR(B9/$B$13,0) | D9: =SUMIFS(p_Value,p_Status,"Won",p_CC,$A9) | E9: =SUMIFS(p_Value,p_Status,"Lost",p_CC,$A9) | F9: =IFERROR(D9/(D9+E9),"") | G9: =SUMIFS(p_Still,p_Status,"Won",p_Still,">0",p_CC,$A9) | H9: =SUMIFS(p_Value,p_Status,"Open",p_CC,$A9) | I9: =SUMIFS(p_Weighted,p_Status,"Open",p_CC,$A9) | J9: =G9+I9
A10: CONSULTING | B10: =SUMIFS(rev_Amt,rev_FY,1,rev_CC,$A10) | C10: =IFERROR(B10/$B$13,0) | D10: =SUMIFS(p_Value,p_Status,"Won",p_CC,$A10) | E10: =SUMIFS(p_Value,p_Status,"Lost",p_CC,$A10) | F10: =IFERROR(D10/(D10+E10),"") | G10: =SUMIFS(p_Still,p_Status,"Won",p_Still,">0",p_CC,$A10) | H10: =SUMIFS(p_Value,p_Status,"Open",p_CC,$A10) | I10: =SUMIFS(p_Weighted,p_Status,"Open",p_CC,$A10) | J10: =G10+I10
A11: CTS | B11: =SUMIFS(rev_Amt,rev_FY,1,rev_CC,$A11) | C11: =IFERROR(B11/$B$13,0) | D11: =SUMIFS(p_Value,p_Status,"Won",p_CC,$A11) | E11: =SUMIFS(p_Value,p_Status,"Lost",p_CC,$A11) | F11: =IFERROR(D11/(D11+E11),"") | G11: =SUMIFS(p_Still,p_Status,"Won",p_Still,">0",p_CC,$A11) | H11: =SUMIFS(p_Value,p_Status,"Open",p_CC,$A11) | I11: =SUMIFS(p_Weighted,p_Status,"Open",p_CC,$A11) | J11: =G11+I11
A12: Other / not set | B12: =SUMIFS(rev_Amt,rev_FY,1)-SUM(B6:B11) | C12: =IFERROR(B12/$B$13,0) | D12: =SUMIFS(p_Value,p_Status,"Won")-SUM(D6:D11) | E12: =SUMIFS(p_Value,p_Status,"Lost")-SUM(E6:E11) | F12: =IFERROR(D12/(D12+E12),"") | G12: =SUMIFS(p_Still,p_Status,"Won",p_Still,">0")-SUM(G6:G11) | H12: =SUMIFS(p_Value,p_Status,"Open")-SUM(H6:H11) | I12: =SUMIFS(p_Weighted,p_Status,"Open")-SUM(I6:I11) | J12: =G12+I12
A13: TOTAL | B13: =SUM(B6:B12) | C13: =SUM(C6:C12) | D13: =SUM(D6:D12) | E13: =SUM(E6:E12) | F13: =IFERROR(D13/(D13+E13),"") | G13: =SUM(G6:G12) | H13: =SUM(H6:H12) | I13: =SUM(I6:I12) | J13: =SUM(J6:J12)
A16: 2. OPEN PIPELINE BY STAGE
A17: Stage | B17: Deals | C17: Full value | D17: Weighted value | E17: Probability | F17: Share of pipeline
A18: Building Value Proposition | B18: =COUNTIFS(p_Status,"Open",p_Stage,$A18) | C18: =SUMIFS(p_Value,p_Status,"Open",p_Stage,$A18) | D18: =SUMIFS(p_Weighted,p_Status,"Open",p_Stage,$A18) | E18: =IFERROR(D18/C18,0) | F18: =IFERROR(C18/$C$22,0)
A19: Proposal Sent | B19: =COUNTIFS(p_Status,"Open",p_Stage,$A19) | C19: =SUMIFS(p_Value,p_Status,"Open",p_Stage,$A19) | D19: =SUMIFS(p_Weighted,p_Status,"Open",p_Stage,$A19) | E19: =IFERROR(D19/C19,0) | F19: =IFERROR(C19/$C$22,0)
A20: Negotiation/Review | B20: =COUNTIFS(p_Status,"Open",p_Stage,$A20) | C20: =SUMIFS(p_Value,p_Status,"Open",p_Stage,$A20) | D20: =SUMIFS(p_Weighted,p_Status,"Open",p_Stage,$A20) | E20: =IFERROR(D20/C20,0) | F20: =IFERROR(C20/$C$22,0)
A21: Verbal Approval | B21: =COUNTIFS(p_Status,"Open",p_Stage,$A21) | C21: =SUMIFS(p_Value,p_Status,"Open",p_Stage,$A21) | D21: =SUMIFS(p_Weighted,p_Status,"Open",p_Stage,$A21) | E21: =IFERROR(D21/C21,0) | F21: =IFERROR(C21/$C$22,0)
A22: TOTAL OPEN | B22: =SUM(B18:B21) | C22: =SUM(C18:C21) | D22: =SUM(D18:D21) | E22: =IFERROR(D22/C22,0) | F22: =SUM(F18:F21)

Sheet Client Concentration
A1: Client Concentration
A2: How dependent FYTD invoiced revenue is on a few clients. Client names are grouped as typed on the tracker (upper case, trimmed).
A4: 1. TOP CLIENTS - invoiced financial year to date
A5: Rank | B5: Client | C5: Invoiced FYTD | D5: Share | E5: Cumulative share | F5: Invoices | L5: Client (all) | M5: No. | N5: Sort key | O5: Share | P5: Share squared
A6: 1 | B6: =IFERROR(INDEX($L$6:$L$305,MATCH(LARGE($N$6:$N$305,1),$N$6:$N$305,0)),"") | C6: =IF(B6="","",SUMIFS(rev_Amt,rev_FY,1,rev_Client,B6)) | D6: =IF(B6="","",IFERROR(C6/$C$28,0)) | E6: =IF(B6="","",SUM($D$6:D6)) | F6: =IF(B6="","",COUNTIFS(rev_FY,1,rev_Client,B6)) | L6: =IFERROR(INDEX(rev_Client,MATCH(1,rev_New,0)),"") | M6: =IF(L6="","",1) | N6: =IF(L6="","",SUMIFS(rev_Amt,rev_FY,1,rev_Client,L6)+1/1E+6) | O6: =IF(L6="","",IFERROR(SUMIFS(rev_Amt,rev_FY,1,rev_Client,L6)/$C$28,0)) | P6: =IF(O6="",0,O6^2)
A7: 2 | B7: =IFERROR(INDEX($L$6:$L$305,MATCH(LARGE($N$6:$N$305,2),$N$6:$N$305,0)),"") | C7: =IF(B7="","",SUMIFS(rev_Amt,rev_FY,1,rev_Client,B7)) | D7: =IF(B7="","",IFERROR(C7/$C$28,0)) | E7: =IF(B7="","",SUM($D$6:D7)) | F7: =IF(B7="","",COUNTIFS(rev_FY,1,rev_Client,B7)) | L7: =IFERROR(INDEX(rev_Client,MATCH(2,rev_New,0)),"") | M7: =IF(L7="","",2) | N7: =IF(L7="","",SUMIFS(rev_Amt,rev_FY,1,rev_Client,L7)+2/1E+6) | O7: =IF(L7="","",IFERROR(SUMIFS(rev_Amt,rev_FY,1,rev_Client,L7)/$C$28,0)) | P7: =IF(O7="",0,O7^2)
A8: 3 | B8: =IFERROR(INDEX($L$6:$L$305,MATCH(LARGE($N$6:$N$305,3),$N$6:$N$305,0)),"") | C8: =IF(B8="","",SUMIFS(rev_Amt,rev_FY,1,rev_Client,B8)) | D8: =IF(B8="","",IFERROR(C8/$C$28,0)) | E8: =IF(B8="","",SUM($D$6:D8)) | F8: =IF(B8="","",COUNTIFS(rev_FY,1,rev_Client,B8)) | L8: =IFERROR(INDEX(rev_Client,MATCH(3,rev_New,0)),"") | M8: =IF(L8="","",3) | N8: =IF(L8="","",SUMIFS(rev_Amt,rev_FY,1,rev_Client,L8)+3/1E+6) | O8: =IF(L8="","",IFERROR(SUMIFS(rev_Amt,rev_FY,1,rev_Client,L8)/$C$28,0)) | P8: =IF(O8="",0,O8^2)
A9: 4 | B9: =IFERROR(INDEX($L$6:$L$305,MATCH(LARGE($N$6:$N$305,4),$N$6:$N$305,0)),"") | C9: =IF(B9="","",SUMIFS(rev_Amt,rev_FY,1,rev_Client,B9)) | D9: =IF(B9="","",IFERROR(C9/$C$28,0)) | E9: =IF(B9="","",SUM($D$6:D9)) | F9: =IF(B9="","",COUNTIFS(rev_FY,1,rev_Client,B9)) | L9: =IFERROR(INDEX(rev_Client,MATCH(4,rev_New,0)),"") | M9: =IF(L9="","",4) | N9: =IF(L9="","",SUMIFS(rev_Amt,rev_FY,1,rev_Client,L9)+4/1E+6) | O9: =IF(L9="","",IFERROR(SUMIFS(rev_Amt,rev_FY,1,rev_Client,L9)/$C$28,0)) | P9: =IF(O9="",0,O9^2)
A10: 5 | B10: =IFERROR(INDEX($L$6:$L$305,MATCH(LARGE($N$6:$N$305,5),$N$6:$N$305,0)),"") | C10: =IF(B10="","",SUMIFS(rev_Amt,rev_FY,1,rev_Client,B10)) | D10: =IF(B10="","",IFERROR(C10/$C$28,0)) | E10: =IF(B10="","",SUM($D$6:D10)) | F10: =IF(B10="","",COUNTIFS(rev_FY,1,rev_Client,B10)) | L10: =IFERROR(INDEX(rev_Client,MATCH(5,rev_New,0)),"") | M10: =IF(L10="","",5) | N10: =IF(L10="","",SUMIFS(rev_Amt,rev_FY,1,rev_Client,L10)+5/1E+6) | O10: =IF(L10="","",IFERROR(SUMIFS(rev_Amt,rev_FY,1,rev_Client,L10)/$C$28,0)) | P10: =IF(O10="",0,O10^2)
A11: 6 | B11: =IFERROR(INDEX($L$6:$L$305,MATCH(LARGE($N$6:$N$305,6),$N$6:$N$305,0)),"") | C11: =IF(B11="","",SUMIFS(rev_Amt,rev_FY,1,rev_Client,B11)) | D11: =IF(B11="","",IFERROR(C11/$C$28,0)) | E11: =IF(B11="","",SUM($D$6:D11)) | F11: =IF(B11="","",COUNTIFS(rev_FY,1,rev_Client,B11)) | L11: =IFERROR(INDEX(rev_Client,MATCH(6,rev_New,0)),"") | M11: =IF(L11="","",6) | N11: =IF(L11="","",SUMIFS(rev_Amt,rev_FY,1,rev_Client,L11)+6/1E+6) | O11: =IF(L11="","",IFERROR(SUMIFS(rev_Amt,rev_FY,1,rev_Client,L11)/$C$28,0)) | P11: =IF(O11="",0,O11^2)
A12: 7 | B12: =IFERROR(INDEX($L$6:$L$305,MATCH(LARGE($N$6:$N$305,7),$N$6:$N$305,0)),"") | C12: =IF(B12="","",SUMIFS(rev_Amt,rev_FY,1,rev_Client,B12)) | D12: =IF(B12="","",IFERROR(C12/$C$28,0)) | E12: =IF(B12="","",SUM($D$6:D12)) | F12: =IF(B12="","",COUNTIFS(rev_FY,1,rev_Client,B12)) | L12: =IFERROR(INDEX(rev_Client,MATCH(7,rev_New,0)),"") | M12: =IF(L12="","",7) | N12: =IF(L12="","",SUMIFS(rev_Amt,rev_FY,1,rev_Client,L12)+7/1E+6) | O12: =IF(L12="","",IFERROR(SUMIFS(rev_Amt,rev_FY,1,rev_Client,L12)/$C$28,0)) | P12: =IF(O12="",0,O12^2)
A13: 8 | B13: =IFERROR(INDEX($L$6:$L$305,MATCH(LARGE($N$6:$N$305,8),$N$6:$N$305,0)),"") | C13: =IF(B13="","",SUMIFS(rev_Amt,rev_FY,1,rev_Client,B13)) | D13: =IF(B13="","",IFERROR(C13/$C$28,0)) | E13: =IF(B13="","",SUM($D$6:D13)) | F13: =IF(B13="","",COUNTIFS(rev_FY,1,rev_Client,B13)) | L13: =IFERROR(INDEX(rev_Client,MATCH(8,rev_New,0)),"") | M13: =IF(L13="","",8) | N13: =IF(L13="","",SUMIFS(rev_Amt,rev_FY,1,rev_Client,L13)+8/1E+6) | O13: =IF(L13="","",IFERROR(SUMIFS(rev_Amt,rev_FY,1,rev_Client,L13)/$C$28,0)) | P13: =IF(O13="",0,O13^2)
A14: 9 | B14: =IFERROR(INDEX($L$6:$L$305,MATCH(LARGE($N$6:$N$305,9),$N$6:$N$305,0)),"") | C14: =IF(B14="","",SUMIFS(rev_Amt,rev_FY,1,rev_Client,B14)) | D14: =IF(B14="","",IFERROR(C14/$C$28,0)) | E14: =IF(B14="","",SUM($D$6:D14)) | F14: =IF(B14="","",COUNTIFS(rev_FY,1,rev_Client,B14)) | L14: =IFERROR(INDEX(rev_Client,MATCH(9,rev_New,0)),"") | M14: =IF(L14="","",9) | N14: =IF(L14="","",SUMIFS(rev_Amt,rev_FY,1,rev_Client,L14)+9/1E+6) | O14: =IF(L14="","",IFERROR(SUMIFS(rev_Amt,rev_FY,1,rev_Client,L14)/$C$28,0)) | P14: =IF(O14="",0,O14^2)
A15: 10 | B15: =IFERROR(INDEX($L$6:$L$305,MATCH(LARGE($N$6:$N$305,10),$N$6:$N$305,0)),"") | C15: =IF(B15="","",SUMIFS(rev_Amt,rev_FY,1,rev_Client,B15)) | D15: =IF(B15="","",IFERROR(C15/$C$28,0)) | E15: =IF(B15="","",SUM($D$6:D15)) | F15: =IF(B15="","",COUNTIFS(rev_FY,1,rev_Client,B15)) | L15: =IFERROR(INDEX(rev_Client,MATCH(10,rev_New,0)),"") | M15: =IF(L15="","",10) | N15: =IF(L15="","",SUMIFS(rev_Amt,rev_FY,1,rev_Client,L15)+10/1E+6) | O15: =IF(L15="","",IFERROR(SUMIFS(rev_Amt,rev_FY,1,rev_Client,L15)/$C$28,0)) | P15: =IF(O15="",0,O15^2)
A16: 11 | B16: =IFERROR(INDEX($L$6:$L$305,MATCH(LARGE($N$6:$N$305,11),$N$6:$N$305,0)),"") | C16: =IF(B16="","",SUMIFS(rev_Amt,rev_FY,1,rev_Client,B16)) | D16: =IF(B16="","",IFERROR(C16/$C$28,0)) | E16: =IF(B16="","",SUM($D$6:D16)) | F16: =IF(B16="","",COUNTIFS(rev_FY,1,rev_Client,B16)) | L16: =IFERROR(INDEX(rev_Client,MATCH(11,rev_New,0)),"") | M16: =IF(L16="","",11) | N16: =IF(L16="","",SUMIFS(rev_Amt,rev_FY,1,rev_Client,L16)+11/1E+6) | O16: =IF(L16="","",IFERROR(SUMIFS(rev_Amt,rev_FY,1,rev_Client,L16)/$C$28,0)) | P16: =IF(O16="",0,O16^2)
A17: 12 | B17: =IFERROR(INDEX($L$6:$L$305,MATCH(LARGE($N$6:$N$305,12),$N$6:$N$305,0)),"") | C17: =IF(B17="","",SUMIFS(rev_Amt,rev_FY,1,rev_Client,B17)) | D17: =IF(B17="","",IFERROR(C17/$C$28,0)) | E17: =IF(B17="","",SUM($D$6:D17)) | F17: =IF(B17="","",COUNTIFS(rev_FY,1,rev_Client,B17)) | L17: =IFERROR(INDEX(rev_Client,MATCH(12,rev_New,0)),"") | M17: =IF(L17="","",12) | N17: =IF(L17="","",SUMIFS(rev_Amt,rev_FY,1,rev_Client,L17)+12/1E+6) | O17: =IF(L17="","",IFERROR(SUMIFS(rev_Amt,rev_FY,1,rev_Client,L17)/$C$28,0)) | P17: =IF(O17="",0,O17^2)
A18: 13 | B18: =IFERROR(INDEX($L$6:$L$305,MATCH(LARGE($N$6:$N$305,13),$N$6:$N$305,0)),"") | C18: =IF(B18="","",SUMIFS(rev_Amt,rev_FY,1,rev_Client,B18)) | D18: =IF(B18="","",IFERROR(C18/$C$28,0)) | E18: =IF(B18="","",SUM($D$6:D18)) | F18: =IF(B18="","",COUNTIFS(rev_FY,1,rev_Client,B18)) | L18: =IFERROR(INDEX(rev_Client,MATCH(13,rev_New,0)),"") | M18: =IF(L18="","",13) | N18: =IF(L18="","",SUMIFS(rev_Amt,rev_FY,1,rev_Client,L18)+13/1E+6) | O18: =IF(L18="","",IFERROR(SUMIFS(rev_Amt,rev_FY,1,rev_Client,L18)/$C$28,0)) | P18: =IF(O18="",0,O18^2)
A19: 14 | B19: =IFERROR(INDEX($L$6:$L$305,MATCH(LARGE($N$6:$N$305,14),$N$6:$N$305,0)),"") | C19: =IF(B19="","",SUMIFS(rev_Amt,rev_FY,1,rev_Client,B19)) | D19: =IF(B19="","",IFERROR(C19/$C$28,0)) | E19: =IF(B19="","",SUM($D$6:D19)) | F19: =IF(B19="","",COUNTIFS(rev_FY,1,rev_Client,B19)) | L19: =IFERROR(INDEX(rev_Client,MATCH(14,rev_New,0)),"") | M19: =IF(L19="","",14) | N19: =IF(L19="","",SUMIFS(rev_Amt,rev_FY,1,rev_Client,L19)+14/1E+6) | O19: =IF(L19="","",IFERROR(SUMIFS(rev_Amt,rev_FY,1,rev_Client,L19)/$C$28,0)) | P19: =IF(O19="",0,O19^2)
A20: 15 | B20: =IFERROR(INDEX($L$6:$L$305,MATCH(LARGE($N$6:$N$305,15),$N$6:$N$305,0)),"") | C20: =IF(B20="","",SUMIFS(rev_Amt,rev_FY,1,rev_Client,B20)) | D20: =IF(B20="","",IFERROR(C20/$C$28,0)) | E20: =IF(B20="","",SUM($D$6:D20)) | F20: =IF(B20="","",COUNTIFS(rev_FY,1,rev_Client,B20)) | L20: =IFERROR(INDEX(rev_Client,MATCH(15,rev_New,0)),"") | M20: =IF(L20="","",15) | N20: =IF(L20="","",SUMIFS(rev_Amt,rev_FY,1,rev_Client,L20)+15/1E+6) | O20: =IF(L20="","",IFERROR(SUMIFS(rev_Amt,rev_FY,1,rev_Client,L20)/$C$28,0)) | P20: =IF(O20="",0,O20^2)
A21: 16 | B21: =IFERROR(INDEX($L$6:$L$305,MATCH(LARGE($N$6:$N$305,16),$N$6:$N$305,0)),"") | C21: =IF(B21="","",SUMIFS(rev_Amt,rev_FY,1,rev_Client,B21)) | D21: =IF(B21="","",IFERROR(C21/$C$28,0)) | E21: =IF(B21="","",SUM($D$6:D21)) | F21: =IF(B21="","",COUNTIFS(rev_FY,1,rev_Client,B21)) | L21: =IFERROR(INDEX(rev_Client,MATCH(16,rev_New,0)),"") | M21: =IF(L21="","",16) | N21: =IF(L21="","",SUMIFS(rev_Amt,rev_FY,1,rev_Client,L21)+16/1E+6) | O21: =IF(L21="","",IFERROR(SUMIFS(rev_Amt,rev_FY,1,rev_Client,L21)/$C$28,0)) | P21: =IF(O21="",0,O21^2)
A22: 17 | B22: =IFERROR(INDEX($L$6:$L$305,MATCH(LARGE($N$6:$N$305,17),$N$6:$N$305,0)),"") | C22: =IF(B22="","",SUMIFS(rev_Amt,rev_FY,1,rev_Client,B22)) | D22: =IF(B22="","",IFERROR(C22/$C$28,0)) | E22: =IF(B22="","",SUM($D$6:D22)) | F22: =IF(B22="","",COUNTIFS(rev_FY,1,rev_Client,B22)) | L22: =IFERROR(INDEX(rev_Client,MATCH(17,rev_New,0)),"") | M22: =IF(L22="","",17) | N22: =IF(L22="","",SUMIFS(rev_Amt,rev_FY,1,rev_Client,L22)+17/1E+6) | O22: =IF(L22="","",IFERROR(SUMIFS(rev_Amt,rev_FY,1,rev_Client,L22)/$C$28,0)) | P22: =IF(O22="",0,O22^2)
A23: 18 | B23: =IFERROR(INDEX($L$6:$L$305,MATCH(LARGE($N$6:$N$305,18),$N$6:$N$305,0)),"") | C23: =IF(B23="","",SUMIFS(rev_Amt,rev_FY,1,rev_Client,B23)) | D23: =IF(B23="","",IFERROR(C23/$C$28,0)) | E23: =IF(B23="","",SUM($D$6:D23)) | F23: =IF(B23="","",COUNTIFS(rev_FY,1,rev_Client,B23)) | L23: =IFERROR(INDEX(rev_Client,MATCH(18,rev_New,0)),"") | M23: =IF(L23="","",18) | N23: =IF(L23="","",SUMIFS(rev_Amt,rev_FY,1,rev_Client,L23)+18/1E+6) | O23: =IF(L23="","",IFERROR(SUMIFS(rev_Amt,rev_FY,1,rev_Client,L23)/$C$28,0)) | P23: =IF(O23="",0,O23^2)
A24: 19 | B24: =IFERROR(INDEX($L$6:$L$305,MATCH(LARGE($N$6:$N$305,19),$N$6:$N$305,0)),"") | C24: =IF(B24="","",SUMIFS(rev_Amt,rev_FY,1,rev_Client,B24)) | D24: =IF(B24="","",IFERROR(C24/$C$28,0)) | E24: =IF(B24="","",SUM($D$6:D24)) | F24: =IF(B24="","",COUNTIFS(rev_FY,1,rev_Client,B24)) | L24: =IFERROR(INDEX(rev_Client,MATCH(19,rev_New,0)),"") | M24: =IF(L24="","",19) | N24: =IF(L24="","",SUMIFS(rev_Amt,rev_FY,1,rev_Client,L24)+19/1E+6) | O24: =IF(L24="","",IFERROR(SUMIFS(rev_Amt,rev_FY,1,rev_Client,L24)/$C$28,0)) | P24: =IF(O24="",0,O24^2)
A25: 20 | B25: =IFERROR(INDEX($L$6:$L$305,MATCH(LARGE($N$6:$N$305,20),$N$6:$N$305,0)),"") | C25: =IF(B25="","",SUMIFS(rev_Amt,rev_FY,1,rev_Client,B25)) | D25: =IF(B25="","",IFERROR(C25/$C$28,0)) | E25: =IF(B25="","",SUM($D$6:D25)) | F25: =IF(B25="","",COUNTIFS(rev_FY,1,rev_Client,B25)) | L25: =IFERROR(INDEX(rev_Client,MATCH(20,rev_New,0)),"") | M25: =IF(L25="","",20) | N25: =IF(L25="","",SUMIFS(rev_Amt,rev_FY,1,rev_Client,L25)+20/1E+6) | O25: =IF(L25="","",IFERROR(SUMIFS(rev_Amt,rev_FY,1,rev_Client,L25)/$C$28,0)) | P25: =IF(O25="",0,O25^2)
L26: =IFERROR(INDEX(rev_Client,MATCH(21,rev_New,0)),"") | M26: =IF(L26="","",21) | N26: =IF(L26="","",SUMIFS(rev_Amt,rev_FY,1,rev_Client,L26)+21/1E+6) | O26: =IF(L26="","",IFERROR(SUMIFS(rev_Amt,rev_FY,1,rev_Client,L26)/$C$28,0)) | P26: =IF(O26="",0,O26^2)
B27: All other clients | C27: =C28-SUM(C6:C25) | D27: =IFERROR(C27/C28,0) | L27: =IFERROR(INDEX(rev_Client,MATCH(22,rev_New,0)),"") | M27: =IF(L27="","",22) | N27: =IF(L27="","",SUMIFS(rev_Amt,rev_FY,1,rev_Client,L27)+22/1E+6) | O27: =IF(L27="","",IFERROR(SUMIFS(rev_Amt,rev_FY,1,rev_Client,L27)/$C$28,0)) | P27: =IF(O27="",0,O27^2)
B28: TOTAL INVOICED FYTD | C28: =SUMIFS(rev_Amt,rev_FY,1) | L28: =IFERROR(INDEX(rev_Client,MATCH(23,rev_New,0)),"") | M28: =IF(L28="","",23) | N28: =IF(L28="","",SUMIFS(rev_Amt,rev_FY,1,rev_Client,L28)+23/1E+6) | O28: =IF(L28="","",IFERROR(SUMIFS(rev_Amt,rev_FY,1,rev_Client,L28)/$C$28,0)) | P28: =IF(O28="",0,O28^2)
L29: =IFERROR(INDEX(rev_Client,MATCH(24,rev_New,0)),"") | M29: =IF(L29="","",24) | N29: =IF(L29="","",SUMIFS(rev_Amt,rev_FY,1,rev_Client,L29)+24/1E+6) | O29: =IF(L29="","",IFERROR(SUMIFS(rev_Amt,rev_FY,1,rev_Client,L29)/$C$28,0)) | P29: =IF(O29="",0,O29^2)
A30: 2. CONCENTRATION MEASURES | L30: =IFERROR(INDEX(rev_Client,MATCH(25,rev_New,0)),"") | M30: =IF(L30="","",25) | N30: =IF(L30="","",SUMIFS(rev_Amt,rev_FY,1,rev_Client,L30)+25/1E+6) | O30: =IF(L30="","",IFERROR(SUMIFS(rev_Amt,rev_FY,1,rev_Client,L30)/$C$28,0)) | P30: =IF(O30="",0,O30^2)
B31: Clients invoiced FYTD | C31: =MAX($M$6:$M$305) | L31: =IFERROR(INDEX(rev_Client,MATCH(26,rev_New,0)),"") | M31: =IF(L31="","",26) | N31: =IF(L31="","",SUMIFS(rev_Amt,rev_FY,1,rev_Client,L31)+26/1E+6) | O31: =IF(L31="","",IFERROR(SUMIFS(rev_Amt,rev_FY,1,rev_Client,L31)/$C$28,0)) | P31: =IF(O31="",0,O31^2)
B32: Largest client share | C32: =D6 | D32: =IF(D6>=set_ClientHigh,"High",IF(D6>=set_ClientHigh*0.6,"Medium","Low")) | L32: =IFERROR(INDEX(rev_Client,MATCH(27,rev_New,0)),"") | M32: =IF(L32="","",27) | N32: =IF(L32="","",SUMIFS(rev_Amt,rev_FY,1,rev_Client,L32)+27/1E+6) | O32: =IF(L32="","",IFERROR(SUMIFS(rev_Amt,rev_FY,1,rev_Client,L32)/$C$28,0)) | P32: =IF(O32="",0,O32^2)
B33: Top 5 clients share | C33: =IFERROR(SUM(C6:C10)/C28,0) | D33: =IF(C33>=set_Top5High,"High",IF(C33>=set_Top5High*0.75,"Medium","Low")) | L33: =IFERROR(INDEX(rev_Client,MATCH(28,rev_New,0)),"") | M33: =IF(L33="","",28) | N33: =IF(L33="","",SUMIFS(rev_Amt,rev_FY,1,rev_Client,L33)+28/1E+6) | O33: =IF(L33="","",IFERROR(SUMIFS(rev_Amt,rev_FY,1,rev_Client,L33)/$C$28,0)) | P33: =IF(O33="",0,O33^2)
B34: Top 10 clients share | C34: =IFERROR(SUM(C6:C15)/C28,0) | L34: =IFERROR(INDEX(rev_Client,MATCH(29,rev_New,0)),"") | M34: =IF(L34="","",29) | N34: =IF(L34="","",SUMIFS(rev_Amt,rev_FY,1,rev_Client,L34)+29/1E+6) | O34: =IF(L34="","",IFERROR(SUMIFS(rev_Amt,rev_FY,1,rev_Client,L34)/$C$28,0)) | P34: =IF(O34="",0,O34^2)
B35: Herfindahl index (0-10,000) | C35: =ROUND(SUM($P$6:$P$305)*10000,0) | D35: =IF(C35>=2500,"High",IF(C35>=1500,"Medium","Low")) | L35: =IFERROR(INDEX(rev_Client,MATCH(30,rev_New,0)),"") | M35: =IF(L35="","",30) | N35: =IF(L35="","",SUMIFS(rev_Amt,rev_FY,1,rev_Client,L35)+30/1E+6) | O35: =IF(L35="","",IFERROR(SUMIFS(rev_Amt,rev_FY,1,rev_Client,L35)/$C$28,0)) | P35: =IF(O35="",0,O35^2)
L36: =IFERROR(INDEX(rev_Client,MATCH(31,rev_New,0)),"") | M36: =IF(L36="","",31) | N36: =IF(L36="","",SUMIFS(rev_Amt,rev_FY,1,rev_Client,L36)+31/1E+6) | O36: =IF(L36="","",IFERROR(SUMIFS(rev_Amt,rev_FY,1,rev_Client,L36)/$C$28,0)) | P36: =IF(O36="",0,O36^2)
B37: Herfindahl index = sum of each client's squared share x 10,000. Under 1,500 is spread out, 1,500-2,500 moderate, over 2,500 concentrated (the usual market-concentration bands). Thresholds for the other two lines are on Settings. | L37: =IFERROR(INDEX(rev_Client,MATCH(32,rev_New,0)),"") | M37: =IF(L37="","",32) | N37: =IF(L37="","",SUMIFS(rev_Amt,rev_FY,1,rev_Client,L37)+32/1E+6) | O37: =IF(L37="","",IFERROR(SUMIFS(rev_Amt,rev_FY,1,rev_Client,L37)/$C$28,0)) | P37: =IF(O37="",0,O37^2)
L38: =IFERROR(INDEX(rev_Client,MATCH(33,rev_New,0)),"") | M38: =IF(L38="","",33) | N38: =IF(L38="","",SUMIFS(rev_Amt,rev_FY,1,rev_Client,L38)+33/1E+6) | O38: =IF(L38="","",IFERROR(SUMIFS(rev_Amt,rev_FY,1,rev_Client,L38)/$C$28,0)) | P38: =IF(O38="",0,O38^2)
L39: =IFERROR(INDEX(rev_Client,MATCH(34,rev_New,0)),"") | M39: =IF(L39="","",34) | N39: =IF(L39="","",SUMIFS(rev_Amt,rev_FY,1,rev_Client,L39)+34/1E+6) | O39: =IF(L39="","",IFERROR(SUMIFS(rev_Amt,rev_FY,1,rev_Client,L39)/$C$28,0)) | P39: =IF(O39="",0,O39^2)
L40: =IFERROR(INDEX(rev_Client,MATCH(35,rev_New,0)),"") | M40: =IF(L40="","",35) | N40: =IF(L40="","",SUMIFS(rev_Amt,rev_FY,1,rev_Client,L40)+35/1E+6) | O40: =IF(L40="","",IFERROR(SUMIFS(rev_Amt,rev_FY,1,rev_Client,L40)/$C$28,0)) | P40: =IF(O40="",0,O40^2)
L41: =IFERROR(INDEX(rev_Client,MATCH(36,rev_New,0)),"") | M41: =IF(L41="","",36) | N41: =IF(L41="","",SUMIFS(rev_Amt,rev_FY,1,rev_Client,L41)+36/1E+6) | O41: =IF(L41="","",IFERROR(SUMIFS(rev_Amt,rev_FY,1,rev_Client,L41)/$C$28,0)) | P41: =IF(O41="",0,O41^2)
...

Sheet Risk Register
A1: Risk Register
A2: Every open deal and every won deal not yet fully invoiced, worst first. Flags and scores are explained at the bottom; thresholds are on Settings.
A4: # | B4: Rating | C4: Score | D4: Job / Opp No | E4: Client | F4: Deal | G4: Cost Centre | H4: Status | I4: Stage | J4: Value | K4: Probability | L4: Revenue at risk | M4: Expected Month | N4: Why
A5: =IF(D5="","",1) | B5: =IFERROR(INDEX(p_Rating,MATCH(LARGE(p_Key,1),p_Key,0)),"") | C5: =IFERROR(INDEX(p_Score,MATCH(LARGE(p_Key,1),p_Key,0)),"") | D5: =IFERROR(INDEX(p_Job,MATCH(LARGE(p_Key,1),p_Key,0)),"") | E5: =IFERROR(INDEX(p_Client,MATCH(LARGE(p_Key,1),p_Key,0)),"") | F5: =IFERROR(INDEX(p_Deal,MATCH(LARGE(p_Key,1),p_Key,0)),"") | G5: =IFERROR(INDEX(p_CC,MATCH(LARGE(p_Key,1),p_Key,0)),"") | H5: =IFERROR(INDEX(p_Status,MATCH(LARGE(p_Key,1),p_Key,0)),"") | I5: =IFERROR(INDEX(p_Stage,MATCH(LARGE(p_Key,1),p_Key,0)),"") | J5: =IFERROR(INDEX(p_Value,MATCH(LARGE(p_Key,1),p_Key,0)),"") | K5: =IFERROR(IF(H5="Open",INDEX(p_Prob,MATCH(LARGE(p_Key,1),p_Key,0)),""),"") | L5: =IFERROR(INDEX(p_Risk,MATCH(LARGE(p_Key,1),p_Key,0)),"") | M5: =IFERROR(INDEX(p_Month,MATCH(LARGE(p_Key,1),p_Key,0)),"") | N5: =IFERROR(INDEX(p_Flags,MATCH(LARGE(p_Key,1),p_Key,0)),"")
A6: =IF(D6="","",2) | B6: =IFERROR(INDEX(p_Rating,MATCH(LARGE(p_Key,2),p_Key,0)),"") | C6: =IFERROR(INDEX(p_Score,MATCH(LARGE(p_Key,2),p_Key,0)),"") | D6: =IFERROR(INDEX(p_Job,MATCH(LARGE(p_Key,2),p_Key,0)),"") | E6: =IFERROR(INDEX(p_Client,MATCH(LARGE(p_Key,2),p_Key,0)),"") | F6: =IFERROR(INDEX(p_Deal,MATCH(LARGE(p_Key,2),p_Key,0)),"") | G6: =IFERROR(INDEX(p_CC,MATCH(LARGE(p_Key,2),p_Key,0)),"") | H6: =IFERROR(INDEX(p_Status,MATCH(LARGE(p_Key,2),p_Key,0)),"") | I6: =IFERROR(INDEX(p_Stage,MATCH(LARGE(p_Key,2),p_Key,0)),"") | J6: =IFERROR(INDEX(p_Value,MATCH(LARGE(p_Key,2),p_Key,0)),"") | K6: =IFERROR(IF(H6="Open",INDEX(p_Prob,MATCH(LARGE(p_Key,2),p_Key,0)),""),"") | L6: =IFERROR(INDEX(p_Risk,MATCH(LARGE(p_Key,2),p_Key,0)),"") | M6: =IFERROR(INDEX(p_Month,MATCH(LARGE(p_Key,2),p_Key,0)),"") | N6: =IFERROR(INDEX(p_Flags,MATCH(LARGE(p_Key,2),p_Key,0)),"")
A7: =IF(D7="","",3) | B7: =IFERROR(INDEX(p_Rating,MATCH(LARGE(p_Key,3),p_Key,0)),"") | C7: =IFERROR(INDEX(p_Score,MATCH(LARGE(p_Key,3),p_Key,0)),"") | D7: =IFERROR(INDEX(p_Job,MATCH(LARGE(p_Key,3),p_Key,0)),"") | E7: =IFERROR(INDEX(p_Client,MATCH(LARGE(p_Key,3),p_Key,0)),"") | F7: =IFERROR(INDEX(p_Deal,MATCH(LARGE(p_Key,3),p_Key,0)),"") | G7: =IFERROR(INDEX(p_CC,MATCH(LARGE(p_Key,3),p_Key,0)),"") | H7: =IFERROR(INDEX(p_Status,MATCH(LARGE(p_Key,3),p_Key,0)),"") | I7: =IFERROR(INDEX(p_Stage,MATCH(LARGE(p_Key,3),p_Key,0)),"") | J7: =IFERROR(INDEX(p_Value,MATCH(LARGE(p_Key,3),p_Key,0)),"") | K7: =IFERROR(IF(H7="Open",INDEX(p_Prob,MATCH(LARGE(p_Key,3),p_Key,0)),""),"") | L7: =IFERROR(INDEX(p_Risk,MATCH(LARGE(p_Key,3),p_Key,0)),"") | M7: =IFERROR(INDEX(p_Month,MATCH(LARGE(p_Key,3),p_Key,0)),"") | N7: =IFERROR(INDEX(p_Flags,MATCH(LARGE(p_Key,3),p_Key,0)),"")
A8: =IF(D8="","",4) | B8: =IFERROR(INDEX(p_Rating,MATCH(LARGE(p_Key,4),p_Key,0)),"") | C8: =IFERROR(INDEX(p_Score,MATCH(LARGE(p_Key,4),p_Key,0)),"") | D8: =IFERROR(INDEX(p_Job,MATCH(LARGE(p_Key,4),p_Key,0)),"") | E8: =IFERROR(INDEX(p_Client,MATCH(LARGE(p_Key,4),p_Key,0)),"") | F8: =IFERROR(INDEX(p_Deal,MATCH(LARGE(p_Key,4),p_Key,0)),"") | G8: =IFERROR(INDEX(p_CC,MATCH(LARGE(p_Key,4),p_Key,0)),"") | H8: =IFERROR(INDEX(p_Status,MATCH(LARGE(p_Key,4),p_Key,0)),"") | I8: =IFERROR(INDEX(p_Stage,MATCH(LARGE(p_Key,4),p_Key,0)),"") | J8: =IFERROR(INDEX(p_Value,MATCH(LARGE(p_Key,4),p_Key,0)),"") | K8: =IFERROR(IF(H8="Open",INDEX(p_Prob,MATCH(LARGE(p_Key,4),p_Key,0)),""),"") | L8: =IFERROR(INDEX(p_Risk,MATCH(LARGE(p_Key,4),p_Key,0)),"") | M8: =IFERROR(INDEX(p_Month,MATCH(LARGE(p_Key,4),p_Key,0)),"") | N8: =IFERROR(INDEX(p_Flags,MATCH(LARGE(p_Key,4),p_Key,0)),"")
A9: =IF(D9="","",5) | B9: =IFERROR(INDEX(p_Rating,MATCH(LARGE(p_Key,5),p_Key,0)),"") | C9: =IFERROR(INDEX(p_Score,MATCH(LARGE(p_Key,5),p_Key,0)),"") | D9: =IFERROR(INDEX(p_Job,MATCH(LARGE(p_Key,5),p_Key,0)),"") | E9: =IFERROR(INDEX(p_Client,MATCH(LARGE(p_Key,5),p_Key,0)),"") | F9: =IFERROR(INDEX(p_Deal,MATCH(LARGE(p_Key,5),p_Key,0)),"") | G9: =IFERROR(INDEX(p_CC,MATCH(LARGE(p_Key,5),p_Key,0)),"") | H9: =IFERROR(INDEX(p_Status,MATCH(LARGE(p_Key,5),p_Key,0)),"") | I9: =IFERROR(INDEX(p_Stage,MATCH(LARGE(p_Key,5),p_Key,0)),"") | J9: =IFERROR(INDEX(p_Value,MATCH(LARGE(p_Key,5),p_Key,0)),"") | K9: =IFERROR(IF(H9="Open",INDEX(p_Prob,MATCH(LARGE(p_Key,5),p_Key,0)),""),"") | L9: =IFERROR(INDEX(p_Risk,MATCH(LARGE(p_Key,5),p_Key,0)),"") | M9: =IFERROR(INDEX(p_Month,MATCH(LARGE(p_Key,5),p_Key,0)),"") | N9: =IFERROR(INDEX(p_Flags,MATCH(LARGE(p_Key,5),p_Key,0)),"")
A10: =IF(D10="","",6) | B10: =IFERROR(INDEX(p_Rating,MATCH(LARGE(p_Key,6),p_Key,0)),"") | C10: =IFERROR(INDEX(p_Score,MATCH(LARGE(p_Key,6),p_Key,0)),"") | D10: =IFERROR(INDEX(p_Job,MATCH(LARGE(p_Key,6),p_Key,0)),"") | E10: =IFERROR(INDEX(p_Client,MATCH(LARGE(p_Key,6),p_Key,0)),"") | F10: =IFERROR(INDEX(p_Deal,MATCH(LARGE(p_Key,6),p_Key,0)),"") | G10: =IFERROR(INDEX(p_CC,MATCH(LARGE(p_Key,6),p_Key,0)),"") | H10: =IFERROR(INDEX(p_Status,MATCH(LARGE(p_Key,6),p_Key,0)),"") | I10: =IFERROR(INDEX(p_Stage,MATCH(LARGE(p_Key,6),p_Key,0)),"") | J10: =IFERROR(INDEX(p_Value,MATCH(LARGE(p_Key,6),p_Key,0)),"") | K10: =IFERROR(IF(H10="Open",INDEX(p_Prob,MATCH(LARGE(p_Key,6),p_Key,0)),""),"") | L10: =IFERROR(INDEX(p_Risk,MATCH(LARGE(p_Key,6),p_Key,0)),"") | M10: =IFERROR(INDEX(p_Month,MATCH(LARGE(p_Key,6),p_Key,0)),"") | N10: =IFERROR(INDEX(p_Flags,MATCH(LARGE(p_Key,6),p_Key,0)),"")
A11: =IF(D11="","",7) | B11: =IFERROR(INDEX(p_Rating,MATCH(LARGE(p_Key,7),p_Key,0)),"") | C11: =IFERROR(INDEX(p_Score,MATCH(LARGE(p_Key,7),p_Key,0)),"") | D11: =IFERROR(INDEX(p_Job,MATCH(LARGE(p_Key,7),p_Key,0)),"") | E11: =IFERROR(INDEX(p_Client,MATCH(LARGE(p_Key,7),p_Key,0)),"") | F11: =IFERROR(INDEX(p_Deal,MATCH(LARGE(p_Key,7),p_Key,0)),"") | G11: =IFERROR(INDEX(p_CC,MATCH(LARGE(p_Key,7),p_Key,0)),"") | H11: =IFERROR(INDEX(p_Status,MATCH(LARGE(p_Key,7),p_Key,0)),"") | I11: =IFERROR(INDEX(p_Stage,MATCH(LARGE(p_Key,7),p_Key,0)),"") | J11: =IFERROR(INDEX(p_Value,MATCH(LARGE(p_Key,7),p_Key,0)),"") | K11: =IFERROR(IF(H11="Open",INDEX(p_Prob,MATCH(LARGE(p_Key,7),p_Key,0)),""),"") | L11: =IFERROR(INDEX(p_Risk,MATCH(LARGE(p_Key,7),p_Key,0)),"") | M11: =IFERROR(INDEX(p_Month,MATCH(LARGE(p_Key,7),p_Key,0)),"") | N11: =IFERROR(INDEX(p_Flags,MATCH(LARGE(p_Key,7),p_Key,0)),"")
A12: =IF(D12="","",8) | B12: =IFERROR(INDEX(p_Rating,MATCH(LARGE(p_Key,8),p_Key,0)),"") | C12: =IFERROR(INDEX(p_Score,MATCH(LARGE(p_Key,8),p_Key,0)),"") | D12: =IFERROR(INDEX(p_Job,MATCH(LARGE(p_Key,8),p_Key,0)),"") | E12: =IFERROR(INDEX(p_Client,MATCH(LARGE(p_Key,8),p_Key,0)),"") | F12: =IFERROR(INDEX(p_Deal,MATCH(LARGE(p_Key,8),p_Key,0)),"") | G12: =IFERROR(INDEX(p_CC,MATCH(LARGE(p_Key,8),p_Key,0)),"") | H12: =IFERROR(INDEX(p_Status,MATCH(LARGE(p_Key,8),p_Key,0)),"") | I12: =IFERROR(INDEX(p_Stage,MATCH(LARGE(p_Key,8),p_Key,0)),"") | J12: =IFERROR(INDEX(p_Value,MATCH(LARGE(p_Key,8),p_Key,0)),"") | K12: =IFERROR(IF(H12="Open",INDEX(p_Prob,MATCH(LARGE(p_Key,8),p_Key,0)),""),"") | L12: =IFERROR(INDEX(p_Risk,MATCH(LARGE(p_Key,8),p_Key,0)),"") | M12: =IFERROR(INDEX(p_Month,MATCH(LARGE(p_Key,8),p_Key,0)),"") | N12: =IFERROR(INDEX(p_Flags,MATCH(LARGE(p_Key,8),p_Key,0)),"")
A13: =IF(D13="","",9) | B13: =IFERROR(INDEX(p_Rating,MATCH(LARGE(p_Key,9),p_Key,0)),"") | C13: =IFERROR(INDEX(p_Score,MATCH(LARGE(p_Key,9),p_Key,0)),"") | D13: =IFERROR(INDEX(p_Job,MATCH(LARGE(p_Key,9),p_Key,0)),"") | E13: =IFERROR(INDEX(p_Client,MATCH(LARGE(p_Key,9),p_Key,0)),"") | F13: =IFERROR(INDEX(p_Deal,MATCH(LARGE(p_Key,9),p_Key,0)),"") | G13: =IFERROR(INDEX(p_CC,MATCH(LARGE(p_Key,9),p_Key,0)),"") | H13: =IFERROR(INDEX(p_Status,MATCH(LARGE(p_Key,9),p_Key,0)),"") | I13: =IFERROR(INDEX(p_Stage,MATCH(LARGE(p_Key,9),p_Key,0)),"") | J13: =IFERROR(INDEX(p_Value,MATCH(LARGE(p_Key,9),p_Key,0)),"") | K13: =IFERROR(IF(H13="Open",INDEX(p_Prob,MATCH(LARGE(p_Key,9),p_Key,0)),""),"") | L13: =IFERROR(INDEX(p_Risk,MATCH(LARGE(p_Key,9),p_Key,0)),"") | M13: =IFERROR(INDEX(p_Month,MATCH(LARGE(p_Key,9),p_Key,0)),"") | N13: =IFERROR(INDEX(p_Flags,MATCH(LARGE(p_Key,9),p_Key,0)),"")
A14: =IF(D14="","",10) | B14: =IFERROR(INDEX(p_Rating,MATCH(LARGE(p_Key,10),p_Key,0)),"") | C14: =IFERROR(INDEX(p_Score,MATCH(LARGE(p_Key,10),p_Key,0)),"") | D14: =IFERROR(INDEX(p_Job,MATCH(LARGE(p_Key,10),p_Key,0)),"") | E14: =IFERROR(INDEX(p_Client,MATCH(LARGE(p_Key,10),p_Key,0)),"") | F14: =IFERROR(INDEX(p_Deal,MATCH(LARGE(p_Key,10),p_Key,0)),"") | G14: =IFERROR(INDEX(p_CC,MATCH(LARGE(p_Key,10),p_Key,0)),"") | H14: =IFERROR(INDEX(p_Status,MATCH(LARGE(p_Key,10),p_Key,0)),"") | I14: =IFERROR(INDEX(p_Stage,MATCH(LARGE(p_Key,10),p_Key,0)),"") | J14: =IFERROR(INDEX(p_Value,MATCH(LARGE(p_Key,10),p_Key,0)),"") | K14: =IFERROR(IF(H14="Open",INDEX(p_Prob,MATCH(LARGE(p_Key,10),p_Key,0)),""),"") | L14: =IFERROR(INDEX(p_Risk,MATCH(LARGE(p_Key,10),p_Key,0)),"") | M14: =IFERROR(INDEX(p_Month,MATCH(LARGE(p_Key,10),p_Key,0)),"") | N14: =IFERROR(INDEX(p_Flags,MATCH(LARGE(p_Key,10),p_Key,0)),"")
A15: =IF(D15="","",11) | B15: =IFERROR(INDEX(p_Rating,MATCH(LARGE(p_Key,11),p_Key,0)),"") | C15: =IFERROR(INDEX(p_Score,MATCH(LARGE(p_Key,11),p_Key,0)),"") | D15: =IFERROR(INDEX(p_Job,MATCH(LARGE(p_Key,11),p_Key,0)),"") | E15: =IFERROR(INDEX(p_Client,MATCH(LARGE(p_Key,11),p_Key,0)),"") | F15: =IFERROR(INDEX(p_Deal,MATCH(LARGE(p_Key,11),p_Key,0)),"") | G15: =IFERROR(INDEX(p_CC,MATCH(LARGE(p_Key,11),p_Key,0)),"") | H15: =IFERROR(INDEX(p_Status,MATCH(LARGE(p_Key,11),p_Key,0)),"") | I15: =IFERROR(INDEX(p_Stage,MATCH(LARGE(p_Key,11),p_Key,0)),"") | J15: =IFERROR(INDEX(p_Value,MATCH(LARGE(p_Key,11),p_Key,0)),"") | K15: =IFERROR(IF(H15="Open",INDEX(p_Prob,MATCH(LARGE(p_Key,11),p_Key,0)),""),"") | L15: =IFERROR(INDEX(p_Risk,MATCH(LARGE(p_Key,11),p_Key,0)),"") | M15: =IFERROR(INDEX(p_Month,MATCH(LARGE(p_Key,11),p_Key,0)),"") | N15: =IFERROR(INDEX(p_Flags,MATCH(LARGE(p_Key,11),p_Key,0)),"")
A16: =IF(D16="","",12) | B16: =IFERROR(INDEX(p_Rating,MATCH(LARGE(p_Key,12),p_Key,0)),"") | C16: =IFERROR(INDEX(p_Score,MATCH(LARGE(p_Key,12),p_Key,0)),"") | D16: =IFERROR(INDEX(p_Job,MATCH(LARGE(p_Key,12),p_Key,0)),"") | E16: =IFERROR(INDEX(p_Client,MATCH(LARGE(p_Key,12),p_Key,0)),"") | F16: =IFERROR(INDEX(p_Deal,MATCH(LARGE(p_Key,12),p_Key,0)),"") | G16: =IFERROR(INDEX(p_CC,MATCH(LARGE(p_Key,12),p_Key,0)),"") | H16: =IFERROR(INDEX(p_Status,MATCH(LARGE(p_Key,12),p_Key,0)),"") | I16: =IFERROR(INDEX(p_Stage,MATCH(LARGE(p_Key,12),p_Key,0)),"") | J16: =IFERROR(INDEX(p_Value,MATCH(LARGE(p_Key,12),p_Key,0)),"") | K16: =IFERROR(IF(H16="Open",INDEX(p_Prob,MATCH(LARGE(p_Key,12),p_Key,0)),""),"") | L16: =IFERROR(INDEX(p_Risk,MATCH(LARGE(p_Key,12),p_Key,0)),"") | M16: =IFERROR(INDEX(p_Month,MATCH(LARGE(p_Key,12),p_Key,0)),"") | N16: =IFERROR(INDEX(p_Flags,MATCH(LARGE(p_Key,12),p_Key,0)),"")
A17: =IF(D17="","",13) | B17: =IFERROR(INDEX(p_Rating,MATCH(LARGE(p_Key,13),p_Key,0)),"") | C17: =IFERROR(INDEX(p_Score,MATCH(LARGE(p_Key,13),p_Key,0)),"") | D17: =IFERROR(INDEX(p_Job,MATCH(LARGE(p_Key,13),p_Key,0)),"") | E17: =IFERROR(INDEX(p_Client,MATCH(LARGE(p_Key,13),p_Key,0)),"") | F17: =IFERROR(INDEX(p_Deal,MATCH(LARGE(p_Key,13),p_Key,0)),"") | G17: =IFERROR(INDEX(p_CC,MATCH(LARGE(p_Key,13),p_Key,0)),"") | H17: =IFERROR(INDEX(p_Status,MATCH(LARGE(p_Key,13),p_Key,0)),"") | I17: =IFERROR(INDEX(p_Stage,MATCH(LARGE(p_Key,13),p_Key,0)),"") | J17: =IFERROR(INDEX(p_Value,MATCH(LARGE(p_Key,13),p_Key,0)),"") | K17: =IFERROR(IF(H17="Open",INDEX(p_Prob,MATCH(LARGE(p_Key,13),p_Key,0)),""),"") | L17: =IFERROR(INDEX(p_Risk,MATCH(LARGE(p_Key,13),p_Key,0)),"") | M17: =IFERROR(INDEX(p_Month,MATCH(LARGE(p_Key,13),p_Key,0)),"") | N17: =IFERROR(INDEX(p_Flags,MATCH(LARGE(p_Key,13),p_Key,0)),"")
A18: =IF(D18="","",14) | B18: =IFERROR(INDEX(p_Rating,MATCH(LARGE(p_Key,14),p_Key,0)),"") | C18: =IFERROR(INDEX(p_Score,MATCH(LARGE(p_Key,14),p_Key,0)),"") | D18: =IFERROR(INDEX(p_Job,MATCH(LARGE(p_Key,14),p_Key,0)),"") | E18: =IFERROR(INDEX(p_Client,MATCH(LARGE(p_Key,14),p_Key,0)),"") | F18: =IFERROR(INDEX(p_Deal,MATCH(LARGE(p_Key,14),p_Key,0)),"") | G18: =IFERROR(INDEX(p_CC,MATCH(LARGE(p_Key,14),p_Key,0)),"") | H18: =IFERROR(INDEX(p_Status,MATCH(LARGE(p_Key,14),p_Key,0)),"") | I18: =IFERROR(INDEX(p_Stage,MATCH(LARGE(p_Key,14),p_Key,0)),"") | J18: =IFERROR(INDEX(p_Value,MATCH(LARGE(p_Key,14),p_Key,0)),"") | K18: =IFERROR(IF(H18="Open",INDEX(p_Prob,MATCH(LARGE(p_Key,14),p_Key,0)),""),"") | L18: =IFERROR(INDEX(p_Risk,MATCH(LARGE(p_Key,14),p_Key,0)),"") | M18: =IFERROR(INDEX(p_Month,MATCH(LARGE(p_Key,14),p_Key,0)),"") | N18: =IFERROR(INDEX(p_Flags,MATCH(LARGE(p_Key,14),p_Key,0)),"")
A19: =IF(D19="","",15) | B19: =IFERROR(INDEX(p_Rating,MATCH(LARGE(p_Key,15),p_Key,0)),"") | C19: =IFERROR(INDEX(p_Score,MATCH(LARGE(p_Key,15),p_Key,0)),"") | D19: =IFERROR(INDEX(p_Job,MATCH(LARGE(p_Key,15),p_Key,0)),"") | E19: =IFERROR(INDEX(p_Client,MATCH(LARGE(p_Key,15),p_Key,0)),"") | F19: =IFERROR(INDEX(p_Deal,MATCH(LARGE(p_Key,15),p_Key,0)),"") | G19: =IFERROR(INDEX(p_CC,MATCH(LARGE(p_Key,15),p_Key,0)),"") | H19: =IFERROR(INDEX(p_Status,MATCH(LARGE(p_Key,15),p_Key,0)),"") | I19: =IFERROR(INDEX(p_Stage,MATCH(LARGE(p_Key,15),p_Key,0)),"") | J19: =IFERROR(INDEX(p_Value,MATCH(LARGE(p_Key,15),p_Key,0)),"") | K19: =IFERROR(IF(H19="Open",INDEX(p_Prob,MATCH(LARGE(p_Key,15),p_Key,0)),""),"") | L19: =IFERROR(INDEX(p_Risk,MATCH(LARGE(p_Key,15),p_Key,0)),"") | M19: =IFERROR(INDEX(p_Month,MATCH(LARGE(p_Key,15),p_Key,0)),"") | N19: =IFERROR(INDEX(p_Flags,MATCH(LARGE(p_Key,15),p_Key,0)),"")
A20: =IF(D20="","",16) | B20: =IFERROR(INDEX(p_Rating,MATCH(LARGE(p_Key,16),p_Key,0)),"") | C20: =IFERROR(INDEX(p_Score,MATCH(LARGE(p_Key,16),p_Key,0)),"") | D20: =IFERROR(INDEX(p_Job,MATCH(LARGE(p_Key,16),p_Key,0)),"") | E20: =IFERROR(INDEX(p_Client,MATCH(LARGE(p_Key,16),p_Key,0)),"") | F20: =IFERROR(INDEX(p_Deal,MATCH(LARGE(p_Key,16),p_Key,0)),"") | G20: =IFERROR(INDEX(p_CC,MATCH(LARGE(p_Key,16),p_Key,0)),"") | H20: =IFERROR(INDEX(p_Status,MATCH(LARGE(p_Key,16),p_Key,0)),"") | I20: =IFERROR(INDEX(p_Stage,MATCH(LARGE(p_Key,16),p_Key,0)),"") | J20: =IFERROR(INDEX(p_Value,MATCH(LARGE(p_Key,16),p_Key,0)),"") | K20: =IFERROR(IF(H20="Open",INDEX(p_Prob,MATCH(LARGE(p_Key,16),p_Key,0)),""),"") | L20: =IFERROR(INDEX(p_Risk,MATCH(LARGE(p_Key,16),p_Key,0)),"") | M20: =IFERROR(INDEX(p_Month,MATCH(LARGE(p_Key,16),p_Key,0)),"") | N20: =IFERROR(INDEX(p_Flags,MATCH(LARGE(p_Key,16),p_Key,0)),"")
A21: =IF(D21="","",17) | B21: =IFERROR(INDEX(p_Rating,MATCH(LARGE(p_Key,17),p_Key,0)),"") | C21: =IFERROR(INDEX(p_Score,MATCH(LARGE(p_Key,17),p_Key,0)),"") | D21: =IFERROR(INDEX(p_Job,MATCH(LARGE(p_Key,17),p_Key,0)),"") | E21: =IFERROR(INDEX(p_Client,MATCH(LARGE(p_Key,17),p_Key,0)),"") | F21: =IFERROR(INDEX(p_Deal,MATCH(LARGE(p_Key,17),p_Key,0)),"") | G21: =IFERROR(INDEX(p_CC,MATCH(LARGE(p_Key,17),p_Key,0)),"") | H21: =IFERROR(INDEX(p_Status,MATCH(LARGE(p_Key,17),p_Key,0)),"") | I21: =IFERROR(INDEX(p_Stage,MATCH(LARGE(p_Key,17),p_Key,0)),"") | J21: =IFERROR(INDEX(p_Value,MATCH(LARGE(p_Key,17),p_Key,0)),"") | K21: =IFERROR(IF(H21="Open",INDEX(p_Prob,MATCH(LARGE(p_Key,17),p_Key,0)),""),"") | L21: =IFERROR(INDEX(p_Risk,MATCH(LARGE(p_Key,17),p_Key,0)),"") | M21: =IFERROR(INDEX(p_Month,MATCH(LARGE(p_Key,17),p_Key,0)),"") | N21: =IFERROR(INDEX(p_Flags,MATCH(LARGE(p_Key,17),p_Key,0)),"")
A22: =IF(D22="","",18) | B22: =IFERROR(INDEX(p_Rating,MATCH(LARGE(p_Key,18),p_Key,0)),"") | C22: =IFERROR(INDEX(p_Score,MATCH(LARGE(p_Key,18),p_Key,0)),"") | D22: =IFERROR(INDEX(p_Job,MATCH(LARGE(p_Key,18),p_Key,0)),"") | E22: =IFERROR(INDEX(p_Client,MATCH(LARGE(p_Key,18),p_Key,0)),"") | F22: =IFERROR(INDEX(p_Deal,MATCH(LARGE(p_Key,18),p_Key,0)),"") | G22: =IFERROR(INDEX(p_CC,MATCH(LARGE(p_Key,18),p_Key,0)),"") | H22: =IFERROR(INDEX(p_Status,MATCH(LARGE(p_Key,18),p_Key,0)),"") | I22: =IFERROR(INDEX(p_Stage,MATCH(LARGE(p_Key,18),p_Key,0)),"") | J22: =IFERROR(INDEX(p_Value,MATCH(LARGE(p_Key,18),p_Key,0)),"") | K22: =IFERROR(IF(H22="Open",INDEX(p_Prob,MATCH(LARGE(p_Key,18),p_Key,0)),""),"") | L22: =IFERROR(INDEX(p_Risk,MATCH(LARGE(p_Key,18),p_Key,0)),"") | M22: =IFERROR(INDEX(p_Month,MATCH(LARGE(p_Key,18),p_Key,0)),"") | N22: =IFERROR(INDEX(p_Flags,MATCH(LARGE(p_Key,18),p_Key,0)),"")
A23: =IF(D23="","",19) | B23: =IFERROR(INDEX(p_Rating,MATCH(LARGE(p_Key,19),p_Key,0)),"") | C23: =IFERROR(INDEX(p_Score,MATCH(LARGE(p_Key,19),p_Key,0)),"") | D23: =IFERROR(INDEX(p_Job,MATCH(LARGE(p_Key,19),p_Key,0)),"") | E23: =IFERROR(INDEX(p_Client,MATCH(LARGE(p_Key,19),p_Key,0)),"") | F23: =IFERROR(INDEX(p_Deal,MATCH(LARGE(p_Key,19),p_Key,0)),"") | G23: =IFERROR(INDEX(p_CC,MATCH(LARGE(p_Key,19),p_Key,0)),"") | H23: =IFERROR(INDEX(p_Status,MATCH(LARGE(p_Key,19),p_Key,0)),"") | I23: =IFERROR(INDEX(p_Stage,MATCH(LARGE(p_Key,19),p_Key,0)),"") | J23: =IFERROR(INDEX(p_Value,MATCH(LARGE(p_Key,19),p_Key,0)),"") | K23: =IFERROR(IF(H23="Open",INDEX(p_Prob,MATCH(LARGE(p_Key,19),p_Key,0)),""),"") | L23: =IFERROR(INDEX(p_Risk,MATCH(LARGE(p_Key,19),p_Key,0)),"") | M23: =IFERROR(INDEX(p_Month,MATCH(LARGE(p_Key,19),p_Key,0)),"") | N23: =IFERROR(INDEX(p_Flags,MATCH(LARGE(p_Key,19),p_Key,0)),"")
A24: =IF(D24="","",20) | B24: =IFERROR(INDEX(p_Rating,MATCH(LARGE(p_Key,20),p_Key,0)),"") | C24: =IFERROR(INDEX(p_Score,MATCH(LARGE(p_Key,20),p_Key,0)),"") | D24: =IFERROR(INDEX(p_Job,MATCH(LARGE(p_Key,20),p_Key,0)),"") | E24: =IFERROR(INDEX(p_Client,MATCH(LARGE(p_Key,20),p_Key,0)),"") | F24: =IFERROR(INDEX(p_Deal,MATCH(LARGE(p_Key,20),p_Key,0)),"") | G24: =IFERROR(INDEX(p_CC,MATCH(LARGE(p_Key,20),p_Key,0)),"") | H24: =IFERROR(INDEX(p_Status,MATCH(LARGE(p_Key,20),p_Key,0)),"") | I24: =IFERROR(INDEX(p_Stage,MATCH(LARGE(p_Key,20),p_Key,0)),"") | J24: =IFERROR(INDEX(p_Value,MATCH(LARGE(p_Key,20),p_Key,0)),"") | K24: =IFERROR(IF(H24="Open",INDEX(p_Prob,MATCH(LARGE(p_Key,20),p_Key,0)),""),"") | L24: =IFERROR(INDEX(p_Risk,MATCH(LARGE(p_Key,20),p_Key,0)),"") | M24: =IFERROR(INDEX(p_Month,MATCH(LARGE(p_Key,20),p_Key,0)),"") | N24: =IFERROR(INDEX(p_Flags,MATCH(LARGE(p_Key,20),p_Key,0)),"")
A25: =IF(D25="","",21) | B25: =IFERROR(INDEX(p_Rating,MATCH(LARGE(p_Key,21),p_Key,0)),"") | C25: =IFERROR(INDEX(p_Score,MATCH(LARGE(p_Key,21),p_Key,0)),"") | D25: =IFERROR(INDEX(p_Job,MATCH(LARGE(p_Key,21),p_Key,0)),"") | E25: =IFERROR(INDEX(p_Client,MATCH(LARGE(p_Key,21),p_Key,0)),"") | F25: =IFERROR(INDEX(p_Deal,MATCH(LARGE(p_Key,21),p_Key,0)),"") | G25: =IFERROR(INDEX(p_CC,MATCH(LARGE(p_Key,21),p_Key,0)),"") | H25: =IFERROR(INDEX(p_Status,MATCH(LARGE(p_Key,21),p_Key,0)),"") | I25: =IFERROR(INDEX(p_Stage,MATCH(LARGE(p_Key,21),p_Key,0)),"") | J25: =IFERROR(INDEX(p_Value,MATCH(LARGE(p_Key,21),p_Key,0)),"") | K25: =IFERROR(IF(H25="Open",INDEX(p_Prob,MATCH(LARGE(p_Key,21),p_Key,0)),""),"") | L25: =IFERROR(INDEX(p_Risk,MATCH(LARGE(p_Key,21),p_Key,0)),"") | M25: =IFERROR(INDEX(p_Month,MATCH(LARGE(p_Key,21),p_Key,0)),"") | N25: =IFERROR(INDEX(p_Flags,MATCH(LARGE(p_Key,21),p_Key,0)),"")
A26: =IF(D26="","",22) | B26: =IFERROR(INDEX(p_Rating,MATCH(LARGE(p_Key,22),p_Key,0)),"") | C26: =IFERROR(INDEX(p_Score,MATCH(LARGE(p_Key,22),p_Key,0)),"") | D26: =IFERROR(INDEX(p_Job,MATCH(LARGE(p_Key,22),p_Key,0)),"") | E26: =IFERROR(INDEX(p_Client,MATCH(LARGE(p_Key,22),p_Key,0)),"") | F26: =IFERROR(INDEX(p_Deal,MATCH(LARGE(p_Key,22),p_Key,0)),"") | G26: =IFERROR(INDEX(p_CC,MATCH(LARGE(p_Key,22),p_Key,0)),"") | H26: =IFERROR(INDEX(p_Status,MATCH(LARGE(p_Key,22),p_Key,0)),"") | I26: =IFERROR(INDEX(p_Stage,MATCH(LARGE(p_Key,22),p_Key,0)),"") | J26: =IFERROR(INDEX(p_Value,MATCH(LARGE(p_Key,22),p_Key,0)),"") | K26: =IFERROR(IF(H26="Open",INDEX(p_Prob,MATCH(LARGE(p_Key,22),p_Key,0)),""),"") | L26: =IFERROR(INDEX(p_Risk,MATCH(LARGE(p_Key,22),p_Key,0)),"") | M26: =IFERROR(INDEX(p_Month,MATCH(LARGE(p_Key,22),p_Key,0)),"") | N26: =IFERROR(INDEX(p_Flags,MATCH(LARGE(p_Key,22),p_Key,0)),"")
A27: =IF(D27="","",23) | B27: =IFERROR(INDEX(p_Rating,MATCH(LARGE(p_Key,23),p_Key,0)),"") | C27: =IFERROR(INDEX(p_Score,MATCH(LARGE(p_Key,23),p_Key,0)),"") | D27: =IFERROR(INDEX(p_Job,MATCH(LARGE(p_Key,23),p_Key,0)),"") | E27: =IFERROR(INDEX(p_Client,MATCH(LARGE(p_Key,23),p_Key,0)),"") | F27: =IFERROR(INDEX(p_Deal,MATCH(LARGE(p_Key,23),p_Key,0)),"") | G27: =IFERROR(INDEX(p_CC,MATCH(LARGE(p_Key,23),p_Key,0)),"") | H27: =IFERROR(INDEX(p_Status,MATCH(LARGE(p_Key,23),p_Key,0)),"") | I27: =IFERROR(INDEX(p_Stage,MATCH(LARGE(p_Key,23),p_Key,0)),"") | J27: =IFERROR(INDEX(p_Value,MATCH(LARGE(p_Key,23),p_Key,0)),"") | K27: =IFERROR(IF(H27="Open",INDEX(p_Prob,MATCH(LARGE(p_Key,23),p_Key,0)),""),"") | L27: =IFERROR(INDEX(p_Risk,MATCH(LARGE(p_Key,23),p_Key,0)),"") | M27: =IFERROR(INDEX(p_Month,MATCH(LARGE(p_Key,23),p_Key,0)),"") | N27: =IFERROR(INDEX(p_Flags,MATCH(LARGE(p_Key,23),p_Key,0)),"")
A28: =IF(D28="","",24) | B28: =IFERROR(INDEX(p_Rating,MATCH(LARGE(p_Key,24),p_Key,0)),"") | C28: =IFERROR(INDEX(p_Score,MATCH(LARGE(p_Key,24),p_Key,0)),"") | D28: =IFERROR(INDEX(p_Job,MATCH(LARGE(p_Key,24),p_Key,0)),"") | E28: =IFERROR(INDEX(p_Client,MATCH(LARGE(p_Key,24),p_Key,0)),"") | F28: =IFERROR(INDEX(p_Deal,MATCH(LARGE(p_Key,24),p_Key,0)),"") | G28: =IFERROR(INDEX(p_CC,MATCH(LARGE(p_Key,24),p_Key,0)),"") | H28: =IFERROR(INDEX(p_Status,MATCH(LARGE(p_Key,24),p_Key,0)),"") | I28: =IFERROR(INDEX(p_Stage,MATCH(LARGE(p_Key,24),p_Key,0)),"") | J28: =IFERROR(INDEX(p_Value,MATCH(LARGE(p_Key,24),p_Key,0)),"") | K28: =IFERROR(IF(H28="Open",INDEX(p_Prob,MATCH(LARGE(p_Key,24),p_Key,0)),""),"") | L28: =IFERROR(INDEX(p_Risk,MATCH(LARGE(p_Key,24),p_Key,0)),"") | M28: =IFERROR(INDEX(p_Month,MATCH(LARGE(p_Key,24),p_Key,0)),"") | N28: =IFERROR(INDEX(p_Flags,MATCH(LARGE(p_Key,24),p_Key,0)),"")
A29: =IF(D29="","",25) | B29: =IFERROR(INDEX(p_Rating,MATCH(LARGE(p_Key,25),p_Key,0)),"") | C29: =IFERROR(INDEX(p_Score,MATCH(LARGE(p_Key,25),p_Key,0)),"") | D29: =IFERROR(INDEX(p_Job,MATCH(LARGE(p_Key,25),p_Key,0)),"") | E29: =IFERROR(INDEX(p_Client,MATCH(LARGE(p_Key,25),p_Key,0)),"") | F29: =IFERROR(INDEX(p_Deal,MATCH(LARGE(p_Key,25),p_Key,0)),"") | G29: =IFERROR(INDEX(p_CC,MATCH(LARGE(p_Key,25),p_Key,0)),"") | H29: =IFERROR(INDEX(p_Status,MATCH(LARGE(p_Key,25),p_Key,0)),"") | I29: =IFERROR(INDEX(p_Stage,MATCH(LARGE(p_Key,25),p_Key,0)),"") | J29: =IFERROR(INDEX(p_Value,MATCH(LARGE(p_Key,25),p_Key,0)),"") | K29: =IFERROR(IF(H29="Open",INDEX(p_Prob,MATCH(LARGE(p_Key,25),p_Key,0)),""),"") | L29: =IFERROR(INDEX(p_Risk,MATCH(LARGE(p_Key,25),p_Key,0)),"") | M29: =IFERROR(INDEX(p_Month,MATCH(LARGE(p_Key,25),p_Key,0)),"") | N29: =IFERROR(INDEX(p_Flags,MATCH(LARGE(p_Key,25),p_Key,0)),"")
A30: =IF(D30="","",26) | B30: =IFERROR(INDEX(p_Rating,MATCH(LARGE(p_Key,26),p_Key,0)),"") | C30: =IFERROR(INDEX(p_Score,MATCH(LARGE(p_Key,26),p_Key,0)),"") | D30: =IFERROR(INDEX(p_Job,MATCH(LARGE(p_Key,26),p_Key,0)),"") | E30: =IFERROR(INDEX(p_Client,MATCH(LARGE(p_Key,26),p_Key,0)),"") | F30: =IFERROR(INDEX(p_Deal,MATCH(LARGE(p_Key,26),p_Key,0)),"") | G30: =IFERROR(INDEX(p_CC,MATCH(LARGE(p_Key,26),p_Key,0)),"") | H30: =IFERROR(INDEX(p_Status,MATCH(LARGE(p_Key,26),p_Key,0)),"") | I30: =IFERROR(INDEX(p_Stage,MATCH(LARGE(p_Key,26),p_Key,0)),"") | J30: =IFERROR(INDEX(p_Value,MATCH(LARGE(p_Key,26),p_Key,0)),"") | K30: =IFERROR(IF(H30="Open",INDEX(p_Prob,MATCH(LARGE(p_Key,26),p_Key,0)),""),"") | L30: =IFERROR(INDEX(p_Risk,MATCH(LARGE(p_Key,26),p_Key,0)),"") | M30: =IFERROR(INDEX(p_Month,MATCH(LARGE(p_Key,26),p_Key,0)),"") | N30: =IFERROR(INDEX(p_Flags,MATCH(LARGE(p_Key,26),p_Key,0)),"")
A31: =IF(D31="","",27) | B31: =IFERROR(INDEX(p_Rating,MATCH(LARGE(p_Key,27),p_Key,0)),"") | C31: =IFERROR(INDEX(p_Score,MATCH(LARGE(p_Key,27),p_Key,0)),"") | D31: =IFERROR(INDEX(p_Job,MATCH(LARGE(p_Key,27),p_Key,0)),"") | E31: =IFERROR(INDEX(p_Client,MATCH(LARGE(p_Key,27),p_Key,0)),"") | F31: =IFERROR(INDEX(p_Deal,MATCH(LARGE(p_Key,27),p_Key,0)),"") | G31: =IFERROR(INDEX(p_CC,MATCH(LARGE(p_Key,27),p_Key,0)),"") | H31: =IFERROR(INDEX(p_Status,MATCH(LARGE(p_Key,27),p_Key,0)),"") | I31: =IFERROR(INDEX(p_Stage,MATCH(LARGE(p_Key,27),p_Key,0)),"") | J31: =IFERROR(INDEX(p_Value,MATCH(LARGE(p_Key,27),p_Key,0)),"") | K31: =IFERROR(IF(H31="Open",INDEX(p_Prob,MATCH(LARGE(p_Key,27),p_Key,0)),""),"") | L31: =IFERROR(INDEX(p_Risk,MATCH(LARGE(p_Key,27),p_Key,0)),"") | M31: =IFERROR(INDEX(p_Month,MATCH(LARGE(p_Key,27),p_Key,0)),"") | N31: =IFERROR(INDEX(p_Flags,MATCH(LARGE(p_Key,27),p_Key,0)),"")
A32: =IF(D32="","",28) | B32: =IFERROR(INDEX(p_Rating,MATCH(LARGE(p_Key,28),p_Key,0)),"") | C32: =IFERROR(INDEX(p_Score,MATCH(LARGE(p_Key,28),p_Key,0)),"") | D32: =IFERROR(INDEX(p_Job,MATCH(LARGE(p_Key,28),p_Key,0)),"") | E32: =IFERROR(INDEX(p_Client,MATCH(LARGE(p_Key,28),p_Key,0)),"") | F32: =IFERROR(INDEX(p_Deal,MATCH(LARGE(p_Key,28),p_Key,0)),"") | G32: =IFERROR(INDEX(p_CC,MATCH(LARGE(p_Key,28),p_Key,0)),"") | H32: =IFERROR(INDEX(p_Status,MATCH(LARGE(p_Key,28),p_Key,0)),"") | I32: =IFERROR(INDEX(p_Stage,MATCH(LARGE(p_Key,28),p_Key,0)),"") | J32: =IFERROR(INDEX(p_Value,MATCH(LARGE(p_Key,28),p_Key,0)),"") | K32: =IFERROR(IF(H32="Open",INDEX(p_Prob,MATCH(LARGE(p_Key,28),p_Key,0)),""),"") | L32: =IFERROR(INDEX(p_Risk,MATCH(LARGE(p_Key,28),p_Key,0)),"") | M32: =IFERROR(INDEX(p_Month,MATCH(LARGE(p_Key,28),p_Key,0)),"") | N32: =IFERROR(INDEX(p_Flags,MATCH(LARGE(p_Key,28),p_Key,0)),"")
A33: =IF(D33="","",29) | B33: =IFERROR(INDEX(p_Rating,MATCH(LARGE(p_Key,29),p_Key,0)),"") | C33: =IFERROR(INDEX(p_Score,MATCH(LARGE(p_Key,29),p_Key,0)),"") | D33: =IFERROR(INDEX(p_Job,MATCH(LARGE(p_Key,29),p_Key,0)),"") | E33: =IFERROR(INDEX(p_Client,MATCH(LARGE(p_Key,29),p_Key,0)),"") | F33: =IFERROR(INDEX(p_Deal,MATCH(LARGE(p_Key,29),p_Key,0)),"") | G33: =IFERROR(INDEX(p_CC,MATCH(LARGE(p_Key,29),p_Key,0)),"") | H33: =IFERROR(INDEX(p_Status,MATCH(LARGE(p_Key,29),p_Key,0)),"") | I33: =IFERROR(INDEX(p_Stage,MATCH(LARGE(p_Key,29),p_Key,0)),"") | J33: =IFERROR(INDEX(p_Value,MATCH(LARGE(p_Key,29),p_Key,0)),"") | K33: =IFERROR(IF(H33="Open",INDEX(p_Prob,MATCH(LARGE(p_Key,29),p_Key,0)),""),"") | L33: =IFERROR(INDEX(p_Risk,MATCH(LARGE(p_Key,29),p_Key,0)),"") | M33: =IFERROR(INDEX(p_Month,MATCH(LARGE(p_Key,29),p_Key,0)),"") | N33: =IFERROR(INDEX(p_Flags,MATCH(LARGE(p_Key,29),p_Key,0)),"")
A34: =IF(D34="","",30) | B34: =IFERROR(INDEX(p_Rating,MATCH(LARGE(p_Key,30),p_Key,0)),"") | C34: =IFERROR(INDEX(p_Score,MATCH(LARGE(p_Key,30),p_Key,0)),"") | D34: =IFERROR(INDEX(p_Job,MATCH(LARGE(p_Key,30),p_Key,0)),"") | E34: =IFERROR(INDEX(p_Client,MATCH(LARGE(p_Key,30),p_Key,0)),"") | F34: =IFERROR(INDEX(p_Deal,MATCH(LARGE(p_Key,30),p_Key,0)),"") | G34: =IFERROR(INDEX(p_CC,MATCH(LARGE(p_Key,30),p_Key,0)),"") | H34: =IFERROR(INDEX(p_Status,MATCH(LARGE(p_Key,30),p_Key,0)),"") | I34: =IFERROR(INDEX(p_Stage,MATCH(LARGE(p_Key,30),p_Key,0)),"") | J34: =IFERROR(INDEX(p_Value,MATCH(LARGE(p_Key,30),p_Key,0)),"") | K34: =IFERROR(IF(H34="Open",INDEX(p_Prob,MATCH(LARGE(p_Key,30),p_Key,0)),""),"") | L34: =IFERROR(INDEX(p_Risk,MATCH(LARGE(p_Key,30),p_Key,0)),"") | M34: =IFERROR(INDEX(p_Month,MATCH(LARGE(p_Key,30),p_Key,0)),"") | N34: =IFERROR(INDEX(p_Flags,MATCH(LARGE(p_Key,30),p_Key,0)),"")
A35: =IF(D35="","",31) | B35: =IFERROR(INDEX(p_Rating,MATCH(LARGE(p_Key,31),p_Key,0)),"") | C35: =IFERROR(INDEX(p_Score,MATCH(LARGE(p_Key,31),p_Key,0)),"") | D35: =IFERROR(INDEX(p_Job,MATCH(LARGE(p_Key,31),p_Key,0)),"") | E35: =IFERROR(INDEX(p_Client,MATCH(LARGE(p_Key,31),p_Key,0)),"") | F35: =IFERROR(INDEX(p_Deal,MATCH(LARGE(p_Key,31),p_Key,0)),"") | G35: =IFERROR(INDEX(p_CC,MATCH(LARGE(p_Key,31),p_Key,0)),"") | H35: =IFERROR(INDEX(p_Status,MATCH(LARGE(p_Key,31),p_Key,0)),"") | I35: =IFERROR(INDEX(p_Stage,MATCH(LARGE(p_Key,31),p_Key,0)),"") | J35: =IFERROR(INDEX(p_Value,MATCH(LARGE(p_Key,31),p_Key,0)),"") | K35: =IFERROR(IF(H35="Open",INDEX(p_Prob,MATCH(LARGE(p_Key,31),p_Key,0)),""),"") | L35: =IFERROR(INDEX(p_Risk,MATCH(LARGE(p_Key,31),p_Key,0)),"") | M35: =IFERROR(INDEX(p_Month,MATCH(LARGE(p_Key,31),p_Key,0)),"") | N35: =IFERROR(INDEX(p_Flags,MATCH(LARGE(p_Key,31),p_Key,0)),"")
A36: =IF(D36="","",32) | B36: =IFERROR(INDEX(p_Rating,MATCH(LARGE(p_Key,32),p_Key,0)),"") | C36: =IFERROR(INDEX(p_Score,MATCH(LARGE(p_Key,32),p_Key,0)),"") | D36: =IFERROR(INDEX(p_Job,MATCH(LARGE(p_Key,32),p_Key,0)),"") | E36: =IFERROR(INDEX(p_Client,MATCH(LARGE(p_Key,32),p_Key,0)),"") | F36: =IFERROR(INDEX(p_Deal,MATCH(LARGE(p_Key,32),p_Key,0)),"") | G36: =IFERROR(INDEX(p_CC,MATCH(LARGE(p_Key,32),p_Key,0)),"") | H36: =IFERROR(INDEX(p_Status,MATCH(LARGE(p_Key,32),p_Key,0)),"") | I36: =IFERROR(INDEX(p_Stage,MATCH(LARGE(p_Key,32),p_Key,0)),"") | J36: =IFERROR(INDEX(p_Value,MATCH(LARGE(p_Key,32),p_Key,0)),"") | K36: =IFERROR(IF(H36="Open",INDEX(p_Prob,MATCH(LARGE(p_Key,32),p_Key,0)),""),"") | L36: =IFERROR(INDEX(p_Risk,MATCH(LARGE(p_Key,32),p_Key,0)),"") | M36: =IFERROR(INDEX(p_Month,MATCH(LARGE(p_Key,32),p_Key,0)),"") | N36: =IFERROR(INDEX(p_Flags,MATCH(LARGE(p_Key,32),p_Key,0)),"")
A37: =IF(D37="","",33) | B37: =IFERROR(INDEX(p_Rating,MATCH(LARGE(p_Key,33),p_Key,0)),"") | C37: =IFERROR(INDEX(p_Score,MATCH(LARGE(p_Key,33),p_Key,0)),"") | D37: =IFERROR(INDEX(p_Job,MATCH(LARGE(p_Key,33),p_Key,0)),"") | E37: =IFERROR(INDEX(p_Client,MATCH(LARGE(p_Key,33),p_Key,0)),"") | F37: =IFERROR(INDEX(p_Deal,MATCH(LARGE(p_Key,33),p_Key,0)),"") | G37: =IFERROR(INDEX(p_CC,MATCH(LARGE(p_Key,33),p_Key,0)),"") | H37: =IFERROR(INDEX(p_Status,MATCH(LARGE(p_Key,33),p_Key,0)),"") | I37: =IFERROR(INDEX(p_Stage,MATCH(LARGE(p_Key,33),p_Key,0)),"") | J37: =IFERROR(INDEX(p_Value,MATCH(LARGE(p_Key,33),p_Key,0)),"") | K37: =IFERROR(IF(H37="Open",INDEX(p_Prob,MATCH(LARGE(p_Key,33),p_Key,0)),""),"") | L37: =IFERROR(INDEX(p_Risk,MATCH(LARGE(p_Key,33),p_Key,0)),"") | M37: =IFERROR(INDEX(p_Month,MATCH(LARGE(p_Key,33),p_Key,0)),"") | N37: =IFERROR(INDEX(p_Flags,MATCH(LARGE(p_Key,33),p_Key,0)),"")
