Workbook
Name AcctName: #REF!
Name AcctName: #REF!
Name AcctName: #REF!
Name AcctName: #REF!
Name AcctSubCate: #REF!
Name AcctSubCate: #REF!
Name AcctSubCate: #REF!
Name AcctSubCate: #REF!

Sheet FY25 Forecast summary - Main
B1: ACTUAL | C1: ACTUAL | D1: FORECAST | E1: FORECAST | F1: FORECAST | G1: FORECAST | H1: FORECAST | I1: FORECAST | J1: FORECAST | K1: FORECAST | L1: FORECAST | M1: FORECAST | N1: FORECAST | O1: FORECAST | P1: FORECAST
B2: FY24 | C2: FY25 | D2: 45474 | E2: 45505 | F2: 45536 | G2: 45566 | H2: 45597 | I2: 45627 | J2: 45658 | K2: 45689 | L2: 45717 | M2: 45748 | N2: 45778 | O2: 45809 | P2: Total (Oct-Jun) | Q2: Forecast vs Actual
A3: Consulting | B3: ='FY27 Budget - detailed'!#REF! -> #REF! | C3: =#REF!+#REF!+#REF! -> #REF! | D3: ='FY27 Budget - detailed'!H3 -> 297416.49 | E3: ='FY27 Budget - detailed'!I3 -> 465645.39 | F3: ='FY27 Budget - detailed'!J3 -> 82321.892 | G3: ='FY27 Budget - detailed'!K3 -> 100061.89 | H3: ='FY27 Budget - detailed'!L3 -> 36337.392 | I3: ='FY27 Budget - detailed'!M3 -> 31337.392 | J3: ='FY27 Budget - detailed'!N3 -> 27340.652 | K3: ='FY27 Budget - detailed'!O3 -> 32340.652 | ... O3: ='FY27 Budget - detailed'!S3 -> 8035.0717 | P3: =D3+E3+F3+G3+H3+I3+J3+K3+L3+M3+N3+O3 -> 1153553.2 | Q3: =(C3-P3)/P3 -> #REF! | R3: =+P3-C3 -> #REF!
A4: Production | B4: ='FY27 Budget - detailed'!#REF! -> #REF! | C4: =#REF!+#REF!+#REF! -> #REF! | D4: ='FY27 Budget - detailed'!H4 -> 73000.02 | E4: ='FY27 Budget - detailed'!I4 -> 251215.02 | F4: ='FY27 Budget - detailed'!J4 -> 83326.02 | G4: ='FY27 Budget - detailed'!K4 -> 587307.02 | H4: ='FY27 Budget - detailed'!L4 -> 241601.02 | I4: ='FY27 Budget - detailed'!M4 -> 62316.02 | J4: ='FY27 Budget - detailed'!N4 -> 64261.937 | K4: ='FY27 Budget - detailed'!O4 -> 281912.02 | ... O4: ='FY27 Budget - detailed'!S4 -> 82637.02 | P4: =D4+E4+F4+G4+H4+I4+J4+K4+L4+M4+N4+O4 -> 2090722.1 | Q4: =(C4-P4)/P4 -> #REF! | R4: =+P4-C4 -> #REF!
A5: Onsite | B5: ='FY27 Budget - detailed'!#REF! -> #REF! | C5: =#REF!+#REF!+#REF! -> #REF! | D5: ='FY27 Budget - detailed'!H5 -> 238860.67 | E5: ='FY27 Budget - detailed'!I5 -> 256307.33 | F5: ='FY27 Budget - detailed'!J5 -> 248016.77 | G5: ='FY27 Budget - detailed'!K5 -> 263046.77 | H5: ='FY27 Budget - detailed'!L5 -> 262366.77 | I5: ='FY27 Budget - detailed'!M5 -> 251316.77 | J5: ='FY27 Budget - detailed'!N5 -> 262366.77 | K5: ='FY27 Budget - detailed'!O5 -> 262366.77 | ... O5: ='FY27 Budget - detailed'!S5 -> 242443.11 | P5: =D5+E5+F5+G5+H5+I5+J5+K5+L5+M5+N5+O5 -> 3060325.4 | Q5: =(C5-P5)/P5 -> #REF! | R5: =+P5-C5 -> #REF!
A6: Total Income | B6: =SUM(B3:B5) -> #REF! | C6: =SUM(C3:C5) -> #REF! | D6: =SUM(D3:D5) -> 609277.18 | E6: =SUM(E3:E5) -> 973167.74 | F6: =SUM(F3:F5) -> 413664.68 | G6: =SUM(G3:G5) -> 950415.68 | H6: =SUM(H3:H5) -> 540305.18 | I6: =SUM(I3:I5) -> 344970.18 | ... O6: =SUM(O3:O5) -> 333115.2 | P6: =D6+E6+F6+G6+H6+I6+J6+K6+L6+M6+N6+O6 -> 6304600.7 | Q6: =(C6-P6)/P6 -> #REF! | R6: =+P6-C6 -> #REF!
A7: Consulting Direct Costs | B7: ='FY27 Budget - detailed'!#REF! -> #REF! | C7: =#REF!+#REF!+#REF! -> #REF! | D7: ='FY27 Budget - detailed'!H7 -> 156894.91 | E7: ='FY27 Budget - detailed'!I7 -> 239607.17 | F7: ='FY27 Budget - detailed'!J7 -> 50130.112 | G7: ='FY27 Budget - detailed'!K7 -> 58336.599 | H7: ='FY27 Budget - detailed'!L7 -> 27394.352 | I7: ='FY27 Budget - detailed'!M7 -> 23963.88 | J7: ='FY27 Budget - detailed'!N7 -> 21263.504 | K7: ='FY27 Budget - detailed'!O7 -> 24080.807 | ... O7: ='FY27 Budget - detailed'!S7 -> 17919.298 | P7: =D7+E7+F7+G7+H7+I7+J7+K7+L7+M7+N7+O7 -> 681494.01 | Q7: =(C7-P7)/P7 -> #REF! | R7: =+P7-C7 -> #REF!
A8: Production Direct Costs | B8: ='FY27 Budget - detailed'!#REF! -> #REF! | C8: =#REF!+#REF!+#REF! -> #REF! | D8: ='FY27 Budget - detailed'!H11 -> 52683.663 | E8: ='FY27 Budget - detailed'!I11 -> 100269.81 | F8: ='FY27 Budget - detailed'!J11 -> 103519.69 | G8: ='FY27 Budget - detailed'!K11 -> 285683.94 | H8: ='FY27 Budget - detailed'!L11 -> 104223.85 | I8: ='FY27 Budget - detailed'!M11 -> 83048.46 | J8: ='FY27 Budget - detailed'!N11 -> 45343.173 | K8: ='FY27 Budget - detailed'!O11 -> 109744.55 | ... O8: ='FY27 Budget - detailed'!S11 -> 85630.235 | P8: =D8+E8+F8+G8+H8+I8+J8+K8+L8+M8+N8+O8 -> 1138130.7 | Q8: =(C8-P8)/P8 -> #REF! | R8: =+P8-C8 -> #REF!
A9: Onsite Direct Costs | B9: ='FY27 Budget - detailed'!#REF! -> #REF! | C9: =#REF!+#REF!+#REF! -> #REF! | D9: ='FY27 Budget - detailed'!H15 -> 129391.68 | E9: ='FY27 Budget - detailed'!I15 -> 115678.57 | F9: ='FY27 Budget - detailed'!J15 -> 135541.85 | G9: ='FY27 Budget - detailed'!K15 -> 130158.68 | H9: ='FY27 Budget - detailed'!L15 -> 127598.94 | I9: ='FY27 Budget - detailed'!M15 -> 134912.18 | J9: ='FY27 Budget - detailed'!N15 -> 112466.56 | K9: ='FY27 Budget - detailed'!O15 -> 116012.62 | ... O9: ='FY27 Budget - detailed'!S15 -> 139270 | P9: =D9+E9+F9+G9+H9+I9+J9+K9+L9+M9+N9+O9 -> 1559522.1 | Q9: =(C9-P9)/P9 -> #REF! | R9: =+P9-C9 -> #REF!
A10: Total Cost of Sales | B10: =SUM(B7:B9) -> #REF! | C10: =SUM(C7:C9) -> #REF! | D10: =SUM(D7:D9) -> 338970.25 | E10: =SUM(E7:E9) -> 455555.55 | F10: =SUM(F7:F9) -> 289191.66 | G10: =SUM(G7:G9) -> 474179.22 | H10: =SUM(H7:H9) -> 259217.14 | I10: =SUM(I7:I9) -> 241924.52 | ... O10: =SUM(O7:O9) -> 242819.53 | P10: =D10+E10+F10+G10+H10+I10+J10+K10+L10+M10+N10+O10 -> 3379146.7 | Q10: =(C10-P10)/P10 -> #REF! | R10: =+P10-C10 -> #REF!
A11: Gross Profit | B11: =+B6-B10 -> #REF! | C11: =+C6-C10 -> #REF! | D11: =+D6-D10 -> 270306.93 | E11: =+E6-E10 -> 517612.19 | F11: =+F6-F10 -> 124473.02 | G11: =+G6-G10 -> 476236.46 | H11: =+H6-H10 -> 281088.04 | I11: =+I6-I10 -> 103045.66 | ... P11: =+P6-P10 -> 2925453.9 | Q11: =(C11-P11)/P11 -> #REF! | R11: =+P11-C11 -> #REF!
A12: Gross Profit Margin | B12: =+B11/B6 -> #REF! | C12: =+C11/C6 -> #REF! | D12: =+D11/D6 -> 0.44365182 | E12: =+E11/E6 -> 0.53188383 | F12: =+F11/F6 -> 0.30090319 | G12: =+G11/G6 -> 0.50108228 | H12: =+H11/H6 -> 0.52023939 | I12: =+I11/I6 -> 0.2987089 | ... P12: =+P11/P6 -> 0.46401891
A13: CTS Overheads | B13: 2434714.2 | C13: =#REF!+#REF!+#REF! -> #REF! | D13: ='FY27 Budget - detailed'!H$73 -> 218401.7 | E13: ='FY27 Budget - detailed'!I$73 -> 239717.06 | F13: ='FY27 Budget - detailed'!J$73 -> 231573.15 | G13: ='FY27 Budget - detailed'!K$73 -> 209130.75 | H13: ='FY27 Budget - detailed'!L$73 -> 202345.83 | I13: ='FY27 Budget - detailed'!M$73 -> 201077.04 | J13: ='FY27 Budget - detailed'!N$73 -> 201203.71 | K13: ='FY27 Budget - detailed'!O$73 -> 197422.84 | ... O13: ='FY27 Budget - detailed'!S$73 -> 208102.17 | P13: =D13+E13+F13+G13+H13+I13+J13+K13+L13+M13+N13+O13 -> 2528203.2 | Q13: =(C13-P13)/P13 -> #REF! | R13: =+P13-C13 -> #REF!
A14: Total Expenses | B14: =SUM(B13:B13) -> 2434714.2 | C14: =SUM(C13:C13) -> #REF! | D14: =SUM(D13:D13) -> 218401.7 | E14: =SUM(E13:E13) -> 239717.06 | F14: =SUM(F13:F13) -> 231573.15 | G14: =SUM(G13:G13) -> 209130.75 | H14: =SUM(H13:H13) -> 202345.83 | I14: =SUM(I13:I13) -> 201077.04 | ... O14: =SUM(O13:O13) -> 208102.17 | P14: =D14+E14+F14+G14+H14+I14+J14+K14+L14+M14+N14+O14 -> 2528203.2 | Q14: =(C14-P14)/P14 -> #REF! | R14: =+P14-C14 -> #REF!
A15: Operating Profit | B15: =+B11-B14 -> #REF! | C15: =+C11-C14 -> #REF! | D15: =+D11-D14 -> 51905.235 | E15: =+E11-E14 -> 277895.13 | F15: =+F11-F14 -> -107100.12 | G15: =+G11-G14 -> 267105.71 | H15: =+H11-H14 -> 78742.202 | I15: =+I11-I14 -> -98031.373 | ... P15: =+P11-P14 -> 397250.75 | Q15: =(C15-P15)/P15 -> #REF! | R15: =+P15-C15 -> #REF!
A16: Profit Margin | B16: =+B15/B6 -> #REF! | C16: =+C15/C6 -> #REF! | D16: =+D15/D6 -> 0.085191497 | E16: =+E15/E6 -> 0.28555727 | F16: =+F15/F6 -> -0.25890565 | G16: =+G15/G6 -> 0.28104093 | H16: =+H15/H6 -> 0.14573653 | I16: =+I15/I6 -> -0.28417347 | ... P16: =+P15/P6 -> 0.063009662
A18: Commentary
A19: Respective Revenue Targets were "sense-checked" by DL | E19: =CONS!H33+ONS!G40+PRD!I38 -> 239717.06 | F19: =CONS!I33+ONS!H40+PRD!J38 -> 247510.84 | G19: =CONS!J33+ONS!I40+PRD!K38 -> 247510.84
A20: Total New Business $292K across all departments ($24K/month)
A21: In comparison to a 45k per month forecasted in the previous FY
A22: 12% Increase in CTS Overheads:
A23: - a standard 3.8% was forecasted for wages across the board
A24: - 16K for additional new office expenses
A25: Approved by DL on 19/07/2024

Sheet Sheet1
P3: Notes:
P4: Red tabs are temporary - should be deleted in new FY
A5: Support | B5: 45839 | C5: 45870 | D5: 45901 | E5: 45931 | F5: 45962 | G5: 45992 | H5: 46023 | I5: 46054 | J5: 46082 | K5: 46113 | L5: 46143 | M5: 46174
A6: Budget | B6: 250360.46 | C6: 249340.46 | D6: 241360.46 | E6: 242840.46 | F6: 243860.46 | G6: 243520.46 | H6: 248860.46 | I6: 248520.46 | J6: 249540.46 | K6: 249200.46 | L6: 249540.46 | M6: 237720.46
A7: Forecast | B7: 230051.49 | C7: 222701.08 | D7: 231234.35 | E7: 226930.46 | F7: 225020.46 | G7: 225700.46 | H7: 219590.46 | I7: 218360.46 | J7: 219380.46 | K7: 221290.46 | L7: 233420.46 | M7: 221600.46
A9: Production | B9: 45839 | C9: 45870 | D9: 45901 | E9: 45931 | F9: 45962 | G9: 45992 | H9: 46023 | I9: 46054 | J9: 46082 | K9: 46113 | L9: 46143 | M9: 46174
A10: Budget | B10: 46825 | C10: 298950 | D10: 170580 | E10: 749300 | F10: 316250 | G10: 106490 | H10: 31860 | I10: 303900 | J10: 156100 | K10: 78400 | L10: 134375 | M10: 167050
A11: Forecast | B11: 49635.14 | C11: 302897.09 | D11: 95379.458 | E11: 694120 | F11: 370750 | G11: 103890 | H11: 31860 | I11: 305300 | J11: 156100 | K11: 79800 | L11: 134375 | M11: 168450
A13: Consulting | B13: 45839 | C13: 45870 | D13: 45901 | E13: 45931 | F13: 45962 | G13: 45992 | H13: 46023 | I13: 46054 | J13: 46082 | K13: 46113 | L13: 46143 | M13: 46174
A14: Budget | B14: 69527 | C14: 80527 | D14: 52027 | E14: 79027 | F14: 69027 | G14: 38527 | H14: 37027 | I14: 80027 | J14: 72027 | K14: 61527 | L14: 51500 | M14: 65500
A15: Forecast | B15: 41121.43 | C15: 25871.288 | D15: 29771.061 | E15: 76880 | F15: 69861.5 | G15: 183880 | H15: 39380 | I15: 80380 | J15: 63380 | K15: 62880 | L15: 42853 | M15: 66853
A18: Budget | F18: Forecast
B19: Support Budget | C19: Production Budget | D19: Consulting Budget | E19: Support Forecast | F19: Production Forecast | G19: Consulting Forecast
A20: 45839 | B20: 250360.46 | C20: 46825 | D20: 69527 | E20: 230051.49 | F20: 49635.14 | G20: 41121.43
A21: 45870 | B21: 249340.46 | C21: 298950 | D21: 80527 | E21: 222694.95 | F21: 302890.78 | G21: 25865.16
A22: 45901 | B22: 241360.46 | C22: 170580 | D22: 52027 | E22: 231214.01 | F22: 95358.5 | G22: 29750.72
A23: 45931 | B23: 242840.46 | C23: 749300 | D23: 79027 | E23: 221948.09 | F23: 776911.15 | G23: 36702.62
A24: 45962 | B24: 243860.46 | C24: 316250 | D24: 69027 | E24: 229035.14 | F24: 253388.39 | G24: 24123.65
A25: 45992 | B25: 243520.46 | C25: 106490 | D25: 38527 | E25: 233853.71 | F25: 96218.49 | G25: 22816.11
A26: 46023 | B26: 248860.46 | C26: 31860 | D26: 37027 | E26: 193910.46 | F26: 26360 | G26: 52896.785
A27: 46054 | B27: 248520.46 | C27: 303900 | D27: 80027 | E27: 197600.46 | F27: 294500 | G27: 105726.79
A28: 46082 | B28: 249540.46 | C28: 156100 | D28: 72027 | E28: 223304.56 | F28: 148700 | G28: 272880
A29: 46113 | B29: 249200.46 | C29: 78400 | D29: 61527 | E29: 221162.62 | F29: 103400 | G29: 81380
A30: 46143 | B30: 249540.46 | C30: 134375 | D30: 51500 | E30: 233092.62 | F30: 151300 | G30: 68353
A31: 46174 | B31: 237720.46 | C31: 167050 | D31: 65500 | E31: 221272.62 | F31: 147550 | G31: 1122853

Sheet TO DO
A2: FALSE | B2: Casual Pays needs to be updated for June
A3: TRUE | B3: Em to check overhead bills
A4: TRUE | B4: Check Ptax calcs and input actual pay for the FY on 29/06
A5: TRUE | B5: AL expense update
A6: TRUE | B6: ONS Sales Budget
A7: TRUE | B7: PRD Sales Budget
A8: TRUE | B8: CONS Sales Budget
A9: FALSE | B9: Re-visit CONS Sales budget based on probability
I12: STAFF
I13: Admin | J13: 7
I14: Consulting | J14: 0 | K14: =(J14/67)*$J$13 -> 0 | L14: =K14/$J$13 -> 0
I15: Integration | J15: 1 | K15: =(J15/67)*$J$13 -> 0.10447761 | L15: =K15/$J$13 -> 0.014925373
I16: Onsite | J16: 39 | K16: =(J16/67)*$J$13 -> 4.0746269 | L16: =K16/$J$13 -> 0.58208955
I17: Prouduction | J17: 24 | K17: =(J17/67)*$J$13 -> 2.5074627 | L17: =K17/$J$13 -> 0.35820896
I18: Video | J18: 3 | K18: =(J18/67)*$J$13 -> 0.31343284 | L18: =K18/$J$13 -> 0.044776119
J19: =SUM(J13:J18) -> 74
I22: OFFICE DEPT
I23: Support | J23: 0.0179
I24: Production | J24: 0.875
I25: Video | J25: 0.0713
I26: Consulting | J26: 0.0179
I27: Integration | J27: 0.0179

Sheet FY27 Budget - Actuals
B1: ACTUAL | C1: ACTUAL | D1: ACTUAL | E1: BUDGET | F1: ACTUAL | G1: BUDGET | H1: BUDGET | I1: BUDGET | J1: BUDGET | K1: BUDGET | L1: BUDGET | M1: BUDGET | N1: BUDGET | O1: BUDGET | P1: BUDGET | Q1: BUDGET | R1: BUDGET
B2: FY26 (YTD) | C2: FY27 (YTD) | D2: 46204 | E2: 46204 | F2: 46235 | G2: 46235 | H2: 46266 | I2: 46296 | J2: 46327 | K2: 46357 | L2: 46388 | M2: 46419 | N2: 46447 | O2: 46478 | P2: 46508 | Q2: 46539 | R2: Total | S2: Budget vs Actual | U2: Budget vs LY
A3: Consulting | B3: 944789.64 | C3: =D3+F3 -> 207091.24 | D3: 112803.24 | E3: =CONS!G2 -> 297416.49 | F3: 94288 | G3: =CONS!H2 -> 465645.39 | H3: =CONS!I2 -> 82321.892 | I3: =CONS!J2 -> 100061.89 | J3: =CONS!K2 -> 36337.392 | K3: =CONS!L2 -> 31337.392 | L3: =CONS!M2 -> 27340.652 | M3: =CONS!N2 -> 32340.652 | N3: =CONS!O2 -> 32340.652 | ... Q3: =CONS!R2 -> 8035.0717 | R3: =E3+G3+H3+I3+J3+K3+L3+M3+N3+O3+P3+Q3 -> 1153553.2 | S3: =(C3-R3)/R3 -> -0.82047535 | T3: =+R3-C3 -> 946461.96 | U3: =(R3-B3)/B3 -> 0.22096301 | V3: =+R3-B3 -> 208763.56 | X3: =R3/$R$6 -> 0.18297007
A4: Production | B4: 2444121.4 | C4: =D4+F4 -> 379542.03 | D4: 110900.03 | E4: ='PRD Sales Forecast'!CN64 -> 73000.02 | F4: 268642 | G4: ='PRD Sales Forecast'!CO64 -> 251215.02 | H4: ='PRD Sales Forecast'!CP64 -> 83326.02 | I4: ='PRD Sales Forecast'!CQ64 -> 587307.02 | J4: ='PRD Sales Forecast'!CR64 -> 241601.02 | K4: ='PRD Sales Forecast'!CS64 -> 62316.02 | L4: ='PRD Sales Forecast'!CT64 -> 64261.937 | M4: ='PRD Sales Forecast'!CU64 -> 281912.02 | N4: ='PRD Sales Forecast'!CV64 -> 128882.02 | ... Q4: ='PRD Sales Forecast'!CY64 -> 82637.02 | R4: =E4+G4+H4+I4+J4+K4+L4+M4+N4+O4+P4+Q4 -> 2090722.1 | S4: =(C4-R4)/R4 -> -0.81846366 | T4: =+R4-C4 -> 1711180 | U4: =(R4-B4)/B4 -> -0.14459156 | V4: =+R4-B4 -> -353399.33 | X4: =R4/$R$6 -> 0.33161848
A5: Support | B5: 2724275 | C5: =D5+F5 -> 475638.94 | D5: 235402.94 | E5: =ONS!F6 -> 238860.67 | F5: 240236 | G5: =ONS!G6 -> 256307.33 | H5: =ONS!H6 -> 248016.77 | I5: =ONS!I6 -> 263046.77 | J5: =ONS!J6 -> 262366.77 | K5: =ONS!K6 -> 251316.77 | L5: =ONS!L6 -> 262366.77 | M5: =ONS!M6 -> 262366.77 | N5: =ONS!N6 -> 253016.77 | ... Q5: =ONS!Q6 -> 242443.11 | R5: =E5+G5+H5+I5+J5+K5+L5+M5+N5+O5+P5+Q5 -> 3060325.4 | S5: =(C5-R5)/R5 -> -0.84457896 | T5: =+R5-C5 -> 2584686.4 | U5: =(R5-B5)/B5 -> 0.12335406 | V5: =+R5-B5 -> 336050.39 | X5: =R5/$R$6 -> 0.48541146
A6: Total Income | B6: =SUM(B3:B5) -> 6113186 | C6: =SUM(C3:C5) -> 1062272.2 | D6: =SUM(D3:D5) -> 459106.21 | E6: =SUM(E3:E5) -> 609277.18 | F6: =SUM(F3:F5) -> 603166 | G6: =SUM(G3:G5) -> 973167.74 | H6: =SUM(H3:H5) -> 413664.68 | I6: =SUM(I3:I5) -> 950415.68 | ... Q6: =SUM(Q3:Q5) -> 333115.2 | R6: =E6+G6+H6+I6+J6+K6+L6+M6+N6+O6+P6+Q6 -> 6304600.7 | S6: =(C6-R6)/R6 -> -0.83150841 | T6: =+R6-C6 -> 5242328.4 | U6: =(R6-B6)/B6 -> 0.031311762 | V6: =+R6-B6 -> 191414.62
A7: Consulting Direct Costs | B7: 744807.04 | C7: =D7+F7 -> 182140.37 | D7: 106364.37 | E7: ='FY27 Budget - detailed'!H7 -> 156894.91 | F7: =73229+2547 -> 75776 | G7: ='FY27 Budget - detailed'!I7 -> 239607.17 | H7: ='FY27 Budget - detailed'!J7 -> 50130.112 | I7: ='FY27 Budget - detailed'!K7 -> 58336.599 | J7: ='FY27 Budget - detailed'!L7 -> 27394.352 | K7: ='FY27 Budget - detailed'!M7 -> 23963.88 | L7: ='FY27 Budget - detailed'!N7 -> 21263.504 | M7: ='FY27 Budget - detailed'!O7 -> 24080.807 | N7: ='FY27 Budget - detailed'!P7 -> 25062.909 | ... Q7: ='FY27 Budget - detailed'!S7 -> 17919.298 | R7: =E7+G7+H7+I7+J7+K7+L7+M7+N7+O7+P7+Q7 -> 681494.01 | S7: =(C7-R7)/R7 -> -0.73273372 | T7: =+R7-C7 -> 499353.64 | U7: =(R7-B7)/B7 -> -0.085005949 | V7: =+R7-B7 -> -63313.029
A8: Production Direct Costs | B8: 1172927.9 | C8: =D8+F8 -> 169851.09 | D8: 44738.09 | E8: ='FY27 Budget - detailed'!H11 -> 52683.663 | F8: =120188+4925 -> 125113 | G8: ='FY27 Budget - detailed'!I11 -> 100269.81 | H8: ='FY27 Budget - detailed'!J11 -> 103519.69 | I8: ='FY27 Budget - detailed'!K11 -> 285683.94 | J8: ='FY27 Budget - detailed'!L11 -> 104223.85 | K8: ='FY27 Budget - detailed'!M11 -> 83048.46 | L8: ='FY27 Budget - detailed'!N11 -> 45343.173 | M8: ='FY27 Budget - detailed'!O11 -> 109744.55 | N8: ='FY27 Budget - detailed'!P11 -> 59313.374 | ... Q8: ='FY27 Budget - detailed'!S11 -> 85630.235 | R8: =E8+G8+H8+I8+J8+K8+L8+M8+N8+O8+P8+Q8 -> 1138130.7 | S8: =(C8-R8)/R8 -> -0.8507631 | T8: =+R8-C8 -> 968279.57 | U8: =(R8-B8)/B8 -> -0.029667025 | V8: =+R8-B8 -> -34797.283
A9: Support Direct Costs | B9: 1579333.4 | C9: =D9+F9 -> 266009.69 | D9: 131411.69 | E9: ='FY27 Budget - detailed'!H15 -> 129391.68 | F9: 134598 | G9: ='FY27 Budget - detailed'!I15 -> 115678.57 | H9: ='FY27 Budget - detailed'!J15 -> 135541.85 | I9: ='FY27 Budget - detailed'!K15 -> 130158.68 | J9: ='FY27 Budget - detailed'!L15 -> 127598.94 | K9: ='FY27 Budget - detailed'!M15 -> 134912.18 | L9: ='FY27 Budget - detailed'!N15 -> 112466.56 | M9: ='FY27 Budget - detailed'!O15 -> 116012.62 | N9: ='FY27 Budget - detailed'!P15 -> 142206.77 | ... Q9: ='FY27 Budget - detailed'!S15 -> 139270 | R9: =E9+G9+H9+I9+J9+K9+L9+M9+N9+O9+P9+Q9 -> 1559522.1 | S9: =(C9-R9)/R9 -> -0.82942871 | T9: =+R9-C9 -> 1293512.4 | U9: =(R9-B9)/B9 -> -0.012544084 | V9: =+R9-B9 -> -19811.289
A10: Total Cost of Sales | B10: =SUM(B7:B9) -> 3497068.3 | C10: =SUM(C7:C9) -> 618001.15 | D10: =SUM(D7:D9) -> 282514.15 | E10: =SUM(E7:E9) -> 338970.25 | F10: =SUM(F7:F9) -> 335487 | G10: =SUM(G7:G9) -> 455555.55 | H10: =SUM(H7:H9) -> 289191.66 | I10: =SUM(I7:I9) -> 474179.22 | ... Q10: =SUM(Q7:Q9) -> 242819.53 | R10: =E10+G10+H10+I10+J10+K10+L10+M10+N10+O10+P10+Q10 -> 3379146.7 | S10: =(C10-R10)/R10 -> -0.81711325 | T10: =+R10-C10 -> 2761145.6 | U10: =(R10-B10)/B10 -> -0.033720131 | V10: =+R10-B10 -> -117921.6
A11: Gross Profit | B11: =+B6-B10 -> 2616117.7 | C11: =+C6-C10 -> 444271.06 | D11: =+D6-D10 -> 176592.06 | E11: =+E6-E10 -> 270306.93 | F11: =+F6-F10 -> 267679 | G11: =+G6-G10 -> 517612.19 | H11: =+H6-H10 -> 124473.02 | I11: =+I6-I10 -> 476236.46 | ... Q11: =+Q6-Q10 -> 90295.668 | R11: =E11+G11+H11+I11+J11+K11+L11+M11+N11+O11+P11+Q11 -> 2925453.9 | S11: =(C11-R11)/R11 -> -0.84813603 | T11: =+R11-C11 -> 2481182.9 | U11: =(R11-B11)/B11 -> 0.11824247 | V11: =+R11-B11 -> 309336.22
A12: Gross Profit Margin | B12: =+B11/B6 -> 0.42794669 | C12: =+C11/C6 -> 0.41822713 | D12: =+D11/D6 -> 0.38464315 | E12: =+E11/E6 -> 0.44365182 | F12: =+F11/F6 -> 0.44378994 | G12: =+G11/G6 -> 0.53188383 | H12: =+H11/H6 -> 0.30090319 | I12: =+I11/I6 -> 0.50108228 | ... R12: =+R11/R6 -> 0.46401891
A13: CTS Overheads | B13: 2380904.7 | C13: =D13+F13 -> 411287.76 | D13: 202397.94 | E13: 202397.94 | F13: 208889.82 | G13: ='FY27 Budget - detailed'!I73 -> 239717.06 | H13: ='FY27 Budget - detailed'!J73 -> 231573.15 | I13: ='FY27 Budget - detailed'!K73 -> 209130.75 | J13: ='FY27 Budget - detailed'!L73 -> 202345.83 | K13: ='FY27 Budget - detailed'!M73 -> 201077.04 | L13: ='FY27 Budget - detailed'!N73 -> 201203.71 | M13: ='FY27 Budget - detailed'!O73 -> 197422.84 | N13: ='FY27 Budget - detailed'!P73 -> 211706.91 | ... Q13: ='FY27 Budget - detailed'!S73 -> 208102.17 | R13: =+E13+G13+H13+I13+J13+K13+L13+M13+N13+O13+P13+Q13 -> 2512199.4 | S13: =(C13-R13)/R13 -> -0.83628379 | T13: =+R13-C13 -> 2100911.7 | U13: =(R13-B13)/B13 -> 0.055144903 | V13: =+R13-B13 -> 131294.76
A14: Total Expenses | B14: =SUM(B13:B13) -> 2380904.7 | C14: =SUM(C13:C13) -> 411287.76 | D14: =SUM(D13:D13) -> 202397.94 | E14: =SUM(E13:E13) -> 202397.94 | F14: =SUM(F13:F13) -> 208889.82 | G14: =SUM(G13:G13) -> 239717.06 | H14: =SUM(H13:H13) -> 231573.15 | I14: =SUM(I13:I13) -> 209130.75 | ... Q14: =SUM(Q13:Q13) -> 208102.17 | R14: =+E14+G14+H14+I14+J14+K14+L14+M14+N14+O14+P14+Q14 -> 2512199.4 | S14: =(C14-R14)/R14 -> -0.83628379 | T14: =+R14-C14 -> 2100911.7 | U14: =(R14-B14)/B14 -> 0.055144903 | V14: =+R14-B14 -> 131294.76
A15: Operating Profit | B15: =+B11-B14 -> 235213.04 | C15: =+C11-C14 -> 32983.3 | D15: =+D11-D14 -> -25805.88 | E15: =+E11-E14 -> 67908.991 | F15: =+F11-F14 -> 58789.18 | G15: =+G11-G14 -> 277895.13 | H15: =+H11-H14 -> -107100.12 | I15: =+I11-I14 -> 267105.71 | ... R15: =+R11-R14 -> 413254.51 | S15: =(C15-R15)/R15 -> -0.92018647 | T15: =+R15-C15 -> 380271.21 | U15: =(R15-B15)/B15 -> 0.75693707 | V15: =+R15-B15 -> 178041.47
A16: Profit Margin | B16: =+B15/B6 -> 0.038476343 | C16: =+C15/C6 -> 0.031049763 | D16: =+D15/D6 -> -0.056208954 | E16: =+E15/E6 -> 0.11145829 | F16: =+F15/F6 -> 0.097467662 | G16: =+G15/G6 -> 0.28555727 | H16: =+H15/H6 -> -0.25890565 | I16: =+I15/I6 -> 0.28104093 | ... R16: =+R15/R6 -> 0.065548087
E18: =E13-E20 -> -16003.755 | G18: =G13-G20 -> 0 | H18: =H13-H20 -> -15937.691 | I18: =I13-I20 -> -38380.086 | J18: =J13-J20 -> -43331.854 | K18: =K13-K20 -> -41895.079 | L18: =L13-L20 -> -39345.275 | M18: =M13-M20 -> -43126.143 | N18: =N13-N20 -> -33688.333 | ... Q18: =Q13-Q20 -> -34869.946
E20: =CONS!G33+ONS!F40+PRD!H38 -> 218401.7 | G20: =CONS!H33+ONS!G40+PRD!I38 -> 239717.06 | H20: =CONS!I33+ONS!H40+PRD!J38 -> 247510.84 | I20: =CONS!J33+ONS!I40+PRD!K38 -> 247510.84 | J20: =CONS!K33+ONS!J40+PRD!L38 -> 245677.69 | K20: =CONS!L33+ONS!K40+PRD!M38 -> 242972.12 | L20: =CONS!M33+ONS!L40+PRD!N38 -> 240548.99 | M20: =CONS!N33+ONS!M40+PRD!O38 -> 240548.99 | N20: =CONS!O33+ONS!N40+PRD!P38 -> 245395.25 | ... R20: =CONS!S33+ONS!R40+PRD!T38 -> 1376440.8
E32: Budget Expense commentaries: | M32: Budget Sales commentaries:
E33: ESG Budget reduced to $500 per month | M33: Production: $2.09M (34% of revenue)Support: $3M (47% of revenue)Consulting: $1.10M (18% of revenue)
E34: Instant Asset reduced to $5k per month | M34: Revenue is forecast to be strongest during: October ($921K for AGM Season) August ($951K where $400k worth of consulting work becomes realised)
E35: IT Support increased by $36k | M35: Support services remain the largest contributor to revenue, followed by Production, indicating the business continues to rely on recurring operational work rather than project-based consulting.
E36: CTS 20-year anniversary budgeted at $8.5k in Aug
E37: Headcount: Budget removed for Office Admin, Head of HR, 2 Prod technicians, 1 Cons intern
E38: Website update cost in Aug $12k
E39: CTS Logo Update $9.3k
E40: Salary increases factored in 3%
N42: CONS | O42: ONS | P42: PRD
M43: N/E | N43: ='CONS Sales Forecast'!EE16+'CONS Sales Forecast'!EE17 -> 31392 | O43: ='ONS Sales Forecast'!DI38 -> 45000 | P43: ='PRD Sales Forecast'!CZ4+'PRD Sales Forecast'!DP4 -> 120000 | Q43: =SUM(N43:P43) -> 196392 | R43: =Q43/$Q$47 -> 0.031150585
M44: N/N | O44: ='ONS Sales Forecast'!DI8 -> 131483.3 | P44: ='PRD Sales Forecast'!CZ5+'PRD Sales Forecast'!DP5 -> 90000 | Q44: =SUM(N44:P44) -> 221483.3 | R44: =Q44/$Q$47 -> 0.035130425
M45: E/E | N45: ='CONS Sales Forecast'!EE67-'FY27 Budget - Actuals'!N43 -> 1122161.2 | O45: ='ONS Sales Forecast'!DI61-'FY27 Budget - Actuals'!O43-'FY27 Budget - Actuals'!O44 -> 2883842.1 | P45: ='PRD Sales Forecast'!CZ51+'PRD Sales Forecast'!DP51-'FY27 Budget - Actuals'!P43-'FY27 Budget - Actuals'!P44 -> 1880722.1 | Q45: =SUM(N45:P45) -> 5886725.4 | R45: =Q45/$Q$47 -> 0.93371899
N47: =SUM(N43:N46) -> 1153553.2 | O47: =SUM(O43:O46) -> 3060325.4 | P47: =SUM(P43:P46) -> 2090722.1 | Q47: =SUM(Q43:Q46) -> 6304600.7
M49: Business Services | N49: =SUMIF('CONS Sales Forecast'!$DO$4:$DO$30,M49,'CONS Sales Forecast'!$EE$4:$EE$30) -> 0 | O49: =SUMIF('ONS Sales Forecast'!$CU$4:$CU$52,M49,'ONS Sales Forecast'!$DI$4:$DI$52) -> 1743442.4 | P49: =SUMIF('PRD Sales Forecast'!$CL$4:$CL$49,M49,'PRD Sales Forecast'!$CZ$4:$CZ$49)+SUMIF('PRD Sales Forecast'!$DB$4:$DB$49,M49,'PRD Sales Forecast'!$DP$4:$DP$49) -> 84352 | Q49: =SUM(N49:P49) -> 1827794.4 | R49: =Q49/$R$6 -> 0.28991438
M50: Finance | N50: =SUMIF('CONS Sales Forecast'!$DO$4:$DO$30,M50,'CONS Sales Forecast'!$EE$4:$EE$30) -> 802388 | O50: =SUMIF('ONS Sales Forecast'!$CU$4:$CU$52,M50,'ONS Sales Forecast'!$DI$4:$DI$52) -> 1147695.3 | P50: =SUMIF('PRD Sales Forecast'!$CL$4:$CL$49,M50,'PRD Sales Forecast'!$CZ$4:$CZ$49)+SUMIF('PRD Sales Forecast'!$DB$4:$DB$49,M50,'PRD Sales Forecast'!$DP$4:$DP$49) -> 877754.63 | Q50: =SUM(N50:P50) -> 2827837.9 | R50: =Q50/$R$6 -> 0.44853561
M51: IT & Media | N51: =SUMIF('CONS Sales Forecast'!$DO$4:$DO$30,M51,'CONS Sales Forecast'!$EE$4:$EE$30) -> 65575 | O51: =SUMIF('ONS Sales Forecast'!$CU$4:$CU$52,M51,'ONS Sales Forecast'!$DI$4:$DI$52) -> 169187.76 | P51: =SUMIF('PRD Sales Forecast'!$CL$4:$CL$49,M51,'PRD Sales Forecast'!$CZ$4:$CZ$49)+SUMIF('PRD Sales Forecast'!$DB$4:$DB$49,M51,'PRD Sales Forecast'!$DP$4:$DP$49) -> 235215.2 | Q51: =SUM(N51:P51) -> 469977.96 | R51: =Q51/$R$6 -> 0.074545239
M52: Energy, Utilities, Infrastructure | N52: =SUMIF('CONS Sales Forecast'!$DO$4:$DO$30,M52,'CONS Sales Forecast'!$EE$4:$EE$30) -> 37402.4 | O52: =SUMIF('ONS Sales Forecast'!$CU$4:$CU$52,M52,'ONS Sales Forecast'!$DI$4:$DI$52) -> 0 | P52: =SUMIF('PRD Sales Forecast'!$CL$4:$CL$49,M52,'PRD Sales Forecast'!$CZ$4:$CZ$49)+SUMIF('PRD Sales Forecast'!$DB$4:$DB$49,M52,'PRD Sales Forecast'!$DP$4:$DP$49) -> 465848.24 | Q52: =SUM(N52:P52) -> 503250.64 | R52: =Q52/$R$6 -> 0.079822762
M53: Other Sectors (Schools, Hospitals, etc) | N53: =SUMIF('CONS Sales Forecast'!$DO$4:$DO$30,M53,'CONS Sales Forecast'!$EE$4:$EE$30) -> 31392 | O53: =SUMIF('ONS Sales Forecast'!$CU$4:$CU$52,M53,'ONS Sales Forecast'!$DI$4:$DI$52) -> 0 | P53: =SUMIF('PRD Sales Forecast'!$CL$4:$CL$49,M53,'PRD Sales Forecast'!$CZ$4:$CZ$49)+SUMIF('PRD Sales Forecast'!$DB$4:$DB$49,M53,'PRD Sales Forecast'!$DP$4:$DP$49) -> 107132 | Q53: =SUM(N53:P53) -> 138524 | R53: =Q53/$R$6 -> 0.021971891
M54: Government | N54: =SUMIF('CONS Sales Forecast'!$DO$4:$DO$30,M54,'CONS Sales Forecast'!$EE$4:$EE$30) -> 207795.8 | O54: =SUMIF('ONS Sales Forecast'!$CU$4:$CU$52,M54,'ONS Sales Forecast'!$DI$4:$DI$52) -> 0 | P54: =SUMIF('PRD Sales Forecast'!$CL$4:$CL$49,M54,'PRD Sales Forecast'!$CZ$4:$CZ$49)+SUMIF('PRD Sales Forecast'!$DB$4:$DB$49,M54,'PRD Sales Forecast'!$DP$4:$DP$49) -> 0 | Q54: =SUM(N54:P54) -> 207795.8 | R54: =Q54/$R$6 -> 0.032959391
M55: Health | N55: =SUMIF('CONS Sales Forecast'!$DO$4:$DO$30,M55,'CONS Sales Forecast'!$EE$4:$EE$30) -> 0 | O55: =SUMIF('ONS Sales Forecast'!$CU$4:$CU$52,M55,'ONS Sales Forecast'!$DI$4:$DI$52) -> 0 | P55: =SUMIF('PRD Sales Forecast'!$CL$4:$CL$49,M55,'PRD Sales Forecast'!$CZ$4:$CZ$49)+SUMIF('PRD Sales Forecast'!$DB$4:$DB$49,M55,'PRD Sales Forecast'!$DP$4:$DP$49) -> 105420 | Q55: =SUM(N55:P55) -> 105420 | R55: =Q55/$R$6 -> 0.016721123
M56: Education | N56: =SUMIF('CONS Sales Forecast'!$DO$4:$DO$30,M56,'CONS Sales Forecast'!$EE$4:$EE$30) -> 0 | O56: =SUMIF('ONS Sales Forecast'!$CU$4:$CU$52,M56,'ONS Sales Forecast'!$DI$4:$DI$52) -> 0 | P56: =SUMIF('PRD Sales Forecast'!$CL$4:$CL$49,M56,'PRD Sales Forecast'!$CZ$4:$CZ$49)+SUMIF('PRD Sales Forecast'!$DB$4:$DB$49,M56,'PRD Sales Forecast'!$DP$4:$DP$49) -> 5000 | Q56: =SUM(N56:P56) -> 5000 | R56: =Q56/$R$6 -> 0.00079307164
...

Sheet FY27 Budget
B1: ACTUAL | C1: ACTUAL | D1: BUDGET | E1: BUDGET | F1: BUDGET | G1: BUDGET | H1: BUDGET | I1: BUDGET | J1: BUDGET | K1: BUDGET | L1: BUDGET | M1: BUDGET | N1: BUDGET | O1: BUDGET | P1: BUDGET
B2: FY26 (YTD) | C2: FY27 (YTD) | D2: 46204 | E2: 46235 | F2: 46266 | G2: 46296 | H2: 46327 | I2: 46357 | J2: 46388 | K2: 46419 | L2: 46447 | M2: 46478 | N2: 46508 | O2: 46539 | P2: Total | Q2: Budget vs Actual | S2: Budget vs LY
A3: Consulting | B3: 944789.64 | C3: 0 | D3: =CONS!G2 -> 297416.49 | E3: =CONS!H2 -> 465645.39 | F3: =CONS!I2 -> 82321.892 | G3: =CONS!J2 -> 100061.89 | H3: =CONS!K2 -> 36337.392 | I3: =CONS!L2 -> 31337.392 | J3: =CONS!M2 -> 27340.652 | K3: =CONS!N2 -> 32340.652 | ... O3: =CONS!R2 -> 8035.0717 | P3: =D3+E3+F3+G3+H3+I3+J3+K3+L3+M3+N3+O3 -> 1153553.2 | Q3: =(C3-P3)/P3 -> -1 | R3: =+P3-C3 -> 1153553.2 | S3: =(P3-B3)/B3 -> 0.22096301 | T3: =+P3-B3 -> 208763.56 | V3: =P3/$P$6 -> 0.18297007
A4: Production | B4: 2444121.4 | C4: 0 | D4: ='PRD Sales Forecast'!CN64 -> 73000.02 | E4: ='PRD Sales Forecast'!CO64 -> 251215.02 | F4: ='PRD Sales Forecast'!CP64 -> 83326.02 | G4: ='PRD Sales Forecast'!CQ64 -> 587307.02 | H4: ='PRD Sales Forecast'!CR64 -> 241601.02 | I4: ='PRD Sales Forecast'!CS64 -> 62316.02 | J4: ='PRD Sales Forecast'!CT64 -> 64261.937 | K4: ='PRD Sales Forecast'!CU64 -> 281912.02 | ... O4: ='PRD Sales Forecast'!CY64 -> 82637.02 | P4: =D4+E4+F4+G4+H4+I4+J4+K4+L4+M4+N4+O4 -> 2090722.1 | Q4: =(C4-P4)/P4 -> -1 | R4: =+P4-C4 -> 2090722.1 | S4: =(P4-B4)/B4 -> -0.14459156 | T4: =+P4-B4 -> -353399.33 | V4: =P4/$P$6 -> 0.33161848
A5: Support | B5: 2724275 | C5: 0 | D5: =ONS!F6 -> 238860.67 | E5: =ONS!G6 -> 256307.33 | F5: =ONS!H6 -> 248016.77 | G5: =ONS!I6 -> 263046.77 | H5: =ONS!J6 -> 262366.77 | I5: =ONS!K6 -> 251316.77 | J5: =ONS!L6 -> 262366.77 | K5: =ONS!M6 -> 262366.77 | ... O5: =ONS!Q6 -> 242443.11 | P5: =D5+E5+F5+G5+H5+I5+J5+K5+L5+M5+N5+O5 -> 3060325.4 | Q5: =(C5-P5)/P5 -> -1 | R5: =+P5-C5 -> 3060325.4 | S5: =(P5-B5)/B5 -> 0.12335406 | T5: =+P5-B5 -> 336050.39 | V5: =P5/$P$6 -> 0.48541146
A6: Total Income | B6: =SUM(B3:B5) -> 6113186 | C6: =SUM(C3:C5) -> 0 | D6: =SUM(D3:D5) -> 609277.18 | E6: =SUM(E3:E5) -> 973167.74 | F6: =SUM(F3:F5) -> 413664.68 | G6: =SUM(G3:G5) -> 950415.68 | H6: =SUM(H3:H5) -> 540305.18 | I6: =SUM(I3:I5) -> 344970.18 | ... O6: =SUM(O3:O5) -> 333115.2 | P6: =D6+E6+F6+G6+H6+I6+J6+K6+L6+M6+N6+O6 -> 6304600.7 | Q6: =(C6-P6)/P6 -> -1 | R6: =+P6-C6 -> 6304600.7 | S6: =(P6-B6)/B6 -> 0.031311762 | T6: =+P6-B6 -> 191414.62
A7: Consulting Direct Costs | B7: 744807.04 | C7: 0 | D7: ='FY27 Budget - detailed'!H7 -> 156894.91 | E7: ='FY27 Budget - detailed'!I7 -> 239607.17 | F7: ='FY27 Budget - detailed'!J7 -> 50130.112 | G7: ='FY27 Budget - detailed'!K7 -> 58336.599 | H7: ='FY27 Budget - detailed'!L7 -> 27394.352 | I7: ='FY27 Budget - detailed'!M7 -> 23963.88 | J7: ='FY27 Budget - detailed'!N7 -> 21263.504 | K7: ='FY27 Budget - detailed'!O7 -> 24080.807 | ... O7: ='FY27 Budget - detailed'!S7 -> 17919.298 | P7: =D7+E7+F7+G7+H7+I7+J7+K7+L7+M7+N7+O7 -> 681494.01 | Q7: =(C7-P7)/P7 -> -1 | R7: =+P7-C7 -> 681494.01 | S7: =(P7-B7)/B7 -> -0.085005949 | T7: =+P7-B7 -> -63313.029
A8: Production Direct Costs | B8: 1172927.9 | C8: 0 | D8: ='FY27 Budget - detailed'!H11 -> 52683.663 | E8: ='FY27 Budget - detailed'!I11 -> 100269.81 | F8: ='FY27 Budget - detailed'!J11 -> 103519.69 | G8: ='FY27 Budget - detailed'!K11 -> 285683.94 | H8: ='FY27 Budget - detailed'!L11 -> 104223.85 | I8: ='FY27 Budget - detailed'!M11 -> 83048.46 | J8: ='FY27 Budget - detailed'!N11 -> 45343.173 | K8: ='FY27 Budget - detailed'!O11 -> 109744.55 | ... O8: ='FY27 Budget - detailed'!S11 -> 85630.235 | P8: =D8+E8+F8+G8+H8+I8+J8+K8+L8+M8+N8+O8 -> 1138130.7 | Q8: =(C8-P8)/P8 -> -1 | R8: =+P8-C8 -> 1138130.7 | S8: =(P8-B8)/B8 -> -0.029667025 | T8: =+P8-B8 -> -34797.283
A9: Support Direct Costs | B9: 1579333.4 | C9: 0 | D9: ='FY27 Budget - detailed'!H15 -> 129391.68 | E9: ='FY27 Budget - detailed'!I15 -> 115678.57 | F9: ='FY27 Budget - detailed'!J15 -> 135541.85 | G9: ='FY27 Budget - detailed'!K15 -> 130158.68 | H9: ='FY27 Budget - detailed'!L15 -> 127598.94 | I9: ='FY27 Budget - detailed'!M15 -> 134912.18 | J9: ='FY27 Budget - detailed'!N15 -> 112466.56 | K9: ='FY27 Budget - detailed'!O15 -> 116012.62 | ... O9: ='FY27 Budget - detailed'!S15 -> 139270 | P9: =D9+E9+F9+G9+H9+I9+J9+K9+L9+M9+N9+O9 -> 1559522.1 | Q9: =(C9-P9)/P9 -> -1 | R9: =+P9-C9 -> 1559522.1 | S9: =(P9-B9)/B9 -> -0.012544084 | T9: =+P9-B9 -> -19811.289
A10: Total Cost of Sales | B10: =SUM(B7:B9) -> 3497068.3 | C10: =SUM(C7:C9) -> 0 | D10: =SUM(D7:D9) -> 338970.25 | E10: =SUM(E7:E9) -> 455555.55 | F10: =SUM(F7:F9) -> 289191.66 | G10: =SUM(G7:G9) -> 474179.22 | H10: =SUM(H7:H9) -> 259217.14 | I10: =SUM(I7:I9) -> 241924.52 | ... O10: =SUM(O7:O9) -> 242819.53 | P10: =D10+E10+F10+G10+H10+I10+J10+K10+L10+M10+N10+O10 -> 3379146.7 | Q10: =(C10-P10)/P10 -> -1 | R10: =+P10-C10 -> 3379146.7 | S10: =(P10-B10)/B10 -> -0.033720131 | T10: =+P10-B10 -> -117921.6
A11: Gross Profit | B11: =+B6-B10 -> 2616117.7 | C11: =+C6-C10 -> 0 | D11: =+D6-D10 -> 270306.93 | E11: =+E6-E10 -> 517612.19 | F11: =+F6-F10 -> 124473.02 | G11: =+G6-G10 -> 476236.46 | H11: =+H6-H10 -> 281088.04 | I11: =+I6-I10 -> 103045.66 | ... O11: =+O6-O10 -> 90295.668 | P11: =D11+E11+F11+G11+H11+I11+J11+K11+L11+M11+N11+O11 -> 2925453.9 | Q11: =(C11-P11)/P11 -> -1 | R11: =+P11-C11 -> 2925453.9 | S11: =(P11-B11)/B11 -> 0.11824247 | T11: =+P11-B11 -> 309336.22
A12: Gross Profit Margin | B12: =+B11/B6 -> 0.42794669 | C12: =+C11/C6 -> #DIV/0! | D12: =+D11/D6 -> 0.44365182 | E12: =+E11/E6 -> 0.53188383 | F12: =+F11/F6 -> 0.30090319 | G12: =+G11/G6 -> 0.50108228 | H12: =+H11/H6 -> 0.52023939 | I12: =+I11/I6 -> 0.2987089 | ... P12: =+P11/P6 -> 0.46401891
A13: CTS Overheads | B13: 2380904.7 | C13: 0 | D13: ='FY27 Budget - detailed'!H73 -> 218401.7 | E13: ='FY27 Budget - detailed'!I73 -> 239717.06 | F13: ='FY27 Budget - detailed'!J73 -> 231573.15 | G13: ='FY27 Budget - detailed'!K73 -> 209130.75 | H13: ='FY27 Budget - detailed'!L73 -> 202345.83 | I13: ='FY27 Budget - detailed'!M73 -> 201077.04 | J13: ='FY27 Budget - detailed'!N73 -> 201203.71 | K13: ='FY27 Budget - detailed'!O73 -> 197422.84 | ... O13: ='FY27 Budget - detailed'!S73 -> 208102.17 | P13: =+D13+E13+F13+G13+H13+I13+J13+K13+L13+M13+N13+O13 -> 2528203.2 | Q13: =(C13-P13)/P13 -> -1 | R13: =+P13-C13 -> 2528203.2 | S13: =(P13-B13)/B13 -> 0.061866615 | T13: =+P13-B13 -> 147298.51
A14: Total Expenses | B14: =SUM(B13:B13) -> 2380904.7 | C14: =SUM(C13:C13) -> 0 | D14: =SUM(D13:D13) -> 218401.7 | E14: =SUM(E13:E13) -> 239717.06 | F14: =SUM(F13:F13) -> 231573.15 | G14: =SUM(G13:G13) -> 209130.75 | H14: =SUM(H13:H13) -> 202345.83 | I14: =SUM(I13:I13) -> 201077.04 | ... O14: =SUM(O13:O13) -> 208102.17 | P14: =+D14+E14+F14+G14+H14+I14+J14+K14+L14+M14+N14+O14 -> 2528203.2 | Q14: =(C14-P14)/P14 -> -1 | R14: =+P14-C14 -> 2528203.2 | S14: =(P14-B14)/B14 -> 0.061866615 | T14: =+P14-B14 -> 147298.51
A15: Operating Profit | B15: =+B11-B14 -> 235213.04 | C15: =+C11-C14 -> 0 | D15: =+D11-D14 -> 51905.235 | E15: =+E11-E14 -> 277895.13 | F15: =+F11-F14 -> -107100.12 | G15: =+G11-G14 -> 267105.71 | H15: =+H11-H14 -> 78742.202 | I15: =+I11-I14 -> -98031.373 | ... P15: =+P11-P14 -> 397250.75 | Q15: =(C15-P15)/P15 -> -1 | R15: =+P15-C15 -> 397250.75 | S15: =(P15-B15)/B15 -> 0.68889766 | T15: =+P15-B15 -> 162037.71
A16: Profit Margin | B16: =+B15/B6 -> 0.038476343 | C16: =+C15/C6 -> #DIV/0! | D16: =+D15/D6 -> 0.085191497 | E16: =+E15/E6 -> 0.28555727 | F16: =+F15/F6 -> -0.25890565 | G16: =+G15/G6 -> 0.28104093 | H16: =+H15/H6 -> 0.14573653 | I16: =+I15/I6 -> -0.28417347 | ... P16: =+P15/P6 -> 0.063009662
D18: =D13-D20 -> 0 | E18: =E13-E20 -> 0 | F18: =F13-F20 -> -15937.691 | G18: =G13-G20 -> -38380.086 | H18: =H13-H20 -> -43331.854 | I18: =I13-I20 -> -41895.079 | J18: =J13-J20 -> -39345.275 | K18: =K13-K20 -> -43126.143 | ... O18: =O13-O20 -> -34869.946
D20: =CONS!G33+ONS!F40+PRD!H38 -> 218401.7 | E20: =CONS!H33+ONS!G40+PRD!I38 -> 239717.06 | F20: =CONS!I33+ONS!H40+PRD!J38 -> 247510.84 | G20: =CONS!J33+ONS!I40+PRD!K38 -> 247510.84 | H20: =CONS!K33+ONS!J40+PRD!L38 -> 245677.69 | I20: =CONS!L33+ONS!K40+PRD!M38 -> 242972.12 | J20: =CONS!M33+ONS!L40+PRD!N38 -> 240548.99 | K20: =CONS!N33+ONS!M40+PRD!O38 -> 240548.99 | ... P20: =CONS!S33+ONS!R40+PRD!T38 -> 1376440.8
D32: Budget Expense commentaries: | K32: Budget Sales commentaries:
D33: ESG Budget reduced to $500 per month | K33: Production: $2.09M (34% of revenue)Support: $3M (47% of revenue)Consulting: $1.10M (18% of revenue)
D34: Instant Asset reduced to $5k per month | K34: Revenue is forecast to be strongest during: October ($921K for AGM Season) August ($951K where $400k worth of consulting work becomes realised)
D35: IT Support increased by $36k | K35: Support services remain the largest contributor to revenue, followed by Production, indicating the business continues to rely on recurring operational work rather than project-based consulting.
D36: CTS 20-year anniversary budgeted at $8.5k in Aug
D37: Headcount: Budget removed for Office Admin, Head of HR, 2 Prod technicians, 1 Cons intern
D38: Website update cost in Aug $12k
D39: CTS Logo Update $9.3k
D40: Salary increases factored in 3%
L42: CONS | M42: ONS | N42: PRD
K43: N/E | L43: ='CONS Sales Forecast'!EE16+'CONS Sales Forecast'!EE17 -> 31392 | M43: ='ONS Sales Forecast'!DI38 -> 45000 | N43: ='PRD Sales Forecast'!CZ4+'PRD Sales Forecast'!DP4 -> 120000 | O43: =SUM(L43:N43) -> 196392 | P43: =O43/$O$47 -> 0.031150585
K44: N/N | M44: ='ONS Sales Forecast'!DI8 -> 131483.3 | N44: ='PRD Sales Forecast'!CZ5+'PRD Sales Forecast'!DP5 -> 90000 | O44: =SUM(L44:N44) -> 221483.3 | P44: =O44/$O$47 -> 0.035130425
K45: E/E | L45: ='CONS Sales Forecast'!EE67-'FY27 Budget'!L43 -> 1122161.2 | M45: ='ONS Sales Forecast'!DI61-'FY27 Budget'!M43-'FY27 Budget'!M44 -> 2883842.1 | N45: ='PRD Sales Forecast'!CZ51+'PRD Sales Forecast'!DP51-'FY27 Budget'!N43-'FY27 Budget'!N44 -> 1880722.1 | O45: =SUM(L45:N45) -> 5886725.4 | P45: =O45/$O$47 -> 0.93371899
L47: =SUM(L43:L46) -> 1153553.2 | M47: =SUM(M43:M46) -> 3060325.4 | N47: =SUM(N43:N46) -> 2090722.1 | O47: =SUM(O43:O46) -> 6304600.7
K49: Business Services | L49: =SUMIF('CONS Sales Forecast'!$DO$4:$DO$30,K49,'CONS Sales Forecast'!$EE$4:$EE$30) -> 0 | M49: =SUMIF('ONS Sales Forecast'!$CU$4:$CU$52,K49,'ONS Sales Forecast'!$DI$4:$DI$52) -> 1743442.4 | N49: =SUMIF('PRD Sales Forecast'!$CL$4:$CL$49,K49,'PRD Sales Forecast'!$CZ$4:$CZ$49)+SUMIF('PRD Sales Forecast'!$DB$4:$DB$49,K49,'PRD Sales Forecast'!$DP$4:$DP$49) -> 84352 | O49: =SUM(L49:N49) -> 1827794.4 | P49: =O49/$P$6 -> 0.28991438
K50: Finance | L50: =SUMIF('CONS Sales Forecast'!$DO$4:$DO$30,K50,'CONS Sales Forecast'!$EE$4:$EE$30) -> 802388 | M50: =SUMIF('ONS Sales Forecast'!$CU$4:$CU$52,K50,'ONS Sales Forecast'!$DI$4:$DI$52) -> 1147695.3 | N50: =SUMIF('PRD Sales Forecast'!$CL$4:$CL$49,K50,'PRD Sales Forecast'!$CZ$4:$CZ$49)+SUMIF('PRD Sales Forecast'!$DB$4:$DB$49,K50,'PRD Sales Forecast'!$DP$4:$DP$49) -> 877754.63 | O50: =SUM(L50:N50) -> 2827837.9 | P50: =O50/$P$6 -> 0.44853561
K51: IT & Media | L51: =SUMIF('CONS Sales Forecast'!$DO$4:$DO$30,K51,'CONS Sales Forecast'!$EE$4:$EE$30) -> 65575 | M51: =SUMIF('ONS Sales Forecast'!$CU$4:$CU$52,K51,'ONS Sales Forecast'!$DI$4:$DI$52) -> 169187.76 | N51: =SUMIF('PRD Sales Forecast'!$CL$4:$CL$49,K51,'PRD Sales Forecast'!$CZ$4:$CZ$49)+SUMIF('PRD Sales Forecast'!$DB$4:$DB$49,K51,'PRD Sales Forecast'!$DP$4:$DP$49) -> 235215.2 | O51: =SUM(L51:N51) -> 469977.96 | P51: =O51/$P$6 -> 0.074545239
K52: Energy, Utilities, Infrastructure | L52: =SUMIF('CONS Sales Forecast'!$DO$4:$DO$30,K52,'CONS Sales Forecast'!$EE$4:$EE$30) -> 37402.4 | M52: =SUMIF('ONS Sales Forecast'!$CU$4:$CU$52,K52,'ONS Sales Forecast'!$DI$4:$DI$52) -> 0 | N52: =SUMIF('PRD Sales Forecast'!$CL$4:$CL$49,K52,'PRD Sales Forecast'!$CZ$4:$CZ$49)+SUMIF('PRD Sales Forecast'!$DB$4:$DB$49,K52,'PRD Sales Forecast'!$DP$4:$DP$49) -> 465848.24 | O52: =SUM(L52:N52) -> 503250.64 | P52: =O52/$P$6 -> 0.079822762
K53: Other Sectors (Schools, Hospitals, etc) | L53: =SUMIF('CONS Sales Forecast'!$DO$4:$DO$30,K53,'CONS Sales Forecast'!$EE$4:$EE$30) -> 31392 | M53: =SUMIF('ONS Sales Forecast'!$CU$4:$CU$52,K53,'ONS Sales Forecast'!$DI$4:$DI$52) -> 0 | N53: =SUMIF('PRD Sales Forecast'!$CL$4:$CL$49,K53,'PRD Sales Forecast'!$CZ$4:$CZ$49)+SUMIF('PRD Sales Forecast'!$DB$4:$DB$49,K53,'PRD Sales Forecast'!$DP$4:$DP$49) -> 107132 | O53: =SUM(L53:N53) -> 138524 | P53: =O53/$P$6 -> 0.021971891
K54: Government | L54: =SUMIF('CONS Sales Forecast'!$DO$4:$DO$30,K54,'CONS Sales Forecast'!$EE$4:$EE$30) -> 207795.8 | M54: =SUMIF('ONS Sales Forecast'!$CU$4:$CU$52,K54,'ONS Sales Forecast'!$DI$4:$DI$52) -> 0 | N54: =SUMIF('PRD Sales Forecast'!$CL$4:$CL$49,K54,'PRD Sales Forecast'!$CZ$4:$CZ$49)+SUMIF('PRD Sales Forecast'!$DB$4:$DB$49,K54,'PRD Sales Forecast'!$DP$4:$DP$49) -> 0 | O54: =SUM(L54:N54) -> 207795.8 | P54: =O54/$P$6 -> 0.032959391
K55: Health | L55: =SUMIF('CONS Sales Forecast'!$DO$4:$DO$30,K55,'CONS Sales Forecast'!$EE$4:$EE$30) -> 0 | M55: =SUMIF('ONS Sales Forecast'!$CU$4:$CU$52,K55,'ONS Sales Forecast'!$DI$4:$DI$52) -> 0 | N55: =SUMIF('PRD Sales Forecast'!$CL$4:$CL$49,K55,'PRD Sales Forecast'!$CZ$4:$CZ$49)+SUMIF('PRD Sales Forecast'!$DB$4:$DB$49,K55,'PRD Sales Forecast'!$DP$4:$DP$49) -> 105420 | O55: =SUM(L55:N55) -> 105420 | P55: =O55/$P$6 -> 0.016721123
K56: Education | L56: =SUMIF('CONS Sales Forecast'!$DO$4:$DO$30,K56,'CONS Sales Forecast'!$EE$4:$EE$30) -> 0 | M56: =SUMIF('ONS Sales Forecast'!$CU$4:$CU$52,K56,'ONS Sales Forecast'!$DI$4:$DI$52) -> 0 | N56: =SUMIF('PRD Sales Forecast'!$CL$4:$CL$49,K56,'PRD Sales Forecast'!$CZ$4:$CZ$49)+SUMIF('PRD Sales Forecast'!$DB$4:$DB$49,K56,'PRD Sales Forecast'!$DP$4:$DP$49) -> 5000 | O56: =SUM(L56:N56) -> 5000 | P56: =O56/$P$6 -> 0.00079307164
...

Sheet FY27 Budget - detailed
A1: 46235 | H1: FORECAST | I1: FORECAST | J1: FORECAST | K1: FORECAST | L1: FORECAST | M1: FORECAST | N1: FORECAST | O1: FORECAST | P1: FORECAST | Q1: FORECAST | R1: FORECAST | S1: FORECAST | T1: FORECAST
H2: 46204 | I2: 46235 | J2: 46266 | K2: 46296 | L2: 46327 | M2: 46357 | N2: 46388 | O2: 46419 | P2: 46447 | Q2: 46478 | R2: 46508 | S2: 46539 | T2: Total | U2: Variance
G3: Consulting | H3: =CONS!G2 -> 297416.49 | I3: =CONS!H2 -> 465645.39 | J3: =CONS!I2 -> 82321.892 | K3: =CONS!J2 -> 100061.89 | L3: =CONS!K2 -> 36337.392 | M3: =CONS!L2 -> 31337.392 | N3: =CONS!M2 -> 27340.652 | O3: =CONS!N2 -> 32340.652 | ... S3: =CONS!R2 -> 8035.0717 | T3: =SUM(H3:S3) -> 1153553.2 | V3: =T3=CONS!S2 -> TRUE
G4: Production | H4: =PRD!H3 -> 73000.02 | I4: =PRD!I3 -> 251215.02 | J4: =PRD!J3 -> 83326.02 | K4: =PRD!K3 -> 587307.02 | L4: =PRD!L3 -> 241601.02 | M4: =PRD!M3 -> 62316.02 | N4: =PRD!N3 -> 64261.937 | O4: =PRD!O3 -> 281912.02 | ... S4: =PRD!S3 -> 82637.02 | T4: =SUM(H4:S4) -> 2090722.1 | V4: =T4=PRD!T2 -> TRUE
G5: Onsite | H5: =ONS!F6 -> 238860.67 | I5: =ONS!G6 -> 256307.33 | J5: =ONS!H6 -> 248016.77 | K5: =ONS!I6 -> 263046.77 | L5: =ONS!J6 -> 262366.77 | M5: =ONS!K6 -> 251316.77 | N5: =ONS!L6 -> 262366.77 | O5: =ONS!M6 -> 262366.77 | ... S5: =ONS!Q6 -> 242443.11 | T5: =SUM(H5:S5) -> 3060325.4 | V5: =T5=ONS!R6 -> TRUE
G6: Total Income | H6: =SUM(H3:H5) -> 609277.18 | I6: =SUM(I3:I5) -> 973167.74 | J6: =SUM(J3:J5) -> 413664.68 | K6: =SUM(K3:K5) -> 950415.68 | L6: =SUM(L3:L5) -> 540305.18 | M6: =SUM(M3:M5) -> 344970.18 | N6: =SUM(N3:N5) -> 353969.36 | O6: =SUM(O3:O5) -> 576619.44 | ... S6: =SUM(S3:S5) -> 333115.2 | T6: =SUM(H6:S6) -> 6304600.7
G7: Consulting COS | H7: =-CONS!G10 -> 156894.91 | I7: =-CONS!H10 -> 239607.17 | J7: =-CONS!I10 -> 50130.112 | K7: =-CONS!J10 -> 58336.599 | L7: =-CONS!K10 -> 27394.352 | M7: =-CONS!L10 -> 23963.88 | N7: =-CONS!M10 -> 21263.504 | O7: =-CONS!N10 -> 24080.807 | ... S7: =-CONS!R10 -> 17919.298 | T7: =SUM(H7:S7) -> 681494.01 | U7: =T7=-CONS!S10 -> TRUE | V7: =CONS!S10 -> -681494.01
G8: Labour | H8: =-CONS!G5-CONS!G6 -> 7209.615 | I8: =-CONS!H5-CONS!H6 -> 6457.3073 | J8: =-CONS!I5-CONS!I6 -> 8018.1534 | K8: =-CONS!J5-CONS!J6 -> 8018.1534 | L8: =-CONS!K5-CONS!K6 -> 7289.2304 | M8: =-CONS!L5-CONS!L6 -> 7653.6919 | N8: =-CONS!M5-CONS!M6 -> 7289.2304 | O8: =-CONS!N5-CONS!N6 -> 7289.2304 | ... S8: =-CONS!R5-CONS!R6 -> 7653.6919
G9: Equipment & Services | H9: =-CONS!G7 -> 148708.25 | I9: =-CONS!H7 -> 232822.7 | J9: =-CONS!I7 -> 41160.946 | K9: =-CONS!J7 -> 50030.946 | L9: =-CONS!K7 -> 18168.696 | M9: =-CONS!L7 -> 15668.696 | N9: =-CONS!M7 -> 13670.326 | O9: =-CONS!N7 -> 16170.326 | ... S9: =-CONS!R7 -> 4017.5358
G10: Transportation | H10: =-CONS!G9 -> 689.55156 | I10: =-CONS!H9 -> 39.67052 | J10: =-CONS!I9 -> 663.51226 | K10: =-CONS!J9 -> 0 | L10: =-CONS!K9 -> 1648.9256 | M10: =-CONS!L9 -> 353.9918 | N10: =-CONS!M9 -> 16.448 | O10: =-CONS!N9 -> 333.75048 | ... S10: =-CONS!R9 -> 5960.5702
G11: Production COS | H11: =-PRD!H15 -> 52683.663 | I11: =-PRD!I15 -> 100269.81 | J11: =-PRD!J15 -> 103519.69 | K11: =-PRD!K15 -> 285683.94 | L11: =-PRD!L15 -> 104223.85 | M11: =-PRD!M15 -> 83048.46 | N11: =-PRD!N15 -> 45343.173 | O11: =-PRD!O15 -> 109744.55 | ... S11: =-PRD!S15 -> 85630.235 | T11: =SUM(H11:S11) -> 1138130.7 | U11: =T11=-PRD!T15 -> TRUE | V11: =PRD!T15 -> -1138130.7
G12: Labour | H12: =-PRD!H4-PRD!H5-PRD!H6-PRD!H7-PRD!H9-PRD!H10-PRD!H8 -> 34963.677 | I12: =-PRD!I4-PRD!I5-PRD!I6-PRD!I7-PRD!I9-PRD!I10-PRD!I8 -> 43309.26 | J12: =-PRD!J4-PRD!J5-PRD!J6-PRD!J7-PRD!J9-PRD!J10-PRD!J8 -> 39454.055 | K12: =-PRD!K4-PRD!K5-PRD!K6-PRD!K7-PRD!K9-PRD!K10-PRD!K8 -> 43781.571 | L12: =-PRD!L4-PRD!L5-PRD!L6-PRD!L7-PRD!L9-PRD!L10-PRD!L8 -> 51301.026 | M12: =-PRD!M4-PRD!M5-PRD!M6-PRD!M7-PRD!M9-PRD!M10-PRD!M8 -> 49723.145 | N12: =-PRD!N4-PRD!N5-PRD!N6-PRD!N7-PRD!N9-PRD!N10-PRD!N8 -> 27041.554 | O12: =-PRD!O4-PRD!O5-PRD!O6-PRD!O7-PRD!O9-PRD!O10-PRD!O8 -> 43046.736 | ... R12: =-PRD!R4-PRD!R5-PRD!R6-PRD!R7-PRD!R9-PRD!R10-PRD!R8 -> 37174.461 | S12: =-PRD!S4-PRD!S5-PRD!S6-PRD!S7-PRD!S9-PRD!S10 -> 48755.36
G13: Equipment & Services | H13: =-PRD!H11-PRD!H12 -> 16456.235 | I13: =-PRD!I11-PRD!I12 -> 53025.213 | J13: =-PRD!J11-PRD!J12 -> 55901.12 | K13: =-PRD!K11-PRD!K12 -> 223518.3 | L13: =-PRD!L11-PRD!L12 -> 47833.787 | M13: =-PRD!M11-PRD!M12 -> 30380.64 | N13: =-PRD!N11-PRD!N12 -> 17774.774 | O13: =-PRD!O11-PRD!O12 -> 60051.722 | ... S13: =-PRD!S11-PRD!S12 -> 32960.714
G14: Transportation | H14: =-PRD!H13-PRD!H14 -> 1263.7512 | I14: =-PRD!I13-PRD!I14 -> 3935.3382 | J14: =-PRD!J13-PRD!J14 -> 8164.5194 | K14: =-PRD!K13-PRD!K14 -> 18384.074 | L14: =-PRD!L13-PRD!L14 -> 5089.038 | M14: =-PRD!M13-PRD!M14 -> 2944.6752 | N14: =-PRD!N13-PRD!N14 -> 526.84486 | O14: =-PRD!O13-PRD!O14 -> 6646.092 | ... S14: =-PRD!S13-PRD!S14 -> 3914.1614
G15: Onsite COS | H15: =-ONS!F14 -> 129391.68 | I15: =-ONS!G14 -> 115678.57 | J15: =-ONS!H14 -> 135541.85 | K15: =-ONS!I14 -> 130158.68 | L15: =-ONS!J14 -> 127598.94 | M15: =-ONS!K14 -> 134912.18 | N15: =-ONS!L14 -> 112466.56 | O15: =-ONS!M14 -> 116012.62 | ... S15: =-ONS!Q14 -> 139270 | T15: =SUM(H15:S15) -> 1559522.1 | U15: =T15=-ONS!R14 -> TRUE | V15: =ONS!R14 -> -1559522.1
A16: 3Way | G16: Labour | H16: =-ONS!F7-ONS!F8-ONS!F10 -> 127977.2 | I16: =-ONS!G7-ONS!G8-ONS!G10 -> 109984.29 | J16: =-ONS!H7-ONS!H8-ONS!H10 -> 128812.69 | K16: =-ONS!I7-ONS!I8-ONS!I10 -> 123051.54 | L16: =-ONS!J7-ONS!J8-ONS!J10 -> 121978.42 | M16: =-ONS!K7-ONS!K8-ONS!K10 -> 133541.68 | N16: =-ONS!L7-ONS!L8-ONS!L10 -> 106761.75 | O16: =-ONS!M7-ONS!M8-ONS!M10 -> 110392.11 | ... S16: =-ONS!Q7-ONS!Q8-ONS!Q10 -> 133831.91
A17: 0.34 | B17: 0.33 | C17: 0.33 | G17: Equipment & Services | H17: =-ONS!F12 -> 1188.723 | I17: =-ONS!G12 -> 991.066 | J17: =-ONS!H12 -> 2214.4794 | K17: =-ONS!I12 -> 1026.6731 | L17: =-ONS!J12 -> 1170.5178 | M17: =-ONS!K12 -> 1170.4972 | N17: =-ONS!L12 -> 1254.813 | O17: =-ONS!M12 -> 1170.5126 | ... S17: =-ONS!Q12 -> 988.0893
A18: Staff | G18: Transportation | H18: =-ONS!F13 -> 25.75 | I18: =-ONS!G13 -> 253.2152 | J18: =-ONS!H13 -> 64.684 | K18: =-ONS!I13 -> 1630.4642 | L18: =-ONS!J13 -> 0 | M18: =-ONS!K13 -> 0 | N18: =-ONS!L13 -> 0 | O18: =-ONS!M13 -> 0 | ... S18: =-ONS!Q13 -> 0
A19: ='TO DO'!L17+'TO DO'!L18 -> 0.40298507 | B19: ='TO DO'!L16 -> 0.58208955 | C19: ='TO DO'!L14+'TO DO'!L15 -> 0.014925373 | G19: Total Cost of Sales | H19: =H7+H11+H15 -> 338970.25 | I19: =I7+I11+I15 -> 455555.55 | J19: =J7+J11+J15 -> 289191.66 | K19: =K7+K11+K15 -> 474179.22 | L19: =L7+L11+L15 -> 259217.14 | M19: =M7+M11+M15 -> 241924.52 | N19: =N7+N11+N15 -> 179073.24 | O19: =O7+O11+O15 -> 249837.98 | ... S19: =S7+S11+S15 -> 242819.53 | T19: =SUM(H19:S19) -> 3379146.7 | Y19: =48+12+41 -> 101
A20: Office Dept | G20: Gross Profit | H20: =+H6-H19 -> 270306.93 | I20: =+I6-I19 -> 517612.19 | J20: =+J6-J19 -> 124473.02 | K20: =+K6-K19 -> 476236.46 | L20: =+L6-L19 -> 281088.04 | M20: =+M6-M19 -> 103045.66 | N20: =+N6-N19 -> 174896.12 | O20: =+O6-O19 -> 326781.46 | ... T20: =+T6-T19 -> 2925453.9
A21: 0.9463 | B21: 0.0179 | C21: 0.0358 | G21: Gross Profit Margin | H21: =+H20/H6 -> 0.44365182 | I21: =+I20/I6 -> 0.53188383 | J21: =+J20/J6 -> 0.30090319 | K21: =+K20/K6 -> 0.50108228 | L21: =+L20/L6 -> 0.52023939 | M21: =+M20/M6 -> 0.2987089 | N21: =+N20/N6 -> 0.49409961 | O21: =+O20/O6 -> 0.56671947 | ... T21: =+T20/T6 -> 0.46401891
A22: PRD/VID | B22: ONS | C22: CONS/INT | G22: General & Admin
A23: =$I$23*A17 -> 1161.6667 | B23: =$I$23*B17 -> 1127.5 | C23: =$I$23*C17 -> 1127.5 | E23: 3 Way | G23: Accounting Fees | H23: ='CTS Overheads'!D3 -> 3416.6667 | I23: ='CTS Overheads'!E3 -> 3416.6667 | J23: ='CTS Overheads'!F3 -> 4166.6667 | K23: ='CTS Overheads'!G3 -> 4166.6667 | L23: ='CTS Overheads'!H3 -> 4166.6667 | M23: ='CTS Overheads'!I3 -> 4166.6667 | N23: ='CTS Overheads'!J3 -> 4166.6667 | O23: ='CTS Overheads'!K3 -> 4166.6667 | ... S23: ='CTS Overheads'!O3 -> 5716.6667 | T23: =SUM(H23:S23) -> 54700 | U23: =T23='CTS Overheads'!P3 -> TRUE
A24: =$I$24*A17 -> 612 | B24: =$I$24*B17 -> 594 | C24: =$I$24*C17 -> 594 | E24: 3 Way | G24: Legal Fees | H24: ='CTS Overheads'!D4+'CTS Overheads'!D5 -> 1800 | I24: ='CTS Overheads'!E4+'CTS Overheads'!E5 -> 1800 | J24: ='CTS Overheads'!F4+'CTS Overheads'!F5 -> 1800 | K24: ='CTS Overheads'!G4+'CTS Overheads'!G5 -> 1800 | L24: ='CTS Overheads'!H4+'CTS Overheads'!H5 -> 1800 | M24: ='CTS Overheads'!I4+'CTS Overheads'!I5 -> 1800 | N24: ='CTS Overheads'!J4+'CTS Overheads'!J5 -> 1800 | O24: ='CTS Overheads'!K4+'CTS Overheads'!K5 -> 1800 | ... S24: ='CTS Overheads'!O4+'CTS Overheads'!O5 -> 1800 | T24: =SUM(H24:S24) -> 21600 | U24: =T24='CTS Overheads'!P4+'CTS Overheads'!P5 -> TRUE | V24: *$42K/12
A25: =$I$25*A19 -> 866.41791 | B25: =$I$25*B19 -> 1251.4925 | C25: =$I$25*C19 -> 32.089552 | E25: Staff | G25: Payroll Processing Fee | H25: ='CTS Overheads'!D6 -> 2150 | I25: ='CTS Overheads'!E6 -> 2150 | J25: ='CTS Overheads'!F6 -> 2150 | K25: ='CTS Overheads'!G6 -> 2150 | L25: ='CTS Overheads'!H6 -> 2150 | M25: ='CTS Overheads'!I6 -> 2150 | N25: ='CTS Overheads'!J6 -> 2150 | O25: ='CTS Overheads'!K6 -> 2150 | ... S25: ='CTS Overheads'!O6 -> 2150 | T25: =SUM(H25:S25) -> 25800 | U25: =T25='CTS Overheads'!P6 -> TRUE
A26: =$I$26*A17 -> 170 | B26: =$I$26*B17 -> 165 | C26: =$I$26*C17 -> 165 | E26: 3 Way | G26: Bank Charges | H26: ='CTS Overheads'!D7 -> 500 | I26: ='CTS Overheads'!E7 -> 500 | J26: ='CTS Overheads'!F7 -> 500 | K26: ='CTS Overheads'!G7 -> 500 | L26: ='CTS Overheads'!H7 -> 500 | M26: ='CTS Overheads'!I7 -> 500 | N26: ='CTS Overheads'!J7 -> 500 | O26: ='CTS Overheads'!K7 -> 500 | ... S26: ='CTS Overheads'!O7 -> 500 | T26: =SUM(H26:S26) -> 10516 | U26: =T26='CTS Overheads'!P7 -> TRUE | V26: *4K
A27: =$I$27*A17 -> 2273.5758 | B27: =$I$27*B17 -> 2206.706 | C27: =$I$27*C17 -> 2206.706 | E27: 3 Way | G27: Dues & Subscriptions (Admin CC) | H27: =SUM('CTS Overheads'!D8:D25) -> 6686.9877 | I27: =SUM('CTS Overheads'!E8:E25) -> 6686.9877 | J27: =SUM('CTS Overheads'!F8:F25) -> 6686.9877 | K27: =SUM('CTS Overheads'!G8:G25) -> 7386.9877 | L27: =SUM('CTS Overheads'!H8:H25) -> 7386.9877 | M27: =SUM('CTS Overheads'!I8:I25) -> 7386.9877 | N27: =SUM('CTS Overheads'!J8:J25) -> 7386.9877 | O27: =SUM('CTS Overheads'!K8:K25) -> 7386.9877 | ... S27: =SUM('CTS Overheads'!O8:O25) -> 7386.9877 | T27: =SUM(H27:S27) -> 86543.853 | U27: =T27=SUM('CTS Overheads'!P8:P25) -> TRUE
A28: =$I$28*A17 -> 0 | B28: =$I$28*B17 -> 0 | C28: =$I$28*C17 -> 0 | E28: 3 Way | G28: Donations / Charity | H28: ='CTS Overheads'!D26 -> 0 | I28: ='CTS Overheads'!E26 -> 0 | J28: ='CTS Overheads'!F26 -> 0 | K28: ='CTS Overheads'!G26 -> 0 | L28: ='CTS Overheads'!H26 -> 0 | M28: ='CTS Overheads'!I26 -> 0 | N28: ='CTS Overheads'!J26 -> 0 | O28: ='CTS Overheads'!K26 -> 200 | ... S28: ='CTS Overheads'!O26 -> 5000 | T28: =SUM(H28:S28) -> 5200 | U28: =T28='CTS Overheads'!P26 -> TRUE
A29: =$I$29*A17 -> 10.2 | B29: =$I$29*B17 -> 9.9 | C29: =$I$29*C17 -> 9.9 | E29: 3 Way | G29: Freight Paid | H29: ='CTS Overheads'!D27 -> 30 | I29: ='CTS Overheads'!E27 -> 30 | J29: ='CTS Overheads'!F27 -> 30 | K29: ='CTS Overheads'!G27 -> 30 | L29: ='CTS Overheads'!H27 -> 30 | M29: ='CTS Overheads'!I27 -> 150 | N29: ='CTS Overheads'!J27 -> 30 | O29: ='CTS Overheads'!K27 -> 30 | ... S29: ='CTS Overheads'!O27 -> 30 | T29: =SUM(H29:S29) -> 480 | U29: =T29='CTS Overheads'!P27 -> TRUE
A30: =$I$30*A17 -> 0 | B30: =$I$30*B17 -> 0 | C30: =$I$30*C17 -> 0 | E30: 3 Way | G30: Filing Fee | H30: ='CTS Overheads'!D28 -> 0 | I30: ='CTS Overheads'!E28 -> 0 | J30: ='CTS Overheads'!F28 -> 825 | K30: ='CTS Overheads'!G28 -> 0 | L30: ='CTS Overheads'!H28 -> 0 | M30: ='CTS Overheads'!I28 -> 0 | N30: ='CTS Overheads'!J28 -> 0 | O30: ='CTS Overheads'!K28 -> 0 | ... S30: ='CTS Overheads'!O28 -> 0 | T30: =SUM(H30:S30) -> 825 | U30: =T30='CTS Overheads'!P28 -> TRUE
A31: =$I$31*A21 -> 4731.5 | B31: =$I$31*B21 -> 89.5 | C31: =$I$31*C21 -> 179 | E31: Office Dept | G31: Instant Asset Write Off | H31: ='CTS Overheads'!D29 -> 5000 | I31: ='CTS Overheads'!E29 -> 5000 | J31: ='CTS Overheads'!F29 -> 5000 | K31: ='CTS Overheads'!G29 -> 5000 | L31: ='CTS Overheads'!H29 -> 5000 | M31: ='CTS Overheads'!I29 -> 5000 | N31: ='CTS Overheads'!J29 -> 5000 | O31: ='CTS Overheads'!K29 -> 5000 | ... S31: ='CTS Overheads'!O29 -> 5000 | T31: =SUM(H31:S31) -> 60000 | U31: =T31='CTS Overheads'!P29 -> TRUE
A32: =$I$32*A17 -> 6.8 | B32: =$I$32*B17 -> 6.6 | C32: =$I$32*C17 -> 6.6 | E32: 3 Way | G32: Credit Card Fees Paid | H32: ='CTS Overheads'!D30 -> 20 | I32: ='CTS Overheads'!E30 -> 20 | J32: ='CTS Overheads'!F30 -> 20 | K32: ='CTS Overheads'!G30 -> 20 | L32: ='CTS Overheads'!H30 -> 20 | M32: ='CTS Overheads'!I30 -> 20 | N32: ='CTS Overheads'!J30 -> 20 | O32: ='CTS Overheads'!K30 -> 20 | ... S32: ='CTS Overheads'!O30 -> 20 | T32: =SUM(H32:S32) -> 240 | U32: =T32='CTS Overheads'!P30 -> TRUE
A33: =$I$33*A17 -> 408 | B33: =$I$33*B17 -> 396 | C33: =$I$33*C17 -> 396 | E33: 3 Way | G33: Business Advisory | H33: ='CTS Overheads'!D31 -> 1200 | I33: ='CTS Overheads'!E31 -> 1200 | J33: ='CTS Overheads'!F31 -> 1200 | K33: ='CTS Overheads'!G31 -> 1200 | L33: ='CTS Overheads'!H31 -> 1200 | M33: ='CTS Overheads'!I31 -> 1200 | N33: ='CTS Overheads'!J31 -> 1200 | O33: ='CTS Overheads'!K31 -> 1200 | ... S33: ='CTS Overheads'!O31 -> 1200 | T33: =SUM(H33:S33) -> 14400 | U33: =T33='CTS Overheads'!P31 -> TRUE
A34: =$I$34*A17 -> 76.474217 | B34: =$I$34*B17 -> 74.224975 | C34: =$I$34*C17 -> 74.224975 | E34: 3 Way | G34: Custodian Vaults | H34: ='CTS Overheads'!D32 -> 224.92417 | I34: ='CTS Overheads'!E32 -> 224.92417 | J34: ='CTS Overheads'!F32 -> 224.92417 | K34: ='CTS Overheads'!G32 -> 224.92417 | L34: ='CTS Overheads'!H32 -> 224.92417 | M34: ='CTS Overheads'!I32 -> 224.92417 | N34: ='CTS Overheads'!J32 -> 224.92417 | O34: ='CTS Overheads'!K32 -> 224.92417 | ... S34: ='CTS Overheads'!O32 -> 224.92417 | T34: =SUM(H34:S34) -> 2699.09 | U34: =T34='CTS Overheads'!P32 -> TRUE
A35: =$I$35*A17 -> 187 | B35: =$I$35*B17 -> 181.5 | C35: =$I$35*C17 -> 181.5 | E35: 3 Way | G35: Taxis/Parking | H35: ='CTS Overheads'!D33 -> 300 | I35: ='CTS Overheads'!E33 -> 550 | J35: ='CTS Overheads'!F33 -> 300 | K35: ='CTS Overheads'!G33 -> 150 | L35: ='CTS Overheads'!H33 -> 150 | M35: ='CTS Overheads'!I33 -> 100 | N35: ='CTS Overheads'!J33 -> 50 | O35: ='CTS Overheads'!K33 -> 150 | ... S35: ='CTS Overheads'!O33 -> 100 | T35: =SUM(H35:S35) -> 2250 | U35: =T35='CTS Overheads'!P33 -> TRUE
A36: =$I$36*A17 -> 0 | B36: =$I$36*B17 -> 0 | C36: =$I$36*C17 -> 0 | E36: 3 Way | G36: Stamp Duty (Indirect) | H36: ='CTS Overheads'!D34 -> 0 | I36: ='CTS Overheads'!E34 -> 0 | J36: ='CTS Overheads'!F34 -> 2741.81 | K36: ='CTS Overheads'!G34 -> 0 | L36: ='CTS Overheads'!H34 -> 0 | M36: ='CTS Overheads'!I34 -> 0 | N36: ='CTS Overheads'!J34 -> 0 | O36: ='CTS Overheads'!K34 -> 0 | ... S36: ='CTS Overheads'!O34 -> 0 | T36: =SUM(H36:S36) -> 2741.81 | U36: =T36='CTS Overheads'!P34 -> TRUE
A37: =SUM(A23:A36) -> 10535.127 | B37: =SUM(B23:B36) -> 6228.4682 | C37: =SUM(C23:C36) -> 4814.9832 | G37: Business Insurances
A38: =$I$38*A17 -> 1160.9847 | B38: =$I$38*B17 -> 1126.8381 | C38: =$I$38*C17 -> 1126.8381 | E38: 3 Way | G38: Other Insurance | H38: ='CTS Overheads'!$A$40 -> 3414.6608 | I38: ='CTS Overheads'!$A$40 -> 3414.6608 | J38: ='CTS Overheads'!$A$40 -> 3414.6608 | K38: ='CTS Overheads'!$A$40 -> 3414.6608 | L38: ='CTS Overheads'!$A$40 -> 3414.6608 | M38: ='CTS Overheads'!$A$40 -> 3414.6608 | N38: ='CTS Overheads'!$A$40 -> 3414.6608 | O38: ='CTS Overheads'!$A$40 -> 3414.6608 | ... S38: ='CTS Overheads'!$A$40 -> 3414.6608 | T38: =SUM(H38:S38) -> 40975.93 | U38: =T38=SUM('CTS Overheads'!P36:P40) -> TRUE
A39: =$I$39*A17 -> 35.785 | B39: =$I$39*B17 -> 34.7325 | C39: =$I$39*C17 -> 34.7325 | E39: 3 Way | G39: Travel Insurance | H39: ='CTS Overheads'!D41 -> 105.25 | I39: ='CTS Overheads'!E41 -> 105.25 | J39: ='CTS Overheads'!F41 -> 105.25 | K39: ='CTS Overheads'!G41 -> 105.25 | L39: ='CTS Overheads'!H41 -> 105.25 | M39: ='CTS Overheads'!I41 -> 105.25 | N39: ='CTS Overheads'!J41 -> 105.25 | O39: ='CTS Overheads'!K41 -> 105.25 | ... S39: ='CTS Overheads'!O41 -> 105.25 | T39: =SUM(H39:S39) -> 1263 | U39: =T39='CTS Overheads'!P41 -> TRUE
A40: =SUM(A38:A39) -> 1196.7697 | B40: =SUM(B38:B39) -> 1161.5706 | C40: =SUM(C38:C39) -> 1161.5706
...

Sheet CTS Overheads
D1: FORECAST | E1: FORECAST | F1: FORECAST | G1: FORECAST | H1: FORECAST | I1: FORECAST | J1: FORECAST | K1: FORECAST | L1: FORECAST | M1: FORECAST | N1: FORECAST | O1: FORECAST | P1: FORECAST
A2: CTS Overheads | D2: 46204 | E2: 46235 | F2: 46266 | G2: 46296 | H2: 46327 | I2: 46357 | J2: 46388 | K2: 46419 | L2: 46447 | M2: 46478 | N2: 46508 | O2: 46539 | P2: Total
A3: Accounting Fees | B3: KPMG FY2027 | D3: =(25000/12)+(16000/12) -> 3416.6667 | E3: =D3 -> 3416.6667 | F3: =E3+750 -> 4166.6667 | G3: =F3 -> 4166.6667 | H3: =G3 -> 4166.6667 | I3: =H3 -> 4166.6667 | J3: =I3 -> 4166.6667 | K3: =J3 -> 4166.6667 | L3: =K3+1550 -> 5716.6667 | M3: =L3 -> 5716.6667 | N3: =M3 -> 5716.6667 | O3: =N3 -> 5716.6667 | P3: =SUM(D3:O3) -> 54700
A4: Legal Fees | B4: Employsure (WHS & FW) until 2028 | D4: 800 | E4: 800 | F4: 800 | G4: 800 | H4: 800 | I4: 800 | J4: 800 | K4: 800 | L4: 800 | M4: 800 | N4: 800 | O4: 800 | P4: =SUM(D4:O4) -> 9600 | Q4: Employsure $800 p/m
A5: Legal Fees | B5: Easton Belle & Meyer West | D5: 1000 | E5: =D5 -> 1000 | F5: =E5 -> 1000 | G5: =F5 -> 1000 | H5: =G5 -> 1000 | I5: =H5 -> 1000 | J5: =I5 -> 1000 | K5: =J5 -> 1000 | L5: =K5 -> 1000 | ... O5: =N5 -> 1000 | P5: =SUM(D5:O5) -> 12000
A6: Payroll Processing Fee | B6: Employment Hero | D6: 2150 | E6: =D6 -> 2150 | F6: =E6 -> 2150 | G6: =F6 -> 2150 | H6: =G6 -> 2150 | I6: =H6 -> 2150 | J6: =I6 -> 2150 | K6: =J6 -> 2150 | L6: =K6 -> 2150 | ... O6: =N6 -> 2150 | P6: =SUM(D6:O6) -> 25800
A7: Bank Charges | B7: CBA/CCs | D7: 500 | E7: =D7 -> 500 | F7: =E7 -> 500 | G7: =F7 -> 500 | H7: =G7 -> 500 | I7: =H7 -> 500 | J7: =I7 -> 500 | K7: =J7 -> 500 | L7: =2258+500 -> 2758 | M7: =K7 -> 500 | N7: =L7 -> 2758 | O7: =M7 -> 500 | P7: =SUM(D7:O7) -> 10516
A8: Dues & Subscriptions | B8: MYOB/Xero | D8: =90.91+2 -> 92.91 | E8: =D8 -> 92.91 | F8: =E8 -> 92.91 | G8: =F8 -> 92.91 | H8: =G8 -> 92.91 | I8: =H8 -> 92.91 | J8: =I8 -> 92.91 | K8: =J8 -> 92.91 | L8: =K8 -> 92.91 | ... O8: =N8 -> 92.91 | P8: =SUM(D8:O8) -> 1114.92
B9: ESG (SBTi) | D9: 500 | E9: =D9 -> 500 | F9: =E9 -> 500 | G9: =F9 -> 500 | H9: =G9 -> 500 | I9: =H9 -> 500 | J9: =I9 -> 500 | K9: =J9 -> 500 | L9: =K9 -> 500 | ... O9: =N9 -> 500 | P9: =SUM(D9:O9) -> 6000
B10: First Focus (Managed Services Azure) | D10: 595 | E10: =D10 -> 595 | F10: =E10 -> 595 | G10: =F10 -> 595 | H10: =G10 -> 595 | I10: =H10 -> 595 | J10: =I10 -> 595 | K10: =J10 -> 595 | L10: =K10 -> 595 | ... O10: =N10 -> 595 | P10: =SUM(D10:O10) -> 7140 | Q10: MS Licences | S10: IT Costs:
