Workbook

Sheet Read Me
A1: How to use the Revenue Risk Profile
A3: What it shows
A4: How much of this year's revenue is already earned, how much is signed, and how much still depends on pipeline. It shows what happens if pipeline does not come through, or if certain customers walk away. It does this for each department.
A6: Each month
A7: 1. Settings: change the last month of P&L actuals to the new month end.
A8: 2. P&L Dump: clear A7 to Z1006. Paste the Xero Profit and Loss from cell A7, account names in column A, months across. In row 5, pick the month for each pasted column.
A9: 3. Zoho Dump: clear columns A to J. Run the Zoho report All Deals by Stage and paste the whole export into cell A1, exactly as it comes out.
A10: 4. Adjustments: add signed or likely revenue that is not in Zoho, such as recurring support contracts.
A11: 5. Dashboard: check the Data checks box at the bottom. Every line should say OK.
A12: 6. Dashboard: pick customers to withdraw and set the stress case to show management the risk.
A14: Colours
A15: Yellow cells with blue text are inputs. Everything else is a formula. Do not type over formulas.
... A31: Revenue that is never entered in Zoho, like recurring contracts, only shows if it is added on Adjustments.

Sheet Dashboard
A1: Revenue Risk Profile
A2: ="Financial year "&TEXT(Settings!$B$4,"dd/mm/yyyy")&" to "&TEXT(Settings!$B$6,"dd/mm/yyyy")&". P&L actuals to "&TEXT(Settings!$B$5,"dd/mm/yyyy")&". Zoho export: "&MID('Zoho Dump'!$A$3,FIND(" on ",'Zoho Dump'!$A$3)+4,40) -> Financial year 01/07/2026 to 30/06/2027. P&L actuals to 30/09/2026. Zoho export: 12/10/2026 11:49 AM
A4: ="Base forecast for the year is "&TEXT(F33,"$#,##0")&". Signed so far (actuals plus backlog) is "&TEXT(B33+C33,"$#,##0")&"." -> Base forecast for the year is $853,202. Signed so far (actuals plus backlog) is $85,402.
A5: ="If no more pipeline comes through than the stress case below, revenue falls by "&TEXT(L33,"$#,##0")&"." -> If no more pipeline comes through than the stress case below, revenue falls by $767,800.
A6: ="The selected customers withdrawing would cost "&TEXT(M33,"$#,##0")&" of forward revenue. Both together leave "&TEXT(O33,"$#,##0")&" for the year." -> The selected customers withdrawing would cost $0 of forward revenue. Both together leave $85,402 for the year.
A7: ="Largest single customer: "&B37&", "&TEXT(F37,"0.0%")&" of all forward revenue. Top 10 customers: "&TEXT(G46,"0.0%")&"." -> Largest single customer: Commonwealth Bank Australia (CBA), 50.3% of all forward revenue. Top 10 customers: 85.2%.
A9: Scenario levers (yellow cells)
A10: Stress case: share of pipeline that still comes through | C10: 0
A11: 0% means no open deal lands. Backlog is kept in full.
A12: Customers who withdraw (pick from the list)
B13: 1
B14: 2
B15: 3
B16: 4
B17: 5
B18: 6
B19: 7
B20: 8
B21: 9
B22: 10
A23: A withdrawal removes that customer's backlog and pipeline for the rest of the year. It does not touch actuals already earned, or revenue that is not in Zoho or Adjustments.
A25: Department | B25: Actual to date (P&L) | C25: Backlog, signed | D25: Pipeline, full value | E25: Pipeline, weighted | F25: Base forecast for FY | G25: Budget for FY | H25: Forecast less budget | I25: Signed as % of budget | J25: Pipeline share of forward revenue | K25: If pipeline falls through | L25: Revenue at risk from pipeline | M25: Lost if selected customers withdraw | N25: Forecast after withdrawals | O25: Worst case: both | P25: Largest customer | Q25: Largest customer share | R25: Overdue Zoho deals, full value | S25: Won to date in Zoho (reference) | T25: Risk rating | V25: Budget score | W25: Concentration score | X25: Pipeline score
A26: =Settings!$A$12 -> Onsite | B26: =SUMIFS('Monthly Outlook'!$C$8:$N$8,'Monthly Outlook'!$C$5:$N$5,"Actual") -> 0 | C26: ='Monthly Outlook'!$O$18 -> 17000 | D26: =SUMIFS('Zoho Dump'!$Y$8:$Y$3007,'Zoho Dump'!$P$8:$P$3007,$A26,'Zoho Dump'!$T$8:$T$3007,"Pipeline")+SUMIFS(Adjustments!$L$8:$L$207,Adjustments!$A$8:$A$207,$A26,Adjustments!$H$8:$H$207,"Pipeline")+SUMIFS('Zoho Dump'!$Y$8:$Y$3007,'Zoho Dump'!$P$8:$P$3007,$A26,'Zoho Dump'!$T$8:$T$3007,"Overdue")+SUMIFS(Adjustments!$L$8:$L$207,Adjustments!$A$8:$A$207,$A26,Adjustments!$H$8:$H$207,"Overdue") -> 75000 | E26: ='Monthly Outlook'!$O$28 -> 52500 | F26: ='Monthly Outlook'!$O$38 -> 69500 | G26: ='Monthly Outlook'!$O$58 -> 0 | H26: =IF(G26=0,"No budget",F26-G26) -> No budget | I26: =IF(G26=0,"No budget",(B26+C26)/G26) -> No budget | J26: =IF(C26+E26=0,0,E26/(C26+E26)) -> 0.75539568 | K26: ='Monthly Outlook'!$O$48 -> 17000 | L26: =F26-K26 -> 52500 | M26: =SUMIFS('Zoho Dump'!$X$8:$X$3007,'Zoho Dump'!$P$8:$P$3007,$A26,'Zoho Dump'!$AA$8:$AA$3007,1)+SUMIFS(Adjustments!$K$8:$K$207,Adjustments!$A$8:$A$207,$A26,Adjustments!$N$8:$N$207,1) -> 0 | N26: =F26-M26 -> 69500 | O26: =K26-(SUMIFS('Zoho Dump'!$Z$8:$Z$3007,'Zoho Dump'!$P$8:$P$3007,$A26,'Zoho Dump'!$AA$8:$AA$3007,1)+SUMIFS(Adjustments!$M$8:$M$207,Adjustments!$A$8:$A$207,$A26,Adjustments!$N$8:$N$207,1)) -> 17000 | P26: =IF(MAX('Customer Risk'!$K$5:$K$404)=0,"-",INDEX('Customer Risk'!$B$5:$B$404,MATCH(MAX('Customer Risk'!$K$5:$K$404),'Customer Risk'!$K$5:$K$404,0))) -> Deloitte Australia | Q26: =IF(SUM('Customer Risk'!$K$5:$K$404)=0,0,MAX('Customer Risk'!$K$5:$K$404)/SUM('Customer Risk'!$K$5:$K$404)) -> 0.75539568 | R26: =SUMIFS('Zoho Dump'!$Q$8:$Q$3007,'Zoho Dump'!$P$8:$P$3007,$A26,'Zoho Dump'!$T$8:$T$3007,"Overdue")+SUMIFS(Adjustments!$G$8:$G$207,Adjustments!$A$8:$A$207,$A26,Adjustments!$H$8:$H$207,"Overdue") -> 137200 | S26: =SUMIFS('Zoho Dump'!$Q$8:$Q$3007,'Zoho Dump'!$P$8:$P$3007,$A26,'Zoho Dump'!$T$8:$T$3007,"Delivered",'Zoho Dump'!$R$8:$R$3007,">="&Settings!$B$4) -> 159259 | T26: =IF(AND(B26=0,F26=0),"-",CHOOSE(MAX(V26:X26)+1,"Low","Medium","High")) -> High | V26: =IF(G26=0,0,IF(F26<G26*(1-Settings!$C$54),2,IF(F26<G26*(1-Settings!$B$54),1,0))) -> 0 | W26: =IF(Q26>=Settings!$C$55,2,IF(Q26>=Settings!$B$55,1,0)) -> 2 | X26: =IF(J26>=Settings!$C$56,2,IF(J26>=Settings!$B$56,1,0)) -> 2
A27: =Settings!$A$13 -> Production | B27: =SUMIFS('Monthly Outlook'!$C$9:$N$9,'Monthly Outlook'!$C$5:$N$5,"Actual") -> 0 | C27: ='Monthly Outlook'!$O$19 -> 57060 | D27: =SUMIFS('Zoho Dump'!$Y$8:$Y$3007,'Zoho Dump'!$P$8:$P$3007,$A27,'Zoho Dump'!$T$8:$T$3007,"Pipeline")+SUMIFS(Adjustments!$L$8:$L$207,Adjustments!$A$8:$A$207,$A27,Adjustments!$H$8:$H$207,"Pipeline")+SUMIFS('Zoho Dump'!$Y$8:$Y$3007,'Zoho Dump'!$P$8:$P$3007,$A27,'Zoho Dump'!$T$8:$T$3007,"Overdue")+SUMIFS(Adjustments!$L$8:$L$207,Adjustments!$A$8:$A$207,$A27,Adjustments!$H$8:$H$207,"Overdue") -> 874626 | E27: ='Monthly Outlook'!$O$29 -> 645044.5 | F27: ='Monthly Outlook'!$O$39 -> 702104.5 | G27: ='Monthly Outlook'!$O$59 -> 0 | H27: =IF(G27=0,"No budget",F27-G27) -> No budget | I27: =IF(G27=0,"No budget",(B27+C27)/G27) -> No budget | J27: =IF(C27+E27=0,0,E27/(C27+E27)) -> 0.91873005 | K27: ='Monthly Outlook'!$O$49 -> 57060 | L27: =F27-K27 -> 645044.5 | M27: =SUMIFS('Zoho Dump'!$X$8:$X$3007,'Zoho Dump'!$P$8:$P$3007,$A27,'Zoho Dump'!$AA$8:$AA$3007,1)+SUMIFS(Adjustments!$K$8:$K$207,Adjustments!$A$8:$A$207,$A27,Adjustments!$N$8:$N$207,1) -> 0 | N27: =F27-M27 -> 702104.5 | O27: =K27-(SUMIFS('Zoho Dump'!$Z$8:$Z$3007,'Zoho Dump'!$P$8:$P$3007,$A27,'Zoho Dump'!$AA$8:$AA$3007,1)+SUMIFS(Adjustments!$M$8:$M$207,Adjustments!$A$8:$A$207,$A27,Adjustments!$N$8:$N$207,1)) -> 57060 | P27: =IF(MAX('Customer Risk'!$L$5:$L$404)=0,"-",INDEX('Customer Risk'!$B$5:$B$404,MATCH(MAX('Customer Risk'!$L$5:$L$404),'Customer Risk'!$L$5:$L$404,0))) -> Commonwealth Bank Australia (CBA) | Q27: =IF(SUM('Customer Risk'!$L$5:$L$404)=0,0,MAX('Customer Risk'!$L$5:$L$404)/SUM('Customer Risk'!$L$5:$L$404)) -> 0.61155569 | R27: =SUMIFS('Zoho Dump'!$Q$8:$Q$3007,'Zoho Dump'!$P$8:$P$3007,$A27,'Zoho Dump'!$T$8:$T$3007,"Overdue")+SUMIFS(Adjustments!$G$8:$G$207,Adjustments!$A$8:$A$207,$A27,Adjustments!$H$8:$H$207,"Overdue") -> 60795 | S27: =SUMIFS('Zoho Dump'!$Q$8:$Q$3007,'Zoho Dump'!$P$8:$P$3007,$A27,'Zoho Dump'!$T$8:$T$3007,"Delivered",'Zoho Dump'!$R$8:$R$3007,">="&Settings!$B$4) -> 478946 | T27: =IF(AND(B27=0,F27=0),"-",CHOOSE(MAX(V27:X27)+1,"Low","Medium","High")) -> High | V27: =IF(G27=0,0,IF(F27<G27*(1-Settings!$C$54),2,IF(F27<G27*(1-Settings!$B$54),1,0))) -> 0 | W27: =IF(Q27>=Settings!$C$55,2,IF(Q27>=Settings!$B$55,1,0)) -> 2 | X27: =IF(J27>=Settings!$C$56,2,IF(J27>=Settings!$B$56,1,0)) -> 2
A28: =Settings!$A$14 -> Video | B28: =SUMIFS('Monthly Outlook'!$C$10:$N$10,'Monthly Outlook'!$C$5:$N$5,"Actual") -> 0 | C28: ='Monthly Outlook'!$O$20 -> 11342 | D28: =SUMIFS('Zoho Dump'!$Y$8:$Y$3007,'Zoho Dump'!$P$8:$P$3007,$A28,'Zoho Dump'!$T$8:$T$3007,"Pipeline")+SUMIFS(Adjustments!$L$8:$L$207,Adjustments!$A$8:$A$207,$A28,Adjustments!$H$8:$H$207,"Pipeline")+SUMIFS('Zoho Dump'!$Y$8:$Y$3007,'Zoho Dump'!$P$8:$P$3007,$A28,'Zoho Dump'!$T$8:$T$3007,"Overdue")+SUMIFS(Adjustments!$L$8:$L$207,Adjustments!$A$8:$A$207,$A28,Adjustments!$H$8:$H$207,"Overdue") -> 1395 | E28: ='Monthly Outlook'!$O$30 -> 1255.5 | F28: ='Monthly Outlook'!$O$40 -> 12597.5 | G28: ='Monthly Outlook'!$O$60 -> 0 | H28: =IF(G28=0,"No budget",F28-G28) -> No budget | I28: =IF(G28=0,"No budget",(B28+C28)/G28) -> No budget | J28: =IF(C28+E28=0,0,E28/(C28+E28)) -> 0.099662631 | K28: ='Monthly Outlook'!$O$50 -> 11342 | L28: =F28-K28 -> 1255.5 | M28: =SUMIFS('Zoho Dump'!$X$8:$X$3007,'Zoho Dump'!$P$8:$P$3007,$A28,'Zoho Dump'!$AA$8:$AA$3007,1)+SUMIFS(Adjustments!$K$8:$K$207,Adjustments!$A$8:$A$207,$A28,Adjustments!$N$8:$N$207,1) -> 0 | N28: =F28-M28 -> 12597.5 | O28: =K28-(SUMIFS('Zoho Dump'!$Z$8:$Z$3007,'Zoho Dump'!$P$8:$P$3007,$A28,'Zoho Dump'!$AA$8:$AA$3007,1)+SUMIFS(Adjustments!$M$8:$M$207,Adjustments!$A$8:$A$207,$A28,Adjustments!$N$8:$N$207,1)) -> 11342 | P28: =IF(MAX('Customer Risk'!$M$5:$M$404)=0,"-",INDEX('Customer Risk'!$B$5:$B$404,MATCH(MAX('Customer Risk'!$M$5:$M$404),'Customer Risk'!$M$5:$M$404,0))) -> ASX Refinitiv Charity Foundation Ltd | Q28: =IF(SUM('Customer Risk'!$M$5:$M$404)=0,0,MAX('Customer Risk'!$M$5:$M$404)/SUM('Customer Risk'!$M$5:$M$404)) -> 0.70101211 | R28: =SUMIFS('Zoho Dump'!$Q$8:$Q$3007,'Zoho Dump'!$P$8:$P$3007,$A28,'Zoho Dump'!$T$8:$T$3007,"Overdue")+SUMIFS(Adjustments!$G$8:$G$207,Adjustments!$A$8:$A$207,$A28,Adjustments!$H$8:$H$207,"Overdue") -> 0 | S28: =SUMIFS('Zoho Dump'!$Q$8:$Q$3007,'Zoho Dump'!$P$8:$P$3007,$A28,'Zoho Dump'!$T$8:$T$3007,"Delivered",'Zoho Dump'!$R$8:$R$3007,">="&Settings!$B$4) -> 6401 | T28: =IF(AND(B28=0,F28=0),"-",CHOOSE(MAX(V28:X28)+1,"Low","Medium","High")) -> High | V28: =IF(G28=0,0,IF(F28<G28*(1-Settings!$C$54),2,IF(F28<G28*(1-Settings!$B$54),1,0))) -> 0 | W28: =IF(Q28>=Settings!$C$55,2,IF(Q28>=Settings!$B$55,1,0)) -> 2 | X28: =IF(J28>=Settings!$C$56,2,IF(J28>=Settings!$B$56,1,0)) -> 0
A29: =Settings!$A$15 -> Consulting | B29: =SUMIFS('Monthly Outlook'!$C$11:$N$11,'Monthly Outlook'!$C$5:$N$5,"Actual") -> 0 | C29: ='Monthly Outlook'!$O$21 -> 0 | D29: =SUMIFS('Zoho Dump'!$Y$8:$Y$3007,'Zoho Dump'!$P$8:$P$3007,$A29,'Zoho Dump'!$T$8:$T$3007,"Pipeline")+SUMIFS(Adjustments!$L$8:$L$207,Adjustments!$A$8:$A$207,$A29,Adjustments!$H$8:$H$207,"Pipeline")+SUMIFS('Zoho Dump'!$Y$8:$Y$3007,'Zoho Dump'!$P$8:$P$3007,$A29,'Zoho Dump'!$T$8:$T$3007,"Overdue")+SUMIFS(Adjustments!$L$8:$L$207,Adjustments!$A$8:$A$207,$A29,Adjustments!$H$8:$H$207,"Overdue") -> 75000 | E29: ='Monthly Outlook'!$O$31 -> 15000 | F29: ='Monthly Outlook'!$O$41 -> 15000 | G29: ='Monthly Outlook'!$O$61 -> 0 | H29: =IF(G29=0,"No budget",F29-G29) -> No budget | I29: =IF(G29=0,"No budget",(B29+C29)/G29) -> No budget | J29: =IF(C29+E29=0,0,E29/(C29+E29)) -> 1 | K29: ='Monthly Outlook'!$O$51 -> 0 | L29: =F29-K29 -> 15000 | M29: =SUMIFS('Zoho Dump'!$X$8:$X$3007,'Zoho Dump'!$P$8:$P$3007,$A29,'Zoho Dump'!$AA$8:$AA$3007,1)+SUMIFS(Adjustments!$K$8:$K$207,Adjustments!$A$8:$A$207,$A29,Adjustments!$N$8:$N$207,1) -> 0 | N29: =F29-M29 -> 15000 | O29: =K29-(SUMIFS('Zoho Dump'!$Z$8:$Z$3007,'Zoho Dump'!$P$8:$P$3007,$A29,'Zoho Dump'!$AA$8:$AA$3007,1)+SUMIFS(Adjustments!$M$8:$M$207,Adjustments!$A$8:$A$207,$A29,Adjustments!$N$8:$N$207,1)) -> 0 | P29: =IF(MAX('Customer Risk'!$N$5:$N$404)=0,"-",INDEX('Customer Risk'!$B$5:$B$404,MATCH(MAX('Customer Risk'!$N$5:$N$404),'Customer Risk'!$N$5:$N$404,0))) -> Hills Grammar | Q29: =IF(SUM('Customer Risk'!$N$5:$N$404)=0,0,MAX('Customer Risk'!$N$5:$N$404)/SUM('Customer Risk'!$N$5:$N$404)) -> 1 | R29: =SUMIFS('Zoho Dump'!$Q$8:$Q$3007,'Zoho Dump'!$P$8:$P$3007,$A29,'Zoho Dump'!$T$8:$T$3007,"Overdue")+SUMIFS(Adjustments!$G$8:$G$207,Adjustments!$A$8:$A$207,$A29,Adjustments!$H$8:$H$207,"Overdue") -> 3000 | S29: =SUMIFS('Zoho Dump'!$Q$8:$Q$3007,'Zoho Dump'!$P$8:$P$3007,$A29,'Zoho Dump'!$T$8:$T$3007,"Delivered",'Zoho Dump'!$R$8:$R$3007,">="&Settings!$B$4) -> 53469 | T29: =IF(AND(B29=0,F29=0),"-",CHOOSE(MAX(V29:X29)+1,"Low","Medium","High")) -> High | V29: =IF(G29=0,0,IF(F29<G29*(1-Settings!$C$54),2,IF(F29<G29*(1-Settings!$B$54),1,0))) -> 0 | W29: =IF(Q29>=Settings!$C$55,2,IF(Q29>=Settings!$B$55,1,0)) -> 2 | X29: =IF(J29>=Settings!$C$56,2,IF(J29>=Settings!$B$56,1,0)) -> 2
A30: =Settings!$A$16 -> Integration | B30: =SUMIFS('Monthly Outlook'!$C$12:$N$12,'Monthly Outlook'!$C$5:$N$5,"Actual") -> 0 | C30: ='Monthly Outlook'!$O$22 -> 0 | D30: =SUMIFS('Zoho Dump'!$Y$8:$Y$3007,'Zoho Dump'!$P$8:$P$3007,$A30,'Zoho Dump'!$T$8:$T$3007,"Pipeline")+SUMIFS(Adjustments!$L$8:$L$207,Adjustments!$A$8:$A$207,$A30,Adjustments!$H$8:$H$207,"Pipeline")+SUMIFS('Zoho Dump'!$Y$8:$Y$3007,'Zoho Dump'!$P$8:$P$3007,$A30,'Zoho Dump'!$T$8:$T$3007,"Overdue")+SUMIFS(Adjustments!$L$8:$L$207,Adjustments!$A$8:$A$207,$A30,Adjustments!$H$8:$H$207,"Overdue") -> 98456 | E30: ='Monthly Outlook'!$O$32 -> 53999.7 | F30: ='Monthly Outlook'!$O$42 -> 53999.7 | G30: ='Monthly Outlook'!$O$62 -> 0 | H30: =IF(G30=0,"No budget",F30-G30) -> No budget | I30: =IF(G30=0,"No budget",(B30+C30)/G30) -> No budget | J30: =IF(C30+E30=0,0,E30/(C30+E30)) -> 1 | K30: ='Monthly Outlook'!$O$52 -> 0 | L30: =F30-K30 -> 53999.7 | M30: =SUMIFS('Zoho Dump'!$X$8:$X$3007,'Zoho Dump'!$P$8:$P$3007,$A30,'Zoho Dump'!$AA$8:$AA$3007,1)+SUMIFS(Adjustments!$K$8:$K$207,Adjustments!$A$8:$A$207,$A30,Adjustments!$N$8:$N$207,1) -> 0 | N30: =F30-M30 -> 53999.7 | O30: =K30-(SUMIFS('Zoho Dump'!$Z$8:$Z$3007,'Zoho Dump'!$P$8:$P$3007,$A30,'Zoho Dump'!$AA$8:$AA$3007,1)+SUMIFS(Adjustments!$M$8:$M$207,Adjustments!$A$8:$A$207,$A30,Adjustments!$N$8:$N$207,1)) -> 0 | P30: =IF(MAX('Customer Risk'!$O$5:$O$404)=0,"-",INDEX('Customer Risk'!$B$5:$B$404,MATCH(MAX('Customer Risk'!$O$5:$O$404),'Customer Risk'!$O$5:$O$404,0))) -> Aware Super | Q30: =IF(SUM('Customer Risk'!$O$5:$O$404)=0,0,MAX('Customer Risk'!$O$5:$O$404)/SUM('Customer Risk'!$O$5:$O$404)) -> 0.3823762 | R30: =SUMIFS('Zoho Dump'!$Q$8:$Q$3007,'Zoho Dump'!$P$8:$P$3007,$A30,'Zoho Dump'!$T$8:$T$3007,"Overdue")+SUMIFS(Adjustments!$G$8:$G$207,Adjustments!$A$8:$A$207,$A30,Adjustments!$H$8:$H$207,"Overdue") -> 0 | S30: =SUMIFS('Zoho Dump'!$Q$8:$Q$3007,'Zoho Dump'!$P$8:$P$3007,$A30,'Zoho Dump'!$T$8:$T$3007,"Delivered",'Zoho Dump'!$R$8:$R$3007,">="&Settings!$B$4) -> 181846 | T30: =IF(AND(B30=0,F30=0),"-",CHOOSE(MAX(V30:X30)+1,"Low","Medium","High")) -> High | V30: =IF(G30=0,0,IF(F30<G30*(1-Settings!$C$54),2,IF(F30<G30*(1-Settings!$B$54),1,0))) -> 0 | W30: =IF(Q30>=Settings!$C$55,2,IF(Q30>=Settings!$B$55,1,0)) -> 1 | X30: =IF(J30>=Settings!$C$56,2,IF(J30>=Settings!$B$56,1,0)) -> 2
A31: =Settings!$A$17 -> Admin | B31: =SUMIFS('Monthly Outlook'!$C$13:$N$13,'Monthly Outlook'!$C$5:$N$5,"Actual") -> 0 | C31: ='Monthly Outlook'!$O$23 -> 0 | D31: =SUMIFS('Zoho Dump'!$Y$8:$Y$3007,'Zoho Dump'!$P$8:$P$3007,$A31,'Zoho Dump'!$T$8:$T$3007,"Pipeline")+SUMIFS(Adjustments!$L$8:$L$207,Adjustments!$A$8:$A$207,$A31,Adjustments!$H$8:$H$207,"Pipeline")+SUMIFS('Zoho Dump'!$Y$8:$Y$3007,'Zoho Dump'!$P$8:$P$3007,$A31,'Zoho Dump'!$T$8:$T$3007,"Overdue")+SUMIFS(Adjustments!$L$8:$L$207,Adjustments!$A$8:$A$207,$A31,Adjustments!$H$8:$H$207,"Overdue") -> 0 | E31: ='Monthly Outlook'!$O$33 -> 0 | F31: ='Monthly Outlook'!$O$43 -> 0 | G31: ='Monthly Outlook'!$O$63 -> 0 | H31: =IF(G31=0,"No budget",F31-G31) -> No budget | I31: =IF(G31=0,"No budget",(B31+C31)/G31) -> No budget | J31: =IF(C31+E31=0,0,E31/(C31+E31)) -> 0 | K31: ='Monthly Outlook'!$O$53 -> 0 | L31: =F31-K31 -> 0 | M31: =SUMIFS('Zoho Dump'!$X$8:$X$3007,'Zoho Dump'!$P$8:$P$3007,$A31,'Zoho Dump'!$AA$8:$AA$3007,1)+SUMIFS(Adjustments!$K$8:$K$207,Adjustments!$A$8:$A$207,$A31,Adjustments!$N$8:$N$207,1) -> 0 | N31: =F31-M31 -> 0 | O31: =K31-(SUMIFS('Zoho Dump'!$Z$8:$Z$3007,'Zoho Dump'!$P$8:$P$3007,$A31,'Zoho Dump'!$AA$8:$AA$3007,1)+SUMIFS(Adjustments!$M$8:$M$207,Adjustments!$A$8:$A$207,$A31,Adjustments!$N$8:$N$207,1)) -> 0 | P31: =IF(MAX('Customer Risk'!$P$5:$P$404)=0,"-",INDEX('Customer Risk'!$B$5:$B$404,MATCH(MAX('Customer Risk'!$P$5:$P$404),'Customer Risk'!$P$5:$P$404,0))) -> - | Q31: =IF(SUM('Customer Risk'!$P$5:$P$404)=0,0,MAX('Customer Risk'!$P$5:$P$404)/SUM('Customer Risk'!$P$5:$P$404)) -> 0 | R31: =SUMIFS('Zoho Dump'!$Q$8:$Q$3007,'Zoho Dump'!$P$8:$P$3007,$A31,'Zoho Dump'!$T$8:$T$3007,"Overdue")+SUMIFS(Adjustments!$G$8:$G$207,Adjustments!$A$8:$A$207,$A31,Adjustments!$H$8:$H$207,"Overdue") -> 0 | S31: =SUMIFS('Zoho Dump'!$Q$8:$Q$3007,'Zoho Dump'!$P$8:$P$3007,$A31,'Zoho Dump'!$T$8:$T$3007,"Delivered",'Zoho Dump'!$R$8:$R$3007,">="&Settings!$B$4) -> 0 | T31: =IF(AND(B31=0,F31=0),"-",CHOOSE(MAX(V31:X31)+1,"Low","Medium","High")) -> - | V31: =IF(G31=0,0,IF(F31<G31*(1-Settings!$C$54),2,IF(F31<G31*(1-Settings!$B$54),1,0))) -> 0 | W31: =IF(Q31>=Settings!$C$55,2,IF(Q31>=Settings!$B$55,1,0)) -> 0 | X31: =IF(J31>=Settings!$C$56,2,IF(J31>=Settings!$B$56,1,0)) -> 0
A32: =Settings!$A$18 -> Unallocated | B32: =SUMIFS('Monthly Outlook'!$C$14:$N$14,'Monthly Outlook'!$C$5:$N$5,"Actual") -> 0 | C32: ='Monthly Outlook'!$O$24 -> 0 | D32: =SUMIFS('Zoho Dump'!$Y$8:$Y$3007,'Zoho Dump'!$P$8:$P$3007,$A32,'Zoho Dump'!$T$8:$T$3007,"Pipeline")+SUMIFS(Adjustments!$L$8:$L$207,Adjustments!$A$8:$A$207,$A32,Adjustments!$H$8:$H$207,"Pipeline")+SUMIFS('Zoho Dump'!$Y$8:$Y$3007,'Zoho Dump'!$P$8:$P$3007,$A32,'Zoho Dump'!$T$8:$T$3007,"Overdue")+SUMIFS(Adjustments!$L$8:$L$207,Adjustments!$A$8:$A$207,$A32,Adjustments!$H$8:$H$207,"Overdue") -> 0 | E32: ='Monthly Outlook'!$O$34 -> 0 | F32: ='Monthly Outlook'!$O$44 -> 0 | G32: ='Monthly Outlook'!$O$64 -> 0 | H32: =IF(G32=0,"No budget",F32-G32) -> No budget | I32: =IF(G32=0,"No budget",(B32+C32)/G32) -> No budget | J32: =IF(C32+E32=0,0,E32/(C32+E32)) -> 0 | K32: ='Monthly Outlook'!$O$54 -> 0 | L32: =F32-K32 -> 0 | M32: =SUMIFS('Zoho Dump'!$X$8:$X$3007,'Zoho Dump'!$P$8:$P$3007,$A32,'Zoho Dump'!$AA$8:$AA$3007,1)+SUMIFS(Adjustments!$K$8:$K$207,Adjustments!$A$8:$A$207,$A32,Adjustments!$N$8:$N$207,1) -> 0 | N32: =F32-M32 -> 0 | O32: =K32-(SUMIFS('Zoho Dump'!$Z$8:$Z$3007,'Zoho Dump'!$P$8:$P$3007,$A32,'Zoho Dump'!$AA$8:$AA$3007,1)+SUMIFS(Adjustments!$M$8:$M$207,Adjustments!$A$8:$A$207,$A32,Adjustments!$N$8:$N$207,1)) -> 0 | P32: =IF(MAX('Customer Risk'!$Q$5:$Q$404)=0,"-",INDEX('Customer Risk'!$B$5:$B$404,MATCH(MAX('Customer Risk'!$Q$5:$Q$404),'Customer Risk'!$Q$5:$Q$404,0))) -> - | Q32: =IF(SUM('Customer Risk'!$Q$5:$Q$404)=0,0,MAX('Customer Risk'!$Q$5:$Q$404)/SUM('Customer Risk'!$Q$5:$Q$404)) -> 0 | R32: =SUMIFS('Zoho Dump'!$Q$8:$Q$3007,'Zoho Dump'!$P$8:$P$3007,$A32,'Zoho Dump'!$T$8:$T$3007,"Overdue")+SUMIFS(Adjustments!$G$8:$G$207,Adjustments!$A$8:$A$207,$A32,Adjustments!$H$8:$H$207,"Overdue") -> 0 | S32: =SUMIFS('Zoho Dump'!$Q$8:$Q$3007,'Zoho Dump'!$P$8:$P$3007,$A32,'Zoho Dump'!$T$8:$T$3007,"Delivered",'Zoho Dump'!$R$8:$R$3007,">="&Settings!$B$4) -> 0 | T32: =IF(AND(B32=0,F32=0),"-",CHOOSE(MAX(V32:X32)+1,"Low","Medium","High")) -> - | V32: =IF(G32=0,0,IF(F32<G32*(1-Settings!$C$54),2,IF(F32<G32*(1-Settings!$B$54),1,0))) -> 0 | W32: =IF(Q32>=Settings!$C$55,2,IF(Q32>=Settings!$B$55,1,0)) -> 0 | X32: =IF(J32>=Settings!$C$56,2,IF(J32>=Settings!$B$56,1,0)) -> 0
A33: Total | B33: =SUM(B26:B32) -> 0 | C33: =SUM(C26:C32) -> 85402 | D33: =SUM(D26:D32) -> 1124477 | E33: =SUM(E26:E32) -> 767799.7 | F33: =SUM(F26:F32) -> 853201.7 | G33: =SUM(G26:G32) -> 0 | H33: =IF(G33=0,"No budget",F33-G33) -> No budget | I33: =IF(G33=0,"No budget",(B33+C33)/G33) -> No budget | J33: =IF(C33+E33=0,0,E33/(C33+E33)) -> 0.89990409 | K33: =SUM(K26:K32) -> 85402 | L33: =SUM(L26:L32) -> 767799.7 | M33: =SUM(M26:M32) -> 0 | N33: =SUM(N26:N32) -> 853201.7 | O33: =SUM(O26:O32) -> 85402 | P33: =B37 -> Commonwealth Bank Australia (CBA) | Q33: =F37 -> 0.50325263 | R33: =SUM(R26:R32) -> 200995 | S33: =SUM(S26:S32) -> 879921
A35: Top 10 customers by forward revenue
A36: Rank | B36: Customer | C36: Backlog, signed | D36: Pipeline, weighted | E36: Forward revenue | F36: Share of all forward revenue | G36: Cumulative share | H36: Withdrawn in scenario
A37: 1 | B37: =IFERROR(INDEX('Customer Risk'!$B$5:$B$404,MATCH(LARGE('Customer Risk'!$R$5:$R$404,1),'Customer Risk'!$R$5:$R$404,0)),"") -> Commonwealth Bank Australia (CBA) | C37: =IFERROR(INDEX('Customer Risk'!$D$5:$D$404,MATCH(LARGE('Customer Risk'!$R$5:$R$404,1),'Customer Risk'!$R$5:$R$404,0)),0) -> 0 | D37: =IFERROR(INDEX('Customer Risk'!$F$5:$F$404,MATCH(LARGE('Customer Risk'!$R$5:$R$404,1),'Customer Risk'!$R$5:$R$404,0)),0) -> 429376 | E37: =IFERROR(INDEX('Customer Risk'!$G$5:$G$404,MATCH(LARGE('Customer Risk'!$R$5:$R$404,1),'Customer Risk'!$R$5:$R$404,0)),0) -> 429376 | F37: =IFERROR(INDEX('Customer Risk'!$H$5:$H$404,MATCH(LARGE('Customer Risk'!$R$5:$R$404,1),'Customer Risk'!$R$5:$R$404,0)),0) -> 0.50325263 | G37: =SUM($F$37:F37) -> 0.50325263 | H37: =IFERROR(INDEX('Customer Risk'!$J$5:$J$404,MATCH(LARGE('Customer Risk'!$R$5:$R$404,1),'Customer Risk'!$R$5:$R$404,0)),"")
A38: 2 | B38: =IFERROR(INDEX('Customer Risk'!$B$5:$B$404,MATCH(LARGE('Customer Risk'!$R$5:$R$404,2),'Customer Risk'!$R$5:$R$404,0)),"") -> MUFG IR / Orient Capital | C38: =IFERROR(INDEX('Customer Risk'!$D$5:$D$404,MATCH(LARGE('Customer Risk'!$R$5:$R$404,2),'Customer Risk'!$R$5:$R$404,0)),0) -> 0 | D38: =IFERROR(INDEX('Customer Risk'!$F$5:$F$404,MATCH(LARGE('Customer Risk'!$R$5:$R$404,2),'Customer Risk'!$R$5:$R$404,0)),0) -> 74751.4 | E38: =IFERROR(INDEX('Customer Risk'!$G$5:$G$404,MATCH(LARGE('Customer Risk'!$R$5:$R$404,2),'Customer Risk'!$R$5:$R$404,0)),0) -> 74751.4 | F38: =IFERROR(INDEX('Customer Risk'!$H$5:$H$404,MATCH(LARGE('Customer Risk'!$R$5:$R$404,2),'Customer Risk'!$R$5:$R$404,0)),0) -> 0.087612812 | G38: =SUM($F$37:F38) -> 0.59086544 | H38: =IFERROR(INDEX('Customer Risk'!$J$5:$J$404,MATCH(LARGE('Customer Risk'!$R$5:$R$404,2),'Customer Risk'!$R$5:$R$404,0)),"")
A39: 3 | B39: =IFERROR(INDEX('Customer Risk'!$B$5:$B$404,MATCH(LARGE('Customer Risk'!$R$5:$R$404,3),'Customer Risk'!$R$5:$R$404,0)),"") -> Deloitte Australia | C39: =IFERROR(INDEX('Customer Risk'!$D$5:$D$404,MATCH(LARGE('Customer Risk'!$R$5:$R$404,3),'Customer Risk'!$R$5:$R$404,0)),0) -> 0 | D39: =IFERROR(INDEX('Customer Risk'!$F$5:$F$404,MATCH(LARGE('Customer Risk'!$R$5:$R$404,3),'Customer Risk'!$R$5:$R$404,0)),0) -> 53012.5 | E39: =IFERROR(INDEX('Customer Risk'!$G$5:$G$404,MATCH(LARGE('Customer Risk'!$R$5:$R$404,3),'Customer Risk'!$R$5:$R$404,0)),0) -> 53012.5 | F39: =IFERROR(INDEX('Customer Risk'!$H$5:$H$404,MATCH(LARGE('Customer Risk'!$R$5:$R$404,3),'Customer Risk'!$R$5:$R$404,0)),0) -> 0.062133608 | G39: =SUM($F$37:F39) -> 0.65299905 | H39: =IFERROR(INDEX('Customer Risk'!$J$5:$J$404,MATCH(LARGE('Customer Risk'!$R$5:$R$404,3),'Customer Risk'!$R$5:$R$404,0)),"")
A40: 4 | B40: =IFERROR(INDEX('Customer Risk'!$B$5:$B$404,MATCH(LARGE('Customer Risk'!$R$5:$R$404,4),'Customer Risk'!$R$5:$R$404,0)),"") -> Automic Group | C40: =IFERROR(INDEX('Customer Risk'!$D$5:$D$404,MATCH(LARGE('Customer Risk'!$R$5:$R$404,4),'Customer Risk'!$R$5:$R$404,0)),0) -> 0 | D40: =IFERROR(INDEX('Customer Risk'!$F$5:$F$404,MATCH(LARGE('Customer Risk'!$R$5:$R$404,4),'Customer Risk'!$R$5:$R$404,0)),0) -> 40654.7 | E40: =IFERROR(INDEX('Customer Risk'!$G$5:$G$404,MATCH(LARGE('Customer Risk'!$R$5:$R$404,4),'Customer Risk'!$R$5:$R$404,0)),0) -> 40654.7 | F40: =IFERROR(INDEX('Customer Risk'!$H$5:$H$404,MATCH(LARGE('Customer Risk'!$R$5:$R$404,4),'Customer Risk'!$R$5:$R$404,0)),0) -> 0.047649577 | G40: =SUM($F$37:F40) -> 0.70064863 | H40: =IFERROR(INDEX('Customer Risk'!$J$5:$J$404,MATCH(LARGE('Customer Risk'!$R$5:$R$404,4),'Customer Risk'!$R$5:$R$404,0)),"")
A41: 5 | B41: =IFERROR(INDEX('Customer Risk'!$B$5:$B$404,MATCH(LARGE('Customer Risk'!$R$5:$R$404,5),'Customer Risk'!$R$5:$R$404,0)),"") -> Microsoft | C41: =IFERROR(INDEX('Customer Risk'!$D$5:$D$404,MATCH(LARGE('Customer Risk'!$R$5:$R$404,5),'Customer Risk'!$R$5:$R$404,0)),0) -> 27122 | D41: =IFERROR(INDEX('Customer Risk'!$F$5:$F$404,MATCH(LARGE('Customer Risk'!$R$5:$R$404,5),'Customer Risk'!$R$5:$R$404,0)),0) -> 0 | E41: =IFERROR(INDEX('Customer Risk'!$G$5:$G$404,MATCH(LARGE('Customer Risk'!$R$5:$R$404,5),'Customer Risk'!$R$5:$R$404,0)),0) -> 27122 | F41: =IFERROR(INDEX('Customer Risk'!$H$5:$H$404,MATCH(LARGE('Customer Risk'!$R$5:$R$404,5),'Customer Risk'!$R$5:$R$404,0)),0) -> 0.031788497 | G41: =SUM($F$37:F41) -> 0.73243712 | H41: =IFERROR(INDEX('Customer Risk'!$J$5:$J$404,MATCH(LARGE('Customer Risk'!$R$5:$R$404,5),'Customer Risk'!$R$5:$R$404,0)),"")
A42: 6 | B42: =IFERROR(INDEX('Customer Risk'!$B$5:$B$404,MATCH(LARGE('Customer Risk'!$R$5:$R$404,6),'Customer Risk'!$R$5:$R$404,0)),"") -> The Lottery Corporation | C42: =IFERROR(INDEX('Customer Risk'!$D$5:$D$404,MATCH(LARGE('Customer Risk'!$R$5:$R$404,6),'Customer Risk'!$R$5:$R$404,0)),0) -> 0 | D42: =IFERROR(INDEX('Customer Risk'!$F$5:$F$404,MATCH(LARGE('Customer Risk'!$R$5:$R$404,6),'Customer Risk'!$R$5:$R$404,0)),0) -> 25543.8 | E42: =IFERROR(INDEX('Customer Risk'!$G$5:$G$404,MATCH(LARGE('Customer Risk'!$R$5:$R$404,6),'Customer Risk'!$R$5:$R$404,0)),0) -> 25543.8 | F42: =IFERROR(INDEX('Customer Risk'!$H$5:$H$404,MATCH(LARGE('Customer Risk'!$R$5:$R$404,6),'Customer Risk'!$R$5:$R$404,0)),0) -> 0.029938759 | G42: =SUM($F$37:F42) -> 0.76237588 | H42: =IFERROR(INDEX('Customer Risk'!$J$5:$J$404,MATCH(LARGE('Customer Risk'!$R$5:$R$404,6),'Customer Risk'!$R$5:$R$404,0)),"")
A43: 7 | B43: =IFERROR(INDEX('Customer Risk'!$B$5:$B$404,MATCH(LARGE('Customer Risk'!$R$5:$R$404,7),'Customer Risk'!$R$5:$R$404,0)),"") -> Aware Super | C43: =IFERROR(INDEX('Customer Risk'!$D$5:$D$404,MATCH(LARGE('Customer Risk'!$R$5:$R$404,7),'Customer Risk'!$R$5:$R$404,0)),0) -> 0 | D43: =IFERROR(INDEX('Customer Risk'!$F$5:$F$404,MATCH(LARGE('Customer Risk'!$R$5:$R$404,7),'Customer Risk'!$R$5:$R$404,0)),0) -> 22648.2 | E43: =IFERROR(INDEX('Customer Risk'!$G$5:$G$404,MATCH(LARGE('Customer Risk'!$R$5:$R$404,7),'Customer Risk'!$R$5:$R$404,0)),0) -> 22648.2 | F43: =IFERROR(INDEX('Customer Risk'!$H$5:$H$404,MATCH(LARGE('Customer Risk'!$R$5:$R$404,7),'Customer Risk'!$R$5:$R$404,0)),0) -> 0.026544954 | G43: =SUM($F$37:F43) -> 0.78892084 | H43: =IFERROR(INDEX('Customer Risk'!$J$5:$J$404,MATCH(LARGE('Customer Risk'!$R$5:$R$404,7),'Customer Risk'!$R$5:$R$404,0)),"")
A44: 8 | B44: =IFERROR(INDEX('Customer Risk'!$B$5:$B$404,MATCH(LARGE('Customer Risk'!$R$5:$R$404,8),'Customer Risk'!$R$5:$R$404,0)),"") -> PWC | C44: =IFERROR(INDEX('Customer Risk'!$D$5:$D$404,MATCH(LARGE('Customer Risk'!$R$5:$R$404,8),'Customer Risk'!$R$5:$R$404,0)),0) -> 17000 | D44: =IFERROR(INDEX('Customer Risk'!$F$5:$F$404,MATCH(LARGE('Customer Risk'!$R$5:$R$404,8),'Customer Risk'!$R$5:$R$404,0)),0) -> 4428 | E44: =IFERROR(INDEX('Customer Risk'!$G$5:$G$404,MATCH(LARGE('Customer Risk'!$R$5:$R$404,8),'Customer Risk'!$R$5:$R$404,0)),0) -> 21428 | F44: =IFERROR(INDEX('Customer Risk'!$H$5:$H$404,MATCH(LARGE('Customer Risk'!$R$5:$R$404,8),'Customer Risk'!$R$5:$R$404,0)),0) -> 0.025114812 | G44: =SUM($F$37:F44) -> 0.81403565 | H44: =IFERROR(INDEX('Customer Risk'!$J$5:$J$404,MATCH(LARGE('Customer Risk'!$R$5:$R$404,8),'Customer Risk'!$R$5:$R$404,0)),"")
...

Sheet Monthly Outlook
A1: Monthly Outlook by department
A2: Months up to the last P&L month show actuals. Later months show Zoho backlog plus weighted pipeline, plus Adjustments.
A4: Month | C4: =Settings!$D$12 -> 46204 | D4: =Settings!$D$13 -> 46235 | E4: =Settings!$D$14 -> 46266 | F4: =Settings!$D$15 -> 46296 | G4: =Settings!$D$16 -> 46327 | H4: =Settings!$D$17 -> 46357 | I4: =Settings!$D$18 -> 46388 | J4: =Settings!$D$19 -> 46419 | K4: =Settings!$D$20 -> 46447 | L4: =Settings!$D$21 -> 46478 | M4: =Settings!$D$22 -> 46508 | N4: =Settings!$D$23 -> 46539 | O4: FY total
A5: Actual or forecast | C5: =IF(C$4<=Settings!$B$5,"Actual","Forecast") -> Actual | D5: =IF(D$4<=Settings!$B$5,"Actual","Forecast") -> Actual | E5: =IF(E$4<=Settings!$B$5,"Actual","Forecast") -> Actual | F5: =IF(F$4<=Settings!$B$5,"Actual","Forecast") -> Forecast | G5: =IF(G$4<=Settings!$B$5,"Actual","Forecast") -> Forecast | H5: =IF(H$4<=Settings!$B$5,"Actual","Forecast") -> Forecast | I5: =IF(I$4<=Settings!$B$5,"Actual","Forecast") -> Forecast | J5: =IF(J$4<=Settings!$B$5,"Actual","Forecast") -> Forecast | ... N5: =IF(N$4<=Settings!$B$5,"Actual","Forecast") -> Forecast
A7: Actual revenue | B7: From P&L Dump, Income accounts
A8: =Settings!$A$12 -> Onsite | C8: =IFERROR(SUMIFS(INDEX('P&L Dump'!$B$7:$Z$1006,0,MATCH(C$4,'P&L Dump'!$B$5:$Z$5,0)),'P&L Dump'!$AC$7:$AC$1006,"Income",'P&L Dump'!$AD$7:$AD$1006,$A8),0) -> 0 | D8: =IFERROR(SUMIFS(INDEX('P&L Dump'!$B$7:$Z$1006,0,MATCH(D$4,'P&L Dump'!$B$5:$Z$5,0)),'P&L Dump'!$AC$7:$AC$1006,"Income",'P&L Dump'!$AD$7:$AD$1006,$A8),0) -> 0 | E8: =IFERROR(SUMIFS(INDEX('P&L Dump'!$B$7:$Z$1006,0,MATCH(E$4,'P&L Dump'!$B$5:$Z$5,0)),'P&L Dump'!$AC$7:$AC$1006,"Income",'P&L Dump'!$AD$7:$AD$1006,$A8),0) -> 0 | F8: =IFERROR(SUMIFS(INDEX('P&L Dump'!$B$7:$Z$1006,0,MATCH(F$4,'P&L Dump'!$B$5:$Z$5,0)),'P&L Dump'!$AC$7:$AC$1006,"Income",'P&L Dump'!$AD$7:$AD$1006,$A8),0) -> 0 | G8: =IFERROR(SUMIFS(INDEX('P&L Dump'!$B$7:$Z$1006,0,MATCH(G$4,'P&L Dump'!$B$5:$Z$5,0)),'P&L Dump'!$AC$7:$AC$1006,"Income",'P&L Dump'!$AD$7:$AD$1006,$A8),0) -> 0 | H8: =IFERROR(SUMIFS(INDEX('P&L Dump'!$B$7:$Z$1006,0,MATCH(H$4,'P&L Dump'!$B$5:$Z$5,0)),'P&L Dump'!$AC$7:$AC$1006,"Income",'P&L Dump'!$AD$7:$AD$1006,$A8),0) -> 0 | I8: =IFERROR(SUMIFS(INDEX('P&L Dump'!$B$7:$Z$1006,0,MATCH(I$4,'P&L Dump'!$B$5:$Z$5,0)),'P&L Dump'!$AC$7:$AC$1006,"Income",'P&L Dump'!$AD$7:$AD$1006,$A8),0) -> 0 | J8: =IFERROR(SUMIFS(INDEX('P&L Dump'!$B$7:$Z$1006,0,MATCH(J$4,'P&L Dump'!$B$5:$Z$5,0)),'P&L Dump'!$AC$7:$AC$1006,"Income",'P&L Dump'!$AD$7:$AD$1006,$A8),0) -> 0 | ... N8: =IFERROR(SUMIFS(INDEX('P&L Dump'!$B$7:$Z$1006,0,MATCH(N$4,'P&L Dump'!$B$5:$Z$5,0)),'P&L Dump'!$AC$7:$AC$1006,"Income",'P&L Dump'!$AD$7:$AD$1006,$A8),0) -> 0 | O8: =SUM(C8:N8) -> 0
A9: =Settings!$A$13 -> Production | C9: =IFERROR(SUMIFS(INDEX('P&L Dump'!$B$7:$Z$1006,0,MATCH(C$4,'P&L Dump'!$B$5:$Z$5,0)),'P&L Dump'!$AC$7:$AC$1006,"Income",'P&L Dump'!$AD$7:$AD$1006,$A9),0) -> 0 | D9: =IFERROR(SUMIFS(INDEX('P&L Dump'!$B$7:$Z$1006,0,MATCH(D$4,'P&L Dump'!$B$5:$Z$5,0)),'P&L Dump'!$AC$7:$AC$1006,"Income",'P&L Dump'!$AD$7:$AD$1006,$A9),0) -> 0 | E9: =IFERROR(SUMIFS(INDEX('P&L Dump'!$B$7:$Z$1006,0,MATCH(E$4,'P&L Dump'!$B$5:$Z$5,0)),'P&L Dump'!$AC$7:$AC$1006,"Income",'P&L Dump'!$AD$7:$AD$1006,$A9),0) -> 0 | F9: =IFERROR(SUMIFS(INDEX('P&L Dump'!$B$7:$Z$1006,0,MATCH(F$4,'P&L Dump'!$B$5:$Z$5,0)),'P&L Dump'!$AC$7:$AC$1006,"Income",'P&L Dump'!$AD$7:$AD$1006,$A9),0) -> 0 | G9: =IFERROR(SUMIFS(INDEX('P&L Dump'!$B$7:$Z$1006,0,MATCH(G$4,'P&L Dump'!$B$5:$Z$5,0)),'P&L Dump'!$AC$7:$AC$1006,"Income",'P&L Dump'!$AD$7:$AD$1006,$A9),0) -> 0 | H9: =IFERROR(SUMIFS(INDEX('P&L Dump'!$B$7:$Z$1006,0,MATCH(H$4,'P&L Dump'!$B$5:$Z$5,0)),'P&L Dump'!$AC$7:$AC$1006,"Income",'P&L Dump'!$AD$7:$AD$1006,$A9),0) -> 0 | I9: =IFERROR(SUMIFS(INDEX('P&L Dump'!$B$7:$Z$1006,0,MATCH(I$4,'P&L Dump'!$B$5:$Z$5,0)),'P&L Dump'!$AC$7:$AC$1006,"Income",'P&L Dump'!$AD$7:$AD$1006,$A9),0) -> 0 | J9: =IFERROR(SUMIFS(INDEX('P&L Dump'!$B$7:$Z$1006,0,MATCH(J$4,'P&L Dump'!$B$5:$Z$5,0)),'P&L Dump'!$AC$7:$AC$1006,"Income",'P&L Dump'!$AD$7:$AD$1006,$A9),0) -> 0 | ... N9: =IFERROR(SUMIFS(INDEX('P&L Dump'!$B$7:$Z$1006,0,MATCH(N$4,'P&L Dump'!$B$5:$Z$5,0)),'P&L Dump'!$AC$7:$AC$1006,"Income",'P&L Dump'!$AD$7:$AD$1006,$A9),0) -> 0 | O9: =SUM(C9:N9) -> 0
A10: =Settings!$A$14 -> Video | C10: =IFERROR(SUMIFS(INDEX('P&L Dump'!$B$7:$Z$1006,0,MATCH(C$4,'P&L Dump'!$B$5:$Z$5,0)),'P&L Dump'!$AC$7:$AC$1006,"Income",'P&L Dump'!$AD$7:$AD$1006,$A10),0) -> 0 | D10: =IFERROR(SUMIFS(INDEX('P&L Dump'!$B$7:$Z$1006,0,MATCH(D$4,'P&L Dump'!$B$5:$Z$5,0)),'P&L Dump'!$AC$7:$AC$1006,"Income",'P&L Dump'!$AD$7:$AD$1006,$A10),0) -> 0 | E10: =IFERROR(SUMIFS(INDEX('P&L Dump'!$B$7:$Z$1006,0,MATCH(E$4,'P&L Dump'!$B$5:$Z$5,0)),'P&L Dump'!$AC$7:$AC$1006,"Income",'P&L Dump'!$AD$7:$AD$1006,$A10),0) -> 0 | F10: =IFERROR(SUMIFS(INDEX('P&L Dump'!$B$7:$Z$1006,0,MATCH(F$4,'P&L Dump'!$B$5:$Z$5,0)),'P&L Dump'!$AC$7:$AC$1006,"Income",'P&L Dump'!$AD$7:$AD$1006,$A10),0) -> 0 | G10: =IFERROR(SUMIFS(INDEX('P&L Dump'!$B$7:$Z$1006,0,MATCH(G$4,'P&L Dump'!$B$5:$Z$5,0)),'P&L Dump'!$AC$7:$AC$1006,"Income",'P&L Dump'!$AD$7:$AD$1006,$A10),0) -> 0 | H10: =IFERROR(SUMIFS(INDEX('P&L Dump'!$B$7:$Z$1006,0,MATCH(H$4,'P&L Dump'!$B$5:$Z$5,0)),'P&L Dump'!$AC$7:$AC$1006,"Income",'P&L Dump'!$AD$7:$AD$1006,$A10),0) -> 0 | I10: =IFERROR(SUMIFS(INDEX('P&L Dump'!$B$7:$Z$1006,0,MATCH(I$4,'P&L Dump'!$B$5:$Z$5,0)),'P&L Dump'!$AC$7:$AC$1006,"Income",'P&L Dump'!$AD$7:$AD$1006,$A10),0) -> 0 | J10: =IFERROR(SUMIFS(INDEX('P&L Dump'!$B$7:$Z$1006,0,MATCH(J$4,'P&L Dump'!$B$5:$Z$5,0)),'P&L Dump'!$AC$7:$AC$1006,"Income",'P&L Dump'!$AD$7:$AD$1006,$A10),0) -> 0 | ... N10: =IFERROR(SUMIFS(INDEX('P&L Dump'!$B$7:$Z$1006,0,MATCH(N$4,'P&L Dump'!$B$5:$Z$5,0)),'P&L Dump'!$AC$7:$AC$1006,"Income",'P&L Dump'!$AD$7:$AD$1006,$A10),0) -> 0 | O10: =SUM(C10:N10) -> 0
A11: =Settings!$A$15 -> Consulting | C11: =IFERROR(SUMIFS(INDEX('P&L Dump'!$B$7:$Z$1006,0,MATCH(C$4,'P&L Dump'!$B$5:$Z$5,0)),'P&L Dump'!$AC$7:$AC$1006,"Income",'P&L Dump'!$AD$7:$AD$1006,$A11),0) -> 0 | D11: =IFERROR(SUMIFS(INDEX('P&L Dump'!$B$7:$Z$1006,0,MATCH(D$4,'P&L Dump'!$B$5:$Z$5,0)),'P&L Dump'!$AC$7:$AC$1006,"Income",'P&L Dump'!$AD$7:$AD$1006,$A11),0) -> 0 | E11: =IFERROR(SUMIFS(INDEX('P&L Dump'!$B$7:$Z$1006,0,MATCH(E$4,'P&L Dump'!$B$5:$Z$5,0)),'P&L Dump'!$AC$7:$AC$1006,"Income",'P&L Dump'!$AD$7:$AD$1006,$A11),0) -> 0 | F11: =IFERROR(SUMIFS(INDEX('P&L Dump'!$B$7:$Z$1006,0,MATCH(F$4,'P&L Dump'!$B$5:$Z$5,0)),'P&L Dump'!$AC$7:$AC$1006,"Income",'P&L Dump'!$AD$7:$AD$1006,$A11),0) -> 0 | G11: =IFERROR(SUMIFS(INDEX('P&L Dump'!$B$7:$Z$1006,0,MATCH(G$4,'P&L Dump'!$B$5:$Z$5,0)),'P&L Dump'!$AC$7:$AC$1006,"Income",'P&L Dump'!$AD$7:$AD$1006,$A11),0) -> 0 | H11: =IFERROR(SUMIFS(INDEX('P&L Dump'!$B$7:$Z$1006,0,MATCH(H$4,'P&L Dump'!$B$5:$Z$5,0)),'P&L Dump'!$AC$7:$AC$1006,"Income",'P&L Dump'!$AD$7:$AD$1006,$A11),0) -> 0 | I11: =IFERROR(SUMIFS(INDEX('P&L Dump'!$B$7:$Z$1006,0,MATCH(I$4,'P&L Dump'!$B$5:$Z$5,0)),'P&L Dump'!$AC$7:$AC$1006,"Income",'P&L Dump'!$AD$7:$AD$1006,$A11),0) -> 0 | J11: =IFERROR(SUMIFS(INDEX('P&L Dump'!$B$7:$Z$1006,0,MATCH(J$4,'P&L Dump'!$B$5:$Z$5,0)),'P&L Dump'!$AC$7:$AC$1006,"Income",'P&L Dump'!$AD$7:$AD$1006,$A11),0) -> 0 | ... N11: =IFERROR(SUMIFS(INDEX('P&L Dump'!$B$7:$Z$1006,0,MATCH(N$4,'P&L Dump'!$B$5:$Z$5,0)),'P&L Dump'!$AC$7:$AC$1006,"Income",'P&L Dump'!$AD$7:$AD$1006,$A11),0) -> 0 | O11: =SUM(C11:N11) -> 0
A12: =Settings!$A$16 -> Integration | C12: =IFERROR(SUMIFS(INDEX('P&L Dump'!$B$7:$Z$1006,0,MATCH(C$4,'P&L Dump'!$B$5:$Z$5,0)),'P&L Dump'!$AC$7:$AC$1006,"Income",'P&L Dump'!$AD$7:$AD$1006,$A12),0) -> 0 | D12: =IFERROR(SUMIFS(INDEX('P&L Dump'!$B$7:$Z$1006,0,MATCH(D$4,'P&L Dump'!$B$5:$Z$5,0)),'P&L Dump'!$AC$7:$AC$1006,"Income",'P&L Dump'!$AD$7:$AD$1006,$A12),0) -> 0 | E12: =IFERROR(SUMIFS(INDEX('P&L Dump'!$B$7:$Z$1006,0,MATCH(E$4,'P&L Dump'!$B$5:$Z$5,0)),'P&L Dump'!$AC$7:$AC$1006,"Income",'P&L Dump'!$AD$7:$AD$1006,$A12),0) -> 0 | F12: =IFERROR(SUMIFS(INDEX('P&L Dump'!$B$7:$Z$1006,0,MATCH(F$4,'P&L Dump'!$B$5:$Z$5,0)),'P&L Dump'!$AC$7:$AC$1006,"Income",'P&L Dump'!$AD$7:$AD$1006,$A12),0) -> 0 | G12: =IFERROR(SUMIFS(INDEX('P&L Dump'!$B$7:$Z$1006,0,MATCH(G$4,'P&L Dump'!$B$5:$Z$5,0)),'P&L Dump'!$AC$7:$AC$1006,"Income",'P&L Dump'!$AD$7:$AD$1006,$A12),0) -> 0 | H12: =IFERROR(SUMIFS(INDEX('P&L Dump'!$B$7:$Z$1006,0,MATCH(H$4,'P&L Dump'!$B$5:$Z$5,0)),'P&L Dump'!$AC$7:$AC$1006,"Income",'P&L Dump'!$AD$7:$AD$1006,$A12),0) -> 0 | I12: =IFERROR(SUMIFS(INDEX('P&L Dump'!$B$7:$Z$1006,0,MATCH(I$4,'P&L Dump'!$B$5:$Z$5,0)),'P&L Dump'!$AC$7:$AC$1006,"Income",'P&L Dump'!$AD$7:$AD$1006,$A12),0) -> 0 | J12: =IFERROR(SUMIFS(INDEX('P&L Dump'!$B$7:$Z$1006,0,MATCH(J$4,'P&L Dump'!$B$5:$Z$5,0)),'P&L Dump'!$AC$7:$AC$1006,"Income",'P&L Dump'!$AD$7:$AD$1006,$A12),0) -> 0 | ... N12: =IFERROR(SUMIFS(INDEX('P&L Dump'!$B$7:$Z$1006,0,MATCH(N$4,'P&L Dump'!$B$5:$Z$5,0)),'P&L Dump'!$AC$7:$AC$1006,"Income",'P&L Dump'!$AD$7:$AD$1006,$A12),0) -> 0 | O12: =SUM(C12:N12) -> 0
A13: =Settings!$A$17 -> Admin | C13: =IFERROR(SUMIFS(INDEX('P&L Dump'!$B$7:$Z$1006,0,MATCH(C$4,'P&L Dump'!$B$5:$Z$5,0)),'P&L Dump'!$AC$7:$AC$1006,"Income",'P&L Dump'!$AD$7:$AD$1006,$A13),0) -> 0 | D13: =IFERROR(SUMIFS(INDEX('P&L Dump'!$B$7:$Z$1006,0,MATCH(D$4,'P&L Dump'!$B$5:$Z$5,0)),'P&L Dump'!$AC$7:$AC$1006,"Income",'P&L Dump'!$AD$7:$AD$1006,$A13),0) -> 0 | E13: =IFERROR(SUMIFS(INDEX('P&L Dump'!$B$7:$Z$1006,0,MATCH(E$4,'P&L Dump'!$B$5:$Z$5,0)),'P&L Dump'!$AC$7:$AC$1006,"Income",'P&L Dump'!$AD$7:$AD$1006,$A13),0) -> 0 | F13: =IFERROR(SUMIFS(INDEX('P&L Dump'!$B$7:$Z$1006,0,MATCH(F$4,'P&L Dump'!$B$5:$Z$5,0)),'P&L Dump'!$AC$7:$AC$1006,"Income",'P&L Dump'!$AD$7:$AD$1006,$A13),0) -> 0 | G13: =IFERROR(SUMIFS(INDEX('P&L Dump'!$B$7:$Z$1006,0,MATCH(G$4,'P&L Dump'!$B$5:$Z$5,0)),'P&L Dump'!$AC$7:$AC$1006,"Income",'P&L Dump'!$AD$7:$AD$1006,$A13),0) -> 0 | H13: =IFERROR(SUMIFS(INDEX('P&L Dump'!$B$7:$Z$1006,0,MATCH(H$4,'P&L Dump'!$B$5:$Z$5,0)),'P&L Dump'!$AC$7:$AC$1006,"Income",'P&L Dump'!$AD$7:$AD$1006,$A13),0) -> 0 | I13: =IFERROR(SUMIFS(INDEX('P&L Dump'!$B$7:$Z$1006,0,MATCH(I$4,'P&L Dump'!$B$5:$Z$5,0)),'P&L Dump'!$AC$7:$AC$1006,"Income",'P&L Dump'!$AD$7:$AD$1006,$A13),0) -> 0 | J13: =IFERROR(SUMIFS(INDEX('P&L Dump'!$B$7:$Z$1006,0,MATCH(J$4,'P&L Dump'!$B$5:$Z$5,0)),'P&L Dump'!$AC$7:$AC$1006,"Income",'P&L Dump'!$AD$7:$AD$1006,$A13),0) -> 0 | ... N13: =IFERROR(SUMIFS(INDEX('P&L Dump'!$B$7:$Z$1006,0,MATCH(N$4,'P&L Dump'!$B$5:$Z$5,0)),'P&L Dump'!$AC$7:$AC$1006,"Income",'P&L Dump'!$AD$7:$AD$1006,$A13),0) -> 0 | O13: =SUM(C13:N13) -> 0
A14: =Settings!$A$18 -> Unallocated | C14: =IFERROR(SUMIFS(INDEX('P&L Dump'!$B$7:$Z$1006,0,MATCH(C$4,'P&L Dump'!$B$5:$Z$5,0)),'P&L Dump'!$AC$7:$AC$1006,"Income",'P&L Dump'!$AD$7:$AD$1006,$A14),0) -> 0 | D14: =IFERROR(SUMIFS(INDEX('P&L Dump'!$B$7:$Z$1006,0,MATCH(D$4,'P&L Dump'!$B$5:$Z$5,0)),'P&L Dump'!$AC$7:$AC$1006,"Income",'P&L Dump'!$AD$7:$AD$1006,$A14),0) -> 0 | E14: =IFERROR(SUMIFS(INDEX('P&L Dump'!$B$7:$Z$1006,0,MATCH(E$4,'P&L Dump'!$B$5:$Z$5,0)),'P&L Dump'!$AC$7:$AC$1006,"Income",'P&L Dump'!$AD$7:$AD$1006,$A14),0) -> 0 | F14: =IFERROR(SUMIFS(INDEX('P&L Dump'!$B$7:$Z$1006,0,MATCH(F$4,'P&L Dump'!$B$5:$Z$5,0)),'P&L Dump'!$AC$7:$AC$1006,"Income",'P&L Dump'!$AD$7:$AD$1006,$A14),0) -> 0 | G14: =IFERROR(SUMIFS(INDEX('P&L Dump'!$B$7:$Z$1006,0,MATCH(G$4,'P&L Dump'!$B$5:$Z$5,0)),'P&L Dump'!$AC$7:$AC$1006,"Income",'P&L Dump'!$AD$7:$AD$1006,$A14),0) -> 0 | H14: =IFERROR(SUMIFS(INDEX('P&L Dump'!$B$7:$Z$1006,0,MATCH(H$4,'P&L Dump'!$B$5:$Z$5,0)),'P&L Dump'!$AC$7:$AC$1006,"Income",'P&L Dump'!$AD$7:$AD$1006,$A14),0) -> 0 | I14: =IFERROR(SUMIFS(INDEX('P&L Dump'!$B$7:$Z$1006,0,MATCH(I$4,'P&L Dump'!$B$5:$Z$5,0)),'P&L Dump'!$AC$7:$AC$1006,"Income",'P&L Dump'!$AD$7:$AD$1006,$A14),0) -> 0 | J14: =IFERROR(SUMIFS(INDEX('P&L Dump'!$B$7:$Z$1006,0,MATCH(J$4,'P&L Dump'!$B$5:$Z$5,0)),'P&L Dump'!$AC$7:$AC$1006,"Income",'P&L Dump'!$AD$7:$AD$1006,$A14),0) -> 0 | ... N14: =IFERROR(SUMIFS(INDEX('P&L Dump'!$B$7:$Z$1006,0,MATCH(N$4,'P&L Dump'!$B$5:$Z$5,0)),'P&L Dump'!$AC$7:$AC$1006,"Income",'P&L Dump'!$AD$7:$AD$1006,$A14),0) -> 0 | O14: =SUM(C14:N14) -> 0
A15: Total | C15: =SUM(C8:C14) -> 0 | D15: =SUM(D8:D14) -> 0 | E15: =SUM(E8:E14) -> 0 | F15: =SUM(F8:F14) -> 0 | G15: =SUM(G8:G14) -> 0 | H15: =SUM(H8:H14) -> 0 | I15: =SUM(I8:I14) -> 0 | J15: =SUM(J8:J14) -> 0 | ... O15: =SUM(O8:O14) -> 0
A17: Backlog | B17: Signed. Zoho Closed Won after the last P&L month, plus Adjustments
A18: =Settings!$A$12 -> Onsite | C18: =SUMIFS('Zoho Dump'!$X$8:$X$3007,'Zoho Dump'!$P$8:$P$3007,$A18,'Zoho Dump'!$W$8:$W$3007,C$4,'Zoho Dump'!$T$8:$T$3007,"Backlog")+SUMIFS(Adjustments!$K$8:$K$207,Adjustments!$A$8:$A$207,$A18,Adjustments!$J$8:$J$207,C$4,Adjustments!$H$8:$H$207,"Backlog") -> 0 | D18: =SUMIFS('Zoho Dump'!$X$8:$X$3007,'Zoho Dump'!$P$8:$P$3007,$A18,'Zoho Dump'!$W$8:$W$3007,D$4,'Zoho Dump'!$T$8:$T$3007,"Backlog")+SUMIFS(Adjustments!$K$8:$K$207,Adjustments!$A$8:$A$207,$A18,Adjustments!$J$8:$J$207,D$4,Adjustments!$H$8:$H$207,"Backlog") -> 0 | E18: =SUMIFS('Zoho Dump'!$X$8:$X$3007,'Zoho Dump'!$P$8:$P$3007,$A18,'Zoho Dump'!$W$8:$W$3007,E$4,'Zoho Dump'!$T$8:$T$3007,"Backlog")+SUMIFS(Adjustments!$K$8:$K$207,Adjustments!$A$8:$A$207,$A18,Adjustments!$J$8:$J$207,E$4,Adjustments!$H$8:$H$207,"Backlog") -> 0 | F18: =SUMIFS('Zoho Dump'!$X$8:$X$3007,'Zoho Dump'!$P$8:$P$3007,$A18,'Zoho Dump'!$W$8:$W$3007,F$4,'Zoho Dump'!$T$8:$T$3007,"Backlog")+SUMIFS(Adjustments!$K$8:$K$207,Adjustments!$A$8:$A$207,$A18,Adjustments!$J$8:$J$207,F$4,Adjustments!$H$8:$H$207,"Backlog") -> 17000 | G18: =SUMIFS('Zoho Dump'!$X$8:$X$3007,'Zoho Dump'!$P$8:$P$3007,$A18,'Zoho Dump'!$W$8:$W$3007,G$4,'Zoho Dump'!$T$8:$T$3007,"Backlog")+SUMIFS(Adjustments!$K$8:$K$207,Adjustments!$A$8:$A$207,$A18,Adjustments!$J$8:$J$207,G$4,Adjustments!$H$8:$H$207,"Backlog") -> 0 | H18: =SUMIFS('Zoho Dump'!$X$8:$X$3007,'Zoho Dump'!$P$8:$P$3007,$A18,'Zoho Dump'!$W$8:$W$3007,H$4,'Zoho Dump'!$T$8:$T$3007,"Backlog")+SUMIFS(Adjustments!$K$8:$K$207,Adjustments!$A$8:$A$207,$A18,Adjustments!$J$8:$J$207,H$4,Adjustments!$H$8:$H$207,"Backlog") -> 0 | I18: =SUMIFS('Zoho Dump'!$X$8:$X$3007,'Zoho Dump'!$P$8:$P$3007,$A18,'Zoho Dump'!$W$8:$W$3007,I$4,'Zoho Dump'!$T$8:$T$3007,"Backlog")+SUMIFS(Adjustments!$K$8:$K$207,Adjustments!$A$8:$A$207,$A18,Adjustments!$J$8:$J$207,I$4,Adjustments!$H$8:$H$207,"Backlog") -> 0 | J18: =SUMIFS('Zoho Dump'!$X$8:$X$3007,'Zoho Dump'!$P$8:$P$3007,$A18,'Zoho Dump'!$W$8:$W$3007,J$4,'Zoho Dump'!$T$8:$T$3007,"Backlog")+SUMIFS(Adjustments!$K$8:$K$207,Adjustments!$A$8:$A$207,$A18,Adjustments!$J$8:$J$207,J$4,Adjustments!$H$8:$H$207,"Backlog") -> 0 | ... N18: =SUMIFS('Zoho Dump'!$X$8:$X$3007,'Zoho Dump'!$P$8:$P$3007,$A18,'Zoho Dump'!$W$8:$W$3007,N$4,'Zoho Dump'!$T$8:$T$3007,"Backlog")+SUMIFS(Adjustments!$K$8:$K$207,Adjustments!$A$8:$A$207,$A18,Adjustments!$J$8:$J$207,N$4,Adjustments!$H$8:$H$207,"Backlog") -> 0 | O18: =SUM(C18:N18) -> 17000
A19: =Settings!$A$13 -> Production | C19: =SUMIFS('Zoho Dump'!$X$8:$X$3007,'Zoho Dump'!$P$8:$P$3007,$A19,'Zoho Dump'!$W$8:$W$3007,C$4,'Zoho Dump'!$T$8:$T$3007,"Backlog")+SUMIFS(Adjustments!$K$8:$K$207,Adjustments!$A$8:$A$207,$A19,Adjustments!$J$8:$J$207,C$4,Adjustments!$H$8:$H$207,"Backlog") -> 0 | D19: =SUMIFS('Zoho Dump'!$X$8:$X$3007,'Zoho Dump'!$P$8:$P$3007,$A19,'Zoho Dump'!$W$8:$W$3007,D$4,'Zoho Dump'!$T$8:$T$3007,"Backlog")+SUMIFS(Adjustments!$K$8:$K$207,Adjustments!$A$8:$A$207,$A19,Adjustments!$J$8:$J$207,D$4,Adjustments!$H$8:$H$207,"Backlog") -> 0 | E19: =SUMIFS('Zoho Dump'!$X$8:$X$3007,'Zoho Dump'!$P$8:$P$3007,$A19,'Zoho Dump'!$W$8:$W$3007,E$4,'Zoho Dump'!$T$8:$T$3007,"Backlog")+SUMIFS(Adjustments!$K$8:$K$207,Adjustments!$A$8:$A$207,$A19,Adjustments!$J$8:$J$207,E$4,Adjustments!$H$8:$H$207,"Backlog") -> 0 | F19: =SUMIFS('Zoho Dump'!$X$8:$X$3007,'Zoho Dump'!$P$8:$P$3007,$A19,'Zoho Dump'!$W$8:$W$3007,F$4,'Zoho Dump'!$T$8:$T$3007,"Backlog")+SUMIFS(Adjustments!$K$8:$K$207,Adjustments!$A$8:$A$207,$A19,Adjustments!$J$8:$J$207,F$4,Adjustments!$H$8:$H$207,"Backlog") -> 40626 | G19: =SUMIFS('Zoho Dump'!$X$8:$X$3007,'Zoho Dump'!$P$8:$P$3007,$A19,'Zoho Dump'!$W$8:$W$3007,G$4,'Zoho Dump'!$T$8:$T$3007,"Backlog")+SUMIFS(Adjustments!$K$8:$K$207,Adjustments!$A$8:$A$207,$A19,Adjustments!$J$8:$J$207,G$4,Adjustments!$H$8:$H$207,"Backlog") -> 13553 | H19: =SUMIFS('Zoho Dump'!$X$8:$X$3007,'Zoho Dump'!$P$8:$P$3007,$A19,'Zoho Dump'!$W$8:$W$3007,H$4,'Zoho Dump'!$T$8:$T$3007,"Backlog")+SUMIFS(Adjustments!$K$8:$K$207,Adjustments!$A$8:$A$207,$A19,Adjustments!$J$8:$J$207,H$4,Adjustments!$H$8:$H$207,"Backlog") -> 2881 | I19: =SUMIFS('Zoho Dump'!$X$8:$X$3007,'Zoho Dump'!$P$8:$P$3007,$A19,'Zoho Dump'!$W$8:$W$3007,I$4,'Zoho Dump'!$T$8:$T$3007,"Backlog")+SUMIFS(Adjustments!$K$8:$K$207,Adjustments!$A$8:$A$207,$A19,Adjustments!$J$8:$J$207,I$4,Adjustments!$H$8:$H$207,"Backlog") -> 0 | J19: =SUMIFS('Zoho Dump'!$X$8:$X$3007,'Zoho Dump'!$P$8:$P$3007,$A19,'Zoho Dump'!$W$8:$W$3007,J$4,'Zoho Dump'!$T$8:$T$3007,"Backlog")+SUMIFS(Adjustments!$K$8:$K$207,Adjustments!$A$8:$A$207,$A19,Adjustments!$J$8:$J$207,J$4,Adjustments!$H$8:$H$207,"Backlog") -> 0 | ... N19: =SUMIFS('Zoho Dump'!$X$8:$X$3007,'Zoho Dump'!$P$8:$P$3007,$A19,'Zoho Dump'!$W$8:$W$3007,N$4,'Zoho Dump'!$T$8:$T$3007,"Backlog")+SUMIFS(Adjustments!$K$8:$K$207,Adjustments!$A$8:$A$207,$A19,Adjustments!$J$8:$J$207,N$4,Adjustments!$H$8:$H$207,"Backlog") -> 0 | O19: =SUM(C19:N19) -> 57060
A20: =Settings!$A$14 -> Video | C20: =SUMIFS('Zoho Dump'!$X$8:$X$3007,'Zoho Dump'!$P$8:$P$3007,$A20,'Zoho Dump'!$W$8:$W$3007,C$4,'Zoho Dump'!$T$8:$T$3007,"Backlog")+SUMIFS(Adjustments!$K$8:$K$207,Adjustments!$A$8:$A$207,$A20,Adjustments!$J$8:$J$207,C$4,Adjustments!$H$8:$H$207,"Backlog") -> 0 | D20: =SUMIFS('Zoho Dump'!$X$8:$X$3007,'Zoho Dump'!$P$8:$P$3007,$A20,'Zoho Dump'!$W$8:$W$3007,D$4,'Zoho Dump'!$T$8:$T$3007,"Backlog")+SUMIFS(Adjustments!$K$8:$K$207,Adjustments!$A$8:$A$207,$A20,Adjustments!$J$8:$J$207,D$4,Adjustments!$H$8:$H$207,"Backlog") -> 0 | E20: =SUMIFS('Zoho Dump'!$X$8:$X$3007,'Zoho Dump'!$P$8:$P$3007,$A20,'Zoho Dump'!$W$8:$W$3007,E$4,'Zoho Dump'!$T$8:$T$3007,"Backlog")+SUMIFS(Adjustments!$K$8:$K$207,Adjustments!$A$8:$A$207,$A20,Adjustments!$J$8:$J$207,E$4,Adjustments!$H$8:$H$207,"Backlog") -> 0 | F20: =SUMIFS('Zoho Dump'!$X$8:$X$3007,'Zoho Dump'!$P$8:$P$3007,$A20,'Zoho Dump'!$W$8:$W$3007,F$4,'Zoho Dump'!$T$8:$T$3007,"Backlog")+SUMIFS(Adjustments!$K$8:$K$207,Adjustments!$A$8:$A$207,$A20,Adjustments!$J$8:$J$207,F$4,Adjustments!$H$8:$H$207,"Backlog") -> 0 | G20: =SUMIFS('Zoho Dump'!$X$8:$X$3007,'Zoho Dump'!$P$8:$P$3007,$A20,'Zoho Dump'!$W$8:$W$3007,G$4,'Zoho Dump'!$T$8:$T$3007,"Backlog")+SUMIFS(Adjustments!$K$8:$K$207,Adjustments!$A$8:$A$207,$A20,Adjustments!$J$8:$J$207,G$4,Adjustments!$H$8:$H$207,"Backlog") -> 11342 | H20: =SUMIFS('Zoho Dump'!$X$8:$X$3007,'Zoho Dump'!$P$8:$P$3007,$A20,'Zoho Dump'!$W$8:$W$3007,H$4,'Zoho Dump'!$T$8:$T$3007,"Backlog")+SUMIFS(Adjustments!$K$8:$K$207,Adjustments!$A$8:$A$207,$A20,Adjustments!$J$8:$J$207,H$4,Adjustments!$H$8:$H$207,"Backlog") -> 0 | I20: =SUMIFS('Zoho Dump'!$X$8:$X$3007,'Zoho Dump'!$P$8:$P$3007,$A20,'Zoho Dump'!$W$8:$W$3007,I$4,'Zoho Dump'!$T$8:$T$3007,"Backlog")+SUMIFS(Adjustments!$K$8:$K$207,Adjustments!$A$8:$A$207,$A20,Adjustments!$J$8:$J$207,I$4,Adjustments!$H$8:$H$207,"Backlog") -> 0 | J20: =SUMIFS('Zoho Dump'!$X$8:$X$3007,'Zoho Dump'!$P$8:$P$3007,$A20,'Zoho Dump'!$W$8:$W$3007,J$4,'Zoho Dump'!$T$8:$T$3007,"Backlog")+SUMIFS(Adjustments!$K$8:$K$207,Adjustments!$A$8:$A$207,$A20,Adjustments!$J$8:$J$207,J$4,Adjustments!$H$8:$H$207,"Backlog") -> 0 | ... N20: =SUMIFS('Zoho Dump'!$X$8:$X$3007,'Zoho Dump'!$P$8:$P$3007,$A20,'Zoho Dump'!$W$8:$W$3007,N$4,'Zoho Dump'!$T$8:$T$3007,"Backlog")+SUMIFS(Adjustments!$K$8:$K$207,Adjustments!$A$8:$A$207,$A20,Adjustments!$J$8:$J$207,N$4,Adjustments!$H$8:$H$207,"Backlog") -> 0 | O20: =SUM(C20:N20) -> 11342
A21: =Settings!$A$15 -> Consulting | C21: =SUMIFS('Zoho Dump'!$X$8:$X$3007,'Zoho Dump'!$P$8:$P$3007,$A21,'Zoho Dump'!$W$8:$W$3007,C$4,'Zoho Dump'!$T$8:$T$3007,"Backlog")+SUMIFS(Adjustments!$K$8:$K$207,Adjustments!$A$8:$A$207,$A21,Adjustments!$J$8:$J$207,C$4,Adjustments!$H$8:$H$207,"Backlog") -> 0 | D21: =SUMIFS('Zoho Dump'!$X$8:$X$3007,'Zoho Dump'!$P$8:$P$3007,$A21,'Zoho Dump'!$W$8:$W$3007,D$4,'Zoho Dump'!$T$8:$T$3007,"Backlog")+SUMIFS(Adjustments!$K$8:$K$207,Adjustments!$A$8:$A$207,$A21,Adjustments!$J$8:$J$207,D$4,Adjustments!$H$8:$H$207,"Backlog") -> 0 | E21: =SUMIFS('Zoho Dump'!$X$8:$X$3007,'Zoho Dump'!$P$8:$P$3007,$A21,'Zoho Dump'!$W$8:$W$3007,E$4,'Zoho Dump'!$T$8:$T$3007,"Backlog")+SUMIFS(Adjustments!$K$8:$K$207,Adjustments!$A$8:$A$207,$A21,Adjustments!$J$8:$J$207,E$4,Adjustments!$H$8:$H$207,"Backlog") -> 0 | F21: =SUMIFS('Zoho Dump'!$X$8:$X$3007,'Zoho Dump'!$P$8:$P$3007,$A21,'Zoho Dump'!$W$8:$W$3007,F$4,'Zoho Dump'!$T$8:$T$3007,"Backlog")+SUMIFS(Adjustments!$K$8:$K$207,Adjustments!$A$8:$A$207,$A21,Adjustments!$J$8:$J$207,F$4,Adjustments!$H$8:$H$207,"Backlog") -> 0 | G21: =SUMIFS('Zoho Dump'!$X$8:$X$3007,'Zoho Dump'!$P$8:$P$3007,$A21,'Zoho Dump'!$W$8:$W$3007,G$4,'Zoho Dump'!$T$8:$T$3007,"Backlog")+SUMIFS(Adjustments!$K$8:$K$207,Adjustments!$A$8:$A$207,$A21,Adjustments!$J$8:$J$207,G$4,Adjustments!$H$8:$H$207,"Backlog") -> 0 | H21: =SUMIFS('Zoho Dump'!$X$8:$X$3007,'Zoho Dump'!$P$8:$P$3007,$A21,'Zoho Dump'!$W$8:$W$3007,H$4,'Zoho Dump'!$T$8:$T$3007,"Backlog")+SUMIFS(Adjustments!$K$8:$K$207,Adjustments!$A$8:$A$207,$A21,Adjustments!$J$8:$J$207,H$4,Adjustments!$H$8:$H$207,"Backlog") -> 0 | I21: =SUMIFS('Zoho Dump'!$X$8:$X$3007,'Zoho Dump'!$P$8:$P$3007,$A21,'Zoho Dump'!$W$8:$W$3007,I$4,'Zoho Dump'!$T$8:$T$3007,"Backlog")+SUMIFS(Adjustments!$K$8:$K$207,Adjustments!$A$8:$A$207,$A21,Adjustments!$J$8:$J$207,I$4,Adjustments!$H$8:$H$207,"Backlog") -> 0 | J21: =SUMIFS('Zoho Dump'!$X$8:$X$3007,'Zoho Dump'!$P$8:$P$3007,$A21,'Zoho Dump'!$W$8:$W$3007,J$4,'Zoho Dump'!$T$8:$T$3007,"Backlog")+SUMIFS(Adjustments!$K$8:$K$207,Adjustments!$A$8:$A$207,$A21,Adjustments!$J$8:$J$207,J$4,Adjustments!$H$8:$H$207,"Backlog") -> 0 | ... N21: =SUMIFS('Zoho Dump'!$X$8:$X$3007,'Zoho Dump'!$P$8:$P$3007,$A21,'Zoho Dump'!$W$8:$W$3007,N$4,'Zoho Dump'!$T$8:$T$3007,"Backlog")+SUMIFS(Adjustments!$K$8:$K$207,Adjustments!$A$8:$A$207,$A21,Adjustments!$J$8:$J$207,N$4,Adjustments!$H$8:$H$207,"Backlog") -> 0 | O21: =SUM(C21:N21) -> 0
A22: =Settings!$A$16 -> Integration | C22: =SUMIFS('Zoho Dump'!$X$8:$X$3007,'Zoho Dump'!$P$8:$P$3007,$A22,'Zoho Dump'!$W$8:$W$3007,C$4,'Zoho Dump'!$T$8:$T$3007,"Backlog")+SUMIFS(Adjustments!$K$8:$K$207,Adjustments!$A$8:$A$207,$A22,Adjustments!$J$8:$J$207,C$4,Adjustments!$H$8:$H$207,"Backlog") -> 0 | D22: =SUMIFS('Zoho Dump'!$X$8:$X$3007,'Zoho Dump'!$P$8:$P$3007,$A22,'Zoho Dump'!$W$8:$W$3007,D$4,'Zoho Dump'!$T$8:$T$3007,"Backlog")+SUMIFS(Adjustments!$K$8:$K$207,Adjustments!$A$8:$A$207,$A22,Adjustments!$J$8:$J$207,D$4,Adjustments!$H$8:$H$207,"Backlog") -> 0 | E22: =SUMIFS('Zoho Dump'!$X$8:$X$3007,'Zoho Dump'!$P$8:$P$3007,$A22,'Zoho Dump'!$W$8:$W$3007,E$4,'Zoho Dump'!$T$8:$T$3007,"Backlog")+SUMIFS(Adjustments!$K$8:$K$207,Adjustments!$A$8:$A$207,$A22,Adjustments!$J$8:$J$207,E$4,Adjustments!$H$8:$H$207,"Backlog") -> 0 | F22: =SUMIFS('Zoho Dump'!$X$8:$X$3007,'Zoho Dump'!$P$8:$P$3007,$A22,'Zoho Dump'!$W$8:$W$3007,F$4,'Zoho Dump'!$T$8:$T$3007,"Backlog")+SUMIFS(Adjustments!$K$8:$K$207,Adjustments!$A$8:$A$207,$A22,Adjustments!$J$8:$J$207,F$4,Adjustments!$H$8:$H$207,"Backlog") -> 0 | G22: =SUMIFS('Zoho Dump'!$X$8:$X$3007,'Zoho Dump'!$P$8:$P$3007,$A22,'Zoho Dump'!$W$8:$W$3007,G$4,'Zoho Dump'!$T$8:$T$3007,"Backlog")+SUMIFS(Adjustments!$K$8:$K$207,Adjustments!$A$8:$A$207,$A22,Adjustments!$J$8:$J$207,G$4,Adjustments!$H$8:$H$207,"Backlog") -> 0 | H22: =SUMIFS('Zoho Dump'!$X$8:$X$3007,'Zoho Dump'!$P$8:$P$3007,$A22,'Zoho Dump'!$W$8:$W$3007,H$4,'Zoho Dump'!$T$8:$T$3007,"Backlog")+SUMIFS(Adjustments!$K$8:$K$207,Adjustments!$A$8:$A$207,$A22,Adjustments!$J$8:$J$207,H$4,Adjustments!$H$8:$H$207,"Backlog") -> 0 | I22: =SUMIFS('Zoho Dump'!$X$8:$X$3007,'Zoho Dump'!$P$8:$P$3007,$A22,'Zoho Dump'!$W$8:$W$3007,I$4,'Zoho Dump'!$T$8:$T$3007,"Backlog")+SUMIFS(Adjustments!$K$8:$K$207,Adjustments!$A$8:$A$207,$A22,Adjustments!$J$8:$J$207,I$4,Adjustments!$H$8:$H$207,"Backlog") -> 0 | J22: =SUMIFS('Zoho Dump'!$X$8:$X$3007,'Zoho Dump'!$P$8:$P$3007,$A22,'Zoho Dump'!$W$8:$W$3007,J$4,'Zoho Dump'!$T$8:$T$3007,"Backlog")+SUMIFS(Adjustments!$K$8:$K$207,Adjustments!$A$8:$A$207,$A22,Adjustments!$J$8:$J$207,J$4,Adjustments!$H$8:$H$207,"Backlog") -> 0 | ... N22: =SUMIFS('Zoho Dump'!$X$8:$X$3007,'Zoho Dump'!$P$8:$P$3007,$A22,'Zoho Dump'!$W$8:$W$3007,N$4,'Zoho Dump'!$T$8:$T$3007,"Backlog")+SUMIFS(Adjustments!$K$8:$K$207,Adjustments!$A$8:$A$207,$A22,Adjustments!$J$8:$J$207,N$4,Adjustments!$H$8:$H$207,"Backlog") -> 0 | O22: =SUM(C22:N22) -> 0
A23: =Settings!$A$17 -> Admin | C23: =SUMIFS('Zoho Dump'!$X$8:$X$3007,'Zoho Dump'!$P$8:$P$3007,$A23,'Zoho Dump'!$W$8:$W$3007,C$4,'Zoho Dump'!$T$8:$T$3007,"Backlog")+SUMIFS(Adjustments!$K$8:$K$207,Adjustments!$A$8:$A$207,$A23,Adjustments!$J$8:$J$207,C$4,Adjustments!$H$8:$H$207,"Backlog") -> 0 | D23: =SUMIFS('Zoho Dump'!$X$8:$X$3007,'Zoho Dump'!$P$8:$P$3007,$A23,'Zoho Dump'!$W$8:$W$3007,D$4,'Zoho Dump'!$T$8:$T$3007,"Backlog")+SUMIFS(Adjustments!$K$8:$K$207,Adjustments!$A$8:$A$207,$A23,Adjustments!$J$8:$J$207,D$4,Adjustments!$H$8:$H$207,"Backlog") -> 0 | E23: =SUMIFS('Zoho Dump'!$X$8:$X$3007,'Zoho Dump'!$P$8:$P$3007,$A23,'Zoho Dump'!$W$8:$W$3007,E$4,'Zoho Dump'!$T$8:$T$3007,"Backlog")+SUMIFS(Adjustments!$K$8:$K$207,Adjustments!$A$8:$A$207,$A23,Adjustments!$J$8:$J$207,E$4,Adjustments!$H$8:$H$207,"Backlog") -> 0 | F23: =SUMIFS('Zoho Dump'!$X$8:$X$3007,'Zoho Dump'!$P$8:$P$3007,$A23,'Zoho Dump'!$W$8:$W$3007,F$4,'Zoho Dump'!$T$8:$T$3007,"Backlog")+SUMIFS(Adjustments!$K$8:$K$207,Adjustments!$A$8:$A$207,$A23,Adjustments!$J$8:$J$207,F$4,Adjustments!$H$8:$H$207,"Backlog") -> 0 | G23: =SUMIFS('Zoho Dump'!$X$8:$X$3007,'Zoho Dump'!$P$8:$P$3007,$A23,'Zoho Dump'!$W$8:$W$3007,G$4,'Zoho Dump'!$T$8:$T$3007,"Backlog")+SUMIFS(Adjustments!$K$8:$K$207,Adjustments!$A$8:$A$207,$A23,Adjustments!$J$8:$J$207,G$4,Adjustments!$H$8:$H$207,"Backlog") -> 0 | H23: =SUMIFS('Zoho Dump'!$X$8:$X$3007,'Zoho Dump'!$P$8:$P$3007,$A23,'Zoho Dump'!$W$8:$W$3007,H$4,'Zoho Dump'!$T$8:$T$3007,"Backlog")+SUMIFS(Adjustments!$K$8:$K$207,Adjustments!$A$8:$A$207,$A23,Adjustments!$J$8:$J$207,H$4,Adjustments!$H$8:$H$207,"Backlog") -> 0 | I23: =SUMIFS('Zoho Dump'!$X$8:$X$3007,'Zoho Dump'!$P$8:$P$3007,$A23,'Zoho Dump'!$W$8:$W$3007,I$4,'Zoho Dump'!$T$8:$T$3007,"Backlog")+SUMIFS(Adjustments!$K$8:$K$207,Adjustments!$A$8:$A$207,$A23,Adjustments!$J$8:$J$207,I$4,Adjustments!$H$8:$H$207,"Backlog") -> 0 | J23: =SUMIFS('Zoho Dump'!$X$8:$X$3007,'Zoho Dump'!$P$8:$P$3007,$A23,'Zoho Dump'!$W$8:$W$3007,J$4,'Zoho Dump'!$T$8:$T$3007,"Backlog")+SUMIFS(Adjustments!$K$8:$K$207,Adjustments!$A$8:$A$207,$A23,Adjustments!$J$8:$J$207,J$4,Adjustments!$H$8:$H$207,"Backlog") -> 0 | ... N23: =SUMIFS('Zoho Dump'!$X$8:$X$3007,'Zoho Dump'!$P$8:$P$3007,$A23,'Zoho Dump'!$W$8:$W$3007,N$4,'Zoho Dump'!$T$8:$T$3007,"Backlog")+SUMIFS(Adjustments!$K$8:$K$207,Adjustments!$A$8:$A$207,$A23,Adjustments!$J$8:$J$207,N$4,Adjustments!$H$8:$H$207,"Backlog") -> 0 | O23: =SUM(C23:N23) -> 0
A24: =Settings!$A$18 -> Unallocated | C24: =SUMIFS('Zoho Dump'!$X$8:$X$3007,'Zoho Dump'!$P$8:$P$3007,$A24,'Zoho Dump'!$W$8:$W$3007,C$4,'Zoho Dump'!$T$8:$T$3007,"Backlog")+SUMIFS(Adjustments!$K$8:$K$207,Adjustments!$A$8:$A$207,$A24,Adjustments!$J$8:$J$207,C$4,Adjustments!$H$8:$H$207,"Backlog") -> 0 | D24: =SUMIFS('Zoho Dump'!$X$8:$X$3007,'Zoho Dump'!$P$8:$P$3007,$A24,'Zoho Dump'!$W$8:$W$3007,D$4,'Zoho Dump'!$T$8:$T$3007,"Backlog")+SUMIFS(Adjustments!$K$8:$K$207,Adjustments!$A$8:$A$207,$A24,Adjustments!$J$8:$J$207,D$4,Adjustments!$H$8:$H$207,"Backlog") -> 0 | E24: =SUMIFS('Zoho Dump'!$X$8:$X$3007,'Zoho Dump'!$P$8:$P$3007,$A24,'Zoho Dump'!$W$8:$W$3007,E$4,'Zoho Dump'!$T$8:$T$3007,"Backlog")+SUMIFS(Adjustments!$K$8:$K$207,Adjustments!$A$8:$A$207,$A24,Adjustments!$J$8:$J$207,E$4,Adjustments!$H$8:$H$207,"Backlog") -> 0 | F24: =SUMIFS('Zoho Dump'!$X$8:$X$3007,'Zoho Dump'!$P$8:$P$3007,$A24,'Zoho Dump'!$W$8:$W$3007,F$4,'Zoho Dump'!$T$8:$T$3007,"Backlog")+SUMIFS(Adjustments!$K$8:$K$207,Adjustments!$A$8:$A$207,$A24,Adjustments!$J$8:$J$207,F$4,Adjustments!$H$8:$H$207,"Backlog") -> 0 | G24: =SUMIFS('Zoho Dump'!$X$8:$X$3007,'Zoho Dump'!$P$8:$P$3007,$A24,'Zoho Dump'!$W$8:$W$3007,G$4,'Zoho Dump'!$T$8:$T$3007,"Backlog")+SUMIFS(Adjustments!$K$8:$K$207,Adjustments!$A$8:$A$207,$A24,Adjustments!$J$8:$J$207,G$4,Adjustments!$H$8:$H$207,"Backlog") -> 0 | H24: =SUMIFS('Zoho Dump'!$X$8:$X$3007,'Zoho Dump'!$P$8:$P$3007,$A24,'Zoho Dump'!$W$8:$W$3007,H$4,'Zoho Dump'!$T$8:$T$3007,"Backlog")+SUMIFS(Adjustments!$K$8:$K$207,Adjustments!$A$8:$A$207,$A24,Adjustments!$J$8:$J$207,H$4,Adjustments!$H$8:$H$207,"Backlog") -> 0 | I24: =SUMIFS('Zoho Dump'!$X$8:$X$3007,'Zoho Dump'!$P$8:$P$3007,$A24,'Zoho Dump'!$W$8:$W$3007,I$4,'Zoho Dump'!$T$8:$T$3007,"Backlog")+SUMIFS(Adjustments!$K$8:$K$207,Adjustments!$A$8:$A$207,$A24,Adjustments!$J$8:$J$207,I$4,Adjustments!$H$8:$H$207,"Backlog") -> 0 | J24: =SUMIFS('Zoho Dump'!$X$8:$X$3007,'Zoho Dump'!$P$8:$P$3007,$A24,'Zoho Dump'!$W$8:$W$3007,J$4,'Zoho Dump'!$T$8:$T$3007,"Backlog")+SUMIFS(Adjustments!$K$8:$K$207,Adjustments!$A$8:$A$207,$A24,Adjustments!$J$8:$J$207,J$4,Adjustments!$H$8:$H$207,"Backlog") -> 0 | ... N24: =SUMIFS('Zoho Dump'!$X$8:$X$3007,'Zoho Dump'!$P$8:$P$3007,$A24,'Zoho Dump'!$W$8:$W$3007,N$4,'Zoho Dump'!$T$8:$T$3007,"Backlog")+SUMIFS(Adjustments!$K$8:$K$207,Adjustments!$A$8:$A$207,$A24,Adjustments!$J$8:$J$207,N$4,Adjustments!$H$8:$H$207,"Backlog") -> 0 | O24: =SUM(C24:N24) -> 0
A25: Total | C25: =SUM(C18:C24) -> 0 | D25: =SUM(D18:D24) -> 0 | E25: =SUM(E18:E24) -> 0 | F25: =SUM(F18:F24) -> 57626 | G25: =SUM(G18:G24) -> 24895 | H25: =SUM(H18:H24) -> 2881 | I25: =SUM(I18:I24) -> 0 | J25: =SUM(J18:J24) -> 0 | ... O25: =SUM(O18:O24) -> 85402
A27: Pipeline (weighted) | B27: Open Zoho deals times stage probability, plus Adjustments
