Workbook

Sheet Summary
A1: Aware Super Seminar Room AV Upgrade (Project 2604704) - Cost vs Sell
A2: Complete AV Solutions bill INV41565 vs Aware Super invoice INV-10596. Source: Xero, Corporate Technology Services Pty Ltd, pulled 29 Sep 2026. Ex GST unless stated. Blue = hardcoded from Xero, black = formula, green = link to another tab, yellow = the number to confirm.
A4: 1. Headline | B4: Ex GST | C4: Inc GST | D4: Margin %
A5: Sell to Aware (INV-10596) | B5: ='Aware Invoice INV-10596'!C18 | C5: ='Aware Invoice INV-10596'!E18
A6: Cost billed so far by Complete AV (INV41565) | B6: ='Supplier Bill INV41565'!G47 | C6: ='Supplier Bill INV41565'!I47
A7: Gross profit on what is billed today | B7: =B5-B6 | D7: =IF(B5=0,0,B7/B5)
A8: Complete AV retention still to be billed | B8: =-'Supplier Bill INV41565'!G57 | C8: =-'Supplier Bill INV41565'!I57
A9: Gross profit after retention | B9: =B7-B8 | D9: =IF(B5=0,0,B9/B5)
A10: PO-00016899 (PO 2/2) to Complete AV, authorised, NOT yet billed, contents unconfirmed | B10: ='Section Margin'!C14 | C10: =ROUND(B10*1.1,2)
A11: Gross profit if PO 2/2 is all cost for this job | B11: =B9-B10 | D11: =IF(B5=0,0,B11/B5)
A12: Plain English: on paper the job makes about 21%. After the $4,848.68 retention it is 18.8%. If PO 2/2 ($17,700.52) is also cost for this job, the real margin is about 10%. Confirm PO 2/2 before calling this a 20% job.
A14: 2. Tracker figure $136,163 reconciles | B14: Ex GST | C14: Inc GST
A15: Bill total INV41565 | B15: ='Supplier Bill INV41565'!G47 | C15: ='Supplier Bill INV41565'!I47
A16: Less the four labour lines (23,320 + 7,196 + 6,561.80 + 1,064) | B16: ='Supplier Bill INV41565'!G71 | C16: ='Supplier Bill INV41565'!I71
A17: Materials portion = what the tracker calls 'Complete AV materials' | B17: =B15-B16 | C17: =C15-C16
A18: Tracker note | C18: 136163
A19: Difference (rounding only) | C19: =ROUND(C17-C18,0)
A20: Paying $136,163 this week is a PART payment of INV41565. The labour balance in C16 stays owing to Complete AV. Record it as a part payment in Xero so the balance stays visible.
A22: 3. Section margin (best-fit mapping, see Section Margin tab) | B22: Sell | C22: Cost | D22: Margin %
A23: ='Section Margin'!A5 | B23: ='Section Margin'!B5 | C23: ='Section Margin'!C5 | D23: ='Section Margin'!F5
A24: ='Section Margin'!A6 | B24: ='Section Margin'!B6 | C24: ='Section Margin'!C6 | D24: ='Section Margin'!F6
A25: ='Section Margin'!A7 | B25: ='Section Margin'!B7 | C25: ='Section Margin'!C7 | D25: ='Section Margin'!F7
A26: ='Section Margin'!A8 | B26: ='Section Margin'!B8 | C26: ='Section Margin'!C8 | D26: ='Section Margin'!F8
A27: ='Section Margin'!A9 | B27: ='Section Margin'!B9 | C27: ='Section Margin'!C9 | D27: ='Section Margin'!F9
A28: ='Section Margin'!A10 | B28: ='Section Margin'!B10 | C28: ='Section Margin'!C10 | D28: ='Section Margin'!F10
A29: Option A shows a small loss and the UE80 upgrade has no cost on this bill (probably PO 2/2). If the Sennheiser mics belong to Phase 2 instead of Option A, the loss moves to Phase 2. One of the two is priced at or below cost either way.
A31: 4. Variations (see Variations tab) | B31: Complete AV | C31: Aware | D31: Effect on CTS
A32: Net variations | B32: =Variations!B12 | C32: =Variations!C12 | D32: =Variations!E12
A33: Loss on the four ADDED items (sold below cost) | D33: =Variations!E14
A34: Kept on the three REMOVED items | D34: =Variations!E15
A35: Every variation was passed to Aware at exactly 85% (or 77%) of the supplier figure. That is a discount off cost, not a markup. The net is in CTS's favour only because the removals were bigger than the additions. Fix the method before the next Aware claim. Do not re-issue INV-10596 now; it would delay a $225k payment.
A37: 5. Cash timing | B37: Date | C37: Inc GST | D37: Note
A38: Complete AV bill INV41565 due | B38: 26 Sep 26 | C38: ='Supplier Bill INV41565'!I47 | D38: Already overdue at 29 Sep. Xero note says hold until Aware pays.
A39: Planned materials payment | B39: w/c 28 Sep 26 | C39: =C17 | D39: Part payment. Contradicts the Xero hold note, so make it a deliberate call.
A40: Aware invoice INV-10596 due | B40: 9 Oct 26 | C40: ='Aware Invoice INV-10596'!E18 | D40: Aware paid its last two invoices in 6-7 days but took the full 30 in June. Confirm it is in the Converga approval queue now.
A41: Days CTS is out of pocket if Aware pays on due date | C41: =DATE(2026,10,9)-DATE(2026,9,28)
A43: 6. Actions, in order
A44: 1. Open PO-00016899 (PO 2/2, $17,700.52) in Xero and confirm what it covers. If it is the UE80 upgrade, that line is sold for $12,042.88 against a $17,700.52 cost and the job is a 10% job, not 21%.
A45: 2. Confirm with Aware's Converga inbox that INV-10596 is received and in approval.
A46: 3. Ask Complete AV for the unit breakdown behind the three 'Removed' variation lines. None reconcile to whole units at the bill's prices.
...

Sheet Supplier Bill INV41565
A1: Complete AV Solutions Pty Ltd - Bill INV41565 (ex GST line detail from Xero)
A2: Bill date 1 Sep 26, due 26 Sep 26, status Authorised (unpaid). Xero note: 'Partial Equipment purchase & Services hire for 2604704 Aware Super Seminar Room Audio Upgrade [Q-12140v1 - PO-00016902] Hold off until payment received from aware'.
A3: Blue = hardcoded from Xero. Black = formula.
A5: Block | B5: Maps to Aware line | C5: Description | D5: Type | E5: Qty | F5: Unit price ex GST | G5: Line ex GST | H5: GST | I5: Line inc GST | J5: Xero account
A6: 1 Core install | B6: Phase 2 | C6: Crestron DM-NVX-E30 4K60 network AV encoder | D6: Equipment | E6: 6 | F6: 1345.56 | G6: =E6*F6 | H6: =ROUND(G6*0.1,2) | I6: =G6+H6 | J6: 51100
A7: 1 Core install | B7: Phase 2 | C7: Crestron DM-NVX-385 AV-over-IP switcher HDMI/USB-C | D7: Equipment | E7: 2 | F7: 3390.25 | G7: =E7*F7 | H7: =ROUND(G7*0.1,2) | I7: =G7+H7 | J7: 51100
A8: 1 Core install | B8: Phase 2 | C8: Crestron DM-NVX-360 4K60 encoder/decoder | D8: Equipment | E8: 8 | F8: 2144.14 | G8: =E8*F8 | H8: =ROUND(G8*0.1,2) | I8: =G8+H8 | J8: 51100
A9: 1 Core install | B9: Phase 2 | C9: Panasonic AW-UE40WEJ 4K integrated camera, white | D9: Equipment | E9: 4 | F9: 4063.96 | G9: =E9*F9 | H9: =ROUND(G9*0.1,2) | I9: =G9+H9 | J9: 51100
A10: 1 Core install | B10: Phase 2 | C10: Crestron UC-C100-T Flex Teams Rooms integrator kit | D10: Equipment | E10: 2 | F10: 5350.41 | G10: =E10*F10 | H10: =ROUND(G10*0.1,2) | I10: =G10+H10 | J10: 51100
A11: 1 Core install | B11: Phase 2 | C11: Q-SYS Core 24f DSP core | D11: Equipment | E11: 2 | F11: 8295.67 | G11: =E11*F11 | H11: =ROUND(G11*0.1,2) | I11: =G11+H11 | J11: 51100
A12: 1 Core install | B12: Phase 2 | C12: Crestron DM-NAX-BTIO-100-1G audio-over-IP wall plate | D12: Equipment | E12: 2 | F12: 815.49 | G12: =E12*F12 | H12: =ROUND(G12*0.1,2) | I12: =G12+H12 | J12: 51100
A13: 1 Core install | B13: Phase 2 | C13: Crestron FP-G1-B-T faceplate 1 gang black | D13: Equipment | E13: 2 | F13: 21 | G13: =E13*F13 | H13: =ROUND(G13*0.1,2) | I13: =G13+H13 | J13: 51100
A14: 1 Core install | B14: Phase 2 | C14: Crestron TSS-880-B 8.1in room scheduling touch screen | D14: Equipment | E14: 2 | F14: 1223.23 | G14: =E14*F14 | H14: =ROUND(G14*0.1,2) | I14: =G14+H14 | J14: 51100
A15: 1 Core install | B15: Phase 2 | C15: Crestron TSW-1080-B 10.1in wall mount touch screen | D15: Equipment | E15: 2 | F15: 3186.38 | G15: =E15*F15 | H15: =ROUND(G15*0.1,2) | I15: =G15+H15 | J15: 51100
A16: 1 Core install | B16: Phase 2 | C16: Crestron CP4N 4-series control system (later credited back) | D16: Equipment | E16: 1 | F16: 3032.23 | G16: =E16*F16 | H16: =ROUND(G16*0.1,2) | I16: =G16+H16 | J16: 51100
A17: 1 Core install | B17: Phase 2 | C17: Netgear M4250-26G4XF-PoE+ managed switch | D17: Equipment | E17: 2 | F17: 3179.58 | G17: =E17*F17 | H17: =ROUND(G17*0.1,2) | I17: =G17+H17 | J17: 51100
... A45: 5 Retention | B45: Not yet billed | C45: Remaining claim balance $4,848.68 to be invoiced | D45: Retention | E45: 1 | F45: -4848.68 | G45: =E45*F45 | H45: =ROUND(G45*0.1,2) | I45: =G45+H45 | J45: 51100
C47: TOTAL BILL | G47: =SUM(G6:G45) | H47: =SUM(H6:H45) | I47: =SUM(I6:I45)
C48: Xero bill total ex GST (check) | G48: 161926.6 | I48: 178119.25
C49: Difference (line-level GST rounding only) | G49: =ROUND(G47-G48,2) | I49: =ROUND(I47-I48,2)
C51: Subtotals by block
C52: Block | G52: Ex GST | H52: GST | I52: Inc GST
C53: 1 Core install | G53: =SUMIFS($G$6:$G$45,$A$6:$A$45,C53) | H53: =SUMIFS($H$6:$H$45,$A$6:$A$45,C53) | I53: =SUMIFS($I$6:$I$45,$A$6:$A$45,C53)
C54: 2 Extra encoders | G54: =SUMIFS($G$6:$G$45,$A$6:$A$45,C54) | H54: =SUMIFS($H$6:$H$45,$A$6:$A$45,C54) | I54: =SUMIFS($I$6:$I$45,$A$6:$A$45,C54)
C55: 3 Tracking & audio | G55: =SUMIFS($G$6:$G$45,$A$6:$A$45,C55) | H55: =SUMIFS($H$6:$H$45,$A$6:$A$45,C55) | I55: =SUMIFS($I$6:$I$45,$A$6:$A$45,C55)
C56: 4 Variations | G56: =SUMIFS($G$6:$G$45,$A$6:$A$45,C56) | H56: =SUMIFS($H$6:$H$45,$A$6:$A$45,C56) | I56: =SUMIFS($I$6:$I$45,$A$6:$A$45,C56)
C57: 5 Retention | G57: =SUMIFS($G$6:$G$45,$A$6:$A$45,C57) | H57: =SUMIFS($H$6:$H$45,$A$6:$A$45,C57) | I57: =SUMIFS($I$6:$I$45,$A$6:$A$45,C57)
C58: Blocks 1-3 (should equal PO-00016902, PO 1/2) | G58: =SUM(G53:G55) | I58: =SUM(I53:I55)
C59: PO-00016902 per Xero | G59: 177457.98 | I59: 195203.79
C60: Difference | G60: =ROUND(G58-G59,2) | I60: =ROUND(I58-I59,2)
C61: Full claim value (blocks 1-4, before retention) | G61: =SUM(G53:G56) | I61: =SUM(I53:I56)
C63: Subtotals by type
C64: Type | G64: Ex GST | H64: GST | I64: Inc GST
C65: Equipment | G65: =SUMIFS($G$6:$G$45,$D$6:$D$45,C65) | H65: =SUMIFS($H$6:$H$45,$D$6:$D$45,C65) | I65: =SUMIFS($I$6:$I$45,$D$6:$D$45,C65)
C66: Labour | G66: =SUMIFS($G$6:$G$45,$D$6:$D$45,C66) | H66: =SUMIFS($H$6:$H$45,$D$6:$D$45,C66) | I66: =SUMIFS($I$6:$I$45,$D$6:$D$45,C66)
C67: Freight | G67: =SUMIFS($G$6:$G$45,$D$6:$D$45,C67) | H67: =SUMIFS($H$6:$H$45,$D$6:$D$45,C67) | I67: =SUMIFS($I$6:$I$45,$D$6:$D$45,C67)
C68: Misc | G68: =SUMIFS($G$6:$G$45,$D$6:$D$45,C68) | H68: =SUMIFS($H$6:$H$45,$D$6:$D$45,C68) | I68: =SUMIFS($I$6:$I$45,$D$6:$D$45,C68)
C69: Variation | G69: =SUMIFS($G$6:$G$45,$D$6:$D$45,C69) | H69: =SUMIFS($H$6:$H$45,$D$6:$D$45,C69) | I69: =SUMIFS($I$6:$I$45,$D$6:$D$45,C69)
C70: Retention | G70: =SUMIFS($G$6:$G$45,$D$6:$D$45,C70) | H70: =SUMIFS($H$6:$H$45,$D$6:$D$45,C70) | I70: =SUMIFS($I$6:$I$45,$D$6:$D$45,C70)
C71: Labour incl. lighting integration programming (variation line) | G71: =G66+G44 | H71: =H66+H44 | I71: =I66+I44
...

Sheet Aware Invoice INV-10596
A1: Aware Super - Sales invoice INV-10596 'Aware Super Seminar Room AV Upgrade' (ex GST line detail from Xero)
A2: Invoice date 9 Sep 26, due 9 Oct 26, status Authorised (unpaid). Project 2604704. Aware invoices go to awaresuper.invoices@converga.com.au.
A4: Section | B4: Description | C4: Line ex GST | D4: GST | E4: Line inc GST | F4: Xero account
A5: Phase 1 | B5: Phase 1 - Audit | C5: 0 | D5: =ROUND(C5*0.1,2) | E5: =C5+D5
A6: Phase 2 | B6: Phase 2 - Installation and Integration | C6: 144049 | D6: =ROUND(C6*0.1,2) | E6: =C6+D6 | F6: 42300
A7: Option A | B7: Option A: Advanced Camera Tracking Features | C7: 45162 | D7: =ROUND(C7*0.1,2) | E7: =C7+D7 | F7: 42600
A8: Option B | B8: Option B: Additional Presenter Cameras | C8: 13436 | D8: =ROUND(C8*0.1,2) | E8: =C8+D8 | F8: 42600
A9: UE80 upgrade | B9: Upgrade Cost - Panasonic AW-UE40 to AW-UE80, Supply & Removal of Loan AW-UE80. 2x Devices | C9: 12042.88 | D9: =ROUND(C9*0.1,2) | E9: =C9+D9 | F9: 42600
A10: Variations | B10: Panasonic Cameras & Licences. Underlying change: 4x AW-UE40WEJ; (+2) PA AW-UE40KEJ; AW-SF200z, 300z, (1) 501Z | C10: -6188.91 | D10: =ROUND(C10*0.1,2) | E10: =C10+D10 | F10: 42600
A11: Variations | B11: RMB Hardware. Crestron TSW-880/1080-MSMK-ANG-B multisurface mount kit, angled, black | C11: 273.28 | D11: =ROUND(C11*0.1,2) | E11: =C11+D11 | F11: 42600
A12: Variations | B12: Control Processor. Crestron CP4N 4-series control system | C12: -2577.4 | D12: =ROUND(C12*0.1,2) | E12: =C12+D12 | F12: 42600
A13: Variations | B13: Camera Crestron Encoder. Crestron DM-NVX-E30 4K60 network AV encoder | C13: -3910.17 | D13: =ROUND(C13*0.1,2) | E13: =C13+D13 | F13: 42600
A14: Variations | B14: Cabling. Rack cabling | C14: 587.86 | D14: =ROUND(C14*0.1,2) | E14: =C14+D14 | F14: 42600
A15: Variations | B15: Graphics Card. Palit GeForce RTX 3060 Infinity 2 OC 12GB | C15: 1658.35 | D15: =ROUND(C15*0.1,2) | E15: =C15+D15 | F15: 42600
A16: Variations | B16: Lighting Integration Programming. Programming | C16: 819.28 | D16: =ROUND(C16*0.1,2) | E16: =C16+D16 | F16: 42600
B18: TOTAL INVOICE | C18: =SUM(C5:C16) | D18: =SUM(D5:D16) | E18: =SUM(E5:E16)
B19: Xero invoice total (check) | C19: 205352.17 | E19: 225887.4
B20: Difference (should be zero) | C20: =ROUND(C18-C19,2) | E20: =ROUND(E18-E19,2)
B22: Subtotals by section
B23: Section | C23: Ex GST | D23: GST | E23: Inc GST
B24: Phase 1 | C24: =SUMIFS($C$5:$C$16,$A$5:$A$16,B24) | D24: =SUMIFS($D$5:$D$16,$A$5:$A$16,B24) | E24: =SUMIFS($E$5:$E$16,$A$5:$A$16,B24)
B25: Phase 2 | C25: =SUMIFS($C$5:$C$16,$A$5:$A$16,B25) | D25: =SUMIFS($D$5:$D$16,$A$5:$A$16,B25) | E25: =SUMIFS($E$5:$E$16,$A$5:$A$16,B25)
B26: Option A | C26: =SUMIFS($C$5:$C$16,$A$5:$A$16,B26) | D26: =SUMIFS($D$5:$D$16,$A$5:$A$16,B26) | E26: =SUMIFS($E$5:$E$16,$A$5:$A$16,B26)
B27: Option B | C27: =SUMIFS($C$5:$C$16,$A$5:$A$16,B27) | D27: =SUMIFS($D$5:$D$16,$A$5:$A$16,B27) | E27: =SUMIFS($E$5:$E$16,$A$5:$A$16,B27)
B28: UE80 upgrade | C28: =SUMIFS($C$5:$C$16,$A$5:$A$16,B28) | D28: =SUMIFS($D$5:$D$16,$A$5:$A$16,B28) | E28: =SUMIFS($E$5:$E$16,$A$5:$A$16,B28)
B29: Variations | C29: =SUMIFS($C$5:$C$16,$A$5:$A$16,B29) | D29: =SUMIFS($D$5:$D$16,$A$5:$A$16,B29) | E29: =SUMIFS($E$5:$E$16,$A$5:$A$16,B29)
B30: Invoice states 'Total Variations Amount Credited is $9,337.71' | C30: -9337.71
B31: Difference to variation lines | C31: =ROUND(C29-C30,2)

Sheet Variations
A1: Variations: what Complete AV charged/credited CTS vs what CTS charged/credited Aware
A2: Green = pulled from the two invoice tabs. Every Aware figure is an exact 85% or 77% of the supplier figure, which is a discount off cost, not a markup.
A4: Variation | B4: Complete AV (cost to CTS) | C4: Aware (sell) | D4: Aware as % of cost | E4: Effect on CTS (sell - cost) | F4: Add or Remove | G4: Should have been at Phase 2 markup | H4: Shortfall vs Phase 2 markup
A5: Removed Panasonic cameras & licences | B5: ='Supplier Bill INV41565'!G38 | C5: ='Aware Invoice INV-10596'!C10 | D5: =IF(B5=0,0,C5/B5) | E5: =C5-B5 | F5: =IF(B5<0,"Remove (credit)","Add (charge)") | G5: =B5*'Section Margin'!$C$16 | H5: =C5-G5
A6: RMB hardware added (angled mount kit) | B6: ='Supplier Bill INV41565'!G39 | C6: ='Aware Invoice INV-10596'!C11 | D6: =IF(B6=0,0,C6/B6) | E6: =C6-B6 | F6: =IF(B6<0,"Remove (credit)","Add (charge)") | G6: =B6*'Section Margin'!$C$16 | H6: =C6-G6
A7: Removed control processor CP4N | B7: ='Supplier Bill INV41565'!G40 | C7: ='Aware Invoice INV-10596'!C12 | D7: =IF(B7=0,0,C7/B7) | E7: =C7-B7 | F7: =IF(B7<0,"Remove (credit)","Add (charge)") | G7: =B7*'Section Margin'!$C$16 | H7: =C7-G7
A8: Removed camera Crestron encoder/decoder | B8: ='Supplier Bill INV41565'!G41 | C8: ='Aware Invoice INV-10596'!C13 | D8: =IF(B8=0,0,C8/B8) | E8: =C8-B8 | F8: =IF(B8<0,"Remove (credit)","Add (charge)") | G8: =B8*'Section Margin'!$C$16 | H8: =C8-G8
A9: Cables (rack cabling) | B9: ='Supplier Bill INV41565'!G42 | C9: ='Aware Invoice INV-10596'!C14 | D9: =IF(B9=0,0,C9/B9) | E9: =C9-B9 | F9: =IF(B9<0,"Remove (credit)","Add (charge)") | G9: =B9*'Section Margin'!$C$16 | H9: =C9-G9
A10: Graphics card RTX 3060 | B10: ='Supplier Bill INV41565'!G43 | C10: ='Aware Invoice INV-10596'!C15 | D10: =IF(B10=0,0,C10/B10) | E10: =C10-B10 | F10: =IF(B10<0,"Remove (credit)","Add (charge)") | G10: =B10*'Section Margin'!$C$16 | H10: =C10-G10
A11: Lighting integration programming | B11: ='Supplier Bill INV41565'!G44 | C11: ='Aware Invoice INV-10596'!C16 | D11: =IF(B11=0,0,C11/B11) | E11: =C11-B11 | F11: =IF(B11<0,"Remove (credit)","Add (charge)") | G11: =B11*'Section Margin'!$C$16 | H11: =C11-G11
A12: NET | B12: =SUM(B5:B11) | C12: =SUM(C5:C11) | D12: =IF(B12=0,0,C12/B12) | E12: =SUM(E5:E11) | G12: =SUM(G5:G11) | H12: =SUM(H5:H11)
A14: Loss on ADDED items (Aware charged less than cost) | E14: =SUMIFS(E5:E11,F5:F11,"Add (charge)")
A15: Kept on REMOVED items (Aware credited less than CTS was credited) | E15: =SUMIFS(E5:E11,F5:F11,"Remove (credit)")
A16: Net effect on CTS | E16: =E14+E15
A18: Reading this: on the four added items CTS sells below cost. On the three removals CTS keeps part of the credit. The net is positive only because the removals happen to be bigger than the additions. The method (cost x 0.85 / 0.77) is a template or formula error and should be cost x markup. Column G shows what each line would have been at the Phase 2 sell/cost ratio.

Sheet Section Margin
A1: Section margin: Aware sell vs Complete AV cost, best-fit mapping of bill blocks to invoice lines
A2: Mapping caveat: the 4x Sennheiser ceiling mics ($23,786.60) sit in block 3 on the bill. If they belong to Phase 2 rather than Option A, the loss moves from Option A to Phase 2. Totals are unaffected. See the sensitivity below.
A4: Aware invoice line | B4: Sell to Aware ex GST | C4: Complete AV cost ex GST | D4: Cost source (bill block) | E4: Gross profit | F4: Margin % (GP / sell) | G4: Markup % (GP / cost)
A5: Phase 1 - Audit | B5: ='Aware Invoice INV-10596'!C24 | C5: 0 | D5: none billed | E5: =B5-C5 | F5: =IF(B5=0,0,E5/B5) | G5: =IF(C5=0,0,E5/C5)
A6: Phase 2 - Installation and Integration | B6: ='Aware Invoice INV-10596'!C25 | C6: ='Supplier Bill INV41565'!G53 | D6: Block 1 core install | E6: =B6-C6 | F6: =IF(B6=0,0,E6/B6) | G6: =IF(C6=0,0,E6/C6)
A7: Option A - Advanced Camera Tracking | B7: ='Aware Invoice INV-10596'!C26 | C7: ='Supplier Bill INV41565'!G55 | D7: Block 3 tracking & audio | E7: =B7-C7 | F7: =IF(B7=0,0,E7/B7) | G7: =IF(C7=0,0,E7/C7)
A8: Option B - Additional Presenter Cameras | B8: ='Aware Invoice INV-10596'!C27 | C8: ='Supplier Bill INV41565'!G54 | D8: Block 2 extra encoders | E8: =B8-C8 | F8: =IF(B8=0,0,E8/B8) | G8: =IF(C8=0,0,E8/C8)
A9: Upgrade UE40 to UE80 (2 units) | B9: ='Aware Invoice INV-10596'!C28 | C9: 0 | D9: NOT on INV41565 - probably PO-00016899 (PO 2/2) | E9: =B9-C9 | F9: =IF(B9=0,0,E9/B9) | G9: =IF(C9=0,0,E9/C9)
A10: Variations (net credit) | B10: ='Aware Invoice INV-10596'!C29 | C10: ='Supplier Bill INV41565'!G56 | D10: Block 4 variations | E10: =B10-C10 | F10: =IF(B10=0,0,E10/B10) | G10: =IF(C10=0,0,E10/C10)
A11: Total full claim value (blocks 1-4, i.e. after retention is eventually billed) | B11: =SUM(B5:B10) | C11: =SUM(C5:C10) | E11: =B11-C11 | F11: =IF(B11=0,0,E11/B11) | G11: =IF(C11=0,0,E11/C11)
A12: Less retention Complete AV has not billed yet (line on INV41565) | C12: ='Supplier Bill INV41565'!G57
A13: Total cost as billed today on INV41565 | B13: =B11 | C13: =C11+C12 | E13: =B13-C13 | F13: =IF(B13=0,0,E13/B13) | G13: =IF(C13=0,0,E13/C13)
A14: Add PO-00016899 (PO 2/2) if it is all cost for this job - UNCONFIRMED | C14: 17700.52
A15: Total if PO 2/2 is also project cost (full claim + PO 2/2) | B15: =B11 | C15: =C11+C14 | E15: =B15-C15 | F15: =IF(B15=0,0,E15/B15) | G15: =IF(C15=0,0,E15/C15)
A16: Phase 2 implied sell / cost ratio (used on Variations tab) | C16: =IF(C6=0,0,B6/C6)
A18: Sensitivity: if the Sennheiser mics and Dante licence belong to Phase 2 instead of Option A
A19: Line | B19: Sell | C19: Cost | E19: Gross profit | F19: Margin %
A20: Phase 2 incl. mics + Dante licence | B20: =B6 | C20: =C6+'Supplier Bill INV41565'!G32+'Supplier Bill INV41565'!G33 | E20: =B20-C20 | F20: =IF(B20=0,0,E20/B20)
A21: Option A excl. mics + Dante licence | B21: =B7 | C21: =C7-('Supplier Bill INV41565'!G32+'Supplier Bill INV41565'!G33) | E21: =B21-C21 | F21: =IF(B21=0,0,E21/B21)
A23: Labour on the bill incl. programming - Aware invoice does not split labour so labour margin cannot be isolated | C23: ='Supplier Bill INV41565'!G71
A24: Labour as % of full claim cost | C24: =IF(C11=0,0,C23/C11)

Sheet Notes & Sources
A1: Notes, sources and things that do not reconcile
A3: Topic | B3: Detail
A4: Sources | B4: Xero organisation Corporate Technology Services Pty Ltd. Bill INV41565 (Complete AV Solutions Pty Ltd, contact shaun@completeav.com.au). Invoice INV-10596 (Aware Super). Purchase orders PO-00016902 and PO-00016899. Data pulled 29 Sep 2026.
A5: PO 1/2 ties exactly | B5: Blocks 1-3 of the bill = $177,457.98 = PO-00016902 exactly. Less variations $10,682.70 = $166,775.28 full claim. Less retention $4,848.68 = $161,926.60 billed. Everything ties to the cent.
A6: PO 2/2 unknown | B6: PO-00016899 'Q-12140v1 Audio Visual Proposal (PO 2/2)' $17,700.52 ex GST, dated 24 Jul 26, status Authorised, not billed. PO line items are not visible through the Xero connector. This is the biggest unknown in the job.
A7: UE80 upgrade has no cost on the bill | B7: Aware is charged $12,042.88 for upgrading 2 cameras from AW-UE40 to AW-UE80 plus loan units. Nothing on INV41565 relates to UE80. The cost is either in PO 2/2 or from another supplier not yet billed.
A8: Option B cameras | B8: Aware's variation wording says the job added '(+2) PA AW-UE40KEJ' cameras, but the bill only has 4 cameras (block 1) and 2 extra encoders (block 2). The 2 extra cameras are either inside the 'Removed Panasonic cameras' credit or replaced by the UE80 upgrade. Confirm against Complete AV quote Q-12140v1.
A9: Removed lines do not reconcile to units | B9: 'Removed camera Crestron decoder' $4,600.20 is not a multiple of either E30 price (1,345.56 / 1,517.06) or the NVX-360 price (2,144.14). 'Removed Panasonic cameras & licences' $7,281.07 vs 4 cameras at 16,255.84 and three licences at 9,771.81. Ask Complete AV for the breakdown.
A10: Same part, two prices | B10: DM-NVX-E30 encoder is $1,345.56 each in block 1 and $1,517.06 each in block 2, $171.50 more per unit for the same part on the same bill.
A11: Account coding | B11: Bill: equipment 51100, labour 51325, freight 58225. Aware: Phase 2 to 42300 (services), options and variations to 42600 (equipment). Phase 2 is mostly equipment on the cost side, so revenue and cost land in different categories and gross margin by category will look odd in the P&L.
A12: Mapping caveat | B12: Block-to-line mapping is best fit from the bill's structure and the Aware headings. The Sennheiser mics could belong to Phase 2 rather than Option A. Totals are unaffected; see Section Margin tab sensitivity.
A13: Earlier claims | B13: No earlier Aware invoice exists for project 2604704. INV-10441 (29 May 26) is a different project, 555 Collins St Melbourne.

Sheet Invoice Extracts
A1: Line-item extracts of both documents as recorded in Xero (data extracts, not the original PDFs - the Xero connector cannot download attachments)
A3: Complete AV Solutions bill INV41565
A66: Aware Super sales invoice INV-10596
